{
  "version": 8,
  "blockIdVersion": 11,
  "anchorX": 0,
  "anchorY": 1,
  "anchorZ": 0,
  "blocks": [
    {
      "x": -4,
      "y": -3,
      "z": -1,
      "name": "Rock_Marble"
    },
    {
      "x": -4,
      "y": -2,
      "z": -1,
      "name": "Rock_Lime"
    },
    {
      "x": -4,
      "y": -1,
      "z": -1,
      "name": "Rock_Marble"
    },
    {
      "x": -4,
      "y": 0,
      "z": -1,
      "name": "Rock_Marble"
    },
    {
      "x": -4,
      "y": 1,
      "z": -1,
      "name": "Rock_Marble_SkyGrass"
    },
    {
      "x": -4,
      "y": -3,
      "z": 0,
      "name": "Rock_Marble"
    },
    {
      "x": -4,
      "y": -2,
      "z": 0,
      "name": "Rock_Lime"
    },
    {
      "x": -4,
      "y": -1,
      "z": 0,
      "name": "Rock_Marble"
    },
    {
      "x": -4,
      "y": 0,
      "z": 0,
      "name": "Rock_Marble"
    },
    {
      "x": -4,
      "y": 1,
      "z": 0,
      "name": "Rock_Marble_SkyGrass"
    },
    {
      "x": -4,
      "y": -3,
      "z": 1,
      "name": "Rock_Marble"
    },
    {
      "x": -4,
      "y": -2,
      "z": 1,
      "name": "Rock_Lime"
    },
    {
      "x": -4,
      "y": -1,
      "z": 1,
      "name": "Rock_Lime"
    },
    {
      "x": -4,
      "y": 0,
      "z": 1,
      "name": "Rock_Marble"
    },
    {
      "x": -4,
      "y": 1,
      "z": 1,
      "name": "Rock_Marble_SkyGrass"
    },
    {
      "x": -3,
      "y": -3,
      "z": -3,
      "name": "Rock_Marble"
    },
    {
      "x": -3,
      "y": -2,
      "z": -3,
      "name": "Rock_Marble"
    },
    {
      "x": -3,
      "y": -1,
      "z": -3,
      "name": "Rock_Marble"
    },
    {
      "x": -3,
      "y": 0,
      "z": -3,
      "name": "Rock_Marble"
    },
    {
      "x": -3,
      "y": 1,
      "z": -3,
      "name": "Rock_Marble_SkyGrass"
    },
    {
      "x": -3,
      "y": 2,
      "z": -3,
      "name": "Plant_Grass_Sky_Long",
      "support": 15
    },
    {
      "x": -3,
      "y": -3,
      "z": -2,
      "name": "Rock_Marble"
    },
    {
      "x": -3,
      "y": -2,
      "z": -2,
      "name": "Rock_Marble"
    },
    {
      "x": -3,
      "y": -1,
      "z": -2,
      "name": "Rock_Marble"
    },
    {
      "x": -3,
      "y": 0,
      "z": -2,
      "name": "Rock_Marble"
    },
    {
      "x": -3,
      "y": 1,
      "z": -2,
      "name": "Rock_Marble_SkyGrass"
    },
    {
      "x": -3,
      "y": 2,
      "z": -2,
      "name": "Plant_Grass_Sky_Short",
      "support": 15
    },
    {
      "x": -3,
      "y": -3,
      "z": -1,
      "name": "Rock_Marble"
    },
    {
      "x": -3,
      "y": -2,
      "z": -1,
      "name": "Rock_Marble"
    },
    {
      "x": -3,
      "y": -1,
      "z": -1,
      "name": "Rock_Marble"
    },
    {
      "x": -3,
      "y": 0,
      "z": -1,
      "name": "Rock_Marble"
    },
    {
      "x": -3,
      "y": 1,
      "z": -1,
      "name": "Rock_Marble_SkyGrass"
    },
    {
      "x": -3,
      "y": -3,
      "z": 0,
      "name": "Rock_Marble"
    },
    {
      "x": -3,
      "y": -2,
      "z": 0,
      "name": "Rock_Marble"
    },
    {
      "x": -3,
      "y": -1,
      "z": 0,
      "name": "Rock_Marble"
    },
    {
      "x": -3,
      "y": 0,
      "z": 0,
      "name": "Rock_Marble"
    },
    {
      "x": -3,
      "y": 1,
      "z": 0,
      "name": "Rock_Marble_SkyGrass"
    },
    {
      "x": -3,
      "y": -5,
      "z": 1,
      "name": "Rock_Marble"
    },
    {
      "x": -3,
      "y": -4,
      "z": 1,
      "name": "Rock_Marble"
    },
    {
      "x": -3,
      "y": -3,
      "z": 1,
      "name": "Rock_Marble"
    },
    {
      "x": -3,
      "y": -2,
      "z": 1,
      "name": "Rock_Marble"
    },
    {
      "x": -3,
      "y": -1,
      "z": 1,
      "name": "Rock_Marble"
    },
    {
      "x": -3,
      "y": 0,
      "z": 1,
      "name": "Rock_Marble"
    },
    {
      "x": -3,
      "y": 1,
      "z": 1,
      "name": "Rock_Marble_SkyGrass"
    },
    {
      "x": -3,
      "y": -5,
      "z": 2,
      "name": "Rock_Marble"
    },
    {
      "x": -3,
      "y": -4,
      "z": 2,
      "name": "Rock_Marble"
    },
    {
      "x": -3,
      "y": -3,
      "z": 2,
      "name": "Rock_Marble"
    },
    {
      "x": -3,
      "y": -2,
      "z": 2,
      "name": "Rock_Lime"
    },
    {
      "x": -3,
      "y": -1,
      "z": 2,
      "name": "Rock_Lime"
    },
    {
      "x": -3,
      "y": 0,
      "z": 2,
      "name": "Rock_Marble"
    },
    {
      "x": -3,
      "y": 1,
      "z": 2,
      "name": "Rock_Marble_SkyGrass"
    },
    {
      "x": -3,
      "y": -5,
      "z": 3,
      "name": "Rock_Marble"
    },
    {
      "x": -3,
      "y": -4,
      "z": 3,
      "name": "Rock_Marble"
    },
    {
      "x": -3,
      "y": -3,
      "z": 3,
      "name": "Rock_Marble"
    },
    {
      "x": -3,
      "y": -2,
      "z": 3,
      "name": "Rock_Lime"
    },
    {
      "x": -3,
      "y": -1,
      "z": 3,
      "name": "Rock_Lime"
    },
    {
      "x": -3,
      "y": 0,
      "z": 3,
      "name": "Rock_Marble"
    },
    {
      "x": -3,
      "y": 1,
      "z": 3,
      "name": "Rock_Marble_SkyGrass"
    },
    {
      "x": -2,
      "y": -3,
      "z": -3,
      "name": "Rock_Marble"
    },
    {
      "x": -2,
      "y": -2,
      "z": -3,
      "name": "Rock_Marble"
    },
    {
      "x": -2,
      "y": -1,
      "z": -3,
      "name": "Rock_Marble"
    },
    {
      "x": -2,
      "y": 0,
      "z": -3,
      "name": "Rock_Marble"
    },
    {
      "x": -2,
      "y": 1,
      "z": -3,
      "name": "Rock_Marble_SkyGrass"
    },
    {
      "x": -2,
      "y": -3,
      "z": -2,
      "name": "Rock_Marble"
    },
    {
      "x": -2,
      "y": -2,
      "z": -2,
      "name": "Rock_Marble"
    },
    {
      "x": -2,
      "y": -1,
      "z": -2,
      "name": "Rock_Marble"
    },
    {
      "x": -2,
      "y": 0,
      "z": -2,
      "name": "Rock_Marble"
    },
    {
      "x": -2,
      "y": 1,
      "z": -2,
      "name": "Rock_Marble_SkyGrass"
    },
    {
      "x": -2,
      "y": -3,
      "z": -1,
      "name": "Rock_Marble"
    },
    {
      "x": -2,
      "y": -2,
      "z": -1,
      "name": "Rock_Marble"
    },
    {
      "x": -2,
      "y": -1,
      "z": -1,
      "name": "Rock_Marble"
    },
    {
      "x": -2,
      "y": 0,
      "z": -1,
      "name": "Rock_Marble"
    },
    {
      "x": -2,
      "y": 1,
      "z": -1,
      "name": "Rock_Marble_SkyGrass"
    },
    {
      "x": -2,
      "y": -3,
      "z": 0,
      "name": "Rock_Marble"
    },
    {
      "x": -2,
      "y": -2,
      "z": 0,
      "name": "Rock_Marble"
    },
    {
      "x": -2,
      "y": -1,
      "z": 0,
      "name": "Rock_Marble"
    },
    {
      "x": -2,
      "y": 0,
      "z": 0,
      "name": "Rock_Marble"
    },
    {
      "x": -2,
      "y": 1,
      "z": 0,
      "name": "Rock_Marble_SkyGrass"
    },
    {
      "x": -2,
      "y": -5,
      "z": 1,
      "name": "Rock_Marble"
    },
    {
      "x": -2,
      "y": -4,
      "z": 1,
      "name": "Rock_Marble"
    },
    {
      "x": -2,
      "y": -3,
      "z": 1,
      "name": "Rock_Marble"
    },
    {
      "x": -2,
      "y": -2,
      "z": 1,
      "name": "Rock_Marble"
    },
    {
      "x": -2,
      "y": -1,
      "z": 1,
      "name": "Rock_Marble"
    },
    {
      "x": -2,
      "y": 0,
      "z": 1,
      "name": "Rock_Marble"
    },
    {
      "x": -2,
      "y": 1,
      "z": 1,
      "name": "Rock_Lime"
    },
    {
      "x": -2,
      "y": -5,
      "z": 2,
      "name": "Rock_Marble"
    },
    {
      "x": -2,
      "y": -4,
      "z": 2,
      "name": "Rock_Marble"
    },
    {
      "x": -2,
      "y": -3,
      "z": 2,
      "name": "Rock_Marble"
    },
    {
      "x": -2,
      "y": -2,
      "z": 2,
      "name": "Rock_Marble"
    },
    {
      "x": -2,
      "y": -1,
      "z": 2,
      "name": "Rock_Marble"
    },
    {
      "x": -2,
      "y": 0,
      "z": 2,
      "name": "Rock_Marble"
    },
    {
      "x": -2,
      "y": 1,
      "z": 2,
      "name": "Rock_Marble_SkyGrass"
    },
    {
      "x": -2,
      "y": -5,
      "z": 3,
      "name": "Rock_Marble"
    },
    {
      "x": -2,
      "y": -4,
      "z": 3,
      "name": "Rock_Marble"
    },
    {
      "x": -2,
      "y": -3,
      "z": 3,
      "name": "Rock_Marble"
    },
    {
      "x": -2,
      "y": -2,
      "z": 3,
      "name": "Rock_Lime"
    },
    {
      "x": -2,
      "y": -1,
      "z": 3,
      "name": "Rock_Lime"
    },
    {
      "x": -2,
      "y": 0,
      "z": 3,
      "name": "Rock_Marble"
    },
    {
      "x": -2,
      "y": 1,
      "z": 3,
      "name": "Rock_Marble_SkyGrass"
    },
    {
      "x": -2,
      "y": 2,
      "z": 3,
      "name": "Plant_Grass_Sky_Long",
      "support": 15
    },
    {
      "x": -1,
      "y": -3,
      "z": -4,
      "name": "Rock_Marble"
    },
    {
      "x": -1,
      "y": -2,
      "z": -4,
      "name": "Rock_Marble"
    },
    {
      "x": -1,
      "y": -1,
      "z": -4,
      "name": "Rock_Marble"
    },
    {
      "x": -1,
      "y": 0,
      "z": -4,
      "name": "Rock_Marble"
    },
    {
      "x": -1,
      "y": 1,
      "z": -4,
      "name": "Rock_Marble_SkyGrass"
    },
    {
      "x": -1,
      "y": -4,
      "z": -3,
      "name": "Rock_Marble"
    },
    {
      "x": -1,
      "y": -3,
      "z": -3,
      "name": "Rock_Marble"
    },
    {
      "x": -1,
      "y": -2,
      "z": -3,
      "name": "Rock_Marble"
    },
    {
      "x": -1,
      "y": -1,
      "z": -3,
      "name": "Rock_Marble"
    },
    {
      "x": -1,
      "y": 0,
      "z": -3,
      "name": "Rock_Marble"
    },
    {
      "x": -1,
      "y": 1,
      "z": -3,
      "name": "Rock_Marble_SkyGrass"
    },
    {
      "x": -1,
      "y": -4,
      "z": -2,
      "name": "Rock_Marble"
    },
    {
      "x": -1,
      "y": -3,
      "z": -2,
      "name": "Rock_Marble"
    },
    {
      "x": -1,
      "y": -2,
      "z": -2,
      "name": "Rock_Marble"
    },
    {
      "x": -1,
      "y": -1,
      "z": -2,
      "name": "Rock_Marble"
    },
    {
      "x": -1,
      "y": 0,
      "z": -2,
      "name": "Rock_Marble"
    },
    {
      "x": -1,
      "y": 1,
      "z": -2,
      "name": "Rock_Marble_SkyGrass"
    },
    {
      "x": -1,
      "y": -3,
      "z": -1,
      "name": "Rock_Marble"
    },
    {
      "x": -1,
      "y": -2,
      "z": -1,
      "name": "Rock_Marble"
    },
    {
      "x": -1,
      "y": -1,
      "z": -1,
      "name": "Rock_Marble"
    },
    {
      "x": -1,
      "y": 0,
      "z": -1,
      "name": "Rock_Marble"
    },
    {
      "x": -1,
      "y": 1,
      "z": -1,
      "name": "Rock_Lime"
    },
    {
      "x": -1,
      "y": -3,
      "z": 0,
      "name": "Rock_Marble"
    },
    {
      "x": -1,
      "y": -2,
      "z": 0,
      "name": "Rock_Marble"
    },
    {
      "x": -1,
      "y": -1,
      "z": 0,
      "name": "Rock_Marble"
    },
    {
      "x": -1,
      "y": 0,
      "z": 0,
      "name": "Rock_Marble"
    },
    {
      "x": -1,
      "y": 1,
      "z": 0,
      "name": "Rock_Marble_SkyGrass"
    },
    {
      "x": -1,
      "y": 2,
      "z": 0,
      "name": "Plant_Grass_Sky_Short",
      "support": 15
    },
    {
      "x": -1,
      "y": -5,
      "z": 1,
      "name": "Rock_Marble"
    },
    {
      "x": -1,
      "y": -4,
      "z": 1,
      "name": "Rock_Marble"
    },
    {
      "x": -1,
      "y": -3,
      "z": 1,
      "name": "Rock_Marble"
    },
    {
      "x": -1,
      "y": -2,
      "z": 1,
      "name": "Rock_Marble"
    },
    {
      "x": -1,
      "y": -1,
      "z": 1,
      "name": "Rock_Marble"
    },
    {
      "x": -1,
      "y": 0,
      "z": 1,
      "name": "Rock_Marble"
    },
    {
      "x": -1,
      "y": 1,
      "z": 1,
      "name": "Rock_Marble_SkyGrass"
    },
    {
      "x": -1,
      "y": -5,
      "z": 2,
      "name": "Rock_Marble"
    },
    {
      "x": -1,
      "y": -4,
      "z": 2,
      "name": "Rock_Marble"
    },
    {
      "x": -1,
      "y": -3,
      "z": 2,
      "name": "Rock_Marble"
    },
    {
      "x": -1,
      "y": -2,
      "z": 2,
      "name": "Rock_Marble"
    },
    {
      "x": -1,
      "y": -1,
      "z": 2,
      "name": "Rock_Marble"
    },
    {
      "x": -1,
      "y": 0,
      "z": 2,
      "name": "Rock_Marble"
    },
    {
      "x": -1,
      "y": 1,
      "z": 2,
      "name": "Rock_Marble_SkyGrass"
    },
    {
      "x": -1,
      "y": 2,
      "z": 2,
      "name": "Plant_Grass_Sky",
      "support": 15
    },
    {
      "x": -1,
      "y": -5,
      "z": 3,
      "name": "Rock_Marble"
    },
    {
      "x": -1,
      "y": -4,
      "z": 3,
      "name": "Rock_Marble"
    },
    {
      "x": -1,
      "y": -3,
      "z": 3,
      "name": "Rock_Marble"
    },
    {
      "x": -1,
      "y": -2,
      "z": 3,
      "name": "Rock_Marble"
    },
    {
      "x": -1,
      "y": -1,
      "z": 3,
      "name": "Rock_Marble"
    },
    {
      "x": -1,
      "y": 0,
      "z": 3,
      "name": "Rock_Marble"
    },
    {
      "x": -1,
      "y": 1,
      "z": 3,
      "name": "Rock_Marble_SkyGrass"
    },
    {
      "x": -1,
      "y": 2,
      "z": 3,
      "name": "Plant_Grass_Sky_Short",
      "support": 15
    },
    {
      "x": -1,
      "y": -3,
      "z": 4,
      "name": "Rock_Marble"
    },
    {
      "x": -1,
      "y": -2,
      "z": 4,
      "name": "Rock_Lime"
    },
    {
      "x": -1,
      "y": -1,
      "z": 4,
      "name": "Rock_Lime"
    },
    {
      "x": -1,
      "y": 0,
      "z": 4,
      "name": "Rock_Marble"
    },
    {
      "x": -1,
      "y": 1,
      "z": 4,
      "name": "Rock_Marble_SkyGrass"
    },
    {
      "x": 0,
      "y": -4,
      "z": -4,
      "name": "Rock_Marble"
    },
    {
      "x": 0,
      "y": -3,
      "z": -4,
      "name": "Rock_Marble"
    },
    {
      "x": 0,
      "y": -2,
      "z": -4,
      "name": "Rock_Marble"
    },
    {
      "x": 0,
      "y": -1,
      "z": -4,
      "name": "Rock_Marble"
    },
    {
      "x": 0,
      "y": 0,
      "z": -4,
      "name": "Rock_Marble"
    },
    {
      "x": 0,
      "y": 1,
      "z": -4,
      "name": "Rock_Marble_SkyGrass"
    },
    {
      "x": 0,
      "y": -4,
      "z": -3,
      "name": "Rock_Marble"
    },
    {
      "x": 0,
      "y": -3,
      "z": -3,
      "name": "Rock_Marble"
    },
    {
      "x": 0,
      "y": -2,
      "z": -3,
      "name": "Rock_Marble"
    },
    {
      "x": 0,
      "y": -1,
      "z": -3,
      "name": "Rock_Marble"
    },
    {
      "x": 0,
      "y": 0,
      "z": -3,
      "name": "Rock_Marble"
    },
    {
      "x": 0,
      "y": 1,
      "z": -3,
      "name": "Rock_Marble_SkyGrass"
    },
    {
      "x": 0,
      "y": 2,
      "z": -3,
      "name": "Plant_Grass_Sky",
      "support": 15
    },
    {
      "x": 0,
      "y": -4,
      "z": -2,
      "name": "Rock_Marble"
    },
    {
      "x": 0,
      "y": -3,
      "z": -2,
      "name": "Rock_Marble"
    },
    {
      "x": 0,
      "y": -2,
      "z": -2,
      "name": "Rock_Marble"
    },
    {
      "x": 0,
      "y": -1,
      "z": -2,
      "name": "Rock_Marble"
    },
    {
      "x": 0,
      "y": 0,
      "z": -2,
      "name": "Rock_Marble"
    },
    {
      "x": 0,
      "y": 1,
      "z": -2,
      "name": "Rock_Chalk"
    },
    {
      "x": 0,
      "y": -4,
      "z": -1,
      "name": "Rock_Marble"
    },
    {
      "x": 0,
      "y": -3,
      "z": -1,
      "name": "Rock_Marble"
    },
    {
      "x": 0,
      "y": -2,
      "z": -1,
      "name": "Rock_Marble"
    },
    {
      "x": 0,
      "y": -1,
      "z": -1,
      "name": "Rock_Marble"
    },
    {
      "x": 0,
      "y": 0,
      "z": -1,
      "name": "Rock_Marble"
    },
    {
      "x": 0,
      "y": 1,
      "z": -1,
      "name": "Rock_Chalk"
    },
    {
      "x": 0,
      "y": -3,
      "z": 0,
      "name": "Rock_Marble"
    },
    {
      "x": 0,
      "y": -2,
      "z": 0,
      "name": "Rock_Marble"
    },
    {
      "x": 0,
      "y": -1,
      "z": 0,
      "name": "Rock_Marble"
    },
    {
      "x": 0,
      "y": 0,
      "z": 0,
      "name": "Rock_Marble"
    },
    {
      "x": 0,
      "y": 1,
      "z": 0,
      "name": "Rock_Lime"
    },
    {
      "x": 0,
      "y": -3,
      "z": 1,
      "name": "Rock_Marble"
    },
    {
      "x": 0,
      "y": -2,
      "z": 1,
      "name": "Rock_Marble"
    },
    {
      "x": 0,
      "y": -1,
      "z": 1,
      "name": "Rock_Marble"
    },
    {
      "x": 0,
      "y": 0,
      "z": 1,
      "name": "Rock_Marble"
    },
    {
      "x": 0,
      "y": 1,
      "z": 1,
      "name": "Rock_Lime"
    },
    {
      "x": 0,
      "y": -3,
      "z": 2,
      "name": "Rock_Marble"
    },
    {
      "x": 0,
      "y": -2,
      "z": 2,
      "name": "Rock_Marble"
    },
    {
      "x": 0,
      "y": -1,
      "z": 2,
      "name": "Rock_Marble"
    },
    {
      "x": 0,
      "y": 0,
      "z": 2,
      "name": "Rock_Marble"
    },
    {
      "x": 0,
      "y": 1,
      "z": 2,
      "name": "Rock_Marble_SkyGrass"
    },
    {
      "x": 0,
      "y": 2,
      "z": 2,
      "name": "Plant_Grass_Sky_Short",
      "support": 15
    },
    {
      "x": 0,
      "y": -3,
      "z": 3,
      "name": "Rock_Marble"
    },
    {
      "x": 0,
      "y": -2,
      "z": 3,
      "name": "Rock_Marble"
    },
    {
      "x": 0,
      "y": -1,
      "z": 3,
      "name": "Rock_Marble"
    },
    {
      "x": 0,
      "y": 0,
      "z": 3,
      "name": "Rock_Marble"
    },
    {
      "x": 0,
      "y": 1,
      "z": 3,
      "name": "Rock_Marble_SkyGrass"
    },
    {
      "x": 0,
      "y": -3,
      "z": 4,
      "name": "Rock_Marble"
    },
    {
      "x": 0,
      "y": -2,
      "z": 4,
      "name": "Rock_Marble"
    },
    {
      "x": 0,
      "y": -1,
      "z": 4,
      "name": "Rock_Lime"
    },
    {
      "x": 0,
      "y": 0,
      "z": 4,
      "name": "Rock_Marble"
    },
    {
      "x": 0,
      "y": 1,
      "z": 4,
      "name": "Rock_Marble_SkyGrass"
    },
    {
      "x": 1,
      "y": -4,
      "z": -4,
      "name": "Rock_Marble"
    },
    {
      "x": 1,
      "y": -3,
      "z": -4,
      "name": "Rock_Marble"
    },
    {
      "x": 1,
      "y": -2,
      "z": -4,
      "name": "Rock_Marble"
    },
    {
      "x": 1,
      "y": -1,
      "z": -4,
      "name": "Rock_Marble"
    },
    {
      "x": 1,
      "y": 0,
      "z": -4,
      "name": "Rock_Marble"
    },
    {
      "x": 1,
      "y": 1,
      "z": -4,
      "name": "Rock_Marble_SkyGrass"
    },
    {
      "x": 1,
      "y": 2,
      "z": -4,
      "name": "Plant_Grass_Sky_Long",
      "support": 15
    },
    {
      "x": 1,
      "y": -4,
      "z": -3,
      "name": "Rock_Marble"
    },
    {
      "x": 1,
      "y": -3,
      "z": -3,
      "name": "Rock_Marble"
    },
    {
      "x": 1,
      "y": -2,
      "z": -3,
      "name": "Rock_Marble"
    },
    {
      "x": 1,
      "y": -1,
      "z": -3,
      "name": "Rock_Marble"
    },
    {
      "x": 1,
      "y": 0,
      "z": -3,
      "name": "Rock_Marble"
    },
    {
      "x": 1,
      "y": 1,
      "z": -3,
      "name": "Rock_Marble_SkyGrass"
    },
    {
      "x": 1,
      "y": 2,
      "z": -3,
      "name": "Plant_Grass_Sky_Short",
      "support": 15
    },
    {
      "x": 1,
      "y": -4,
      "z": -2,
      "name": "Rock_Marble"
    },
    {
      "x": 1,
      "y": -3,
      "z": -2,
      "name": "Rock_Marble"
    },
    {
      "x": 1,
      "y": -2,
      "z": -2,
      "name": "Rock_Marble"
    },
    {
      "x": 1,
      "y": -1,
      "z": -2,
      "name": "Rock_Marble"
    },
    {
      "x": 1,
      "y": 0,
      "z": -2,
      "name": "Rock_Marble"
    },
    {
      "x": 1,
      "y": 1,
      "z": -2,
      "name": "Rock_Chalk"
    },
    {
      "x": 1,
      "y": -4,
      "z": -1,
      "name": "Rock_Marble"
    },
    {
      "x": 1,
      "y": -3,
      "z": -1,
      "name": "Rock_Marble"
    },
    {
      "x": 1,
      "y": -2,
      "z": -1,
      "name": "Rock_Marble"
    },
    {
      "x": 1,
      "y": -1,
      "z": -1,
      "name": "Rock_Marble"
    },
    {
      "x": 1,
      "y": 0,
      "z": -1,
      "name": "Rock_Marble"
    },
    {
      "x": 1,
      "y": 1,
      "z": -1,
      "name": "Rock_Chalk"
    },
    {
      "x": 1,
      "y": -3,
      "z": 0,
      "name": "Rock_Marble"
    },
    {
      "x": 1,
      "y": -2,
      "z": 0,
      "name": "Rock_Marble"
    },
    {
      "x": 1,
      "y": -1,
      "z": 0,
      "name": "Rock_Marble"
    },
    {
      "x": 1,
      "y": 0,
      "z": 0,
      "name": "Rock_Marble"
    },
    {
      "x": 1,
      "y": 1,
      "z": 0,
      "name": "Rock_Lime"
    },
    {
      "x": 1,
      "y": -3,
      "z": 1,
      "name": "Rock_Marble"
    },
    {
      "x": 1,
      "y": -2,
      "z": 1,
      "name": "Rock_Marble"
    },
    {
      "x": 1,
      "y": -1,
      "z": 1,
      "name": "Rock_Marble"
    },
    {
      "x": 1,
      "y": 0,
      "z": 1,
      "name": "Rock_Marble"
    },
    {
      "x": 1,
      "y": 1,
      "z": 1,
      "name": "Rock_Lime"
    },
    {
      "x": 1,
      "y": -3,
      "z": 2,
      "name": "Rock_Marble"
    },
    {
      "x": 1,
      "y": -2,
      "z": 2,
      "name": "Rock_Marble"
    },
    {
      "x": 1,
      "y": -1,
      "z": 2,
      "name": "Rock_Marble"
    },
    {
      "x": 1,
      "y": 0,
      "z": 2,
      "name": "Rock_Marble"
    },
    {
      "x": 1,
      "y": 1,
      "z": 2,
      "name": "Rock_Marble_SkyGrass"
    },
    {
      "x": 1,
      "y": -3,
      "z": 3,
      "name": "Rock_Marble"
    },
    {
      "x": 1,
      "y": -2,
      "z": 3,
      "name": "Rock_Marble"
    },
    {
      "x": 1,
      "y": -1,
      "z": 3,
      "name": "Rock_Marble"
    },
    {
      "x": 1,
      "y": 0,
      "z": 3,
      "name": "Rock_Marble"
    },
    {
      "x": 1,
      "y": 1,
      "z": 3,
      "name": "Rock_Marble_SkyGrass"
    },
    {
      "x": 1,
      "y": -3,
      "z": 4,
      "name": "Rock_Marble"
    },
    {
      "x": 1,
      "y": -2,
      "z": 4,
      "name": "Rock_Chalk"
    },
    {
      "x": 1,
      "y": -1,
      "z": 4,
      "name": "Rock_Marble"
    },
    {
      "x": 1,
      "y": 0,
      "z": 4,
      "name": "Rock_Marble"
    },
    {
      "x": 1,
      "y": 1,
      "z": 4,
      "name": "Rock_Marble_SkyGrass"
    },
    {
      "x": 2,
      "y": -4,
      "z": -3,
      "name": "Rock_Marble"
    },
    {
      "x": 2,
      "y": -3,
      "z": -3,
      "name": "Rock_Marble"
    },
    {
      "x": 2,
      "y": -2,
      "z": -3,
      "name": "Rock_Marble"
    },
    {
      "x": 2,
      "y": -1,
      "z": -3,
      "name": "Rock_Marble"
    },
    {
      "x": 2,
      "y": 0,
      "z": -3,
      "name": "Rock_Marble"
    },
    {
      "x": 2,
      "y": 1,
      "z": -3,
      "name": "Rock_Marble_SkyGrass"
    },
    {
      "x": 2,
      "y": -4,
      "z": -2,
      "name": "Rock_Marble"
    },
    {
      "x": 2,
      "y": -3,
      "z": -2,
      "name": "Rock_Marble"
    },
    {
      "x": 2,
      "y": -2,
      "z": -2,
      "name": "Rock_Marble"
    },
    {
      "x": 2,
      "y": -1,
      "z": -2,
      "name": "Rock_Marble"
    },
    {
      "x": 2,
      "y": 0,
      "z": -2,
      "name": "Rock_Marble"
    },
    {
      "x": 2,
      "y": 1,
      "z": -2,
      "name": "Rock_Marble_SkyGrass"
    },
    {
      "x": 2,
      "y": -3,
      "z": -1,
      "name": "Rock_Chalk"
    },
    {
      "x": 2,
      "y": -2,
      "z": -1,
      "name": "Rock_Marble"
    },
    {
      "x": 2,
      "y": -1,
      "z": -1,
      "name": "Rock_Marble"
    },
    {
      "x": 2,
      "y": 0,
      "z": -1,
      "name": "Rock_Marble"
    },
    {
      "x": 2,
      "y": 1,
      "z": -1,
      "name": "Rock_Lime"
    },
    {
      "x": 2,
      "y": -3,
      "z": 0,
      "name": "Rock_Chalk"
    },
    {
      "x": 2,
      "y": -2,
      "z": 0,
      "name": "Rock_Marble"
    },
    {
      "x": 2,
      "y": -1,
      "z": 0,
      "name": "Rock_Marble"
    },
    {
      "x": 2,
      "y": 0,
      "z": 0,
      "name": "Rock_Marble"
    },
    {
      "x": 2,
      "y": 1,
      "z": 0,
      "name": "Rock_Lime"
    },
    {
      "x": 2,
      "y": -3,
      "z": 1,
      "name": "Rock_Chalk"
    },
    {
      "x": 2,
      "y": -2,
      "z": 1,
      "name": "Rock_Chalk"
    },
    {
      "x": 2,
      "y": -1,
      "z": 1,
      "name": "Rock_Marble"
    },
    {
      "x": 2,
      "y": 0,
      "z": 1,
      "name": "Rock_Marble"
    },
    {
      "x": 2,
      "y": 1,
      "z": 1,
      "name": "Rock_Marble_SkyGrass"
    },
    {
      "x": 2,
      "y": -3,
      "z": 2,
      "name": "Rock_Chalk"
    },
    {
      "x": 2,
      "y": -2,
      "z": 2,
      "name": "Rock_Marble"
    },
    {
      "x": 2,
      "y": -1,
      "z": 2,
      "name": "Rock_Marble"
    },
    {
      "x": 2,
      "y": 0,
      "z": 2,
      "name": "Rock_Marble"
    },
    {
      "x": 2,
      "y": 1,
      "z": 2,
      "name": "Rock_Marble_SkyGrass"
    },
    {
      "x": 2,
      "y": 2,
      "z": 2,
      "name": "Plant_Grass_Sky_Short",
      "support": 15
    },
    {
      "x": 2,
      "y": -3,
      "z": 3,
      "name": "Rock_Chalk"
    },
    {
      "x": 2,
      "y": -2,
      "z": 3,
      "name": "Rock_Chalk"
    },
    {
      "x": 2,
      "y": -1,
      "z": 3,
      "name": "Rock_Marble"
    },
    {
      "x": 2,
      "y": 0,
      "z": 3,
      "name": "Rock_Marble"
    },
    {
      "x": 2,
      "y": 1,
      "z": 3,
      "name": "Rock_Marble_SkyGrass"
    },
    {
      "x": 3,
      "y": -3,
      "z": -3,
      "name": "Rock_Marble"
    },
    {
      "x": 3,
      "y": -2,
      "z": -3,
      "name": "Rock_Marble"
    },
    {
      "x": 3,
      "y": -1,
      "z": -3,
      "name": "Rock_Marble"
    },
    {
      "x": 3,
      "y": 0,
      "z": -3,
      "name": "Rock_Marble"
    },
    {
      "x": 3,
      "y": 1,
      "z": -3,
      "name": "Rock_Marble_SkyGrass"
    },
    {
      "x": 3,
      "y": -3,
      "z": -2,
      "name": "Rock_Marble"
    },
    {
      "x": 3,
      "y": -2,
      "z": -2,
      "name": "Rock_Marble"
    },
    {
      "x": 3,
      "y": -1,
      "z": -2,
      "name": "Rock_Marble"
    },
    {
      "x": 3,
      "y": 0,
      "z": -2,
      "name": "Rock_Marble"
    },
    {
      "x": 3,
      "y": 1,
      "z": -2,
      "name": "Rock_Marble_SkyGrass"
    },
    {
      "x": 3,
      "y": -3,
      "z": -1,
      "name": "Rock_Marble"
    },
    {
      "x": 3,
      "y": -2,
      "z": -1,
      "name": "Rock_Marble"
    },
    {
      "x": 3,
      "y": -1,
      "z": -1,
      "name": "Rock_Marble"
    },
    {
      "x": 3,
      "y": 0,
      "z": -1,
      "name": "Rock_Marble"
    },
    {
      "x": 3,
      "y": 1,
      "z": -1,
      "name": "Rock_Marble_SkyGrass"
    },
    {
      "x": 3,
      "y": 2,
      "z": -1,
      "name": "Plant_Grass_Sky",
      "support": 15
    },
    {
      "x": 3,
      "y": -3,
      "z": 0,
      "name": "Rock_Chalk"
    },
    {
      "x": 3,
      "y": -2,
      "z": 0,
      "name": "Rock_Chalk"
    },
    {
      "x": 3,
      "y": -1,
      "z": 0,
      "name": "Rock_Marble"
    },
    {
      "x": 3,
      "y": 0,
      "z": 0,
      "name": "Rock_Marble"
    },
    {
      "x": 3,
      "y": 1,
      "z": 0,
      "name": "Rock_Marble_SkyGrass"
    },
    {
      "x": 3,
      "y": 2,
      "z": 0,
      "name": "Plant_Grass_Sky_Short",
      "support": 15
    },
    {
      "x": 3,
      "y": -3,
      "z": 1,
      "name": "Rock_Chalk"
    },
    {
      "x": 3,
      "y": -2,
      "z": 1,
      "name": "Rock_Chalk"
    },
    {
      "x": 3,
      "y": -1,
      "z": 1,
      "name": "Rock_Marble"
    },
    {
      "x": 3,
      "y": 0,
      "z": 1,
      "name": "Rock_Marble"
    },
    {
      "x": 3,
      "y": 1,
      "z": 1,
      "name": "Rock_Marble_SkyGrass"
    },
    {
      "x": 3,
      "y": -3,
      "z": 2,
      "name": "Rock_Chalk"
    },
    {
      "x": 3,
      "y": -2,
      "z": 2,
      "name": "Rock_Chalk"
    },
    {
      "x": 3,
      "y": -1,
      "z": 2,
      "name": "Rock_Lime"
    },
    {
      "x": 3,
      "y": 0,
      "z": 2,
      "name": "Rock_Marble"
    },
    {
      "x": 3,
      "y": 1,
      "z": 2,
      "name": "Rock_Marble_SkyGrass"
    },
    {
      "x": 3,
      "y": 2,
      "z": 2,
      "name": "Plant_Grass_Sky",
      "support": 15
    },
    {
      "x": 3,
      "y": -3,
      "z": 3,
      "name": "Rock_Chalk"
    },
    {
      "x": 3,
      "y": -2,
      "z": 3,
      "name": "Rock_Chalk"
    },
    {
      "x": 3,
      "y": -1,
      "z": 3,
      "name": "Rock_Lime"
    },
    {
      "x": 3,
      "y": 0,
      "z": 3,
      "name": "Rock_Marble"
    },
    {
      "x": 3,
      "y": 1,
      "z": 3,
      "name": "Rock_Marble_SkyGrass"
    },
    {
      "x": 3,
      "y": 2,
      "z": 3,
      "name": "Plant_Grass_Sky_Long",
      "support": 15
    },
    {
      "x": 4,
      "y": -3,
      "z": -1,
      "name": "Rock_Chalk"
    },
    {
      "x": 4,
      "y": -2,
      "z": -1,
      "name": "Rock_Marble"
    },
    {
      "x": 4,
      "y": -1,
      "z": -1,
      "name": "Rock_Marble"
    },
    {
      "x": 4,
      "y": 0,
      "z": -1,
      "name": "Rock_Marble"
    },
    {
      "x": 4,
      "y": 1,
      "z": -1,
      "name": "Rock_Marble_SkyGrass"
    },
    {
      "x": 4,
      "y": -3,
      "z": 0,
      "name": "Rock_Chalk"
    },
    {
      "x": 4,
      "y": -2,
      "z": 0,
      "name": "Rock_Chalk"
    },
    {
      "x": 4,
      "y": -1,
      "z": 0,
      "name": "Rock_Marble"
    },
    {
      "x": 4,
      "y": 0,
      "z": 0,
      "name": "Rock_Marble"
    },
    {
      "x": 4,
      "y": 1,
      "z": 0,
      "name": "Rock_Marble_SkyGrass"
    },
    {
      "x": 4,
      "y": 2,
      "z": 0,
      "name": "Plant_Grass_Sky_Long",
      "support": 15
    },
    {
      "x": 4,
      "y": -3,
      "z": 1,
      "name": "Rock_Chalk"
    },
    {
      "x": 4,
      "y": -2,
      "z": 1,
      "name": "Rock_Chalk"
    },
    {
      "x": 4,
      "y": -1,
      "z": 1,
      "name": "Rock_Marble"
    },
    {
      "x": 4,
      "y": 0,
      "z": 1,
      "name": "Rock_Marble"
    },
    {
      "x": 4,
      "y": 1,
      "z": 1,
      "name": "Rock_Marble_SkyGrass"
    }
  ]
}