{
  "version": 8,
  "blockIdVersion": 11,
  "anchorX": 0,
  "anchorY": 12,
  "anchorZ": 0,
  "blocks": [
    {
      "x": -6,
      "y": 10,
      "z": 3,
      "name": "Rock_Marble"
    },
    {
      "x": -6,
      "y": 11,
      "z": 3,
      "name": "Rock_Marble_SkyGrass"
    },
    {
      "x": -6,
      "y": 12,
      "z": 3,
      "name": "Plant_Grass_Sky",
      "support": 15
    },
    {
      "x": -6,
      "y": 9,
      "z": 4,
      "name": "Rock_Marble_Stalactite_Small",
      "rotation": 8
    },
    {
      "x": -6,
      "y": 10,
      "z": 4,
      "name": "Rock_Marble"
    },
    {
      "x": -6,
      "y": 11,
      "z": 4,
      "name": "Rock_Marble_SkyGrass"
    },
    {
      "x": -6,
      "y": 12,
      "z": 4,
      "name": "Plant_Grass_Sky_Short",
      "support": 15
    },
    {
      "x": -6,
      "y": 10,
      "z": 5,
      "name": "Rock_Marble"
    },
    {
      "x": -6,
      "y": 11,
      "z": 5,
      "name": "Rock_Marble_SkyGrass"
    },
    {
      "x": -5,
      "y": 8,
      "z": -2,
      "name": "Rock_Marble"
    },
    {
      "x": -5,
      "y": 9,
      "z": -2,
      "name": "Rock_Lime"
    },
    {
      "x": -5,
      "y": 10,
      "z": -2,
      "name": "Rock_Lime"
    },
    {
      "x": -5,
      "y": 11,
      "z": -2,
      "name": "Rock_Marble"
    },
    {
      "x": -5,
      "y": 12,
      "z": -2,
      "name": "Rock_Marble"
    },
    {
      "x": -5,
      "y": 13,
      "z": -2,
      "name": "Rock_Marble_SkyGrass"
    },
    {
      "x": -5,
      "y": 6,
      "z": -1,
      "name": "Rock_Marble_Stalactite_Large",
      "filler": 31744,
      "rotation": 8
    },
    {
      "x": -5,
      "y": 7,
      "z": -1,
      "name": "Rock_Marble_Stalactite_Large",
      "rotation": 8
    },
    {
      "x": -5,
      "y": 8,
      "z": -1,
      "name": "Rock_Marble"
    },
    {
      "x": -5,
      "y": 9,
      "z": -1,
      "name": "Rock_Lime"
    },
    {
      "x": -5,
      "y": 10,
      "z": -1,
      "name": "Rock_Lime"
    },
    {
      "x": -5,
      "y": 11,
      "z": -1,
      "name": "Rock_Marble"
    },
    {
      "x": -5,
      "y": 12,
      "z": -1,
      "name": "Rock_Marble"
    },
    {
      "x": -5,
      "y": 13,
      "z": -1,
      "name": "Rock_Marble_SkyGrass"
    },
    {
      "x": -5,
      "y": 14,
      "z": -1,
      "name": "Plant_Grass_Sky_Short",
      "support": 15
    },
    {
      "x": -5,
      "y": 9,
      "z": 0,
      "name": "Rock_Lime"
    },
    {
      "x": -5,
      "y": 10,
      "z": 0,
      "name": "Rock_Lime"
    },
    {
      "x": -5,
      "y": 11,
      "z": 0,
      "name": "Rock_Marble"
    },
    {
      "x": -5,
      "y": 12,
      "z": 0,
      "name": "Rock_Marble"
    },
    {
      "x": -5,
      "y": 13,
      "z": 0,
      "name": "Rock_Marble_SkyGrass"
    },
    {
      "x": -5,
      "y": 9,
      "z": 1,
      "name": "Rock_Lime"
    },
    {
      "x": -5,
      "y": 10,
      "z": 1,
      "name": "Rock_Marble"
    },
    {
      "x": -5,
      "y": 11,
      "z": 1,
      "name": "Rock_Marble"
    },
    {
      "x": -5,
      "y": 12,
      "z": 1,
      "name": "Rock_Marble"
    },
    {
      "x": -5,
      "y": 13,
      "z": 1,
      "name": "Rock_Marble_SkyGrass"
    },
    {
      "x": -5,
      "y": 9,
      "z": 2,
      "name": "Rock_Marble"
    },
    {
      "x": -5,
      "y": 10,
      "z": 2,
      "name": "Rock_Marble"
    },
    {
      "x": -5,
      "y": 11,
      "z": 2,
      "name": "Rock_Marble"
    },
    {
      "x": -5,
      "y": 12,
      "z": 2,
      "name": "Rock_Marble"
    },
    {
      "x": -5,
      "y": 13,
      "z": 2,
      "name": "Rock_Marble_SkyGrass"
    },
    {
      "x": -5,
      "y": 10,
      "z": 3,
      "name": "Rock_Marble"
    },
    {
      "x": -5,
      "y": 11,
      "z": 3,
      "name": "Rock_Marble"
    },
    {
      "x": -5,
      "y": 12,
      "z": 3,
      "name": "Rubble_Marble_Medium",
      "support": 15
    },
    {
      "x": -5,
      "y": 10,
      "z": 4,
      "name": "Rock_Marble"
    },
    {
      "x": -5,
      "y": 11,
      "z": 4,
      "name": "Rock_Marble"
    },
    {
      "x": -5,
      "y": 10,
      "z": 5,
      "name": "Rock_Marble"
    },
    {
      "x": -5,
      "y": 11,
      "z": 5,
      "name": "Rock_Marble_SkyGrass"
    },
    {
      "x": -5,
      "y": 10,
      "z": 6,
      "name": "Rock_Marble"
    },
    {
      "x": -5,
      "y": 11,
      "z": 6,
      "name": "Rock_Marble_SkyGrass"
    },
    {
      "x": -5,
      "y": 12,
      "z": 6,
      "name": "Plant_Grass_Sky",
      "support": 15
    },
    {
      "x": -4,
      "y": 9,
      "z": -3,
      "name": "Rock_Lime"
    },
    {
      "x": -4,
      "y": 10,
      "z": -3,
      "name": "Rock_Lime"
    },
    {
      "x": -4,
      "y": 11,
      "z": -3,
      "name": "Rock_Marble"
    },
    {
      "x": -4,
      "y": 12,
      "z": -3,
      "name": "Rock_Marble"
    },
    {
      "x": -4,
      "y": 13,
      "z": -3,
      "name": "Rock_Marble_SkyGrass"
    },
    {
      "x": -4,
      "y": 8,
      "z": -2,
      "name": "Rock_Marble"
    },
    {
      "x": -4,
      "y": 9,
      "z": -2,
      "name": "Rock_Lime"
    },
    {
      "x": -4,
      "y": 10,
      "z": -2,
      "name": "Rock_Lime"
    },
    {
      "x": -4,
      "y": 11,
      "z": -2,
      "name": "Rock_Marble"
    },
    {
      "x": -4,
      "y": 12,
      "z": -2,
      "name": "Rock_Marble"
    },
    {
      "x": -4,
      "y": 13,
      "z": -2,
      "name": "Rock_Marble_SkyGrass"
    },
    {
      "x": -4,
      "y": 8,
      "z": -1,
      "name": "Rock_Marble"
    },
    {
      "x": -4,
      "y": 9,
      "z": -1,
      "name": "Rock_Lime"
    },
    {
      "x": -4,
      "y": 10,
      "z": -1,
      "name": "Rock_Lime"
    },
    {
      "x": -4,
      "y": 11,
      "z": -1,
      "name": "Rock_Marble"
    },
    {
      "x": -4,
      "y": 12,
      "z": -1,
      "name": "Rock_Marble"
    },
    {
      "x": -4,
      "y": 13,
      "z": -1,
      "name": "Rock_Marble_SkyGrass"
    },
    {
      "x": -4,
      "y": 9,
      "z": 0,
      "name": "Rock_Lime"
    },
    {
      "x": -4,
      "y": 10,
      "z": 0,
      "name": "Rock_Lime"
    },
    {
      "x": -4,
      "y": 11,
      "z": 0,
      "name": "Rock_Marble"
    },
    {
      "x": -4,
      "y": 12,
      "z": 0,
      "name": "Rock_Marble"
    },
    {
      "x": -4,
      "y": 13,
      "z": 0,
      "name": "Rock_Marble_SkyGrass"
    },
    {
      "x": -4,
      "y": 14,
      "z": 0,
      "name": "Plant_Grass_Sky",
      "support": 15
    },
    {
      "x": -4,
      "y": 4,
      "z": 1,
      "name": "Rock_Marble"
    },
    {
      "x": -4,
      "y": 5,
      "z": 1,
      "name": "Rock_Marble"
    },
    {
      "x": -4,
      "y": 6,
      "z": 1,
      "name": "Rock_Marble"
    },
    {
      "x": -4,
      "y": 7,
      "z": 1,
      "name": "Rock_Marble"
    },
    {
      "x": -4,
      "y": 8,
      "z": 1,
      "name": "Rock_Marble"
    },
    {
      "x": -4,
      "y": 9,
      "z": 1,
      "name": "Rock_Lime"
    },
    {
      "x": -4,
      "y": 10,
      "z": 1,
      "name": "Rock_Marble"
    },
    {
      "x": -4,
      "y": 11,
      "z": 1,
      "name": "Rock_Marble"
    },
    {
      "x": -4,
      "y": 12,
      "z": 1,
      "name": "Rock_Marble"
    },
    {
      "x": -4,
      "y": 13,
      "z": 1,
      "name": "Rock_Marble_SkyGrass"
    },
    {
      "x": -4,
      "y": 14,
      "z": 1,
      "name": "Plant_Bush_Sky",
      "support": 15
    },
    {
      "x": -4,
      "y": 4,
      "z": 2,
      "name": "Rock_Marble"
    },
    {
      "x": -4,
      "y": 5,
      "z": 2,
      "name": "Rock_Marble"
    },
    {
      "x": -4,
      "y": 6,
      "z": 2,
      "name": "Rock_Chalk"
    },
    {
      "x": -4,
      "y": 7,
      "z": 2,
      "name": "Rock_Marble"
    },
    {
      "x": -4,
      "y": 8,
      "z": 2,
      "name": "Rock_Marble"
    },
    {
      "x": -4,
      "y": 9,
      "z": 2,
      "name": "Rock_Marble"
    },
    {
      "x": -4,
      "y": 10,
      "z": 2,
      "name": "Rock_Marble"
    },
    {
      "x": -4,
      "y": 11,
      "z": 2,
      "name": "Rock_Marble"
    },
    {
      "x": -4,
      "y": 12,
      "z": 2,
      "name": "Rock_Marble"
    },
    {
      "x": -4,
      "y": 13,
      "z": 2,
      "name": "Rock_Marble_SkyGrass"
    },
    {
      "x": -4,
      "y": 14,
      "z": 2,
      "name": "Rubble_Marble",
      "support": 15
    },
    {
      "x": -4,
      "y": 4,
      "z": 3,
      "name": "Rock_Marble"
    },
    {
      "x": -4,
      "y": 5,
      "z": 3,
      "name": "Rock_Lime"
    },
    {
      "x": -4,
      "y": 6,
      "z": 3,
      "name": "Rock_Chalk"
    },
    {
      "x": -4,
      "y": 7,
      "z": 3,
      "name": "Rock_Marble"
    },
    {
      "x": -4,
      "y": 8,
      "z": 3,
      "name": "Rock_Marble"
    },
    {
      "x": -4,
      "y": 9,
      "z": 3,
      "name": "Rock_Marble"
    },
    {
      "x": -4,
      "y": 10,
      "z": 3,
      "name": "Rock_Marble"
    },
    {
      "x": -4,
      "y": 11,
      "z": 3,
      "name": "Rock_Marble"
    },
    {
      "x": -4,
      "y": 12,
      "z": 3,
      "name": "Rock_Marble"
    },
    {
      "x": -4,
      "y": 13,
      "z": 3,
      "name": "Rock_Marble_SkyGrass"
    },
    {
      "x": -4,
      "y": 10,
      "z": 4,
      "name": "Rock_Marble"
    },
    {
      "x": -4,
      "y": 11,
      "z": 4,
      "name": "Rock_Marble"
    },
    {
      "x": -4,
      "y": 12,
      "z": 4,
      "name": "Rubble_Marble",
      "support": 15
    },
    {
      "x": -4,
      "y": 8,
      "z": 5,
      "name": "Rock_Marble_Stalactite_Large",
      "filler": 31744,
      "rotation": 8
    },
    {
      "x": -4,
      "y": 9,
      "z": 5,
      "name": "Rock_Marble_Stalactite_Large",
      "rotation": 8
    },
    {
      "x": -4,
      "y": 10,
      "z": 5,
      "name": "Rock_Marble"
    },
    {
      "x": -4,
      "y": 11,
      "z": 5,
      "name": "Rock_Marble_SkyGrass"
    },
    {
      "x": -4,
      "y": 12,
      "z": 5,
      "name": "Plant_Grass_Sky_Long",
      "support": 15
    },
    {
      "x": -4,
      "y": 13,
      "z": 5,
      "name": "Plant_Grass_Sky_Long",
      "filler": 1024
    },
    {
      "x": -4,
      "y": 10,
      "z": 6,
      "name": "Rock_Marble"
    },
    {
      "x": -4,
      "y": 11,
      "z": 6,
      "name": "Rock_Marble_SkyGrass"
    },
    {
      "x": -4,
      "y": 10,
      "z": 7,
      "name": "Rock_Marble"
    },
    {
      "x": -4,
      "y": 11,
      "z": 7,
      "name": "Rock_Marble_SkyGrass"
    },
    {
      "x": -3,
      "y": 7,
      "z": -4,
      "name": "Rock_Marble_Stalactite_Large",
      "filler": 31744,
      "rotation": 8
    },
    {
      "x": -3,
      "y": 8,
      "z": -4,
      "name": "Rock_Marble_Stalactite_Large",
      "rotation": 8
    },
    {
      "x": -3,
      "y": 9,
      "z": -4,
      "name": "Rock_Lime"
    },
    {
      "x": -3,
      "y": 10,
      "z": -4,
      "name": "Rock_Lime"
    },
    {
      "x": -3,
      "y": 11,
      "z": -4,
      "name": "Rock_Chalk"
    },
    {
      "x": -3,
      "y": 12,
      "z": -4,
      "name": "Rock_Marble"
    },
    {
      "x": -3,
      "y": 13,
      "z": -4,
      "name": "Rock_Marble_SkyGrass"
    },
    {
      "x": -3,
      "y": 14,
      "z": -4,
      "name": "Plant_Grass_Sky",
      "support": 15
    },
    {
      "x": -3,
      "y": 9,
      "z": -3,
      "name": "Rock_Lime"
    },
    {
      "x": -3,
      "y": 10,
      "z": -3,
      "name": "Rock_Lime"
    },
    {
      "x": -3,
      "y": 11,
      "z": -3,
      "name": "Rock_Marble"
    },
    {
      "x": -3,
      "y": 12,
      "z": -3,
      "name": "Rock_Marble"
    },
    {
      "x": -3,
      "y": 13,
      "z": -3,
      "name": "Rock_Marble_SkyGrass"
    },
    {
      "x": -3,
      "y": 14,
      "z": -3,
      "name": "Plant_Grass_Sky_Short",
      "support": 15
    },
    {
      "x": -3,
      "y": 9,
      "z": -2,
      "name": "Rock_Lime"
    },
    {
      "x": -3,
      "y": 10,
      "z": -2,
      "name": "Rock_Lime"
    },
    {
      "x": -3,
      "y": 11,
      "z": -2,
      "name": "Rock_Marble"
    },
    {
      "x": -3,
      "y": 12,
      "z": -2,
      "name": "Rock_Marble"
    },
    {
      "x": -3,
      "y": 13,
      "z": -2,
      "name": "Rock_Lime"
    },
    {
      "x": -3,
      "y": 14,
      "z": -2,
      "name": "Rubble_Marble",
      "support": 15
    },
    {
      "x": -3,
      "y": 9,
      "z": -1,
      "name": "Rock_Lime"
    },
    {
      "x": -3,
      "y": 10,
      "z": -1,
      "name": "Rock_Lime"
    },
    {
      "x": -3,
      "y": 11,
      "z": -1,
      "name": "Rock_Marble"
    },
    {
      "x": -3,
      "y": 12,
      "z": -1,
      "name": "Rock_Marble"
    },
    {
      "x": -3,
      "y": 13,
      "z": -1,
      "name": "Rock_Lime"
    },
    {
      "x": -3,
      "y": 4,
      "z": 0,
      "name": "Rock_Marble"
    },
    {
      "x": -3,
      "y": 5,
      "z": 0,
      "name": "Rock_Marble"
    },
    {
      "x": -3,
      "y": 6,
      "z": 0,
      "name": "Rock_Lime"
    },
    {
      "x": -3,
      "y": 7,
      "z": 0,
      "name": "Rock_Marble"
    },
    {
      "x": -3,
      "y": 8,
      "z": 0,
      "name": "Rock_Marble"
    },
    {
      "x": -3,
      "y": 9,
      "z": 0,
      "name": "Rock_Lime"
    },
    {
      "x": -3,
      "y": 10,
      "z": 0,
      "name": "Rock_Lime"
    },
    {
      "x": -3,
      "y": 11,
      "z": 0,
      "name": "Rock_Marble"
    },
    {
      "x": -3,
      "y": 12,
      "z": 0,
      "name": "Rock_Marble"
    },
    {
      "x": -3,
      "y": 13,
      "z": 0,
      "name": "Rock_Marble_SkyGrass"
    },
    {
      "x": -3,
      "y": 4,
      "z": 1,
      "name": "Rock_Marble"
    },
    {
      "x": -3,
      "y": 5,
      "z": 1,
      "name": "Rock_Marble"
    },
    {
      "x": -3,
      "y": 6,
      "z": 1,
      "name": "Rock_Lime"
    },
    {
      "x": -3,
      "y": 7,
      "z": 1,
      "name": "Rock_Marble"
    },
    {
      "x": -3,
      "y": 8,
      "z": 1,
      "name": "Rock_Marble"
    },
    {
      "x": -3,
      "y": 9,
      "z": 1,
      "name": "Rock_Marble"
    },
    {
      "x": -3,
      "y": 10,
      "z": 1,
      "name": "Rock_Marble"
    },
    {
      "x": -3,
      "y": 11,
      "z": 1,
      "name": "Rock_Marble"
    },
    {
      "x": -3,
      "y": 12,
      "z": 1,
      "name": "Rock_Marble"
    },
    {
      "x": -3,
      "y": 13,
      "z": 1,
      "name": "Rock_Marble_SkyGrass"
    },
    {
      "x": -3,
      "y": 14,
      "z": 1,
      "name": "Plant_Bush_Sky",
      "support": 15
    },
    {
      "x": -3,
      "y": 4,
      "z": 2,
      "name": "Rock_Marble"
    },
    {
      "x": -3,
      "y": 5,
      "z": 2,
      "name": "Rock_Lime"
    },
    {
      "x": -3,
      "y": 6,
      "z": 2,
      "name": "Rock_Chalk"
    },
    {
      "x": -3,
      "y": 7,
      "z": 2,
      "name": "Rock_Marble"
    },
    {
      "x": -3,
      "y": 8,
      "z": 2,
      "name": "Rock_Marble"
    },
    {
      "x": -3,
      "y": 9,
      "z": 2,
      "name": "Rock_Marble"
    },
    {
      "x": -3,
      "y": 10,
      "z": 2,
      "name": "Rock_Marble"
    },
    {
      "x": -3,
      "y": 11,
      "z": 2,
      "name": "Rock_Marble"
    },
    {
      "x": -3,
      "y": 12,
      "z": 2,
      "name": "Rock_Marble"
    },
    {
      "x": -3,
      "y": 13,
      "z": 2,
      "name": "Rock_Marble_SkyGrass"
    },
    {
      "x": -3,
      "y": 14,
      "z": 2,
      "name": "Plant_Bush_Sky",
      "support": 15
    },
    {
      "x": -3,
      "y": 4,
      "z": 3,
      "name": "Rock_Marble"
    },
    {
      "x": -3,
      "y": 5,
      "z": 3,
      "name": "Rock_Lime"
    },
    {
      "x": -3,
      "y": 6,
      "z": 3,
      "name": "Rock_Chalk"
    },
    {
      "x": -3,
      "y": 7,
      "z": 3,
      "name": "Rock_Marble"
    },
    {
      "x": -3,
      "y": 8,
      "z": 3,
      "name": "Rock_Marble"
    },
    {
      "x": -3,
      "y": 9,
      "z": 3,
      "name": "Rock_Marble"
    },
    {
      "x": -3,
      "y": 10,
      "z": 3,
      "name": "Rock_Marble"
    },
    {
      "x": -3,
      "y": 11,
      "z": 3,
      "name": "Rock_Marble"
    },
    {
      "x": -3,
      "y": 12,
      "z": 3,
      "name": "Rock_Marble"
    },
    {
      "x": -3,
      "y": 13,
      "z": 3,
      "name": "Rock_Marble_SkyGrass"
    },
    {
      "x": -3,
      "y": 4,
      "z": 4,
      "name": "Rock_Marble"
    },
    {
      "x": -3,
      "y": 5,
      "z": 4,
      "name": "Rock_Lime"
    },
    {
      "x": -3,
      "y": 6,
      "z": 4,
      "name": "Rock_Chalk"
    },
    {
      "x": -3,
      "y": 7,
      "z": 4,
      "name": "Rock_Marble"
    },
    {
      "x": -3,
      "y": 8,
      "z": 4,
      "name": "Rock_Marble"
    },
    {
      "x": -3,
      "y": 9,
      "z": 4,
      "name": "Rock_Marble"
    },
    {
      "x": -3,
      "y": 10,
      "z": 4,
      "name": "Rock_Marble"
    },
    {
      "x": -3,
      "y": 11,
      "z": 4,
      "name": "Rock_Marble"
    },
    {
      "x": -3,
      "y": 12,
      "z": 4,
      "name": "Rock_Marble"
    },
    {
      "x": -3,
      "y": 13,
      "z": 4,
      "name": "Rock_Marble_SkyGrass"
    },
    {
      "x": -3,
      "y": 10,
      "z": 5,
      "name": "Rock_Marble"
    },
    {
      "x": -3,
      "y": 11,
      "z": 5,
      "name": "Rock_Marble_SkyGrass"
    },
    {
      "x": -3,
      "y": 12,
      "z": 5,
      "name": "Plant_Grass_Sky_Wild",
      "support": 15
    },
    {
      "x": -3,
      "y": 13,
      "z": 5,
      "name": "Plant_Grass_Sky_Wild",
      "filler": 1024
    },
    {
      "x": -3,
      "y": 10,
      "z": 6,
      "name": "Rock_Marble"
    },
    {
      "x": -3,
      "y": 11,
      "z": 6,
      "name": "Rock_Marble_SkyGrass"
    },
    {
      "x": -3,
      "y": 12,
      "z": 6,
      "name": "Plant_Grass_Sky_Short",
      "support": 15
    },
    {
      "x": -3,
      "y": 10,
      "z": 7,
      "name": "Rock_Marble"
    },
    {
      "x": -3,
      "y": 11,
      "z": 7,
      "name": "Rock_Marble_SkyGrass"
    },
    {
      "x": -2,
      "y": 9,
      "z": -5,
      "name": "Rock_Lime"
    },
    {
      "x": -2,
      "y": 10,
      "z": -5,
      "name": "Rock_Lime"
    },
    {
      "x": -2,
      "y": 11,
      "z": -5,
      "name": "Rock_Chalk"
    },
    {
      "x": -2,
      "y": 12,
      "z": -5,
      "name": "Rock_Marble"
    },
    {
      "x": -2,
      "y": 13,
      "z": -5,
      "name": "Rock_Marble_SkyGrass"
    },
    {
      "x": -2,
      "y": 14,
      "z": -5,
      "name": "Plant_Grass_Sky",
      "support": 15
    },
    {
      "x": -2,
      "y": 9,
      "z": -4,
      "name": "Rock_Lime"
    },
    {
      "x": -2,
      "y": 10,
      "z": -4,
      "name": "Rock_Lime"
    },
    {
      "x": -2,
      "y": 11,
      "z": -4,
      "name": "Rock_Chalk"
    },
    {
      "x": -2,
      "y": 12,
      "z": -4,
      "name": "Rock_Marble"
    },
    {
      "x": -2,
      "y": 13,
      "z": -4,
      "name": "Rock_Marble_SkyGrass"
    },
    {
      "x": -2,
      "y": 14,
      "z": -4,
      "name": "Plant_Grass_Sky_Long",
      "support": 15
    },
    {
      "x": -2,
      "y": 6,
      "z": -3,
      "name": "Rock_Lime"
    },
    {
      "x": -2,
      "y": 7,
      "z": -3,
      "name": "Rock_Lime"
    },
    {
      "x": -2,
      "y": 8,
      "z": -3,
      "name": "Rock_Marble"
    },
    {
      "x": -2,
      "y": 9,
      "z": -3,
      "name": "Rock_Lime"
    },
    {
      "x": -2,
      "y": 10,
      "z": -3,
      "name": "Rock_Lime"
    },
    {
      "x": -2,
      "y": 11,
      "z": -3,
      "name": "Rock_Chalk"
    },
    {
      "x": -2,
      "y": 12,
      "z": -3,
      "name": "Rock_Marble"
    },
    {
      "x": -2,
      "y": 13,
      "z": -3,
      "name": "Rock_Marble_SkyGrass"
    },
    {
      "x": -2,
      "y": 6,
      "z": -2,
      "name": "Rock_Lime"
    },
    {
      "x": -2,
      "y": 7,
      "z": -2,
      "name": "Rock_Lime"
    },
    {
      "x": -2,
      "y": 8,
      "z": -2,
      "name": "Rock_Marble"
    },
    {
      "x": -2,
      "y": 9,
      "z": -2,
      "name": "Rock_Lime"
    },
    {
      "x": -2,
      "y": 10,
      "z": -2,
      "name": "Rock_Lime"
    },
    {
      "x": -2,
      "y": 11,
      "z": -2,
      "name": "Rock_Marble"
    },
    {
      "x": -2,
      "y": 12,
      "z": -2,
      "name": "Rock_Marble"
    },
    {
      "x": -2,
      "y": 13,
      "z": -2,
      "name": "Rock_Lime"
    },
    {
      "x": -2,
      "y": 3,
      "z": -1,
      "name": "Rock_Marble"
    },
    {
      "x": -2,
      "y": 4,
      "z": -1,
      "name": "Rock_Marble"
    },
    {
      "x": -2,
      "y": 5,
      "z": -1,
      "name": "Rock_Marble"
    },
    {
      "x": -2,
      "y": 6,
      "z": -1,
      "name": "Rock_Lime"
    },
    {
      "x": -2,
      "y": 7,
      "z": -1,
      "name": "Rock_Lime"
    },
    {
      "x": -2,
      "y": 8,
      "z": -1,
      "name": "Rock_Marble"
    },
    {
      "x": -2,
      "y": 9,
      "z": -1,
      "name": "Rock_Lime"
    },
    {
      "x": -2,
      "y": 10,
      "z": -1,
      "name": "Rock_Lime"
    },
    {
      "x": -2,
      "y": 11,
      "z": -1,
      "name": "Rock_Marble"
    },
    {
      "x": -2,
      "y": 12,
      "z": -1,
      "name": "Rock_Marble"
    },
    {
      "x": -2,
      "y": 13,
      "z": -1,
      "name": "Rock_Lime"
    },
    {
      "x": -2,
      "y": 3,
      "z": 0,
      "name": "Rock_Marble"
    },
    {
      "x": -2,
      "y": 4,
      "z": 0,
      "name": "Rock_Marble"
    },
    {
      "x": -2,
      "y": 5,
      "z": 0,
      "name": "Rock_Marble"
    },
    {
      "x": -2,
      "y": 6,
      "z": 0,
      "name": "Rock_Lime"
    },
    {
      "x": -2,
      "y": 7,
      "z": 0,
      "name": "Rock_Marble"
    },
    {
      "x": -2,
      "y": 8,
      "z": 0,
      "name": "Rock_Marble"
    },
    {
      "x": -2,
      "y": 9,
      "z": 0,
      "name": "Rock_Marble"
    },
    {
      "x": -2,
      "y": 10,
      "z": 0,
      "name": "Rock_Marble"
    },
    {
      "x": -2,
      "y": 11,
      "z": 0,
      "name": "Rock_Marble"
    },
    {
      "x": -2,
      "y": 12,
      "z": 0,
      "name": "Rock_Marble"
    },
    {
      "x": -2,
      "y": 13,
      "z": 0,
      "name": "Rock_Marble_SkyGrass"
    },
    {
      "x": -2,
      "y": 14,
      "z": 0,
      "name": "Plant_Grass_Sky",
      "support": 15
    },
    {
      "x": -2,
      "y": 4,
      "z": 1,
      "name": "Rock_Marble"
    },
    {
      "x": -2,
      "y": 5,
      "z": 1,
      "name": "Rock_Lime"
    },
    {
      "x": -2,
      "y": 6,
      "z": 1,
      "name": "Rock_Lime"
    },
    {
      "x": -2,
      "y": 7,
      "z": 1,
      "name": "Rock_Marble"
    },
    {
      "x": -2,
      "y": 8,
      "z": 1,
      "name": "Rock_Marble"
    },
    {
      "x": -2,
      "y": 9,
      "z": 1,
      "name": "Rock_Marble"
    },
    {
      "x": -2,
      "y": 10,
      "z": 1,
      "name": "Rock_Marble"
    },
    {
      "x": -2,
      "y": 11,
      "z": 1,
      "name": "Rock_Marble"
    },
    {
      "x": -2,
      "y": 12,
      "z": 1,
      "name": "Rock_Marble"
    },
    {
      "x": -2,
      "y": 13,
      "z": 1,
      "name": "Rock_Marble_SkyGrass"
    },
    {
      "x": -2,
      "y": 4,
      "z": 2,
      "name": "Rock_Marble"
    },
    {
      "x": -2,
      "y": 5,
      "z": 2,
      "name": "Rock_Lime"
    },
    {
      "x": -2,
      "y": 6,
      "z": 2,
      "name": "Rock_Chalk"
    },
    {
      "x": -2,
      "y": 7,
      "z": 2,
      "name": "Rock_Marble"
    },
    {
      "x": -2,
      "y": 8,
      "z": 2,
      "name": "Rock_Marble"
    },
    {
      "x": -2,
      "y": 9,
      "z": 2,
      "name": "Rock_Marble"
    },
    {
      "x": -2,
      "y": 10,
      "z": 2,
      "name": "Rock_Marble"
    },
    {
      "x": -2,
      "y": 11,
      "z": 2,
      "name": "Rock_Marble"
    },
    {
      "x": -2,
      "y": 12,
      "z": 2,
      "name": "Rock_Marble"
    },
    {
      "x": -2,
      "y": 13,
      "z": 2,
      "name": "Rock_Chalk"
    },
    {
      "x": -2,
      "y": 4,
      "z": 3,
      "name": "Rock_Marble"
    },
    {
      "x": -2,
      "y": 5,
      "z": 3,
      "name": "Rock_Lime"
    },
    {
      "x": -2,
      "y": 6,
      "z": 3,
      "name": "Rock_Chalk"
    },
    {
      "x": -2,
      "y": 7,
      "z": 3,
      "name": "Rock_Marble"
    },
    {
      "x": -2,
      "y": 8,
      "z": 3,
      "name": "Rock_Lime"
    },
    {
      "x": -2,
      "y": 9,
      "z": 3,
      "name": "Rock_Marble"
    },
    {
      "x": -2,
      "y": 10,
      "z": 3,
      "name": "Rock_Marble"
    },
    {
      "x": -2,
      "y": 11,
      "z": 3,
      "name": "Rock_Marble"
    },
    {
      "x": -2,
      "y": 12,
      "z": 3,
      "name": "Rock_Marble"
    },
    {
      "x": -2,
      "y": 13,
      "z": 3,
      "name": "Rock_Chalk"
    },
    {
      "x": -2,
      "y": 4,
      "z": 4,
      "name": "Rock_Marble"
    },
    {
      "x": -2,
      "y": 5,
      "z": 4,
      "name": "Rock_Lime"
    },
    {
      "x": -2,
      "y": 6,
      "z": 4,
      "name": "Rock_Chalk"
    },
    {
      "x": -2,
      "y": 7,
      "z": 4,
      "name": "Rock_Marble"
    },
    {
      "x": -2,
      "y": 8,
      "z": 4,
      "name": "Rock_Lime"
    },
    {
      "x": -2,
      "y": 9,
      "z": 4,
      "name": "Rock_Marble"
    },
    {
      "x": -2,
      "y": 10,
      "z": 4,
      "name": "Rock_Marble"
    },
    {
      "x": -2,
      "y": 11,
      "z": 4,
      "name": "Rock_Marble"
    },
    {
      "x": -2,
      "y": 12,
      "z": 4,
      "name": "Rock_Marble"
    },
    {
      "x": -2,
      "y": 13,
      "z": 4,
      "name": "Rock_Marble_SkyGrass"
    },
    {
      "x": -2,
      "y": 9,
      "z": 5,
      "name": "Rock_Marble"
    },
    {
      "x": -2,
      "y": 10,
      "z": 5,
      "name": "Rock_Marble"
    },
    {
      "x": -2,
      "y": 11,
      "z": 5,
      "name": "Rock_Marble"
    },
    {
      "x": -2,
      "y": 12,
      "z": 5,
      "name": "Rock_Marble"
    },
    {
      "x": -2,
      "y": 13,
      "z": 5,
      "name": "Rock_Marble_SkyGrass"
    },
    {
      "x": -2,
      "y": 10,
      "z": 6,
      "name": "Rock_Marble"
    },
    {
      "x": -2,
      "y": 11,
      "z": 6,
      "name": "Rock_Marble_SkyGrass"
    },
    {
      "x": -2,
      "y": 12,
      "z": 6,
      "name": "Plant_Grass_Sky_Long",
      "support": 15
    },
    {
      "x": -2,
      "y": 13,
      "z": 6,
      "name": "Plant_Grass_Sky_Long",
      "filler": 1024
    },
    {
      "x": -2,
      "y": 10,
      "z": 7,
      "name": "Rock_Marble"
    },
    {
      "x": -2,
      "y": 11,
      "z": 7,
      "name": "Rock_Marble_SkyGrass"
    },
    {
      "x": -2,
      "y": 12,
      "z": 7,
      "name": "Plant_Grass_Sky_Short",
      "support": 15
    },
    {
      "x": -1,
      "y": 9,
      "z": -5,
      "name": "Rock_Lime"
    },
    {
      "x": -1,
      "y": 10,
      "z": -5,
      "name": "Rock_Marble"
    },
    {
      "x": -1,
      "y": 11,
      "z": -5,
      "name": "Rock_Chalk"
    },
    {
      "x": -1,
      "y": 12,
      "z": -5,
      "name": "Rock_Marble"
    },
    {
      "x": -1,
      "y": 13,
      "z": -5,
      "name": "Rock_Marble_SkyGrass"
    },
    {
      "x": -1,
      "y": 14,
      "z": -5,
      "name": "Plant_Grass_Sky",
      "support": 15
    },
    {
      "x": -1,
      "y": 5,
      "z": -4,
      "name": "Rock_Marble_Stalactite_Small",
      "rotation": 8
    },
    {
      "x": -1,
      "y": 6,
      "z": -4,
      "name": "Rock_Lime"
    },
    {
      "x": -1,
      "y": 7,
      "z": -4,
      "name": "Rock_Lime"
    },
    {
      "x": -1,
      "y": 8,
      "z": -4,
      "name": "Rock_Chalk"
    },
    {
      "x": -1,
      "y": 9,
      "z": -4,
      "name": "Rock_Lime"
    },
    {
      "x": -1,
      "y": 10,
      "z": -4,
      "name": "Rock_Lime"
    },
    {
      "x": -1,
      "y": 11,
      "z": -4,
      "name": "Rock_Chalk"
    },
    {
      "x": -1,
      "y": 12,
      "z": -4,
      "name": "Rock_Marble"
    },
    {
      "x": -1,
      "y": 13,
      "z": -4,
      "name": "Rock_Marble_SkyGrass"
    },
    {
      "x": -1,
      "y": 6,
      "z": -3,
      "name": "Rock_Lime"
    },
    {
      "x": -1,
      "y": 7,
      "z": -3,
      "name": "Rock_Lime"
    },
    {
      "x": -1,
      "y": 8,
      "z": -3,
      "name": "Rock_Marble"
    },
    {
      "x": -1,
      "y": 9,
      "z": -3,
      "name": "Rock_Lime"
    },
    {
      "x": -1,
      "y": 10,
      "z": -3,
      "name": "Rock_Lime"
    },
    {
      "x": -1,
      "y": 11,
      "z": -3,
      "name": "Rock_Chalk"
    },
    {
      "x": -1,
      "y": 12,
      "z": -3,
      "name": "Rock_Marble"
    },
    {
      "x": -1,
      "y": 13,
      "z": -3,
      "name": "Rock_Marble_SkyGrass"
    },
    {
      "x": -1,
      "y": 3,
      "z": -2,
      "name": "Rock_Marble"
    },
    {
      "x": -1,
      "y": 4,
      "z": -2,
      "name": "Rock_Marble"
    },
    {
      "x": -1,
      "y": 5,
      "z": -2,
      "name": "Rock_Marble"
    },
    {
      "x": -1,
      "y": 6,
      "z": -2,
      "name": "Rock_Lime"
    },
    {
      "x": -1,
      "y": 7,
      "z": -2,
      "name": "Rock_Lime"
    },
    {
      "x": -1,
      "y": 8,
      "z": -2,
      "name": "Rock_Marble"
    },
    {
      "x": -1,
      "y": 9,
      "z": -2,
      "name": "Rock_Lime"
    },
    {
      "x": -1,
      "y": 10,
      "z": -2,
      "name": "Rock_Lime"
    },
    {
      "x": -1,
      "y": 11,
      "z": -2,
      "name": "Rock_Chalk"
    },
    {
      "x": -1,
      "y": 12,
      "z": -2,
      "name": "Rock_Marble"
    },
    {
      "x": -1,
      "y": 13,
      "z": -2,
      "name": "Rock_Marble_SkyGrass"
    },
    {
      "x": -1,
      "y": 3,
      "z": -1,
      "name": "Rock_Marble"
    },
    {
      "x": -1,
      "y": 4,
      "z": -1,
      "name": "Rock_Marble"
    },
    {
      "x": -1,
      "y": 5,
      "z": -1,
      "name": "Rock_Marble"
    },
    {
      "x": -1,
      "y": 6,
      "z": -1,
      "name": "Rock_Lime"
    },
    {
      "x": -1,
      "y": 7,
      "z": -1,
      "name": "Rock_Lime"
    },
    {
      "x": -1,
      "y": 8,
      "z": -1,
      "name": "Rock_Marble"
    },
    {
      "x": -1,
      "y": 9,
      "z": -1,
      "name": "Rock_Marble"
    },
    {
      "x": -1,
      "y": 10,
      "z": -1,
      "name": "Rock_Marble"
    },
    {
      "x": -1,
      "y": 11,
      "z": -1,
      "name": "Rock_Marble"
    },
    {
      "x": -1,
      "y": 12,
      "z": -1,
      "name": "Rock_Marble"
    },
    {
      "x": -1,
      "y": 13,
      "z": -1,
      "name": "Rock_Marble_SkyGrass"
    },
    {
      "x": -1,
      "y": 14,
      "z": -1,
      "name": "Plant_Grass_Sky",
      "support": 15
    },
    {
      "x": -1,
      "y": 3,
      "z": 0,
      "name": "Rock_Marble"
    },
    {
      "x": -1,
      "y": 4,
      "z": 0,
      "name": "Rock_Marble"
    },
    {
      "x": -1,
      "y": 5,
      "z": 0,
      "name": "Rock_Marble"
    },
    {
      "x": -1,
      "y": 6,
      "z": 0,
      "name": "Rock_Lime"
    },
    {
      "x": -1,
      "y": 7,
      "z": 0,
      "name": "Rock_Marble"
    },
    {
      "x": -1,
      "y": 8,
      "z": 0,
      "name": "Rock_Marble"
    },
    {
      "x": -1,
      "y": 9,
      "z": 0,
      "name": "Rock_Marble"
    },
    {
      "x": -1,
      "y": 10,
      "z": 0,
      "name": "Rock_Marble"
    },
    {
      "x": -1,
      "y": 11,
      "z": 0,
      "name": "Rock_Marble"
    },
    {
      "x": -1,
      "y": 12,
      "z": 0,
      "name": "Rock_Marble"
    },
    {
      "x": -1,
      "y": 13,
      "z": 0,
      "name": "Rock_Marble_SkyGrass"
    },
    {
      "x": -1,
      "y": 14,
      "z": 0,
      "name": "Plant_Grass_Sky",
      "support": 15
    },
    {
      "x": -1,
      "y": 3,
      "z": 1,
      "name": "Rock_Marble"
    },
    {
      "x": -1,
      "y": 4,
      "z": 1,
      "name": "Rock_Marble"
    },
    {
      "x": -1,
      "y": 5,
      "z": 1,
      "name": "Rock_Lime"
    },
    {
      "x": -1,
      "y": 6,
      "z": 1,
      "name": "Rock_Lime"
    },
    {
      "x": -1,
      "y": 7,
      "z": 1,
      "name": "Rock_Marble"
    },
    {
      "x": -1,
      "y": 8,
      "z": 1,
      "name": "Rock_Marble"
    },
    {
      "x": -1,
      "y": 9,
      "z": 1,
      "name": "Rock_Marble"
    },
    {
      "x": -1,
      "y": 10,
      "z": 1,
      "name": "Rock_Marble"
    },
    {
      "x": -1,
      "y": 11,
      "z": 1,
      "name": "Rock_Lime"
    },
    {
      "x": -1,
      "y": 12,
      "z": 1,
      "name": "Rock_Marble"
    },
    {
      "x": -1,
      "y": 13,
      "z": 1,
      "name": "Rock_Chalk"
    },
    {
      "x": -1,
      "y": 4,
      "z": 2,
      "name": "Rock_Marble"
    },
    {
      "x": -1,
      "y": 5,
      "z": 2,
      "name": "Rock_Lime"
    },
    {
      "x": -1,
      "y": 6,
      "z": 2,
      "name": "Rock_Chalk"
    },
    {
      "x": -1,
      "y": 7,
      "z": 2,
      "name": "Rock_Marble"
    },
    {
      "x": -1,
      "y": 8,
      "z": 2,
      "name": "Rock_Lime"
    },
    {
      "x": -1,
      "y": 9,
      "z": 2,
      "name": "Rock_Marble"
    },
    {
      "x": -1,
      "y": 10,
      "z": 2,
      "name": "Rock_Marble"
    },
    {
      "x": -1,
      "y": 11,
      "z": 2,
      "name": "Rock_Lime"
    },
    {
      "x": -1,
      "y": 12,
      "z": 2,
      "name": "Rock_Marble"
    },
    {
      "x": -1,
      "y": 13,
      "z": 2,
      "name": "Rock_Chalk"
    },
    {
      "x": -1,
      "y": 4,
      "z": 3,
      "name": "Rock_Marble"
    },
    {
      "x": -1,
      "y": 5,
      "z": 3,
      "name": "Rock_Lime"
    },
    {
      "x": -1,
      "y": 6,
      "z": 3,
      "name": "Rock_Chalk"
    },
    {
      "x": -1,
      "y": 7,
      "z": 3,
      "name": "Rock_Marble"
    },
    {
      "x": -1,
      "y": 8,
      "z": 3,
      "name": "Rock_Lime"
    },
    {
      "x": -1,
      "y": 9,
      "z": 3,
      "name": "Rock_Marble"
    },
    {
      "x": -1,
      "y": 10,
      "z": 3,
      "name": "Rock_Marble"
    },
    {
      "x": -1,
      "y": 11,
      "z": 3,
      "name": "Rock_Lime"
    },
    {
      "x": -1,
      "y": 12,
      "z": 3,
      "name": "Rock_Marble"
    },
    {
      "x": -1,
      "y": 13,
      "z": 3,
      "name": "Rock_Chalk"
    },
    {
      "x": -1,
      "y": 4,
      "z": 4,
      "name": "Rock_Marble"
    },
    {
      "x": -1,
      "y": 5,
      "z": 4,
      "name": "Rock_Lime"
    },
    {
      "x": -1,
      "y": 6,
      "z": 4,
      "name": "Rock_Chalk"
    },
    {
      "x": -1,
      "y": 7,
      "z": 4,
      "name": "Rock_Marble"
    },
    {
      "x": -1,
      "y": 8,
      "z": 4,
      "name": "Rock_Lime"
    },
    {
      "x": -1,
      "y": 9,
      "z": 4,
      "name": "Rock_Lime"
    },
    {
      "x": -1,
      "y": 10,
      "z": 4,
      "name": "Rock_Marble"
    },
    {
      "x": -1,
      "y": 11,
      "z": 4,
      "name": "Rock_Lime"
    },
    {
      "x": -1,
      "y": 12,
      "z": 4,
      "name": "Rock_Marble"
    },
    {
      "x": -1,
      "y": 13,
      "z": 4,
      "name": "Rock_Marble_SkyGrass"
    },
    {
      "x": -1,
      "y": 8,
      "z": 5,
      "name": "Rock_Marble_Stalactite_Small",
      "rotation": 8
    },
    {
      "x": -1,
      "y": 9,
      "z": 5,
      "name": "Rock_Lime"
    },
    {
      "x": -1,
      "y": 10,
      "z": 5,
      "name": "Rock_Marble"
    },
    {
      "x": -1,
      "y": 11,
      "z": 5,
      "name": "Rock_Lime"
    },
    {
      "x": -1,
      "y": 12,
      "z": 5,
      "name": "Rock_Marble"
    },
    {
      "x": -1,
      "y": 13,
      "z": 5,
      "name": "Rock_Marble_SkyGrass"
    },
    {
      "x": -1,
      "y": 10,
      "z": 6,
      "name": "Rock_Marble"
    },
    {
      "x": -1,
      "y": 11,
      "z": 6,
      "name": "Rock_Marble_SkyGrass"
    },
    {
      "x": -1,
      "y": 12,
      "z": 6,
      "name": "Plant_Grass_Sky",
      "support": 15
    },
    {
      "x": 0,
      "y": 6,
      "z": -5,
      "name": "Rock_Lime"
    },
    {
      "x": 0,
      "y": 7,
      "z": -5,
      "name": "Rock_Lime"
    },
    {
      "x": 0,
      "y": 8,
      "z": -5,
      "name": "Rock_Chalk"
    },
    {
      "x": 0,
      "y": 9,
      "z": -5,
      "name": "Rock_Lime"
    },
    {
      "x": 0,
      "y": 10,
      "z": -5,
      "name": "Rock_Marble"
    },
    {
      "x": 0,
      "y": 11,
      "z": -5,
      "name": "Rock_Chalk"
    },
    {
      "x": 0,
      "y": 12,
      "z": -5,
      "name": "Rock_Marble"
    },
    {
      "x": 0,
      "y": 13,
      "z": -5,
      "name": "Rock_Marble_SkyGrass"
    },
    {
      "x": 0,
      "y": 14,
      "z": -5,
      "name": "Plant_Grass_Sky_Short",
      "support": 15
    },
    {
      "x": 0,
      "y": 6,
      "z": -4,
      "name": "Rock_Lime"
    },
    {
      "x": 0,
      "y": 7,
      "z": -4,
      "name": "Rock_Lime"
    },
    {
      "x": 0,
      "y": 8,
      "z": -4,
      "name": "Rock_Chalk"
    },
    {
      "x": 0,
      "y": 9,
      "z": -4,
      "name": "Rock_Lime"
    },
    {
      "x": 0,
      "y": 10,
      "z": -4,
      "name": "Rock_Marble"
    },
    {
      "x": 0,
      "y": 11,
      "z": -4,
      "name": "Rock_Chalk"
    },
    {
      "x": 0,
      "y": 12,
      "z": -4,
      "name": "Rock_Marble"
    },
    {
      "x": 0,
      "y": 13,
      "z": -4,
      "name": "Rock_Marble_SkyGrass"
    },
    {
      "x": 0,
      "y": 6,
      "z": -3,
      "name": "Rock_Lime"
    },
    {
      "x": 0,
      "y": 7,
      "z": -3,
      "name": "Rock_Lime"
    },
    {
      "x": 0,
      "y": 8,
      "z": -3,
      "name": "Rock_Chalk"
    },
    {
      "x": 0,
      "y": 9,
      "z": -3,
      "name": "Rock_Lime"
    },
    {
      "x": 0,
      "y": 10,
      "z": -3,
      "name": "Rock_Marble"
    },
    {
      "x": 0,
      "y": 11,
      "z": -3,
      "name": "Rock_Chalk"
    },
    {
      "x": 0,
      "y": 12,
      "z": -3,
      "name": "Rock_Marble"
    },
    {
      "x": 0,
      "y": 13,
      "z": -3,
      "name": "Rock_Marble_SkyGrass"
    },
    {
      "x": 0,
      "y": 3,
      "z": -2,
      "name": "Rock_Marble"
    },
    {
      "x": 0,
      "y": 4,
      "z": -2,
      "name": "Rock_Marble"
    },
    {
      "x": 0,
      "y": 5,
      "z": -2,
      "name": "Rock_Marble"
    },
    {
      "x": 0,
      "y": 6,
      "z": -2,
      "name": "Rock_Lime"
    },
    {
      "x": 0,
      "y": 7,
      "z": -2,
      "name": "Rock_Lime"
    },
    {
      "x": 0,
      "y": 8,
      "z": -2,
      "name": "Rock_Marble"
    },
    {
      "x": 0,
      "y": 9,
      "z": -2,
      "name": "Rock_Marble"
    },
    {
      "x": 0,
      "y": 10,
      "z": -2,
      "name": "Rock_Marble"
    },
    {
      "x": 0,
      "y": 11,
      "z": -2,
      "name": "Rock_Chalk"
    },
    {
      "x": 0,
      "y": 12,
      "z": -2,
      "name": "Rock_Marble"
    },
    {
      "x": 0,
      "y": 13,
      "z": -2,
      "name": "Rock_Marble_SkyGrass"
    },
    {
      "x": 0,
      "y": 3,
      "z": -1,
      "name": "Rock_Marble"
    },
    {
      "x": 0,
      "y": 4,
      "z": -1,
      "name": "Rock_Marble"
    },
    {
      "x": 0,
      "y": 5,
      "z": -1,
      "name": "Rock_Marble"
    },
    {
      "x": 0,
      "y": 6,
      "z": -1,
      "name": "Rock_Lime"
    },
    {
      "x": 0,
      "y": 7,
      "z": -1,
      "name": "Rock_Lime"
    },
    {
      "x": 0,
      "y": 8,
      "z": -1,
      "name": "Rock_Marble"
    },
    {
      "x": 0,
      "y": 9,
      "z": -1,
      "name": "Rock_Marble"
    },
    {
      "x": 0,
      "y": 10,
      "z": -1,
      "name": "Rock_Marble"
    },
    {
      "x": 0,
      "y": 11,
      "z": -1,
      "name": "Rock_Marble"
    },
    {
      "x": 0,
      "y": 12,
      "z": -1,
      "name": "Rock_Marble"
    },
    {
      "x": 0,
      "y": 13,
      "z": -1,
      "name": "Rock_Marble_SkyGrass"
    },
    {
      "x": 0,
      "y": 3,
      "z": 0,
      "name": "Rock_Marble"
    },
    {
      "x": 0,
      "y": 4,
      "z": 0,
      "name": "Rock_Marble"
    },
    {
      "x": 0,
      "y": 5,
      "z": 0,
      "name": "Rock_Marble"
    },
    {
      "x": 0,
      "y": 6,
      "z": 0,
      "name": "Rock_Lime"
    },
    {
      "x": 0,
      "y": 7,
      "z": 0,
      "name": "Rock_Marble"
    },
    {
      "x": 0,
      "y": 8,
      "z": 0,
      "name": "Rock_Marble"
    },
    {
      "x": 0,
      "y": 9,
      "z": 0,
      "name": "Rock_Marble"
    },
    {
      "x": 0,
      "y": 10,
      "z": 0,
      "name": "Rock_Marble"
    },
    {
      "x": 0,
      "y": 11,
      "z": 0,
      "name": "Rock_Lime"
    },
    {
      "x": 0,
      "y": 12,
      "z": 0,
      "name": "Rock_Marble"
    },
    {
      "x": 0,
      "y": 13,
      "z": 0,
      "name": "Rock_Marble_SkyGrass"
    },
    {
      "x": 0,
      "y": 14,
      "z": 0,
      "name": "Plant_Grass_Sky",
      "support": 15
    },
    {
      "x": 0,
      "y": 3,
      "z": 1,
      "name": "Rock_Marble"
    },
    {
      "x": 0,
      "y": 4,
      "z": 1,
      "name": "Rock_Marble"
    },
    {
      "x": 0,
      "y": 5,
      "z": 1,
      "name": "Rock_Lime"
    },
    {
      "x": 0,
      "y": 6,
      "z": 1,
      "name": "Rock_Chalk"
    },
    {
      "x": 0,
      "y": 7,
      "z": 1,
      "name": "Rock_Marble"
    },
    {
      "x": 0,
      "y": 8,
      "z": 1,
      "name": "Rock_Lime"
    },
    {
      "x": 0,
      "y": 9,
      "z": 1,
      "name": "Rock_Marble"
    },
    {
      "x": 0,
      "y": 10,
      "z": 1,
      "name": "Rock_Marble"
    },
    {
      "x": 0,
      "y": 11,
      "z": 1,
      "name": "Rock_Lime"
    },
    {
      "x": 0,
      "y": 12,
      "z": 1,
      "name": "Rock_Marble"
    },
    {
      "x": 0,
      "y": 13,
      "z": 1,
      "name": "Rock_Chalk"
    },
    {
      "x": 0,
      "y": 4,
      "z": 2,
      "name": "Rock_Marble"
    },
    {
      "x": 0,
      "y": 5,
      "z": 2,
      "name": "Rock_Lime"
    },
    {
      "x": 0,
      "y": 6,
      "z": 2,
      "name": "Rock_Chalk"
    },
    {
      "x": 0,
      "y": 7,
      "z": 2,
      "name": "Rock_Marble"
    },
    {
      "x": 0,
      "y": 8,
      "z": 2,
      "name": "Rock_Lime"
    },
    {
      "x": 0,
      "y": 9,
      "z": 2,
      "name": "Rock_Marble"
    },
    {
      "x": 0,
      "y": 10,
      "z": 2,
      "name": "Rock_Marble"
    },
    {
      "x": 0,
      "y": 11,
      "z": 2,
      "name": "Rock_Lime"
    },
    {
      "x": 0,
      "y": 12,
      "z": 2,
      "name": "Rock_Marble"
    },
    {
      "x": 0,
      "y": 13,
      "z": 2,
      "name": "Rock_Chalk"
    },
    {
      "x": 0,
      "y": 14,
      "z": 2,
      "name": "Rubble_Marble",
      "support": 15
    },
    {
      "x": 0,
      "y": 4,
      "z": 3,
      "name": "Rock_Marble"
    },
    {
      "x": 0,
      "y": 5,
      "z": 3,
      "name": "Rock_Lime"
    },
    {
      "x": 0,
      "y": 6,
      "z": 3,
      "name": "Rock_Chalk"
    },
    {
      "x": 0,
      "y": 7,
      "z": 3,
      "name": "Rock_Marble"
    },
    {
      "x": 0,
      "y": 8,
      "z": 3,
      "name": "Rock_Lime"
    },
    {
      "x": 0,
      "y": 9,
      "z": 3,
      "name": "Rock_Lime"
    },
    {
      "x": 0,
      "y": 10,
      "z": 3,
      "name": "Rock_Marble"
    },
    {
      "x": 0,
      "y": 11,
      "z": 3,
      "name": "Rock_Lime"
    },
    {
      "x": 0,
      "y": 12,
      "z": 3,
      "name": "Rock_Marble"
    },
    {
      "x": 0,
      "y": 13,
      "z": 3,
      "name": "Rock_Marble_SkyGrass"
    },
    {
      "x": 0,
      "y": 9,
      "z": 4,
      "name": "Rock_Lime"
    },
    {
      "x": 0,
      "y": 10,
      "z": 4,
      "name": "Rock_Marble"
    },
    {
      "x": 0,
      "y": 11,
      "z": 4,
      "name": "Rock_Lime"
    },
    {
      "x": 0,
      "y": 12,
      "z": 4,
      "name": "Rock_Marble"
    },
    {
      "x": 0,
      "y": 13,
      "z": 4,
      "name": "Rock_Marble_SkyGrass"
    },
    {
      "x": 0,
      "y": 9,
      "z": 5,
      "name": "Rock_Lime"
    },
    {
      "x": 0,
      "y": 10,
      "z": 5,
      "name": "Rock_Marble"
    },
    {
      "x": 0,
      "y": 11,
      "z": 5,
      "name": "Rock_Lime"
    },
    {
      "x": 0,
      "y": 12,
      "z": 5,
      "name": "Rock_Marble"
    },
    {
      "x": 0,
      "y": 13,
      "z": 5,
      "name": "Rock_Marble_SkyGrass"
    },
    {
      "x": 1,
      "y": 6,
      "z": -5,
      "name": "Rock_Lime"
    },
    {
      "x": 1,
      "y": 7,
      "z": -5,
      "name": "Rock_Lime"
    },
    {
      "x": 1,
      "y": 8,
      "z": -5,
      "name": "Rock_Chalk"
    },
    {
      "x": 1,
      "y": 9,
      "z": -5,
      "name": "Rock_Lime"
    },
    {
      "x": 1,
      "y": 10,
      "z": -5,
      "name": "Rock_Marble"
    },
    {
      "x": 1,
      "y": 11,
      "z": -5,
      "name": "Rock_Chalk"
    },
    {
      "x": 1,
      "y": 12,
      "z": -5,
      "name": "Rock_Marble"
    },
    {
      "x": 1,
      "y": 13,
      "z": -5,
      "name": "Rock_Marble_SkyGrass"
    },
    {
      "x": 1,
      "y": 6,
      "z": -4,
      "name": "Rock_Lime"
    },
    {
      "x": 1,
      "y": 7,
      "z": -4,
      "name": "Rock_Lime"
    },
    {
      "x": 1,
      "y": 8,
      "z": -4,
      "name": "Rock_Chalk"
    },
    {
      "x": 1,
      "y": 9,
      "z": -4,
      "name": "Rock_Lime"
    },
    {
      "x": 1,
      "y": 10,
      "z": -4,
      "name": "Rock_Marble"
    },
    {
      "x": 1,
      "y": 11,
      "z": -4,
      "name": "Rock_Chalk"
    },
    {
      "x": 1,
      "y": 12,
      "z": -4,
      "name": "Rock_Chalk"
    },
    {
      "x": 1,
      "y": 13,
      "z": -4,
      "name": "Rock_Marble_SkyGrass"
    },
    {
      "x": 1,
      "y": 4,
      "z": -3,
      "name": "Rock_Marble_Stalactite_Large",
      "filler": 31744,
      "rotation": 8
    },
    {
      "x": 1,
      "y": 5,
      "z": -3,
      "name": "Rock_Marble_Stalactite_Large",
      "rotation": 8
    },
    {
      "x": 1,
      "y": 6,
      "z": -3,
      "name": "Rock_Lime"
    },
    {
      "x": 1,
      "y": 7,
      "z": -3,
      "name": "Rock_Lime"
    },
    {
      "x": 1,
      "y": 8,
      "z": -3,
      "name": "Rock_Chalk"
    },
    {
      "x": 1,
      "y": 9,
      "z": -3,
      "name": "Rock_Chalk"
    },
    {
      "x": 1,
      "y": 10,
      "z": -3,
      "name": "Rock_Marble"
    },
    {
      "x": 1,
      "y": 11,
      "z": -3,
      "name": "Rock_Chalk"
    },
    {
      "x": 1,
      "y": 12,
      "z": -3,
      "name": "Rock_Chalk"
    },
    {
      "x": 1,
      "y": 13,
      "z": -3,
      "name": "Rock_Marble_SkyGrass"
    },
    {
      "x": 1,
      "y": 6,
      "z": -2,
      "name": "Rock_Lime"
    },
    {
      "x": 1,
      "y": 7,
      "z": -2,
      "name": "Rock_Lime"
    },
    {
      "x": 1,
      "y": 8,
      "z": -2,
      "name": "Rock_Chalk"
    },
    {
      "x": 1,
      "y": 9,
      "z": -2,
      "name": "Rock_Chalk"
    },
    {
      "x": 1,
      "y": 10,
      "z": -2,
      "name": "Rock_Marble"
    },
    {
      "x": 1,
      "y": 11,
      "z": -2,
      "name": "Rock_Chalk"
    },
    {
      "x": 1,
      "y": 12,
      "z": -2,
      "name": "Rock_Chalk"
    },
    {
      "x": 1,
      "y": 13,
      "z": -2,
      "name": "Rock_Marble_SkyGrass"
    },
    {
      "x": 1,
      "y": 3,
      "z": -1,
      "name": "Rock_Marble"
    },
    {
      "x": 1,
      "y": 4,
      "z": -1,
      "name": "Rock_Marble"
    },
    {
      "x": 1,
      "y": 5,
      "z": -1,
      "name": "Rock_Marble"
    },
    {
      "x": 1,
      "y": 6,
      "z": -1,
      "name": "Rock_Lime"
    },
    {
      "x": 1,
      "y": 7,
      "z": -1,
      "name": "Rock_Marble"
    },
    {
      "x": 1,
      "y": 8,
      "z": -1,
      "name": "Rock_Marble"
    },
    {
      "x": 1,
      "y": 9,
      "z": -1,
      "name": "Rock_Marble"
    },
    {
      "x": 1,
      "y": 10,
      "z": -1,
      "name": "Rock_Marble"
    },
    {
      "x": 1,
      "y": 11,
      "z": -1,
      "name": "Rock_Lime"
    },
    {
      "x": 1,
      "y": 12,
      "z": -1,
      "name": "Rock_Marble"
    },
    {
      "x": 1,
      "y": 13,
      "z": -1,
      "name": "Rock_Marble_SkyGrass"
    },
    {
      "x": 1,
      "y": 3,
      "z": 0,
      "name": "Rock_Marble"
    },
    {
      "x": 1,
      "y": 4,
      "z": 0,
      "name": "Rock_Marble"
    },
    {
      "x": 1,
      "y": 5,
      "z": 0,
      "name": "Rock_Marble"
    },
    {
      "x": 1,
      "y": 6,
      "z": 0,
      "name": "Rock_Chalk"
    },
    {
      "x": 1,
      "y": 7,
      "z": 0,
      "name": "Rock_Marble"
    },
    {
      "x": 1,
      "y": 8,
      "z": 0,
      "name": "Rock_Marble"
    },
    {
      "x": 1,
      "y": 9,
      "z": 0,
      "name": "Rock_Marble"
    },
    {
      "x": 1,
      "y": 10,
      "z": 0,
      "name": "Rock_Marble"
    },
    {
      "x": 1,
      "y": 11,
      "z": 0,
      "name": "Rock_Lime"
    },
    {
      "x": 1,
      "y": 12,
      "z": 0,
      "name": "Rock_Marble"
    },
    {
      "x": 1,
      "y": 13,
      "z": 0,
      "name": "Rock_Marble_SkyGrass"
    },
    {
      "x": 1,
      "y": 6,
      "z": 1,
      "name": "Rock_Chalk"
    },
    {
      "x": 1,
      "y": 7,
      "z": 1,
      "name": "Rock_Marble"
    },
    {
      "x": 1,
      "y": 8,
      "z": 1,
      "name": "Rock_Lime"
    },
    {
      "x": 1,
      "y": 9,
      "z": 1,
      "name": "Rock_Marble"
    },
    {
      "x": 1,
      "y": 10,
      "z": 1,
      "name": "Rock_Marble"
    },
    {
      "x": 1,
      "y": 11,
      "z": 1,
      "name": "Rock_Lime"
    },
    {
      "x": 1,
      "y": 12,
      "z": 1,
      "name": "Rock_Marble"
    },
    {
      "x": 1,
      "y": 13,
      "z": 1,
      "name": "Rock_Marble_SkyGrass"
    },
    {
      "x": 1,
      "y": 9,
      "z": 2,
      "name": "Rock_Lime"
    },
    {
      "x": 1,
      "y": 10,
      "z": 2,
      "name": "Rock_Lime"
    },
    {
      "x": 1,
      "y": 11,
      "z": 2,
      "name": "Rock_Lime"
    },
    {
      "x": 1,
      "y": 12,
      "z": 2,
      "name": "Rock_Marble"
    },
    {
      "x": 1,
      "y": 13,
      "z": 2,
      "name": "Rock_Marble_SkyGrass"
    },
    {
      "x": 1,
      "y": 9,
      "z": 3,
      "name": "Rock_Lime"
    },
    {
      "x": 1,
      "y": 10,
      "z": 3,
      "name": "Rock_Lime"
    },
    {
      "x": 1,
      "y": 11,
      "z": 3,
      "name": "Rock_Lime"
    },
    {
      "x": 1,
      "y": 12,
      "z": 3,
      "name": "Rock_Marble"
    },
    {
      "x": 1,
      "y": 13,
      "z": 3,
      "name": "Rock_Marble_SkyGrass"
    },
    {
      "x": 1,
      "y": 7,
      "z": 4,
      "name": "Rock_Marble_Stalactite_Large",
      "filler": 31744,
      "rotation": 8
    },
    {
      "x": 1,
      "y": 8,
      "z": 4,
      "name": "Rock_Marble_Stalactite_Large",
      "rotation": 8
    },
    {
      "x": 1,
      "y": 9,
      "z": 4,
      "name": "Rock_Lime"
    },
    {
      "x": 1,
      "y": 10,
      "z": 4,
      "name": "Rock_Lime"
    },
    {
      "x": 1,
      "y": 11,
      "z": 4,
      "name": "Rock_Lime"
    },
    {
      "x": 1,
      "y": 12,
      "z": 4,
      "name": "Rock_Marble"
    },
    {
      "x": 1,
      "y": 13,
      "z": 4,
      "name": "Rock_Marble_SkyGrass"
    },
    {
      "x": 1,
      "y": 9,
      "z": 5,
      "name": "Rock_Lime"
    },
    {
      "x": 1,
      "y": 10,
      "z": 5,
      "name": "Rock_Marble"
    },
    {
      "x": 1,
      "y": 11,
      "z": 5,
      "name": "Rock_Lime"
    },
    {
      "x": 1,
      "y": 12,
      "z": 5,
      "name": "Rock_Marble"
    },
    {
      "x": 1,
      "y": 13,
      "z": 5,
      "name": "Rock_Marble_SkyGrass"
    },
    {
      "x": 1,
      "y": 14,
      "z": 5,
      "name": "Plant_Grass_Sky_Short",
      "support": 15
    },
    {
      "x": 2,
      "y": 6,
      "z": -5,
      "name": "Rock_Lime"
    },
    {
      "x": 2,
      "y": 7,
      "z": -5,
      "name": "Rock_Lime"
    },
    {
      "x": 2,
      "y": 8,
      "z": -5,
      "name": "Rock_Chalk"
    },
    {
      "x": 2,
      "y": 9,
      "z": -5,
      "name": "Rock_Chalk"
    },
    {
      "x": 2,
      "y": 10,
      "z": -5,
      "name": "Rock_Marble"
    },
    {
      "x": 2,
      "y": 11,
      "z": -5,
      "name": "Rock_Chalk"
    },
    {
      "x": 2,
      "y": 12,
      "z": -5,
      "name": "Rock_Chalk"
    },
    {
      "x": 2,
      "y": 13,
      "z": -5,
      "name": "Rock_Marble_SkyGrass"
    },
    {
      "x": 2,
      "y": 6,
      "z": -4,
      "name": "Rock_Lime"
    },
    {
      "x": 2,
      "y": 7,
      "z": -4,
      "name": "Rock_Lime"
    },
    {
      "x": 2,
      "y": 8,
      "z": -4,
      "name": "Rock_Chalk"
    },
    {
      "x": 2,
      "y": 9,
      "z": -4,
      "name": "Rock_Chalk"
    },
    {
      "x": 2,
      "y": 10,
      "z": -4,
      "name": "Rock_Marble"
    },
    {
      "x": 2,
      "y": 11,
      "z": -4,
      "name": "Rock_Chalk"
    },
    {
      "x": 2,
      "y": 12,
      "z": -4,
      "name": "Rock_Chalk"
    },
    {
      "x": 2,
      "y": 13,
      "z": -4,
      "name": "Rock_Marble_SkyGrass"
    },
    {
      "x": 2,
      "y": 6,
      "z": -3,
      "name": "Rock_Lime"
    },
    {
      "x": 2,
      "y": 7,
      "z": -3,
      "name": "Rock_Lime"
    },
    {
      "x": 2,
      "y": 8,
      "z": -3,
      "name": "Rock_Chalk"
    },
    {
      "x": 2,
      "y": 9,
      "z": -3,
      "name": "Rock_Chalk"
    },
    {
      "x": 2,
      "y": 10,
      "z": -3,
      "name": "Rock_Marble"
    },
    {
      "x": 2,
      "y": 11,
      "z": -3,
      "name": "Rock_Chalk"
    },
    {
      "x": 2,
      "y": 12,
      "z": -3,
      "name": "Rock_Chalk"
    },
    {
      "x": 2,
      "y": 13,
      "z": -3,
      "name": "Rock_Marble_SkyGrass"
    },
    {
      "x": 2,
      "y": 6,
      "z": -2,
      "name": "Rock_Lime"
    },
    {
      "x": 2,
      "y": 7,
      "z": -2,
      "name": "Rock_Lime"
    },
    {
      "x": 2,
      "y": 8,
      "z": -2,
      "name": "Rock_Chalk"
    },
    {
      "x": 2,
      "y": 9,
      "z": -2,
      "name": "Rock_Chalk"
    },
    {
      "x": 2,
      "y": 10,
      "z": -2,
      "name": "Rock_Marble"
    },
    {
      "x": 2,
      "y": 11,
      "z": -2,
      "name": "Rock_Lime"
    },
    {
      "x": 2,
      "y": 12,
      "z": -2,
      "name": "Rock_Chalk"
    },
    {
      "x": 2,
      "y": 13,
      "z": -2,
      "name": "Rock_Marble_SkyGrass"
    },
    {
      "x": 2,
      "y": 6,
      "z": -1,
      "name": "Rock_Marble"
    },
    {
      "x": 2,
      "y": 7,
      "z": -1,
      "name": "Rock_Lime"
    },
    {
      "x": 2,
      "y": 8,
      "z": -1,
      "name": "Rock_Marble"
    },
    {
      "x": 2,
      "y": 9,
      "z": -1,
      "name": "Rock_Marble"
    },
    {
      "x": 2,
      "y": 10,
      "z": -1,
      "name": "Rock_Marble"
    },
    {
      "x": 2,
      "y": 11,
      "z": -1,
      "name": "Rock_Lime"
    },
    {
      "x": 2,
      "y": 12,
      "z": -1,
      "name": "Rock_Chalk"
    },
    {
      "x": 2,
      "y": 13,
      "z": -1,
      "name": "Rock_Marble_SkyGrass"
    },
    {
      "x": 2,
      "y": 5,
      "z": 0,
      "name": "Rock_Marble_Stalactite_Small",
      "rotation": 8
    },
    {
      "x": 2,
      "y": 6,
      "z": 0,
      "name": "Rock_Chalk"
    },
    {
      "x": 2,
      "y": 7,
      "z": 0,
      "name": "Rock_Marble"
    },
    {
      "x": 2,
      "y": 8,
      "z": 0,
      "name": "Rock_Marble"
    },
    {
      "x": 2,
      "y": 9,
      "z": 0,
      "name": "Rock_Marble"
    },
    {
      "x": 2,
      "y": 10,
      "z": 0,
      "name": "Rock_Marble"
    },
    {
      "x": 2,
      "y": 11,
      "z": 0,
      "name": "Rock_Lime"
    },
    {
      "x": 2,
      "y": 12,
      "z": 0,
      "name": "Rock_Marble"
    },
    {
      "x": 2,
      "y": 13,
      "z": 0,
      "name": "Rock_Marble_SkyGrass"
    },
    {
      "x": 2,
      "y": 6,
      "z": 1,
      "name": "Rock_Chalk"
    },
    {
      "x": 2,
      "y": 7,
      "z": 1,
      "name": "Rock_Marble"
    },
    {
      "x": 2,
      "y": 8,
      "z": 1,
      "name": "Rock_Lime"
    },
    {
      "x": 2,
      "y": 9,
      "z": 1,
      "name": "Rock_Marble"
    },
    {
      "x": 2,
      "y": 10,
      "z": 1,
      "name": "Rock_Lime"
    },
    {
      "x": 2,
      "y": 11,
      "z": 1,
      "name": "Rock_Lime"
    },
    {
      "x": 2,
      "y": 12,
      "z": 1,
      "name": "Rock_Marble"
    },
    {
      "x": 2,
      "y": 13,
      "z": 1,
      "name": "Rock_Marble_SkyGrass"
    },
    {
      "x": 2,
      "y": 9,
      "z": 2,
      "name": "Rock_Lime"
    },
    {
      "x": 2,
      "y": 10,
      "z": 2,
      "name": "Rock_Lime"
    },
    {
      "x": 2,
      "y": 11,
      "z": 2,
      "name": "Rock_Lime"
    },
    {
      "x": 2,
      "y": 12,
      "z": 2,
      "name": "Rock_Marble"
    },
    {
      "x": 2,
      "y": 13,
      "z": 2,
      "name": "Rock_Marble_SkyGrass"
    },
    {
      "x": 2,
      "y": 9,
      "z": 3,
      "name": "Rock_Lime"
    },
    {
      "x": 2,
      "y": 10,
      "z": 3,
      "name": "Rock_Lime"
    },
    {
      "x": 2,
      "y": 11,
      "z": 3,
      "name": "Rock_Lime"
    },
    {
      "x": 2,
      "y": 12,
      "z": 3,
      "name": "Rock_Marble"
    },
    {
      "x": 2,
      "y": 13,
      "z": 3,
      "name": "Rock_Marble_SkyGrass"
    },
    {
      "x": 2,
      "y": 14,
      "z": 3,
      "name": "Plant_Grass_Sky_Short",
      "support": 15
    },
    {
      "x": 2,
      "y": 9,
      "z": 4,
      "name": "Rock_Lime"
    },
    {
      "x": 2,
      "y": 10,
      "z": 4,
      "name": "Rock_Lime"
    },
    {
      "x": 2,
      "y": 11,
      "z": 4,
      "name": "Rock_Lime"
    },
    {
      "x": 2,
      "y": 12,
      "z": 4,
      "name": "Rock_Marble"
    },
    {
      "x": 2,
      "y": 13,
      "z": 4,
      "name": "Rock_Marble_SkyGrass"
    },
    {
      "x": 2,
      "y": 14,
      "z": 4,
      "name": "Plant_Grass_Sky",
      "support": 15
    },
    {
      "x": 2,
      "y": 9,
      "z": 5,
      "name": "Rock_Lime"
    },
    {
      "x": 2,
      "y": 10,
      "z": 5,
      "name": "Rock_Lime"
    },
    {
      "x": 2,
      "y": 11,
      "z": 5,
      "name": "Rock_Lime"
    },
    {
      "x": 2,
      "y": 12,
      "z": 5,
      "name": "Rock_Marble"
    },
    {
      "x": 2,
      "y": 13,
      "z": 5,
      "name": "Rock_Marble_SkyGrass"
    },
    {
      "x": 2,
      "y": 14,
      "z": 5,
      "name": "Plant_Grass_Sky_Short",
      "support": 15
    },
    {
      "x": 3,
      "y": 6,
      "z": -4,
      "name": "Rock_Lime"
    },
    {
      "x": 3,
      "y": 7,
      "z": -4,
      "name": "Rock_Lime"
    },
    {
      "x": 3,
      "y": 8,
      "z": -4,
      "name": "Rock_Chalk"
    },
    {
      "x": 3,
      "y": 9,
      "z": -4,
      "name": "Rock_Chalk"
    },
    {
      "x": 3,
      "y": 10,
      "z": -4,
      "name": "Rock_Marble"
    },
    {
      "x": 3,
      "y": 11,
      "z": -4,
      "name": "Rock_Chalk"
    },
    {
      "x": 3,
      "y": 12,
      "z": -4,
      "name": "Rock_Chalk"
    },
    {
      "x": 3,
      "y": 13,
      "z": -4,
      "name": "Rock_Marble_SkyGrass"
    },
    {
      "x": 3,
      "y": 5,
      "z": -3,
      "name": "Rock_Marble_Stalactite_Small",
      "rotation": 8
    },
    {
      "x": 3,
      "y": 6,
      "z": -3,
      "name": "Rock_Lime"
    },
    {
      "x": 3,
      "y": 7,
      "z": -3,
      "name": "Rock_Lime"
    },
    {
      "x": 3,
      "y": 8,
      "z": -3,
      "name": "Rock_Chalk"
    },
    {
      "x": 3,
      "y": 9,
      "z": -3,
      "name": "Rock_Chalk"
    },
    {
      "x": 3,
      "y": 10,
      "z": -3,
      "name": "Rock_Marble"
    },
    {
      "x": 3,
      "y": 11,
      "z": -3,
      "name": "Rock_Marble"
    },
    {
      "x": 3,
      "y": 12,
      "z": -3,
      "name": "Rock_Chalk"
    },
    {
      "x": 3,
      "y": 13,
      "z": -3,
      "name": "Rock_Marble_SkyGrass"
    },
    {
      "x": 3,
      "y": 14,
      "z": -3,
      "name": "Plant_Grass_Sky_Short",
      "support": 15
    },
    {
      "x": 3,
      "y": 6,
      "z": -2,
      "name": "Rock_Lime"
    },
    {
      "x": 3,
      "y": 7,
      "z": -2,
      "name": "Rock_Lime"
    },
    {
      "x": 3,
      "y": 8,
      "z": -2,
      "name": "Rock_Chalk"
    },
    {
      "x": 3,
      "y": 9,
      "z": -2,
      "name": "Rock_Chalk"
    },
    {
      "x": 3,
      "y": 10,
      "z": -2,
      "name": "Rock_Marble"
    },
    {
      "x": 3,
      "y": 11,
      "z": -2,
      "name": "Rock_Lime"
    },
    {
      "x": 3,
      "y": 12,
      "z": -2,
      "name": "Rock_Chalk"
    },
    {
      "x": 3,
      "y": 13,
      "z": -2,
      "name": "Rock_Marble_SkyGrass"
    },
    {
      "x": 3,
      "y": 14,
      "z": -2,
      "name": "Rubble_Marble",
      "support": 15
    },
    {
      "x": 3,
      "y": 6,
      "z": -1,
      "name": "Rock_Marble"
    },
    {
      "x": 3,
      "y": 7,
      "z": -1,
      "name": "Rock_Lime"
    },
    {
      "x": 3,
      "y": 8,
      "z": -1,
      "name": "Rock_Marble"
    },
    {
      "x": 3,
      "y": 9,
      "z": -1,
      "name": "Rock_Marble"
    },
    {
      "x": 3,
      "y": 10,
      "z": -1,
      "name": "Rock_Marble"
    },
    {
      "x": 3,
      "y": 11,
      "z": -1,
      "name": "Rock_Lime"
    },
    {
      "x": 3,
      "y": 12,
      "z": -1,
      "name": "Rock_Chalk"
    },
    {
      "x": 3,
      "y": 13,
      "z": -1,
      "name": "Rock_Marble_SkyGrass"
    },
    {
      "x": 3,
      "y": 6,
      "z": 0,
      "name": "Rock_Marble"
    },
    {
      "x": 3,
      "y": 7,
      "z": 0,
      "name": "Rock_Lime"
    },
    {
      "x": 3,
      "y": 8,
      "z": 0,
      "name": "Rock_Marble"
    },
    {
      "x": 3,
      "y": 9,
      "z": 0,
      "name": "Rock_Marble"
    },
    {
      "x": 3,
      "y": 10,
      "z": 0,
      "name": "Rock_Lime"
    },
    {
      "x": 3,
      "y": 11,
      "z": 0,
      "name": "Rock_Lime"
    },
    {
      "x": 3,
      "y": 12,
      "z": 0,
      "name": "Rock_Chalk"
    },
    {
      "x": 3,
      "y": 13,
      "z": 0,
      "name": "Rock_Marble_SkyGrass"
    },
    {
      "x": 3,
      "y": 9,
      "z": 1,
      "name": "Rock_Marble"
    },
    {
      "x": 3,
      "y": 10,
      "z": 1,
      "name": "Rock_Lime"
    },
    {
      "x": 3,
      "y": 11,
      "z": 1,
      "name": "Rock_Lime"
    },
    {
      "x": 3,
      "y": 12,
      "z": 1,
      "name": "Rock_Marble"
    },
    {
      "x": 3,
      "y": 13,
      "z": 1,
      "name": "Rock_Marble_SkyGrass"
    },
    {
      "x": 3,
      "y": 14,
      "z": 1,
      "name": "Plant_Grass_Sky",
      "support": 15
    },
    {
      "x": 3,
      "y": 9,
      "z": 2,
      "name": "Rock_Lime"
    },
    {
      "x": 3,
      "y": 10,
      "z": 2,
      "name": "Rock_Lime"
    },
    {
      "x": 3,
      "y": 11,
      "z": 2,
      "name": "Rock_Lime"
    },
    {
      "x": 3,
      "y": 12,
      "z": 2,
      "name": "Rock_Marble"
    },
    {
      "x": 3,
      "y": 13,
      "z": 2,
      "name": "Rock_Marble_SkyGrass"
    },
    {
      "x": 3,
      "y": 8,
      "z": 3,
      "name": "Rock_Marble_Stalactite_Small",
      "rotation": 8
    },
    {
      "x": 3,
      "y": 9,
      "z": 3,
      "name": "Rock_Lime"
    },
    {
      "x": 3,
      "y": 10,
      "z": 3,
      "name": "Rock_Lime"
    },
    {
      "x": 3,
      "y": 11,
      "z": 3,
      "name": "Rock_Lime"
    },
    {
      "x": 3,
      "y": 12,
      "z": 3,
      "name": "Rock_Marble"
    },
    {
      "x": 3,
      "y": 13,
      "z": 3,
      "name": "Rock_Marble_SkyGrass"
    },
    {
      "x": 3,
      "y": 14,
      "z": 3,
      "name": "Plant_Grass_Sky_Long",
      "support": 15
    },
    {
      "x": 3,
      "y": 9,
      "z": 4,
      "name": "Rock_Lime"
    },
    {
      "x": 3,
      "y": 10,
      "z": 4,
      "name": "Rock_Lime"
    },
    {
      "x": 3,
      "y": 11,
      "z": 4,
      "name": "Rock_Lime"
    },
    {
      "x": 3,
      "y": 12,
      "z": 4,
      "name": "Rock_Marble"
    },
    {
      "x": 3,
      "y": 13,
      "z": 4,
      "name": "Rock_Marble_SkyGrass"
    },
    {
      "x": 3,
      "y": 14,
      "z": 4,
      "name": "Plant_Grass_Sky_Short",
      "support": 15
    },
    {
      "x": 4,
      "y": 6,
      "z": -3,
      "name": "Rock_Lime"
    },
    {
      "x": 4,
      "y": 7,
      "z": -3,
      "name": "Rock_Lime"
    },
    {
      "x": 4,
      "y": 8,
      "z": -3,
      "name": "Rock_Chalk"
    },
    {
      "x": 4,
      "y": 9,
      "z": -3,
      "name": "Rock_Chalk"
    },
    {
      "x": 4,
      "y": 10,
      "z": -3,
      "name": "Rock_Marble"
    },
    {
      "x": 4,
      "y": 11,
      "z": -3,
      "name": "Rock_Marble"
    },
    {
      "x": 4,
      "y": 12,
      "z": -3,
      "name": "Rock_Chalk"
    },
    {
      "x": 4,
      "y": 13,
      "z": -3,
      "name": "Rock_Marble_SkyGrass"
    },
    {
      "x": 4,
      "y": 6,
      "z": -2,
      "name": "Rock_Marble"
    },
    {
      "x": 4,
      "y": 7,
      "z": -2,
      "name": "Rock_Lime"
    },
    {
      "x": 4,
      "y": 8,
      "z": -2,
      "name": "Rock_Marble"
    },
    {
      "x": 4,
      "y": 9,
      "z": -2,
      "name": "Rock_Marble"
    },
    {
      "x": 4,
      "y": 10,
      "z": -2,
      "name": "Rock_Marble"
    },
    {
      "x": 4,
      "y": 11,
      "z": -2,
      "name": "Rock_Lime"
    },
    {
      "x": 4,
      "y": 12,
      "z": -2,
      "name": "Rock_Chalk"
    },
    {
      "x": 4,
      "y": 13,
      "z": -2,
      "name": "Rock_Marble_SkyGrass"
    },
    {
      "x": 4,
      "y": 14,
      "z": -2,
      "name": "Plant_Grass_Sky",
      "support": 15
    },
    {
      "x": 4,
      "y": 6,
      "z": -1,
      "name": "Rock_Marble"
    },
    {
      "x": 4,
      "y": 7,
      "z": -1,
      "name": "Rock_Lime"
    },
    {
      "x": 4,
      "y": 8,
      "z": -1,
      "name": "Rock_Marble"
    },
    {
      "x": 4,
      "y": 9,
      "z": -1,
      "name": "Rock_Marble"
    },
    {
      "x": 4,
      "y": 10,
      "z": -1,
      "name": "Rock_Marble"
    },
    {
      "x": 4,
      "y": 11,
      "z": -1,
      "name": "Rock_Lime"
    },
    {
      "x": 4,
      "y": 12,
      "z": -1,
      "name": "Rock_Chalk"
    },
    {
      "x": 4,
      "y": 13,
      "z": -1,
      "name": "Rock_Marble_SkyGrass"
    },
    {
      "x": 4,
      "y": 14,
      "z": -1,
      "name": "Plant_Grass_Sky_Short",
      "support": 15
    },
    {
      "x": 4,
      "y": 7,
      "z": 0,
      "name": "Rock_Marble_Stalactite_Large",
      "filler": 31744,
      "rotation": 8
    },
    {
      "x": 4,
      "y": 8,
      "z": 0,
      "name": "Rock_Marble_Stalactite_Large",
      "rotation": 8
    },
    {
      "x": 4,
      "y": 9,
      "z": 0,
      "name": "Rock_Marble"
    },
    {
      "x": 4,
      "y": 10,
      "z": 0,
      "name": "Rock_Lime"
    },
    {
      "x": 4,
      "y": 11,
      "z": 0,
      "name": "Rock_Lime"
    },
    {
      "x": 4,
      "y": 12,
      "z": 0,
      "name": "Rock_Chalk"
    },
    {
      "x": 4,
      "y": 13,
      "z": 0,
      "name": "Rock_Marble_SkyGrass"
    },
    {
      "x": 4,
      "y": 14,
      "z": 0,
      "name": "Plant_Grass_Sky",
      "support": 15
    },
    {
      "x": 4,
      "y": 9,
      "z": 1,
      "name": "Rock_Marble"
    },
    {
      "x": 4,
      "y": 10,
      "z": 1,
      "name": "Rock_Lime"
    },
    {
      "x": 4,
      "y": 11,
      "z": 1,
      "name": "Rock_Lime"
    },
    {
      "x": 4,
      "y": 12,
      "z": 1,
      "name": "Rock_Marble"
    },
    {
      "x": 4,
      "y": 13,
      "z": 1,
      "name": "Rock_Marble_SkyGrass"
    },
    {
      "x": 4,
      "y": 14,
      "z": 1,
      "name": "Plant_Grass_Sky_Long",
      "support": 15
    },
    {
      "x": 4,
      "y": 9,
      "z": 2,
      "name": "Rock_Marble"
    },
    {
      "x": 4,
      "y": 10,
      "z": 2,
      "name": "Rock_Lime"
    },
    {
      "x": 4,
      "y": 11,
      "z": 2,
      "name": "Rock_Lime"
    },
    {
      "x": 4,
      "y": 12,
      "z": 2,
      "name": "Rock_Marble"
    },
    {
      "x": 4,
      "y": 13,
      "z": 2,
      "name": "Rock_Marble_SkyGrass"
    },
    {
      "x": 4,
      "y": 14,
      "z": 2,
      "name": "Plant_Grass_Sky",
      "support": 15
    },
    {
      "x": 4,
      "y": 9,
      "z": 3,
      "name": "Rock_Lime"
    },
    {
      "x": 4,
      "y": 10,
      "z": 3,
      "name": "Rock_Lime"
    },
    {
      "x": 4,
      "y": 11,
      "z": 3,
      "name": "Rock_Lime"
    },
    {
      "x": 4,
      "y": 12,
      "z": 3,
      "name": "Rock_Marble"
    },
    {
      "x": 4,
      "y": 13,
      "z": 3,
      "name": "Rock_Marble_SkyGrass"
    },
    {
      "x": 5,
      "y": 9,
      "z": -2,
      "name": "Rock_Marble"
    },
    {
      "x": 5,
      "y": 10,
      "z": -2,
      "name": "Rock_Marble"
    },
    {
      "x": 5,
      "y": 11,
      "z": -2,
      "name": "Rock_Lime"
    },
    {
      "x": 5,
      "y": 12,
      "z": -2,
      "name": "Rock_Chalk"
    },
    {
      "x": 5,
      "y": 13,
      "z": -2,
      "name": "Rock_Marble_SkyGrass"
    },
    {
      "x": 5,
      "y": 9,
      "z": -1,
      "name": "Rock_Marble"
    },
    {
      "x": 5,
      "y": 10,
      "z": -1,
      "name": "Rock_Marble"
    },
    {
      "x": 5,
      "y": 11,
      "z": -1,
      "name": "Rock_Lime"
    },
    {
      "x": 5,
      "y": 12,
      "z": -1,
      "name": "Rock_Chalk"
    },
    {
      "x": 5,
      "y": 13,
      "z": -1,
      "name": "Rock_Marble_SkyGrass"
    },
    {
      "x": 5,
      "y": 9,
      "z": 0,
      "name": "Rock_Marble"
    },
    {
      "x": 5,
      "y": 10,
      "z": 0,
      "name": "Rock_Lime"
    },
    {
      "x": 5,
      "y": 11,
      "z": 0,
      "name": "Rock_Lime"
    },
    {
      "x": 5,
      "y": 12,
      "z": 0,
      "name": "Rock_Chalk"
    },
    {
      "x": 5,
      "y": 13,
      "z": 0,
      "name": "Rock_Marble_SkyGrass"
    },
    {
      "x": 5,
      "y": 14,
      "z": 0,
      "name": "Plant_Grass_Sky",
      "support": 15
    },
    {
      "x": 5,
      "y": 8,
      "z": 1,
      "name": "Rock_Marble_Stalactite_Small",
      "rotation": 8
    },
    {
      "x": 5,
      "y": 9,
      "z": 1,
      "name": "Rock_Marble"
    },
    {
      "x": 5,
      "y": 10,
      "z": 1,
      "name": "Rock_Lime"
    },
    {
      "x": 5,
      "y": 11,
      "z": 1,
      "name": "Rock_Lime"
    },
    {
      "x": 5,
      "y": 12,
      "z": 1,
      "name": "Rock_Marble"
    },
    {
      "x": 5,
      "y": 13,
      "z": 1,
      "name": "Rock_Marble_SkyGrass"
    },
    {
      "x": 5,
      "y": 14,
      "z": 1,
      "name": "Plant_Grass_Sky",
      "support": 15
    },
    {
      "x": 5,
      "y": 9,
      "z": 2,
      "name": "Rock_Marble"
    },
    {
      "x": 5,
      "y": 10,
      "z": 2,
      "name": "Rock_Lime"
    },
    {
      "x": 5,
      "y": 11,
      "z": 2,
      "name": "Rock_Lime"
    },
    {
      "x": 5,
      "y": 12,
      "z": 2,
      "name": "Rock_Marble"
    },
    {
      "x": 5,
      "y": 13,
      "z": 2,
      "name": "Rock_Marble_SkyGrass"
    }
  ]
}