{
  "version": 8,
  "blockIdVersion": 11,
  "anchorX": 0,
  "anchorY": 5,
  "anchorZ": 0,
  "blocks": [
    {
      "x": -4,
      "y": -1,
      "z": 0,
      "name": "Wood_Fig_Blue_Branch_Corner",
      "rotation": 3
    },
    {
      "x": -4,
      "y": 0,
      "z": 0,
      "name": "Wood_Fig_Blue_Branch_Corner",
      "rotation": 9
    },
    {
      "x": -3,
      "y": -1,
      "z": 0,
      "name": "Wood_Fig_Blue_Branch_Long",
      "rotation": 5
    },
    {
      "x": -2,
      "y": 11,
      "z": -2,
      "name": "Plant_Leaves_Maple"
    },
    {
      "x": -2,
      "y": 12,
      "z": -2,
      "name": "Plant_Leaves_Maple"
    },
    {
      "x": -2,
      "y": 12,
      "z": -1,
      "name": "Plant_Leaves_Maple"
    },
    {
      "x": -2,
      "y": -1,
      "z": 0,
      "name": "Wood_Fig_Blue_Trunk_Full",
      "rotation": 4
    },
    {
      "x": -2,
      "y": 0,
      "z": 0,
      "name": "Wood_Fig_Blue_Trunk"
    },
    {
      "x": -2,
      "y": 1,
      "z": 0,
      "name": "Wood_Fig_Blue_Trunk"
    },
    {
      "x": -2,
      "y": 2,
      "z": 0,
      "name": "Wood_Fig_Blue_Trunk"
    },
    {
      "x": -2,
      "y": 3,
      "z": 0,
      "name": "Wood_Fig_Blue_Trunk_Full"
    },
    {
      "x": -2,
      "y": 12,
      "z": 0,
      "name": "Plant_Leaves_Maple"
    },
    {
      "x": -2,
      "y": 9,
      "z": 1,
      "name": "Plant_Leaves_Maple"
    },
    {
      "x": -2,
      "y": 9,
      "z": 2,
      "name": "Plant_Leaves_Maple"
    },
    {
      "x": -2,
      "y": 9,
      "z": 3,
      "name": "Plant_Leaves_Maple"
    },
    {
      "x": -1,
      "y": 12,
      "z": -4,
      "name": "Plant_Leaves_Maple"
    },
    {
      "x": -1,
      "y": 12,
      "z": -3,
      "name": "Plant_Leaves_Maple"
    },
    {
      "x": -1,
      "y": 12,
      "z": -2,
      "name": "Plant_Leaves_Maple"
    },
    {
      "x": -1,
      "y": 13,
      "z": -2,
      "name": "Plant_Leaves_Maple"
    },
    {
      "x": -1,
      "y": 9,
      "z": -1,
      "name": "Wood_Fig_Blue_Trunk_Full",
      "rotation": 5
    },
    {
      "x": -1,
      "y": 12,
      "z": -1,
      "name": "Plant_Leaves_Maple"
    },
    {
      "x": -1,
      "y": 13,
      "z": -1,
      "name": "Plant_Leaves_Maple"
    },
    {
      "x": -1,
      "y": 2,
      "z": 0,
      "name": "Wood_Fig_Blue_Trunk"
    },
    {
      "x": -1,
      "y": 3,
      "z": 0,
      "name": "Wood_Fig_Blue_Trunk"
    },
    {
      "x": -1,
      "y": 4,
      "z": 0,
      "name": "Wood_Fig_Blue_Trunk"
    },
    {
      "x": -1,
      "y": 5,
      "z": 0,
      "name": "Wood_Fig_Blue_Trunk"
    },
    {
      "x": -1,
      "y": 6,
      "z": 0,
      "name": "Wood_Fig_Blue_Trunk"
    },
    {
      "x": -1,
      "y": 7,
      "z": 0,
      "name": "Wood_Fig_Blue_Trunk"
    },
    {
      "x": -1,
      "y": 8,
      "z": 0,
      "name": "Wood_Fig_Blue_Trunk_Full",
      "rotation": 5
    },
    {
      "x": -1,
      "y": 9,
      "z": 0,
      "name": "Plant_Leaves_Maple"
    },
    {
      "x": -1,
      "y": 12,
      "z": 0,
      "name": "Plant_Leaves_Maple"
    },
    {
      "x": -1,
      "y": 9,
      "z": 1,
      "name": "Plant_Leaves_Maple"
    },
    {
      "x": -1,
      "y": 10,
      "z": 1,
      "name": "Plant_Leaves_Maple"
    },
    {
      "x": -1,
      "y": 12,
      "z": 1,
      "name": "Plant_Leaves_Maple"
    },
    {
      "x": -1,
      "y": -1,
      "z": 2,
      "name": "Wood_Fig_Blue_Branch_Long"
    },
    {
      "x": -1,
      "y": 0,
      "z": 2,
      "name": "Wood_Fig_Blue_Branch_Corner",
      "rotation": 9
    },
    {
      "x": -1,
      "y": 9,
      "z": 2,
      "name": "Plant_Leaves_Maple"
    },
    {
      "x": -1,
      "y": 10,
      "z": 2,
      "name": "Plant_Leaves_Maple"
    },
    {
      "x": -1,
      "y": 9,
      "z": 3,
      "name": "Plant_Leaves_Maple"
    },
    {
      "x": -1,
      "y": 9,
      "z": 4,
      "name": "Plant_Leaves_Maple"
    },
    {
      "x": 0,
      "y": 9,
      "z": -4,
      "name": "Wood_Fig_Blue_Branch_Corner",
      "rotation": 2
    },
    {
      "x": 0,
      "y": 10,
      "z": -4,
      "name": "Wood_Fig_Blue_Branch_Corner",
      "rotation": 8
    },
    {
      "x": 0,
      "y": 12,
      "z": -4,
      "name": "Plant_Leaves_Maple"
    },
    {
      "x": 0,
      "y": 10,
      "z": -3,
      "name": "Wood_Fig_Blue_Branch_Long",
      "rotation": 4
    },
    {
      "x": 0,
      "y": 12,
      "z": -3,
      "name": "Plant_Leaves_Maple"
    },
    {
      "x": 0,
      "y": 13,
      "z": -3,
      "name": "Plant_Leaves_Maple"
    },
    {
      "x": 0,
      "y": 16,
      "z": -3,
      "name": "Plant_Leaves_Maple"
    },
    {
      "x": 0,
      "y": -1,
      "z": -2,
      "name": "Wood_Fig_Blue_Branch_Long"
    },
    {
      "x": 0,
      "y": 0,
      "z": -2,
      "name": "Wood_Fig_Blue_Branch_Long"
    },
    {
      "x": 0,
      "y": 1,
      "z": -2,
      "name": "Wood_Fig_Blue_Branch_Corner",
      "rotation": 8
    },
    {
      "x": 0,
      "y": 9,
      "z": -2,
      "name": "Wood_Fig_Blue_Trunk_Full"
    },
    {
      "x": 0,
      "y": 10,
      "z": -2,
      "name": "Wood_Fig_Blue_Trunk"
    },
    {
      "x": 0,
      "y": 11,
      "z": -2,
      "name": "Wood_Fig_Blue_Trunk_Full"
    },
    {
      "x": 0,
      "y": 12,
      "z": -2,
      "name": "Plant_Leaves_Maple"
    },
    {
      "x": 0,
      "y": 13,
      "z": -2,
      "name": "Plant_Leaves_Maple"
    },
    {
      "x": 0,
      "y": 16,
      "z": -2,
      "name": "Plant_Leaves_Maple"
    },
    {
      "x": 0,
      "y": 17,
      "z": -2,
      "name": "Plant_Leaves_Maple"
    },
    {
      "x": 0,
      "y": 0,
      "z": -1,
      "name": "Wood_Fig_Blue_Trunk_Full",
      "rotation": 5
    },
    {
      "x": 0,
      "y": 1,
      "z": -1,
      "name": "Wood_Fig_Blue_Trunk"
    },
    {
      "x": 0,
      "y": 2,
      "z": -1,
      "name": "Wood_Fig_Blue_Trunk"
    },
    {
      "x": 0,
      "y": 3,
      "z": -1,
      "name": "Wood_Fig_Blue_Trunk"
    },
    {
      "x": 0,
      "y": 4,
      "z": -1,
      "name": "Wood_Fig_Blue_Trunk"
    },
    {
      "x": 0,
      "y": 5,
      "z": -1,
      "name": "Wood_Fig_Blue_Trunk_Full"
    },
    {
      "x": 0,
      "y": 8,
      "z": -1,
      "name": "Wood_Fig_Blue_Trunk_Full",
      "rotation": 5
    },
    {
      "x": 0,
      "y": 9,
      "z": -1,
      "name": "Wood_Fig_Blue_Trunk_Full"
    },
    {
      "x": 0,
      "y": 11,
      "z": -1,
      "name": "Wood_Fig_Blue_Branch_Long",
      "rotation": 4
    },
    {
      "x": 0,
      "y": 12,
      "z": -1,
      "name": "Plant_Leaves_Maple"
    },
    {
      "x": 0,
      "y": 13,
      "z": -1,
      "name": "Plant_Leaves_Maple"
    },
    {
      "x": 0,
      "y": 15,
      "z": -1,
      "name": "Plant_Leaves_Maple"
    },
    {
      "x": 0,
      "y": 16,
      "z": -1,
      "name": "Plant_Leaves_Maple"
    },
    {
      "x": 0,
      "y": 2,
      "z": 0,
      "name": "Wood_Fig_Blue_Trunk"
    },
    {
      "x": 0,
      "y": 3,
      "z": 0,
      "name": "Wood_Fig_Blue_Trunk"
    },
    {
      "x": 0,
      "y": 4,
      "z": 0,
      "name": "Wood_Fig_Blue_Trunk"
    },
    {
      "x": 0,
      "y": 5,
      "z": 0,
      "name": "Wood_Fig_Blue_Trunk"
    },
    {
      "x": 0,
      "y": 6,
      "z": 0,
      "name": "Wood_Fig_Blue_Trunk"
    },
    {
      "x": 0,
      "y": 7,
      "z": 0,
      "name": "Wood_Fig_Blue_Trunk"
    },
    {
      "x": 0,
      "y": 8,
      "z": 0,
      "name": "Wood_Fig_Blue_Trunk_Full",
      "rotation": 5
    },
    {
      "x": 0,
      "y": 9,
      "z": 0,
      "name": "Plant_Leaves_Maple"
    },
    {
      "x": 0,
      "y": 11,
      "z": 0,
      "name": "Wood_Fig_Blue_Branch_Long",
      "rotation": 4
    },
    {
      "x": 0,
      "y": 12,
      "z": 0,
      "name": "Plant_Leaves_Maple"
    },
    {
      "x": 0,
      "y": 13,
      "z": 0,
      "name": "Plant_Leaves_Maple"
    },
    {
      "x": 0,
      "y": 16,
      "z": 0,
      "name": "Plant_Leaves_Maple"
    },
    {
      "x": 0,
      "y": 3,
      "z": 1,
      "name": "Wood_Fig_Blue_Trunk_Full"
    },
    {
      "x": 0,
      "y": 4,
      "z": 1,
      "name": "Wood_Fig_Blue_Trunk"
    },
    {
      "x": 0,
      "y": 5,
      "z": 1,
      "name": "Wood_Fig_Blue_Trunk"
    },
    {
      "x": 0,
      "y": 6,
      "z": 1,
      "name": "Wood_Fig_Blue_Trunk_Full",
      "rotation": 5
    },
    {
      "x": 0,
      "y": 8,
      "z": 1,
      "name": "Wood_Fig_Blue_Branch_Long",
      "rotation": 4
    },
    {
      "x": 0,
      "y": 9,
      "z": 1,
      "name": "Plant_Leaves_Maple"
    },
    {
      "x": 0,
      "y": 10,
      "z": 1,
      "name": "Plant_Leaves_Maple"
    },
    {
      "x": 0,
      "y": 11,
      "z": 1,
      "name": "Wood_Fig_Blue_Branch_Corner"
    },
    {
      "x": 0,
      "y": 12,
      "z": 1,
      "name": "Wood_Fig_Blue_Branch_Long"
    },
    {
      "x": 0,
      "y": 13,
      "z": 1,
      "name": "Plant_Leaves_Maple"
    },
    {
      "x": 0,
      "y": -1,
      "z": 2,
      "name": "Wood_Fig_Blue_Branch_Corner",
      "rotation": 2
    },
    {
      "x": 0,
      "y": 0,
      "z": 2,
      "name": "Wood_Fig_Blue_Trunk_Full"
    },
    {
      "x": 0,
      "y": 1,
      "z": 2,
      "name": "Wood_Fig_Blue_Trunk"
    },
    {
      "x": 0,
      "y": 2,
      "z": 2,
      "name": "Wood_Fig_Blue_Trunk"
    },
    {
      "x": 0,
      "y": 3,
      "z": 2,
      "name": "Wood_Fig_Blue_Trunk_Full"
    },
    {
      "x": 0,
      "y": 8,
      "z": 2,
      "name": "Wood_Fig_Blue_Branch_Corner"
    },
    {
      "x": 0,
      "y": 9,
      "z": 2,
      "name": "Wood_Fig_Blue_Branch_Corner",
      "rotation": 8
    },
    {
      "x": 0,
      "y": 10,
      "z": 2,
      "name": "Plant_Leaves_Maple"
    },
    {
      "x": 0,
      "y": 12,
      "z": 2,
      "name": "Plant_Leaves_Maple"
    },
    {
      "x": 0,
      "y": -1,
      "z": 3,
      "name": "Wood_Fig_Blue_Branch_Long",
      "rotation": 4
    },
    {
      "x": 0,
      "y": 9,
      "z": 3,
      "name": "Plant_Leaves_Maple"
    },
    {
      "x": 0,
      "y": 10,
      "z": 3,
      "name": "Plant_Leaves_Maple"
    },
    {
      "x": 0,
      "y": -1,
      "z": 4,
      "name": "Wood_Fig_Blue_Branch_Corner"
    },
    {
      "x": 0,
      "y": 0,
      "z": 4,
      "name": "Wood_Fig_Blue_Branch_Long"
    },
    {
      "x": 0,
      "y": 1,
      "z": 4,
      "name": "Wood_Fig_Blue_Branch_Corner",
      "rotation": 10
    },
    {
      "x": 0,
      "y": 9,
      "z": 4,
      "name": "Plant_Leaves_Maple"
    },
    {
      "x": 1,
      "y": 12,
      "z": -5,
      "name": "Plant_Leaves_Maple"
    },
    {
      "x": 1,
      "y": 12,
      "z": -4,
      "name": "Plant_Leaves_Maple"
    },
    {
      "x": 1,
      "y": 13,
      "z": -4,
      "name": "Plant_Leaves_Maple"
    },
    {
      "x": 1,
      "y": 14,
      "z": -4,
      "name": "Plant_Leaves_Maple"
    },
    {
      "x": 1,
      "y": 16,
      "z": -4,
      "name": "Plant_Leaves_Maple"
    },
    {
      "x": 1,
      "y": 12,
      "z": -3,
      "name": "Wood_Fig_Blue_Branch_Corner",
      "rotation": 2
    },
    {
      "x": 1,
      "y": 13,
      "z": -3,
      "name": "Wood_Fig_Blue_Branch_Long"
    },
    {
      "x": 1,
      "y": 14,
      "z": -3,
      "name": "Plant_Leaves_Maple"
    },
    {
      "x": 1,
      "y": 16,
      "z": -3,
      "name": "Plant_Leaves_Maple"
    },
    {
      "x": 1,
      "y": 17,
      "z": -3,
      "name": "Plant_Leaves_Maple"
    },
    {
      "x": 1,
      "y": 11,
      "z": -2,
      "name": "Wood_Fig_Blue_Trunk_Full"
    },
    {
      "x": 1,
      "y": 12,
      "z": -2,
      "name": "Wood_Fig_Blue_Trunk"
    },
    {
      "x": 1,
      "y": 13,
      "z": -2,
      "name": "Wood_Fig_Blue_Trunk_Full"
    },
    {
      "x": 1,
      "y": 14,
      "z": -2,
      "name": "Wood_Fig_Blue_Branch_Long"
    },
    {
      "x": 1,
      "y": 15,
      "z": -2,
      "name": "Wood_Fig_Blue_Branch_Long"
    },
    {
      "x": 1,
      "y": 16,
      "z": -2,
      "name": "Wood_Fig_Blue_Branch_Long"
    },
    {
      "x": 1,
      "y": 17,
      "z": -2,
      "name": "Plant_Leaves_Maple"
    },
    {
      "x": 1,
      "y": 8,
      "z": -1,
      "name": "Wood_Fig_Blue_Branch_Short",
      "rotation": 1
    },
    {
      "x": 1,
      "y": 12,
      "z": -1,
      "name": "Plant_Leaves_Maple"
    },
    {
      "x": 1,
      "y": 13,
      "z": -1,
      "name": "Plant_Leaves_Maple"
    },
    {
      "x": 1,
      "y": 16,
      "z": -1,
      "name": "Plant_Leaves_Maple"
    },
    {
      "x": 1,
      "y": 17,
      "z": -1,
      "name": "Plant_Leaves_Maple"
    },
    {
      "x": 1,
      "y": 0,
      "z": 0,
      "name": "Wood_Fig_Blue_Roots"
    },
    {
      "x": 1,
      "y": 1,
      "z": 0,
      "name": "Wood_Fig_Blue_Trunk_Full",
      "rotation": 4
    },
    {
      "x": 1,
      "y": 2,
      "z": 0,
      "name": "Wood_Fig_Blue_Trunk"
    },
    {
      "x": 1,
      "y": 3,
      "z": 0,
      "name": "Wood_Fig_Blue_Trunk"
    },
    {
      "x": 1,
      "y": 4,
      "z": 0,
      "name": "Wood_Fig_Blue_Trunk_Full"
    },
    {
      "x": 1,
      "y": 12,
      "z": 0,
      "name": "Plant_Leaves_Maple"
    },
    {
      "x": 1,
      "y": 13,
      "z": 0,
      "name": "Plant_Leaves_Maple"
    },
    {
      "x": 1,
      "y": 16,
      "z": 0,
      "name": "Plant_Leaves_Maple"
    },
    {
      "x": 1,
      "y": 9,
      "z": 1,
      "name": "Plant_Leaves_Maple"
    },
    {
      "x": 1,
      "y": 12,
      "z": 1,
      "name": "Plant_Leaves_Maple"
    },
    {
      "x": 1,
      "y": 13,
      "z": 1,
      "name": "Plant_Leaves_Maple"
    },
    {
      "x": 1,
      "y": 9,
      "z": 2,
      "name": "Plant_Leaves_Maple"
    },
    {
      "x": 1,
      "y": 12,
      "z": 2,
      "name": "Plant_Leaves_Maple"
    },
    {
      "x": 1,
      "y": 9,
      "z": 3,
      "name": "Plant_Leaves_Maple"
    },
    {
      "x": 1,
      "y": 10,
      "z": 3,
      "name": "Plant_Leaves_Maple"
    },
    {
      "x": 1,
      "y": 9,
      "z": 4,
      "name": "Plant_Leaves_Maple"
    },
    {
      "x": 2,
      "y": 12,
      "z": -4,
      "name": "Plant_Leaves_Maple"
    },
    {
      "x": 2,
      "y": 13,
      "z": -4,
      "name": "Plant_Leaves_Maple"
    },
    {
      "x": 2,
      "y": 16,
      "z": -4,
      "name": "Plant_Leaves_Maple"
    },
    {
      "x": 2,
      "y": 10,
      "z": -3,
      "name": "Plant_Leaves_Maple"
    },
    {
      "x": 2,
      "y": 11,
      "z": -3,
      "name": "Plant_Leaves_Maple"
    },
    {
      "x": 2,
      "y": 12,
      "z": -3,
      "name": "Plant_Leaves_Maple"
    },
    {
      "x": 2,
      "y": 13,
      "z": -3,
      "name": "Plant_Leaves_Maple"
    },
    {
      "x": 2,
      "y": 14,
      "z": -3,
      "name": "Plant_Leaves_Maple"
    },
    {
      "x": 2,
      "y": 16,
      "z": -3,
      "name": "Plant_Leaves_Maple"
    },
    {
      "x": 2,
      "y": 12,
      "z": -2,
      "name": "Plant_Leaves_Maple"
    },
    {
      "x": 2,
      "y": 13,
      "z": -2,
      "name": "Plant_Leaves_Maple"
    },
    {
      "x": 2,
      "y": 16,
      "z": -2,
      "name": "Plant_Leaves_Maple"
    },
    {
      "x": 2,
      "y": 17,
      "z": -2,
      "name": "Plant_Leaves_Maple"
    },
    {
      "x": 2,
      "y": 12,
      "z": -1,
      "name": "Plant_Leaves_Maple"
    },
    {
      "x": 2,
      "y": 13,
      "z": -1,
      "name": "Plant_Leaves_Maple"
    },
    {
      "x": 2,
      "y": 16,
      "z": -1,
      "name": "Plant_Leaves_Maple"
    },
    {
      "x": 2,
      "y": -1,
      "z": 0,
      "name": "Wood_Fig_Blue_Branch_Corner",
      "rotation": 3
    },
    {
      "x": 2,
      "y": 0,
      "z": 0,
      "name": "Wood_Fig_Blue_Branch_Long"
    },
    {
      "x": 2,
      "y": 1,
      "z": 0,
      "name": "Wood_Fig_Blue_Branch_Long"
    },
    {
      "x": 2,
      "y": 2,
      "z": 0,
      "name": "Wood_Fig_Blue_Branch_Corner",
      "rotation": 11
    },
    {
      "x": 2,
      "y": 12,
      "z": 0,
      "name": "Plant_Leaves_Maple"
    },
    {
      "x": 2,
      "y": 13,
      "z": 0,
      "name": "Plant_Leaves_Maple"
    },
    {
      "x": 2,
      "y": 12,
      "z": 1,
      "name": "Plant_Leaves_Maple"
    },
    {
      "x": 2,
      "y": 13,
      "z": 1,
      "name": "Plant_Leaves_Maple"
    },
    {
      "x": 2,
      "y": 9,
      "z": 2,
      "name": "Plant_Leaves_Maple"
    },
    {
      "x": 2,
      "y": 9,
      "z": 3,
      "name": "Plant_Leaves_Maple"
    },
    {
      "x": 3,
      "y": 12,
      "z": -2,
      "name": "Plant_Leaves_Maple"
    },
    {
      "x": 3,
      "y": 12,
      "z": -1,
      "name": "Plant_Leaves_Maple"
    },
    {
      "x": 3,
      "y": -1,
      "z": 0,
      "name": "Wood_Fig_Blue_Branch_Long",
      "rotation": 5
    },
    {
      "x": 3,
      "y": 0,
      "z": 0,
      "name": "Wood_Fig_Blue_Branch_Corner",
      "rotation": 3
    },
    {
      "x": 3,
      "y": 1,
      "z": 0,
      "name": "Wood_Fig_Blue_Branch_Corner",
      "rotation": 9
    },
    {
      "x": 4,
      "y": -1,
      "z": 0,
      "name": "Wood_Fig_Blue_Branch_Corner",
      "rotation": 1
    },
    {
      "x": 4,
      "y": 0,
      "z": 0,
      "name": "Wood_Fig_Blue_Branch_Long"
    },
    {
      "x": 4,
      "y": 1,
      "z": 0,
      "name": "Wood_Fig_Blue_Branch_Corner",
      "rotation": 11
    }
  ]
}