{
  "version": 8,
  "blockIdVersion": 11,
  "anchorX": 0,
  "anchorY": 5,
  "anchorZ": 0,
  "blocks": [
    {
      "x": -3,
      "y": 5,
      "z": 0,
      "name": "Wood_Poisoned_Trunk_Half",
      "rotation": 7
    },
    {
      "x": -3,
      "y": 5,
      "z": 1,
      "name": "Wood_Poisoned_Trunk_Half",
      "rotation": 7
    },
    {
      "x": -2,
      "y": 6,
      "z": -2,
      "name": "Wood_Poisoned_Trunk_Full",
      "support": 15,
      "rotation": 5
    },
    {
      "x": -2,
      "y": 7,
      "z": -2,
      "name": "Wood_Poisoned_Trunk_Half"
    },
    {
      "x": -2,
      "y": 5,
      "z": -1,
      "name": "Wood_Poisoned_Trunk_Half",
      "rotation": 8
    },
    {
      "x": -2,
      "y": 6,
      "z": -1,
      "name": "Wood_Poisoned_Trunk_Full",
      "support": 15,
      "rotation": 4
    },
    {
      "x": -2,
      "y": 2,
      "z": 0,
      "name": "Plant_Crop_Health3",
      "rotation": 3
    },
    {
      "x": -2,
      "y": 3,
      "z": 0,
      "name": "Plant_Crop_Health3",
      "filler": 1024,
      "rotation": 3
    },
    {
      "x": -2,
      "y": 4,
      "z": 0,
      "name": "Rock_Crystal_Red_Block"
    },
    {
      "x": -2,
      "y": 5,
      "z": 0,
      "name": "Wood_Poisoned_Trunk_Full",
      "support": 15,
      "rotation": 5
    },
    {
      "x": -2,
      "y": 6,
      "z": 0,
      "name": "Wood_Poisoned_Trunk_Half"
    },
    {
      "x": -2,
      "y": 7,
      "z": 0,
      "name": "Plant_Crop_Health3",
      "rotation": 3
    },
    {
      "x": -2,
      "y": 8,
      "z": 0,
      "name": "Plant_Crop_Health3",
      "filler": 1024,
      "rotation": 3
    },
    {
      "x": -2,
      "y": 5,
      "z": 1,
      "name": "Wood_Poisoned_Trunk_Full",
      "support": 15,
      "rotation": 5
    },
    {
      "x": -2,
      "y": 6,
      "z": 1,
      "name": "Wood_Poisoned_Trunk_Half"
    },
    {
      "x": -2,
      "y": 5,
      "z": 2,
      "name": "Wood_Poisoned_Trunk_Full",
      "support": 15,
      "rotation": 4
    },
    {
      "x": -1,
      "y": 6,
      "z": -3,
      "name": "Wood_Poisoned_Trunk_Full",
      "support": 15,
      "rotation": 5
    },
    {
      "x": -1,
      "y": 6,
      "z": -2,
      "name": "Wood_Poisoned_Trunk_Full",
      "support": 15
    },
    {
      "x": -1,
      "y": 7,
      "z": -2,
      "name": "Wood_Poisoned_Trunk_Half"
    },
    {
      "x": -1,
      "y": 2,
      "z": -1,
      "name": "Rock_Crystal_Red_Medium",
      "rotation": 8
    },
    {
      "x": -1,
      "y": 3,
      "z": -1,
      "name": "Rock_Crystal_Red_Block"
    },
    {
      "x": -1,
      "y": 4,
      "z": -1,
      "name": "Rock_Crystal_Red_Block"
    },
    {
      "x": -1,
      "y": 5,
      "z": -1,
      "name": "Rock_Crystal_Red_Block"
    },
    {
      "x": -1,
      "y": 6,
      "z": -1,
      "name": "Rock_Crystal_Red_Block"
    },
    {
      "x": -1,
      "y": 7,
      "z": -1,
      "name": "Rock_Crystal_Red_Block"
    },
    {
      "x": -1,
      "y": 8,
      "z": -1,
      "name": "Rock_Crystal_Red_Small"
    },
    {
      "x": -1,
      "y": 2,
      "z": 0,
      "name": "Rock_Crystal_Red_Block"
    },
    {
      "x": -1,
      "y": 3,
      "z": 0,
      "name": "Rock_Crystal_Red_Block"
    },
    {
      "x": -1,
      "y": 4,
      "z": 0,
      "name": "Rock_Crystal_Red_Block"
    },
    {
      "x": -1,
      "y": 5,
      "z": 0,
      "name": "Rock_Crystal_Red_Block"
    },
    {
      "x": -1,
      "y": 6,
      "z": 0,
      "name": "Rock_Crystal_Red_Block"
    },
    {
      "x": -1,
      "y": 7,
      "z": 0,
      "name": "Rock_Crystal_Red_Block"
    },
    {
      "x": -1,
      "y": 8,
      "z": 0,
      "name": "Rock_Crystal_Red_Block"
    },
    {
      "x": -1,
      "y": 3,
      "z": 1,
      "name": "Rock_Crystal_Red_Block"
    },
    {
      "x": -1,
      "y": 4,
      "z": 1,
      "name": "Rock_Crystal_Red_Block"
    },
    {
      "x": -1,
      "y": 5,
      "z": 1,
      "name": "Rock_Crystal_Red_Block"
    },
    {
      "x": -1,
      "y": 6,
      "z": 1,
      "name": "Rock_Crystal_Red_Block"
    },
    {
      "x": -1,
      "y": 7,
      "z": 1,
      "name": "Rock_Crystal_Red_Block"
    },
    {
      "x": -1,
      "y": 4,
      "z": 2,
      "name": "Wood_Poisoned_Trunk_Half",
      "rotation": 8
    },
    {
      "x": -1,
      "y": 5,
      "z": 2,
      "name": "Wood_Poisoned_Trunk_Full",
      "support": 15,
      "rotation": 4
    },
    {
      "x": -1,
      "y": 6,
      "z": 2,
      "name": "Plant_Crop_Health3"
    },
    {
      "x": -1,
      "y": 7,
      "z": 2,
      "name": "Plant_Crop_Health3",
      "filler": 1024
    },
    {
      "x": -1,
      "y": 5,
      "z": 3,
      "name": "Wood_Poisoned_Trunk_Half",
      "rotation": 4
    },
    {
      "x": 0,
      "y": 6,
      "z": -3,
      "name": "Wood_Poisoned_Trunk_Full",
      "support": 15,
      "rotation": 5
    },
    {
      "x": 0,
      "y": 3,
      "z": -2,
      "name": "Rock_Crystal_Red_Large",
      "rotation": 8
    },
    {
      "x": 0,
      "y": 4,
      "z": -2,
      "name": "Rock_Crystal_Red_Block"
    },
    {
      "x": 0,
      "y": 5,
      "z": -2,
      "name": "Rock_Crystal_Red_Block"
    },
    {
      "x": 0,
      "y": 6,
      "z": -2,
      "name": "Rock_Crystal_Red_Block"
    },
    {
      "x": 0,
      "y": 7,
      "z": -2,
      "name": "Rock_Crystal_Red_Medium"
    },
    {
      "x": 0,
      "y": 1,
      "z": -1,
      "name": "Rock_Crystal_Red_Medium",
      "rotation": 8
    },
    {
      "x": 0,
      "y": 2,
      "z": -1,
      "name": "Rock_Crystal_Red_Block"
    },
    {
      "x": 0,
      "y": 3,
      "z": -1,
      "name": "Rock_Crystal_Red_Block"
    },
    {
      "x": 0,
      "y": 4,
      "z": -1,
      "name": "Rock_Crystal_Red_Block"
    },
    {
      "x": 0,
      "y": 5,
      "z": -1,
      "name": "Rock_Crystal_Red_Block"
    },
    {
      "x": 0,
      "y": 6,
      "z": -1,
      "name": "Rock_Crystal_Red_Block"
    },
    {
      "x": 0,
      "y": 7,
      "z": -1,
      "name": "Rock_Crystal_Red_Block"
    },
    {
      "x": 0,
      "y": 8,
      "z": -1,
      "name": "Rock_Crystal_Red_Block"
    },
    {
      "x": 0,
      "y": 9,
      "z": -1,
      "name": "Rock_Crystal_Red_Medium"
    },
    {
      "x": 0,
      "y": 0,
      "z": 0,
      "name": "Rock_Crystal_Red_Block"
    },
    {
      "x": 0,
      "y": 1,
      "z": 0,
      "name": "Rock_Crystal_Red_Block"
    },
    {
      "x": 0,
      "y": 2,
      "z": 0,
      "name": "Rock_Crystal_Red_Block"
    },
    {
      "x": 0,
      "y": 3,
      "z": 0,
      "name": "Rock_Crystal_Red_Block"
    },
    {
      "x": 0,
      "y": 4,
      "z": 0,
      "name": "Rock_Crystal_Red_Block"
    },
    {
      "x": 0,
      "y": 5,
      "z": 0,
      "name": "Rock_Crystal_Red_Block"
    },
    {
      "x": 0,
      "y": 6,
      "z": 0,
      "name": "Rock_Crystal_Red_Block"
    },
    {
      "x": 0,
      "y": 7,
      "z": 0,
      "name": "Rock_Crystal_Red_Block"
    },
    {
      "x": 0,
      "y": 8,
      "z": 0,
      "name": "Rock_Crystal_Red_Block"
    },
    {
      "x": 0,
      "y": 9,
      "z": 0,
      "name": "Rock_Crystal_Red_Block"
    },
    {
      "x": 0,
      "y": 10,
      "z": 0,
      "name": "Rock_Crystal_Red_Block"
    },
    {
      "x": 0,
      "y": 11,
      "z": 0,
      "name": "Rock_Crystal_Red_Medium"
    },
    {
      "x": 0,
      "y": 0,
      "z": 1,
      "name": "Plant_Crop_Health3"
    },
    {
      "x": 0,
      "y": 1,
      "z": 1,
      "name": "Plant_Crop_Health3",
      "filler": 1024
    },
    {
      "x": 0,
      "y": 2,
      "z": 1,
      "name": "Rock_Crystal_Red_Block"
    },
    {
      "x": 0,
      "y": 3,
      "z": 1,
      "name": "Rock_Crystal_Red_Block"
    },
    {
      "x": 0,
      "y": 4,
      "z": 1,
      "name": "Rock_Crystal_Red_Block"
    },
    {
      "x": 0,
      "y": 5,
      "z": 1,
      "name": "Rock_Crystal_Red_Block"
    },
    {
      "x": 0,
      "y": 6,
      "z": 1,
      "name": "Rock_Crystal_Red_Block"
    },
    {
      "x": 0,
      "y": 7,
      "z": 1,
      "name": "Rock_Crystal_Red_Block"
    },
    {
      "x": 0,
      "y": 8,
      "z": 1,
      "name": "Rock_Crystal_Red_Block"
    },
    {
      "x": 0,
      "y": 9,
      "z": 1,
      "name": "Plant_Crop_Health3"
    },
    {
      "x": 0,
      "y": 10,
      "z": 1,
      "name": "Plant_Crop_Health3",
      "filler": 1024
    },
    {
      "x": 0,
      "y": 3,
      "z": 2,
      "name": "Wood_Poisoned_Trunk_Stairs",
      "rotation": 9
    },
    {
      "x": 0,
      "y": 4,
      "z": 2,
      "name": "Wood_Poisoned_Trunk_Full",
      "support": 15
    },
    {
      "x": 0,
      "y": 5,
      "z": 2,
      "name": "Rock_Crystal_Red_Block"
    },
    {
      "x": 0,
      "y": 6,
      "z": 2,
      "name": "Rock_Crystal_Red_Block"
    },
    {
      "x": 0,
      "y": 7,
      "z": 2,
      "name": "Rock_Crystal_Red_Small"
    },
    {
      "x": 0,
      "y": 4,
      "z": 3,
      "name": "Wood_Poisoned_Trunk_Half",
      "rotation": 4
    },
    {
      "x": 0,
      "y": 5,
      "z": 3,
      "name": "Wood_Poisoned_Trunk_Half",
      "rotation": 4
    },
    {
      "x": 0,
      "y": 7,
      "z": 3,
      "name": "Wood_Poisoned_Trunk_Full",
      "support": 15,
      "rotation": 5
    },
    {
      "x": 0,
      "y": 8,
      "z": 3,
      "name": "Wood_Poisoned_Trunk_Full",
      "support": 15
    },
    {
      "x": 0,
      "y": 9,
      "z": 3,
      "name": "Wood_Poisoned_Trunk_Half",
      "rotation": 6
    },
    {
      "x": 0,
      "y": 9,
      "z": 4,
      "name": "Wood_Poisoned_Trunk_Stairs",
      "rotation": 10
    },
    {
      "x": 0,
      "y": 10,
      "z": 4,
      "name": "Wood_Poisoned_Trunk_Half"
    },
    {
      "x": 0,
      "y": 6,
      "z": 5,
      "name": "Wood_Poisoned_Branch_Corner",
      "support": 15,
      "rotation": 2
    },
    {
      "x": 0,
      "y": 7,
      "z": 5,
      "name": "Wood_Poisoned_Branch_Corner",
      "support": 15,
      "rotation": 9
    },
    {
      "x": 0,
      "y": 10,
      "z": 5,
      "name": "Wood_Poisoned_Trunk_Full",
      "support": 15,
      "rotation": 4
    },
    {
      "x": 0,
      "y": 6,
      "z": 6,
      "name": "Wood_Poisoned_Branch_Corner",
      "support": 15
    },
    {
      "x": 0,
      "y": 7,
      "z": 6,
      "name": "Wood_Poisoned_Branch_Corner",
      "support": 15,
      "rotation": 8
    },
    {
      "x": 0,
      "y": 10,
      "z": 6,
      "name": "Wood_Poisoned_Trunk_Full",
      "support": 15,
      "rotation": 4
    },
    {
      "x": 0,
      "y": 7,
      "z": 7,
      "name": "Wood_Poisoned_Branch_Corner",
      "support": 15
    },
    {
      "x": 0,
      "y": 8,
      "z": 7,
      "name": "Wood_Poisoned_Branch_Long",
      "support": 15
    },
    {
      "x": 0,
      "y": 9,
      "z": 7,
      "name": "Wood_Poisoned_Trunk_Full",
      "support": 15
    },
    {
      "x": 0,
      "y": 10,
      "z": 7,
      "name": "Wood_Poisoned_Trunk_Stairs"
    },
    {
      "x": 1,
      "y": 5,
      "z": -3,
      "name": "Wood_Poisoned_Trunk_Half",
      "rotation": 8
    },
    {
      "x": 1,
      "y": 6,
      "z": -3,
      "name": "Wood_Poisoned_Trunk_Full",
      "support": 15,
      "rotation": 5
    },
    {
      "x": 1,
      "y": 5,
      "z": -2,
      "name": "Wood_Poisoned_Trunk_Full",
      "support": 15,
      "rotation": 5
    },
    {
      "x": 1,
      "y": 6,
      "z": -2,
      "name": "Wood_Poisoned_Trunk_Half"
    },
    {
      "x": 1,
      "y": 2,
      "z": -1,
      "name": "Rock_Crystal_Red_Small",
      "rotation": 8
    },
    {
      "x": 1,
      "y": 3,
      "z": -1,
      "name": "Rock_Crystal_Red_Block"
    },
    {
      "x": 1,
      "y": 4,
      "z": -1,
      "name": "Rock_Crystal_Red_Block"
    },
    {
      "x": 1,
      "y": 5,
      "z": -1,
      "name": "Rock_Crystal_Red_Block"
    },
    {
      "x": 1,
      "y": 6,
      "z": -1,
      "name": "Rock_Crystal_Red_Block"
    },
    {
      "x": 1,
      "y": 7,
      "z": -1,
      "name": "Rock_Crystal_Red_Block"
    },
    {
      "x": 1,
      "y": 8,
      "z": -1,
      "name": "Rock_Crystal_Red_Small",
      "rotation": 6
    },
    {
      "x": 1,
      "y": 2,
      "z": 0,
      "name": "Rock_Crystal_Red_Block"
    },
    {
      "x": 1,
      "y": 3,
      "z": 0,
      "name": "Rock_Crystal_Red_Block"
    },
    {
      "x": 1,
      "y": 4,
      "z": 0,
      "name": "Rock_Crystal_Red_Block"
    },
    {
      "x": 1,
      "y": 5,
      "z": 0,
      "name": "Rock_Crystal_Red_Block"
    },
    {
      "x": 1,
      "y": 6,
      "z": 0,
      "name": "Rock_Crystal_Red_Block"
    },
    {
      "x": 1,
      "y": 7,
      "z": 0,
      "name": "Rock_Crystal_Red_Block"
    },
    {
      "x": 1,
      "y": 8,
      "z": 0,
      "name": "Rock_Crystal_Red_Block"
    },
    {
      "x": 1,
      "y": 3,
      "z": 1,
      "name": "Rock_Crystal_Red_Block"
    },
    {
      "x": 1,
      "y": 4,
      "z": 1,
      "name": "Rock_Crystal_Red_Block"
    },
    {
      "x": 1,
      "y": 5,
      "z": 1,
      "name": "Rock_Crystal_Red_Block"
    },
    {
      "x": 1,
      "y": 6,
      "z": 1,
      "name": "Rock_Crystal_Red_Block"
    },
    {
      "x": 1,
      "y": 7,
      "z": 1,
      "name": "Rock_Crystal_Red_Block"
    },
    {
      "x": 1,
      "y": 1,
      "z": 2,
      "name": "Wood_Poisoned_Branch_Corner",
      "support": 15,
      "rotation": 3
    },
    {
      "x": 1,
      "y": 3,
      "z": 2,
      "name": "Wood_Poisoned_Trunk_Full",
      "support": 15
    },
    {
      "x": 1,
      "y": 4,
      "z": 2,
      "name": "Wood_Poisoned_Trunk_Full",
      "support": 15,
      "rotation": 5
    },
    {
      "x": 1,
      "y": 5,
      "z": 2,
      "name": "Wood_Poisoned_Trunk_Full",
      "support": 15,
      "rotation": 4
    },
    {
      "x": 1,
      "y": 6,
      "z": 2,
      "name": "Wood_Poisoned_Trunk_Full",
      "support": 15,
      "rotation": 4
    },
    {
      "x": 1,
      "y": 7,
      "z": 2,
      "name": "Wood_Poisoned_Trunk_Full",
      "support": 15
    },
    {
      "x": 1,
      "y": 6,
      "z": 3,
      "name": "Wood_Poisoned_Trunk_Full",
      "support": 15,
      "rotation": 4
    },
    {
      "x": 1,
      "y": 7,
      "z": 3,
      "name": "Wood_Poisoned_Trunk_Full",
      "support": 15,
      "rotation": 4
    },
    {
      "x": 2,
      "y": 5,
      "z": -2,
      "name": "Wood_Poisoned_Trunk_Full",
      "support": 15,
      "rotation": 5
    },
    {
      "x": 2,
      "y": 3,
      "z": -1,
      "name": "Plant_Crop_Health3",
      "rotation": 1
    },
    {
      "x": 2,
      "y": 4,
      "z": -1,
      "name": "Plant_Crop_Health3",
      "filler": 1024,
      "rotation": 1
    },
    {
      "x": 2,
      "y": 5,
      "z": -1,
      "name": "Wood_Poisoned_Trunk_Full",
      "support": 15,
      "rotation": 5
    },
    {
      "x": 2,
      "y": 6,
      "z": -1,
      "name": "Plant_Crop_Health3",
      "rotation": 1
    },
    {
      "x": 2,
      "y": 7,
      "z": -1,
      "name": "Plant_Crop_Health3",
      "filler": 1024,
      "rotation": 1
    },
    {
      "x": 2,
      "y": 3,
      "z": 0,
      "name": "Rock_Crystal_Red_Medium",
      "rotation": 8
    },
    {
      "x": 2,
      "y": 4,
      "z": 0,
      "name": "Rock_Crystal_Red_Block"
    },
    {
      "x": 2,
      "y": 5,
      "z": 0,
      "name": "Rock_Crystal_Red_Block"
    },
    {
      "x": 2,
      "y": 6,
      "z": 0,
      "name": "Rock_Crystal_Red_Block"
    },
    {
      "x": 2,
      "y": 7,
      "z": 0,
      "name": "Rock_Crystal_Red_Medium",
      "rotation": 5
    },
    {
      "x": 2,
      "y": 5,
      "z": 1,
      "name": "Wood_Poisoned_Trunk_Full",
      "support": 15,
      "rotation": 5
    },
    {
      "x": 2,
      "y": 6,
      "z": 1,
      "name": "Wood_Poisoned_Trunk_Full",
      "support": 15,
      "rotation": 5
    },
    {
      "x": 2,
      "y": 1,
      "z": 2,
      "name": "Wood_Poisoned_Branch_Corner",
      "support": 15,
      "rotation": 1
    },
    {
      "x": 2,
      "y": 2,
      "z": 2,
      "name": "Wood_Poisoned_Trunk_Full",
      "support": 15
    },
    {
      "x": 2,
      "y": 3,
      "z": 2,
      "name": "Wood_Poisoned_Trunk_Stairs",
      "rotation": 1
    },
    {
      "x": 2,
      "y": 5,
      "z": 2,
      "name": "Wood_Poisoned_Trunk_Half",
      "rotation": 8
    },
    {
      "x": 2,
      "y": 6,
      "z": 2,
      "name": "Wood_Poisoned_Trunk_Full",
      "support": 15,
      "rotation": 5
    },
    {
      "x": 2,
      "y": 7,
      "z": 2,
      "name": "Wood_Poisoned_Trunk_Half"
    },
    {
      "x": 3,
      "y": 5,
      "z": -1,
      "name": "Wood_Poisoned_Trunk_Full",
      "support": 15,
      "rotation": 4
    },
    {
      "x": 3,
      "y": 5,
      "z": 0,
      "name": "Wood_Poisoned_Trunk_Full",
      "support": 15,
      "rotation": 4
    },
    {
      "x": 3,
      "y": 5,
      "z": 1,
      "name": "Wood_Poisoned_Trunk_Full",
      "support": 15,
      "rotation": 4
    }
  ]
}