{
  "version": 8,
  "blockIdVersion": 11,
  "anchorX": 0,
  "anchorY": 4,
  "anchorZ": 0,
  "blocks": [
    {
      "x": -5,
      "y": 1,
      "z": 0,
      "name": "Wood_Poisoned_Trunk_Stairs",
      "rotation": 8
    },
    {
      "x": -5,
      "y": 2,
      "z": 0,
      "name": "Wood_Poisoned_Trunk_Full",
      "support": 15
    },
    {
      "x": -5,
      "y": 3,
      "z": 0,
      "name": "Wood_Poisoned_Trunk_Half",
      "rotation": 7
    },
    {
      "x": -5,
      "y": 1,
      "z": 1,
      "name": "Wood_Poisoned_Trunk_Full",
      "support": 15,
      "rotation": 4
    },
    {
      "x": -5,
      "y": 1,
      "z": 2,
      "name": "Wood_Poisoned_Trunk_Full",
      "support": 15,
      "rotation": 4
    },
    {
      "x": -4,
      "y": 3,
      "z": 0,
      "name": "Wood_Poisoned_Trunk_Stairs",
      "rotation": 11
    },
    {
      "x": -4,
      "y": 4,
      "z": 0,
      "name": "Wood_Poisoned_Trunk_Half"
    },
    {
      "x": -4,
      "y": 1,
      "z": 2,
      "name": "Wood_Poisoned_Trunk_Full",
      "support": 15,
      "rotation": 5
    },
    {
      "x": -4,
      "y": 7,
      "z": 3,
      "name": "Rock_Crystal_Red_Small",
      "rotation": 7
    },
    {
      "x": -4,
      "y": 8,
      "z": 3,
      "name": "Rock_Crystal_Red_Small",
      "rotation": 6
    },
    {
      "x": -4,
      "y": 7,
      "z": 4,
      "name": "Rock_Crystal_Red_Small",
      "rotation": 8
    },
    {
      "x": -4,
      "y": 8,
      "z": 4,
      "name": "Rock_Crystal_Red_Block",
      "rotation": 4
    },
    {
      "x": -3,
      "y": 1,
      "z": -1,
      "name": "Wood_Poisoned_Branch_Corner",
      "support": 15,
      "rotation": 3
    },
    {
      "x": -3,
      "y": 4,
      "z": 0,
      "name": "Wood_Poisoned_Trunk_Full",
      "support": 15,
      "rotation": 5
    },
    {
      "x": -3,
      "y": 4,
      "z": 1,
      "name": "Wood_Poisoned_Trunk_Half",
      "rotation": 7
    },
    {
      "x": -3,
      "y": 5,
      "z": 1,
      "name": "Rock_Crystal_Red_Medium",
      "rotation": 7
    },
    {
      "x": -3,
      "y": 1,
      "z": 2,
      "name": "Wood_Poisoned_Branch_Long",
      "support": 15,
      "rotation": 5
    },
    {
      "x": -3,
      "y": 6,
      "z": 2,
      "name": "Rock_Crystal_Red_Block",
      "rotation": 5
    },
    {
      "x": -3,
      "y": 6,
      "z": 3,
      "name": "Rock_Crystal_Red_Medium",
      "rotation": 8
    },
    {
      "x": -3,
      "y": 7,
      "z": 3,
      "name": "Rock_Crystal_Red_Block",
      "rotation": 4
    },
    {
      "x": -3,
      "y": 8,
      "z": 3,
      "name": "Rock_Crystal_Red_Small"
    },
    {
      "x": -3,
      "y": 7,
      "z": 4,
      "name": "Rock_Crystal_Red_Small",
      "rotation": 4
    },
    {
      "x": -3,
      "y": 8,
      "z": 4,
      "name": "Rock_Crystal_Red_Small",
      "rotation": 5
    },
    {
      "x": -2,
      "y": 1,
      "z": -1,
      "name": "Wood_Poisoned_Branch_Corner",
      "support": 15,
      "rotation": 1
    },
    {
      "x": -2,
      "y": 2,
      "z": -1,
      "name": "Wood_Poisoned_Branch_Corner",
      "support": 15,
      "rotation": 8
    },
    {
      "x": -2,
      "y": 3,
      "z": -1,
      "name": "Wood_Poisoned_Trunk_Half",
      "rotation": 8
    },
    {
      "x": -2,
      "y": 4,
      "z": -1,
      "name": "Wood_Poisoned_Trunk_Full",
      "support": 15,
      "rotation": 5
    },
    {
      "x": -2,
      "y": 2,
      "z": 0,
      "name": "Wood_Poisoned_Branch_Long",
      "support": 15,
      "rotation": 4
    },
    {
      "x": -2,
      "y": 4,
      "z": 0,
      "name": "Wood_Poisoned_Trunk_Full",
      "support": 15,
      "rotation": 5
    },
    {
      "x": -2,
      "y": 5,
      "z": 0,
      "name": "Rock_Crystal_Red_Block",
      "rotation": 5
    },
    {
      "x": -2,
      "y": 2,
      "z": 1,
      "name": "Wood_Poisoned_Branch_Corner",
      "support": 15
    },
    {
      "x": -2,
      "y": 3,
      "z": 1,
      "name": "Wood_Poisoned_Branch_Corner",
      "support": 15,
      "rotation": 8
    },
    {
      "x": -2,
      "y": 4,
      "z": 1,
      "name": "Wood_Poisoned_Trunk_Full",
      "support": 15,
      "rotation": 5
    },
    {
      "x": -2,
      "y": 5,
      "z": 1,
      "name": "Rock_Crystal_Red_Block",
      "rotation": 5
    },
    {
      "x": -2,
      "y": 6,
      "z": 1,
      "name": "Rock_Crystal_Red_Block",
      "rotation": 4
    },
    {
      "x": -2,
      "y": 1,
      "z": 2,
      "name": "Wood_Poisoned_Branch_Corner",
      "support": 15,
      "rotation": 1
    },
    {
      "x": -2,
      "y": 2,
      "z": 2,
      "name": "Wood_Poisoned_Branch_Long",
      "support": 15
    },
    {
      "x": -2,
      "y": 3,
      "z": 2,
      "name": "Wood_Poisoned_Branch_Corner",
      "support": 15,
      "rotation": 10
    },
    {
      "x": -2,
      "y": 4,
      "z": 2,
      "name": "Rock_Crystal_Red_Medium",
      "rotation": 8
    },
    {
      "x": -2,
      "y": 5,
      "z": 2,
      "name": "Rock_Crystal_Red_Block"
    },
    {
      "x": -2,
      "y": 6,
      "z": 2,
      "name": "Rock_Crystal_Red_Block"
    },
    {
      "x": -2,
      "y": 7,
      "z": 2,
      "name": "Rock_Crystal_Red_Block"
    },
    {
      "x": -2,
      "y": 6,
      "z": 3,
      "name": "Rock_Crystal_Red_Block",
      "rotation": 4
    },
    {
      "x": -1,
      "y": 4,
      "z": -3,
      "name": "Wood_Poisoned_Trunk_Half",
      "rotation": 6
    },
    {
      "x": -1,
      "y": 3,
      "z": -2,
      "name": "Wood_Poisoned_Trunk_Half",
      "rotation": 8
    },
    {
      "x": -1,
      "y": 4,
      "z": -2,
      "name": "Wood_Poisoned_Trunk_Full",
      "support": 15,
      "rotation": 4
    },
    {
      "x": -1,
      "y": 3,
      "z": -1,
      "name": "Rock_Crystal_Red_Block",
      "rotation": 5
    },
    {
      "x": -1,
      "y": 4,
      "z": -1,
      "name": "Rock_Crystal_Red_Block",
      "rotation": 5
    },
    {
      "x": -1,
      "y": 5,
      "z": -1,
      "name": "Rock_Crystal_Red_Block",
      "rotation": 4
    },
    {
      "x": -1,
      "y": 3,
      "z": 0,
      "name": "Rock_Crystal_Red_Block",
      "rotation": 5
    },
    {
      "x": -1,
      "y": 4,
      "z": 0,
      "name": "Rock_Crystal_Red_Block",
      "rotation": 5
    },
    {
      "x": -1,
      "y": 5,
      "z": 0,
      "name": "Rock_Crystal_Red_Block",
      "rotation": 4
    },
    {
      "x": -1,
      "y": 6,
      "z": 0,
      "name": "Rock_Crystal_Red_Block"
    },
    {
      "x": -1,
      "y": 3,
      "z": 1,
      "name": "Rock_Crystal_Red_Block"
    },
    {
      "x": -1,
      "y": 4,
      "z": 1,
      "name": "Rock_Crystal_Red_Block",
      "rotation": 4
    },
    {
      "x": -1,
      "y": 5,
      "z": 1,
      "name": "Rock_Crystal_Red_Block",
      "rotation": 5
    },
    {
      "x": -1,
      "y": 6,
      "z": 1,
      "name": "Rock_Crystal_Red_Block"
    },
    {
      "x": -1,
      "y": 4,
      "z": 2,
      "name": "Wood_Poisoned_Trunk_Full",
      "support": 15,
      "rotation": 4
    },
    {
      "x": -1,
      "y": 5,
      "z": 2,
      "name": "Rock_Crystal_Red_Block",
      "rotation": 4
    },
    {
      "x": -1,
      "y": 6,
      "z": 2,
      "name": "Rock_Crystal_Red_Block",
      "rotation": 5
    },
    {
      "x": 0,
      "y": 4,
      "z": -3,
      "name": "Wood_Poisoned_Trunk_Half",
      "rotation": 6
    },
    {
      "x": 0,
      "y": 7,
      "z": -3,
      "name": "Wood_Poisoned_Branch_Corner",
      "support": 15,
      "rotation": 3
    },
    {
      "x": 0,
      "y": 8,
      "z": -3,
      "name": "Wood_Poisoned_Branch_Corner",
      "support": 15,
      "rotation": 9
    },
    {
      "x": 0,
      "y": 2,
      "z": -2,
      "name": "Rock_Crystal_Red_Small",
      "rotation": 7
    },
    {
      "x": 0,
      "y": 3,
      "z": -2,
      "name": "Rock_Crystal_Red_Block",
      "rotation": 5
    },
    {
      "x": 0,
      "y": 4,
      "z": -2,
      "name": "Wood_Poisoned_Trunk_Full",
      "support": 15,
      "rotation": 4
    },
    {
      "x": 0,
      "y": 5,
      "z": -2,
      "name": "Wood_Poisoned_Trunk_Half"
    },
    {
      "x": 0,
      "y": 2,
      "z": -1,
      "name": "Rock_Crystal_Red_Block",
      "rotation": 5
    },
    {
      "x": 0,
      "y": 3,
      "z": -1,
      "name": "Rock_Crystal_Red_Block",
      "rotation": 5
    },
    {
      "x": 0,
      "y": 4,
      "z": -1,
      "name": "Rock_Crystal_Red_Block",
      "rotation": 4
    },
    {
      "x": 0,
      "y": 5,
      "z": -1,
      "name": "Rock_Crystal_Red_Block",
      "rotation": 4
    },
    {
      "x": 0,
      "y": 3,
      "z": 0,
      "name": "Rock_Crystal_Red_Block"
    },
    {
      "x": 0,
      "y": 4,
      "z": 0,
      "name": "Rock_Crystal_Red_Block",
      "rotation": 5
    },
    {
      "x": 0,
      "y": 5,
      "z": 0,
      "name": "Rock_Crystal_Red_Block"
    },
    {
      "x": 0,
      "y": 6,
      "z": 0,
      "name": "Rock_Crystal_Red_Medium",
      "rotation": 5
    },
    {
      "x": 0,
      "y": 3,
      "z": 1,
      "name": "Rock_Crystal_Red_Block",
      "rotation": 4
    },
    {
      "x": 0,
      "y": 4,
      "z": 1,
      "name": "Rock_Crystal_Red_Block",
      "rotation": 4
    },
    {
      "x": 0,
      "y": 5,
      "z": 1,
      "name": "Rock_Crystal_Red_Block",
      "rotation": 5
    },
    {
      "x": 0,
      "y": 6,
      "z": 1,
      "name": "Rock_Crystal_Red_Block"
    },
    {
      "x": 0,
      "y": 4,
      "z": 2,
      "name": "Wood_Poisoned_Trunk_Full",
      "support": 15,
      "rotation": 4
    },
    {
      "x": 0,
      "y": 5,
      "z": 2,
      "name": "Plant_Crop_Health3"
    },
    {
      "x": 0,
      "y": 6,
      "z": 2,
      "name": "Plant_Crop_Health3",
      "filler": 1024
    },
    {
      "x": 1,
      "y": 3,
      "z": -3,
      "name": "Rock_Crystal_Red_Medium",
      "rotation": 6
    },
    {
      "x": 1,
      "y": 8,
      "z": -3,
      "name": "Wood_Poisoned_Branch_Long",
      "support": 15,
      "rotation": 5
    },
    {
      "x": 1,
      "y": 2,
      "z": -2,
      "name": "Rock_Crystal_Red_Block",
      "rotation": 5
    },
    {
      "x": 1,
      "y": 3,
      "z": -2,
      "name": "Rock_Crystal_Red_Block",
      "rotation": 4
    },
    {
      "x": 1,
      "y": 4,
      "z": -2,
      "name": "Wood_Poisoned_Trunk_Full",
      "support": 15,
      "rotation": 4
    },
    {
      "x": 1,
      "y": 5,
      "z": -2,
      "name": "Wood_Poisoned_Trunk_Half"
    },
    {
      "x": 1,
      "y": 2,
      "z": -1,
      "name": "Rock_Crystal_Red_Block"
    },
    {
      "x": 1,
      "y": 3,
      "z": -1,
      "name": "Rock_Crystal_Red_Block",
      "rotation": 4
    },
    {
      "x": 1,
      "y": 4,
      "z": -1,
      "name": "Rock_Crystal_Red_Block"
    },
    {
      "x": 1,
      "y": 5,
      "z": -1,
      "name": "Rock_Crystal_Red_Block"
    },
    {
      "x": 1,
      "y": 2,
      "z": 0,
      "name": "Rock_Crystal_Red_Block",
      "rotation": 5
    },
    {
      "x": 1,
      "y": 3,
      "z": 0,
      "name": "Rock_Crystal_Red_Block",
      "rotation": 4
    },
    {
      "x": 1,
      "y": 4,
      "z": 0,
      "name": "Rock_Crystal_Red_Block",
      "rotation": 5
    },
    {
      "x": 1,
      "y": 5,
      "z": 0,
      "name": "Rock_Crystal_Red_Block",
      "rotation": 5
    },
    {
      "x": 1,
      "y": 3,
      "z": 1,
      "name": "Rock_Crystal_Red_Block",
      "rotation": 4
    },
    {
      "x": 1,
      "y": 4,
      "z": 1,
      "name": "Rock_Crystal_Red_Block",
      "rotation": 4
    },
    {
      "x": 1,
      "y": 5,
      "z": 1,
      "name": "Rock_Crystal_Red_Block",
      "rotation": 5
    },
    {
      "x": 1,
      "y": 4,
      "z": 2,
      "name": "Wood_Poisoned_Trunk_Full",
      "support": 15,
      "rotation": 4
    },
    {
      "x": 2,
      "y": 1,
      "z": -3,
      "name": "Rock_Crystal_Red_Small",
      "rotation": 7
    },
    {
      "x": 2,
      "y": 2,
      "z": -3,
      "name": "Rock_Crystal_Red_Block",
      "rotation": 4
    },
    {
      "x": 2,
      "y": 3,
      "z": -3,
      "name": "Plant_Crop_Health3",
      "rotation": 2
    },
    {
      "x": 2,
      "y": 4,
      "z": -3,
      "name": "Plant_Crop_Health3",
      "filler": 1024,
      "rotation": 2
    },
    {
      "x": 2,
      "y": 7,
      "z": -3,
      "name": "Wood_Poisoned_Branch_Corner",
      "support": 15,
      "rotation": 2
    },
    {
      "x": 2,
      "y": 8,
      "z": -3,
      "name": "Wood_Poisoned_Branch_Corner",
      "support": 15,
      "rotation": 11
    },
    {
      "x": 2,
      "y": 1,
      "z": -2,
      "name": "Rock_Crystal_Red_Block"
    },
    {
      "x": 2,
      "y": 2,
      "z": -2,
      "name": "Rock_Crystal_Red_Block",
      "rotation": 4
    },
    {
      "x": 2,
      "y": 3,
      "z": -2,
      "name": "Rock_Crystal_Red_Block"
    },
    {
      "x": 2,
      "y": 4,
      "z": -2,
      "name": "Wood_Poisoned_Trunk_Full",
      "support": 15,
      "rotation": 5
    },
    {
      "x": 2,
      "y": 7,
      "z": -2,
      "name": "Wood_Poisoned_Branch_Long",
      "support": 15,
      "rotation": 4
    },
    {
      "x": 2,
      "y": 2,
      "z": -1,
      "name": "Rock_Crystal_Red_Block",
      "rotation": 4
    },
    {
      "x": 2,
      "y": 3,
      "z": -1,
      "name": "Rock_Crystal_Red_Block",
      "rotation": 5
    },
    {
      "x": 2,
      "y": 4,
      "z": -1,
      "name": "Wood_Poisoned_Trunk_Full",
      "support": 15,
      "rotation": 5
    },
    {
      "x": 2,
      "y": 5,
      "z": -1,
      "name": "Wood_Poisoned_Trunk_Half"
    },
    {
      "x": 2,
      "y": 7,
      "z": -1,
      "name": "Wood_Poisoned_Branch_Corner",
      "support": 15
    },
    {
      "x": 2,
      "y": 8,
      "z": -1,
      "name": "Wood_Poisoned_Branch_Long",
      "support": 15
    },
    {
      "x": 2,
      "y": 9,
      "z": -1,
      "name": "Wood_Poisoned_Trunk_Full",
      "support": 15
    },
    {
      "x": 2,
      "y": 10,
      "z": -1,
      "name": "Wood_Poisoned_Trunk_Half"
    },
    {
      "x": 2,
      "y": 3,
      "z": 0,
      "name": "Rock_Crystal_Red_Block",
      "rotation": 5
    },
    {
      "x": 2,
      "y": 4,
      "z": 0,
      "name": "Wood_Poisoned_Trunk_Full",
      "support": 15,
      "rotation": 5
    },
    {
      "x": 2,
      "y": 5,
      "z": 0,
      "name": "Wood_Poisoned_Trunk_Full",
      "support": 15
    },
    {
      "x": 2,
      "y": 10,
      "z": 0,
      "name": "Wood_Poisoned_Trunk_Full",
      "support": 15,
      "rotation": 4
    },
    {
      "x": 2,
      "y": 4,
      "z": 1,
      "name": "Wood_Poisoned_Trunk_Full",
      "support": 15,
      "rotation": 5
    },
    {
      "x": 2,
      "y": 5,
      "z": 1,
      "name": "Wood_Poisoned_Trunk_Full",
      "support": 15
    },
    {
      "x": 2,
      "y": 6,
      "z": 1,
      "name": "Wood_Poisoned_Trunk_Half"
    },
    {
      "x": 2,
      "y": 9,
      "z": 1,
      "name": "Wood_Poisoned_Trunk_Half",
      "rotation": 8
    },
    {
      "x": 2,
      "y": 10,
      "z": 1,
      "name": "Wood_Poisoned_Trunk_Full",
      "support": 15,
      "rotation": 4
    },
    {
      "x": 2,
      "y": 5,
      "z": 2,
      "name": "Wood_Poisoned_Trunk_Half",
      "rotation": 8
    },
    {
      "x": 2,
      "y": 6,
      "z": 2,
      "name": "Wood_Poisoned_Trunk_Stairs",
      "rotation": 2
    },
    {
      "x": 2,
      "y": 8,
      "z": 2,
      "name": "Wood_Poisoned_Trunk_Half",
      "rotation": 6
    },
    {
      "x": 2,
      "y": 9,
      "z": 2,
      "name": "Wood_Poisoned_Trunk_Full",
      "support": 15
    },
    {
      "x": 2,
      "y": 10,
      "z": 2,
      "name": "Wood_Poisoned_Trunk_Stairs"
    },
    {
      "x": 2,
      "y": 6,
      "z": 3,
      "name": "Wood_Poisoned_Trunk_Half",
      "rotation": 4
    },
    {
      "x": 2,
      "y": 7,
      "z": 3,
      "name": "Wood_Poisoned_Trunk_Full",
      "support": 15
    },
    {
      "x": 2,
      "y": 8,
      "z": 3,
      "name": "Wood_Poisoned_Trunk_Full",
      "support": 15
    },
    {
      "x": 2,
      "y": 9,
      "z": 3,
      "name": "Wood_Poisoned_Trunk_Stairs"
    },
    {
      "x": 3,
      "y": 0,
      "z": -4,
      "name": "Rock_Crystal_Red_Small",
      "rotation": 7
    },
    {
      "x": 3,
      "y": 1,
      "z": -4,
      "name": "Rock_Crystal_Red_Medium",
      "rotation": 6
    },
    {
      "x": 3,
      "y": 0,
      "z": -3,
      "name": "Rock_Crystal_Red_Medium",
      "rotation": 8
    },
    {
      "x": 3,
      "y": 1,
      "z": -3,
      "name": "Rock_Crystal_Red_Block"
    },
    {
      "x": 3,
      "y": 2,
      "z": -2,
      "name": "Rock_Crystal_Red_Block",
      "rotation": 5
    },
    {
      "x": 3,
      "y": 3,
      "z": -2,
      "name": "Plant_Crop_Health3",
      "rotation": 1
    },
    {
      "x": 3,
      "y": 4,
      "z": -2,
      "name": "Plant_Crop_Health3",
      "filler": 1024,
      "rotation": 1
    },
    {
      "x": 3,
      "y": 2,
      "z": -1,
      "name": "Plant_Crop_Health3",
      "rotation": 1
    },
    {
      "x": 3,
      "y": 3,
      "z": -1,
      "name": "Plant_Crop_Health3",
      "filler": 1024,
      "rotation": 1
    },
    {
      "x": 3,
      "y": 4,
      "z": -1,
      "name": "Wood_Poisoned_Trunk_Half",
      "rotation": 5
    },
    {
      "x": 3,
      "y": 4,
      "z": 0,
      "name": "Wood_Poisoned_Trunk_Half",
      "rotation": 5
    },
    {
      "x": 3,
      "y": 5,
      "z": 0,
      "name": "Wood_Poisoned_Trunk_Half",
      "rotation": 5
    },
    {
      "x": 3,
      "y": 5,
      "z": 1,
      "name": "Wood_Poisoned_Trunk_Half",
      "rotation": 5
    },
    {
      "x": 3,
      "y": 7,
      "z": 3,
      "name": "Plant_Crop_Health3",
      "rotation": 1
    },
    {
      "x": 3,
      "y": 8,
      "z": 3,
      "name": "Plant_Crop_Health3",
      "filler": 1024,
      "rotation": 1
    },
    {
      "x": 4,
      "y": 0,
      "z": -4,
      "name": "Rock_Crystal_Red_Block"
    },
    {
      "x": 4,
      "y": 1,
      "z": -4,
      "name": "Rock_Crystal_Red_Small"
    },
    {
      "x": 4,
      "y": 0,
      "z": -3,
      "name": "Rock_Crystal_Red_Small",
      "rotation": 4
    },
    {
      "x": 4,
      "y": 1,
      "z": -3,
      "name": "Rock_Crystal_Red_Medium",
      "rotation": 5
    }
  ]
}