{
  "version": 8,
  "blockIdVersion": 11,
  "anchorX": 0,
  "anchorY": 0,
  "anchorZ": 0,
  "blocks": [
    {
      "x": -8,
      "y": 0,
      "z": -2,
      "name": "Rock_Aqua"
    },
    {
      "x": -8,
      "y": 0,
      "z": -1,
      "name": "Rock_Aqua"
    },
    {
      "x": -8,
      "y": -1,
      "z": 0,
      "name": "Rock_Basalt"
    },
    {
      "x": -8,
      "y": 0,
      "z": 0,
      "name": "Rock_Basalt"
    },
    {
      "x": -8,
      "y": 0,
      "z": 1,
      "name": "Rock_Basalt"
    },
    {
      "x": -8,
      "y": 0,
      "z": 2,
      "name": "Rock_Aqua"
    },
    {
      "x": -7,
      "y": 0,
      "z": -4,
      "name": "Rock_Aqua"
    },
    {
      "x": -7,
      "y": -1,
      "z": -3,
      "name": "Rock_Aqua"
    },
    {
      "x": -7,
      "y": 0,
      "z": -3,
      "name": "Rock_Aqua"
    },
    {
      "x": -7,
      "y": -1,
      "z": -2,
      "name": "Rock_Aqua"
    },
    {
      "x": -7,
      "y": 0,
      "z": -2,
      "name": "Rock_Aqua"
    },
    {
      "x": -7,
      "y": -1,
      "z": -1,
      "name": "Rock_Aqua"
    },
    {
      "x": -7,
      "y": -1,
      "z": 0,
      "name": "Rock_Basalt"
    },
    {
      "x": -7,
      "y": -1,
      "z": 1,
      "name": "Rock_Aqua"
    },
    {
      "x": -7,
      "y": -1,
      "z": 2,
      "name": "Rock_Aqua"
    },
    {
      "x": -7,
      "y": 0,
      "z": 2,
      "name": "Rock_Aqua"
    },
    {
      "x": -6,
      "y": -1,
      "z": -5,
      "name": "Rock_Aqua"
    },
    {
      "x": -6,
      "y": 0,
      "z": -5,
      "name": "Rock_Aqua"
    },
    {
      "x": -6,
      "y": -1,
      "z": -4,
      "name": "Rock_Aqua"
    },
    {
      "x": -6,
      "y": 0,
      "z": -4,
      "name": "Rock_Aqua"
    },
    {
      "x": -6,
      "y": -2,
      "z": -3,
      "name": "Rock_Aqua"
    },
    {
      "x": -6,
      "y": -1,
      "z": -3,
      "name": "Rock_Aqua"
    },
    {
      "x": -6,
      "y": -2,
      "z": -2,
      "name": "Rock_Basalt"
    },
    {
      "x": -6,
      "y": -1,
      "z": -2,
      "name": "Rock_Aqua"
    },
    {
      "x": -6,
      "y": -2,
      "z": -1,
      "name": "Rock_Aqua"
    },
    {
      "x": -6,
      "y": -2,
      "z": 0,
      "name": "Rock_Aqua"
    },
    {
      "x": -6,
      "y": -2,
      "z": 1,
      "name": "Rock_Aqua"
    },
    {
      "x": -6,
      "y": -2,
      "z": 2,
      "name": "Rock_Aqua"
    },
    {
      "x": -6,
      "y": -1,
      "z": 2,
      "name": "Rock_Aqua"
    },
    {
      "x": -6,
      "y": -2,
      "z": 3,
      "name": "Rock_Aqua"
    },
    {
      "x": -6,
      "y": -1,
      "z": 3,
      "name": "Rock_Aqua"
    },
    {
      "x": -6,
      "y": -1,
      "z": 4,
      "name": "Rock_Aqua"
    },
    {
      "x": -6,
      "y": -1,
      "z": 5,
      "name": "Rock_Aqua"
    },
    {
      "x": -6,
      "y": 0,
      "z": 5,
      "name": "Rock_Aqua"
    },
    {
      "x": -5,
      "y": -1,
      "z": -5,
      "name": "Rock_Aqua"
    },
    {
      "x": -5,
      "y": -2,
      "z": -4,
      "name": "Rock_Slate"
    },
    {
      "x": -5,
      "y": -1,
      "z": -4,
      "name": "Rock_Aqua"
    },
    {
      "x": -5,
      "y": -2,
      "z": -3,
      "name": "Rock_Slate"
    },
    {
      "x": -5,
      "y": -2,
      "z": -2,
      "name": "Rock_Basalt"
    },
    {
      "x": -5,
      "y": -2,
      "z": -1,
      "name": "Rock_Aqua"
    },
    {
      "x": -5,
      "y": -2,
      "z": 0,
      "name": "Rock_Aqua"
    },
    {
      "x": -5,
      "y": -2,
      "z": 1,
      "name": "Rock_Aqua"
    },
    {
      "x": -5,
      "y": -2,
      "z": 2,
      "name": "Rock_Aqua"
    },
    {
      "x": -5,
      "y": -2,
      "z": 3,
      "name": "Rock_Aqua"
    },
    {
      "x": -5,
      "y": -2,
      "z": 4,
      "name": "Rock_Aqua"
    },
    {
      "x": -5,
      "y": -1,
      "z": 4,
      "name": "Rock_Aqua"
    },
    {
      "x": -5,
      "y": -1,
      "z": 5,
      "name": "Rock_Aqua"
    },
    {
      "x": -5,
      "y": 0,
      "z": 5,
      "name": "Rock_Aqua"
    },
    {
      "x": -5,
      "y": -1,
      "z": 6,
      "name": "Rock_Aqua"
    },
    {
      "x": -5,
      "y": 0,
      "z": 6,
      "name": "Rock_Aqua"
    },
    {
      "x": -4,
      "y": 0,
      "z": -7,
      "name": "Rock_Aqua"
    },
    {
      "x": -4,
      "y": -1,
      "z": -6,
      "name": "Rock_Aqua"
    },
    {
      "x": -4,
      "y": -2,
      "z": -5,
      "name": "Rock_Slate"
    },
    {
      "x": -4,
      "y": -1,
      "z": -5,
      "name": "Rock_Aqua"
    },
    {
      "x": -4,
      "y": -2,
      "z": -4,
      "name": "Rock_Slate"
    },
    {
      "x": -4,
      "y": -2,
      "z": -3,
      "name": "Rock_Slate"
    },
    {
      "x": -4,
      "y": -2,
      "z": -2,
      "name": "Rock_Slate"
    },
    {
      "x": -4,
      "y": -2,
      "z": -1,
      "name": "Rock_Aqua"
    },
    {
      "x": -4,
      "y": -2,
      "z": 0,
      "name": "Rock_Aqua"
    },
    {
      "x": -4,
      "y": -2,
      "z": 1,
      "name": "Rock_Aqua"
    },
    {
      "x": -4,
      "y": -2,
      "z": 2,
      "name": "Rock_Aqua"
    },
    {
      "x": -4,
      "y": -2,
      "z": 3,
      "name": "Rock_Aqua"
    },
    {
      "x": -4,
      "y": -2,
      "z": 4,
      "name": "Rock_Basalt"
    },
    {
      "x": -4,
      "y": -2,
      "z": 5,
      "name": "Rock_Basalt"
    },
    {
      "x": -4,
      "y": -1,
      "z": 5,
      "name": "Rock_Aqua"
    },
    {
      "x": -4,
      "y": -1,
      "z": 6,
      "name": "Rock_Aqua"
    },
    {
      "x": -4,
      "y": 0,
      "z": 6,
      "name": "Rock_Aqua"
    },
    {
      "x": -4,
      "y": 0,
      "z": 7,
      "name": "Rock_Aqua"
    },
    {
      "x": -3,
      "y": -1,
      "z": -7,
      "name": "Rock_Aqua"
    },
    {
      "x": -3,
      "y": 0,
      "z": -7,
      "name": "Rock_Aqua"
    },
    {
      "x": -3,
      "y": -2,
      "z": -6,
      "name": "Rock_Slate"
    },
    {
      "x": -3,
      "y": -1,
      "z": -6,
      "name": "Rock_Aqua"
    },
    {
      "x": -3,
      "y": -2,
      "z": -5,
      "name": "Rock_Slate"
    },
    {
      "x": -3,
      "y": -2,
      "z": -4,
      "name": "Rock_Slate"
    },
    {
      "x": -3,
      "y": -2,
      "z": -3,
      "name": "Rock_Slate"
    },
    {
      "x": -3,
      "y": -3,
      "z": -2,
      "name": "Rock_Slate"
    },
    {
      "x": -3,
      "y": -2,
      "z": -2,
      "name": "Rock_Slate"
    },
    {
      "x": -3,
      "y": -3,
      "z": -1,
      "name": "Rock_Slate"
    },
    {
      "x": -3,
      "y": -2,
      "z": -1,
      "name": "Rock_Slate"
    },
    {
      "x": -3,
      "y": -3,
      "z": 0,
      "name": "Rock_Slate"
    },
    {
      "x": -3,
      "y": -2,
      "z": 0,
      "name": "Rock_Aqua"
    },
    {
      "x": -3,
      "y": -3,
      "z": 1,
      "name": "Rock_Aqua"
    },
    {
      "x": -3,
      "y": -2,
      "z": 1,
      "name": "Rock_Aqua"
    },
    {
      "x": -3,
      "y": -3,
      "z": 2,
      "name": "Rock_Slate"
    },
    {
      "x": -3,
      "y": -2,
      "z": 2,
      "name": "Rock_Aqua"
    },
    {
      "x": -3,
      "y": -2,
      "z": 3,
      "name": "Rock_Basalt"
    },
    {
      "x": -3,
      "y": -2,
      "z": 4,
      "name": "Rock_Basalt"
    },
    {
      "x": -3,
      "y": -2,
      "z": 5,
      "name": "Rock_Basalt"
    },
    {
      "x": -3,
      "y": -2,
      "z": 6,
      "name": "Rock_Aqua"
    },
    {
      "x": -3,
      "y": -1,
      "z": 6,
      "name": "Rock_Aqua"
    },
    {
      "x": -3,
      "y": -1,
      "z": 7,
      "name": "Rock_Aqua"
    },
    {
      "x": -3,
      "y": 0,
      "z": 7,
      "name": "Rock_Aqua"
    },
    {
      "x": -2,
      "y": 0,
      "z": -8,
      "name": "Rock_Aqua"
    },
    {
      "x": -2,
      "y": -1,
      "z": -7,
      "name": "Rock_Aqua"
    },
    {
      "x": -2,
      "y": 0,
      "z": -7,
      "name": "Rock_Aqua"
    },
    {
      "x": -2,
      "y": -2,
      "z": -6,
      "name": "Rock_Slate"
    },
    {
      "x": -2,
      "y": -1,
      "z": -6,
      "name": "Rock_Slate"
    },
    {
      "x": -2,
      "y": -2,
      "z": -5,
      "name": "Rock_Slate"
    },
    {
      "x": -2,
      "y": -2,
      "z": -4,
      "name": "Rock_Slate"
    },
    {
      "x": -2,
      "y": -3,
      "z": -3,
      "name": "Rock_Slate"
    },
    {
      "x": -2,
      "y": -2,
      "z": -3,
      "name": "Rock_Slate"
    },
    {
      "x": -2,
      "y": -3,
      "z": -2,
      "name": "Rock_Slate"
    },
    {
      "x": -2,
      "y": -2,
      "z": -2,
      "name": "Rock_Slate"
    },
    {
      "x": -2,
      "y": -3,
      "z": -1,
      "name": "Rock_Slate"
    },
    {
      "x": -2,
      "y": -3,
      "z": 0,
      "name": "Rock_Slate"
    },
    {
      "x": -2,
      "y": -3,
      "z": 1,
      "name": "Rock_Slate"
    },
    {
      "x": -2,
      "y": -3,
      "z": 2,
      "name": "Rock_Slate"
    },
    {
      "x": -2,
      "y": -2,
      "z": 2,
      "name": "Rock_Slate"
    },
    {
      "x": -2,
      "y": -3,
      "z": 3,
      "name": "Rock_Slate"
    },
    {
      "x": -2,
      "y": -2,
      "z": 3,
      "name": "Rock_Slate"
    },
    {
      "x": -2,
      "y": -2,
      "z": 4,
      "name": "Rock_Basalt"
    },
    {
      "x": -2,
      "y": -2,
      "z": 5,
      "name": "Rock_Basalt"
    },
    {
      "x": -2,
      "y": -2,
      "z": 6,
      "name": "Rock_Basalt"
    },
    {
      "x": -2,
      "y": -1,
      "z": 6,
      "name": "Rock_Aqua"
    },
    {
      "x": -2,
      "y": -1,
      "z": 7,
      "name": "Rock_Aqua"
    },
    {
      "x": -2,
      "y": 0,
      "z": 7,
      "name": "Rock_Aqua"
    },
    {
      "x": -2,
      "y": 0,
      "z": 8,
      "name": "Rock_Aqua"
    },
    {
      "x": -1,
      "y": 0,
      "z": -8,
      "name": "Rock_Slate"
    },
    {
      "x": -1,
      "y": -1,
      "z": -7,
      "name": "Rock_Slate"
    },
    {
      "x": -1,
      "y": -2,
      "z": -6,
      "name": "Rock_Slate"
    },
    {
      "x": -1,
      "y": -2,
      "z": -5,
      "name": "Rock_Slate"
    },
    {
      "x": -1,
      "y": -2,
      "z": -4,
      "name": "Rock_Slate"
    },
    {
      "x": -1,
      "y": -3,
      "z": -3,
      "name": "Rock_Slate"
    },
    {
      "x": -1,
      "y": -2,
      "z": -3,
      "name": "Rock_Slate"
    },
    {
      "x": -1,
      "y": -3,
      "z": -2,
      "name": "Rock_Slate"
    },
    {
      "x": -1,
      "y": -3,
      "z": -1,
      "name": "Rock_Slate"
    },
    {
      "x": -1,
      "y": -3,
      "z": 0,
      "name": "Rock_Slate"
    },
    {
      "x": -1,
      "y": -3,
      "z": 1,
      "name": "Rock_Slate"
    },
    {
      "x": -1,
      "y": -3,
      "z": 2,
      "name": "Rock_Slate"
    },
    {
      "x": -1,
      "y": -3,
      "z": 3,
      "name": "Rock_Slate"
    },
    {
      "x": -1,
      "y": -2,
      "z": 3,
      "name": "Rock_Basalt"
    },
    {
      "x": -1,
      "y": -2,
      "z": 4,
      "name": "Rock_Basalt"
    },
    {
      "x": -1,
      "y": -2,
      "z": 5,
      "name": "Rock_Basalt"
    },
    {
      "x": -1,
      "y": -2,
      "z": 6,
      "name": "Rock_Basalt"
    },
    {
      "x": -1,
      "y": -1,
      "z": 7,
      "name": "Rock_Aqua"
    },
    {
      "x": -1,
      "y": 0,
      "z": 8,
      "name": "Rock_Aqua"
    },
    {
      "x": 0,
      "y": -1,
      "z": -8,
      "name": "Rock_Slate"
    },
    {
      "x": 0,
      "y": 0,
      "z": -8,
      "name": "Rock_Slate"
    },
    {
      "x": 0,
      "y": -1,
      "z": -7,
      "name": "Rock_Slate"
    },
    {
      "x": 0,
      "y": -2,
      "z": -6,
      "name": "Rock_Slate"
    },
    {
      "x": 0,
      "y": -2,
      "z": -5,
      "name": "Rock_Slate"
    },
    {
      "x": 0,
      "y": -2,
      "z": -4,
      "name": "Rock_Slate"
    },
    {
      "x": 0,
      "y": -3,
      "z": -3,
      "name": "Rock_Slate"
    },
    {
      "x": 0,
      "y": -2,
      "z": -3,
      "name": "Rock_Slate"
    },
    {
      "x": 0,
      "y": -3,
      "z": -2,
      "name": "Rock_Slate"
    },
    {
      "x": 0,
      "y": -3,
      "z": -1,
      "name": "Rock_Slate"
    },
    {
      "x": 0,
      "y": -3,
      "z": 0,
      "name": "Rock_Slate"
    },
    {
      "x": 0,
      "y": -3,
      "z": 1,
      "name": "Rock_Slate"
    },
    {
      "x": 0,
      "y": -3,
      "z": 2,
      "name": "Rock_Slate"
    },
    {
      "x": 0,
      "y": -3,
      "z": 3,
      "name": "Rock_Slate"
    },
    {
      "x": 0,
      "y": -2,
      "z": 3,
      "name": "Rock_Slate"
    },
    {
      "x": 0,
      "y": -2,
      "z": 4,
      "name": "Rock_Basalt"
    },
    {
      "x": 0,
      "y": -2,
      "z": 5,
      "name": "Rock_Basalt"
    },
    {
      "x": 0,
      "y": -2,
      "z": 6,
      "name": "Rock_Basalt"
    },
    {
      "x": 0,
      "y": -1,
      "z": 7,
      "name": "Rock_Basalt"
    },
    {
      "x": 0,
      "y": -1,
      "z": 8,
      "name": "Rock_Aqua"
    },
    {
      "x": 0,
      "y": 0,
      "z": 8,
      "name": "Rock_Aqua"
    },
    {
      "x": 1,
      "y": 0,
      "z": -8,
      "name": "Rock_Slate"
    },
    {
      "x": 1,
      "y": -1,
      "z": -7,
      "name": "Rock_Slate"
    },
    {
      "x": 1,
      "y": -2,
      "z": -6,
      "name": "Rock_Slate"
    },
    {
      "x": 1,
      "y": -2,
      "z": -5,
      "name": "Rock_Aqua"
    },
    {
      "x": 1,
      "y": -2,
      "z": -4,
      "name": "Rock_Aqua"
    },
    {
      "x": 1,
      "y": -3,
      "z": -3,
      "name": "Rock_Slate"
    },
    {
      "x": 1,
      "y": -2,
      "z": -3,
      "name": "Rock_Aqua"
    },
    {
      "x": 1,
      "y": -3,
      "z": -2,
      "name": "Rock_Slate"
    },
    {
      "x": 1,
      "y": -3,
      "z": -1,
      "name": "Rock_Aqua"
    },
    {
      "x": 1,
      "y": -3,
      "z": 0,
      "name": "Rock_Slate"
    },
    {
      "x": 1,
      "y": -3,
      "z": 1,
      "name": "Rock_Slate"
    },
    {
      "x": 1,
      "y": -3,
      "z": 2,
      "name": "Rock_Slate"
    },
    {
      "x": 1,
      "y": -3,
      "z": 3,
      "name": "Rock_Slate"
    },
    {
      "x": 1,
      "y": -2,
      "z": 3,
      "name": "Rock_Basalt"
    },
    {
      "x": 1,
      "y": -2,
      "z": 4,
      "name": "Rock_Basalt"
    },
    {
      "x": 1,
      "y": -2,
      "z": 5,
      "name": "Rock_Basalt"
    },
    {
      "x": 1,
      "y": -2,
      "z": 6,
      "name": "Rock_Basalt"
    },
    {
      "x": 1,
      "y": -1,
      "z": 7,
      "name": "Rock_Basalt"
    },
    {
      "x": 1,
      "y": 0,
      "z": 8,
      "name": "Rock_Aqua"
    },
    {
      "x": 2,
      "y": 0,
      "z": -8,
      "name": "Rock_Slate"
    },
    {
      "x": 2,
      "y": -1,
      "z": -7,
      "name": "Rock_Slate"
    },
    {
      "x": 2,
      "y": 0,
      "z": -7,
      "name": "Rock_Slate"
    },
    {
      "x": 2,
      "y": -2,
      "z": -6,
      "name": "Rock_Aqua"
    },
    {
      "x": 2,
      "y": -1,
      "z": -6,
      "name": "Rock_Slate"
    },
    {
      "x": 2,
      "y": -2,
      "z": -5,
      "name": "Rock_Aqua"
    },
    {
      "x": 2,
      "y": -2,
      "z": -4,
      "name": "Rock_Aqua"
    },
    {
      "x": 2,
      "y": -3,
      "z": -3,
      "name": "Rock_Aqua"
    },
    {
      "x": 2,
      "y": -2,
      "z": -3,
      "name": "Rock_Aqua"
    },
    {
      "x": 2,
      "y": -3,
      "z": -2,
      "name": "Rock_Aqua"
    },
    {
      "x": 2,
      "y": -2,
      "z": -2,
      "name": "Rock_Aqua"
    },
    {
      "x": 2,
      "y": -3,
      "z": -1,
      "name": "Rock_Aqua"
    },
    {
      "x": 2,
      "y": -3,
      "z": 0,
      "name": "Rock_Aqua"
    },
    {
      "x": 2,
      "y": -3,
      "z": 1,
      "name": "Rock_Slate"
    },
    {
      "x": 2,
      "y": -3,
      "z": 2,
      "name": "Rock_Slate"
    },
    {
      "x": 2,
      "y": -2,
      "z": 2,
      "name": "Rock_Slate"
    },
    {
      "x": 2,
      "y": -3,
      "z": 3,
      "name": "Rock_Slate"
    },
    {
      "x": 2,
      "y": -2,
      "z": 3,
      "name": "Rock_Slate"
    },
    {
      "x": 2,
      "y": -2,
      "z": 4,
      "name": "Rock_Basalt"
    },
    {
      "x": 2,
      "y": -2,
      "z": 5,
      "name": "Rock_Basalt"
    },
    {
      "x": 2,
      "y": -2,
      "z": 6,
      "name": "Rock_Basalt"
    },
    {
      "x": 2,
      "y": -1,
      "z": 6,
      "name": "Rock_Basalt"
    },
    {
      "x": 2,
      "y": -1,
      "z": 7,
      "name": "Rock_Basalt"
    },
    {
      "x": 2,
      "y": 0,
      "z": 7,
      "name": "Rock_Basalt"
    },
    {
      "x": 2,
      "y": 0,
      "z": 8,
      "name": "Rock_Basalt"
    },
    {
      "x": 3,
      "y": -1,
      "z": -7,
      "name": "Rock_Slate"
    },
    {
      "x": 3,
      "y": 0,
      "z": -7,
      "name": "Rock_Slate"
    },
    {
      "x": 3,
      "y": -2,
      "z": -6,
      "name": "Rock_Aqua"
    },
    {
      "x": 3,
      "y": -1,
      "z": -6,
      "name": "Rock_Aqua"
    },
    {
      "x": 3,
      "y": -2,
      "z": -5,
      "name": "Rock_Aqua"
    },
    {
      "x": 3,
      "y": -2,
      "z": -4,
      "name": "Rock_Aqua"
    },
    {
      "x": 3,
      "y": -2,
      "z": -3,
      "name": "Rock_Aqua"
    },
    {
      "x": 3,
      "y": -3,
      "z": -2,
      "name": "Rock_Aqua"
    },
    {
      "x": 3,
      "y": -2,
      "z": -2,
      "name": "Rock_Aqua"
    },
    {
      "x": 3,
      "y": -3,
      "z": -1,
      "name": "Rock_Aqua"
    },
    {
      "x": 3,
      "y": -2,
      "z": -1,
      "name": "Rock_Aqua"
    },
    {
      "x": 3,
      "y": -3,
      "z": 0,
      "name": "Rock_Aqua"
    },
    {
      "x": 3,
      "y": -2,
      "z": 0,
      "name": "Rock_Aqua"
    },
    {
      "x": 3,
      "y": -3,
      "z": 1,
      "name": "Rock_Aqua"
    },
    {
      "x": 3,
      "y": -2,
      "z": 1,
      "name": "Rock_Aqua"
    },
    {
      "x": 3,
      "y": -3,
      "z": 2,
      "name": "Rock_Slate"
    },
    {
      "x": 3,
      "y": -2,
      "z": 2,
      "name": "Rock_Slate"
    },
    {
      "x": 3,
      "y": -2,
      "z": 3,
      "name": "Rock_Basalt"
    },
    {
      "x": 3,
      "y": -2,
      "z": 4,
      "name": "Rock_Basalt"
    },
    {
      "x": 3,
      "y": -2,
      "z": 5,
      "name": "Rock_Basalt"
    },
    {
      "x": 3,
      "y": -2,
      "z": 6,
      "name": "Rock_Basalt"
    },
    {
      "x": 3,
      "y": -1,
      "z": 6,
      "name": "Rock_Basalt"
    },
    {
      "x": 3,
      "y": -1,
      "z": 7,
      "name": "Rock_Basalt"
    },
    {
      "x": 3,
      "y": 0,
      "z": 7,
      "name": "Rock_Basalt"
    },
    {
      "x": 4,
      "y": 0,
      "z": -7,
      "name": "Rock_Slate"
    },
    {
      "x": 4,
      "y": -1,
      "z": -6,
      "name": "Rock_Slate"
    },
    {
      "x": 4,
      "y": 0,
      "z": -6,
      "name": "Rock_Aqua"
    },
    {
      "x": 4,
      "y": -2,
      "z": -5,
      "name": "Rock_Aqua"
    },
    {
      "x": 4,
      "y": -1,
      "z": -5,
      "name": "Rock_Aqua"
    },
    {
      "x": 4,
      "y": -2,
      "z": -4,
      "name": "Rock_Aqua"
    },
    {
      "x": 4,
      "y": -2,
      "z": -3,
      "name": "Rock_Aqua"
    },
    {
      "x": 4,
      "y": -2,
      "z": -2,
      "name": "Rock_Aqua"
    },
    {
      "x": 4,
      "y": -2,
      "z": -1,
      "name": "Rock_Aqua"
    },
    {
      "x": 4,
      "y": -2,
      "z": 0,
      "name": "Rock_Aqua"
    },
    {
      "x": 4,
      "y": -2,
      "z": 1,
      "name": "Rock_Aqua"
    },
    {
      "x": 4,
      "y": -2,
      "z": 2,
      "name": "Rock_Basalt"
    },
    {
      "x": 4,
      "y": -2,
      "z": 3,
      "name": "Rock_Basalt"
    },
    {
      "x": 4,
      "y": -2,
      "z": 4,
      "name": "Rock_Basalt"
    },
    {
      "x": 4,
      "y": -2,
      "z": 5,
      "name": "Rock_Basalt"
    },
    {
      "x": 4,
      "y": -1,
      "z": 5,
      "name": "Rock_Basalt"
    },
    {
      "x": 4,
      "y": -1,
      "z": 6,
      "name": "Rock_Basalt"
    },
    {
      "x": 5,
      "y": -1,
      "z": -6,
      "name": "Rock_Aqua"
    },
    {
      "x": 5,
      "y": 0,
      "z": -6,
      "name": "Rock_Aqua"
    },
    {
      "x": 5,
      "y": -1,
      "z": -5,
      "name": "Rock_Aqua"
    },
    {
      "x": 5,
      "y": 0,
      "z": -5,
      "name": "Rock_Aqua"
    },
    {
      "x": 5,
      "y": -2,
      "z": -4,
      "name": "Rock_Aqua"
    },
    {
      "x": 5,
      "y": -1,
      "z": -4,
      "name": "Rock_Aqua"
    },
    {
      "x": 5,
      "y": -2,
      "z": -3,
      "name": "Rock_Aqua"
    },
    {
      "x": 5,
      "y": -2,
      "z": -2,
      "name": "Rock_Aqua"
    },
    {
      "x": 5,
      "y": -2,
      "z": -1,
      "name": "Rock_Aqua"
    },
    {
      "x": 5,
      "y": -2,
      "z": 0,
      "name": "Rock_Aqua"
    },
    {
      "x": 5,
      "y": -2,
      "z": 1,
      "name": "Rock_Basalt"
    },
    {
      "x": 5,
      "y": -2,
      "z": 2,
      "name": "Rock_Basalt"
    },
    {
      "x": 5,
      "y": -2,
      "z": 3,
      "name": "Rock_Basalt"
    },
    {
      "x": 5,
      "y": -2,
      "z": 4,
      "name": "Rock_Basalt"
    },
    {
      "x": 5,
      "y": -1,
      "z": 4,
      "name": "Rock_Basalt"
    },
    {
      "x": 5,
      "y": -1,
      "z": 5,
      "name": "Rock_Basalt"
    },
    {
      "x": 5,
      "y": 0,
      "z": 5,
      "name": "Rock_Basalt"
    },
    {
      "x": 5,
      "y": -1,
      "z": 6,
      "name": "Rock_Basalt"
    },
    {
      "x": 5,
      "y": 0,
      "z": 6,
      "name": "Rock_Basalt"
    },
    {
      "x": 6,
      "y": -1,
      "z": -5,
      "name": "Rock_Aqua"
    },
    {
      "x": 6,
      "y": 0,
      "z": -5,
      "name": "Rock_Aqua"
    },
    {
      "x": 6,
      "y": -1,
      "z": -4,
      "name": "Rock_Aqua"
    },
    {
      "x": 6,
      "y": 0,
      "z": -4,
      "name": "Rock_Aqua"
    },
    {
      "x": 6,
      "y": -2,
      "z": -3,
      "name": "Rock_Aqua"
    },
    {
      "x": 6,
      "y": -1,
      "z": -3,
      "name": "Rock_Aqua"
    },
    {
      "x": 6,
      "y": -2,
      "z": -2,
      "name": "Rock_Aqua"
    },
    {
      "x": 6,
      "y": -1,
      "z": -2,
      "name": "Rock_Aqua"
    },
    {
      "x": 6,
      "y": -2,
      "z": -1,
      "name": "Rock_Basalt"
    },
    {
      "x": 6,
      "y": -2,
      "z": 0,
      "name": "Rock_Basalt"
    },
    {
      "x": 6,
      "y": -2,
      "z": 1,
      "name": "Rock_Basalt"
    },
    {
      "x": 6,
      "y": -2,
      "z": 2,
      "name": "Rock_Basalt"
    },
    {
      "x": 6,
      "y": -1,
      "z": 2,
      "name": "Rock_Basalt"
    },
    {
      "x": 6,
      "y": -2,
      "z": 3,
      "name": "Rock_Basalt"
    },
    {
      "x": 6,
      "y": -1,
      "z": 3,
      "name": "Rock_Basalt"
    },
    {
      "x": 6,
      "y": -1,
      "z": 4,
      "name": "Rock_Basalt"
    },
    {
      "x": 6,
      "y": 0,
      "z": 4,
      "name": "Rock_Basalt"
    },
    {
      "x": 6,
      "y": -1,
      "z": 5,
      "name": "Rock_Basalt"
    },
    {
      "x": 6,
      "y": 0,
      "z": 5,
      "name": "Rock_Basalt"
    },
    {
      "x": 7,
      "y": 0,
      "z": -4,
      "name": "Rock_Aqua"
    },
    {
      "x": 7,
      "y": -1,
      "z": -3,
      "name": "Rock_Aqua"
    },
    {
      "x": 7,
      "y": 0,
      "z": -3,
      "name": "Rock_Aqua"
    },
    {
      "x": 7,
      "y": -1,
      "z": -2,
      "name": "Rock_Aqua"
    },
    {
      "x": 7,
      "y": 0,
      "z": -2,
      "name": "Rock_Aqua"
    },
    {
      "x": 7,
      "y": -1,
      "z": -1,
      "name": "Rock_Aqua"
    },
    {
      "x": 7,
      "y": -1,
      "z": 0,
      "name": "Rock_Basalt"
    },
    {
      "x": 7,
      "y": -1,
      "z": 1,
      "name": "Rock_Basalt"
    },
    {
      "x": 7,
      "y": -1,
      "z": 2,
      "name": "Rock_Basalt"
    },
    {
      "x": 7,
      "y": 0,
      "z": 2,
      "name": "Rock_Basalt"
    },
    {
      "x": 7,
      "y": -1,
      "z": 3,
      "name": "Rock_Basalt"
    },
    {
      "x": 7,
      "y": 0,
      "z": 3,
      "name": "Rock_Basalt"
    },
    {
      "x": 7,
      "y": 0,
      "z": 4,
      "name": "Rock_Basalt"
    },
    {
      "x": 8,
      "y": 0,
      "z": -2,
      "name": "Rock_Aqua"
    },
    {
      "x": 8,
      "y": 0,
      "z": -1,
      "name": "Rock_Aqua"
    },
    {
      "x": 8,
      "y": 0,
      "z": 2,
      "name": "Rock_Basalt"
    }
  ],
  "fluids": [
    {
      "x": -7,
      "y": 0,
      "z": -1,
      "name": "Glow_Water_Source",
      "level": 1
    },
    {
      "x": -7,
      "y": 0,
      "z": 0,
      "name": "Glow_Water_Source",
      "level": 1
    },
    {
      "x": -7,
      "y": 0,
      "z": 1,
      "name": "Glow_Water_Source",
      "level": 1
    },
    {
      "x": -7,
      "y": 0,
      "z": 3,
      "name": "Glow_Water_Source",
      "level": 1
    },
    {
      "x": -6,
      "y": 0,
      "z": -3,
      "name": "Glow_Water_Source",
      "level": 1
    },
    {
      "x": -6,
      "y": 0,
      "z": -2,
      "name": "Glow_Water_Source",
      "level": 1
    },
    {
      "x": -6,
      "y": -1,
      "z": -1,
      "name": "Glow_Water_Source",
      "level": 1
    },
    {
      "x": -6,
      "y": 0,
      "z": -1,
      "name": "Glow_Water_Source",
      "level": 1
    },
    {
      "x": -6,
      "y": -1,
      "z": 0,
      "name": "Glow_Water_Source",
      "level": 1
    },
    {
      "x": -6,
      "y": 0,
      "z": 0,
      "name": "Glow_Water_Source",
      "level": 1
    },
    {
      "x": -6,
      "y": -1,
      "z": 1,
      "name": "Glow_Water_Source",
      "level": 1
    },
    {
      "x": -6,
      "y": 0,
      "z": 1,
      "name": "Glow_Water_Source",
      "level": 1
    },
    {
      "x": -6,
      "y": 0,
      "z": 2,
      "name": "Glow_Water_Source",
      "level": 1
    },
    {
      "x": -6,
      "y": 0,
      "z": 3,
      "name": "Glow_Water_Source",
      "level": 1
    },
    {
      "x": -6,
      "y": 0,
      "z": 4,
      "name": "Glow_Water_Source",
      "level": 1
    },
    {
      "x": -5,
      "y": 0,
      "z": -5,
      "name": "Glow_Water_Source",
      "level": 1
    },
    {
      "x": -5,
      "y": 0,
      "z": -4,
      "name": "Glow_Water_Source",
      "level": 1
    },
    {
      "x": -5,
      "y": -1,
      "z": -3,
      "name": "Glow_Water_Source",
      "level": 1
    },
    {
      "x": -5,
      "y": 0,
      "z": -3,
      "name": "Glow_Water_Source",
      "level": 1
    },
    {
      "x": -5,
      "y": -1,
      "z": -2,
      "name": "Glow_Water_Source",
      "level": 1
    },
    {
      "x": -5,
      "y": 0,
      "z": -2,
      "name": "Glow_Water_Source",
      "level": 1
    },
    {
      "x": -5,
      "y": -1,
      "z": -1,
      "name": "Glow_Water_Source",
      "level": 1
    },
    {
      "x": -5,
      "y": 0,
      "z": -1,
      "name": "Glow_Water_Source",
      "level": 1
    },
    {
      "x": -5,
      "y": -1,
      "z": 0,
      "name": "Glow_Water_Source",
      "level": 1
    },
    {
      "x": -5,
      "y": 0,
      "z": 0,
      "name": "Glow_Water_Source",
      "level": 1
    },
    {
      "x": -5,
      "y": -1,
      "z": 1,
      "name": "Glow_Water_Source",
      "level": 1
    },
    {
      "x": -5,
      "y": 0,
      "z": 1,
      "name": "Glow_Water_Source",
      "level": 1
    },
    {
      "x": -5,
      "y": -1,
      "z": 2,
      "name": "Glow_Water_Source",
      "level": 1
    },
    {
      "x": -5,
      "y": 0,
      "z": 2,
      "name": "Glow_Water_Source",
      "level": 1
    },
    {
      "x": -5,
      "y": -1,
      "z": 3,
      "name": "Glow_Water_Source",
      "level": 1
    },
    {
      "x": -5,
      "y": 0,
      "z": 3,
      "name": "Glow_Water_Source",
      "level": 1
    },
    {
      "x": -5,
      "y": 0,
      "z": 4,
      "name": "Glow_Water_Source",
      "level": 1
    },
    {
      "x": -4,
      "y": 0,
      "z": -6,
      "name": "Glow_Water_Source",
      "level": 1
    },
    {
      "x": -4,
      "y": 0,
      "z": -5,
      "name": "Glow_Water_Source",
      "level": 1
    },
    {
      "x": -4,
      "y": -1,
      "z": -4,
      "name": "Glow_Water_Source",
      "level": 1
    },
    {
      "x": -4,
      "y": 0,
      "z": -4,
      "name": "Glow_Water_Source",
      "level": 1
    },
    {
      "x": -4,
      "y": -1,
      "z": -3,
      "name": "Glow_Water_Source",
      "level": 1
    },
    {
      "x": -4,
      "y": 0,
      "z": -3,
      "name": "Glow_Water_Source",
      "level": 1
    },
    {
      "x": -4,
      "y": -1,
      "z": -2,
      "name": "Glow_Water_Source",
      "level": 1
    },
    {
      "x": -4,
      "y": 0,
      "z": -2,
      "name": "Glow_Water_Source",
      "level": 1
    },
    {
      "x": -4,
      "y": -1,
      "z": -1,
      "name": "Glow_Water_Source",
      "level": 1
    },
    {
      "x": -4,
      "y": 0,
      "z": -1,
      "name": "Glow_Water_Source",
      "level": 1
    },
    {
      "x": -4,
      "y": -1,
      "z": 0,
      "name": "Glow_Water_Source",
      "level": 1
    },
    {
      "x": -4,
      "y": 0,
      "z": 0,
      "name": "Glow_Water_Source",
      "level": 1
    },
    {
      "x": -4,
      "y": -1,
      "z": 1,
      "name": "Glow_Water_Source",
      "level": 1
    },
    {
      "x": -4,
      "y": 0,
      "z": 1,
      "name": "Glow_Water_Source",
      "level": 1
    },
    {
      "x": -4,
      "y": -1,
      "z": 2,
      "name": "Glow_Water_Source",
      "level": 1
    },
    {
      "x": -4,
      "y": 0,
      "z": 2,
      "name": "Glow_Water_Source",
      "level": 1
    },
    {
      "x": -4,
      "y": -1,
      "z": 3,
      "name": "Glow_Water_Source",
      "level": 1
    },
    {
      "x": -4,
      "y": 0,
      "z": 3,
      "name": "Glow_Water_Source",
      "level": 1
    },
    {
      "x": -4,
      "y": -1,
      "z": 4,
      "name": "Glow_Water_Source",
      "level": 1
    },
    {
      "x": -4,
      "y": 0,
      "z": 4,
      "name": "Glow_Water_Source",
      "level": 1
    },
    {
      "x": -4,
      "y": 0,
      "z": 5,
      "name": "Glow_Water_Source",
      "level": 1
    },
    {
      "x": -3,
      "y": 0,
      "z": -6,
      "name": "Glow_Water_Source",
      "level": 1
    },
    {
      "x": -3,
      "y": -1,
      "z": -5,
      "name": "Glow_Water_Source",
      "level": 1
    },
    {
      "x": -3,
      "y": 0,
      "z": -5,
      "name": "Glow_Water_Source",
      "level": 1
    },
    {
      "x": -3,
      "y": -1,
      "z": -4,
      "name": "Glow_Water_Source",
      "level": 1
    },
    {
      "x": -3,
      "y": 0,
      "z": -4,
      "name": "Glow_Water_Source",
      "level": 1
    },
    {
      "x": -3,
      "y": -1,
      "z": -3,
      "name": "Glow_Water_Source",
      "level": 1
    },
    {
      "x": -3,
      "y": 0,
      "z": -3,
      "name": "Glow_Water_Source",
      "level": 1
    },
    {
      "x": -3,
      "y": -1,
      "z": -2,
      "name": "Glow_Water_Source",
      "level": 1
    },
    {
      "x": -3,
      "y": 0,
      "z": -2,
      "name": "Glow_Water_Source",
      "level": 1
    },
    {
      "x": -3,
      "y": -1,
      "z": -1,
      "name": "Glow_Water_Source",
      "level": 1
    },
    {
      "x": -3,
      "y": 0,
      "z": -1,
      "name": "Glow_Water_Source",
      "level": 1
    },
    {
      "x": -3,
      "y": -1,
      "z": 0,
      "name": "Glow_Water_Source",
      "level": 1
    },
    {
      "x": -3,
      "y": 0,
      "z": 0,
      "name": "Glow_Water_Source",
      "level": 1
    },
    {
      "x": -3,
      "y": -1,
      "z": 1,
      "name": "Glow_Water_Source",
      "level": 1
    },
    {
      "x": -3,
      "y": 0,
      "z": 1,
      "name": "Glow_Water_Source",
      "level": 1
    },
    {
      "x": -3,
      "y": -1,
      "z": 2,
      "name": "Glow_Water_Source",
      "level": 1
    },
    {
      "x": -3,
      "y": 0,
      "z": 2,
      "name": "Glow_Water_Source",
      "level": 1
    },
    {
      "x": -3,
      "y": -1,
      "z": 3,
      "name": "Glow_Water_Source",
      "level": 1
    },
    {
      "x": -3,
      "y": 0,
      "z": 3,
      "name": "Glow_Water_Source",
      "level": 1
    },
    {
      "x": -3,
      "y": -1,
      "z": 4,
      "name": "Glow_Water_Source",
      "level": 1
    },
    {
      "x": -3,
      "y": 0,
      "z": 4,
      "name": "Glow_Water_Source",
      "level": 1
    },
    {
      "x": -3,
      "y": -1,
      "z": 5,
      "name": "Glow_Water_Source",
      "level": 1
    },
    {
      "x": -3,
      "y": 0,
      "z": 5,
      "name": "Glow_Water_Source",
      "level": 1
    },
    {
      "x": -3,
      "y": 0,
      "z": 6,
      "name": "Glow_Water_Source",
      "level": 1
    },
    {
      "x": -2,
      "y": 0,
      "z": -6,
      "name": "Glow_Water_Source",
      "level": 1
    },
    {
      "x": -2,
      "y": -1,
      "z": -5,
      "name": "Glow_Water_Source",
      "level": 1
    },
    {
      "x": -2,
      "y": 0,
      "z": -5,
      "name": "Glow_Water_Source",
      "level": 1
    },
    {
      "x": -2,
      "y": -1,
      "z": -4,
      "name": "Glow_Water_Source",
      "level": 1
    },
    {
      "x": -2,
      "y": 0,
      "z": -4,
      "name": "Glow_Water_Source",
      "level": 1
    },
    {
      "x": -2,
      "y": -1,
      "z": -3,
      "name": "Glow_Water_Source",
      "level": 1
    },
    {
      "x": -2,
      "y": 0,
      "z": -3,
      "name": "Glow_Water_Source",
      "level": 1
    },
    {
      "x": -2,
      "y": -1,
      "z": -2,
      "name": "Glow_Water_Source",
      "level": 1
    },
    {
      "x": -2,
      "y": 0,
      "z": -2,
      "name": "Glow_Water_Source",
      "level": 1
    },
    {
      "x": -2,
      "y": -2,
      "z": -1,
      "name": "Glow_Water_Source",
      "level": 1
    },
    {
      "x": -2,
      "y": -1,
      "z": -1,
      "name": "Glow_Water_Source",
      "level": 1
    },
    {
      "x": -2,
      "y": 0,
      "z": -1,
      "name": "Glow_Water_Source",
      "level": 1
    },
    {
      "x": -2,
      "y": -2,
      "z": 0,
      "name": "Glow_Water_Source",
      "level": 1
    },
    {
      "x": -2,
      "y": -1,
      "z": 0,
      "name": "Glow_Water_Source",
      "level": 1
    },
    {
      "x": -2,
      "y": 0,
      "z": 0,
      "name": "Glow_Water_Source",
      "level": 1
    },
    {
      "x": -2,
      "y": -2,
      "z": 1,
      "name": "Glow_Water_Source",
      "level": 1
    },
    {
      "x": -2,
      "y": -1,
      "z": 1,
      "name": "Glow_Water_Source",
      "level": 1
    },
    {
      "x": -2,
      "y": 0,
      "z": 1,
      "name": "Glow_Water_Source",
      "level": 1
    },
    {
      "x": -2,
      "y": -1,
      "z": 2,
      "name": "Glow_Water_Source",
      "level": 1
    },
    {
      "x": -2,
      "y": 0,
      "z": 2,
      "name": "Glow_Water_Source",
      "level": 1
    },
    {
      "x": -2,
      "y": -1,
      "z": 3,
      "name": "Glow_Water_Source",
      "level": 1
    },
    {
      "x": -2,
      "y": 0,
      "z": 3,
      "name": "Glow_Water_Source",
      "level": 1
    },
    {
      "x": -2,
      "y": -1,
      "z": 4,
      "name": "Glow_Water_Source",
      "level": 1
    },
    {
      "x": -2,
      "y": 0,
      "z": 4,
      "name": "Glow_Water_Source",
      "level": 1
    },
    {
      "x": -2,
      "y": -1,
      "z": 5,
      "name": "Glow_Water_Source",
      "level": 1
    },
    {
      "x": -2,
      "y": 0,
      "z": 5,
      "name": "Glow_Water_Source",
      "level": 1
    },
    {
      "x": -2,
      "y": 0,
      "z": 6,
      "name": "Glow_Water_Source",
      "level": 1
    },
    {
      "x": -1,
      "y": 0,
      "z": -7,
      "name": "Glow_Water_Source",
      "level": 1
    },
    {
      "x": -1,
      "y": -1,
      "z": -6,
      "name": "Glow_Water_Source",
      "level": 1
    },
    {
      "x": -1,
      "y": 0,
      "z": -6,
      "name": "Glow_Water_Source",
      "level": 1
    },
    {
      "x": -1,
      "y": -1,
      "z": -5,
      "name": "Glow_Water_Source",
      "level": 1
    },
    {
      "x": -1,
      "y": 0,
      "z": -5,
      "name": "Glow_Water_Source",
      "level": 1
    },
    {
      "x": -1,
      "y": -1,
      "z": -4,
      "name": "Glow_Water_Source",
      "level": 1
    },
    {
      "x": -1,
      "y": 0,
      "z": -4,
      "name": "Glow_Water_Source",
      "level": 1
    },
    {
      "x": -1,
      "y": -1,
      "z": -3,
      "name": "Glow_Water_Source",
      "level": 1
    },
    {
      "x": -1,
      "y": 0,
      "z": -3,
      "name": "Glow_Water_Source",
      "level": 1
    },
    {
      "x": -1,
      "y": -2,
      "z": -2,
      "name": "Glow_Water_Source",
      "level": 1
    },
    {
      "x": -1,
      "y": -1,
      "z": -2,
      "name": "Glow_Water_Source",
      "level": 1
    },
    {
      "x": -1,
      "y": 0,
      "z": -2,
      "name": "Glow_Water_Source",
      "level": 1
    },
    {
      "x": -1,
      "y": -2,
      "z": -1,
      "name": "Glow_Water_Source",
      "level": 1
    },
    {
      "x": -1,
      "y": -1,
      "z": -1,
      "name": "Glow_Water_Source",
      "level": 1
    },
    {
      "x": -1,
      "y": 0,
      "z": -1,
      "name": "Glow_Water_Source",
      "level": 1
    },
    {
      "x": -1,
      "y": -2,
      "z": 0,
      "name": "Glow_Water_Source",
      "level": 1
    },
    {
      "x": -1,
      "y": -1,
      "z": 0,
      "name": "Glow_Water_Source",
      "level": 1
    },
    {
      "x": -1,
      "y": 0,
      "z": 0,
      "name": "Glow_Water_Source",
      "level": 1
    },
    {
      "x": -1,
      "y": -2,
      "z": 1,
      "name": "Glow_Water_Source",
      "level": 1
    },
    {
      "x": -1,
      "y": -1,
      "z": 1,
      "name": "Glow_Water_Source",
      "level": 1
    },
    {
      "x": -1,
      "y": 0,
      "z": 1,
      "name": "Glow_Water_Source",
      "level": 1
    },
    {
      "x": -1,
      "y": -2,
      "z": 2,
      "name": "Glow_Water_Source",
      "level": 1
    },
    {
      "x": -1,
      "y": -1,
      "z": 2,
      "name": "Glow_Water_Source",
      "level": 1
    },
    {
      "x": -1,
      "y": 0,
      "z": 2,
      "name": "Glow_Water_Source",
      "level": 1
    },
    {
      "x": -1,
      "y": -1,
      "z": 3,
      "name": "Glow_Water_Source",
      "level": 1
    },
    {
      "x": -1,
      "y": 0,
      "z": 3,
      "name": "Glow_Water_Source",
      "level": 1
    },
    {
      "x": -1,
      "y": -1,
      "z": 4,
      "name": "Glow_Water_Source",
      "level": 1
    },
    {
      "x": -1,
      "y": 0,
      "z": 4,
      "name": "Glow_Water_Source",
      "level": 1
    },
    {
      "x": -1,
      "y": -1,
      "z": 5,
      "name": "Glow_Water_Source",
      "level": 1
    },
    {
      "x": -1,
      "y": 0,
      "z": 5,
      "name": "Glow_Water_Source",
      "level": 1
    },
    {
      "x": -1,
      "y": -1,
      "z": 6,
      "name": "Glow_Water_Source",
      "level": 1
    },
    {
      "x": -1,
      "y": 0,
      "z": 6,
      "name": "Glow_Water_Source",
      "level": 1
    },
    {
      "x": -1,
      "y": 0,
      "z": 7,
      "name": "Glow_Water_Source",
      "level": 1
    },
    {
      "x": 0,
      "y": 0,
      "z": -7,
      "name": "Glow_Water_Source",
      "level": 1
    },
    {
      "x": 0,
      "y": -1,
      "z": -6,
      "name": "Glow_Water_Source",
      "level": 1
    },
    {
      "x": 0,
      "y": 0,
      "z": -6,
      "name": "Glow_Water_Source",
      "level": 1
    },
    {
      "x": 0,
      "y": -1,
      "z": -5,
      "name": "Glow_Water_Source",
      "level": 1
    },
    {
      "x": 0,
      "y": 0,
      "z": -5,
      "name": "Glow_Water_Source",
      "level": 1
    },
    {
      "x": 0,
      "y": -1,
      "z": -4,
      "name": "Glow_Water_Source",
      "level": 1
    },
    {
      "x": 0,
      "y": 0,
      "z": -4,
      "name": "Glow_Water_Source",
      "level": 1
    },
    {
      "x": 0,
      "y": -1,
      "z": -3,
      "name": "Glow_Water_Source",
      "level": 1
    },
    {
      "x": 0,
      "y": 0,
      "z": -3,
      "name": "Glow_Water_Source",
      "level": 1
    },
    {
      "x": 0,
      "y": -2,
      "z": -2,
      "name": "Glow_Water_Source",
      "level": 1
    },
    {
      "x": 0,
      "y": -1,
      "z": -2,
      "name": "Glow_Water_Source",
      "level": 1
    },
    {
      "x": 0,
      "y": 0,
      "z": -2,
      "name": "Glow_Water_Source",
      "level": 1
    },
    {
      "x": 0,
      "y": -2,
      "z": -1,
      "name": "Glow_Water_Source",
      "level": 1
    },
    {
      "x": 0,
      "y": -1,
      "z": -1,
      "name": "Glow_Water_Source",
      "level": 1
    },
    {
      "x": 0,
      "y": 0,
      "z": -1,
      "name": "Glow_Water_Source",
      "level": 1
    },
    {
      "x": 0,
      "y": -2,
      "z": 0,
      "name": "Glow_Water_Source",
      "level": 1
    },
    {
      "x": 0,
      "y": -1,
      "z": 0,
      "name": "Glow_Water_Source",
      "level": 1
    },
    {
      "x": 0,
      "y": 0,
      "z": 0,
      "name": "Glow_Water_Source",
      "level": 1
    },
    {
      "x": 0,
      "y": -2,
      "z": 1,
      "name": "Glow_Water_Source",
      "level": 1
    },
    {
      "x": 0,
      "y": -1,
      "z": 1,
      "name": "Glow_Water_Source",
      "level": 1
    },
    {
      "x": 0,
      "y": 0,
      "z": 1,
      "name": "Glow_Water_Source",
      "level": 1
    },
    {
      "x": 0,
      "y": -2,
      "z": 2,
      "name": "Glow_Water_Source",
      "level": 1
    },
    {
      "x": 0,
      "y": -1,
      "z": 2,
      "name": "Glow_Water_Source",
      "level": 1
    },
    {
      "x": 0,
      "y": 0,
      "z": 2,
      "name": "Glow_Water_Source",
      "level": 1
    },
    {
      "x": 0,
      "y": -1,
      "z": 3,
      "name": "Glow_Water_Source",
      "level": 1
    },
    {
      "x": 0,
      "y": 0,
      "z": 3,
      "name": "Glow_Water_Source",
      "level": 1
    },
    {
      "x": 0,
      "y": -1,
      "z": 4,
      "name": "Glow_Water_Source",
      "level": 1
    },
    {
      "x": 0,
      "y": 0,
      "z": 4,
      "name": "Glow_Water_Source",
      "level": 1
    },
    {
      "x": 0,
      "y": -1,
      "z": 5,
      "name": "Glow_Water_Source",
      "level": 1
    },
    {
      "x": 0,
      "y": 0,
      "z": 5,
      "name": "Glow_Water_Source",
      "level": 1
    },
    {
      "x": 0,
      "y": -1,
      "z": 6,
      "name": "Glow_Water_Source",
      "level": 1
    },
    {
      "x": 0,
      "y": 0,
      "z": 6,
      "name": "Glow_Water_Source",
      "level": 1
    },
    {
      "x": 0,
      "y": 0,
      "z": 7,
      "name": "Glow_Water_Source",
      "level": 1
    },
    {
      "x": 1,
      "y": 0,
      "z": -7,
      "name": "Glow_Water_Source",
      "level": 1
    },
    {
      "x": 1,
      "y": -1,
      "z": -6,
      "name": "Glow_Water_Source",
      "level": 1
    },
    {
      "x": 1,
      "y": 0,
      "z": -6,
      "name": "Glow_Water_Source",
      "level": 1
    },
    {
      "x": 1,
      "y": -1,
      "z": -5,
      "name": "Glow_Water_Source",
      "level": 1
    },
    {
      "x": 1,
      "y": 0,
      "z": -5,
      "name": "Glow_Water_Source",
      "level": 1
    },
    {
      "x": 1,
      "y": -1,
      "z": -4,
      "name": "Glow_Water_Source",
      "level": 1
    },
    {
      "x": 1,
      "y": 0,
      "z": -4,
      "name": "Glow_Water_Source",
      "level": 1
    },
    {
      "x": 1,
      "y": -1,
      "z": -3,
      "name": "Glow_Water_Source",
      "level": 1
    },
    {
      "x": 1,
      "y": 0,
      "z": -3,
      "name": "Glow_Water_Source",
      "level": 1
    },
    {
      "x": 1,
      "y": -2,
      "z": -2,
      "name": "Glow_Water_Source",
      "level": 1
    },
    {
      "x": 1,
      "y": -1,
      "z": -2,
      "name": "Glow_Water_Source",
      "level": 1
    },
    {
      "x": 1,
      "y": 0,
      "z": -2,
      "name": "Glow_Water_Source",
      "level": 1
    },
    {
      "x": 1,
      "y": -2,
      "z": -1,
      "name": "Glow_Water_Source",
      "level": 1
    },
    {
      "x": 1,
      "y": -1,
      "z": -1,
      "name": "Glow_Water_Source",
      "level": 1
    },
    {
      "x": 1,
      "y": 0,
      "z": -1,
      "name": "Glow_Water_Source",
      "level": 1
    },
    {
      "x": 1,
      "y": -2,
      "z": 0,
      "name": "Glow_Water_Source",
      "level": 1
    },
    {
      "x": 1,
      "y": -1,
      "z": 0,
      "name": "Glow_Water_Source",
      "level": 1
    },
    {
      "x": 1,
      "y": 0,
      "z": 0,
      "name": "Glow_Water_Source",
      "level": 1
    },
    {
      "x": 1,
      "y": -2,
      "z": 1,
      "name": "Glow_Water_Source",
      "level": 1
    },
    {
      "x": 1,
      "y": -1,
      "z": 1,
      "name": "Glow_Water_Source",
      "level": 1
    },
    {
      "x": 1,
      "y": 0,
      "z": 1,
      "name": "Glow_Water_Source",
      "level": 1
    },
    {
      "x": 1,
      "y": -2,
      "z": 2,
      "name": "Glow_Water_Source",
      "level": 1
    },
    {
      "x": 1,
      "y": -1,
      "z": 2,
      "name": "Glow_Water_Source",
      "level": 1
    },
    {
      "x": 1,
      "y": 0,
      "z": 2,
      "name": "Glow_Water_Source",
      "level": 1
    },
    {
      "x": 1,
      "y": -1,
      "z": 3,
      "name": "Glow_Water_Source",
      "level": 1
    },
    {
      "x": 1,
      "y": 0,
      "z": 3,
      "name": "Glow_Water_Source",
      "level": 1
    },
    {
      "x": 1,
      "y": -1,
      "z": 4,
      "name": "Glow_Water_Source",
      "level": 1
    },
    {
      "x": 1,
      "y": 0,
      "z": 4,
      "name": "Glow_Water_Source",
      "level": 1
    },
    {
      "x": 1,
      "y": -1,
      "z": 5,
      "name": "Glow_Water_Source",
      "level": 1
    },
    {
      "x": 1,
      "y": 0,
      "z": 5,
      "name": "Glow_Water_Source",
      "level": 1
    },
    {
      "x": 1,
      "y": -1,
      "z": 6,
      "name": "Glow_Water_Source",
      "level": 1
    },
    {
      "x": 1,
      "y": 0,
      "z": 6,
      "name": "Glow_Water_Source",
      "level": 1
    },
    {
      "x": 1,
      "y": 0,
      "z": 7,
      "name": "Glow_Water_Source",
      "level": 1
    },
    {
      "x": 2,
      "y": 0,
      "z": -6,
      "name": "Glow_Water_Source",
      "level": 1
    },
    {
      "x": 2,
      "y": -1,
      "z": -5,
      "name": "Glow_Water_Source",
      "level": 1
    },
    {
      "x": 2,
      "y": 0,
      "z": -5,
      "name": "Glow_Water_Source",
      "level": 1
    },
    {
      "x": 2,
      "y": -1,
      "z": -4,
      "name": "Glow_Water_Source",
      "level": 1
    },
    {
      "x": 2,
      "y": 0,
      "z": -4,
      "name": "Glow_Water_Source",
      "level": 1
    },
    {
      "x": 2,
      "y": -1,
      "z": -3,
      "name": "Glow_Water_Source",
      "level": 1
    },
    {
      "x": 2,
      "y": 0,
      "z": -3,
      "name": "Glow_Water_Source",
      "level": 1
    },
    {
      "x": 2,
      "y": -1,
      "z": -2,
      "name": "Glow_Water_Source",
      "level": 1
    },
    {
      "x": 2,
      "y": 0,
      "z": -2,
      "name": "Glow_Water_Source",
      "level": 1
    },
    {
      "x": 2,
      "y": -2,
      "z": -1,
      "name": "Glow_Water_Source",
      "level": 1
    },
    {
      "x": 2,
      "y": -1,
      "z": -1,
      "name": "Glow_Water_Source",
      "level": 1
    },
    {
      "x": 2,
      "y": 0,
      "z": -1,
      "name": "Glow_Water_Source",
      "level": 1
    },
    {
      "x": 2,
      "y": -2,
      "z": 0,
      "name": "Glow_Water_Source",
      "level": 1
    },
    {
      "x": 2,
      "y": -1,
      "z": 0,
      "name": "Glow_Water_Source",
      "level": 1
    },
    {
      "x": 2,
      "y": 0,
      "z": 0,
      "name": "Glow_Water_Source",
      "level": 1
    },
    {
      "x": 2,
      "y": -2,
      "z": 1,
      "name": "Glow_Water_Source",
      "level": 1
    },
    {
      "x": 2,
      "y": -1,
      "z": 1,
      "name": "Glow_Water_Source",
      "level": 1
    },
    {
      "x": 2,
      "y": 0,
      "z": 1,
      "name": "Glow_Water_Source",
      "level": 1
    },
    {
      "x": 2,
      "y": -1,
      "z": 2,
      "name": "Glow_Water_Source",
      "level": 1
    },
    {
      "x": 2,
      "y": 0,
      "z": 2,
      "name": "Glow_Water_Source",
      "level": 1
    },
    {
      "x": 2,
      "y": -1,
      "z": 3,
      "name": "Glow_Water_Source",
      "level": 1
    },
    {
      "x": 2,
      "y": 0,
      "z": 3,
      "name": "Glow_Water_Source",
      "level": 1
    },
    {
      "x": 2,
      "y": -1,
      "z": 4,
      "name": "Glow_Water_Source",
      "level": 1
    },
    {
      "x": 2,
      "y": 0,
      "z": 4,
      "name": "Glow_Water_Source",
      "level": 1
    },
    {
      "x": 2,
      "y": -1,
      "z": 5,
      "name": "Glow_Water_Source",
      "level": 1
    },
    {
      "x": 2,
      "y": 0,
      "z": 5,
      "name": "Glow_Water_Source",
      "level": 1
    },
    {
      "x": 2,
      "y": 0,
      "z": 6,
      "name": "Glow_Water_Source",
      "level": 1
    },
    {
      "x": 3,
      "y": 0,
      "z": -6,
      "name": "Glow_Water_Source",
      "level": 1
    },
    {
      "x": 3,
      "y": -1,
      "z": -5,
      "name": "Glow_Water_Source",
      "level": 1
    },
    {
      "x": 3,
      "y": 0,
      "z": -5,
      "name": "Glow_Water_Source",
      "level": 1
    },
    {
      "x": 3,
      "y": -1,
      "z": -4,
      "name": "Glow_Water_Source",
      "level": 1
    },
    {
      "x": 3,
      "y": 0,
      "z": -4,
      "name": "Glow_Water_Source",
      "level": 1
    },
    {
      "x": 3,
      "y": -1,
      "z": -3,
      "name": "Glow_Water_Source",
      "level": 1
    },
    {
      "x": 3,
      "y": 0,
      "z": -3,
      "name": "Glow_Water_Source",
      "level": 1
    },
    {
      "x": 3,
      "y": -1,
      "z": -2,
      "name": "Glow_Water_Source",
      "level": 1
    },
    {
      "x": 3,
      "y": 0,
      "z": -2,
      "name": "Glow_Water_Source",
      "level": 1
    },
    {
      "x": 3,
      "y": -1,
      "z": -1,
      "name": "Glow_Water_Source",
      "level": 1
    },
    {
      "x": 3,
      "y": 0,
      "z": -1,
      "name": "Glow_Water_Source",
      "level": 1
    },
    {
      "x": 3,
      "y": -1,
      "z": 0,
      "name": "Glow_Water_Source",
      "level": 1
    },
    {
      "x": 3,
      "y": 0,
      "z": 0,
      "name": "Glow_Water_Source",
      "level": 1
    },
    {
      "x": 3,
      "y": -1,
      "z": 1,
      "name": "Glow_Water_Source",
      "level": 1
    },
    {
      "x": 3,
      "y": 0,
      "z": 1,
      "name": "Glow_Water_Source",
      "level": 1
    },
    {
      "x": 3,
      "y": -1,
      "z": 2,
      "name": "Glow_Water_Source",
      "level": 1
    },
    {
      "x": 3,
      "y": 0,
      "z": 2,
      "name": "Glow_Water_Source",
      "level": 1
    },
    {
      "x": 3,
      "y": -1,
      "z": 3,
      "name": "Glow_Water_Source",
      "level": 1
    },
    {
      "x": 3,
      "y": 0,
      "z": 3,
      "name": "Glow_Water_Source",
      "level": 1
    },
    {
      "x": 3,
      "y": -1,
      "z": 4,
      "name": "Glow_Water_Source",
      "level": 1
    },
    {
      "x": 3,
      "y": 0,
      "z": 4,
      "name": "Glow_Water_Source",
      "level": 1
    },
    {
      "x": 3,
      "y": -1,
      "z": 5,
      "name": "Glow_Water_Source",
      "level": 1
    },
    {
      "x": 3,
      "y": 0,
      "z": 5,
      "name": "Glow_Water_Source",
      "level": 1
    },
    {
      "x": 3,
      "y": 0,
      "z": 6,
      "name": "Glow_Water_Source",
      "level": 1
    },
    {
      "x": 4,
      "y": 0,
      "z": -5,
      "name": "Glow_Water_Source",
      "level": 1
    },
    {
      "x": 4,
      "y": -1,
      "z": -4,
      "name": "Glow_Water_Source",
      "level": 1
    },
    {
      "x": 4,
      "y": 0,
      "z": -4,
      "name": "Glow_Water_Source",
      "level": 1
    },
    {
      "x": 4,
      "y": -1,
      "z": -3,
      "name": "Glow_Water_Source",
      "level": 1
    },
    {
      "x": 4,
      "y": 0,
      "z": -3,
      "name": "Glow_Water_Source",
      "level": 1
    },
    {
      "x": 4,
      "y": -1,
      "z": -2,
      "name": "Glow_Water_Source",
      "level": 1
    },
    {
      "x": 4,
      "y": 0,
      "z": -2,
      "name": "Glow_Water_Source",
      "level": 1
    },
    {
      "x": 4,
      "y": -1,
      "z": -1,
      "name": "Glow_Water_Source",
      "level": 1
    },
    {
      "x": 4,
      "y": 0,
      "z": -1,
      "name": "Glow_Water_Source",
      "level": 1
    },
    {
      "x": 4,
      "y": -1,
      "z": 0,
      "name": "Glow_Water_Source",
      "level": 1
    },
    {
      "x": 4,
      "y": 0,
      "z": 0,
      "name": "Glow_Water_Source",
      "level": 1
    },
    {
      "x": 4,
      "y": -1,
      "z": 1,
      "name": "Glow_Water_Source",
      "level": 1
    },
    {
      "x": 4,
      "y": 0,
      "z": 1,
      "name": "Glow_Water_Source",
      "level": 1
    },
    {
      "x": 4,
      "y": -1,
      "z": 2,
      "name": "Glow_Water_Source",
      "level": 1
    },
    {
      "x": 4,
      "y": 0,
      "z": 2,
      "name": "Glow_Water_Source",
      "level": 1
    },
    {
      "x": 4,
      "y": -1,
      "z": 3,
      "name": "Glow_Water_Source",
      "level": 1
    },
    {
      "x": 4,
      "y": 0,
      "z": 3,
      "name": "Glow_Water_Source",
      "level": 1
    },
    {
      "x": 4,
      "y": -1,
      "z": 4,
      "name": "Glow_Water_Source",
      "level": 1
    },
    {
      "x": 4,
      "y": 0,
      "z": 4,
      "name": "Glow_Water_Source",
      "level": 1
    },
    {
      "x": 4,
      "y": 0,
      "z": 5,
      "name": "Glow_Water_Source",
      "level": 1
    },
    {
      "x": 4,
      "y": 0,
      "z": 6,
      "name": "Glow_Water_Source",
      "level": 1
    },
    {
      "x": 5,
      "y": 0,
      "z": -4,
      "name": "Glow_Water_Source",
      "level": 1
    },
    {
      "x": 5,
      "y": -1,
      "z": -3,
      "name": "Glow_Water_Source",
      "level": 1
    },
    {
      "x": 5,
      "y": 0,
      "z": -3,
      "name": "Glow_Water_Source",
      "level": 1
    },
    {
      "x": 5,
      "y": -1,
      "z": -2,
      "name": "Glow_Water_Source",
      "level": 1
    },
    {
      "x": 5,
      "y": 0,
      "z": -2,
      "name": "Glow_Water_Source",
      "level": 1
    },
    {
      "x": 5,
      "y": -1,
      "z": -1,
      "name": "Glow_Water_Source",
      "level": 1
    },
    {
      "x": 5,
      "y": 0,
      "z": -1,
      "name": "Glow_Water_Source",
      "level": 1
    },
    {
      "x": 5,
      "y": -1,
      "z": 0,
      "name": "Glow_Water_Source",
      "level": 1
    },
    {
      "x": 5,
      "y": 0,
      "z": 0,
      "name": "Glow_Water_Source",
      "level": 1
    },
    {
      "x": 5,
      "y": -1,
      "z": 1,
      "name": "Glow_Water_Source",
      "level": 1
    },
    {
      "x": 5,
      "y": 0,
      "z": 1,
      "name": "Glow_Water_Source",
      "level": 1
    },
    {
      "x": 5,
      "y": -1,
      "z": 2,
      "name": "Glow_Water_Source",
      "level": 1
    },
    {
      "x": 5,
      "y": 0,
      "z": 2,
      "name": "Glow_Water_Source",
      "level": 1
    },
    {
      "x": 5,
      "y": -1,
      "z": 3,
      "name": "Glow_Water_Source",
      "level": 1
    },
    {
      "x": 5,
      "y": 0,
      "z": 3,
      "name": "Glow_Water_Source",
      "level": 1
    },
    {
      "x": 5,
      "y": 0,
      "z": 4,
      "name": "Glow_Water_Source",
      "level": 1
    },
    {
      "x": 6,
      "y": 0,
      "z": -3,
      "name": "Glow_Water_Source",
      "level": 1
    },
    {
      "x": 6,
      "y": 0,
      "z": -2,
      "name": "Glow_Water_Source",
      "level": 1
    },
    {
      "x": 6,
      "y": -1,
      "z": -1,
      "name": "Glow_Water_Source",
      "level": 1
    },
    {
      "x": 6,
      "y": 0,
      "z": -1,
      "name": "Glow_Water_Source",
      "level": 1
    },
    {
      "x": 6,
      "y": -1,
      "z": 0,
      "name": "Glow_Water_Source",
      "level": 1
    },
    {
      "x": 6,
      "y": 0,
      "z": 0,
      "name": "Glow_Water_Source",
      "level": 1
    },
    {
      "x": 6,
      "y": -1,
      "z": 1,
      "name": "Glow_Water_Source",
      "level": 1
    },
    {
      "x": 6,
      "y": 0,
      "z": 1,
      "name": "Glow_Water_Source",
      "level": 1
    },
    {
      "x": 6,
      "y": 0,
      "z": 2,
      "name": "Glow_Water_Source",
      "level": 1
    },
    {
      "x": 6,
      "y": 0,
      "z": 3,
      "name": "Glow_Water_Source",
      "level": 1
    },
    {
      "x": 7,
      "y": 0,
      "z": -1,
      "name": "Glow_Water_Source",
      "level": 1
    },
    {
      "x": 7,
      "y": 0,
      "z": 0,
      "name": "Glow_Water_Source",
      "level": 1
    },
    {
      "x": 7,
      "y": 0,
      "z": 1,
      "name": "Glow_Water_Source",
      "level": 1
    },
    {
      "x": 8,
      "y": 0,
      "z": 0,
      "name": "Glow_Water_Source",
      "level": 1
    },
    {
      "x": 8,
      "y": 0,
      "z": 1,
      "name": "Glow_Water_Source",
      "level": 1
    }
  ]
}