{
  "version": 8,
  "blockIdVersion": 11,
  "anchorX": 0,
  "anchorY": 0,
  "anchorZ": 0,
  "blocks": [
    {
      "x": -24,
      "y": 15,
      "z": 0,
      "name": "Wood_Darkwood_Planks"
    },
    {
      "x": -24,
      "y": 14,
      "z": 1,
      "name": "Wood_Darkwood_Planks"
    },
    {
      "x": -23,
      "y": 15,
      "z": 0,
      "name": "Deco_Rope",
      "rotation": 5
    },
    {
      "x": -23,
      "y": 14,
      "z": 1,
      "name": "Wood_Darkwood_Planks",
      "rotation": 4
    },
    {
      "x": -23,
      "y": 13,
      "z": 2,
      "name": "Wood_Darkwood_Planks"
    },
    {
      "x": -22,
      "y": 11,
      "z": 0,
      "name": "Wood_Darkwood_Stairs",
      "rotation": 2
    },
    {
      "x": -22,
      "y": 15,
      "z": 0,
      "name": "Deco_Rope",
      "rotation": 15
    },
    {
      "x": -22,
      "y": 11,
      "z": 1,
      "name": "Wood_Darkwood_Stairs",
      "rotation": 10
    },
    {
      "x": -22,
      "y": 12,
      "z": 1,
      "name": "Wood_Darkwood_Stairs",
      "rotation": 2
    },
    {
      "x": -22,
      "y": 14,
      "z": 1,
      "name": "Wood_Darkwood_Planks",
      "rotation": 4
    },
    {
      "x": -22,
      "y": 12,
      "z": 2,
      "name": "Wood_Darkwood_Planks"
    },
    {
      "x": -22,
      "y": 13,
      "z": 2,
      "name": "Wood_Darkwood_Planks"
    },
    {
      "x": -22,
      "y": 12,
      "z": 3,
      "name": "Wood_Darkwood_Planks"
    },
    {
      "x": -22,
      "y": 13,
      "z": 3,
      "name": "Wood_Darkwood_Planks"
    },
    {
      "x": -22,
      "y": 14,
      "z": 3,
      "name": "Wood_Darkwood_Stairs",
      "rotation": 2
    },
    {
      "x": -22,
      "y": 14,
      "z": 4,
      "name": "Wood_Darkwood_Stairs",
      "rotation": 10
    },
    {
      "x": -22,
      "y": 15,
      "z": 4,
      "name": "Wood_Darkwood_Stairs",
      "rotation": 2
    },
    {
      "x": -21,
      "y": 15,
      "z": 0,
      "name": "Deco_Rope",
      "rotation": 15
    },
    {
      "x": -21,
      "y": 12,
      "z": 2,
      "name": "Wood_Darkwood_Planks"
    },
    {
      "x": -21,
      "y": 13,
      "z": 2,
      "name": "Wood_Darkwood_Planks"
    },
    {
      "x": -21,
      "y": 12,
      "z": 3,
      "name": "Wood_Darkwood_Planks"
    },
    {
      "x": -20,
      "y": 15,
      "z": 0,
      "name": "Deco_Rope",
      "rotation": 5
    },
    {
      "x": -20,
      "y": 12,
      "z": 3,
      "name": "Wood_Darkwood_Planks",
      "rotation": 4
    },
    {
      "x": -20,
      "y": 11,
      "z": 4,
      "name": "Wood_Darkwood_Planks"
    },
    {
      "x": -19,
      "y": 15,
      "z": 0,
      "name": "Wood_Darkwood_Planks",
      "rotation": 4
    },
    {
      "x": -19,
      "y": 14,
      "z": 1,
      "name": "Wood_Darkwood_Planks_Half",
      "rotation": 11
    },
    {
      "x": -19,
      "y": 11,
      "z": 2,
      "name": "Wood_Deadwood_Planks",
      "rotation": 4
    },
    {
      "x": -19,
      "y": 11,
      "z": 3,
      "name": "Wood_Deadwood_Planks",
      "rotation": 4
    },
    {
      "x": -19,
      "y": 12,
      "z": 3,
      "name": "Wood_Deadwood_Planks",
      "rotation": 4
    },
    {
      "x": -19,
      "y": 11,
      "z": 4,
      "name": "Wood_Darkwood_Planks",
      "rotation": 4
    },
    {
      "x": -19,
      "y": 12,
      "z": 4,
      "name": "Wood_Deadwood_Planks",
      "rotation": 4
    },
    {
      "x": -19,
      "y": 13,
      "z": 4,
      "name": "Wood_Deadwood_Planks",
      "rotation": 4
    },
    {
      "x": -19,
      "y": 10,
      "z": 5,
      "name": "Wood_Darkwood_Planks"
    },
    {
      "x": -18,
      "y": 15,
      "z": 0,
      "name": "Cloth_Block_Wool_Red",
      "rotation": 4
    },
    {
      "x": -18,
      "y": 14,
      "z": 1,
      "name": "Wood_Darkwood_Planks",
      "rotation": 4
    },
    {
      "x": -18,
      "y": 11,
      "z": 2,
      "name": "Wood_Deadwood_Planks",
      "rotation": 4
    },
    {
      "x": -18,
      "y": 12,
      "z": 2,
      "name": "Wood_Deadwood_Planks",
      "rotation": 4
    },
    {
      "x": -18,
      "y": 13,
      "z": 2,
      "name": "Wood_Darkwood_Planks",
      "rotation": 4
    },
    {
      "x": -18,
      "y": 10,
      "z": 3,
      "name": "Wood_Deadwood_Planks",
      "rotation": 4
    },
    {
      "x": -18,
      "y": 11,
      "z": 3,
      "name": "Wood_Deadwood_Planks",
      "rotation": 4
    },
    {
      "x": -18,
      "y": 12,
      "z": 3,
      "name": "Wood_Deadwood_Planks",
      "rotation": 4
    },
    {
      "x": -18,
      "y": 13,
      "z": 3,
      "name": "Wood_Deadwood_Planks",
      "rotation": 4
    },
    {
      "x": -18,
      "y": 11,
      "z": 4,
      "name": "Wood_Deadwood_Planks",
      "rotation": 4
    },
    {
      "x": -18,
      "y": 12,
      "z": 4,
      "name": "Wood_Deadwood_Planks",
      "rotation": 4
    },
    {
      "x": -18,
      "y": 13,
      "z": 4,
      "name": "Wood_Deadwood_Planks",
      "rotation": 4
    },
    {
      "x": -18,
      "y": 10,
      "z": 5,
      "name": "Wood_Darkwood_Planks",
      "rotation": 4
    },
    {
      "x": -18,
      "y": 12,
      "z": 5,
      "name": "Wood_Deadwood_Planks",
      "rotation": 4
    },
    {
      "x": -17,
      "y": 16,
      "z": -1,
      "name": "Cloth_Block_Wool_Red",
      "rotation": 4
    },
    {
      "x": -17,
      "y": 11,
      "z": 1,
      "name": "Wood_Deadwood_Planks",
      "rotation": 4
    },
    {
      "x": -17,
      "y": 10,
      "z": 2,
      "name": "Wood_Deadwood_Planks",
      "rotation": 4
    },
    {
      "x": -17,
      "y": 11,
      "z": 2,
      "name": "Wood_Deadwood_Planks",
      "rotation": 4
    },
    {
      "x": -17,
      "y": 12,
      "z": 2,
      "name": "Wood_Deadwood_Planks",
      "rotation": 4
    },
    {
      "x": -17,
      "y": 13,
      "z": 2,
      "name": "Wood_Darkwood_Stairs",
      "rotation": 5
    },
    {
      "x": -17,
      "y": 10,
      "z": 3,
      "name": "Wood_Deadwood_Planks",
      "rotation": 4
    },
    {
      "x": -17,
      "y": 11,
      "z": 3,
      "name": "Wood_Deadwood_Planks",
      "rotation": 4
    },
    {
      "x": -17,
      "y": 12,
      "z": 3,
      "name": "Wood_Darkwood_Planks",
      "rotation": 4
    },
    {
      "x": -17,
      "y": 13,
      "z": 3,
      "name": "Wood_Deadwood_Planks",
      "rotation": 4
    },
    {
      "x": -17,
      "y": 9,
      "z": 4,
      "name": "Wood_Deadwood_Planks",
      "rotation": 4
    },
    {
      "x": -17,
      "y": 10,
      "z": 4,
      "name": "Wood_Deadwood_Planks",
      "rotation": 4
    },
    {
      "x": -17,
      "y": 11,
      "z": 4,
      "name": "Wood_Darkwood_Planks",
      "rotation": 4
    },
    {
      "x": -17,
      "y": 12,
      "z": 4,
      "name": "Wood_Deadwood_Planks",
      "rotation": 4
    },
    {
      "x": -17,
      "y": 13,
      "z": 4,
      "name": "Wood_Deadwood_Planks",
      "rotation": 4
    },
    {
      "x": -17,
      "y": 14,
      "z": 4,
      "name": "Wood_Deadwood_Planks",
      "rotation": 4
    },
    {
      "x": -17,
      "y": 9,
      "z": 5,
      "name": "Wood_Deadwood_Planks",
      "rotation": 4
    },
    {
      "x": -17,
      "y": 10,
      "z": 5,
      "name": "Wood_Darkwood_Planks",
      "rotation": 4
    },
    {
      "x": -17,
      "y": 11,
      "z": 5,
      "name": "Wood_Deadwood_Planks",
      "rotation": 4
    },
    {
      "x": -17,
      "y": 12,
      "z": 5,
      "name": "Wood_Deadwood_Planks",
      "rotation": 4
    },
    {
      "x": -17,
      "y": 13,
      "z": 5,
      "name": "Wood_Deadwood_Planks",
      "rotation": 4
    },
    {
      "x": -17,
      "y": 9,
      "z": 6,
      "name": "Wood_Darkwood_Planks"
    },
    {
      "x": -17,
      "y": 10,
      "z": 6,
      "name": "Wood_Deadwood_Planks",
      "rotation": 4
    },
    {
      "x": -17,
      "y": 11,
      "z": 6,
      "name": "Wood_Deadwood_Planks",
      "rotation": 4
    },
    {
      "x": -16,
      "y": 10,
      "z": 1,
      "name": "Wood_Deadwood_Planks",
      "rotation": 4
    },
    {
      "x": -16,
      "y": 11,
      "z": 1,
      "name": "Wood_Deadwood_Planks",
      "rotation": 4
    },
    {
      "x": -16,
      "y": 10,
      "z": 2,
      "name": "Wood_Deadwood_Planks",
      "rotation": 4
    },
    {
      "x": -16,
      "y": 11,
      "z": 2,
      "name": "Wood_Darkwood_Planks",
      "rotation": 4
    },
    {
      "x": -16,
      "y": 9,
      "z": 3,
      "name": "Wood_Deadwood_Planks",
      "rotation": 4
    },
    {
      "x": -16,
      "y": 10,
      "z": 3,
      "name": "Wood_Darkwood_Planks",
      "rotation": 4
    },
    {
      "x": -16,
      "y": 11,
      "z": 3,
      "name": "Wood_Darkwood_Planks",
      "rotation": 4
    },
    {
      "x": -16,
      "y": 12,
      "z": 3,
      "name": "Wood_Darkwood_Planks",
      "rotation": 4
    },
    {
      "x": -16,
      "y": 8,
      "z": 4,
      "name": "Wood_Deadwood_Planks",
      "rotation": 4
    },
    {
      "x": -16,
      "y": 11,
      "z": 4,
      "name": "Wood_Darkwood_Planks",
      "rotation": 4
    },
    {
      "x": -16,
      "y": 12,
      "z": 4,
      "name": "Wood_Darkwood_Planks",
      "rotation": 4
    },
    {
      "x": -16,
      "y": 13,
      "z": 4,
      "name": "Wood_Darkwood_Planks",
      "rotation": 4
    },
    {
      "x": -16,
      "y": 14,
      "z": 4,
      "name": "Wood_Deadwood_Planks",
      "rotation": 4
    },
    {
      "x": -16,
      "y": 8,
      "z": 5,
      "name": "Wood_Deadwood_Planks",
      "rotation": 4
    },
    {
      "x": -16,
      "y": 10,
      "z": 5,
      "name": "Wood_Darkwood_Planks",
      "rotation": 4
    },
    {
      "x": -16,
      "y": 12,
      "z": 5,
      "name": "Wood_Darkwood_Planks",
      "rotation": 4
    },
    {
      "x": -16,
      "y": 13,
      "z": 5,
      "name": "Wood_Deadwood_Planks",
      "rotation": 4
    },
    {
      "x": -16,
      "y": 14,
      "z": 5,
      "name": "Wood_Deadwood_Planks",
      "rotation": 4
    },
    {
      "x": -16,
      "y": 8,
      "z": 6,
      "name": "Wood_Deadwood_Planks",
      "rotation": 4
    },
    {
      "x": -16,
      "y": 9,
      "z": 6,
      "name": "Wood_Darkwood_Planks",
      "rotation": 4
    },
    {
      "x": -16,
      "y": 12,
      "z": 6,
      "name": "Wood_Deadwood_Planks",
      "rotation": 4
    },
    {
      "x": -16,
      "y": 8,
      "z": 7,
      "name": "Wood_Darkwood_Planks"
    },
    {
      "x": -16,
      "y": 9,
      "z": 7,
      "name": "Wood_Deadwood_Planks",
      "rotation": 4
    },
    {
      "x": -16,
      "y": 10,
      "z": 7,
      "name": "Wood_Deadwood_Planks",
      "rotation": 4
    },
    {
      "x": -16,
      "y": 11,
      "z": 7,
      "name": "Wood_Deadwood_Planks",
      "rotation": 4
    },
    {
      "x": -15,
      "y": 17,
      "z": -2,
      "name": "Cloth_Block_Wool_Red",
      "rotation": 4
    },
    {
      "x": -15,
      "y": 10,
      "z": 0,
      "name": "Wood_Deadwood_Planks",
      "rotation": 4
    },
    {
      "x": -15,
      "y": 10,
      "z": 1,
      "name": "Wood_Deadwood_Planks",
      "rotation": 4
    },
    {
      "x": -15,
      "y": 9,
      "z": 2,
      "name": "Wood_Deadwood_Planks",
      "rotation": 4
    },
    {
      "x": -15,
      "y": 10,
      "z": 2,
      "name": "Wood_Darkwood_Planks",
      "rotation": 4
    },
    {
      "x": -15,
      "y": 11,
      "z": 2,
      "name": "Wood_Darkwood_Planks",
      "rotation": 4
    },
    {
      "x": -15,
      "y": 8,
      "z": 3,
      "name": "Wood_Deadwood_Planks",
      "rotation": 4
    },
    {
      "x": -15,
      "y": 9,
      "z": 3,
      "name": "Wood_Deadwood_Planks",
      "rotation": 4
    },
    {
      "x": -15,
      "y": 10,
      "z": 3,
      "name": "Wood_Darkwood_Planks",
      "rotation": 4
    },
    {
      "x": -15,
      "y": 11,
      "z": 3,
      "name": "Wood_Darkwood_Planks",
      "rotation": 4
    },
    {
      "x": -15,
      "y": 12,
      "z": 3,
      "name": "Wood_Darkwood_Planks",
      "rotation": 4
    },
    {
      "x": -15,
      "y": 8,
      "z": 4,
      "name": "Wood_Deadwood_Planks",
      "rotation": 4
    },
    {
      "x": -15,
      "y": 11,
      "z": 4,
      "name": "Wood_Oak_Trunk",
      "support": 15,
      "rotation": 9
    },
    {
      "x": -15,
      "y": 12,
      "z": 4,
      "name": "Wood_Darkwood_Planks",
      "rotation": 4
    },
    {
      "x": -15,
      "y": 13,
      "z": 4,
      "name": "Wood_Darkwood_Planks",
      "rotation": 4
    },
    {
      "x": -15,
      "y": 7,
      "z": 5,
      "name": "Wood_Deadwood_Planks",
      "rotation": 4
    },
    {
      "x": -15,
      "y": 8,
      "z": 5,
      "name": "Wood_Darkwood_Planks",
      "rotation": 4
    },
    {
      "x": -15,
      "y": 12,
      "z": 5,
      "name": "Wood_Darkwood_Planks",
      "rotation": 4
    },
    {
      "x": -15,
      "y": 13,
      "z": 5,
      "name": "Wood_Darkwood_Planks",
      "rotation": 4
    },
    {
      "x": -15,
      "y": 14,
      "z": 5,
      "name": "Wood_Deadwood_Planks",
      "rotation": 4
    },
    {
      "x": -15,
      "y": 15,
      "z": 5,
      "name": "Wood_Deadwood_Planks",
      "rotation": 4
    },
    {
      "x": -15,
      "y": 7,
      "z": 6,
      "name": "Wood_Deadwood_Planks",
      "rotation": 4
    },
    {
      "x": -15,
      "y": 8,
      "z": 6,
      "name": "Wood_Darkwood_Planks",
      "rotation": 4
    },
    {
      "x": -15,
      "y": 9,
      "z": 6,
      "name": "Wood_Oak_Trunk",
      "support": 15,
      "rotation": 9
    },
    {
      "x": -15,
      "y": 12,
      "z": 6,
      "name": "Wood_Deadwood_Planks",
      "rotation": 4
    },
    {
      "x": -15,
      "y": 13,
      "z": 6,
      "name": "Wood_Deadwood_Planks",
      "rotation": 4
    },
    {
      "x": -15,
      "y": 8,
      "z": 7,
      "name": "Wood_Darkwood_Planks",
      "rotation": 4
    },
    {
      "x": -15,
      "y": 9,
      "z": 7,
      "name": "Wood_Darkwood_Planks",
      "rotation": 4
    },
    {
      "x": -15,
      "y": 10,
      "z": 7,
      "name": "Wood_Darkwood_Planks",
      "rotation": 4
    },
    {
      "x": -15,
      "y": 11,
      "z": 7,
      "name": "Wood_Deadwood_Planks",
      "rotation": 4
    },
    {
      "x": -15,
      "y": 12,
      "z": 7,
      "name": "Wood_Deadwood_Planks",
      "rotation": 4
    },
    {
      "x": -15,
      "y": 9,
      "z": 8,
      "name": "Wood_Deadwood_Planks",
      "rotation": 4
    },
    {
      "x": -15,
      "y": 10,
      "z": 8,
      "name": "Wood_Deadwood_Planks",
      "rotation": 4
    },
    {
      "x": -14,
      "y": 18,
      "z": -3,
      "name": "Cloth_Block_Wool_Red",
      "rotation": 4
    },
    {
      "x": -14,
      "y": 9,
      "z": 0,
      "name": "Wood_Deadwood_Planks",
      "rotation": 4
    },
    {
      "x": -14,
      "y": 10,
      "z": 0,
      "name": "Wood_Deadwood_Planks",
      "rotation": 4
    },
    {
      "x": -14,
      "y": 8,
      "z": 1,
      "name": "Wood_Redwood_Planks",
      "rotation": 4
    },
    {
      "x": -14,
      "y": 9,
      "z": 1,
      "name": "Wood_Deadwood_Planks",
      "rotation": 4
    },
    {
      "x": -14,
      "y": 10,
      "z": 1,
      "name": "Wood_Darkwood_Planks",
      "rotation": 4
    },
    {
      "x": -14,
      "y": 9,
      "z": 2,
      "name": "Wood_Darkwood_Planks",
      "rotation": 4
    },
    {
      "x": -14,
      "y": 10,
      "z": 2,
      "name": "Wood_Darkwood_Planks",
      "rotation": 4
    },
    {
      "x": -14,
      "y": 11,
      "z": 2,
      "name": "Wood_Darkwood_Planks",
      "rotation": 4
    },
    {
      "x": -14,
      "y": 8,
      "z": 3,
      "name": "Wood_Redwood_Planks",
      "rotation": 4
    },
    {
      "x": -14,
      "y": 10,
      "z": 3,
      "name": "Wood_Darkwood_Planks",
      "rotation": 4
    },
    {
      "x": -14,
      "y": 11,
      "z": 3,
      "name": "Wood_Darkwood_Planks",
      "rotation": 4
    },
    {
      "x": -14,
      "y": 12,
      "z": 3,
      "name": "Wood_Darkwood_Planks",
      "rotation": 4
    },
    {
      "x": -14,
      "y": 11,
      "z": 4,
      "name": "Wood_Oak_Trunk",
      "support": 15,
      "rotation": 9
    },
    {
      "x": -14,
      "y": 12,
      "z": 4,
      "name": "Wood_Darkwood_Planks",
      "rotation": 4
    },
    {
      "x": -14,
      "y": 13,
      "z": 4,
      "name": "Wood_Darkwood_Planks",
      "rotation": 4
    },
    {
      "x": -14,
      "y": 7,
      "z": 5,
      "name": "Wood_Deadwood_Planks",
      "rotation": 4
    },
    {
      "x": -14,
      "y": 8,
      "z": 5,
      "name": "Wood_Darkwood_Planks",
      "rotation": 4
    },
    {
      "x": -14,
      "y": 12,
      "z": 5,
      "name": "Wood_Darkwood_Planks",
      "rotation": 4
    },
    {
      "x": -14,
      "y": 13,
      "z": 5,
      "name": "Wood_Darkwood_Planks",
      "rotation": 4
    },
    {
      "x": -14,
      "y": 14,
      "z": 5,
      "name": "Wood_Darkwood_Planks",
      "rotation": 4
    },
    {
      "x": -14,
      "y": 15,
      "z": 5,
      "name": "Wood_Deadwood_Planks",
      "rotation": 4
    },
    {
      "x": -14,
      "y": 7,
      "z": 6,
      "name": "Wood_Deadwood_Planks",
      "rotation": 4
    },
    {
      "x": -14,
      "y": 8,
      "z": 6,
      "name": "Wood_Darkwood_Planks",
      "rotation": 4
    },
    {
      "x": -14,
      "y": 9,
      "z": 6,
      "name": "Wood_Oak_Trunk",
      "support": 15,
      "rotation": 9
    },
    {
      "x": -14,
      "y": 13,
      "z": 6,
      "name": "Wood_Redwood_Planks",
      "rotation": 4
    },
    {
      "x": -14,
      "y": 14,
      "z": 6,
      "name": "Wood_Deadwood_Planks",
      "rotation": 4
    },
    {
      "x": -14,
      "y": 15,
      "z": 6,
      "name": "Wood_Deadwood_Planks",
      "rotation": 4
    },
    {
      "x": -14,
      "y": 8,
      "z": 7,
      "name": "Wood_Darkwood_Planks",
      "rotation": 4
    },
    {
      "x": -14,
      "y": 9,
      "z": 7,
      "name": "Wood_Darkwood_Planks",
      "rotation": 4
    },
    {
      "x": -14,
      "y": 10,
      "z": 7,
      "name": "Wood_Darkwood_Planks",
      "rotation": 4
    },
    {
      "x": -14,
      "y": 12,
      "z": 7,
      "name": "Wood_Redwood_Planks",
      "rotation": 4
    },
    {
      "x": -14,
      "y": 14,
      "z": 7,
      "name": "Wood_Redwood_Planks",
      "rotation": 4
    },
    {
      "x": -14,
      "y": 9,
      "z": 8,
      "name": "Wood_Deadwood_Planks",
      "rotation": 4
    },
    {
      "x": -14,
      "y": 10,
      "z": 8,
      "name": "Wood_Deadwood_Planks",
      "rotation": 4
    },
    {
      "x": -14,
      "y": 11,
      "z": 8,
      "name": "Wood_Deadwood_Planks"
    },
    {
      "x": -13,
      "y": 15,
      "z": -7,
      "name": "Wood_Darkwood_Stairs",
      "rotation": 2
    },
    {
      "x": -13,
      "y": 15,
      "z": -6,
      "name": "Wood_Darkwood_Stairs",
      "rotation": 10
    },
    {
      "x": -13,
      "y": 16,
      "z": -6,
      "name": "Wood_Darkwood_Stairs",
      "rotation": 2
    },
    {
      "x": -13,
      "y": 16,
      "z": -5,
      "name": "Wood_Darkwood_Stairs",
      "rotation": 10
    },
    {
      "x": -13,
      "y": 17,
      "z": -5,
      "name": "Wood_Darkwood_Stairs",
      "rotation": 2
    },
    {
      "x": -13,
      "y": 19,
      "z": -5,
      "name": "Wood_Darkwood_Stairs",
      "rotation": 8
    },
    {
      "x": -13,
      "y": 20,
      "z": -5,
      "name": "Wood_Oak_Trunk",
      "support": 15
    },
    {
      "x": -13,
      "y": 17,
      "z": -4,
      "name": "Wood_Darkwood_Stairs",
      "rotation": 10
    },
    {
      "x": -13,
      "y": 18,
      "z": -4,
      "name": "Wood_Darkwood_Stairs",
      "rotation": 2
    },
    {
      "x": -13,
      "y": 19,
      "z": -4,
      "name": "Wood_Oak_Trunk",
      "support": 15,
      "rotation": 4
    },
    {
      "x": -13,
      "y": 20,
      "z": -4,
      "name": "Wood_Darkwood_Stairs"
    },
    {
      "x": -13,
      "y": 17,
      "z": -3,
      "name": "Wood_Darkwood_Stairs",
      "rotation": 8
    },
    {
      "x": -13,
      "y": 18,
      "z": -3,
      "name": "Wood_Oak_Trunk",
      "support": 15,
      "rotation": 4
    },
    {
      "x": -13,
      "y": 19,
      "z": -3,
      "name": "Wood_Darkwood_Stairs"
    },
    {
      "x": -13,
      "y": 16,
      "z": -2,
      "name": "Wood_Darkwood_Stairs",
      "rotation": 8
    },
    {
      "x": -13,
      "y": 17,
      "z": -2,
      "name": "Wood_Oak_Trunk",
      "support": 15,
      "rotation": 4
    },
    {
      "x": -13,
      "y": 18,
      "z": -2,
      "name": "Wood_Darkwood_Stairs"
    },
    {
      "x": -13,
      "y": 19,
      "z": -2,
      "name": "Wood_Darkwood_Stairs",
      "rotation": 10
    },
    {
      "x": -13,
      "y": 20,
      "z": -2,
      "name": "Wood_Darkwood_Stairs",
      "rotation": 2
    },
    {
      "x": -13,
      "y": 9,
      "z": -1,
      "name": "Wood_Deadwood_Planks",
      "rotation": 4
    },
    {
      "x": -13,
      "y": 10,
      "z": -1,
      "name": "Deco_Rope"
    },
    {
      "x": -13,
      "y": 11,
      "z": -1,
      "name": "Deco_Rope"
    },
    {
      "x": -13,
      "y": 12,
      "z": -1,
      "name": "Deco_Rope"
    },
    {
      "x": -13,
      "y": 13,
      "z": -1,
      "name": "Deco_Rope"
    },
    {
      "x": -13,
      "y": 14,
      "z": -1,
      "name": "Deco_Rope"
    },
    {
      "x": -13,
      "y": 15,
      "z": -1,
      "name": "Wood_Oak_Trunk",
      "support": 15
    },
    {
      "x": -13,
      "y": 16,
      "z": -1,
      "name": "Wood_Oak_Trunk",
      "support": 15,
      "rotation": 4
    },
    {
      "x": -13,
      "y": 17,
      "z": -1,
      "name": "Wood_Darkwood_Stairs"
    },
    {
      "x": -13,
      "y": 20,
      "z": -1,
      "name": "Wood_Darkwood_Stairs",
      "rotation": 10
    },
    {
      "x": -13,
      "y": 21,
      "z": -1,
      "name": "Wood_Darkwood_Stairs",
      "rotation": 2
    },
    {
      "x": -13,
      "y": 9,
      "z": 0,
      "name": "Wood_Deadwood_Planks",
      "rotation": 4
    },
    {
      "x": -13,
      "y": 10,
      "z": 0,
      "name": "Wood_Deadwood_Planks",
      "rotation": 4
    },
    {
      "x": -13,
      "y": 14,
      "z": 0,
      "name": "Wood_Darkwood_Stairs",
      "rotation": 8
    },
    {
      "x": -13,
      "y": 15,
      "z": 0,
      "name": "Wood_Oak_Trunk",
      "support": 15,
      "rotation": 4
    },
    {
      "x": -13,
      "y": 16,
      "z": 0,
      "name": "Wood_Oak_Trunk",
      "support": 15,
      "rotation": 4
    },
    {
      "x": -13,
      "y": 21,
      "z": 0,
      "name": "Wood_Darkwood_Stairs",
      "rotation": 10
    },
    {
      "x": -13,
      "y": 22,
      "z": 0,
      "name": "Wood_Darkwood_Stairs",
      "rotation": 2
    },
    {
      "x": -13,
      "y": 8,
      "z": 1,
      "name": "Wood_Redwood_Planks",
      "rotation": 4
    },
    {
      "x": -13,
      "y": 9,
      "z": 1,
      "name": "Wood_Deadwood_Planks",
      "rotation": 4
    },
    {
      "x": -13,
      "y": 13,
      "z": 1,
      "name": "Wood_Darkwood_Stairs",
      "rotation": 8
    },
    {
      "x": -13,
      "y": 14,
      "z": 1,
      "name": "Wood_Oak_Trunk",
      "support": 15,
      "rotation": 4
    },
    {
      "x": -13,
      "y": 15,
      "z": 1,
      "name": "Wood_Darkwood_Stairs"
    },
    {
      "x": -13,
      "y": 16,
      "z": 1,
      "name": "Deco_Rope",
      "rotation": 14
    },
    {
      "x": -13,
      "y": 7,
      "z": 2,
      "name": "Wood_Redwood_Planks",
      "rotation": 4
    },
    {
      "x": -13,
      "y": 8,
      "z": 2,
      "name": "Wood_Redwood_Planks",
      "rotation": 4
    },
    {
      "x": -13,
      "y": 9,
      "z": 2,
      "name": "Wood_Oak_Trunk",
      "support": 15,
      "rotation": 8
    },
    {
      "x": -13,
      "y": 10,
      "z": 2,
      "name": "Wood_Darkwood_Planks"
    },
    {
      "x": -13,
      "y": 12,
      "z": 2,
      "name": "Wood_Darkwood_Stairs",
      "rotation": 8
    },
    {
      "x": -13,
      "y": 13,
      "z": 2,
      "name": "Wood_Oak_Trunk",
      "support": 15,
      "rotation": 4
    },
    {
      "x": -13,
      "y": 14,
      "z": 2,
      "name": "Wood_Darkwood_Stairs"
    },
    {
      "x": -13,
      "y": 16,
      "z": 2,
      "name": "Deco_Rope",
      "support": 3,
      "rotation": 12
    },
    {
      "x": -13,
      "y": 10,
      "z": 3,
      "name": "Wood_Oak_Trunk",
      "support": 15,
      "rotation": 8
    },
    {
      "x": -13,
      "y": 11,
      "z": 3,
      "name": "Wood_Darkwood_Planks"
    },
    {
      "x": -13,
      "y": 12,
      "z": 3,
      "name": "Wood_Oak_Trunk",
      "support": 15,
      "rotation": 4
    },
    {
      "x": -13,
      "y": 13,
      "z": 3,
      "name": "Wood_Darkwood_Stairs"
    },
    {
      "x": -13,
      "y": 16,
      "z": 3,
      "name": "Deco_Rope",
      "support": 2,
      "rotation": 12
    },
    {
      "x": -13,
      "y": 7,
      "z": 4,
      "name": "Wood_Deadwood_Planks",
      "rotation": 4
    },
    {
      "x": -13,
      "y": 11,
      "z": 4,
      "name": "Wood_Oak_Trunk",
      "support": 15,
      "rotation": 4
    },
    {
      "x": -13,
      "y": 12,
      "z": 4,
      "name": "Wood_Darkwood_Planks"
    },
    {
      "x": -13,
      "y": 16,
      "z": 4,
      "name": "Deco_Rope",
      "support": 1,
      "rotation": 12
    },
    {
      "x": -13,
      "y": 7,
      "z": 5,
      "name": "Wood_Darkwood_Planks",
      "rotation": 4
    },
    {
      "x": -13,
      "y": 8,
      "z": 5,
      "name": "Wood_Darkwood_Planks",
      "rotation": 4
    },
    {
      "x": -13,
      "y": 10,
      "z": 5,
      "name": "Wood_Oak_Trunk",
      "support": 15,
      "rotation": 4
    },
    {
      "x": -13,
      "y": 12,
      "z": 5,
      "name": "Wood_Oak_Trunk",
      "support": 15,
      "rotation": 8
    },
    {
      "x": -13,
      "y": 13,
      "z": 5,
      "name": "Wood_Darkwood_Planks"
    },
    {
      "x": -13,
      "y": 15,
      "z": 5,
      "name": "Wood_Deadwood_Planks",
      "rotation": 4
    },
    {
      "x": -13,
      "y": 16,
      "z": 5,
      "name": "Deco_Rope",
      "rotation": 12
    },
    {
      "x": -13,
      "y": 8,
      "z": 6,
      "name": "Wood_Darkwood_Planks",
      "rotation": 4
    },
    {
      "x": -13,
      "y": 9,
      "z": 6,
      "name": "Wood_Oak_Trunk",
      "support": 15,
      "rotation": 9
    },
    {
      "x": -13,
      "y": 13,
      "z": 6,
      "name": "Wood_Oak_Trunk",
      "support": 15,
      "rotation": 8
    },
    {
      "x": -13,
      "y": 14,
      "z": 6,
      "name": "Wood_Deadwood_Planks",
      "rotation": 4
    },
    {
      "x": -13,
      "y": 15,
      "z": 6,
      "name": "Wood_Deadwood_Planks",
      "rotation": 4
    },
    {
      "x": -13,
      "y": 16,
      "z": 6,
      "name": "Wood_Deadwood_Planks",
      "rotation": 4
    },
    {
      "x": -13,
      "y": 7,
      "z": 7,
      "name": "Wood_Deadwood_Planks",
      "rotation": 4
    },
    {
      "x": -13,
      "y": 8,
      "z": 7,
      "name": "Wood_Darkwood_Planks",
      "rotation": 4
    },
    {
      "x": -13,
      "y": 9,
      "z": 7,
      "name": "Wood_Oak_Trunk",
      "support": 15,
      "rotation": 8
    },
    {
      "x": -13,
      "y": 10,
      "z": 7,
      "name": "Wood_Oak_Trunk",
      "support": 15,
      "rotation": 8
    },
    {
      "x": -13,
      "y": 12,
      "z": 7,
      "name": "Wood_Redwood_Planks",
      "rotation": 4
    },
    {
      "x": -13,
      "y": 13,
      "z": 7,
      "name": "Wood_Redwood_Planks",
      "rotation": 4
    },
    {
      "x": -13,
      "y": 14,
      "z": 7,
      "name": "Wood_Redwood_Planks",
      "rotation": 4
    },
    {
      "x": -13,
      "y": 8,
      "z": 8,
      "name": "Wood_Deadwood_Planks",
      "rotation": 4
    },
    {
      "x": -13,
      "y": 9,
      "z": 8,
      "name": "Wood_Deadwood_Planks",
      "rotation": 4
    },
    {
      "x": -13,
      "y": 10,
      "z": 8,
      "name": "Wood_Deadwood_Planks"
    },
    {
      "x": -13,
      "y": 11,
      "z": 8,
      "name": "Wood_Deadwood_Planks",
      "rotation": 4
    },
    {
      "x": -13,
      "y": 12,
      "z": 8,
      "name": "Wood_Deadwood_Planks"
    },
    {
      "x": -13,
      "y": 13,
      "z": 8,
      "name": "Wood_Redwood_Planks",
      "rotation": 4
    },
    {
      "x": -12,
      "y": 19,
      "z": -4,
      "name": "Deco_Rope",
      "rotation": 15
    },
    {
      "x": -12,
      "y": 9,
      "z": -1,
      "name": "Wood_Deadwood_Planks",
      "rotation": 4
    },
    {
      "x": -12,
      "y": 8,
      "z": 0,
      "name": "Wood_Deadwood_Planks",
      "rotation": 4
    },
    {
      "x": -12,
      "y": 9,
      "z": 0,
      "name": "Wood_Deadwood_Planks",
      "rotation": 4
    },
    {
      "x": -12,
      "y": 8,
      "z": 1,
      "name": "Wood_Oak_Trunk",
      "support": 15,
      "rotation": 9
    },
    {
      "x": -12,
      "y": 9,
      "z": 1,
      "name": "Wood_Deadwood_Planks",
      "rotation": 4
    },
    {
      "x": -12,
      "y": 7,
      "z": 2,
      "name": "Wood_Redwood_Planks",
      "rotation": 4
    },
    {
      "x": -12,
      "y": 8,
      "z": 2,
      "name": "Wood_Redwood_Planks",
      "rotation": 4
    },
    {
      "x": -12,
      "y": 9,
      "z": 2,
      "name": "Wood_Darkwood_Planks",
      "rotation": 4
    },
    {
      "x": -12,
      "y": 7,
      "z": 3,
      "name": "Wood_Deadwood_Planks",
      "rotation": 4
    },
    {
      "x": -12,
      "y": 10,
      "z": 3,
      "name": "Wood_Darkwood_Planks",
      "rotation": 4
    },
    {
      "x": -12,
      "y": 7,
      "z": 4,
      "name": "Wood_Deadwood_Planks",
      "rotation": 4
    },
    {
      "x": -12,
      "y": 11,
      "z": 4,
      "name": "Wood_Oak_Trunk",
      "support": 15,
      "rotation": 5
    },
    {
      "x": -12,
      "y": 7,
      "z": 5,
      "name": "Wood_Darkwood_Planks",
      "rotation": 4
    },
    {
      "x": -12,
      "y": 8,
      "z": 5,
      "name": "Wood_Darkwood_Planks",
      "rotation": 4
    },
    {
      "x": -12,
      "y": 12,
      "z": 5,
      "name": "Wood_Darkwood_Planks",
      "rotation": 4
    },
    {
      "x": -12,
      "y": 8,
      "z": 6,
      "name": "Wood_Darkwood_Planks",
      "rotation": 4
    },
    {
      "x": -12,
      "y": 9,
      "z": 6,
      "name": "Wood_Oak_Trunk",
      "support": 15,
      "rotation": 9
    },
    {
      "x": -12,
      "y": 13,
      "z": 6,
      "name": "Wood_Darkwood_Planks",
      "rotation": 4
    },
    {
      "x": -12,
      "y": 14,
      "z": 6,
      "name": "Wood_Deadwood_Planks",
      "rotation": 4
    },
    {
      "x": -12,
      "y": 15,
      "z": 6,
      "name": "Wood_Deadwood_Planks",
      "rotation": 4
    },
    {
      "x": -12,
      "y": 16,
      "z": 6,
      "name": "Wood_Deadwood_Planks",
      "rotation": 4
    },
    {
      "x": -12,
      "y": 7,
      "z": 7,
      "name": "Wood_Deadwood_Planks",
      "rotation": 4
    },
    {
      "x": -12,
      "y": 9,
      "z": 7,
      "name": "Wood_Darkwood_Planks",
      "rotation": 4
    },
    {
      "x": -12,
      "y": 10,
      "z": 7,
      "name": "Wood_Darkwood_Planks",
      "rotation": 4
    },
    {
      "x": -12,
      "y": 13,
      "z": 7,
      "name": "Wood_Redwood_Planks",
      "rotation": 4
    },
    {
      "x": -12,
      "y": 14,
      "z": 7,
      "name": "Wood_Oak_Trunk",
      "support": 15,
      "rotation": 9
    },
    {
      "x": -12,
      "y": 15,
      "z": 7,
      "name": "Wood_Deadwood_Planks",
      "rotation": 4
    },
    {
      "x": -12,
      "y": 7,
      "z": 8,
      "name": "Wood_Darkwood_Planks"
    },
    {
      "x": -12,
      "y": 8,
      "z": 8,
      "name": "Wood_Deadwood_Planks",
      "rotation": 4
    },
    {
      "x": -12,
      "y": 9,
      "z": 8,
      "name": "Wood_Deadwood_Planks"
    },
    {
      "x": -12,
      "y": 10,
      "z": 8,
      "name": "Wood_Deadwood_Planks"
    },
    {
      "x": -12,
      "y": 11,
      "z": 8,
      "name": "Wood_Deadwood_Planks",
      "rotation": 4
    },
    {
      "x": -12,
      "y": 12,
      "z": 8,
      "name": "Wood_Deadwood_Planks",
      "rotation": 4
    },
    {
      "x": -12,
      "y": 13,
      "z": 8,
      "name": "Wood_Redwood_Planks",
      "rotation": 4
    },
    {
      "x": -11,
      "y": 19,
      "z": -4,
      "name": "Deco_Rope",
      "support": 1,
      "rotation": 15
    },
    {
      "x": -11,
      "y": 8,
      "z": 0,
      "name": "Wood_Deadwood_Planks",
      "rotation": 4
    },
    {
      "x": -11,
      "y": 7,
      "z": 1,
      "name": "Wood_Redwood_Planks",
      "rotation": 4
    },
    {
      "x": -11,
      "y": 8,
      "z": 1,
      "name": "Wood_Oak_Trunk",
      "support": 15,
      "rotation": 5
    },
    {
      "x": -11,
      "y": 6,
      "z": 2,
      "name": "Wood_Deadwood_Planks",
      "rotation": 4
    },
    {
      "x": -11,
      "y": 9,
      "z": 2,
      "name": "Wood_Darkwood_Planks",
      "rotation": 4
    },
    {
      "x": -11,
      "y": 6,
      "z": 3,
      "name": "Wood_Redwood_Planks",
      "rotation": 4
    },
    {
      "x": -11,
      "y": 10,
      "z": 3,
      "name": "Wood_Darkwood_Planks",
      "rotation": 4
    },
    {
      "x": -11,
      "y": 6,
      "z": 4,
      "name": "Wood_Redwood_Planks",
      "rotation": 4
    },
    {
      "x": -11,
      "y": 7,
      "z": 4,
      "name": "Wood_Darkwood_Planks",
      "rotation": 4
    },
    {
      "x": -11,
      "y": 11,
      "z": 4,
      "name": "Wood_Oak_Trunk",
      "support": 15,
      "rotation": 5
    },
    {
      "x": -11,
      "y": 6,
      "z": 5,
      "name": "Wood_Redwood_Planks",
      "rotation": 4
    },
    {
      "x": -11,
      "y": 7,
      "z": 5,
      "name": "Wood_Darkwood_Planks",
      "rotation": 4
    },
    {
      "x": -11,
      "y": 8,
      "z": 5,
      "name": "Wood_Darkwood_Planks",
      "rotation": 4
    },
    {
      "x": -11,
      "y": 12,
      "z": 5,
      "name": "Wood_Darkwood_Planks",
      "rotation": 4
    },
    {
      "x": -11,
      "y": 6,
      "z": 6,
      "name": "Wood_Deadwood_Planks",
      "rotation": 4
    },
    {
      "x": -11,
      "y": 8,
      "z": 6,
      "name": "Wood_Darkwood_Planks",
      "rotation": 4
    },
    {
      "x": -11,
      "y": 9,
      "z": 6,
      "name": "Wood_Oak_Trunk",
      "support": 15,
      "rotation": 9
    },
    {
      "x": -11,
      "y": 13,
      "z": 6,
      "name": "Wood_Darkwood_Planks",
      "rotation": 4
    },
    {
      "x": -11,
      "y": 6,
      "z": 7,
      "name": "Wood_Deadwood_Planks",
      "rotation": 4
    },
    {
      "x": -11,
      "y": 7,
      "z": 7,
      "name": "Wood_Deadwood_Planks",
      "rotation": 4
    },
    {
      "x": -11,
      "y": 9,
      "z": 7,
      "name": "Wood_Darkwood_Planks",
      "rotation": 4
    },
    {
      "x": -11,
      "y": 10,
      "z": 7,
      "name": "Wood_Darkwood_Planks",
      "rotation": 4
    },
    {
      "x": -11,
      "y": 14,
      "z": 7,
      "name": "Wood_Oak_Trunk",
      "support": 15,
      "rotation": 9
    },
    {
      "x": -11,
      "y": 15,
      "z": 7,
      "name": "Wood_Deadwood_Planks",
      "rotation": 4
    },
    {
      "x": -11,
      "y": 6,
      "z": 8,
      "name": "Wood_Deadwood_Planks",
      "rotation": 4
    },
    {
      "x": -11,
      "y": 7,
      "z": 8,
      "name": "Wood_Darkwood_Planks",
      "rotation": 4
    },
    {
      "x": -11,
      "y": 8,
      "z": 8,
      "name": "Wood_Deadwood_Planks",
      "rotation": 4
    },
    {
      "x": -11,
      "y": 10,
      "z": 8,
      "name": "Wood_Darkwood_Planks",
      "rotation": 4
    },
    {
      "x": -11,
      "y": 11,
      "z": 8,
      "name": "Wood_Darkwood_Planks",
      "rotation": 4
    },
    {
      "x": -11,
      "y": 12,
      "z": 8,
      "name": "Wood_Deadwood_Planks",
      "rotation": 4
    },
    {
      "x": -11,
      "y": 14,
      "z": 8,
      "name": "Wood_Redwood_Planks",
      "rotation": 4
    },
    {
      "x": -11,
      "y": 7,
      "z": 9,
      "name": "Wood_Deadwood_Planks",
      "rotation": 4
    },
    {
      "x": -11,
      "y": 8,
      "z": 9,
      "name": "Wood_Deadwood_Planks",
      "rotation": 4
    },
    {
      "x": -11,
      "y": 9,
      "z": 9,
      "name": "Wood_Deadwood_Planks",
      "rotation": 4
    },
    {
      "x": -11,
      "y": 10,
      "z": 9,
      "name": "Wood_Deadwood_Planks"
    },
    {
      "x": -11,
      "y": 11,
      "z": 9,
      "name": "Wood_Redwood_Planks",
      "rotation": 4
    },
    {
      "x": -11,
      "y": 12,
      "z": 9,
      "name": "Wood_Redwood_Planks",
      "rotation": 4
    },
    {
      "x": -11,
      "y": 13,
      "z": 9,
      "name": "Wood_Deadwood_Planks",
      "rotation": 4
    },
    {
      "x": -10,
      "y": 19,
      "z": -4,
      "name": "Deco_Rope",
      "support": 2,
      "rotation": 15
    },
    {
      "x": -10,
      "y": 8,
      "z": 0,
      "name": "Wood_Deadwood_Planks",
      "rotation": 4
    },
    {
      "x": -10,
      "y": 7,
      "z": 1,
      "name": "Wood_Redwood_Planks",
      "rotation": 4
    },
    {
      "x": -10,
      "y": 8,
      "z": 1,
      "name": "Wood_Oak_Trunk",
      "support": 15,
      "rotation": 5
    },
    {
      "x": -10,
      "y": 6,
      "z": 2,
      "name": "Wood_Deadwood_Planks",
      "rotation": 4
    },
    {
      "x": -10,
      "y": 9,
      "z": 2,
      "name": "Wood_Darkwood_Planks",
      "rotation": 4
    },
    {
      "x": -10,
      "y": 5,
      "z": 3,
      "name": "Wood_Redwood_Planks",
      "rotation": 4
    },
    {
      "x": -10,
      "y": 6,
      "z": 3,
      "name": "Wood_Oak_Trunk",
      "support": 15,
      "rotation": 9
    },
    {
      "x": -10,
      "y": 9,
      "z": 3,
      "name": "Wood_Darkwood_Stairs",
      "rotation": 12
    },
    {
      "x": -10,
      "y": 5,
      "z": 4,
      "name": "Wood_Redwood_Planks",
      "rotation": 4
    },
    {
      "x": -10,
      "y": 6,
      "z": 4,
      "name": "Wood_Oak_Trunk",
      "support": 15,
      "rotation": 9
    },
    {
      "x": -10,
      "y": 7,
      "z": 4,
      "name": "Wood_Darkwood_Planks",
      "rotation": 4
    },
    {
      "x": -10,
      "y": 9,
      "z": 4,
      "name": "Wood_Darkwood_Stairs",
      "rotation": 4
    },
    {
      "x": -10,
      "y": 10,
      "z": 4,
      "name": "Wood_Darkwood_Stairs",
      "rotation": 4
    },
    {
      "x": -10,
      "y": 6,
      "z": 5,
      "name": "Wood_Redwood_Planks",
      "rotation": 4
    },
    {
      "x": -10,
      "y": 7,
      "z": 5,
      "name": "Wood_Darkwood_Planks",
      "rotation": 4
    },
    {
      "x": -10,
      "y": 8,
      "z": 5,
      "name": "Wood_Darkwood_Planks",
      "rotation": 4
    },
    {
      "x": -10,
      "y": 9,
      "z": 5,
      "name": "Wood_Darkwood_Stairs",
      "rotation": 12
    },
    {
      "x": -10,
      "y": 6,
      "z": 6,
      "name": "Wood_Deadwood_Planks",
      "rotation": 4
    },
    {
      "x": -10,
      "y": 8,
      "z": 6,
      "name": "Wood_Darkwood_Planks",
      "rotation": 4
    },
    {
      "x": -10,
      "y": 9,
      "z": 6,
      "name": "Wood_Oak_Trunk",
      "support": 15,
      "rotation": 9
    },
    {
      "x": -10,
      "y": 13,
      "z": 6,
      "name": "Wood_Darkwood_Planks",
      "rotation": 4
    },
    {
      "x": -10,
      "y": 6,
      "z": 7,
      "name": "Wood_Deadwood_Planks",
      "rotation": 4
    },
    {
      "x": -10,
      "y": 7,
      "z": 7,
      "name": "Wood_Deadwood_Planks",
      "rotation": 4
    },
    {
      "x": -10,
      "y": 9,
      "z": 7,
      "name": "Wood_Darkwood_Planks",
      "rotation": 4
    },
    {
      "x": -10,
      "y": 10,
      "z": 7,
      "name": "Wood_Darkwood_Planks",
      "rotation": 4
    },
    {
      "x": -10,
      "y": 14,
      "z": 7,
      "name": "Wood_Oak_Trunk",
      "support": 15,
      "rotation": 9
    },
    {
      "x": -10,
      "y": 15,
      "z": 7,
      "name": "Wood_Deadwood_Planks",
      "rotation": 4
    },
    {
      "x": -10,
      "y": 6,
      "z": 8,
      "name": "Wood_Deadwood_Planks",
      "rotation": 4
    },
    {
      "x": -10,
      "y": 7,
      "z": 8,
      "name": "Wood_Darkwood_Planks",
      "rotation": 4
    },
    {
      "x": -10,
      "y": 8,
      "z": 8,
      "name": "Wood_Deadwood_Planks",
      "rotation": 4
    },
    {
      "x": -10,
      "y": 10,
      "z": 8,
      "name": "Wood_Darkwood_Planks",
      "rotation": 4
    },
    {
      "x": -10,
      "y": 11,
      "z": 8,
      "name": "Wood_Darkwood_Planks",
      "rotation": 4
    },
    {
      "x": -10,
      "y": 14,
      "z": 8,
      "name": "Wood_Redwood_Planks",
      "rotation": 4
    },
    {
      "x": -10,
      "y": 7,
      "z": 9,
      "name": "Wood_Deadwood_Planks",
      "rotation": 4
    },
    {
      "x": -10,
      "y": 8,
      "z": 9,
      "name": "Wood_Deadwood_Planks",
      "rotation": 4
    },
    {
      "x": -10,
      "y": 9,
      "z": 9,
      "name": "Wood_Deadwood_Planks",
      "rotation": 4
    },
    {
      "x": -10,
      "y": 10,
      "z": 9,
      "name": "Wood_Redwood_Planks",
      "rotation": 4
    },
    {
      "x": -10,
      "y": 11,
      "z": 9,
      "name": "Wood_Oak_Trunk",
      "support": 15,
      "rotation": 9
    },
    {
      "x": -10,
      "y": 12,
      "z": 9,
      "name": "Wood_Oak_Trunk",
      "support": 15,
      "rotation": 9
    },
    {
      "x": -10,
      "y": 13,
      "z": 9,
      "name": "Wood_Deadwood_Planks",
      "rotation": 4
    },
    {
      "x": -10,
      "y": 11,
      "z": 10,
      "name": "Wood_Redwood_Planks",
      "rotation": 4
    },
    {
      "x": -10,
      "y": 12,
      "z": 10,
      "name": "Wood_Redwood_Planks",
      "rotation": 4
    },
    {
      "x": -9,
      "y": 19,
      "z": -4,
      "name": "Deco_Rope",
      "support": 3,
      "rotation": 15
    },
    {
      "x": -9,
      "y": 8,
      "z": 0,
      "name": "Wood_Deadwood_Planks",
      "rotation": 4
    },
    {
      "x": -9,
      "y": 7,
      "z": 1,
      "name": "Wood_Redwood_Planks",
      "rotation": 4
    },
    {
      "x": -9,
      "y": 8,
      "z": 1,
      "name": "Wood_Oak_Trunk",
      "support": 15,
      "rotation": 5
    },
    {
      "x": -9,
      "y": 6,
      "z": 2,
      "name": "Wood_Deadwood_Planks",
      "rotation": 4
    },
    {
      "x": -9,
      "y": 9,
      "z": 2,
      "name": "Wood_Darkwood_Planks",
      "rotation": 4
    },
    {
      "x": -9,
      "y": 5,
      "z": 3,
      "name": "Wood_Redwood_Planks",
      "rotation": 4
    },
    {
      "x": -9,
      "y": 6,
      "z": 3,
      "name": "Wood_Oak_Trunk",
      "support": 15,
      "rotation": 9
    },
    {
      "x": -9,
      "y": 9,
      "z": 3,
      "name": "Wood_Darkwood_Stairs",
      "rotation": 12
    },
    {
      "x": -9,
      "y": 5,
      "z": 4,
      "name": "Wood_Redwood_Planks",
      "rotation": 4
    },
    {
      "x": -9,
      "y": 6,
      "z": 4,
      "name": "Wood_Oak_Trunk",
      "support": 15,
      "rotation": 9
    },
    {
      "x": -9,
      "y": 7,
      "z": 4,
      "name": "Wood_Darkwood_Planks",
      "rotation": 4
    },
    {
      "x": -9,
      "y": 9,
      "z": 4,
      "name": "Wood_Darkwood_Stairs",
      "rotation": 4
    },
    {
      "x": -9,
      "y": 10,
      "z": 4,
      "name": "Wood_Darkwood_Stairs",
      "rotation": 4
    },
    {
      "x": -9,
      "y": 6,
      "z": 5,
      "name": "Wood_Redwood_Planks",
      "rotation": 4
    },
    {
      "x": -9,
      "y": 7,
      "z": 5,
      "name": "Wood_Darkwood_Planks",
      "rotation": 4
    },
    {
      "x": -9,
      "y": 8,
      "z": 5,
      "name": "Wood_Darkwood_Planks",
      "rotation": 4
    },
    {
      "x": -9,
      "y": 9,
      "z": 5,
      "name": "Wood_Darkwood_Stairs",
      "rotation": 12
    },
    {
      "x": -9,
      "y": 6,
      "z": 6,
      "name": "Wood_Deadwood_Planks",
      "rotation": 4
    },
    {
      "x": -9,
      "y": 8,
      "z": 6,
      "name": "Wood_Darkwood_Planks",
      "rotation": 4
    },
    {
      "x": -9,
      "y": 9,
      "z": 6,
      "name": "Wood_Oak_Trunk",
      "support": 15,
      "rotation": 9
    },
    {
      "x": -9,
      "y": 13,
      "z": 6,
      "name": "Wood_Darkwood_Planks",
      "rotation": 4
    },
    {
      "x": -9,
      "y": 6,
      "z": 7,
      "name": "Wood_Deadwood_Planks",
      "rotation": 4
    },
    {
      "x": -9,
      "y": 7,
      "z": 7,
      "name": "Wood_Deadwood_Planks",
      "rotation": 4
    },
    {
      "x": -9,
      "y": 9,
      "z": 7,
      "name": "Wood_Darkwood_Planks",
      "rotation": 4
    },
    {
      "x": -9,
      "y": 10,
      "z": 7,
      "name": "Wood_Darkwood_Planks",
      "rotation": 4
    },
    {
      "x": -9,
      "y": 14,
      "z": 7,
      "name": "Wood_Oak_Trunk",
      "support": 15,
      "rotation": 9
    },
    {
      "x": -9,
      "y": 15,
      "z": 7,
      "name": "Wood_Deadwood_Planks",
      "rotation": 4
    },
    {
      "x": -9,
      "y": 6,
      "z": 8,
      "name": "Wood_Deadwood_Planks",
      "rotation": 4
    },
    {
      "x": -9,
      "y": 7,
      "z": 8,
      "name": "Wood_Darkwood_Planks",
      "rotation": 4
    },
    {
      "x": -9,
      "y": 8,
      "z": 8,
      "name": "Wood_Deadwood_Planks",
      "rotation": 4
    },
    {
      "x": -9,
      "y": 10,
      "z": 8,
      "name": "Wood_Darkwood_Planks",
      "rotation": 4
    },
    {
      "x": -9,
      "y": 11,
      "z": 8,
      "name": "Wood_Darkwood_Planks",
      "rotation": 4
    },
    {
      "x": -9,
      "y": 14,
      "z": 8,
      "name": "Wood_Redwood_Planks",
      "rotation": 4
    },
    {
      "x": -9,
      "y": 7,
      "z": 9,
      "name": "Wood_Deadwood_Planks",
      "rotation": 4
    },
    {
      "x": -9,
      "y": 8,
      "z": 9,
      "name": "Wood_Deadwood_Planks",
      "rotation": 4
    },
    {
      "x": -9,
      "y": 9,
      "z": 9,
      "name": "Wood_Deadwood_Planks",
      "rotation": 4
    },
    {
      "x": -9,
      "y": 10,
      "z": 9,
      "name": "Wood_Redwood_Planks",
      "rotation": 4
    },
    {
      "x": -9,
      "y": 11,
      "z": 9,
      "name": "Wood_Oak_Trunk",
      "support": 15,
      "rotation": 9
    },
    {
      "x": -9,
      "y": 12,
      "z": 9,
      "name": "Wood_Oak_Trunk",
      "support": 15,
      "rotation": 9
    },
    {
      "x": -9,
      "y": 13,
      "z": 9,
      "name": "Wood_Deadwood_Planks",
      "rotation": 4
    },
    {
      "x": -9,
      "y": 11,
      "z": 10,
      "name": "Wood_Redwood_Planks",
      "rotation": 4
    },
    {
      "x": -9,
      "y": 12,
      "z": 10,
      "name": "Wood_Redwood_Planks",
      "rotation": 4
    },
    {
      "x": -8,
      "y": 19,
      "z": -4,
      "name": "Deco_Rope",
      "support": 4,
      "rotation": 15
    },
    {
      "x": -8,
      "y": 8,
      "z": 0,
      "name": "Wood_Deadwood_Planks",
      "rotation": 4
    },
    {
      "x": -8,
      "y": 5,
      "z": 1,
      "name": "Furniture_Tavern_Shelf",
      "rotation": 6
    },
    {
      "x": -8,
      "y": 8,
      "z": 1,
      "name": "Wood_Oak_Trunk",
      "support": 15,
      "rotation": 5
    },
    {
      "x": -8,
      "y": 6,
      "z": 2,
      "name": "Wood_Deadwood_Planks",
      "rotation": 4
    },
    {
      "x": -8,
      "y": 9,
      "z": 2,
      "name": "Wood_Darkwood_Planks",
      "rotation": 4
    },
    {
      "x": -8,
      "y": 5,
      "z": 3,
      "name": "Wood_Redwood_Planks",
      "rotation": 4
    },
    {
      "x": -8,
      "y": 6,
      "z": 3,
      "name": "Wood_Oak_Trunk",
      "support": 15,
      "rotation": 9
    },
    {
      "x": -8,
      "y": 9,
      "z": 3,
      "name": "Wood_Darkwood_Stairs",
      "rotation": 12
    },
    {
      "x": -8,
      "y": 5,
      "z": 4,
      "name": "Wood_Redwood_Planks",
      "rotation": 4
    },
    {
      "x": -8,
      "y": 6,
      "z": 4,
      "name": "Wood_Oak_Trunk",
      "support": 15,
      "rotation": 9
    },
    {
      "x": -8,
      "y": 7,
      "z": 4,
      "name": "Wood_Darkwood_Planks",
      "rotation": 4
    },
    {
      "x": -8,
      "y": 9,
      "z": 4,
      "name": "Wood_Darkwood_Stairs",
      "rotation": 4
    },
    {
      "x": -8,
      "y": 10,
      "z": 4,
      "name": "Wood_Darkwood_Stairs",
      "rotation": 4
    },
    {
      "x": -8,
      "y": 6,
      "z": 5,
      "name": "Wood_Redwood_Planks",
      "rotation": 4
    },
    {
      "x": -8,
      "y": 7,
      "z": 5,
      "name": "Wood_Darkwood_Planks",
      "rotation": 4
    },
    {
      "x": -8,
      "y": 8,
      "z": 5,
      "name": "Wood_Darkwood_Planks",
      "rotation": 4
    },
    {
      "x": -8,
      "y": 9,
      "z": 5,
      "name": "Wood_Darkwood_Stairs",
      "rotation": 12
    },
    {
      "x": -8,
      "y": 6,
      "z": 6,
      "name": "Wood_Deadwood_Planks",
      "rotation": 4
    },
    {
      "x": -8,
      "y": 8,
      "z": 6,
      "name": "Wood_Darkwood_Planks",
      "rotation": 4
    },
    {
      "x": -8,
      "y": 9,
      "z": 6,
      "name": "Wood_Oak_Trunk",
      "support": 15,
      "rotation": 9
    },
    {
      "x": -8,
      "y": 13,
      "z": 6,
      "name": "Wood_Darkwood_Planks",
      "rotation": 4
    },
    {
      "x": -8,
      "y": 5,
      "z": 7,
      "name": "Wood_Deadwood_Planks",
      "rotation": 4
    },
    {
      "x": -8,
      "y": 6,
      "z": 7,
      "name": "Wood_Deadwood_Planks",
      "rotation": 4
    },
    {
      "x": -8,
      "y": 9,
      "z": 7,
      "name": "Wood_Darkwood_Planks",
      "rotation": 4
    },
    {
      "x": -8,
      "y": 10,
      "z": 7,
      "name": "Wood_Darkwood_Planks",
      "rotation": 4
    },
    {
      "x": -8,
      "y": 14,
      "z": 7,
      "name": "Wood_Oak_Trunk",
      "support": 15,
      "rotation": 9
    },
    {
      "x": -8,
      "y": 15,
      "z": 7,
      "name": "Wood_Deadwood_Planks",
      "rotation": 4
    },
    {
      "x": -8,
      "y": 6,
      "z": 8,
      "name": "Wood_Deadwood_Planks",
      "rotation": 4
    },
    {
      "x": -8,
      "y": 7,
      "z": 8,
      "name": "Wood_Darkwood_Planks",
      "rotation": 4
    },
    {
      "x": -8,
      "y": 10,
      "z": 8,
      "name": "Wood_Darkwood_Planks",
      "rotation": 4
    },
    {
      "x": -8,
      "y": 11,
      "z": 8,
      "name": "Wood_Darkwood_Planks",
      "rotation": 4
    },
    {
      "x": -8,
      "y": 7,
      "z": 9,
      "name": "Wood_Deadwood_Planks",
      "rotation": 4
    },
    {
      "x": -8,
      "y": 8,
      "z": 9,
      "name": "Wood_Deadwood_Planks",
      "rotation": 4
    },
    {
      "x": -8,
      "y": 9,
      "z": 9,
      "name": "Wood_Deadwood_Planks",
      "rotation": 4
    },
    {
      "x": -8,
      "y": 10,
      "z": 9,
      "name": "Wood_Redwood_Planks",
      "rotation": 4
    },
    {
      "x": -8,
      "y": 11,
      "z": 9,
      "name": "Wood_Oak_Trunk",
      "support": 15,
      "rotation": 9
    },
    {
      "x": -8,
      "y": 12,
      "z": 9,
      "name": "Wood_Oak_Trunk",
      "support": 15,
      "rotation": 9
    },
    {
      "x": -8,
      "y": 13,
      "z": 9,
      "name": "Wood_Deadwood_Planks",
      "rotation": 4
    },
    {
      "x": -8,
      "y": 8,
      "z": 10,
      "name": "Wood_Deadwood_Planks",
      "rotation": 4
    },
    {
      "x": -8,
      "y": 11,
      "z": 10,
      "name": "Wood_Redwood_Planks",
      "rotation": 4
    },
    {
      "x": -8,
      "y": 12,
      "z": 10,
      "name": "Wood_Redwood_Planks",
      "rotation": 4
    },
    {
      "x": -7,
      "y": 19,
      "z": -4,
      "name": "Deco_Rope",
      "rotation": 15
    },
    {
      "x": -7,
      "y": 8,
      "z": 0,
      "name": "Wood_Deadwood_Planks",
      "rotation": 4
    },
    {
      "x": -7,
      "y": 7,
      "z": 1,
      "name": "Wood_Redwood_Planks",
      "rotation": 4
    },
    {
      "x": -7,
      "y": 8,
      "z": 1,
      "name": "Wood_Oak_Trunk",
      "support": 15,
      "rotation": 5
    },
    {
      "x": -7,
      "y": 6,
      "z": 2,
      "name": "Wood_Deadwood_Planks",
      "rotation": 4
    },
    {
      "x": -7,
      "y": 9,
      "z": 2,
      "name": "Wood_Darkwood_Planks",
      "rotation": 4
    },
    {
      "x": -7,
      "y": 5,
      "z": 3,
      "name": "Wood_Redwood_Planks",
      "rotation": 4
    },
    {
      "x": -7,
      "y": 6,
      "z": 3,
      "name": "Wood_Oak_Trunk",
      "support": 15,
      "rotation": 9
    },
    {
      "x": -7,
      "y": 10,
      "z": 3,
      "name": "Wood_Darkwood_Planks",
      "rotation": 4
    },
    {
      "x": -7,
      "y": 5,
      "z": 4,
      "name": "Wood_Redwood_Planks",
      "rotation": 4
    },
    {
      "x": -7,
      "y": 6,
      "z": 4,
      "name": "Wood_Oak_Trunk",
      "support": 15,
      "rotation": 9
    },
    {
      "x": -7,
      "y": 7,
      "z": 4,
      "name": "Wood_Darkwood_Planks",
      "rotation": 4
    },
    {
      "x": -7,
      "y": 11,
      "z": 4,
      "name": "Wood_Oak_Trunk",
      "support": 15,
      "rotation": 5
    },
    {
      "x": -7,
      "y": 6,
      "z": 5,
      "name": "Wood_Redwood_Planks",
      "rotation": 4
    },
    {
      "x": -7,
      "y": 7,
      "z": 5,
      "name": "Wood_Darkwood_Planks",
      "rotation": 4
    },
    {
      "x": -7,
      "y": 8,
      "z": 5,
      "name": "Wood_Darkwood_Planks",
      "rotation": 4
    },
    {
      "x": -7,
      "y": 12,
      "z": 5,
      "name": "Wood_Darkwood_Planks",
      "rotation": 4
    },
    {
      "x": -7,
      "y": 6,
      "z": 6,
      "name": "Wood_Deadwood_Planks",
      "rotation": 4
    },
    {
      "x": -7,
      "y": 8,
      "z": 6,
      "name": "Wood_Darkwood_Planks",
      "rotation": 4
    },
    {
      "x": -7,
      "y": 9,
      "z": 6,
      "name": "Wood_Oak_Trunk",
      "support": 15,
      "rotation": 9
    },
    {
      "x": -7,
      "y": 13,
      "z": 6,
      "name": "Wood_Darkwood_Planks",
      "rotation": 4
    },
    {
      "x": -7,
      "y": 5,
      "z": 7,
      "name": "Wood_Deadwood_Planks",
      "rotation": 4
    },
    {
      "x": -7,
      "y": 6,
      "z": 7,
      "name": "Wood_Deadwood_Planks",
      "rotation": 4
    },
    {
      "x": -7,
      "y": 9,
      "z": 7,
      "name": "Wood_Darkwood_Planks",
      "rotation": 4
    },
    {
      "x": -7,
      "y": 10,
      "z": 7,
      "name": "Wood_Darkwood_Planks",
      "rotation": 4
    },
    {
      "x": -7,
      "y": 14,
      "z": 7,
      "name": "Wood_Oak_Trunk",
      "support": 15,
      "rotation": 9
    },
    {
      "x": -7,
      "y": 15,
      "z": 7,
      "name": "Wood_Deadwood_Planks",
      "rotation": 4
    },
    {
      "x": -7,
      "y": 6,
      "z": 8,
      "name": "Wood_Deadwood_Planks",
      "rotation": 4
    },
    {
      "x": -7,
      "y": 7,
      "z": 8,
      "name": "Wood_Darkwood_Planks",
      "rotation": 4
    },
    {
      "x": -7,
      "y": 10,
      "z": 8,
      "name": "Wood_Darkwood_Planks",
      "rotation": 4
    },
    {
      "x": -7,
      "y": 11,
      "z": 8,
      "name": "Wood_Darkwood_Planks",
      "rotation": 4
    },
    {
      "x": -7,
      "y": 14,
      "z": 8,
      "name": "Wood_Redwood_Planks",
      "rotation": 4
    },
    {
      "x": -7,
      "y": 7,
      "z": 9,
      "name": "Wood_Deadwood_Planks",
      "rotation": 4
    },
    {
      "x": -7,
      "y": 8,
      "z": 9,
      "name": "Wood_Deadwood_Planks",
      "rotation": 4
    },
    {
      "x": -7,
      "y": 9,
      "z": 9,
      "name": "Wood_Deadwood_Planks",
      "rotation": 4
    },
    {
      "x": -7,
      "y": 10,
      "z": 9,
      "name": "Wood_Redwood_Planks",
      "rotation": 4
    },
    {
      "x": -7,
      "y": 11,
      "z": 9,
      "name": "Wood_Oak_Trunk",
      "support": 15,
      "rotation": 9
    },
    {
      "x": -7,
      "y": 12,
      "z": 9,
      "name": "Wood_Oak_Trunk",
      "support": 15,
      "rotation": 9
    },
    {
      "x": -7,
      "y": 13,
      "z": 9,
      "name": "Wood_Deadwood_Planks",
      "rotation": 4
    },
    {
      "x": -7,
      "y": 8,
      "z": 10,
      "name": "Wood_Deadwood_Planks",
      "rotation": 4
    },
    {
      "x": -7,
      "y": 11,
      "z": 10,
      "name": "Wood_Redwood_Planks",
      "rotation": 4
    },
    {
      "x": -7,
      "y": 12,
      "z": 10,
      "name": "Wood_Redwood_Planks",
      "rotation": 4
    },
    {
      "x": -6,
      "y": 19,
      "z": -4,
      "name": "Deco_Rope",
      "support": 4,
      "rotation": 15
    },
    {
      "x": -6,
      "y": 8,
      "z": 0,
      "name": "Wood_Deadwood_Planks",
      "rotation": 4
    },
    {
      "x": -6,
      "y": 5,
      "z": 1,
      "name": "Furniture_Tavern_Shelf",
      "rotation": 6
    },
    {
      "x": -6,
      "y": 8,
      "z": 1,
      "name": "Wood_Oak_Trunk",
      "support": 15,
      "rotation": 5
    },
    {
      "x": -6,
      "y": 6,
      "z": 2,
      "name": "Wood_Deadwood_Planks",
      "rotation": 4
    },
    {
      "x": -6,
      "y": 9,
      "z": 2,
      "name": "Wood_Darkwood_Planks",
      "rotation": 4
    },
    {
      "x": -6,
      "y": 5,
      "z": 3,
      "name": "Wood_Redwood_Planks",
      "rotation": 4
    },
    {
      "x": -6,
      "y": 6,
      "z": 3,
      "name": "Wood_Oak_Trunk",
      "support": 15,
      "rotation": 9
    },
    {
      "x": -6,
      "y": 10,
      "z": 3,
      "name": "Wood_Darkwood_Planks",
      "rotation": 4
    },
    {
      "x": -6,
      "y": 5,
      "z": 4,
      "name": "Wood_Redwood_Planks",
      "rotation": 4
    },
    {
      "x": -6,
      "y": 6,
      "z": 4,
      "name": "Wood_Oak_Trunk",
      "support": 15,
      "rotation": 9
    },
    {
      "x": -6,
      "y": 7,
      "z": 4,
      "name": "Wood_Darkwood_Planks",
      "rotation": 4
    },
    {
      "x": -6,
      "y": 10,
      "z": 4,
      "name": "Wood_Darkwood_Stairs",
      "rotation": 8
    },
    {
      "x": -6,
      "y": 11,
      "z": 4,
      "name": "Wood_Oak_Trunk",
      "support": 15,
      "rotation": 5
    },
    {
      "x": -6,
      "y": 5,
      "z": 5,
      "name": "Wood_Deadwood_Planks",
      "rotation": 4
    },
    {
      "x": -6,
      "y": 7,
      "z": 5,
      "name": "Wood_Darkwood_Planks",
      "rotation": 4
    },
    {
      "x": -6,
      "y": 8,
      "z": 5,
      "name": "Wood_Darkwood_Planks",
      "rotation": 4
    },
    {
      "x": -6,
      "y": 9,
      "z": 5,
      "name": "Wood_Darkwood_Stairs",
      "rotation": 8
    },
    {
      "x": -6,
      "y": 10,
      "z": 5,
      "name": "Wood_Oak_Trunk",
      "support": 15,
      "rotation": 4
    },
    {
      "x": -6,
      "y": 11,
      "z": 5,
      "name": "Wood_Darkwood_Stairs"
    },
    {
      "x": -6,
      "y": 12,
      "z": 5,
      "name": "Wood_Darkwood_Planks",
      "rotation": 4
    },
    {
      "x": -6,
      "y": 6,
      "z": 6,
      "name": "Wood_Deadwood_Planks",
      "rotation": 4
    },
    {
      "x": -6,
      "y": 8,
      "z": 6,
      "name": "Wood_Darkwood_Planks",
      "rotation": 4
    },
    {
      "x": -6,
      "y": 9,
      "z": 6,
      "name": "Wood_Oak_Trunk",
      "support": 15,
      "rotation": 9
    },
    {
      "x": -6,
      "y": 10,
      "z": 6,
      "name": "Wood_Darkwood_Stairs"
    },
    {
      "x": -6,
      "y": 13,
      "z": 6,
      "name": "Wood_Darkwood_Planks",
      "rotation": 4
    },
    {
      "x": -6,
      "y": 5,
      "z": 7,
      "name": "Wood_Deadwood_Planks",
      "rotation": 4
    },
    {
      "x": -6,
      "y": 6,
      "z": 7,
      "name": "Wood_Deadwood_Planks",
      "rotation": 4
    },
    {
      "x": -6,
      "y": 9,
      "z": 7,
      "name": "Wood_Darkwood_Planks",
      "rotation": 4
    },
    {
      "x": -6,
      "y": 10,
      "z": 7,
      "name": "Wood_Darkwood_Planks",
      "rotation": 4
    },
    {
      "x": -6,
      "y": 14,
      "z": 7,
      "name": "Wood_Oak_Trunk",
      "support": 15,
      "rotation": 9
    },
    {
      "x": -6,
      "y": 15,
      "z": 7,
      "name": "Wood_Deadwood_Planks",
      "rotation": 4
    },
    {
      "x": -6,
      "y": 6,
      "z": 8,
      "name": "Wood_Deadwood_Planks",
      "rotation": 4
    },
    {
      "x": -6,
      "y": 7,
      "z": 8,
      "name": "Wood_Darkwood_Planks",
      "rotation": 4
    },
    {
      "x": -6,
      "y": 10,
      "z": 8,
      "name": "Wood_Darkwood_Planks",
      "rotation": 4
    },
    {
      "x": -6,
      "y": 11,
      "z": 8,
      "name": "Wood_Darkwood_Planks",
      "rotation": 4
    },
    {
      "x": -6,
      "y": 7,
      "z": 9,
      "name": "Wood_Deadwood_Planks",
      "rotation": 4
    },
    {
      "x": -6,
      "y": 8,
      "z": 9,
      "name": "Wood_Deadwood_Planks",
      "rotation": 4
    },
    {
      "x": -6,
      "y": 9,
      "z": 9,
      "name": "Wood_Deadwood_Planks",
      "rotation": 4
    },
    {
      "x": -6,
      "y": 11,
      "z": 9,
      "name": "Wood_Oak_Trunk",
      "support": 15,
      "rotation": 9
    },
    {
      "x": -6,
      "y": 12,
      "z": 9,
      "name": "Wood_Oak_Trunk",
      "support": 15,
      "rotation": 9
    },
    {
      "x": -6,
      "y": 13,
      "z": 9,
      "name": "Wood_Deadwood_Planks",
      "rotation": 4
    },
    {
      "x": -6,
      "y": 8,
      "z": 10,
      "name": "Wood_Deadwood_Planks",
      "rotation": 4
    },
    {
      "x": -6,
      "y": 10,
      "z": 10,
      "name": "Wood_Deadwood_Planks",
      "rotation": 4
    },
    {
      "x": -6,
      "y": 11,
      "z": 10,
      "name": "Wood_Redwood_Planks",
      "rotation": 4
    },
    {
      "x": -6,
      "y": 12,
      "z": 10,
      "name": "Wood_Redwood_Planks",
      "rotation": 4
    },
    {
      "x": -5,
      "y": 19,
      "z": -4,
      "name": "Deco_Rope",
      "support": 3,
      "rotation": 15
    },
    {
      "x": -5,
      "y": 8,
      "z": 0,
      "name": "Wood_Deadwood_Planks",
      "rotation": 4
    },
    {
      "x": -5,
      "y": 7,
      "z": 1,
      "name": "Wood_Redwood_Planks",
      "rotation": 4
    },
    {
      "x": -5,
      "y": 8,
      "z": 1,
      "name": "Wood_Oak_Trunk",
      "support": 15,
      "rotation": 5
    },
    {
      "x": -5,
      "y": 6,
      "z": 2,
      "name": "Wood_Deadwood_Planks",
      "rotation": 4
    },
    {
      "x": -5,
      "y": 9,
      "z": 2,
      "name": "Wood_Darkwood_Planks",
      "rotation": 4
    },
    {
      "x": -5,
      "y": 5,
      "z": 3,
      "name": "Wood_Redwood_Planks",
      "rotation": 4
    },
    {
      "x": -5,
      "y": 6,
      "z": 3,
      "name": "Wood_Oak_Trunk",
      "support": 15,
      "rotation": 9
    },
    {
      "x": -5,
      "y": 5,
      "z": 4,
      "name": "Wood_Redwood_Planks",
      "rotation": 4
    },
    {
      "x": -5,
      "y": 6,
      "z": 4,
      "name": "Wood_Oak_Trunk",
      "support": 15,
      "rotation": 9
    },
    {
      "x": -5,
      "y": 7,
      "z": 4,
      "name": "Wood_Darkwood_Planks",
      "rotation": 4
    },
    {
      "x": -5,
      "y": 5,
      "z": 5,
      "name": "Wood_Deadwood_Planks",
      "rotation": 4
    },
    {
      "x": -5,
      "y": 7,
      "z": 5,
      "name": "Wood_Darkwood_Planks",
      "rotation": 4
    },
    {
      "x": -5,
      "y": 8,
      "z": 5,
      "name": "Wood_Darkwood_Planks",
      "rotation": 4
    },
    {
      "x": -5,
      "y": 6,
      "z": 6,
      "name": "Wood_Deadwood_Planks",
      "rotation": 4
    },
    {
      "x": -5,
      "y": 8,
      "z": 6,
      "name": "Wood_Darkwood_Planks",
      "rotation": 4
    },
    {
      "x": -5,
      "y": 9,
      "z": 6,
      "name": "Wood_Oak_Trunk",
      "support": 15,
      "rotation": 9
    },
    {
      "x": -5,
      "y": 13,
      "z": 6,
      "name": "Wood_Darkwood_Planks",
      "rotation": 4
    },
    {
      "x": -5,
      "y": 5,
      "z": 7,
      "name": "Wood_Deadwood_Planks",
      "rotation": 4
    },
    {
      "x": -5,
      "y": 6,
      "z": 7,
      "name": "Wood_Deadwood_Planks",
      "rotation": 4
    },
    {
      "x": -5,
      "y": 9,
      "z": 7,
      "name": "Wood_Darkwood_Planks",
      "rotation": 4
    },
    {
      "x": -5,
      "y": 10,
      "z": 7,
      "name": "Wood_Darkwood_Planks",
      "rotation": 4
    },
    {
      "x": -5,
      "y": 14,
      "z": 7,
      "name": "Wood_Oak_Trunk",
      "support": 15,
      "rotation": 9
    },
    {
      "x": -5,
      "y": 15,
      "z": 7,
      "name": "Wood_Deadwood_Planks",
      "rotation": 4
    },
    {
      "x": -5,
      "y": 6,
      "z": 8,
      "name": "Wood_Deadwood_Planks",
      "rotation": 4
    },
    {
      "x": -5,
      "y": 7,
      "z": 8,
      "name": "Wood_Darkwood_Planks",
      "rotation": 4
    },
    {
      "x": -5,
      "y": 10,
      "z": 8,
      "name": "Wood_Darkwood_Planks",
      "rotation": 4
    },
    {
      "x": -5,
      "y": 11,
      "z": 8,
      "name": "Wood_Darkwood_Planks",
      "rotation": 4
    },
    {
      "x": -5,
      "y": 14,
      "z": 8,
      "name": "Wood_Redwood_Planks",
      "rotation": 4
    },
    {
      "x": -5,
      "y": 7,
      "z": 9,
      "name": "Wood_Deadwood_Planks",
      "rotation": 4
    },
    {
      "x": -5,
      "y": 8,
      "z": 9,
      "name": "Wood_Deadwood_Planks",
      "rotation": 4
    },
    {
      "x": -5,
      "y": 9,
      "z": 9,
      "name": "Wood_Deadwood_Planks",
      "rotation": 4
    },
    {
      "x": -5,
      "y": 11,
      "z": 9,
      "name": "Wood_Oak_Trunk",
      "support": 15,
      "rotation": 9
    },
    {
      "x": -5,
      "y": 12,
      "z": 9,
      "name": "Wood_Oak_Trunk",
      "support": 15,
      "rotation": 9
    },
    {
      "x": -5,
      "y": 13,
      "z": 9,
      "name": "Wood_Deadwood_Planks",
      "rotation": 4
    },
    {
      "x": -5,
      "y": 8,
      "z": 10,
      "name": "Wood_Deadwood_Planks",
      "rotation": 4
    },
    {
      "x": -5,
      "y": 10,
      "z": 10,
      "name": "Wood_Deadwood_Planks",
      "rotation": 4
    },
    {
      "x": -5,
      "y": 11,
      "z": 10,
      "name": "Wood_Redwood_Planks",
      "rotation": 4
    },
    {
      "x": -5,
      "y": 12,
      "z": 10,
      "name": "Wood_Redwood_Planks",
      "rotation": 4
    },
    {
      "x": -4,
      "y": 19,
      "z": -4,
      "name": "Deco_Rope",
      "support": 2,
      "rotation": 15
    },
    {
      "x": -4,
      "y": 8,
      "z": 0,
      "name": "Wood_Deadwood_Planks",
      "rotation": 4
    },
    {
      "x": -4,
      "y": 5,
      "z": 1,
      "name": "Furniture_Tavern_Shelf",
      "rotation": 6
    },
    {
      "x": -4,
      "y": 8,
      "z": 1,
      "name": "Wood_Oak_Trunk",
      "support": 15,
      "rotation": 5
    },
    {
      "x": -4,
      "y": 6,
      "z": 2,
      "name": "Wood_Deadwood_Planks",
      "rotation": 4
    },
    {
      "x": -4,
      "y": 9,
      "z": 2,
      "name": "Wood_Darkwood_Planks",
      "rotation": 4
    },
    {
      "x": -4,
      "y": 5,
      "z": 3,
      "name": "Wood_Redwood_Planks",
      "rotation": 4
    },
    {
      "x": -4,
      "y": 6,
      "z": 3,
      "name": "Wood_Oak_Trunk",
      "support": 15,
      "rotation": 9
    },
    {
      "x": -4,
      "y": 5,
      "z": 4,
      "name": "Wood_Redwood_Planks",
      "rotation": 4
    },
    {
      "x": -4,
      "y": 6,
      "z": 4,
      "name": "Wood_Oak_Trunk",
      "support": 15,
      "rotation": 9
    },
    {
      "x": -4,
      "y": 7,
      "z": 4,
      "name": "Wood_Darkwood_Planks",
      "rotation": 4
    },
    {
      "x": -4,
      "y": 5,
      "z": 5,
      "name": "Wood_Deadwood_Planks",
      "rotation": 4
    },
    {
      "x": -4,
      "y": 7,
      "z": 5,
      "name": "Wood_Darkwood_Planks",
      "rotation": 4
    },
    {
      "x": -4,
      "y": 8,
      "z": 5,
      "name": "Wood_Darkwood_Planks",
      "rotation": 4
    },
    {
      "x": -4,
      "y": 6,
      "z": 6,
      "name": "Wood_Deadwood_Planks",
      "rotation": 4
    },
    {
      "x": -4,
      "y": 8,
      "z": 6,
      "name": "Wood_Darkwood_Planks",
      "rotation": 4
    },
    {
      "x": -4,
      "y": 9,
      "z": 6,
      "name": "Wood_Oak_Trunk",
      "support": 15,
      "rotation": 9
    },
    {
      "x": -4,
      "y": 13,
      "z": 6,
      "name": "Wood_Darkwood_Planks",
      "rotation": 4
    },
    {
      "x": -4,
      "y": 5,
      "z": 7,
      "name": "Wood_Deadwood_Planks",
      "rotation": 4
    },
    {
      "x": -4,
      "y": 6,
      "z": 7,
      "name": "Wood_Deadwood_Planks",
      "rotation": 4
    },
    {
      "x": -4,
      "y": 9,
      "z": 7,
      "name": "Wood_Darkwood_Planks",
      "rotation": 4
    },
    {
      "x": -4,
      "y": 10,
      "z": 7,
      "name": "Wood_Darkwood_Planks",
      "rotation": 4
    },
    {
      "x": -4,
      "y": 14,
      "z": 7,
      "name": "Wood_Oak_Trunk",
      "support": 15,
      "rotation": 9
    },
    {
      "x": -4,
      "y": 15,
      "z": 7,
      "name": "Wood_Deadwood_Planks",
      "rotation": 4
    },
    {
      "x": -4,
      "y": 6,
      "z": 8,
      "name": "Wood_Deadwood_Planks",
      "rotation": 4
    },
    {
      "x": -4,
      "y": 7,
      "z": 8,
      "name": "Wood_Darkwood_Planks",
      "rotation": 4
    },
    {
      "x": -4,
      "y": 10,
      "z": 8,
      "name": "Wood_Darkwood_Planks",
      "rotation": 4
    },
    {
      "x": -4,
      "y": 11,
      "z": 8,
      "name": "Wood_Darkwood_Planks",
      "rotation": 4
    },
    {
      "x": -4,
      "y": 7,
      "z": 9,
      "name": "Wood_Deadwood_Planks",
      "rotation": 4
    },
    {
      "x": -4,
      "y": 8,
      "z": 9,
      "name": "Wood_Deadwood_Planks",
      "rotation": 4
    },
    {
      "x": -4,
      "y": 9,
      "z": 9,
      "name": "Wood_Deadwood_Planks",
      "rotation": 4
    },
    {
      "x": -4,
      "y": 11,
      "z": 9,
      "name": "Wood_Oak_Trunk",
      "support": 15,
      "rotation": 9
    },
    {
      "x": -4,
      "y": 12,
      "z": 9,
      "name": "Wood_Oak_Trunk",
      "support": 15,
      "rotation": 9
    },
    {
      "x": -4,
      "y": 13,
      "z": 9,
      "name": "Wood_Deadwood_Planks",
      "rotation": 4
    },
    {
      "x": -4,
      "y": 8,
      "z": 10,
      "name": "Wood_Deadwood_Planks",
      "rotation": 4
    },
    {
      "x": -4,
      "y": 10,
      "z": 10,
      "name": "Wood_Deadwood_Planks",
      "rotation": 4
    },
    {
      "x": -4,
      "y": 11,
      "z": 10,
      "name": "Wood_Redwood_Planks",
      "rotation": 4
    },
    {
      "x": -4,
      "y": 12,
      "z": 10,
      "name": "Wood_Redwood_Planks",
      "rotation": 4
    },
    {
      "x": -3,
      "y": 19,
      "z": -4,
      "name": "Deco_Rope",
      "support": 1,
      "rotation": 15
    },
    {
      "x": -3,
      "y": 8,
      "z": 0,
      "name": "Wood_Deadwood_Planks",
      "rotation": 4
    },
    {
      "x": -3,
      "y": 7,
      "z": 1,
      "name": "Wood_Redwood_Planks",
      "rotation": 4
    },
    {
      "x": -3,
      "y": 8,
      "z": 1,
      "name": "Wood_Oak_Trunk",
      "support": 15,
      "rotation": 5
    },
    {
      "x": -3,
      "y": 6,
      "z": 2,
      "name": "Wood_Deadwood_Planks",
      "rotation": 4
    },
    {
      "x": -3,
      "y": 9,
      "z": 2,
      "name": "Wood_Darkwood_Planks",
      "rotation": 4
    },
    {
      "x": -3,
      "y": 5,
      "z": 3,
      "name": "Wood_Redwood_Planks",
      "rotation": 4
    },
    {
      "x": -3,
      "y": 6,
      "z": 3,
      "name": "Wood_Oak_Trunk",
      "support": 15,
      "rotation": 9
    },
    {
      "x": -3,
      "y": 5,
      "z": 4,
      "name": "Wood_Redwood_Planks",
      "rotation": 4
    },
    {
      "x": -3,
      "y": 6,
      "z": 4,
      "name": "Wood_Oak_Trunk",
      "support": 15,
      "rotation": 9
    },
    {
      "x": -3,
      "y": 7,
      "z": 4,
      "name": "Wood_Darkwood_Planks",
      "rotation": 4
    },
    {
      "x": -3,
      "y": 5,
      "z": 5,
      "name": "Wood_Deadwood_Planks",
      "rotation": 4
    },
    {
      "x": -3,
      "y": 7,
      "z": 5,
      "name": "Wood_Darkwood_Planks",
      "rotation": 4
    },
    {
      "x": -3,
      "y": 8,
      "z": 5,
      "name": "Wood_Darkwood_Planks",
      "rotation": 4
    },
    {
      "x": -3,
      "y": 6,
      "z": 6,
      "name": "Wood_Deadwood_Planks",
      "rotation": 4
    },
    {
      "x": -3,
      "y": 8,
      "z": 6,
      "name": "Wood_Darkwood_Planks",
      "rotation": 4
    },
    {
      "x": -3,
      "y": 9,
      "z": 6,
      "name": "Wood_Oak_Trunk",
      "support": 15,
      "rotation": 9
    },
    {
      "x": -3,
      "y": 13,
      "z": 6,
      "name": "Wood_Darkwood_Planks",
      "rotation": 4
    },
    {
      "x": -3,
      "y": 5,
      "z": 7,
      "name": "Wood_Deadwood_Planks",
      "rotation": 4
    },
    {
      "x": -3,
      "y": 6,
      "z": 7,
      "name": "Wood_Deadwood_Planks",
      "rotation": 4
    },
    {
      "x": -3,
      "y": 9,
      "z": 7,
      "name": "Wood_Darkwood_Planks",
      "rotation": 4
    },
    {
      "x": -3,
      "y": 10,
      "z": 7,
      "name": "Wood_Darkwood_Planks",
      "rotation": 4
    },
    {
      "x": -3,
      "y": 14,
      "z": 7,
      "name": "Wood_Oak_Trunk",
      "support": 15,
      "rotation": 9
    },
    {
      "x": -3,
      "y": 15,
      "z": 7,
      "name": "Wood_Deadwood_Planks",
      "rotation": 4
    },
    {
      "x": -3,
      "y": 6,
      "z": 8,
      "name": "Wood_Deadwood_Planks",
      "rotation": 4
    },
    {
      "x": -3,
      "y": 7,
      "z": 8,
      "name": "Wood_Darkwood_Planks",
      "rotation": 4
    },
    {
      "x": -3,
      "y": 10,
      "z": 8,
      "name": "Wood_Darkwood_Planks",
      "rotation": 4
    },
    {
      "x": -3,
      "y": 11,
      "z": 8,
      "name": "Wood_Darkwood_Planks",
      "rotation": 4
    },
    {
      "x": -3,
      "y": 14,
      "z": 8,
      "name": "Wood_Redwood_Planks",
      "rotation": 4
    },
    {
      "x": -3,
      "y": 7,
      "z": 9,
      "name": "Wood_Deadwood_Planks",
      "rotation": 4
    },
    {
      "x": -3,
      "y": 8,
      "z": 9,
      "name": "Wood_Deadwood_Planks",
      "rotation": 4
    },
    {
      "x": -3,
      "y": 9,
      "z": 9,
      "name": "Wood_Deadwood_Planks",
      "rotation": 4
    },
    {
      "x": -3,
      "y": 11,
      "z": 9,
      "name": "Wood_Oak_Trunk",
      "support": 15,
      "rotation": 9
    },
    {
      "x": -3,
      "y": 12,
      "z": 9,
      "name": "Wood_Oak_Trunk",
      "support": 15,
      "rotation": 9
    },
    {
      "x": -3,
      "y": 13,
      "z": 9,
      "name": "Wood_Deadwood_Planks",
      "rotation": 4
    },
    {
      "x": -3,
      "y": 8,
      "z": 10,
      "name": "Wood_Deadwood_Planks",
      "rotation": 4
    },
    {
      "x": -3,
      "y": 10,
      "z": 10,
      "name": "Wood_Deadwood_Planks",
      "rotation": 4
    },
    {
      "x": -3,
      "y": 11,
      "z": 10,
      "name": "Wood_Redwood_Planks",
      "rotation": 4
    },
    {
      "x": -3,
      "y": 12,
      "z": 10,
      "name": "Wood_Redwood_Planks",
      "rotation": 4
    },
    {
      "x": -2,
      "y": 18,
      "z": -15,
      "name": "Wood_Darkwood_Stairs",
      "rotation": 2
    },
    {
      "x": -2,
      "y": 18,
      "z": -14,
      "name": "Wood_Darkwood_Stairs",
      "rotation": 10
    },
    {
      "x": -2,
      "y": 19,
      "z": -14,
      "name": "Wood_Darkwood_Stairs",
      "rotation": 2
    },
    {
      "x": -2,
      "y": 19,
      "z": -13,
      "name": "Wood_Darkwood_Stairs",
      "rotation": 10
    },
    {
      "x": -2,
      "y": 20,
      "z": -13,
      "name": "Wood_Darkwood_Stairs",
      "rotation": 2
    },
    {
      "x": -2,
      "y": 20,
      "z": -12,
      "name": "Wood_Darkwood_Stairs",
      "rotation": 10
    },
    {
      "x": -2,
      "y": 21,
      "z": -12,
      "name": "Wood_Darkwood_Stairs",
      "rotation": 2
    },
    {
      "x": -2,
      "y": 21,
      "z": -11,
      "name": "Wood_Darkwood_Stairs",
      "rotation": 10
    },
    {
      "x": -2,
      "y": 22,
      "z": -11,
      "name": "Wood_Darkwood_Stairs",
      "rotation": 2
    },
    {
      "x": -2,
      "y": 22,
      "z": -10,
      "name": "Wood_Darkwood_Stairs",
      "rotation": 10
    },
    {
      "x": -2,
      "y": 23,
      "z": -10,
      "name": "Wood_Darkwood_Stairs",
      "rotation": 2
    },
    {
      "x": -2,
      "y": 23,
      "z": -9,
      "name": "Wood_Darkwood_Stairs",
      "rotation": 10
    },
    {
      "x": -2,
      "y": 24,
      "z": -9,
      "name": "Wood_Darkwood_Stairs",
      "rotation": 2
    },
    {
      "x": -2,
      "y": 24,
      "z": -8,
      "name": "Wood_Darkwood_Stairs",
      "rotation": 10
    },
    {
      "x": -2,
      "y": 25,
      "z": -8,
      "name": "Wood_Darkwood_Stairs",
      "rotation": 2
    },
    {
      "x": -2,
      "y": 25,
      "z": -7,
      "name": "Wood_Darkwood_Stairs",
      "rotation": 10
    },
    {
      "x": -2,
      "y": 26,
      "z": -7,
      "name": "Wood_Darkwood_Stairs",
      "rotation": 2
    },
    {
      "x": -2,
      "y": 26,
      "z": -6,
      "name": "Wood_Darkwood_Stairs",
      "rotation": 10
    },
    {
      "x": -2,
      "y": 27,
      "z": -6,
      "name": "Wood_Darkwood_Stairs",
      "rotation": 2
    },
    {
      "x": -2,
      "y": 27,
      "z": -5,
      "name": "Wood_Darkwood_Stairs",
      "rotation": 10
    },
    {
      "x": -2,
      "y": 28,
      "z": -5,
      "name": "Wood_Darkwood_Stairs",
      "rotation": 2
    },
    {
      "x": -2,
      "y": 19,
      "z": -4,
      "name": "Deco_Rope",
      "rotation": 15
    },
    {
      "x": -2,
      "y": 28,
      "z": -4,
      "name": "Wood_Darkwood_Stairs",
      "rotation": 10
    },
    {
      "x": -2,
      "y": 29,
      "z": -4,
      "name": "Wood_Darkwood_Stairs",
      "rotation": 2
    },
    {
      "x": -2,
      "y": 8,
      "z": 0,
      "name": "Wood_Deadwood_Planks",
      "rotation": 4
    },
    {
      "x": -2,
      "y": 7,
      "z": 1,
      "name": "Wood_Redwood_Planks",
      "rotation": 4
    },
    {
      "x": -2,
      "y": 8,
      "z": 1,
      "name": "Wood_Oak_Trunk",
      "support": 15,
      "rotation": 5
    },
    {
      "x": -2,
      "y": 6,
      "z": 2,
      "name": "Wood_Deadwood_Planks",
      "rotation": 4
    },
    {
      "x": -2,
      "y": 9,
      "z": 2,
      "name": "Wood_Darkwood_Planks",
      "rotation": 4
    },
    {
      "x": -2,
      "y": 5,
      "z": 3,
      "name": "Wood_Redwood_Planks",
      "rotation": 4
    },
    {
      "x": -2,
      "y": 6,
      "z": 3,
      "name": "Wood_Oak_Trunk",
      "support": 15,
      "rotation": 9
    },
    {
      "x": -2,
      "y": 10,
      "z": 3,
      "name": "Wood_Darkwood_Planks",
      "rotation": 4
    },
    {
      "x": -2,
      "y": 5,
      "z": 4,
      "name": "Wood_Redwood_Planks",
      "rotation": 4
    },
    {
      "x": -2,
      "y": 6,
      "z": 4,
      "name": "Wood_Oak_Trunk",
      "support": 15,
      "rotation": 9
    },
    {
      "x": -2,
      "y": 7,
      "z": 4,
      "name": "Wood_Darkwood_Planks",
      "rotation": 4
    },
    {
      "x": -2,
      "y": 11,
      "z": 4,
      "name": "Wood_Oak_Trunk",
      "support": 15,
      "rotation": 5
    },
    {
      "x": -2,
      "y": 5,
      "z": 5,
      "name": "Wood_Deadwood_Planks",
      "rotation": 4
    },
    {
      "x": -2,
      "y": 7,
      "z": 5,
      "name": "Wood_Darkwood_Planks",
      "rotation": 4
    },
    {
      "x": -2,
      "y": 8,
      "z": 5,
      "name": "Wood_Darkwood_Planks",
      "rotation": 4
    },
    {
      "x": -2,
      "y": 12,
      "z": 5,
      "name": "Wood_Darkwood_Planks",
      "rotation": 4
    },
    {
      "x": -2,
      "y": 6,
      "z": 6,
      "name": "Wood_Deadwood_Planks",
      "rotation": 4
    },
    {
      "x": -2,
      "y": 8,
      "z": 6,
      "name": "Wood_Darkwood_Planks",
      "rotation": 4
    },
    {
      "x": -2,
      "y": 9,
      "z": 6,
      "name": "Wood_Oak_Trunk",
      "support": 15,
      "rotation": 9
    },
    {
      "x": -2,
      "y": 13,
      "z": 6,
      "name": "Wood_Darkwood_Planks",
      "rotation": 4
    },
    {
      "x": -2,
      "y": 5,
      "z": 7,
      "name": "Wood_Deadwood_Planks",
      "rotation": 4
    },
    {
      "x": -2,
      "y": 6,
      "z": 7,
      "name": "Wood_Deadwood_Planks",
      "rotation": 4
    },
    {
      "x": -2,
      "y": 9,
      "z": 7,
      "name": "Wood_Darkwood_Planks",
      "rotation": 4
    },
    {
      "x": -2,
      "y": 10,
      "z": 7,
      "name": "Wood_Darkwood_Planks",
      "rotation": 4
    },
    {
      "x": -2,
      "y": 14,
      "z": 7,
      "name": "Wood_Oak_Trunk",
      "support": 15,
      "rotation": 9
    },
    {
      "x": -2,
      "y": 15,
      "z": 7,
      "name": "Wood_Deadwood_Planks",
      "rotation": 4
    },
    {
      "x": -2,
      "y": 6,
      "z": 8,
      "name": "Wood_Deadwood_Planks",
      "rotation": 4
    },
    {
      "x": -2,
      "y": 7,
      "z": 8,
      "name": "Wood_Darkwood_Planks",
      "rotation": 4
    },
    {
      "x": -2,
      "y": 10,
      "z": 8,
      "name": "Wood_Darkwood_Planks",
      "rotation": 4
    },
    {
      "x": -2,
      "y": 11,
      "z": 8,
      "name": "Wood_Darkwood_Planks",
      "rotation": 4
    },
    {
      "x": -2,
      "y": 14,
      "z": 8,
      "name": "Wood_Redwood_Planks",
      "rotation": 4
    },
    {
      "x": -2,
      "y": 7,
      "z": 9,
      "name": "Wood_Deadwood_Planks",
      "rotation": 4
    },
    {
      "x": -2,
      "y": 8,
      "z": 9,
      "name": "Wood_Deadwood_Planks",
      "rotation": 4
    },
    {
      "x": -2,
      "y": 9,
      "z": 9,
      "name": "Wood_Deadwood_Planks",
      "rotation": 4
    },
    {
      "x": -2,
      "y": 11,
      "z": 9,
      "name": "Wood_Oak_Trunk",
      "support": 15,
      "rotation": 9
    },
    {
      "x": -2,
      "y": 12,
      "z": 9,
      "name": "Wood_Oak_Trunk",
      "support": 15,
      "rotation": 9
    },
    {
      "x": -2,
      "y": 13,
      "z": 9,
      "name": "Wood_Deadwood_Planks",
      "rotation": 4
    },
    {
      "x": -2,
      "y": 8,
      "z": 10,
      "name": "Wood_Deadwood_Planks",
      "rotation": 4
    },
    {
      "x": -2,
      "y": 10,
      "z": 10,
      "name": "Wood_Deadwood_Planks",
      "rotation": 4
    },
    {
      "x": -2,
      "y": 11,
      "z": 10,
      "name": "Wood_Redwood_Planks",
      "rotation": 4
    },
    {
      "x": -2,
      "y": 12,
      "z": 10,
      "name": "Wood_Redwood_Planks",
      "rotation": 4
    },
    {
      "x": -1,
      "y": 25,
      "z": -11,
      "name": "Wood_Darkwood_Stairs",
      "rotation": 8
    },
    {
      "x": -1,
      "y": 26,
      "z": -11,
      "name": "Wood_Oak_Trunk",
      "support": 15,
      "rotation": 4
    },
    {
      "x": -1,
      "y": 24,
      "z": -10,
      "name": "Wood_Oak_Trunk",
      "support": 15,
      "rotation": 8
    },
    {
      "x": -1,
      "y": 25,
      "z": -10,
      "name": "Wood_Oak_Trunk",
      "support": 15,
      "rotation": 4
    },
    {
      "x": -1,
      "y": 26,
      "z": -10,
      "name": "Wood_Darkwood_Stairs"
    },
    {
      "x": -1,
      "y": 23,
      "z": -9,
      "name": "Wood_Darkwood_Stairs",
      "rotation": 8
    },
    {
      "x": -1,
      "y": 24,
      "z": -9,
      "name": "Wood_Oak_Trunk",
      "support": 15,
      "rotation": 4
    },
    {
      "x": -1,
      "y": 25,
      "z": -9,
      "name": "Wood_Oak_Trunk",
      "support": 15,
      "rotation": 8
    },
    {
      "x": -1,
      "y": 22,
      "z": -8,
      "name": "Wood_Darkwood_Stairs",
      "rotation": 8
    },
    {
      "x": -1,
      "y": 23,
      "z": -8,
      "name": "Wood_Oak_Trunk",
      "support": 15,
      "rotation": 4
    },
    {
      "x": -1,
      "y": 24,
      "z": -8,
      "name": "Wood_Darkwood_Stairs",
      "rotation": 14
    },
    {
      "x": -1,
      "y": 21,
      "z": -7,
      "name": "Wood_Darkwood_Stairs",
      "rotation": 8
    },
    {
      "x": -1,
      "y": 22,
      "z": -7,
      "name": "Wood_Oak_Trunk",
      "support": 15,
      "rotation": 4
    },
    {
      "x": -1,
      "y": 23,
      "z": -7,
      "name": "Wood_Darkwood_Stairs"
    },
    {
      "x": -1,
      "y": 20,
      "z": -6,
      "name": "Wood_Darkwood_Stairs",
      "rotation": 8
    },
    {
      "x": -1,
      "y": 21,
      "z": -6,
      "name": "Wood_Oak_Trunk",
      "support": 15,
      "rotation": 4
    },
    {
      "x": -1,
      "y": 22,
      "z": -6,
      "name": "Wood_Darkwood_Stairs"
    },
    {
      "x": -1,
      "y": 19,
      "z": -5,
      "name": "Wood_Darkwood_Stairs",
      "rotation": 8
    },
    {
      "x": -1,
      "y": 20,
      "z": -5,
      "name": "Wood_Oak_Trunk",
      "support": 15,
      "rotation": 4
    },
    {
      "x": -1,
      "y": 21,
      "z": -5,
      "name": "Wood_Darkwood_Stairs"
    },
    {
      "x": -1,
      "y": 18,
      "z": -4,
      "name": "Wood_Darkwood_Stairs",
      "rotation": 8
    },
    {
      "x": -1,
      "y": 19,
      "z": -4,
      "name": "Wood_Oak_Trunk",
      "support": 15,
      "rotation": 4
    },
    {
      "x": -1,
      "y": 20,
      "z": -4,
      "name": "Wood_Darkwood_Stairs"
    },
    {
      "x": -1,
      "y": 17,
      "z": -3,
      "name": "Wood_Darkwood_Stairs",
      "rotation": 8
    },
    {
      "x": -1,
      "y": 18,
      "z": -3,
      "name": "Wood_Oak_Trunk",
      "support": 15,
      "rotation": 4
    },
    {
      "x": -1,
      "y": 19,
      "z": -3,
      "name": "Wood_Darkwood_Stairs"
    },
    {
      "x": -1,
      "y": 16,
      "z": -2,
      "name": "Wood_Darkwood_Stairs",
      "rotation": 8
    },
    {
      "x": -1,
      "y": 17,
      "z": -2,
      "name": "Wood_Oak_Trunk",
      "support": 15,
      "rotation": 4
    },
    {
      "x": -1,
      "y": 18,
      "z": -2,
      "name": "Wood_Darkwood_Stairs"
    },
    {
      "x": -1,
      "y": 15,
      "z": -1,
      "name": "Wood_Darkwood_Stairs",
      "rotation": 8
    },
    {
      "x": -1,
      "y": 16,
      "z": -1,
      "name": "Wood_Oak_Trunk",
      "support": 15,
      "rotation": 4
    },
    {
      "x": -1,
      "y": 17,
      "z": -1,
      "name": "Wood_Darkwood_Stairs"
    },
    {
      "x": -1,
      "y": 8,
      "z": 0,
      "name": "Wood_Deadwood_Planks",
      "rotation": 4
    },
    {
      "x": -1,
      "y": 9,
      "z": 0,
      "name": "Deco_Rope"
    },
    {
      "x": -1,
      "y": 10,
      "z": 0,
      "name": "Deco_Rope"
    },
    {
      "x": -1,
      "y": 11,
      "z": 0,
      "name": "Deco_Rope"
    },
    {
      "x": -1,
      "y": 12,
      "z": 0,
      "name": "Deco_Rope"
    },
    {
      "x": -1,
      "y": 13,
      "z": 0,
      "name": "Deco_Rope"
    },
    {
      "x": -1,
      "y": 14,
      "z": 0,
      "name": "Wood_Oak_Trunk",
      "support": 15
    },
    {
      "x": -1,
      "y": 15,
      "z": 0,
      "name": "Wood_Oak_Trunk",
      "support": 15,
      "rotation": 4
    },
    {
      "x": -1,
      "y": 16,
      "z": 0,
      "name": "Wood_Darkwood_Stairs"
    },
    {
      "x": -1,
      "y": 7,
      "z": 1,
      "name": "Wood_Redwood_Planks",
      "rotation": 4
    },
    {
      "x": -1,
      "y": 8,
      "z": 1,
      "name": "Wood_Oak_Trunk",
      "support": 15,
      "rotation": 5
    },
    {
      "x": -1,
      "y": 13,
      "z": 1,
      "name": "Wood_Darkwood_Stairs",
      "rotation": 8
    },
    {
      "x": -1,
      "y": 14,
      "z": 1,
      "name": "Wood_Oak_Trunk",
      "support": 15,
      "rotation": 4
    },
    {
      "x": -1,
      "y": 15,
      "z": 1,
      "name": "Wood_Oak_Trunk",
      "support": 15,
      "rotation": 4
    },
    {
      "x": -1,
      "y": 6,
      "z": 2,
      "name": "Wood_Deadwood_Planks",
      "rotation": 4
    },
    {
      "x": -1,
      "y": 9,
      "z": 2,
      "name": "Wood_Oak_Trunk",
      "support": 15,
      "rotation": 8
    },
    {
      "x": -1,
      "y": 12,
      "z": 2,
      "name": "Wood_Darkwood_Stairs",
      "rotation": 8
    },
    {
      "x": -1,
      "y": 13,
      "z": 2,
      "name": "Wood_Oak_Trunk",
      "support": 15,
      "rotation": 4
    },
    {
      "x": -1,
      "y": 14,
      "z": 2,
      "name": "Wood_Darkwood_Stairs"
    },
    {
      "x": -1,
      "y": 15,
      "z": 2,
      "name": "Deco_Rope",
      "rotation": 12
    },
    {
      "x": -1,
      "y": 5,
      "z": 3,
      "name": "Wood_Redwood_Planks",
      "rotation": 4
    },
    {
      "x": -1,
      "y": 6,
      "z": 3,
      "name": "Wood_Oak_Trunk",
      "support": 15,
      "rotation": 8
    },
    {
      "x": -1,
      "y": 10,
      "z": 3,
      "name": "Wood_Oak_Trunk",
      "support": 15,
      "rotation": 8
    },
    {
      "x": -1,
      "y": 11,
      "z": 3,
      "name": "Wood_Darkwood_Stairs",
      "rotation": 8
    },
    {
      "x": -1,
      "y": 12,
      "z": 3,
      "name": "Wood_Oak_Trunk",
      "support": 15,
      "rotation": 4
    },
    {
      "x": -1,
      "y": 13,
      "z": 3,
      "name": "Wood_Darkwood_Stairs"
    },
    {
      "x": -1,
      "y": 15,
      "z": 3,
      "name": "Deco_Rope",
      "support": 1,
      "rotation": 12
    },
    {
      "x": -1,
      "y": 5,
      "z": 4,
      "name": "Wood_Redwood_Planks",
      "rotation": 4
    },
    {
      "x": -1,
      "y": 6,
      "z": 4,
      "name": "Wood_Oak_Trunk",
      "support": 15,
      "rotation": 8
    },
    {
      "x": -1,
      "y": 7,
      "z": 4,
      "name": "Wood_Oak_Trunk",
      "support": 15,
      "rotation": 8
    },
    {
      "x": -1,
      "y": 11,
      "z": 4,
      "name": "Wood_Oak_Trunk",
      "support": 15,
      "rotation": 4
    },
    {
      "x": -1,
      "y": 12,
      "z": 4,
      "name": "Wood_Darkwood_Stairs"
    },
    {
      "x": -1,
      "y": 15,
      "z": 4,
      "name": "Deco_Rope",
      "support": 2,
      "rotation": 12
    },
    {
      "x": -1,
      "y": 5,
      "z": 5,
      "name": "Wood_Deadwood_Planks",
      "rotation": 4
    },
    {
      "x": -1,
      "y": 7,
      "z": 5,
      "name": "Wood_Oak_Trunk",
      "support": 15,
      "rotation": 8
    },
    {
      "x": -1,
      "y": 8,
      "z": 5,
      "name": "Wood_Oak_Trunk",
      "support": 15,
      "rotation": 8
    },
    {
      "x": -1,
      "y": 10,
      "z": 5,
      "name": "Wood_Oak_Trunk",
      "support": 15,
      "rotation": 4
    },
    {
      "x": -1,
      "y": 12,
      "z": 5,
      "name": "Wood_Oak_Trunk",
      "support": 15,
      "rotation": 8
    },
    {
      "x": -1,
      "y": 15,
      "z": 5,
      "name": "Deco_Rope",
      "support": 1,
      "rotation": 12
    },
    {
      "x": -1,
      "y": 6,
      "z": 6,
      "name": "Wood_Deadwood_Planks",
      "rotation": 4
    },
    {
      "x": -1,
      "y": 8,
      "z": 6,
      "name": "Wood_Oak_Trunk",
      "support": 15,
      "rotation": 8
    },
    {
      "x": -1,
      "y": 9,
      "z": 6,
      "name": "Wood_Oak_Trunk",
      "support": 15,
      "rotation": 9
    },
    {
      "x": -1,
      "y": 13,
      "z": 6,
      "name": "Wood_Oak_Trunk",
      "support": 15,
      "rotation": 8
    },
    {
      "x": -1,
      "y": 15,
      "z": 6,
      "name": "Deco_Rope",
      "rotation": 12
    },
    {
      "x": -1,
      "y": 5,
      "z": 7,
      "name": "Wood_Deadwood_Planks",
      "rotation": 4
    },
    {
      "x": -1,
      "y": 6,
      "z": 7,
      "name": "Wood_Deadwood_Planks",
      "rotation": 4
    },
    {
      "x": -1,
      "y": 8,
      "z": 7,
      "name": "Wood_Oak_Trunk",
      "support": 15,
      "rotation": 4
    },
    {
      "x": -1,
      "y": 9,
      "z": 7,
      "name": "Wood_Oak_Trunk",
      "support": 15,
      "rotation": 8
    },
    {
      "x": -1,
      "y": 10,
      "z": 7,
      "name": "Wood_Oak_Trunk",
      "support": 15,
      "rotation": 8
    },
    {
      "x": -1,
      "y": 14,
      "z": 7,
      "name": "Wood_Oak_Trunk",
      "support": 15,
      "rotation": 8
    },
    {
      "x": -1,
      "y": 15,
      "z": 7,
      "name": "Wood_Deadwood_Planks",
      "rotation": 4
    },
    {
      "x": -1,
      "y": 6,
      "z": 8,
      "name": "Wood_Deadwood_Planks",
      "rotation": 4
    },
    {
      "x": -1,
      "y": 7,
      "z": 8,
      "name": "Wood_Darkwood_Planks",
      "rotation": 4
    },
    {
      "x": -1,
      "y": 10,
      "z": 8,
      "name": "Wood_Oak_Trunk",
      "support": 15,
      "rotation": 8
    },
    {
      "x": -1,
      "y": 11,
      "z": 8,
      "name": "Wood_Oak_Trunk",
      "support": 15,
      "rotation": 8
    },
    {
      "x": -1,
      "y": 14,
      "z": 8,
      "name": "Wood_Redwood_Planks",
      "rotation": 4
    },
    {
      "x": -1,
      "y": 7,
      "z": 9,
      "name": "Wood_Deadwood_Planks",
      "rotation": 4
    },
    {
      "x": -1,
      "y": 8,
      "z": 9,
      "name": "Wood_Deadwood_Planks",
      "rotation": 4
    },
    {
      "x": -1,
      "y": 9,
      "z": 9,
      "name": "Wood_Deadwood_Planks",
      "rotation": 4
    },
    {
      "x": -1,
      "y": 11,
      "z": 9,
      "name": "Wood_Oak_Trunk",
      "support": 15,
      "rotation": 8
    },
    {
      "x": -1,
      "y": 12,
      "z": 9,
      "name": "Wood_Oak_Trunk",
      "support": 15,
      "rotation": 8
    },
    {
      "x": -1,
      "y": 13,
      "z": 9,
      "name": "Wood_Deadwood_Planks",
      "rotation": 4
    },
    {
      "x": -1,
      "y": 8,
      "z": 10,
      "name": "Wood_Deadwood_Planks",
      "rotation": 4
    },
    {
      "x": -1,
      "y": 10,
      "z": 10,
      "name": "Wood_Deadwood_Planks",
      "rotation": 4
    },
    {
      "x": -1,
      "y": 11,
      "z": 10,
      "name": "Wood_Redwood_Planks",
      "rotation": 4
    },
    {
      "x": -1,
      "y": 12,
      "z": 10,
      "name": "Wood_Redwood_Planks",
      "rotation": 4
    },
    {
      "x": 0,
      "y": 19,
      "z": -4,
      "name": "Deco_Rope",
      "rotation": 15
    },
    {
      "x": 0,
      "y": 8,
      "z": 0,
      "name": "Wood_Deadwood_Planks"
    },
    {
      "x": 0,
      "y": 7,
      "z": 1,
      "name": "Wood_Redwood_Planks",
      "rotation": 4
    },
    {
      "x": 0,
      "y": 8,
      "z": 1,
      "name": "Wood_Oak_Trunk",
      "support": 15,
      "rotation": 5
    },
    {
      "x": 0,
      "y": 6,
      "z": 2,
      "name": "Wood_Deadwood_Planks",
      "rotation": 4
    },
    {
      "x": 0,
      "y": 9,
      "z": 2,
      "name": "Wood_Darkwood_Planks",
      "rotation": 4
    },
    {
      "x": 0,
      "y": 5,
      "z": 3,
      "name": "Wood_Redwood_Planks",
      "rotation": 4
    },
    {
      "x": 0,
      "y": 6,
      "z": 3,
      "name": "Wood_Oak_Trunk",
      "support": 15,
      "rotation": 9
    },
    {
      "x": 0,
      "y": 10,
      "z": 3,
      "name": "Wood_Darkwood_Planks",
      "rotation": 4
    },
    {
      "x": 0,
      "y": 5,
      "z": 4,
      "name": "Wood_Redwood_Planks",
      "rotation": 4
    },
    {
      "x": 0,
      "y": 6,
      "z": 4,
      "name": "Wood_Oak_Trunk",
      "support": 15,
      "rotation": 9
    },
    {
      "x": 0,
      "y": 7,
      "z": 4,
      "name": "Wood_Darkwood_Planks",
      "rotation": 4
    },
    {
      "x": 0,
      "y": 11,
      "z": 4,
      "name": "Wood_Oak_Trunk",
      "support": 15,
      "rotation": 5
    },
    {
      "x": 0,
      "y": 5,
      "z": 5,
      "name": "Wood_Deadwood_Planks",
      "rotation": 4
    },
    {
      "x": 0,
      "y": 7,
      "z": 5,
      "name": "Wood_Darkwood_Planks",
      "rotation": 4
    },
    {
      "x": 0,
      "y": 8,
      "z": 5,
      "name": "Wood_Darkwood_Planks",
      "rotation": 4
    },
    {
      "x": 0,
      "y": 12,
      "z": 5,
      "name": "Wood_Darkwood_Planks",
      "rotation": 4
    },
    {
      "x": 0,
      "y": 6,
      "z": 6,
      "name": "Wood_Deadwood_Planks",
      "rotation": 4
    },
    {
      "x": 0,
      "y": 8,
      "z": 6,
      "name": "Wood_Darkwood_Planks",
      "rotation": 4
    },
    {
      "x": 0,
      "y": 9,
      "z": 6,
      "name": "Wood_Oak_Trunk",
      "support": 15,
      "rotation": 9
    },
    {
      "x": 0,
      "y": 13,
      "z": 6,
      "name": "Wood_Darkwood_Planks",
      "rotation": 4
    },
    {
      "x": 0,
      "y": 5,
      "z": 7,
      "name": "Wood_Deadwood_Planks",
      "rotation": 4
    },
    {
      "x": 0,
      "y": 6,
      "z": 7,
      "name": "Wood_Deadwood_Planks",
      "rotation": 4
    },
    {
      "x": 0,
      "y": 9,
      "z": 7,
      "name": "Wood_Darkwood_Planks",
      "rotation": 4
    },
    {
      "x": 0,
      "y": 10,
      "z": 7,
      "name": "Wood_Darkwood_Planks",
      "rotation": 4
    },
    {
      "x": 0,
      "y": 14,
      "z": 7,
      "name": "Wood_Oak_Trunk",
      "support": 15,
      "rotation": 9
    },
    {
      "x": 0,
      "y": 15,
      "z": 7,
      "name": "Wood_Deadwood_Planks",
      "rotation": 4
    },
    {
      "x": 0,
      "y": 6,
      "z": 8,
      "name": "Wood_Deadwood_Planks",
      "rotation": 4
    },
    {
      "x": 0,
      "y": 7,
      "z": 8,
      "name": "Wood_Darkwood_Planks",
      "rotation": 4
    },
    {
      "x": 0,
      "y": 10,
      "z": 8,
      "name": "Wood_Darkwood_Planks",
      "rotation": 4
    },
    {
      "x": 0,
      "y": 11,
      "z": 8,
      "name": "Wood_Darkwood_Planks",
      "rotation": 4
    },
    {
      "x": 0,
      "y": 14,
      "z": 8,
      "name": "Wood_Redwood_Planks",
      "rotation": 4
    },
    {
      "x": 0,
      "y": 7,
      "z": 9,
      "name": "Wood_Deadwood_Planks",
      "rotation": 4
    },
    {
      "x": 0,
      "y": 8,
      "z": 9,
      "name": "Wood_Deadwood_Planks",
      "rotation": 4
    },
    {
      "x": 0,
      "y": 9,
      "z": 9,
      "name": "Wood_Deadwood_Planks",
      "rotation": 4
    },
    {
      "x": 0,
      "y": 11,
      "z": 9,
      "name": "Wood_Oak_Trunk",
      "support": 15,
      "rotation": 9
    },
    {
      "x": 0,
      "y": 12,
      "z": 9,
      "name": "Wood_Oak_Trunk",
      "support": 15,
      "rotation": 9
    },
    {
      "x": 0,
      "y": 13,
      "z": 9,
      "name": "Wood_Deadwood_Planks",
      "rotation": 4
    },
    {
      "x": 0,
      "y": 8,
      "z": 10,
      "name": "Wood_Deadwood_Planks",
      "rotation": 4
    },
    {
      "x": 0,
      "y": 10,
      "z": 10,
      "name": "Wood_Deadwood_Planks",
      "rotation": 4
    },
    {
      "x": 0,
      "y": 11,
      "z": 10,
