{
  "version": 8,
  "blockIdVersion": 11,
  "anchorX": 0,
  "anchorY": 0,
  "anchorZ": 0,
  "blocks": [
    {
      "x": -22,
      "y": 11,
      "z": 0,
      "name": "Wood_Darkwood_Stairs",
      "rotation": 9
    },
    {
      "x": -22,
      "y": 12,
      "z": 0,
      "name": "Wood_Darkwood_Planks"
    },
    {
      "x": -22,
      "y": 13,
      "z": 0,
      "name": "Wood_Darkwood_Stairs",
      "rotation": 3
    },
    {
      "x": -21,
      "y": 10,
      "z": 0,
      "name": "Wood_Darkwood_Stairs",
      "rotation": 9
    },
    {
      "x": -21,
      "y": 11,
      "z": 0,
      "name": "Wood_Darkwood_Planks"
    },
    {
      "x": -21,
      "y": 12,
      "z": 0,
      "name": "Wood_Darkwood_Stairs",
      "rotation": 1
    },
    {
      "x": -20,
      "y": 10,
      "z": -2,
      "name": "Wood_Oak_Trunk",
      "support": 15,
      "rotation": 4
    },
    {
      "x": -20,
      "y": 10,
      "z": -1,
      "name": "Wood_Oak_Trunk",
      "support": 15,
      "rotation": 4
    },
    {
      "x": -20,
      "y": 9,
      "z": 0,
      "name": "Wood_Darkwood_Stairs",
      "rotation": 9
    },
    {
      "x": -20,
      "y": 10,
      "z": 0,
      "name": "Wood_Darkwood_Planks"
    },
    {
      "x": -20,
      "y": 11,
      "z": 0,
      "name": "Wood_Darkwood_Planks"
    },
    {
      "x": -20,
      "y": 10,
      "z": 1,
      "name": "Wood_Oak_Trunk",
      "support": 15,
      "rotation": 4
    },
    {
      "x": -20,
      "y": 10,
      "z": 2,
      "name": "Wood_Oak_Trunk",
      "support": 15,
      "rotation": 4
    },
    {
      "x": -19,
      "y": 8,
      "z": 0,
      "name": "Wood_Darkwood_Stairs",
      "rotation": 9
    },
    {
      "x": -19,
      "y": 9,
      "z": 0,
      "name": "Wood_Darkwood_Planks"
    },
    {
      "x": -19,
      "y": 10,
      "z": 0,
      "name": "Wood_Darkwood_Stairs",
      "rotation": 1
    },
    {
      "x": -19,
      "y": 12,
      "z": 0,
      "name": "Cloth_Block_Wool_Red"
    },
    {
      "x": -18,
      "y": 7,
      "z": 0,
      "name": "Wood_Darkwood_Stairs",
      "rotation": 9
    },
    {
      "x": -18,
      "y": 8,
      "z": 0,
      "name": "Wood_Darkwood_Planks"
    },
    {
      "x": -18,
      "y": 9,
      "z": 0,
      "name": "Wood_Darkwood_Stairs",
      "rotation": 1
    },
    {
      "x": -18,
      "y": 13,
      "z": 0,
      "name": "Cloth_Block_Wool_Red"
    },
    {
      "x": -17,
      "y": 8,
      "z": -1,
      "name": "Wood_Deadwood_Planks"
    },
    {
      "x": -17,
      "y": 6,
      "z": 0,
      "name": "Wood_Darkwood_Stairs",
      "rotation": 9
    },
    {
      "x": -17,
      "y": 7,
      "z": 0,
      "name": "Wood_Darkwood_Planks"
    },
    {
      "x": -17,
      "y": 8,
      "z": 0,
      "name": "Wood_Deadwood_Planks"
    },
    {
      "x": -17,
      "y": 11,
      "z": 0,
      "name": "Wood_Darkwood_Planks_Half",
      "rotation": 7
    },
    {
      "x": -17,
      "y": 12,
      "z": 0,
      "name": "Wood_Darkwood_Planks"
    },
    {
      "x": -17,
      "y": 13,
      "z": 0,
      "name": "Wood_Darkwood_Planks"
    },
    {
      "x": -17,
      "y": 8,
      "z": 1,
      "name": "Wood_Deadwood_Planks"
    },
    {
      "x": -16,
      "y": 7,
      "z": -1,
      "name": "Wood_Deadwood_Planks"
    },
    {
      "x": -16,
      "y": 8,
      "z": -1,
      "name": "Wood_Deadwood_Planks"
    },
    {
      "x": -16,
      "y": 9,
      "z": -1,
      "name": "Wood_Deadwood_Planks"
    },
    {
      "x": -16,
      "y": 5,
      "z": 0,
      "name": "Wood_Darkwood_Stairs",
      "rotation": 9
    },
    {
      "x": -16,
      "y": 6,
      "z": 0,
      "name": "Wood_Darkwood_Planks"
    },
    {
      "x": -16,
      "y": 7,
      "z": 0,
      "name": "Wood_Deadwood_Planks"
    },
    {
      "x": -16,
      "y": 8,
      "z": 0,
      "name": "Wood_Deadwood_Planks"
    },
    {
      "x": -16,
      "y": 9,
      "z": 0,
      "name": "Wood_Deadwood_Planks"
    },
    {
      "x": -16,
      "y": 10,
      "z": 0,
      "name": "Wood_Darkwood_Planks"
    },
    {
      "x": -16,
      "y": 11,
      "z": 0,
      "name": "Wood_Darkwood_Planks"
    },
    {
      "x": -16,
      "y": 12,
      "z": 0,
      "name": "Wood_Darkwood_Planks_Half",
      "rotation": 5
    },
    {
      "x": -16,
      "y": 13,
      "z": 0,
      "name": "Cloth_Block_Wool_Red"
    },
    {
      "x": -16,
      "y": 7,
      "z": 1,
      "name": "Wood_Deadwood_Planks"
    },
    {
      "x": -16,
      "y": 8,
      "z": 1,
      "name": "Wood_Deadwood_Planks"
    },
    {
      "x": -16,
      "y": 9,
      "z": 1,
      "name": "Wood_Deadwood_Planks"
    },
    {
      "x": -15,
      "y": 8,
      "z": -2,
      "name": "Wood_Deadwood_Planks"
    },
    {
      "x": -15,
      "y": 9,
      "z": -2,
      "name": "Wood_Deadwood_Planks"
    },
    {
      "x": -15,
      "y": 5,
      "z": -1,
      "name": "Wood_Deadwood_Planks"
    },
    {
      "x": -15,
      "y": 6,
      "z": -1,
      "name": "Wood_Deadwood_Planks"
    },
    {
      "x": -15,
      "y": 7,
      "z": -1,
      "name": "Wood_Deadwood_Planks"
    },
    {
      "x": -15,
      "y": 8,
      "z": -1,
      "name": "Wood_Deadwood_Planks"
    },
    {
      "x": -15,
      "y": 9,
      "z": -1,
      "name": "Wood_Deadwood_Planks"
    },
    {
      "x": -15,
      "y": 4,
      "z": 0,
      "name": "Wood_Darkwood_Stairs",
      "rotation": 9
    },
    {
      "x": -15,
      "y": 5,
      "z": 0,
      "name": "Wood_Darkwood_Planks"
    },
    {
      "x": -15,
      "y": 6,
      "z": 0,
      "name": "Wood_Darkwood_Planks"
    },
    {
      "x": -15,
      "y": 7,
      "z": 0,
      "name": "Wood_Darkwood_Planks"
    },
    {
      "x": -15,
      "y": 8,
      "z": 0,
      "name": "Wood_Darkwood_Planks"
    },
    {
      "x": -15,
      "y": 9,
      "z": 0,
      "name": "Wood_Darkwood_Planks"
    },
    {
      "x": -15,
      "y": 10,
      "z": 0,
      "name": "Wood_Darkwood_Stairs",
      "rotation": 1
    },
    {
      "x": -15,
      "y": 14,
      "z": 0,
      "name": "Cloth_Block_Wool_Red"
    },
    {
      "x": -15,
      "y": 5,
      "z": 1,
      "name": "Wood_Deadwood_Planks"
    },
    {
      "x": -15,
      "y": 6,
      "z": 1,
      "name": "Wood_Deadwood_Planks"
    },
    {
      "x": -15,
      "y": 7,
      "z": 1,
      "name": "Wood_Deadwood_Planks"
    },
    {
      "x": -15,
      "y": 8,
      "z": 1,
      "name": "Wood_Deadwood_Planks"
    },
    {
      "x": -15,
      "y": 9,
      "z": 1,
      "name": "Wood_Deadwood_Planks"
    },
    {
      "x": -15,
      "y": 8,
      "z": 2,
      "name": "Wood_Deadwood_Planks"
    },
    {
      "x": -15,
      "y": 9,
      "z": 2,
      "name": "Wood_Deadwood_Planks"
    },
    {
      "x": -14,
      "y": 8,
      "z": -3,
      "name": "Wood_Deadwood_Planks"
    },
    {
      "x": -14,
      "y": 9,
      "z": -3,
      "name": "Wood_Deadwood_Planks"
    },
    {
      "x": -14,
      "y": 5,
      "z": -2,
      "name": "Wood_Deadwood_Planks"
    },
    {
      "x": -14,
      "y": 6,
      "z": -2,
      "name": "Wood_Deadwood_Planks"
    },
    {
      "x": -14,
      "y": 7,
      "z": -2,
      "name": "Wood_Deadwood_Planks"
    },
    {
      "x": -14,
      "y": 8,
      "z": -2,
      "name": "Wood_Deadwood_Planks"
    },
    {
      "x": -14,
      "y": 9,
      "z": -2,
      "name": "Wood_Deadwood_Planks"
    },
    {
      "x": -14,
      "y": 4,
      "z": -1,
      "name": "Wood_Deadwood_Planks"
    },
    {
      "x": -14,
      "y": 7,
      "z": -1,
      "name": "Wood_Darkwood_Planks"
    },
    {
      "x": -14,
      "y": 8,
      "z": -1,
      "name": "Wood_Darkwood_Planks"
    },
    {
      "x": -14,
      "y": 3,
      "z": 0,
      "name": "Wood_Darkwood_Stairs",
      "rotation": 9
    },
    {
      "x": -14,
      "y": 4,
      "z": 0,
      "name": "Wood_Darkwood_Planks"
    },
    {
      "x": -14,
      "y": 5,
      "z": 0,
      "name": "Wood_Darkwood_Planks"
    },
    {
      "x": -14,
      "y": 6,
      "z": 0,
      "name": "Wood_Darkwood_Planks"
    },
    {
      "x": -14,
      "y": 7,
      "z": 0,
      "name": "Wood_Darkwood_Planks"
    },
    {
      "x": -14,
      "y": 8,
      "z": 0,
      "name": "Wood_Darkwood_Planks"
    },
    {
      "x": -14,
      "y": 9,
      "z": 0,
      "name": "Wood_Darkwood_Planks_Half",
      "rotation": 5
    },
    {
      "x": -14,
      "y": 15,
      "z": 0,
      "name": "Cloth_Block_Wool_Red"
    },
    {
      "x": -14,
      "y": 4,
      "z": 1,
      "name": "Wood_Deadwood_Planks"
    },
    {
      "x": -14,
      "y": 7,
      "z": 1,
      "name": "Wood_Darkwood_Planks"
    },
    {
      "x": -14,
      "y": 8,
      "z": 1,
      "name": "Wood_Darkwood_Planks"
    },
    {
      "x": -14,
      "y": 5,
      "z": 2,
      "name": "Wood_Deadwood_Planks"
    },
    {
      "x": -14,
      "y": 6,
      "z": 2,
      "name": "Wood_Deadwood_Planks"
    },
    {
      "x": -14,
      "y": 7,
      "z": 2,
      "name": "Wood_Deadwood_Planks"
    },
    {
      "x": -14,
      "y": 8,
      "z": 2,
      "name": "Wood_Deadwood_Planks"
    },
    {
      "x": -14,
      "y": 9,
      "z": 2,
      "name": "Wood_Deadwood_Planks"
    },
    {
      "x": -14,
      "y": 8,
      "z": 3,
      "name": "Wood_Deadwood_Planks"
    },
    {
      "x": -14,
      "y": 9,
      "z": 3,
      "name": "Wood_Deadwood_Planks"
    },
    {
      "x": -13,
      "y": 9,
      "z": -4,
      "name": "Wood_Deadwood_Planks"
    },
    {
      "x": -13,
      "y": 6,
      "z": -3,
      "name": "Wood_Deadwood_Planks"
    },
    {
      "x": -13,
      "y": 7,
      "z": -3,
      "name": "Wood_Deadwood_Planks"
    },
    {
      "x": -13,
      "y": 8,
      "z": -3,
      "name": "Wood_Deadwood_Planks"
    },
    {
      "x": -13,
      "y": 9,
      "z": -3,
      "name": "Wood_Deadwood_Planks"
    },
    {
      "x": -13,
      "y": 4,
      "z": -2,
      "name": "Wood_Deadwood_Planks"
    },
    {
      "x": -13,
      "y": 5,
      "z": -2,
      "name": "Wood_Deadwood_Planks"
    },
    {
      "x": -13,
      "y": 6,
      "z": -2,
      "name": "Wood_Deadwood_Planks"
    },
    {
      "x": -13,
      "y": 7,
      "z": -2,
      "name": "Wood_Darkwood_Planks"
    },
    {
      "x": -13,
      "y": 8,
      "z": -2,
      "name": "Wood_Darkwood_Planks"
    },
    {
      "x": -13,
      "y": 3,
      "z": -1,
      "name": "Wood_Deadwood_Planks"
    },
    {
      "x": -13,
      "y": 4,
      "z": -1,
      "name": "Wood_Darkwood_Planks"
    },
    {
      "x": -13,
      "y": 7,
      "z": -1,
      "name": "Wood_Darkwood_Planks"
    },
    {
      "x": -13,
      "y": 8,
      "z": -1,
      "name": "Wood_Darkwood_Planks"
    },
    {
      "x": -13,
      "y": 3,
      "z": 0,
      "name": "Wood_Darkwood_Planks"
    },
    {
      "x": -13,
      "y": 4,
      "z": 0,
      "name": "Wood_Oak_Trunk",
      "support": 15,
      "rotation": 5
    },
    {
      "x": -13,
      "y": 5,
      "z": 0,
      "name": "Wood_Darkwood_Planks"
    },
    {
      "x": -13,
      "y": 7,
      "z": 0,
      "name": "Wood_Oak_Trunk",
      "support": 15,
      "rotation": 5
    },
    {
      "x": -13,
      "y": 8,
      "z": 0,
      "name": "Wood_Darkwood_Planks"
    },
    {
      "x": -13,
      "y": 16,
      "z": 0,
      "name": "Cloth_Block_Wool_Red"
    },
    {
      "x": -13,
      "y": 3,
      "z": 1,
      "name": "Wood_Deadwood_Planks"
    },
    {
      "x": -13,
      "y": 4,
      "z": 1,
      "name": "Wood_Darkwood_Planks"
    },
    {
      "x": -13,
      "y": 7,
      "z": 1,
      "name": "Wood_Darkwood_Planks"
    },
    {
      "x": -13,
      "y": 8,
      "z": 1,
      "name": "Wood_Darkwood_Planks"
    },
    {
      "x": -13,
      "y": 4,
      "z": 2,
      "name": "Wood_Deadwood_Planks"
    },
    {
      "x": -13,
      "y": 5,
      "z": 2,
      "name": "Wood_Deadwood_Planks"
    },
    {
      "x": -13,
      "y": 6,
      "z": 2,
      "name": "Wood_Deadwood_Planks"
    },
    {
      "x": -13,
      "y": 7,
      "z": 2,
      "name": "Wood_Darkwood_Planks"
    },
    {
      "x": -13,
      "y": 8,
      "z": 2,
      "name": "Wood_Darkwood_Planks"
    },
    {
      "x": -13,
      "y": 6,
      "z": 3,
      "name": "Wood_Deadwood_Planks"
    },
    {
      "x": -13,
      "y": 7,
      "z": 3,
      "name": "Wood_Deadwood_Planks"
    },
    {
      "x": -13,
      "y": 8,
      "z": 3,
      "name": "Wood_Deadwood_Planks"
    },
    {
      "x": -13,
      "y": 9,
      "z": 3,
      "name": "Wood_Deadwood_Planks"
    },
    {
      "x": -13,
      "y": 9,
      "z": 4,
      "name": "Wood_Deadwood_Planks"
    },
    {
      "x": -12,
      "y": 7,
      "z": -4,
      "name": "Wood_Redwood_Planks"
    },
    {
      "x": -12,
      "y": 8,
      "z": -4,
      "name": "Wood_Deadwood_Planks"
    },
    {
      "x": -12,
      "y": 9,
      "z": -4,
      "name": "Wood_Deadwood_Planks"
    },
    {
      "x": -12,
      "y": 5,
      "z": -3,
      "name": "Wood_Deadwood_Planks"
    },
    {
      "x": -12,
      "y": 6,
      "z": -3,
      "name": "Wood_Redwood_Planks"
    },
    {
      "x": -12,
      "y": 7,
      "z": -3,
      "name": "Wood_Darkwood_Planks"
    },
    {
      "x": -12,
      "y": 8,
      "z": -3,
      "name": "Wood_Darkwood_Planks"
    },
    {
      "x": -12,
      "y": 3,
      "z": -2,
      "name": "Wood_Deadwood_Planks"
    },
    {
      "x": -12,
      "y": 4,
      "z": -2,
      "name": "Wood_Deadwood_Planks"
    },
    {
      "x": -12,
      "y": 7,
      "z": -2,
      "name": "Wood_Darkwood_Planks"
    },
    {
      "x": -12,
      "y": 8,
      "z": -2,
      "name": "Wood_Darkwood_Planks"
    },
    {
      "x": -12,
      "y": 3,
      "z": -1,
      "name": "Wood_Deadwood_Planks"
    },
    {
      "x": -12,
      "y": 4,
      "z": -1,
      "name": "Wood_Darkwood_Planks"
    },
    {
      "x": -12,
      "y": 7,
      "z": -1,
      "name": "Wood_Darkwood_Planks"
    },
    {
      "x": -12,
      "y": 8,
      "z": -1,
      "name": "Wood_Darkwood_Planks"
    },
    {
      "x": -12,
      "y": 2,
      "z": 0,
      "name": "Wood_Darkwood_Stairs",
      "rotation": 9
    },
    {
      "x": -12,
      "y": 3,
      "z": 0,
      "name": "Wood_Darkwood_Planks"
    },
    {
      "x": -12,
      "y": 4,
      "z": 0,
      "name": "Wood_Oak_Trunk",
      "support": 15,
      "rotation": 5
    },
    {
      "x": -12,
      "y": 7,
      "z": 0,
      "name": "Wood_Oak_Trunk",
      "support": 15,
      "rotation": 5
    },
    {
      "x": -12,
      "y": 8,
      "z": 0,
      "name": "Wood_Darkwood_Planks"
    },
    {
      "x": -12,
      "y": 17,
      "z": 0,
      "name": "Cloth_Block_Wool_Red"
    },
    {
      "x": -12,
      "y": 3,
      "z": 1,
      "name": "Wood_Deadwood_Planks"
    },
    {
      "x": -12,
      "y": 4,
      "z": 1,
      "name": "Wood_Darkwood_Planks"
    },
    {
      "x": -12,
      "y": 7,
      "z": 1,
      "name": "Wood_Darkwood_Planks"
    },
    {
      "x": -12,
      "y": 8,
      "z": 1,
      "name": "Wood_Darkwood_Planks"
    },
    {
      "x": -12,
      "y": 3,
      "z": 2,
      "name": "Wood_Deadwood_Planks"
    },
    {
      "x": -12,
      "y": 4,
      "z": 2,
      "name": "Wood_Deadwood_Planks"
    },
    {
      "x": -12,
      "y": 7,
      "z": 2,
      "name": "Wood_Darkwood_Planks"
    },
    {
      "x": -12,
      "y": 8,
      "z": 2,
      "name": "Wood_Darkwood_Planks"
    },
    {
      "x": -12,
      "y": 5,
      "z": 3,
      "name": "Wood_Deadwood_Planks"
    },
    {
      "x": -12,
      "y": 6,
      "z": 3,
      "name": "Wood_Redwood_Planks"
    },
    {
      "x": -12,
      "y": 7,
      "z": 3,
      "name": "Wood_Redwood_Planks"
    },
    {
      "x": -12,
      "y": 8,
      "z": 3,
      "name": "Wood_Darkwood_Planks"
    },
    {
      "x": -12,
      "y": 7,
      "z": 4,
      "name": "Wood_Redwood_Planks"
    },
    {
      "x": -12,
      "y": 8,
      "z": 4,
      "name": "Wood_Deadwood_Planks"
    },
    {
      "x": -12,
      "y": 9,
      "z": 4,
      "name": "Wood_Deadwood_Planks"
    },
    {
      "x": -11,
      "y": 9,
      "z": -5,
      "name": "Wood_Deadwood_Planks"
    },
    {
      "x": -11,
      "y": 10,
      "z": -5,
      "name": "Cloth_Block_Wool_Red"
    },
    {
      "x": -11,
      "y": 17,
      "z": -5,
      "name": "Wood_Oak_Trunk",
      "support": 15,
      "rotation": 4
    },
    {
      "x": -11,
      "y": 6,
      "z": -4,
      "name": "Wood_Redwood_Planks"
    },
    {
      "x": -11,
      "y": 7,
      "z": -4,
      "name": "Wood_Redwood_Planks"
    },
    {
      "x": -11,
      "y": 8,
      "z": -4,
      "name": "Wood_Deadwood_Planks"
    },
    {
      "x": -11,
      "y": 9,
      "z": -4,
      "name": "Wood_Deadwood_Planks"
    },
    {
      "x": -11,
      "y": 11,
      "z": -4,
      "name": "Cloth_Block_Wool_Red"
    },
    {
      "x": -11,
      "y": 17,
      "z": -4,
      "name": "Wood_Oak_Trunk",
      "support": 15,
      "rotation": 4
    },
    {
      "x": -11,
      "y": 4,
      "z": -3,
      "name": "Wood_Deadwood_Planks"
    },
    {
      "x": -11,
      "y": 5,
      "z": -3,
      "name": "Wood_Deadwood_Planks"
    },
    {
      "x": -11,
      "y": 7,
      "z": -3,
      "name": "Wood_Oak_Trunk",
      "support": 15,
      "rotation": 4
    },
    {
      "x": -11,
      "y": 8,
      "z": -3,
      "name": "Wood_Darkwood_Stairs",
      "rotation": 1
    },
    {
      "x": -11,
      "y": 12,
      "z": -3,
      "name": "Cloth_Block_Wool_Red"
    },
    {
      "x": -11,
      "y": 17,
      "z": -3,
      "name": "Wood_Oak_Trunk",
      "support": 15,
      "rotation": 4
    },
    {
      "x": -11,
      "y": 3,
      "z": -2,
      "name": "Wood_Deadwood_Planks"
    },
    {
      "x": -11,
      "y": 4,
      "z": -2,
      "name": "Wood_Darkwood_Planks"
    },
    {
      "x": -11,
      "y": 7,
      "z": -2,
      "name": "Wood_Oak_Trunk",
      "support": 15,
      "rotation": 4
    },
    {
      "x": -11,
      "y": 8,
      "z": -2,
      "name": "Wood_Darkwood_Stairs",
      "rotation": 1
    },
    {
      "x": -11,
      "y": 13,
      "z": -2,
      "name": "Cloth_Block_Wool_Red"
    },
    {
      "x": -11,
      "y": 17,
      "z": -2,
      "name": "Wood_Oak_Trunk",
      "support": 15,
      "rotation": 4
    },
    {
      "x": -11,
      "y": 2,
      "z": -1,
      "name": "Wood_Deadwood_Planks"
    },
    {
      "x": -11,
      "y": 4,
      "z": -1,
      "name": "Wood_Darkwood_Planks"
    },
    {
      "x": -11,
      "y": 7,
      "z": -1,
      "name": "Wood_Oak_Trunk",
      "support": 15,
      "rotation": 4
    },
    {
      "x": -11,
      "y": 8,
      "z": -1,
      "name": "Wood_Darkwood_Stairs",
      "rotation": 1
    },
    {
      "x": -11,
      "y": 14,
      "z": -1,
      "name": "Cloth_Block_Wool_Red"
    },
    {
      "x": -11,
      "y": 16,
      "z": -1,
      "name": "Wood_Darkwood_Stairs",
      "rotation": 8
    },
    {
      "x": -11,
      "y": 17,
      "z": -1,
      "name": "Wood_Oak_Trunk",
      "support": 15,
      "rotation": 4
    },
    {
      "x": -11,
      "y": 2,
      "z": 0,
      "name": "Wood_Darkwood_Planks"
    },
    {
      "x": -11,
      "y": 3,
      "z": 0,
      "name": "Wood_Darkwood_Planks"
    },
    {
      "x": -11,
      "y": 4,
      "z": 0,
      "name": "Wood_Oak_Trunk",
      "support": 15,
      "rotation": 5
    },
    {
      "x": -11,
      "y": 5,
      "z": 0,
      "name": "Wood_Oak_Trunk",
      "support": 15
    },
    {
      "x": -11,
      "y": 6,
      "z": 0,
      "name": "Wood_Oak_Trunk",
      "support": 15
    },
    {
      "x": -11,
      "y": 7,
      "z": 0,
      "name": "Wood_Oak_Trunk",
      "support": 15
    },
    {
      "x": -11,
      "y": 8,
      "z": 0,
      "name": "Wood_Oak_Trunk",
      "support": 15
    },
    {
      "x": -11,
      "y": 9,
      "z": 0,
      "name": "Wood_Oak_Trunk",
      "support": 15
    },
    {
      "x": -11,
      "y": 10,
      "z": 0,
      "name": "Wood_Oak_Trunk",
      "support": 15
    },
    {
      "x": -11,
      "y": 11,
      "z": 0,
      "name": "Wood_Oak_Trunk",
      "support": 15
    },
    {
      "x": -11,
      "y": 12,
      "z": 0,
      "name": "Wood_Oak_Trunk",
      "support": 15
    },
    {
      "x": -11,
      "y": 13,
      "z": 0,
      "name": "Wood_Oak_Trunk",
      "support": 15
    },
    {
      "x": -11,
      "y": 14,
      "z": 0,
      "name": "Wood_Oak_Trunk",
      "support": 15
    },
    {
      "x": -11,
      "y": 15,
      "z": 0,
      "name": "Wood_Oak_Trunk",
      "support": 15
    },
    {
      "x": -11,
      "y": 16,
      "z": 0,
      "name": "Wood_Oak_Trunk",
      "support": 15
    },
    {
      "x": -11,
      "y": 17,
      "z": 0,
      "name": "Wood_Oak_Trunk",
      "support": 15
    },
    {
      "x": -11,
      "y": 18,
      "z": 0,
      "name": "Wood_Oak_Trunk",
      "support": 15
    },
    {
      "x": -11,
      "y": 19,
      "z": 0,
      "name": "Wood_Oak_Trunk",
      "support": 15
    },
    {
      "x": -11,
      "y": 2,
      "z": 1,
      "name": "Wood_Deadwood_Planks"
    },
    {
      "x": -11,
      "y": 3,
      "z": 1,
      "name": "Wood_Deadwood_Planks"
    },
    {
      "x": -11,
      "y": 4,
      "z": 1,
      "name": "Wood_Oak_Trunk",
      "support": 15,
      "rotation": 4
    },
    {
      "x": -11,
      "y": 7,
      "z": 1,
      "name": "Wood_Oak_Trunk",
      "support": 15,
      "rotation": 4
    },
    {
      "x": -11,
      "y": 8,
      "z": 1,
      "name": "Wood_Darkwood_Stairs",
      "rotation": 1
    },
    {
      "x": -11,
      "y": 14,
      "z": 1,
      "name": "Cloth_Block_Wool_Red"
    },
    {
      "x": -11,
      "y": 17,
      "z": 1,
      "name": "Wood_Oak_Trunk",
      "support": 15,
      "rotation": 4
    },
    {
      "x": -11,
      "y": 3,
      "z": 2,
      "name": "Wood_Deadwood_Planks"
    },
    {
      "x": -11,
      "y": 4,
      "z": 2,
      "name": "Wood_Oak_Trunk",
      "support": 15,
      "rotation": 4
    },
    {
      "x": -11,
      "y": 7,
      "z": 2,
      "name": "Wood_Oak_Trunk",
      "support": 15,
      "rotation": 4
    },
    {
      "x": -11,
      "y": 8,
      "z": 2,
      "name": "Wood_Darkwood_Stairs",
      "rotation": 1
    },
    {
      "x": -11,
      "y": 13,
      "z": 2,
      "name": "Cloth_Block_Wool_Red"
    },
    {
      "x": -11,
      "y": 17,
      "z": 2,
      "name": "Wood_Oak_Trunk",
      "support": 15,
      "rotation": 4
    },
    {
      "x": -11,
      "y": 4,
      "z": 3,
      "name": "Wood_Deadwood_Planks"
    },
    {
      "x": -11,
      "y": 5,
      "z": 3,
      "name": "Wood_Deadwood_Planks"
    },
    {
      "x": -11,
      "y": 6,
      "z": 3,
      "name": "Wood_Redwood_Planks"
    },
    {
      "x": -11,
      "y": 7,
      "z": 3,
      "name": "Wood_Oak_Trunk",
      "support": 15,
      "rotation": 4
    },
    {
      "x": -11,
      "y": 8,
      "z": 3,
      "name": "Wood_Darkwood_Stairs",
      "rotation": 1
    },
    {
      "x": -11,
      "y": 12,
      "z": 3,
      "name": "Cloth_Block_Wool_Red"
    },
    {
      "x": -11,
      "y": 17,
      "z": 3,
      "name": "Wood_Oak_Trunk",
      "support": 15,
      "rotation": 4
    },
    {
      "x": -11,
      "y": 6,
      "z": 4,
      "name": "Wood_Redwood_Planks"
    },
    {
      "x": -11,
      "y": 7,
      "z": 4,
      "name": "Wood_Redwood_Planks"
    },
    {
      "x": -11,
      "y": 8,
      "z": 4,
      "name": "Wood_Deadwood_Planks"
    },
    {
      "x": -11,
      "y": 9,
      "z": 4,
      "name": "Wood_Deadwood_Planks"
    },
    {
      "x": -11,
      "y": 11,
      "z": 4,
      "name": "Cloth_Block_Wool_Red"
    },
    {
      "x": -11,
      "y": 17,
      "z": 4,
      "name": "Wood_Oak_Trunk",
      "support": 15,
      "rotation": 4
    },
    {
      "x": -11,
      "y": 9,
      "z": 5,
      "name": "Wood_Deadwood_Planks"
    },
    {
      "x": -11,
      "y": 10,
      "z": 5,
      "name": "Cloth_Block_Wool_Red"
    },
    {
      "x": -11,
      "y": 17,
      "z": 5,
      "name": "Wood_Oak_Trunk",
      "support": 15,
      "rotation": 4
    },
    {
      "x": -10,
      "y": 7,
      "z": -5,
      "name": "Wood_Redwood_Planks"
    },
    {
      "x": -10,
      "y": 8,
      "z": -5,
      "name": "Wood_Deadwood_Planks"
    },
    {
      "x": -10,
      "y": 9,
      "z": -5,
      "name": "Wood_Deadwood_Planks"
    },
    {
      "x": -10,
      "y": 5,
      "z": -4,
      "name": "Wood_Deadwood_Planks"
    },
    {
      "x": -10,
      "y": 6,
      "z": -4,
      "name": "Wood_Redwood_Planks"
    },
    {
      "x": -10,
      "y": 7,
      "z": -4,
      "name": "Wood_Oak_Trunk",
      "support": 15,
      "rotation": 5
    },
    {
      "x": -10,
      "y": 8,
      "z": -4,
      "name": "Wood_Deadwood_Planks"
    },
    {
      "x": -10,
      "y": 4,
      "z": -3,
      "name": "Wood_Deadwood_Planks"
    },
    {
      "x": -10,
      "y": 7,
      "z": -3,
      "name": "Wood_Darkwood_Planks"
    },
    {
      "x": -10,
      "y": 3,
      "z": -2,
      "name": "Wood_Deadwood_Planks"
    },
    {
      "x": -10,
      "y": 4,
      "z": -2,
      "name": "Wood_Darkwood_Planks"
    },
    {
      "x": -10,
      "y": 7,
      "z": -2,
      "name": "Wood_Darkwood_Planks"
    },
    {
      "x": -10,
      "y": 2,
      "z": -1,
      "name": "Wood_Deadwood_Planks"
    },
    {
      "x": -10,
      "y": 4,
      "z": -1,
      "name": "Wood_Darkwood_Planks"
    },
    {
      "x": -10,
      "y": 7,
      "z": -1,
      "name": "Wood_Darkwood_Planks"
    },
    {
      "x": -10,
      "y": 1,
      "z": 0,
      "name": "Wood_Darkwood_Stairs",
      "rotation": 9
    },
    {
      "x": -10,
      "y": 4,
      "z": 0,
      "name": "Wood_Oak_Trunk",
      "support": 15,
      "rotation": 5
    },
    {
      "x": -10,
      "y": 7,
      "z": 0,
      "name": "Wood_Oak_Trunk",
      "support": 15,
      "rotation": 5
    },
    {
      "x": -10,
      "y": 19,
      "z": 0,
      "name": "Cloth_Block_Wool_Red"
    },
    {
      "x": -10,
      "y": 2,
      "z": 1,
      "name": "Wood_Deadwood_Planks"
    },
    {
      "x": -10,
      "y": 4,
      "z": 1,
      "name": "Wood_Darkwood_Planks"
    },
    {
      "x": -10,
      "y": 7,
      "z": 1,
      "name": "Wood_Darkwood_Planks"
    },
    {
      "x": -10,
      "y": 3,
      "z": 2,
      "name": "Wood_Deadwood_Planks"
    },
    {
      "x": -10,
      "y": 4,
      "z": 2,
      "name": "Wood_Darkwood_Planks"
    },
    {
      "x": -10,
      "y": 7,
      "z": 2,
      "name": "Wood_Darkwood_Planks"
    },
    {
      "x": -10,
      "y": 4,
      "z": 3,
      "name": "Wood_Deadwood_Planks"
    },
    {
      "x": -10,
      "y": 7,
      "z": 3,
      "name": "Wood_Darkwood_Planks"
    },
    {
      "x": -10,
      "y": 5,
      "z": 4,
      "name": "Wood_Deadwood_Planks"
    },
    {
      "x": -10,
      "y": 6,
      "z": 4,
      "name": "Wood_Redwood_Planks"
    },
    {
      "x": -10,
      "y": 7,
      "z": 4,
      "name": "Wood_Oak_Trunk",
      "support": 15,
      "rotation": 5
    },
    {
      "x": -10,
      "y": 8,
      "z": 4,
      "name": "Wood_Deadwood_Planks"
    },
    {
      "x": -10,
      "y": 7,
      "z": 5,
      "name": "Wood_Redwood_Planks"
    },
    {
      "x": -10,
      "y": 8,
      "z": 5,
      "name": "Wood_Deadwood_Planks"
    },
    {
      "x": -10,
      "y": 9,
      "z": 5,
      "name": "Wood_Deadwood_Planks"
    },
    {
      "x": -9,
      "y": 5,
      "z": -5,
      "name": "Wood_Deadwood_Planks"
    },
    {
      "x": -9,
      "y": 6,
      "z": -5,
      "name": "Wood_Redwood_Planks"
    },
    {
      "x": -9,
      "y": 7,
      "z": -5,
      "name": "Wood_Redwood_Planks"
    },
    {
      "x": -9,
      "y": 8,
      "z": -5,
      "name": "Wood_Deadwood_Planks"
    },
    {
      "x": -9,
      "y": 4,
      "z": -4,
      "name": "Wood_Redwood_Planks"
    },
    {
      "x": -9,
      "y": 7,
      "z": -4,
      "name": "Wood_Oak_Trunk",
      "support": 15,
      "rotation": 5
    },
    {
      "x": -9,
      "y": 3,
      "z": -3,
      "name": "Wood_Redwood_Planks"
    },
    {
      "x": -9,
      "y": 4,
      "z": -3,
      "name": "Wood_Darkwood_Planks"
    },
    {
      "x": -9,
      "y": 7,
      "z": -3,
      "name": "Wood_Darkwood_Planks"
    },
    {
      "x": -9,
      "y": 2,
      "z": -2,
      "name": "Wood_Deadwood_Planks"
    },
    {
      "x": -9,
      "y": 4,
      "z": -2,
      "name": "Wood_Darkwood_Planks"
    },
    {
      "x": -9,
      "y": 7,
      "z": -2,
      "name": "Wood_Darkwood_Planks"
    },
    {
      "x": -9,
      "y": 1,
      "z": -1,
      "name": "Wood_Deadwood_Planks"
    },
    {
      "x": -9,
      "y": 2,
      "z": -1,
      "name": "Wood_Deadwood_Planks"
    },
    {
      "x": -9,
      "y": 4,
      "z": -1,
      "name": "Wood_Darkwood_Planks"
    },
    {
      "x": -9,
      "y": 7,
      "z": -1,
      "name": "Wood_Darkwood_Planks"
    },
    {
      "x": -9,
      "y": 1,
      "z": 0,
      "name": "Wood_Darkwood_Planks"
    },
    {
      "x": -9,
      "y": 4,
      "z": 0,
      "name": "Wood_Oak_Trunk",
      "support": 15,
      "rotation": 5
    },
    {
      "x": -9,
      "y": 7,
      "z": 0,
      "name": "Wood_Oak_Trunk",
      "support": 15,
      "rotation": 5
    },
    {
      "x": -9,
      "y": 19,
      "z": 0,
      "name": "Cloth_Block_Wool_Red"
    },
    {
      "x": -9,
      "y": 20,
      "z": 0,
      "name": "Cloth_Block_Wool_Red"
    },
    {
      "x": -9,
      "y": 1,
      "z": 1,
      "name": "Wood_Deadwood_Planks"
    },
    {
      "x": -9,
      "y": 2,
      "z": 1,
      "name": "Wood_Deadwood_Planks"
    },
    {
      "x": -9,
      "y": 4,
      "z": 1,
      "name": "Wood_Darkwood_Planks"
    },
    {
      "x": -9,
      "y": 7,
      "z": 1,
      "name": "Wood_Darkwood_Planks"
    },
    {
      "x": -9,
      "y": 2,
      "z": 2,
      "name": "Wood_Deadwood_Planks"
    },
    {
      "x": -9,
      "y": 3,
      "z": 2,
      "name": "Wood_Deadwood_Planks"
    },
    {
      "x": -9,
      "y": 4,
      "z": 2,
      "name": "Wood_Darkwood_Planks"
    },
    {
      "x": -9,
      "y": 7,
      "z": 2,
      "name": "Wood_Darkwood_Planks"
    },
    {
      "x": -9,
      "y": 3,
      "z": 3,
      "name": "Wood_Redwood_Planks"
    },
    {
      "x": -9,
      "y": 4,
      "z": 3,
      "name": "Wood_Darkwood_Planks"
    },
    {
      "x": -9,
      "y": 7,
      "z": 3,
      "name": "Wood_Darkwood_Planks"
    },
    {
      "x": -9,
      "y": 4,
      "z": 4,
      "name": "Wood_Redwood_Planks"
    },
    {
      "x": -9,
      "y": 5,
      "z": 4,
      "name": "Wood_Deadwood_Planks"
    },
    {
      "x": -9,
      "y": 7,
      "z": 4,
      "name": "Wood_Oak_Trunk",
      "support": 15,
      "rotation": 5
    },
    {
      "x": -9,
      "y": 5,
      "z": 5,
      "name": "Wood_Deadwood_Planks"
    },
    {
      "x": -9,
      "y": 6,
      "z": 5,
      "name": "Wood_Redwood_Planks"
    },
    {
      "x": -9,
      "y": 7,
      "z": 5,
      "name": "Wood_Redwood_Planks"
    },
    {
      "x": -9,
      "y": 8,
      "z": 5,
      "name": "Wood_Deadwood_Planks"
    },
    {
      "x": -8,
      "y": 4,
      "z": -5,
      "name": "Wood_Redwood_Planks"
    },
    {
      "x": -8,
      "y": 5,
      "z": -5,
      "name": "Wood_Deadwood_Planks"
    },
    {
      "x": -8,
      "y": 6,
      "z": -5,
      "name": "Wood_Redwood_Planks"
    },
    {
      "x": -8,
      "y": 7,
      "z": -5,
      "name": "Wood_Redwood_Planks"
    },
    {
      "x": -8,
      "y": 8,
      "z": -5,
      "name": "Wood_Deadwood_Planks"
    },
    {
      "x": -8,
      "y": 3,
      "z": -4,
      "name": "Wood_Redwood_Planks"
    },
    {
      "x": -8,
      "y": 4,
      "z": -4,
      "name": "Wood_Oak_Trunk",
      "support": 15,
      "rotation": 5
    },
    {
      "x": -8,
      "y": 7,
      "z": -4,
      "name": "Wood_Oak_Trunk",
      "support": 15,
      "rotation": 5
    },
    {
      "x": -8,
      "y": 3,
      "z": -3,
      "name": "Wood_Redwood_Planks"
    },
    {
      "x": -8,
      "y": 4,
      "z": -3,
      "name": "Wood_Darkwood_Planks"
    },
    {
      "x": -8,
      "y": 7,
      "z": -3,
      "name": "Wood_Darkwood_Planks"
    },
    {
      "x": -8,
      "y": 2,
      "z": -2,
      "name": "Wood_Deadwood_Planks"
    },
    {
      "x": -8,
      "y": 4,
      "z": -2,
      "name": "Wood_Darkwood_Planks"
    },
    {
      "x": -8,
      "y": 6,
      "z": -2,
      "name": "Wood_Darkwood_Stairs",
      "rotation": 8
    },
    {
      "x": -8,
      "y": 7,
      "z": -2,
      "name": "Wood_Darkwood_Stairs"
    },
    {
      "x": -8,
      "y": 1,
      "z": -1,
      "name": "Wood_Deadwood_Planks"
    },
    {
      "x": -8,
      "y": 2,
      "z": -1,
      "name": "Wood_Deadwood_Planks"
    },
    {
      "x": -8,
      "y": 4,
      "z": -1,
      "name": "Wood_Darkwood_Planks"
    },
    {
      "x": -8,
      "y": 5,
      "z": -1,
      "name": "Wood_Darkwood_Stairs",
      "rotation": 8
    },
    {
      "x": -8,
      "y": 6,
      "z": -1,
      "name": "Wood_Darkwood_Stairs"
    },
    {
      "x": -8,
      "y": 1,
      "z": 0,
      "name": "Wood_Darkwood_Planks"
    },
    {
      "x": -8,
      "y": 4,
      "z": 0,
      "name": "Wood_Oak_Trunk",
      "support": 15,
      "rotation": 5
    },
    {
      "x": -8,
      "y": 5,
      "z": 0,
      "name": "Wood_Darkwood_Stairs"
    },
    {
      "x": -8,
      "y": 19,
      "z": 0,
      "name": "Cloth_Block_Wool_Red"
    },
    {
      "x": -8,
      "y": 21,
      "z": 0,
      "name": "Cloth_Block_Wool_Red"
    },
    {
      "x": -8,
      "y": 1,
      "z": 1,
      "name": "Wood_Deadwood_Planks"
    },
    {
      "x": -8,
      "y": 2,
      "z": 1,
      "name": "Wood_Deadwood_Planks"
    },
    {
      "x": -8,
      "y": 4,
      "z": 1,
      "name": "Wood_Darkwood_Planks"
    },
    {
      "x": -8,
      "y": 2,
      "z": 2,
      "name": "Wood_Deadwood_Planks"
    },
    {
      "x": -8,
      "y": 4,
      "z": 2,
      "name": "Wood_Darkwood_Planks"
    },
    {
      "x": -8,
      "y": 7,
      "z": 2,
      "name": "Wood_Darkwood_Planks"
    },
    {
      "x": -8,
      "y": 3,
      "z": 3,
      "name": "Wood_Redwood_Planks"
    },
    {
      "x": -8,
      "y": 4,
      "z": 3,
      "name": "Wood_Darkwood_Planks"
    },
    {
      "x": -8,
      "y": 7,
      "z": 3,
      "name": "Wood_Darkwood_Planks"
    },
    {
      "x": -8,
      "y": 3,
      "z": 4,
      "name": "Wood_Redwood_Planks"
    },
    {
      "x": -8,
      "y": 4,
      "z": 4,
      "name": "Wood_Oak_Trunk",
      "support": 15,
      "rotation": 5
    },
    {
      "x": -8,
      "y": 7,
      "z": 4,
      "name": "Wood_Oak_Trunk",
      "support": 15,
      "rotation": 5
    },
    {
      "x": -8,
      "y": 4,
      "z": 5,
      "name": "Wood_Redwood_Planks"
    },
    {
      "x": -8,
      "y": 5,
      "z": 5,
      "name": "Wood_Deadwood_Planks"
    },
    {
      "x": -8,
      "y": 6,
      "z": 5,
      "name": "Wood_Redwood_Planks"
    },
    {
      "x": -8,
      "y": 7,
      "z": 5,
      "name": "Wood_Redwood_Planks"
    },
    {
      "x": -8,
      "y": 8,
      "z": 5,
      "name": "Wood_Deadwood_Planks"
    },
    {
      "x": -7,
      "y": 4,
      "z": -5,
      "name": "Wood_Redwood_Planks"
    },
    {
      "x": -7,
      "y": 5,
      "z": -5,
      "name": "Wood_Deadwood_Planks"
    },
    {
      "x": -7,
      "y": 6,
      "z": -5,
      "name": "Wood_Redwood_Planks"
    },
    {
      "x": -7,
      "y": 7,
      "z": -5,
      "name": "Wood_Redwood_Planks"
    },
    {
      "x": -7,
      "y": 8,
      "z": -5,
      "name": "Wood_Deadwood_Planks"
    },
    {
      "x": -7,
      "y": 3,
      "z": -4,
      "name": "Wood_Redwood_Planks"
    },
    {
      "x": -7,
      "y": 4,
      "z": -4,
      "name": "Wood_Oak_Trunk",
      "support": 15,
      "rotation": 5
    },
    {
      "x": -7,
      "y": 7,
      "z": -4,
      "name": "Wood_Oak_Trunk",
      "support": 15,
      "rotation": 5
    },
    {
      "x": -7,
      "y": 2,
      "z": -3,
      "name": "Wood_Deadwood_Planks"
    },
    {
      "x": -7,
      "y": 3,
      "z": -3,
      "name": "Wood_Redwood_Planks"
    },
    {
      "x": -7,
      "y": 4,
      "z": -3,
      "name": "Wood_Darkwood_Planks"
    },
    {
      "x": -7,
      "y": 7,
      "z": -3,
      "name": "Wood_Darkwood_Planks"
    },
    {
      "x": -7,
      "y": 2,
      "z": -2,
      "name": "Wood_Deadwood_Planks"
    },
    {
      "x": -7,
      "y": 4,
      "z": -2,
      "name": "Wood_Darkwood_Planks"
    },
    {
      "x": -7,
      "y": 6,
      "z": -2,
      "name": "Wood_Darkwood_Stairs",
      "rotation": 8
    },
    {
      "x": -7,
      "y": 7,
      "z": -2,
      "name": "Wood_Darkwood_Stairs"
    },
    {
      "x": -7,
      "y": 1,
      "z": -1,
      "name": "Wood_Deadwood_Planks"
    },
    {
      "x": -7,
      "y": 2,
      "z": -1,
      "name": "Wood_Deadwood_Planks"
    },
    {
      "x": -7,
      "y": 4,
      "z": -1,
      "name": "Wood_Darkwood_Planks"
    },
    {
      "x": -7,
      "y": 5,
      "z": -1,
      "name": "Wood_Darkwood_Stairs",
      "rotation": 8
    },
    {
      "x": -7,
      "y": 6,
      "z": -1,
      "name": "Wood_Darkwood_Stairs"
    },
    {
      "x": -7,
      "y": 1,
      "z": 0,
      "name": "Wood_Darkwood_Planks"
    },
    {
      "x": -7,
      "y": 4,
      "z": 0,
      "name": "Wood_Oak_Trunk",
      "support": 15,
      "rotation": 5
    },
    {
      "x": -7,
      "y": 5,
      "z": 0,
      "name": "Wood_Darkwood_Stairs"
    },
    {
      "x": -7,
      "y": 19,
      "z": 0,
      "name": "Cloth_Block_Wool_Red"
    },
    {
      "x": -7,
      "y": 22,
      "z": 0,
      "name": "Cloth_Block_Wool_Red"
    },
    {
      "x": -7,
      "y": 1,
      "z": 1,
      "name": "Wood_Deadwood_Planks"
    },
    {
      "x": -7,
      "y": 2,
      "z": 1,
      "name": "Wood_Deadwood_Planks"
    },
    {
      "x": -7,
      "y": 4,
      "z": 1,
      "name": "Wood_Darkwood_Planks"
    },
    {
      "x": -7,
      "y": 2,
      "z": 2,
      "name": "Wood_Deadwood_Planks"
    },
    {
      "x": -7,
      "y": 4,
      "z": 2,
      "name": "Wood_Darkwood_Planks"
    },
    {
      "x": -7,
      "y": 7,
      "z": 2,
      "name": "Wood_Darkwood_Planks"
    },
    {
      "x": -7,
      "y": 2,
      "z": 3,
      "name": "Wood_Deadwood_Planks"
    },
    {
      "x": -7,
      "y": 3,
      "z": 3,
      "name": "Wood_Redwood_Planks"
    },
    {
      "x": -7,
      "y": 4,
      "z": 3,
      "name": "Wood_Darkwood_Planks"
    },
    {
      "x": -7,
      "y": 7,
      "z": 3,
      "name": "Wood_Darkwood_Planks"
    },
    {
      "x": -7,
      "y": 3,
      "z": 4,
      "name": "Wood_Redwood_Planks"
    },
    {
      "x": -7,
      "y": 4,
      "z": 4,
      "name": "Wood_Oak_Trunk",
      "support": 15,
      "rotation": 5
    },
    {
      "x": -7,
      "y": 7,
      "z": 4,
      "name": "Wood_Oak_Trunk",
      "support": 15,
      "rotation": 5
    },
    {
      "x": -7,
      "y": 4,
      "z": 5,
      "name": "Wood_Redwood_Planks"
    },
    {
      "x": -7,
      "y": 5,
      "z": 5,
      "name": "Wood_Deadwood_Planks"
    },
    {
      "x": -7,
      "y": 6,
      "z": 5,
      "name": "Wood_Redwood_Planks"
    },
    {
      "x": -7,
      "y": 7,
      "z": 5,
      "name": "Wood_Redwood_Planks"
    },
    {
      "x": -7,
      "y": 8,
      "z": 5,
      "name": "Wood_Deadwood_Planks"
    },
    {
      "x": -6,
      "y": 5,
      "z": -6,
      "name": "Furniture_Tavern_Shelf",
      "rotation": 2
    },
    {
      "x": -6,
      "y": 4,
      "z": -5,
      "name": "Wood_Redwood_Planks"
    },
    {
      "x": -6,
      "y": 5,
      "z": -5,
      "name": "Wood_Deadwood_Planks"
    },
    {
      "x": -6,
      "y": 7,
      "z": -5,
      "name": "Wood_Redwood_Planks"
    },
    {
      "x": -6,
      "y": 8,
      "z": -5,
      "name": "Wood_Deadwood_Planks"
    },
    {
      "x": -6,
      "y": 3,
      "z": -4,
      "name": "Wood_Redwood_Planks"
    },
    {
      "x": -6,
      "y": 4,
      "z": -4,
      "name": "Wood_Oak_Trunk",
      "support": 15,
      "rotation": 5
    },
    {
      "x": -6,
      "y": 7,
      "z": -4,
      "name": "Wood_Oak_Trunk",
      "support": 15,
      "rotation": 5
    },
    {
      "x": -6,
      "y": 2,
      "z": -3,
      "name": "Wood_Deadwood_Planks"
    },
    {
      "x": -6,
      "y": 3,
      "z": -3,
      "name": "Wood_Redwood_Planks"
    },
    {
      "x": -6,
      "y": 4,
      "z": -3,
      "name": "Wood_Darkwood_Planks"
    },
    {
      "x": -6,
      "y": 7,
      "z": -3,
      "name": "Wood_Darkwood_Planks"
    },
    {
      "x": -6,
      "y": 1,
      "z": -2,
      "name": "Wood_Deadwood_Planks"
    },
    {
      "x": -6,
      "y": 2,
      "z": -2,
      "name": "Wood_Deadwood_Planks"
    },
    {
      "x": -6,
      "y": 4,
      "z": -2,
      "name": "Wood_Darkwood_Planks"
    },
    {
      "x": -6,
      "y": 6,
      "z": -2,
      "name": "Wood_Darkwood_Stairs",
      "rotation": 8
    },
    {
      "x": -6,
      "y": 7,
      "z": -2,
      "name": "Wood_Darkwood_Stairs"
    },
    {
      "x": -6,
      "y": 1,
      "z": -1,
      "name": "Wood_Deadwood_Planks"
    },
    {
      "x": -6,
      "y": 4,
      "z": -1,
      "name": "Wood_Darkwood_Planks"
    },
    {
      "x": -6,
      "y": 5,
      "z": -1,
      "name": "Wood_Darkwood_Stairs",
      "rotation": 8
    },
    {
      "x": -6,
      "y": 6,
      "z": -1,
      "name": "Wood_Darkwood_Stairs"
    },
    {
      "x": -6,
      "y": 1,
      "z": 0,
      "name": "Wood_Darkwood_Planks"
    },
    {
      "x": -6,
      "y": 4,
      "z": 0,
      "name": "Wood_Oak_Trunk",
      "support": 15,
      "rotation": 5
    },
    {
      "x": -6,
      "y": 5,
      "z": 0,
      "name": "Wood_Darkwood_Stairs"
    },
    {
      "x": -6,
      "y": 19,
      "z": 0,
      "name": "Cloth_Block_Wool_Red"
    },
    {
      "x": -6,
      "y": 23,
      "z": 0,
      "name": "Cloth_Block_Wool_Red"
    },
    {
      "x": -6,
      "y": 1,
      "z": 1,
      "name": "Wood_Deadwood_Planks"
    },
    {
      "x": -6,
      "y": 4,
      "z": 1,
      "name": "Wood_Darkwood_Planks"
    },
    {
      "x": -6,
      "y": 1,
      "z": 2,
      "name": "Wood_Deadwood_Planks"
    },
    {
      "x": -6,
      "y": 2,
      "z": 2,
      "name": "Wood_Deadwood_Planks"
    },
    {
      "x": -6,
      "y": 4,
      "z": 2,
      "name": "Wood_Darkwood_Planks"
    },
    {
      "x": -6,
      "y": 7,
      "z": 2,
      "name": "Wood_Darkwood_Planks"
    },
    {
      "x": -6,
      "y": 2,
      "z": 3,
      "name": "Wood_Deadwood_Planks"
    },
    {
      "x": -6,
      "y": 3,
      "z": 3,
      "name": "Wood_Redwood_Planks"
    },
    {
      "x": -6,
      "y": 4,
      "z": 3,
      "name": "Wood_Darkwood_Planks"
    },
    {
      "x": -6,
      "y": 7,
      "z": 3,
      "name": "Wood_Darkwood_Planks"
    },
    {
      "x": -6,
      "y": 3,
      "z": 4,
      "name": "Wood_Redwood_Planks"
    },
    {
      "x": -6,
      "y": 4,
      "z": 4,
      "name": "Wood_Oak_Trunk",
      "support": 15,
      "rotation": 5
    },
    {
      "x": -6,
      "y": 7,
      "z": 4,
      "name": "Wood_Oak_Trunk",
      "support": 15,
      "rotation": 5
    },
    {
      "x": -6,
      "y": 4,
      "z": 5,
      "name": "Wood_Redwood_Planks"
    },
    {
      "x": -6,
      "y": 5,
      "z": 5,
      "name": "Wood_Deadwood_Planks"
    },
    {
      "x": -6,
      "y": 7,
      "z": 5,
      "name": "Wood_Redwood_Planks"
    },
    {
      "x": -6,
      "y": 8,
      "z": 5,
      "name": "Wood_Deadwood_Planks"
    },
    {
      "x": -6,
      "y": 5,
      "z": 6,
      "name": "Furniture_Tavern_Shelf"
    },
    {
      "x": -5,
      "y": 4,
      "z": -5,
      "name": "Wood_Redwood_Planks"
    },
    {
      "x": -5,
      "y": 5,
      "z": -5,
      "name": "Wood_Deadwood_Planks"
    },
    {
      "x": -5,
      "y": 6,
      "z": -5,
      "name": "Wood_Redwood_Planks"
    },
    {
      "x": -5,
      "y": 7,
      "z": -5,
      "name": "Wood_Redwood_Planks"
    },
    {
      "x": -5,
      "y": 8,
      "z": -5,
      "name": "Wood_Deadwood_Planks"
    },
    {
      "x": -5,
      "y": 3,
      "z": -4,
      "name": "Wood_Redwood_Planks"
    },
    {
      "x": -5,
      "y": 4,
      "z": -4,
      "name": "Wood_Oak_Trunk",
      "support": 15,
      "rotation": 5
    },
    {
      "x": -5,
      "y": 7,
      "z": -4,
      "name": "Wood_Oak_Trunk",
      "support": 15,
      "rotation": 5
    },
    {
      "x": -5,
      "y": 2,
      "z": -3,
      "name": "Wood_Deadwood_Planks"
    },
    {
      "x": -5,
      "y": 3,
      "z": -3,
      "name": "Wood_Redwood_Planks"
    },
    {
      "x": -5,
      "y": 4,
      "z": -3,
      "name": "Wood_Darkwood_Planks"
    },
    {
      "x": -5,
      "y": 7,
      "z": -3,
      "name": "Wood_Darkwood_Planks"
    },
    {
      "x": -5,
      "y": 1,
      "z": -2,
      "name": "Wood_Deadwood_Planks"
    },
    {
      "x": -5,
      "y": 2,
      "z": -2,
      "name": "Wood_Deadwood_Planks"
    },
    {
      "x": -5,
      "y": 4,
      "z": -2,
      "name": "Wood_Darkwood_Planks"
    },
    {
      "x": -5,
      "y": 7,
      "z": -2,
      "name": "Wood_Darkwood_Planks"
    },
    {
      "x": -5,
      "y": 1,
      "z": -1,
      "name": "Wood_Deadwood_Planks"
    },
    {
      "x": -5,
      "y": 4,
      "z": -1,
      "name": "Wood_Darkwood_Planks"
    },
    {
      "x": -5,
      "y": 7,
      "z": -1,
      "name": "Wood_Darkwood_Planks"
    },
    {
      "x": -5,
      "y": 1,
      "z": 0,
      "name": "Wood_Darkwood_Planks"
    },
    {
      "x": -5,
      "y": 4,
      "z": 0,
      "name": "Wood_Oak_Trunk",
      "support": 15,
      "rotation": 5
    },
    {
      "x": -5,
      "y": 7,
      "z": 0,
      "name": "Wood_Oak_Trunk",
      "support": 15,
      "rotation": 5
    },
    {
      "x": -5,
      "y": 19,
      "z": 0,
      "name": "Cloth_Block_Wool_Red"
    },
    {
      "x": -5,
      "y": 24,
      "z": 0,
      "name": "Cloth_Block_Wool_Red"
    },
    {
      "x": -5,
      "y": 1,
      "z": 1,
      "name": "Wood_Deadwood_Planks"
    },
    {
      "x": -5,
      "y": 4,
      "z": 1,
      "name": "Wood_Darkwood_Planks"
    },
    {
      "x": -5,
      "y": 7,
      "z": 1,
      "name": "Wood_Darkwood_Planks"
    },
    {
      "x": -5,
      "y": 1,
      "z": 2,
      "name": "Wood_Deadwood_Planks"
    },
    {
      "x": -5,
      "y": 2,
      "z": 2,
      "name": "Wood_Deadwood_Planks"
    },
    {
      "x": -5,
      "y": 4,
      "z": 2,
      "name": "Wood_Darkwood_Planks"
    },
    {
      "x": -5,
      "y": 7,
      "z": 2,
      "name": "Wood_Darkwood_Planks"
    },
    {
      "x": -5,
      "y": 2,
      "z": 3,
      "name": "Wood_Deadwood_Planks"
    },
    {
      "x": -5,
      "y": 3,
      "z": 3,
      "name": "Wood_Redwood_Planks"
    },
    {
      "x": -5,
      "y": 4,
      "z": 3,
      "name": "Wood_Darkwood_Planks"
    },
    {
      "x": -5,
      "y": 7,
      "z": 3,
      "name": "Wood_Darkwood_Planks"
    },
    {
      "x": -5,
      "y": 3,
      "z": 4,
      "name": "Wood_Redwood_Planks"
    },
    {
      "x": -5,
      "y": 4,
      "z": 4,
      "name": "Wood_Oak_Trunk",
      "support": 15,
      "rotation": 5
    },
    {
      "x": -5,
      "y": 7,
      "z": 4,
      "name": "Wood_Oak_Trunk",
      "support": 15,
      "rotation": 5
    },
    {
      "x": -5,
      "y": 4,
      "z": 5,
      "name": "Wood_Redwood_Planks"
    },
    {
      "x": -5,
      "y": 5,
      "z": 5,
      "name": "Wood_Deadwood_Planks"
    },
    {
      "x": -5,
      "y": 6,
      "z": 5,
      "name": "Wood_Redwood_Planks"
    },
    {
      "x": -5,
      "y": 7,
      "z": 5,
      "name": "Wood_Redwood_Planks"
    },
    {
      "x": -5,
      "y": 8,
      "z": 5,
      "name": "Wood_Deadwood_Planks"
    },
    {
      "x": -4,
      "y": 5,
      "z": -6,
      "name": "Furniture_Tavern_Shelf",
      "rotation": 2
    },
    {
      "x": -4,
      "y": 4,
      "z": -5,
      "name": "Wood_Redwood_Planks"
    },
    {
      "x": -4,
      "y": 5,
      "z": -5,
      "name": "Wood_Deadwood_Planks"
    },
    {
      "x": -4,
      "y": 7,
      "z": -5,
      "name": "Wood_Redwood_Planks"
    },
    {
      "x": -4,
      "y": 8,
      "z": -5,
      "name": "Wood_Deadwood_Planks"
    },
    {
      "x": -4,
      "y": 2,
      "z": -4,
      "name": "Wood_Deadwood_Planks"
    },
    {
      "x": -4,
      "y": 3,
      "z": -4,
      "name": "Wood_Redwood_Planks"
    },
    {
      "x": -4,
      "y": 4,
      "z": -4,
      "name": "Wood_Oak_Trunk",
      "support": 15,
      "rotation": 5
    },
    {
      "x": -4,
      "y": 7,
      "z": -4,
      "name": "Wood_Oak_Trunk",
      "support": 15,
      "rotation": 5
    },
    {
      "x": -4,
      "y": 2,
      "z": -3,
      "name": "Wood_Deadwood_Planks"
    },
    {
      "x": -4,
      "y": 4,
      "z": -3,
      "name": "Wood_Darkwood_Planks"
    },
    {
      "x": -4,
      "y": 7,
      "z": -3,
      "name": "Wood_Darkwood_Planks"
    },
    {
      "x": -4,
      "y": 1,
      "z": -2,
      "name": "Wood_Deadwood_Planks"
    },
    {
      "x": -4,
      "y": 2,
      "z": -2,
      "name": "Wood_Deadwood_Planks"
    },
    {
      "x": -4,
      "y": 4,
      "z": -2,
      "name": "Wood_Darkwood_Planks"
    },
    {
      "x": -4,
      "y": 7,
      "z": -2,
      "name": "Wood_Darkwood_Planks"
    },
    {
      "x": -4,
      "y": 1,
      "z": -1,
      "name": "Wood_Deadwood_Planks"
    },
    {
      "x": -4,
      "y": 4,
      "z": -1,
      "name": "Wood_Darkwood_Planks"
    },
    {
      "x": -4,
      "y": 7,
      "z": -1,
      "name": "Wood_Darkwood_Planks"
    },
    {
      "x": -4,
      "y": 1,
      "z": 0,
      "name": "Wood_Darkwood_Planks"
    },
    {
      "x": -4,
      "y": 4,
      "z": 0,
      "name": "Wood_Oak_Trunk",
      "support": 15,
      "rotation": 5
    },
    {
      "x": -4,
      "y": 5,
      "z": 0,
      "name": "Wood_Oak_Trunk",
      "support": 15
    },
    {
      "x": -4,
      "y": 6,
      "z": 0,
      "name": "Wood_Oak_Trunk",
      "support": 15
    },
    {
      "x": -4,
      "y": 7,
      "z": 0,
      "name": "Wood_Oak_Trunk",
      "support": 15,
      "rotation": 5
    },
    {
      "x": -4,
      "y": 19,
      "z": 0,
      "name": "Cloth_Block_Wool_Red"
    },
    {
      "x": -4,
      "y": 25,
      "z": 0,
      "name": "Cloth_Block_Wool_Red"
    },
    {
      "x": -4,
      "y": 1,
      "z": 1,
      "name": "Wood_Deadwood_Planks"
    },
    {
      "x": -4,
      "y": 4,
      "z": 1,
      "name": "Wood_Darkwood_Planks"
    },
    {
      "x": -4,
      "y": 7,
      "z": 1,
      "name": "Wood_Darkwood_Planks"
    },
    {
      "x": -4,
      "y": 1,
      "z": 2,
      "name": "Wood_Deadwood_Planks"
    },
    {
      "x": -4,
      "y": 2,
      "z": 2,
      "name": "Wood_Deadwood_Planks"
    },
    {
      "x": -4,
      "y": 4,
      "z": 2,
      "name": "Wood_Darkwood_Planks"
    },
    {
      "x": -4,
      "y": 7,
      "z": 2,
      "name": "Wood_Darkwood_Planks"
    },
    {
      "x": -4,
      "y": 2,
      "z": 3,
      "name": "Wood_Deadwood_Planks"
    },
    {
      "x": -4,
      "y": 4,
      "z": 3,
      "name": "Wood_Darkwood_Planks"
    },
    {
      "x": -4,
      "y": 7,
      "z": 3,
      "name": "Wood_Darkwood_Planks"
    },
    {
      "x": -4,
      "y": 2,
      "z": 4,
      "name": "Wood_Deadwood_Planks"
    },
    {
      "x": -4,
      "y": 3,
      "z": 4,
      "name": "Wood_Redwood_Planks"
    },
    {
      "x": -4,
      "y": 4,
      "z": 4,
      "name": "Wood_Oak_Trunk",
      "support": 15,
      "rotation": 5
    },
    {
      "x": -4,
      "y": 7,
      "z": 4,
      "name": "Wood_Oak_Trunk",
      "support": 15,
      "rotation": 5
    },
    {
      "x": -4,
      "y": 4,
      "z": 5,
      "name": "Wood_Redwood_Planks"
    },
    {
      "x": -4,
      "y": 5,
      "z": 5,
      "name": "Wood_Deadwood_Planks"
    },
    {
      "x": -4,
      "y": 7,
      "z": 5,
      "name": "Wood_Redwood_Planks"
    },
    {
      "x": -4,
      "y": 8,
      "z": 5,
      "name": "Wood_Deadwood_Planks"
    },
    {
      "x": -4,
      "y": 5,
      "z": 6,
      "name": "Furniture_Tavern_Shelf"
    },
    {
      "x": -3,
      "y": 4,
      "z": -5,
      "name": "Wood_Redwood_Planks"
    },
    {
      "x": -3,
      "y": 5,
      "z": -5,
      "name": "Wood_Deadwood_Planks"
    },
    {
      "x": -3,
      "y": 6,
      "z": -5,
      "name": "Wood_Redwood_Planks"
    },
    {
      "x": -3,
      "y": 7,
      "z": -5,
      "name": "Wood_Redwood_Planks"
    },
    {
      "x": -3,
      "y": 8,
      "z": -5,
      "name": "Wood_Deadwood_Planks"
    },
    {
      "x": -3,
      "y": 2,
      "z": -4,
      "name": "Wood_Deadwood_Planks"
    },
    {
      "x": -3,
      "y": 3,
      "z": -4,
      "name": "Wood_Redwood_Planks"
    },
    {
      "x": -3,
      "y": 4,
      "z": -4,
      "name": "Wood_Oak_Trunk",
      "support": 15,
      "rotation": 5
    },
    {
      "x": -3,
      "y": 7,
      "z": -4,
      "name": "Wood_Oak_Trunk",
      "support": 15,
      "rotation": 5
    },
    {
      "x": -3,
      "y": 2,
      "z": -3,
      "name": "Wood_Deadwood_Planks"
    },
    {
      "x": -3,
      "y": 4,
      "z": -3,
      "name": "Wood_Darkwood_Planks"
    },
    {
      "x": -3,
      "y": 7,
      "z": -3,
      "name": "Wood_Darkwood_Planks"
    },
    {
      "x": -3,
      "y": 1,
      "z": -2,
      "name": "Wood_Deadwood_Planks"
    },
    {
      "x": -3,
      "y": 2,
      "z": -2,
      "name": "Wood_Deadwood_Planks"
    },
    {
      "x": -3,
      "y": 4,
      "z": -2,
      "name": "Wood_Darkwood_Planks"
    },
    {
      "x": -3,
      "y": 7,
      "z": -2,
      "name": "Wood_Darkwood_Planks"
    },
    {
      "x": -3,
      "y": 1,
      "z": -1,
      "name": "Wood_Deadwood_Planks"
    },
    {
      "x": -3,
      "y": 4,
      "z": -1,
      "name": "Wood_Darkwood_Planks"
    },
    {
      "x": -3,
      "y": 1,
      "z": 0,
      "name": "Wood_Darkwood_Planks"
    },
    {
      "x": -3,
      "y": 4,
      "z": 0,
      "name": "Wood_Oak_Trunk",
      "support": 15,
      "rotation": 5
    },
    {
      "x": -3,
      "y": 19,
      "z": 0,
      "name": "Cloth_Block_Wool_Red"
    },
    {
      "x": -3,
      "y": 26,
      "z": 0,
      "name": "Cloth_Block_Wool_Red"
    },
    {
      "x": -3,
      "y": 1,
      "z": 1,
      "name": "Wood_Deadwood_Planks"
    },
    {
      "x": -3,
      "y": 4,
      "z": 1,
      "name": "Wood_Darkwood_Planks"
    },
    {
      "x": -3,
      "y": 1,
      "z": 2,
      "name": "Wood_Deadwood_Planks"
    },
    {
      "x": -3,
      "y": 2,
      "z": 2,
      "name": "Wood_Deadwood_Planks"
    },
    {
      "x": -3,
      "y": 4,
      "z": 2,
      "name": "Wood_Darkwood_Planks"
    },
    {
      "x": -3,
      "y": 7,
      "z": 2,
      "name": "Wood_Darkwood_Planks"
    },
    {
      "x": -3,
      "y": 2,
      "z": 3,
      "name": "Wood_Deadwood_Planks"
    },
    {
      "x": -3,
      "y": 4,
      "z": 3,
      "name": "Wood_Darkwood_Planks"
    },
    {
      "x": -3,
      "y": 7,
      "z": 3,
      "name": "Wood_Darkwood_Planks"
    },
    {
      "x": -3,
      "y": 2,
      "z": 4,
      "name": "Wood_Deadwood_Planks"
    },
    {
      "x": -3,
      "y": 3,
      "z": 4,
      "name": "Wood_Redwood_Planks"
    },
    {
      "x": -3,
      "y": 4,
      "z": 4,
      "name": "Wood_Oak_Trunk",
      "support": 15,
      "rotation": 5
    },
    {
      "x": -3,
      "y": 7,
      "z": 4,
      "name": "Wood_Oak_Trunk",
      "support": 15,
      "rotation": 5
    },
    {
      "x": -3,
      "y": 4,
      "z": 5,
      "name": "Wood_Redwood_Planks"
    },
    {
      "x": -3,
      "y": 5,
      "z": 5,
      "name": "Wood_Deadwood_Planks"
    },
    {
      "x": -3,
      "y": 6,
      "z": 5,
      "name": "Wood_Redwood_Planks"
    },
    {
      "x": -3,
      "y": 7,
      "z": 5,
      "name": "Wood_Redwood_Planks"
    },
    {
      "x": -3,
      "y": 8,
      "z": 5,
      "name": "Wood_Deadwood_Planks"
    },
    {
      "x": -2,
      "y": 5,
      "z": -6,
      "name": "Furniture_Tavern_Shelf",
      "rotation": 2
    },
    {
      "x": -2,
      "y": 4,
      "z": -5,
      "name": "Wood_Redwood_Planks"
    },
    {
      "x": -2,
      "y": 5,
      "z": -5,
      "name": "Wood_Deadwood_Planks"
    },
    {
      "x": -2,
      "y": 7,
      "z": -5,
      "name": "Wood_Redwood_Planks"
    },
    {
      "x": -2,
      "y": 8,
      "z": -5,
      "name": "Wood_Deadwood_Planks"
    },
    {
      "x": -2,
      "y": 2,
      "z": -4,
      "name": "Wood_Deadwood_Planks"
    },
    {
      "x": -2,
      "y": 3,
      "z": -4,
      "name": "Wood_Redwood_Planks"
    },
    {
      "x": -2,
      "y": 4,
      "z": -4,
      "name": "Wood_Oak_Trunk",
      "support": 15,
      "rotation": 5
    },
    {
      "x": -2,
      "y": 7,
      "z": -4,
      "name": "Wood_Oak_Trunk",
      "support": 15,
      "rotation": 5
    },
    {
      "x": -2,
      "y": 2,
      "z": -3,
      "name": "Wood_Deadwood_Planks"
    },
    {
      "x": -2,
      "y": 4,
      "z": -3,
      "name": "Wood_Darkwood_Planks"
    },
    {
      "x": -2,
      "y": 7,
      "z": -3,
      "name": "Wood_Darkwood_Planks"
    },
    {
      "x": -2,
      "y": 1,
      "z": -2,
      "name": "Wood_Deadwood_Planks"
    },
    {
      "x": -2,
      "y": 2,
      "z": -2,
      "name": "Wood_Deadwood_Planks"
    },
    {
      "x": -2,
      "y": 4,
      "z": -2,
      "name": "Wood_Darkwood_Planks"
    },
    {
      "x": -2,
      "y": 7,
      "z": -2,
      "name": "Wood_Darkwood_Planks"
    },
    {
      "x": -2,
      "y": 1,
      "z": -1,
      "name": "Wood_Deadwood_Planks"
    },
    {
      "x": -2,
      "y": 4,
      "z": -1,
      "name": "Wood_Darkwood_Planks"
    },
    {
      "x": -2,
      "y": 1,
      "z": 0,
      "name": "Wood_Darkwood_Planks"
    },
    {
      "x": -2,
      "y": 4,
      "z": 0,
      "name": "Wood_Oak_Trunk",
      "support": 15,
      "rotation": 5
    },
    {
      "x": -2,
      "y": 19,
      "z": 0,
      "name": "Cloth_Block_Wool_Red"
    },
    {
      "x": -2,
      "y": 27,
      "z": 0,
      "name": "Cloth_Block_Wool_Red"
    },
    {
      "x": -2,
      "y": 1,
      "z": 1,
      "name": "Wood_Deadwood_Planks"
    },
    {
      "x": -2,
      "y": 4,
      "z": 1,
      "name": "Wood_Darkwood_Planks"
    },
    {
      "x": -2,
      "y": 1,
      "z": 2,
      "name": "Wood_Deadwood_Planks"
    },
    {
      "x": -2,
      "y": 2,
      "z": 2,
      "name": "Wood_Deadwood_Planks"
    },
    {
      "x": -2,
      "y": 4,
      "z": 2,
      "name": "Wood_Darkwood_Planks"
    },
    {
      "x": -2,
      "y": 7,
      "z": 2,
      "name": "Wood_Darkwood_Planks"
    },
    {
      "x": -2,
      "y": 2,
      "z": 3,
      "name": "Wood_Deadwood_Planks"
    },
    {
      "x": -2,
      "y": 4,
      "z": 3,
      "name": "Wood_Darkwood_Planks"
    },
    {
      "x": -2,
      "y": 7,
      "z": 3,
      "name": "Wood_Darkwood_Planks"
    },
    {
      "x": -2,
      "y": 2,
      "z": 4,
      "name": "Wood_Deadwood_Planks"
    },
    {
      "x": -2,
      "y": 3,
      "z": 4,
      "name": "Wood_Redwood_Planks"
    },
    {
      "x": -2,
      "y": 4,
      "z": 4,
      "name": "Wood_Oak_Trunk",
      "support": 15,
      "rotation": 5
    },
    {
      "x": -2,
      "y": 7,
      "z": 4,
      "name": "Wood_Oak_Trunk",
      "support": 15,
      "rotation": 5
    },
    {
      "x": -2,
      "y": 4,
      "z": 5,
      "name": "Wood_Redwood_Planks"
    },
    {
      "x": -2,
      "y": 5,
      "z": 5,
      "name": "Wood_Deadwood_Planks"
    },
    {
      "x": -2,
      "y": 7,
      "z": 5,
      "name": "Wood_Redwood_Planks"
    },
    {
      "x": -2,
      "y": 8,
      "z": 5,
      "name": "Wood_Deadwood_Planks"
    },
    {
      "x": -2,
      "y": 5,
      "z": 6,
      "name": "Furniture_Tavern_Shelf"
    },
    {
      "x": -1,
      "y": 4,
      "z": -5,
      "name": "Wood_Redwood_Planks"
    },
    {
      "x": -1,
      "y": 5,
      "z": -5,
      "name": "Wood_Deadwood_Planks"
    },
    {
      "x": -1,
      "y": 6,
      "z": -5,
      "name": "Wood_Redwood_Planks"
    },
    {
      "x": -1,
      "y": 7,
      "z": -5,
      "name": "Wood_Redwood_Planks"
    },
    {
      "x": -1,
      "y": 8,
      "z": -5,
      "name": "Wood_Deadwood_Planks"
    },
    {
      "x": -1,
      "y": 2,
      "z": -4,
      "name": "Wood_Deadwood_Planks"
    },
    {
      "x": -1,
      "y": 3,
      "z": -4,
      "name": "Wood_Redwood_Planks"
    },
    {
      "x": -1,
      "y": 4,
      "z": -4,
      "name": "Wood_Oak_Trunk",
      "support": 15,
      "rotation": 5
    },
    {
      "x": -1,
      "y": 7,
      "z": -4,
      "name": "Wood_Oak_Trunk",
      "support": 15,
      "rotation": 5
    },
    {
      "x": -1,
      "y": 2,
      "z": -3,
      "name": "Wood_Deadwood_Planks"
    },
    {
      "x": -1,
      "y": 4,
      "z": -3,
      "name": "Wood_Darkwood_Planks"
    },
    {
      "x": -1,
      "y": 7,
      "z": -3,
      "name": "Wood_Darkwood_Planks"
    },
    {
      "x": -1,
      "y": 1,
      "z": -2,
      "name": "Wood_Deadwood_Planks"
    },
    {
      "x": -1,
      "y": 2,
      "z": -2,
      "name": "Wood_Deadwood_Planks"
    },
    {
      "x": -1,
      "y": 4,
      "z": -2,
      "name": "Wood_Darkwood_Planks"
    },
    {
      "x": -1,
      "y": 7,
      "z": -2,
      "name": "Wood_Darkwood_Planks"
    },
    {
      "x": -1,
      "y": 1,
      "z": -1,
      "name": "Wood_Deadwood_Planks"
    },
    {
      "x": -1,
      "y": 4,
      "z": -1,
      "name": "Wood_Darkwood_Planks"
    },
    {
      "x": -1,
      "y": 1,
      "z": 0,
      "name": "Wood_Darkwood_Planks"
    },
    {
      "x": -1,
      "y": 4,
      "z": 0,
      "name": "Wood_Oak_Trunk",
      "support": 15,
      "rotation": 5
    },
    {
      "x": -1,
      "y": 19,
      "z": 0,
      "name": "Cloth_Block_Wool_Red"
    },
    {
      "x": -1,
      "y": 28,
      "z": 0,
      "name": "Cloth_Block_Wool_Red"
    },
    {
      "x": -1,
      "y": 1,
      "z": 1,
      "name": "Wood_Deadwood_Planks"
    },
    {
      "x": -1,
      "y": 4,
      "z": 1,
      "name": "Wood_Darkwood_Planks"
    },
    {
      "x": -1,
      "y": 1,
      "z": 2,
      "name": "Wood_Deadwood_Planks"
    },
    {
      "x": -1,
      "y": 2,
      "z": 2,
      "name": "Wood_Deadwood_Planks"
    },
    {
      "x": -1,
      "y": 4,
      "z": 2,
      "name": "Wood_Darkwood_Planks"
    },
    {
      "x": -1,
      "y": 7,
      "z": 2,
      "name": "Wood_Darkwood_Planks"
    },
    {
      "x": -1,
      "y": 2,
      "z": 3,
      "name": "Wood_Deadwood_Planks"
    },
    {
      "x": -1,
      "y": 4,
      "z": 3,
      "name": "Wood_Darkwood_Planks"
    },
    {
      "x": -1,
      "y": 7,
      "z": 3,
      "name": "Wood_Darkwood_Planks"
    },
    {
      "x": -1,
      "y": 2,
      "z": 4,
      "name": "Wood_Deadwood_Planks"
    },
    {
      "x": -1,
      "y": 3,
      "z": 4,
      "name": "Wood_Redwood_Planks"
    },
    {
      "x": -1,
      "y": 4,
      "z": 4,
      "name": "Wood_Oak_Trunk",
      "support": 15,
      "rotation": 5
    },
    {
      "x": -1,
      "y": 7,
      "z": 4,
      "name": "Wood_Oak_Trunk",
      "support": 15,
      "rotation": 5
    },
    {
      "x": -1,
      "y": 4,
      "z": 5,
      "name": "Wood_Redwood_Planks"
    },
    {
      "x": -1,
      "y": 5,
      "z": 5,
      "name": "Wood_Deadwood_Planks"
    },
    {
      "x": -1,
      "y": 6,
      "z": 5,
      "name": "Wood_Redwood_Planks"
    },
    {
      "x": -1,
      "y": 7,
      "z": 5,
      "name": "Wood_Redwood_Planks"
    },
    {
      "x": -1,
      "y": 8,
      "z": 5,
      "name": "Wood_Deadwood_Planks"
    },
    {
      "x": 0,
      "y": 25,
      "z": -8,
      "name": "Wood_Oak_Trunk",
      "support": 15,
      "rotation": 4
    },
    {
      "x": 0,
      "y": 25,
      "z": -7,
      "name": "Wood_Oak_Trunk",
      "support": 15,
      "rotation": 4
    },
    {
      "x": 0,
      "y": 25,
      "z": -6,
      "name": "Wood_Oak_Trunk",
      "support": 15,
      "rotation": 4
    },
    {
      "x": 0,
      "y": 4,
      "z": -5,
      "name": "Wood_Redwood_Planks"
    },
    {
      "x": 0,
      "y": 5,
      "z": -5,
      "name": "Wood_Deadwood_Planks"
    },
    {
      "x": 0,
      "y": 6,
      "z": -5,
      "name": "Wood_Redwood_Planks"
    },
    {
      "x": 0,
      "y": 7,
      "z": -5,
      "name": "Wood_Redwood_Planks"
    },
    {
      "x": 0,
      "y": 8,
      "z": -5,
      "name": "Wood_Deadwood_Planks"
    },
    {
      "x": 0,
      "y": 25,
      "z": -5,
      "name": "Wood_Oak_Trunk",
      "support": 15,
      "rotation": 4
    },
    {
      "x": 0,
      "y": 2,
      "z": -4,
      "name": "Wood_Deadwood_Planks"
    },
    {
      "x": 0,
      "y": 3,
      "z": -4,
      "name": "Wood_Redwood_Planks"
    },
    {
      "x": 0,
      "y": 4,
      "z": -4,
      "name": "Wood_Oak_Trunk",
      "support": 15,
      "rotation": 5
    },
    {
      "x": 0,
      "y": 7,
      "z": -4,
      "name": "Wood_Oak_Trunk",
      "support": 15,
      "rotation": 5
    },
    {
      "x": 0,
      "y": 25,
      "z": -4,
      "name": "Wood_Oak_Trunk",
      "support": 15,
      "rotation": 4
    },
    {
      "x": 0,
      "y": 2,
      "z": -3,
      "name": "Wood_Deadwood_Planks"
    },
    {
      "x": 0,
      "y": 4,
      "z": -3,
      "name": "Wood_Darkwood_Planks"
    },
    {
      "x": 0,
      "y": 7,
      "z": -3,
      "name": "Wood_Darkwood_Planks"
    },
    {
      "x": 0,
      "y": 25,
      "z": -3,
      "name": "Wood_Oak_Trunk",
      "support": 15,
      "rotation": 4
    },
    {
      "x": 0,
      "y": 1,
      "z": -2,
      "name": "Wood_Deadwood_Planks"
    },
    {
      "x": 0,
      "y": 2,
      "z": -2,
      "name": "Wood_Deadwood_Planks"
    },
    {
      "x": 0,
      "y": 4,
      "z": -2,
      "name": "Wood_Darkwood_Planks"
    },
    {
      "x": 0,
      "y": 7,
      "z": -2,
      "name": "Wood_Darkwood_Planks"
    },
    {
      "x": 0,
      "y": 25,
      "z": -2,
      "name": "Wood_Oak_Trunk",
      "support": 15,
      "rotation": 4
    },
    {
      "x": 0,
      "y": 1,
      "z": -1,
      "name": "Wood_Deadwood_Planks"
    },
    {
      "x": 0,
      "y": 4,
      "z": -1,
      "name": "Wood_Darkwood_Planks"
    },
    {
      "x": 0,
      "y": 7,
      "z": -1,
      "name": "Wood_Darkwood_Planks"
    },
    {
      "x": 0,
      "y": 25,
      "z": -1,
      "name": "Wood_Oak_Trunk",
      "support": 15,
      "rotation": 4
    },
    {
      "x": 0,
      "y": 1,
      "z": 0,
      "name": "Wood_Darkwood_Planks"
    },
    {
      "x": 0,
      "y": 4,
      "z": 0,
      "name": "Wood_Oak_Trunk",
      "support": 15,
      "rotation": 5
    },
    {
      "x": 0,
      "y": 7,
      "z": 0,
      "name": "Wood_Oak_Trunk",
      "support": 15,
      "rotation": 5
    },
    {
      "x": 0,
      "y": 19,
      "z": 0,
      "name": "Cloth_Block_Wool_Red"
    },
    {
      "x": 0,
      "y": 25,
      "z": 0,
      "name": "Wood_Oak_Trunk",
      "support": 15,
      "rotation": 4
    },
    {
      "x": 0,
      "y": 26,
      "z": 0,
      "name": "Wood_Oak_Trunk",
      "support": 15,
      "rotation": 5
    },
    {
      "x": 0,
      "y": 29,
      "z": 0,
      "name": "Cloth_Block_Wool_Red"
    },
    {
      "x": 0,
      "y": 1,
      "z": 1,
      "name": "Wood_Deadwood_Planks"
    },
    {
      "x": 0,
      "y": 4,
      "z": 1,
      "name": "Wood_Darkwood_Planks"
    },
    {
      "x": 0,
      "y": 7,
      "z": 1,
      "name": "Wood_Darkwood_Planks"
    },
    {
      "x": 0,
      "y": 25,
      "z": 1,
      "name": "Wood_Oak_Trunk",
      "support": 15,
      "rotation": 4
    },
    {
      "x": 0,
      "y": 1,
      "z": 2,
      "name": "Wood_Deadwood_Planks"
    },
    {
      "x": 0,
      "y": 2,
      "z": 2,
      "name": "Wood_Deadwood_Planks"
    },
    {
      "x": 0,
      "y": 4,
      "z": 2,
      "name": "Wood_Darkwood_Planks"
    },
    {
      "x": 0,
      "y": 7,
      "z": 2,
      "name": "Wood_Darkwood_Planks"
    },
    {
      "x": 0,
      "y": 25,
      "z": 2,
      "name": "Wood_Oak_Trunk",
      "support": 15,
      "rotation": 4
    },
    {
      "x": 0,
      "y": 2,
      "z": 3,
      "name": "Wood_Deadwood_Planks"
    },
    {
      "x": 0,
      "y": 4,
      "z": 3,
      "name": "Wood_Darkwood_Planks"
    },
    {
      "x": 0,
      "y": 7,
      "z": 3,
      "name": "Wood_Darkwood_Planks"
    },
    {
      "x": 0,
      "y": 25,
      "z": 3,
      "name": "Wood_Oak_Trunk",
      "support": 15,
      "rotation": 4
    },
    {
      "x": 0,
      "y": 2,
      "z": 4,
      "name": "Wood_Deadwood_Planks"
    },
    {
      "x": 0,
      "y": 3,
      "z": 4,
      "name": "Wood_Redwood_Planks"
    },
    {
      "x": 0,
      "y": 4,
      "z": 4,
      "name": "Wood_Oak_Trunk",
      "support": 15,
      "rotation": 5
    },
    {
      "x": 0,
      "y": 7,
      "z": 4,
      "name": "Wood_Oak_Trunk",
      "support": 15,
      "rotation": 5
    },
    {
      "x": 0,
      "y": 25,
      "z": 4,
      "name": "Wood_Oak_Trunk",
      "support": 15,
      "rotation": 4
    },
    {
      "x": 0,
      "y": 4,
      "z": 5,
      "name": "Wood_Redwood_Planks"
    },
    {
      "x": 0,
      "y": 5,
      "z": 5,
      "name": "Wood_Deadwood_Planks"
    },
    {
      "x": 0,
      "y": 6,
      "z": 5,
      "name": "Wood_Redwood_Planks"
    },
    {
      "x": 0,
      "y": 7,
      "z": 5,
      "name": "Wood_Redwood_Planks"
    },
    {
      "x": 0,
      "y": 8,
      "z": 5,
      "name": "Wood_Deadwood_Planks"
    },
    {
      "x": 0,
      "y": 25,
      "z": 5,
      "name": "Wood_Oak_Trunk",
      "support": 15,
      "rotation": 4
    },
    {
      "x": 0,
      "y": 25,
      "z": 6,
      "name": "Wood_Oak_Trunk",
      "support": 15,
      "rotation": 4
    },
    {
      "x": 0,
      "y": 25,
      "z": 7,
      "name": "Wood_Oak_Trunk",
      "support": 15,
      "rotation": 4
    },
    {
      "x": 0,
      "y": 25,
      "z": 8,
      "name": "Wood_Oak_Trunk",
      "support": 15,
      "rotation": 4
    },
    {
      "x": 1,
      "y": 4,
      "z": -5,
      "name": "Wood_Redwood_Planks"
    },
    {
      "x": 1,
      "y": 5,
      "z": -5,
      "name": "Wood_Deadwood_Planks"
    },
    {
      "x": 1,
      "y": 6,
      "z": -5,
      "name": "Wood_Redwood_Planks"
    },
    {
      "x": 1,
      "y": 7,
      "z": -5,
      "name": "Wood_Redwood_Planks"
    },
    {
      "x": 1,
      "y": 8,
      "z": -5,
      "name": "Wood_Deadwood_Planks"
    },
    {
      "x": 1,
      "y": 9,
      "z": -5,
      "name": "Cloth_Block_Wool_Red"
    },
    {
      "x": 1,
      "y": 2,
      "z": -4,
      "name": "Wood_Deadwood_Planks"
    },
    {
      "x": 1,
      "y": 3,
      "z": -4,
      "name": "Wood_Redwood_Planks"
    },
    {
      "x": 1,
      "y": 4,
      "z": -4,
      "name": "Wood_Oak_Trunk",
      "support": 15,
      "rotation": 4
    },
    {
      "x": 1,
      "y": 7,
      "z": -4,
      "name": "Wood_Oak_Trunk",
      "support": 15,
      "rotation": 4
    },
    {
      "x": 1,
      "y": 10,
      "z": -4,
      "name": "Cloth_Block_Wool_Red"
    },
    {
      "x": 1,
      "y": 2,
      "z": -3,
      "name": "Wood_Deadwood_Planks"
    },
    {
      "x": 1,
      "y": 4,
      "z": -3,
      "name": "Wood_Oak_Trunk",
      "support": 15,
      "rotation": 4
    },
    {
      "x": 1,
      "y": 7,
      "z": -3,
      "name": "Wood_Oak_Trunk",
      "support": 15,
      "rotation": 4
    },
    {
      "x": 1,
      "y": 11,
      "z": -3,
      "name": "Cloth_Block_Wool_Red"
    },
    {
      "x": 1,
      "y": 1,
      "z": -2,
      "name": "Wood_Deadwood_Planks"
    },
    {
      "x": 1,
      "y": 2,
      "z": -2,
      "name": "Wood_Deadwood_Planks"
    },
    {
      "x": 1,
      "y": 4,
      "z": -2,
      "name": "Wood_Oak_Trunk",
      "support": 15,
      "rotation": 4
    },
    {
      "x": 1,
      "y": 7,
      "z": -2,
      "name": "Wood_Oak_Trunk",
      "support": 15,
      "rotation": 4
    },
    {
      "x": 1,
      "y": 12,
      "z": -2,
      "name": "Cloth_Block_Wool_Red"
    },
    {
      "x": 1,
      "y": 1,
      "z": -1,
      "name": "Wood_Deadwood_Planks"
    },
    {
      "x": 1,
      "y": 4,
      "z": -1,
      "name": "Wood_Oak_Trunk",
      "support": 15,
      "rotation": 4
    },
    {
      "x": 1,
      "y": 7,
      "z": -1,
      "name": "Wood_Oak_Trunk",
      "support": 15,
      "rotation": 4
    },
    {
      "x": 1,
      "y": 13,
      "z": -1,
      "name": "Cloth_Block_Wool_Red"
    },
    {
      "x": 1,
      "y": 25,
      "z": -1,
      "name": "Wood_Darkwood_Stairs",
      "rotation": 8
    },
    {
      "x": 1,
      "y": 26,
      "z": -1,
      "name": "Wood_Oak_Trunk",
      "support": 15,
      "rotation": 4
    },
    {
      "x": 1,
      "y": 1,
      "z": 0,
      "name": "Wood_Darkwood_Planks"
    },
    {
      "x": 1,
      "y": 2,
      "z": 0,
      "name": "Wood_Oak_Trunk",
      "support": 15
    },
    {
      "x": 1,
      "y": 3,
      "z": 0,
      "name": "Wood_Oak_Trunk",
      "support": 15
    },
    {
      "x": 1,
      "y": 4,
      "z": 0,
      "name": "Wood_Oak_Trunk",
      "support": 15,
      "rotation": 5
    },
    {
      "x": 1,
      "y": 5,
      "z": 0,
      "name": "Wood_Oak_Trunk",
      "support": 15
    },
    {
      "x": 1,
      "y": 6,
      "z": 0,
      "name": "Wood_Oak_Trunk",
      "support": 15
    },
    {
      "x": 1,
      "y": 7,
      "z": 0,
      "name": "Wood_Oak_Trunk",
      "support": 15
    },
    {
      "x": 1,
      "y": 8,
      "z": 0,
      "name": "Wood_Oak_Trunk",
      "support": 15
    },
    {
      "x": 1,
      "y": 9,
      "z": 0,
      "name": "Wood_Oak_Trunk",
      "support": 15
    },
    {
      "x": 1,
      "y": 10,
      "z": 0,
      "name": "Wood_Oak_Trunk",
      "support": 15
    },
    {
      "x": 1,
      "y": 11,
      "z": 0,
      "name": "Wood_Oak_Trunk",
      "support": 15
    },
    {
      "x": 1,
      "y": 12,
      "z": 0,
      "name": "Wood_Oak_Trunk",
      "support": 15
    },
    {
      "x": 1,
      "y": 13,
      "z": 0,
      "name": "Wood_Oak_Trunk",
      "support": 15
    },
    {
      "x": 1,
      "y": 14,
      "z": 0,
      "name": "Wood_Oak_Trunk",
      "support": 15
    },
    {
      "x": 1,
      "y": 15,
      "z": 0,
      "name": "Wood_Oak_Trunk",
      "support": 15
    },
    {
      "x": 1,
      "y": 16,
      "z": 0,
      "name": "Wood_Oak_Trunk",
      "support": 15
    },
    {
      "x": 1,
      "y": 17,
      "z": 0,
      "name": "Wood_Oak_Trunk",
      "support": 15
    },
    {
      "x": 1,
      "y": 18,
      "z": 0,
      "name": "Wood_Oak_Trunk",
      "support": 15
    },
    {
      "x": 1,
      "y": 19,
      "z": 0,
      "name": "Wood_Oak_Trunk",
      "support": 15
    },
    {
      "x": 1,
      "y": 20,
      "z": 0,
      "name": "Wood_Oak_Trunk",
      "support": 15
    },
    {
      "x": 1,
      "y": 21,
      "z": 0,
      "name": "Wood_Oak_Trunk",
      "support": 15
    },
    {
      "x": 1,
      "y": 22,
      "z": 0,
      "name": "Wood_Oak_Trunk",
      "support": 15
    },
    {
      "x": 1,
      "y": 23,
      "z": 0,
      "name": "Wood_Oak_Trunk",
      "support": 15
    },
    {
      "x": 1,
      "y": 24,
      "z": 0,
      "name": "Wood_Oak_Trunk",
      "support": 15
    },
    {
      "x": 1,
      "y": 25,
      "z": 0,
      "name": "Wood_Oak_Trunk",
      "support": 15
    },
    {
      "x": 1,
      "y": 26,
      "z": 0,
      "name": "Wood_Oak_Trunk",
      "support": 15
    },
    {
      "x": 1,
      "y": 27,
      "z": 0,
      "name": "Wood_Oak_Trunk",
      "support": 15
    },
    {
      "x": 1,
      "y": 28,
      "z": 0,
      "name": "Wood_Oak_Trunk",
      "support": 15
    },
    {
      "x": 1,
      "y": 29,
      "z": 0,
      "name": "Wood_Oak_Trunk",
      "support": 15
    },
    {
      "x": 1,
      "y": 1,
      "z": 1,
      "name": "Wood_Deadwood_Planks"
    },
    {
      "x": 1,
      "y": 4,
      "z": 1,
      "name": "Wood_Oak_Trunk",
      "support": 15,
      "rotation": 4
    },
    {
      "x": 1,
      "y": 7,
      "z": 1,
      "name": "Wood_Oak_Trunk",
      "support": 15,
      "rotation": 4
    },
    {
      "x": 1,
      "y": 13,
      "z": 1,
      "name": "Cloth_Block_Wool_Red"
    },
    {
      "x": 1,
      "y": 25,
      "z": 1,
      "name": "Wood_Darkwood_Stairs",
      "rotation": 10
    },
    {
      "x": 1,
      "y": 26,
      "z": 1,
      "name": "Wood_Oak_Trunk",
      "support": 15,
      "rotation": 4
    },
    {
      "x": 1,
      "y": 1,
      "z": 2,
      "name": "Wood_Deadwood_Planks"
    },
    {
      "x": 1,
      "y": 2,
      "z": 2,
      "name": "Wood_Deadwood_Planks"
    },
    {
      "x": 1,
      "y": 4,
      "z": 2,
      "name": "Wood_Oak_Trunk",
      "support": 15,
      "rotation": 4
    },
    {
      "x": 1,
      "y": 7,
      "z": 2,
      "name": "Wood_Oak_Trunk",
      "support": 15,
      "rotation": 4
    },
    {
      "x": 1,
      "y": 12,
      "z": 2,
      "name": "Cloth_Block_Wool_Red"
    },
    {
      "x": 1,
      "y": 2,
      "z": 3,
      "name": "Wood_Deadwood_Planks"
    },
    {
      "x": 1,
      "y": 4,
      "z": 3,
      "name": "Wood_Oak_Trunk",
      "support": 15,
      "rotation": 4
    },
    {
      "x": 1,
      "y": 7,
      "z": 3,
      "name": "Wood_Oak_Trunk",
      "support": 15,
      "rotation": 4
    },
    {
      "x": 1,
      "y": 11,
      "z": 3,
      "name": "Cloth_Block_Wool_Red"
    },
    {
      "x": 1,
      "y": 2,
      "z": 4,
      "name": "Wood_Deadwood_Planks"
    },
    {
      "x": 1,
      "y": 3,
      "z": 4,
      "name": "Wood_Redwood_Planks"
    },
    {
      "x": 1,
      "y": 4,
      "z": 4,
      "name": "Wood_Oak_Trunk",
      "support": 15,
      "rotation": 4
    },
    {
      "x": 1,
      "y": 7,
      "z": 4,
      "name": "Wood_Oak_Trunk",
      "support": 15,
      "rotation": 4
    },
    {
      "x": 1,
      "y": 10,
      "z": 4,
      "name": "Cloth_Block_Wool_Red"
    },
    {
      "x": 1,
      "y": 4,
      "z": 5,
      "name": "Wood_Redwood_Planks"
    },
    {
      "x": 1,
      "y": 5,
      "z": 5,
      "name": "Wood_Deadwood_Planks"
    },
    {
      "x": 1,
      "y": 6,
      "z": 5,
      "name": "Wood_Redwood_Planks"
    },
    {
      "x": 1,
      "y": 7,
      "z": 5,
      "name": "Wood_Redwood_Planks"
    },
    {
      "x": 1,
      "y": 8,
      "z": 5,
      "name": "Wood_Deadwood_Planks"
    },
    {
      "x": 1,
      "y": 9,
      "z": 5,
      "name": "Cloth_Block_Wool_Red"
    },
    {
      "x": 2,
      "y": 4,
      "z": -5,
      "name": "Wood_Redwood_Planks"
    },
    {
      "x": 2,
      "y": 5,
      "z": -5,
      "name": "Wood_Deadwood_Planks"
    },
    {
      "x": 2,
      "y": 6,
      "z": -5,
      "name": "Wood_Redwood_Planks"
    },
    {
      "x": 2,
      "y": 7,
      "z": -5,
      "name": "Wood_Redwood_Planks"
    },
    {
      "x": 2,
      "y": 2,
      "z": -4,
      "name": "Wood_Deadwood_Planks"
    },
    {
      "x": 2,
      "y": 3,
      "z": -4,
      "name": "Wood_Redwood_Planks"
    },
    {
      "x": 2,
      "y": 4,
      "z": -4,
      "name": "Wood_Oak_Trunk",
      "support": 15,
      "rotation": 5
    },
    {
      "x": 2,
      "y": 7,
      "z": -4,
      "name": "Wood_Oak_Trunk",
      "support": 15,
      "rotation": 5
    },
    {
      "x": 2,
      "y": 2,
      "z": -3,
      "name": "Wood_Deadwood_Planks"
    },
    {
      "x": 2,
      "y": 4,
      "z": -3,
      "name": "Wood_Darkwood_Planks"
    },
    {
      "x": 2,
      "y": 7,
      "z": -3,
      "name": "Wood_Darkwood_Planks"
    },
    {
      "x": 2,
      "y": 1,
      "z": -2,
      "name": "Wood_Deadwood_Planks"
    },
    {
      "x": 2,
      "y": 2,
      "z": -2,
      "name": "Wood_Deadwood_Planks"
    },
    {
      "x": 2,
      "y": 4,
      "z": -2,
      "name": "Wood_Darkwood_Planks"
    },
    {
      "x": 2,
      "y": 7,
      "z": -2,
      "name": "Wood_Darkwood_Planks"
    },
    {
      "x": 2,
      "y": 1,
      "z": -1,
      "name": "Wood_Deadwood_Planks"
    },
    {
      "x": 2,
      "y": 4,
      "z": -1,
      "name": "Wood_Darkwood_Planks"
    },
    {
      "x": 2,
      "y": 7,
      "z": -1,
      "name": "Wood_Darkwood_Planks"
    },
    {
      "x": 2,
      "y": 1,
      "z": 0,
      "name": "Wood_Darkwood_Planks"
    },
    {
      "x": 2,
      "y": 4,
      "z": 0,
      "name": "Wood_Oak_Trunk",
      "support": 15,
      "rotation": 5
    },
    {
      "x": 2,
      "y": 7,
      "z": 0,
      "name": "Wood_Oak_Trunk",
      "support": 15,
      "rotation": 5
    },
    {
      "x": 2,
      "y": 19,
      "z": 0,
      "name": "Cloth_Block_Wool_Red"
    },
    {
      "x": 2,
      "y": 28,
      "z": 0,
      "name": "Cloth_Block_Wool_Red"
    },
    {
      "x": 2,
      "y": 1,
      "z": 1,
      "name": "Wood_Deadwood_Planks"
    },
    {
      "x": 2,
      "y": 4,
      "z": 1,
      "name": "Wood_Darkwood_Planks"
    },
    {
      "x": 2,
      "y": 7,
      "z": 1,
      "name": "Wood_Darkwood_Planks"
    },
    {
      "x": 2,
      "y": 1,
      "z": 2,
      "name": "Wood_Deadwood_Planks"
    },
    {
      "x": 2,
      "y": 2,
      "z": 2,
      "name": "Wood_Deadwood_Planks"
    },
    {
      "x": 2,
      "y": 4,
      "z": 2,
      "name": "Wood_Darkwood_Planks"
    },
    {
      "x": 2,
      "y": 7,
      "z": 2,
      "name": "Wood_Darkwood_Planks"
    },
    {
      "x": 2,
      "y": 2,
      "z": 3,
      "name": "Wood_Deadwood_Planks"
    },
    {
      "x": 2,
      "y": 4,
      "z": 3,
      "name": "Wood_Darkwood_Planks"
    },
    {
      "x": 2,
      "y": 7,
      "z": 3,
      "name": "Wood_Darkwood_Planks"
    },
    {
      "x": 2,
      "y": 2,
      "z": 4,
      "name": "Wood_Deadwood_Planks"
    },
    {
      "x": 2,
      "y": 3,
      "z": 4,
      "name": "Wood_Redwood_Planks"
    },
    {
      "x": 2,
      "y": 4,
      "z": 4,
      "name": "Wood_Oak_Trunk",
      "support": 15,
      "rotation": 5
    },
    {
      "x": 2,
      "y": 7,
      "z": 4,
      "name": "Wood_Oak_Trunk",
      "support": 15,
      "rotation": 5
    },
    {
      "x": 2,
      "y": 4,
      "z": 5,
      "name": "Wood_Redwood_Planks"
    },
    {
      "x": 2,
      "y": 5,
      "z": 5,
      "name": "Wood_Deadwood_Planks"
    },
    {
      "x": 2,
      "y": 6,
      "z": 5,
      "name": "Wood_Redwood_Planks"
    },
    {
      "x": 2,
      "y": 7,
      "z": 5,
      "name": "Wood_Redwood_Planks"
    },
    {
      "x": 2,
      "y": 8,
      "z": 5,
      "name": "Wood_Deadwood_Planks"
    },
    {
      "x": 3,
      "y": 4,
      "z": -5,
      "name": "Wood_Redwood_Planks"
    },
    {
      "x": 3,
      "y": 5,
      "z": -5,
      "name": "Wood_Deadwood_Planks"
    },
    {
      "x": 3,
      "y": 6,
      "z": -5,
      "name": "Wood_Redwood_Planks"
    },
    {
      "x": 3,
      "y": 7,
      "z": -5,
      "name": "Wood_Redwood_Planks"
    },
    {
      "x": 3,
      "y": 2,
      "z": -4,
      "name": "Wood_Deadwood_Planks"
    },
    {
      "x": 3,
      "y": 3,
      "z": -4,
      "name": "Wood_Redwood_Planks"
    },
    {
      "x": 3,
      "y": 4,
      "z": -4,
      "name": "Wood_Oak_Trunk",
      "support": 15,
      "rotation": 5
    },
    {
      "x": 3,
      "y": 7,
      "z": -4,
      "name": "Wood_Oak_Trunk",
      "support": 15,
      "rotation": 5
    },
    {
      "x": 3,
      "y": 2,
      "z": -3,
      "name": "Wood_Deadwood_Planks"
    },
    {
      "x": 3,
      "y": 4,
      "z": -3,
      "name": "Wood_Darkwood_Planks"
    },
    {
      "x": 3,
      "y": 7,
      "z": -3,
      "name": "Wood_Darkwood_Planks"
    },
    {
      "x": 3,
      "y": 1,
      "z": -2,
      "name": "Wood_Deadwood_Planks"
    },
    {
      "x": 3,
      "y": 2,
      "z": -2,
      "name": "Wood_Deadwood_Planks"
    },
    {
      "x": 3,
      "y": 4,
      "z": -2,
      "name": "Wood_Darkwood_Planks"
    },
    {
      "x": 3,
      "y": 7,
      "z": -2,
      "name": "Wood_Darkwood_Planks"
    },
    {
      "x": 3,
      "y": 1,
      "z": -1,
      "name": "Wood_Deadwood_Planks"
    },
    {
      "x": 3,
      "y": 4,
      "z": -1,
      "name": "Wood_Darkwood_Planks"
    },
    {
      "x": 3,
      "y": 7,
      "z": -1,
      "name": "Wood_Darkwood_Planks"
    },
    {
      "x": 3,
      "y": 1,
      "z": 0,
      "name": "Wood_Darkwood_Planks"
    },
    {
      "x": 3,
      "y": 4,
      "z": 0,
      "name": "Wood_Oak_Trunk",
      "support": 15,
      "rotation": 5
    },
    {
      "x": 3,
      "y": 7,
      "z": 0,
      "name": "Wood_Oak_Trunk",
      "support": 15,
      "rotation": 5
    },
    {
      "x": 3,
      "y": 19,
      "z": 0,
      "name": "Cloth_Block_Wool_Red"
    },
    {
      "x": 3,
      "y": 27,
      "z": 0,
      "name": "Cloth_Block_Wool_Red"
    },
    {
      "x": 3,
      "y": 1,
      "z": 1,
      "name": "Wood_Deadwood_Planks"
    },
    {
      "x": 3,
      "y": 4,
      "z": 1,
      "name": "Wood_Darkwood_Planks"
    },
    {
      "x": 3,
      "y": 7,
      "z": 1,
      "name": "Wood_Darkwood_Planks"
    },
    {
      "x": 3,
      "y": 1,
      "z": 2,
      "name": "Wood_Deadwood_Planks"
    },
    {
      "x": 3,
      "y": 2,
      "z": 2,
      "name": "Wood_Deadwood_Planks"
    },
    {
      "x": 3,
      "y": 4,
      "z": 2,
      "name": "Wood_Darkwood_Planks"
    },
    {
      "x": 3,
      "y": 7,
      "z": 2,
      "name": "Wood_Darkwood_Planks"
    },
    {
      "x": 3,
      "y": 2,
      "z": 3,
      "name": "Wood_Deadwood_Planks"
    },
    {
      "x": 3,
      "y": 4,
      "z": 3,
      "name": "Wood_Darkwood_Planks"
    },
    {
      "x": 3,
      "y": 7,
      "z": 3,
      "name": "Wood_Darkwood_Planks"
    },
    {
      "x": 3,
      "y": 2,
      "z": 4,
      "name": "Wood_Deadwood_Planks"
    },
    {
      "x": 3,
      "y": 3,
      "z": 4,
      "name": "Wood_Redwood_Planks"
    },
    {
      "x": 3,
      "y": 4,
      "z": 4,
      "name": "Wood_Oak_Trunk",
      "support": 15,
      "rotation": 5
    },
    {
      "x": 3,
      "y": 7,
      "z": 4,
      "name": "Wood_Oak_Trunk",
      "support": 15,
      "rotation": 5
    },
    {
      "x": 3,
      "y": 4,
      "z": 5,
      "name": "Wood_Redwood_Planks"
    },
    {
      "x": 3,
      "y": 5,
      "z": 5,
      "name": "Wood_Deadwood_Planks"
    },
    {
      "x": 3,
      "y": 6,
      "z": 5,
      "name": "Wood_Redwood_Planks"
    },
    {
      "x": 3,
      "y": 7,
      "z": 5,
      "name": "Wood_Redwood_Planks"
    },
    {
      "x": 3,
      "y": 8,
      "z": 5,
      "name": "Wood_Deadwood_Planks"
    },
    {
      "x": 4,
      "y": 4,
      "z": -5,
      "name": "Wood_Redwood_Planks"
    },
    {
      "x": 4,
      "y": 5,
      "z": -5,
      "name": "Wood_Deadwood_Planks"
    },
    {
      "x": 4,
      "y": 6,
      "z": -5,
      "name": "Wood_Redwood_Planks"
    },
    {
      "x": 4,
      "y": 7,
      "z": -5,
      "name": "Wood_Redwood_Planks"
    },
    {
      "x": 4,
      "y": 2,
      "z": -4,
      "name": "Wood_Deadwood_Planks"
    },
    {
      "x": 4,
      "y": 3,
      "z": -4,
      "name": "Wood_Redwood_Planks"
    },
    {
      "x": 4,
      "y": 4,
      "z": -4,
      "name": "Wood_Oak_Trunk",
      "support": 15,
      "rotation": 5
    },
    {
      "x": 4,
      "y": 7,
      "z": -4,
      "name": "Wood_Oak_Trunk",
      "support": 15,
      "rotation": 5
    },
    {
      "x": 4,
      "y": 2,
      "z": -3,
      "name": "Wood_Deadwood_Planks"
    },
    {
      "x": 4,
      "y": 4,
      "z": -3,
      "name": "Wood_Darkwood_Planks"
    },
    {
      "x": 4,
      "y": 7,
      "z": -3,
      "name": "Wood_Darkwood_Planks"
    },
    {
      "x": 4,
      "y": 1,
      "z": -2,
      "name": "Wood_Deadwood_Planks"
    },
    {
      "x": 4,
      "y": 2,
      "z": -2,
      "name": "Wood_Deadwood_Planks"
    },
    {
      "x": 4,
      "y": 4,
      "z": -2,
      "name": "Wood_Darkwood_Planks"
    },
    {
      "x": 4,
      "y": 7,
      "z": -2,
      "name": "Wood_Darkwood_Planks"
    },
    {
      "x": 4,
      "y": 1,
      "z": -1,
      "name": "Wood_Deadwood_Planks"
    },
    {
      "x": 4,
      "y": 4,
      "z": -1,
      "name": "Wood_Darkwood_Planks"
    },
    {
      "x": 4,
      "y": 7,
      "z": -1,
      "name": "Wood_Darkwood_Planks"
    },
    {
      "x": 4,
      "y": 1,
      "z": 0,
      "name": "Wood_Darkwood_Planks"
    },
    {
      "x": 4,
      "y": 4,
      "z": 0,
      "name": "Wood_Oak_Trunk",
      "support": 15,
      "rotation": 5
    },
    {
      "x": 4,
      "y": 7,
      "z": 0,
      "name": "Wood_Oak_Trunk",
      "support": 15,
      "rotation": 5
    },
    {
      "x": 4,
      "y": 19,
      "z": 0,
      "name": "Cloth_Block_Wool_Red"
    },
    {
      "x": 4,
      "y": 26,
      "z": 0,
      "name": "Cloth_Block_Wool_Red"
    },
    {
      "x": 4,
      "y": 1,
      "z": 1,
      "name": "Wood_Deadwood_Planks"
    },
    {
      "x": 4,
      "y": 4,
      "z": 1,
      "name": "Wood_Darkwood_Planks"
    },
    {
      "x": 4,
      "y": 7,
      "z": 1,
      "name": "Wood_Darkwood_Planks"
    },
    {
      "x": 4,
      "y": 1,
      "z": 2,
      "name": "Wood_Deadwood_Planks"
    },
    {
      "x": 4,
      "y": 2,
      "z": 2,
      "name": "Wood_Deadwood_Planks"
    },
    {
      "x": 4,
      "y": 4,
      "z": 2,
      "name": "Wood_Darkwood_Planks"
    },
    {
      "x": 4,
      "y": 7,
      "z": 2,
      "name": "Wood_Darkwood_Planks"
    },
    {
      "x": 4,
      "y": 2,
      "z": 3,
      "name": "Wood_Deadwood_Planks"
    },
    {
      "x": 4,
      "y": 4,
      "z": 3,
      "name": "Wood_Darkwood_Planks"
    },
    {
      "x": 4,
      "y": 7,
      "z": 3,
      "name": "Wood_Darkwood_Planks"
    },
    {
      "x": 4,
      "y": 2,
      "z": 4,
      "name": "Wood_Deadwood_Planks"
    },
    {
      "x": 4,
      "y": 3,
      "z": 4,
      "name": "Wood_Redwood_Planks"
    },
    {
      "x": 4,
      "y": 4,
      "z": 4,
      "name": "Wood_Oak_Trunk",
      "support": 15,
      "rotation": 5
    },
    {
      "x": 4,
      "y": 7,
      "z": 4,
      "name": "Wood_Oak_Trunk",
      "support": 15,
      "rotation": 5
    },
    {
      "x": 4,
      "y": 4,
      "z": 5,
      "name": "Wood_Redwood_Planks"
    },
    {
      "x": 4,
      "y": 5,
      "z": 5,
      "name": "Wood_Deadwood_Planks"
    },
    {
      "x": 4,
      "y": 6,
      "z": 5,
      "name": "Wood_Redwood_Planks"
    },
    {
      "x": 4,
      "y": 7,
      "z": 5,
      "name": "Wood_Redwood_Planks"
    },
    {
      "x": 4,
      "y": 8,
      "z": 5,
      "name": "Wood_Deadwood_Planks"
    },
    {
      "x": 5,
      "y": 4,
      "z": -5,
      "name": "Wood_Redwood_Planks"
    },
    {
      "x": 5,
      "y": 5,
      "z": -5,
      "name": "Wood_Deadwood_Planks"
    },
    {
      "x": 5,
      "y": 6,
      "z": -5,
      "name": "Wood_Redwood_Planks"
    },
    {
      "x": 5,
      "y": 7,
      "z": -5,
      "name": "Wood_Redwood_Planks"
    },
    {
      "x": 5,
      "y": 2,
      "z": -4,
      "name": "Wood_Deadwood_Planks"
    },
    {
      "x": 5,
      "y": 3,
      "z": -4,
      "name": "Wood_Redwood_Planks"
    },
    {
      "x": 5,
      "y": 4,
      "z": -4,
      "name": "Wood_Oak_Trunk",
      "support": 15,
      "rotation": 5
    },
    {
      "x": 5,
      "y": 7,
      "z": -4,
      "name": "Wood_Oak_Trunk",
      "support": 15,
      "rotation": 5
    },
    {
      "x": 5,
      "y": 2,
      "z": -3,
      "name": "Wood_Deadwood_Planks"
    },
    {
      "x": 5,
      "y": 4,
      "z": -3,
      "name": "Wood_Darkwood_Planks"
    },
    {
      "x": 5,
      "y": 7,
      "z": -3,
      "name": "Wood_Darkwood_Planks"
    },
    {
      "x": 5,
      "y": 1,
      "z": -2,
      "name": "Wood_Deadwood_Planks"
    },
    {
      "x": 5,
      "y": 2,
      "z": -2,
      "name": "Wood_Deadwood_Planks"
    },
    {
      "x": 5,
      "y": 4,
      "z": -2,
      "name": "Wood_Darkwood_Planks"
    },
    {
      "x": 5,
      "y": 7,
      "z": -2,
      "name": "Wood_Darkwood_Planks"
    },
    {
      "x": 5,
      "y": 1,
      "z": -1,
      "name": "Wood_Deadwood_Planks"
    },
    {
      "x": 5,
      "y": 4,
      "z": -1,
      "name": "Wood_Darkwood_Planks"
    },
    {
      "x": 5,
      "y": 7,
      "z": -1,
      "name": "Wood_Darkwood_Planks"
    },
    {
      "x": 5,
      "y": 1,
      "z": 0,
      "name": "Wood_Darkwood_Planks"
    },
    {
      "x": 5,
      "y": 4,
      "z": 0,
      "name": "Wood_Oak_Trunk",
      "support": 15,
      "rotation": 5
    },
    {
      "x": 5,
      "y": 7,
      "z": 0,
      "name": "Wood_Oak_Trunk",
      "support": 15,
      "rotation": 5
    },
    {
      "x": 5,
      "y": 19,
      "z": 0,
      "name": "Cloth_Block_Wool_Red"
    },
    {
      "x": 5,
      "y": 25,
      "z": 0,
      "name": "Cloth_Block_Wool_Red"
    },
    {
      "x": 5,
      "y": 1,
      "z": 1,
      "name": "Wood_Deadwood_Planks"
    },
    {
      "x": 5,
      "y": 4,
      "z": 1,
      "name": "Wood_Darkwood_Planks"
    },
    {
      "x": 5,
      "y": 7,
      "z": 1,
      "name": "Wood_Darkwood_Planks"
    },
    {
      "x": 5,
      "y": 1,
      "z": 2,
      "name": "Wood_Deadwood_Planks"
    },
    {
      "x": 5,
      "y": 2,
      "z": 2,
      "name": "Wood_Deadwood_Planks"
    },
    {
      "x": 5,
      "y": 4,
      "z": 2,
      "name": "Wood_Darkwood_Planks"
    },
    {
      "x": 5,
      "y": 7,
      "z": 2,
      "name": "Wood_Darkwood_Planks"
    },
    {
      "x": 5,
      "y": 2,
      "z": 3,
      "name": "Wood_Deadwood_Planks"
    },
    {
      "x": 5,
      "y": 4,
      "z": 3,
      "name": "Wood_Darkwood_Planks"
    },
    {
      "x": 5,
      "y": 7,
      "z": 3,
      "name": "Wood_Darkwood_Planks"
    },
    {
      "x": 5,
      "y": 2,
      "z": 4,
      "name": "Wood_Deadwood_Planks"
    },
    {
      "x": 5,
      "y": 3,
      "z": 4,
      "name": "Wood_Redwood_Planks"
    },
    {
      "x": 5,
      "y": 4,
      "z": 4,
      "name": "Wood_Oak_Trunk",
      "support": 15,
      "rotation": 5
    },
    {
      "x": 5,
      "y": 7,
      "z": 4,
      "name": "Wood_Oak_Trunk",
      "support": 15,
      "rotation": 5
    },
    {
      "x": 5,
      "y": 4,
      "z": 5,
      "name": "Wood_Redwood_Planks"
    },
    {
      "x": 5,
      "y": 5,
      "z": 5,
      "name": "Wood_Deadwood_Planks"
    },
    {
      "x": 5,
      "y": 6,
      "z": 5,
      "name": "Wood_Redwood_Planks"
    },
    {
      "x": 5,
      "y": 7,
      "z": 5,
      "name": "Wood_Redwood_Planks"
    },
    {
      "x": 5,
      "y": 8,
      "z": 5,
      "name": "Wood_Deadwood_Planks"
    },
    {
      "x": 6,
      "y": 5,
      "z": -6,
      "name": "Furniture_Tavern_Shelf",
      "rotation": 2
    },
    {
      "x": 6,
      "y": 4,
      "z": -5,
      "name": "Wood_Redwood_Planks"
    },
    {
      "x": 6,
      "y": 5,
      "z": -5,
      "name": "Wood_Deadwood_Planks"
    },
    {
      "x": 6,
      "y": 7,
      "z": -5,
      "name": "Wood_Redwood_Planks"
    },
    {
      "x": 6,
      "y": 2,
      "z": -4,
      "name": "Wood_Deadwood_Planks"
    },
    {
      "x": 6,
      "y": 3,
      "z": -4,
      "name": "Wood_Redwood_Planks"
    },
    {
      "x": 6,
      "y": 4,
      "z": -4,
      "name": "Wood_Oak_Trunk",
      "support": 15,
      "rotation": 5
    },
    {
      "x": 6,
      "y": 7,
      "z": -4,
      "name": "Wood_Oak_Trunk",
      "support": 15,
      "rotation": 5
    },
    {
      "x": 6,
      "y": 2,
      "z": -3,
      "name": "Wood_Deadwood_Planks"
    },
    {
      "x": 6,
      "y": 4,
      "z": -3,
      "name": "Wood_Darkwood_Planks"
    },
    {
      "x": 6,
      "y": 7,
      "z": -3,
      "name": "Wood_Darkwood_Planks"
    },
    {
      "x": 6,
      "y": 1,
      "z": -2,
      "name": "Wood_Deadwood_Planks"
    },
    {
      "x": 6,
      "y": 2,
      "z": -2,
      "name": "Wood_Deadwood_Planks"
    },
    {
      "x": 6,
      "y": 4,
      "z": -2,
      "name": "Wood_Darkwood_Planks"
    },
    {
      "x": 6,
      "y": 7,
      "z": -2,
      "name": "Wood_Darkwood_Planks"
    },
    {
      "x": 6,
      "y": 1,
      "z": -1,
      "name": "Wood_Deadwood_Planks"
    },
    {
      "x": 6,
      "y": 4,
      "z": -1,
      "name": "Wood_Darkwood_Planks"
    },
    {
      "x": 6,
      "y": 7,
      "z": -1,
      "name": "Wood_Darkwood_Planks"
    },
    {
      "x": 6,
      "y": 1,
      "z": 0,
      "name": "Wood_Darkwood_Planks"
    },
    {
      "x": 6,
      "y": 4,
      "z": 0,
      "name": "Wood_Oak_Trunk",
      "support": 15,
      "rotation": 5
    },
    {
      "x": 6,
      "y": 7,
      "z": 0,
      "name": "Wood_Oak_Trunk",
      "support": 15,
      "rotation": 5
    },
    {
      "x": 6,
      "y": 19,
      "z": 0,
      "name": "Cloth_Block_Wool_Red"
    },
    {
      "x": 6,
      "y": 24,
      "z": 0,
      "name": "Cloth_Block_Wool_Red"
    },
    {
      "x": 6,
      "y": 1,
      "z": 1,
      "name": "Wood_Deadwood_Planks"
    },
    {
      "x": 6,
      "y": 4,
      "z": 1,
      "name": "Wood_Darkwood_Planks"
    },
    {
      "x": 6,
      "y": 7,
      "z": 1,
      "name": "Wood_Darkwood_Planks"
    },
    {
      "x": 6,
      "y": 1,
      "z": 2,
      "name": "Wood_Deadwood_Planks"
    },
    {
      "x": 6,
      "y": 2,
      "z": 2,
      "name": "Wood_Deadwood_Planks"
    },
    {
      "x": 6,
      "y": 4,
      "z": 2,
      "name": "Wood_Darkwood_Planks"
    },
    {
      "x": 6,
      "y": 7,
      "z": 2,
      "name": "Wood_Darkwood_Planks"
    },
    {
      "x": 6,
      "y": 2,
      "z": 3,
      "name": "Wood_Deadwood_Planks"
    },
    {
      "x": 6,
      "y": 4,
      "z": 3,
      "name": "Wood_Darkwood_Planks"
    },
    {
      "x": 6,
      "y": 7,
      "z": 3,
      "name": "Wood_Darkwood_Planks"
    },
    {
      "x": 6,
      "y": 2,
      "z": 4,
      "name": "Wood_Deadwood_Planks"
    },
    {
      "x": 6,
      "y": 3,
      "z": 4,
      "name": "Wood_Redwood_Planks"
    },
    {
      "x": 6,
      "y": 4,
      "z": 4,
      "name": "Wood_Oak_Trunk",
      "support": 15,
      "rotation": 5
    },
    {
      "x": 6,
      "y": 7,
      "z": 4,
      "name": "Wood_Oak_Trunk",
