{
  "version": 8,
  "blockIdVersion": 11,
  "anchorX": 0,
  "anchorY": 0,
  "anchorZ": 0,
  "blocks": [
    {
      "x": -7,
      "y": -4,
      "z": -4,
      "name": "Rock_Marble_Brick"
    },
    {
      "x": -7,
      "y": -3,
      "z": -4,
      "name": "Rock_Marble_Brick"
    },
    {
      "x": -7,
      "y": -2,
      "z": -4,
      "name": "Rock_Marble_Brick"
    },
    {
      "x": -7,
      "y": -1,
      "z": -4,
      "name": "Rock_Marble_Brick"
    },
    {
      "x": -7,
      "y": 0,
      "z": -4,
      "name": "Rock_Marble_Brick_Decorative"
    },
    {
      "x": -7,
      "y": 6,
      "z": -4,
      "name": "Rock_Marble_Brick_Decorative"
    },
    {
      "x": -7,
      "y": 7,
      "z": -4,
      "name": "Rock_Marble_Brick_Decorative",
      "rotation": 2
    },
    {
      "x": -7,
      "y": 13,
      "z": -4,
      "name": "Rock_Marble_Brick_Decorative",
      "rotation": 2
    },
    {
      "x": -7,
      "y": 14,
      "z": -4,
      "name": "Rock_Marble_Brick_Decorative"
    },
    {
      "x": -7,
      "y": 20,
      "z": -4,
      "name": "Rock_Marble_Brick_Decorative"
    },
    {
      "x": -7,
      "y": 21,
      "z": -4,
      "name": "Rock_Marble_Brick_Decorative",
      "rotation": 2
    },
    {
      "x": -7,
      "y": 27,
      "z": -4,
      "name": "Rock_Marble_Brick_Decorative",
      "rotation": 2
    },
    {
      "x": -7,
      "y": 28,
      "z": -4,
      "name": "Rock_Marble_Brick_Decorative"
    },
    {
      "x": -7,
      "y": 34,
      "z": -4,
      "name": "Rock_Marble_Brick_Decorative"
    },
    {
      "x": -7,
      "y": 35,
      "z": -4,
      "name": "Rock_Marble_Brick_Decorative",
      "rotation": 2
    },
    {
      "x": -7,
      "y": 41,
      "z": -4,
      "name": "Rock_Marble_Brick_Decorative",
      "rotation": 2
    },
    {
      "x": -7,
      "y": -4,
      "z": -3,
      "name": "Rock_Marble_Brick"
    },
    {
      "x": -7,
      "y": -3,
      "z": -3,
      "name": "Rock_Marble_Brick"
    },
    {
      "x": -7,
      "y": -2,
      "z": -3,
      "name": "Rock_Marble_Brick"
    },
    {
      "x": -7,
      "y": -1,
      "z": -3,
      "name": "Rock_Marble_Brick"
    },
    {
      "x": -7,
      "y": 0,
      "z": -3,
      "name": "Rock_Marble_Brick_Smooth",
      "rotation": 3
    },
    {
      "x": -7,
      "y": 1,
      "z": -3,
      "name": "Rock_Marble_Brick_Pillar_Base",
      "rotation": 3
    },
    {
      "x": -7,
      "y": 2,
      "z": -3,
      "name": "Rock_Marble_Brick_Pillar_Middle",
      "rotation": 3
    },
    {
      "x": -7,
      "y": 3,
      "z": -3,
      "name": "Rock_Marble_Brick_Pillar_Middle",
      "rotation": 3
    },
    {
      "x": -7,
      "y": 4,
      "z": -3,
      "name": "Rock_Marble_Brick_Pillar_Middle",
      "rotation": 3
    },
    {
      "x": -7,
      "y": 5,
      "z": -3,
      "name": "Rock_Marble_Brick_Pillar_Base",
      "rotation": 11
    },
    {
      "x": -7,
      "y": 6,
      "z": -3,
      "name": "Rock_Marble_Brick_Decorative"
    },
    {
      "x": -7,
      "y": 7,
      "z": -3,
      "name": "Rock_Marble_Brick_Decorative",
      "rotation": 2
    },
    {
      "x": -7,
      "y": 8,
      "z": -3,
      "name": "Rock_Marble_Brick_Pillar_Base",
      "rotation": 3
    },
    {
      "x": -7,
      "y": 9,
      "z": -3,
      "name": "Rock_Marble_Brick_Pillar_Middle",
      "rotation": 3
    },
    {
      "x": -7,
      "y": 10,
      "z": -3,
      "name": "Rock_Marble_Brick_Pillar_Middle",
      "rotation": 3
    },
    {
      "x": -7,
      "y": 11,
      "z": -3,
      "name": "Rock_Marble_Brick_Pillar_Middle",
      "rotation": 3
    },
    {
      "x": -7,
      "y": 12,
      "z": -3,
      "name": "Rock_Marble_Brick_Pillar_Base",
      "rotation": 33
    },
    {
      "x": -7,
      "y": 13,
      "z": -3,
      "name": "Rock_Marble_Brick_Ornate",
      "rotation": 3
    },
    {
      "x": -7,
      "y": 14,
      "z": -3,
      "name": "Rock_Marble_Brick_Smooth",
      "rotation": 3
    },
    {
      "x": -7,
      "y": 15,
      "z": -3,
      "name": "Rock_Marble_Brick_Pillar_Base",
      "rotation": 3
    },
    {
      "x": -7,
      "y": 16,
      "z": -3,
      "name": "Rock_Marble_Brick_Pillar_Middle",
      "rotation": 3
    },
    {
      "x": -7,
      "y": 17,
      "z": -3,
      "name": "Rock_Marble_Brick_Pillar_Middle",
      "rotation": 3
    },
    {
      "x": -7,
      "y": 18,
      "z": -3,
      "name": "Rock_Marble_Brick_Pillar_Middle",
      "rotation": 3
    },
    {
      "x": -7,
      "y": 19,
      "z": -3,
      "name": "Rock_Marble_Brick_Pillar_Base",
      "rotation": 33
    },
    {
      "x": -7,
      "y": 20,
      "z": -3,
      "name": "Rock_Marble_Brick_Decorative"
    },
    {
      "x": -7,
      "y": 21,
      "z": -3,
      "name": "Rock_Marble_Brick_Decorative",
      "rotation": 2
    },
    {
      "x": -7,
      "y": 22,
      "z": -3,
      "name": "Rock_Marble_Brick_Pillar_Base",
      "rotation": 3
    },
    {
      "x": -7,
      "y": 23,
      "z": -3,
      "name": "Rock_Marble_Brick_Pillar_Middle",
      "rotation": 3
    },
    {
      "x": -7,
      "y": 24,
      "z": -3,
      "name": "Rock_Marble_Brick_Pillar_Middle",
      "rotation": 3
    },
    {
      "x": -7,
      "y": 25,
      "z": -3,
      "name": "Rock_Marble_Brick_Pillar_Middle",
      "rotation": 3
    },
    {
      "x": -7,
      "y": 26,
      "z": -3,
      "name": "Rock_Marble_Brick_Pillar_Base",
      "rotation": 33
    },
    {
      "x": -7,
      "y": 27,
      "z": -3,
      "name": "Rock_Marble_Brick_Ornate",
      "rotation": 3
    },
    {
      "x": -7,
      "y": 28,
      "z": -3,
      "name": "Rock_Marble_Brick_Smooth",
      "rotation": 3
    },
    {
      "x": -7,
      "y": 29,
      "z": -3,
      "name": "Rock_Marble_Brick_Pillar_Base",
      "rotation": 3
    },
    {
      "x": -7,
      "y": 30,
      "z": -3,
      "name": "Rock_Marble_Brick_Pillar_Middle",
      "rotation": 3
    },
    {
      "x": -7,
      "y": 31,
      "z": -3,
      "name": "Rock_Marble_Brick_Pillar_Middle",
      "rotation": 3
    },
    {
      "x": -7,
      "y": 32,
      "z": -3,
      "name": "Rock_Marble_Brick_Pillar_Middle",
      "rotation": 3
    },
    {
      "x": -7,
      "y": 33,
      "z": -3,
      "name": "Rock_Marble_Brick_Pillar_Base",
      "rotation": 33
    },
    {
      "x": -7,
      "y": 34,
      "z": -3,
      "name": "Rock_Marble_Brick_Decorative"
    },
    {
      "x": -7,
      "y": 35,
      "z": -3,
      "name": "Rock_Marble_Brick_Decorative",
      "rotation": 2
    },
    {
      "x": -7,
      "y": 36,
      "z": -3,
      "name": "Rock_Marble_Brick_Pillar_Base",
      "rotation": 3
    },
    {
      "x": -7,
      "y": 37,
      "z": -3,
      "name": "Rock_Marble_Brick_Pillar_Middle",
      "rotation": 3
    },
    {
      "x": -7,
      "y": 38,
      "z": -3,
      "name": "Rock_Marble_Brick_Pillar_Middle",
      "rotation": 3
    },
    {
      "x": -7,
      "y": 39,
      "z": -3,
      "name": "Rock_Marble_Brick_Pillar_Middle",
      "rotation": 3
    },
    {
      "x": -7,
      "y": 40,
      "z": -3,
      "name": "Rock_Marble_Brick_Pillar_Base",
      "rotation": 33
    },
    {
      "x": -7,
      "y": 41,
      "z": -3,
      "name": "Rock_Marble_Brick_Ornate",
      "rotation": 3
    },
    {
      "x": -7,
      "y": 42,
      "z": -3,
      "name": "Rock_Marble_Brick_Pillar_Base"
    },
    {
      "x": -7,
      "y": 43,
      "z": -3,
      "name": "Rock_Marble_Brick_Pillar_Middle"
    },
    {
      "x": -7,
      "y": 44,
      "z": -3,
      "name": "Rock_Marble_Brick_Pillar_Middle"
    },
    {
      "x": -7,
      "y": 45,
      "z": -3,
      "name": "Rock_Marble_Brick_Pillar_Middle"
    },
    {
      "x": -7,
      "y": 46,
      "z": -3,
      "name": "Rock_Marble_Brick_Pillar_Base",
      "rotation": 8
    },
    {
      "x": -7,
      "y": 47,
      "z": -3,
      "name": "Rock_Marble_SkyGrass"
    },
    {
      "x": -7,
      "y": -4,
      "z": -2,
      "name": "Rock_Marble_Brick"
    },
    {
      "x": -7,
      "y": -3,
      "z": -2,
      "name": "Rock_Marble_Brick"
    },
    {
      "x": -7,
      "y": -2,
      "z": -2,
      "name": "Rock_Marble_Brick"
    },
    {
      "x": -7,
      "y": -1,
      "z": -2,
      "name": "Rock_Marble_Brick"
    },
    {
      "x": -7,
      "y": 0,
      "z": -2,
      "name": "Rock_Marble_Brick_Smooth_Half",
      "rotation": 3
    },
    {
      "x": -7,
      "y": 5,
      "z": -2,
      "name": "Rock_Marble_Brick_Stairs",
      "rotation": 9
    },
    {
      "x": -7,
      "y": 6,
      "z": -2,
      "name": "Rock_Marble_Brick_Decorative"
    },
    {
      "x": -7,
      "y": 7,
      "z": -2,
      "name": "Rock_Marble_Brick_Smooth_Half",
      "rotation": 3
    },
    {
      "x": -7,
      "y": 12,
      "z": -2,
      "name": "Rock_Marble_Brick_Stairs",
      "rotation": 35
    },
    {
      "x": -7,
      "y": 13,
      "z": -2,
      "name": "Rock_Marble_Brick_Decorative",
      "rotation": 3
    },
    {
      "x": -7,
      "y": 14,
      "z": -2,
      "name": "Rock_Marble_Brick_Smooth_Half",
      "rotation": 3
    },
    {
      "x": -7,
      "y": 19,
      "z": -2,
      "name": "Rock_Marble_Brick_Stairs",
      "rotation": 35
    },
    {
      "x": -7,
      "y": 20,
      "z": -2,
      "name": "Rock_Marble_Brick_Decorative"
    },
    {
      "x": -7,
      "y": 21,
      "z": -2,
      "name": "Rock_Marble_Brick_Smooth_Half",
      "rotation": 3
    },
    {
      "x": -7,
      "y": 26,
      "z": -2,
      "name": "Rock_Marble_Brick_Stairs",
      "rotation": 35
    },
    {
      "x": -7,
      "y": 27,
      "z": -2,
      "name": "Rock_Marble_Brick_Decorative",
      "rotation": 3
    },
    {
      "x": -7,
      "y": 28,
      "z": -2,
      "name": "Rock_Marble_Brick_Smooth_Half",
      "rotation": 3
    },
    {
      "x": -7,
      "y": 33,
      "z": -2,
      "name": "Rock_Marble_Brick_Stairs",
      "rotation": 35
    },
    {
      "x": -7,
      "y": 34,
      "z": -2,
      "name": "Rock_Marble_Brick_Decorative"
    },
    {
      "x": -7,
      "y": 35,
      "z": -2,
      "name": "Rock_Marble_Brick_Smooth_Half",
      "rotation": 3
    },
    {
      "x": -7,
      "y": 40,
      "z": -2,
      "name": "Rock_Marble_Brick_Stairs",
      "rotation": 35
    },
    {
      "x": -7,
      "y": 41,
      "z": -2,
      "name": "Rock_Marble_Brick_Decorative",
      "rotation": 3
    },
    {
      "x": -7,
      "y": 47,
      "z": -2,
      "name": "Rock_Marble_SkyGrass"
    },
    {
      "x": -7,
      "y": 48,
      "z": -2,
      "name": "Plant_Grass_Sky",
      "support": 15
    },
    {
      "x": -7,
      "y": -4,
      "z": -1,
      "name": "Rock_Marble_Brick"
    },
    {
      "x": -7,
      "y": -3,
      "z": -1,
      "name": "Rock_Marble_Brick"
    },
    {
      "x": -7,
      "y": -2,
      "z": -1,
      "name": "Rock_Marble_Brick"
    },
    {
      "x": -7,
      "y": -1,
      "z": -1,
      "name": "Rock_Marble_Brick"
    },
    {
      "x": -7,
      "y": 0,
      "z": -1,
      "name": "Rock_Marble_Brick_Smooth_Half",
      "rotation": 3
    },
    {
      "x": -7,
      "y": 5,
      "z": -1,
      "name": "Rock_Marble_Brick_Smooth_Half",
      "rotation": 11
    },
    {
      "x": -7,
      "y": 6,
      "z": -1,
      "name": "Rock_Marble_Brick_Decorative"
    },
    {
      "x": -7,
      "y": 7,
      "z": -1,
      "name": "Rock_Marble_Brick_Smooth_Half",
      "rotation": 3
    },
    {
      "x": -7,
      "y": 12,
      "z": -1,
      "name": "Rock_Marble_Brick_Smooth_Half",
      "rotation": 33
    },
    {
      "x": -7,
      "y": 13,
      "z": -1,
      "name": "Rock_Marble_Brick_Decorative",
      "rotation": 3
    },
    {
      "x": -7,
      "y": 14,
      "z": -1,
      "name": "Rock_Marble_Brick_Smooth_Half",
      "rotation": 3
    },
    {
      "x": -7,
      "y": 19,
      "z": -1,
      "name": "Rock_Marble_Brick_Smooth_Half",
      "rotation": 33
    },
    {
      "x": -7,
      "y": 20,
      "z": -1,
      "name": "Rock_Marble_Brick_Decorative"
    },
    {
      "x": -7,
      "y": 21,
      "z": -1,
      "name": "Rock_Marble_Brick_Smooth_Half",
      "rotation": 3
    },
    {
      "x": -7,
      "y": 26,
      "z": -1,
      "name": "Rock_Marble_Brick_Smooth_Half",
      "rotation": 33
    },
    {
      "x": -7,
      "y": 27,
      "z": -1,
      "name": "Rock_Marble_Brick_Decorative",
      "rotation": 3
    },
    {
      "x": -7,
      "y": 28,
      "z": -1,
      "name": "Rock_Marble_Brick_Smooth_Half",
      "rotation": 3
    },
    {
      "x": -7,
      "y": 33,
      "z": -1,
      "name": "Rock_Marble_Brick_Smooth_Half",
      "rotation": 33
    },
    {
      "x": -7,
      "y": 34,
      "z": -1,
      "name": "Rock_Marble_Brick_Decorative"
    },
    {
      "x": -7,
      "y": 35,
      "z": -1,
      "name": "Rock_Marble_Brick_Smooth_Half",
      "rotation": 3
    },
    {
      "x": -7,
      "y": 40,
      "z": -1,
      "name": "Rock_Marble_Brick_Smooth_Half",
      "rotation": 33
    },
    {
      "x": -7,
      "y": 41,
      "z": -1,
      "name": "Rock_Marble_Brick_Decorative",
      "rotation": 3
    },
    {
      "x": -7,
      "y": 47,
      "z": -1,
      "name": "Rock_Marble_SkyGrass"
    },
    {
      "x": -7,
      "y": -4,
      "z": 0,
      "name": "Rock_Marble_Brick"
    },
    {
      "x": -7,
      "y": -3,
      "z": 0,
      "name": "Rock_Marble_Brick"
    },
    {
      "x": -7,
      "y": -2,
      "z": 0,
      "name": "Rock_Marble_Brick"
    },
    {
      "x": -7,
      "y": -1,
      "z": 0,
      "name": "Rock_Marble_Brick"
    },
    {
      "x": -7,
      "y": 0,
      "z": 0,
      "name": "Rock_Marble_Brick_Smooth_Half",
      "rotation": 3
    },
    {
      "x": -7,
      "y": 5,
      "z": 0,
      "name": "Rock_Marble_Brick_Stairs",
      "rotation": 9
    },
    {
      "x": -7,
      "y": 6,
      "z": 0,
      "name": "Rock_Marble_Brick_Decorative",
      "rotation": 3
    },
    {
      "x": -7,
      "y": 7,
      "z": 0,
      "name": "Rock_Marble_Brick_Smooth_Half",
      "rotation": 3
    },
    {
      "x": -7,
      "y": 12,
      "z": 0,
      "name": "Rock_Marble_Brick_Stairs",
      "rotation": 35
    },
    {
      "x": -7,
      "y": 13,
      "z": 0,
      "name": "Rock_Marble_Brick_Decorative",
      "rotation": 3
    },
    {
      "x": -7,
      "y": 14,
      "z": 0,
      "name": "Rock_Marble_Brick_Smooth_Half",
      "rotation": 3
    },
    {
      "x": -7,
      "y": 19,
      "z": 0,
      "name": "Rock_Marble_Brick_Stairs",
      "rotation": 35
    },
    {
      "x": -7,
      "y": 20,
      "z": 0,
      "name": "Rock_Marble_Brick_Decorative",
      "rotation": 3
    },
    {
      "x": -7,
      "y": 21,
      "z": 0,
      "name": "Rock_Marble_Brick_Smooth_Half",
      "rotation": 3
    },
    {
      "x": -7,
      "y": 26,
      "z": 0,
      "name": "Rock_Marble_Brick_Stairs",
      "rotation": 35
    },
    {
      "x": -7,
      "y": 27,
      "z": 0,
      "name": "Rock_Marble_Brick_Decorative",
      "rotation": 3
    },
    {
      "x": -7,
      "y": 28,
      "z": 0,
      "name": "Rock_Marble_Brick_Smooth_Half",
      "rotation": 3
    },
    {
      "x": -7,
      "y": 33,
      "z": 0,
      "name": "Rock_Marble_Brick_Stairs",
      "rotation": 35
    },
    {
      "x": -7,
      "y": 34,
      "z": 0,
      "name": "Rock_Marble_Brick_Decorative",
      "rotation": 3
    },
    {
      "x": -7,
      "y": 35,
      "z": 0,
      "name": "Rock_Marble_Brick_Smooth_Half",
      "rotation": 3
    },
    {
      "x": -7,
      "y": 40,
      "z": 0,
      "name": "Rock_Marble_Brick_Stairs",
      "rotation": 35
    },
    {
      "x": -7,
      "y": 41,
      "z": 0,
      "name": "Rock_Marble_Brick_Decorative",
      "rotation": 3
    },
    {
      "x": -7,
      "y": 47,
      "z": 0,
      "name": "Rock_Marble_Brick"
    },
    {
      "x": -7,
      "y": -4,
      "z": 1,
      "name": "Rock_Marble_Brick"
    },
    {
      "x": -7,
      "y": -3,
      "z": 1,
      "name": "Rock_Marble_Brick"
    },
    {
      "x": -7,
      "y": -2,
      "z": 1,
      "name": "Rock_Marble_Brick"
    },
    {
      "x": -7,
      "y": -1,
      "z": 1,
      "name": "Rock_Marble_Brick"
    },
    {
      "x": -7,
      "y": 0,
      "z": 1,
      "name": "Rock_Marble_Brick_Smooth",
      "rotation": 3
    },
    {
      "x": -7,
      "y": 1,
      "z": 1,
      "name": "Rock_Marble_Brick_Pillar_Base",
      "rotation": 3
    },
    {
      "x": -7,
      "y": 2,
      "z": 1,
      "name": "Rock_Marble_Brick_Pillar_Middle",
      "rotation": 3
    },
    {
      "x": -7,
      "y": 3,
      "z": 1,
      "name": "Rock_Marble_Brick_Pillar_Middle",
      "rotation": 3
    },
    {
      "x": -7,
      "y": 4,
      "z": 1,
      "name": "Rock_Marble_Brick_Pillar_Middle",
      "rotation": 3
    },
    {
      "x": -7,
      "y": 5,
      "z": 1,
      "name": "Rock_Marble_Brick_Pillar_Base",
      "rotation": 11
    },
    {
      "x": -7,
      "y": 6,
      "z": 1,
      "name": "Rock_Marble_Brick_Ornate",
      "rotation": 3
    },
    {
      "x": -7,
      "y": 7,
      "z": 1,
      "name": "Rock_Marble_Brick_Decorative",
      "rotation": 2
    },
    {
      "x": -7,
      "y": 8,
      "z": 1,
      "name": "Rock_Marble_Brick_Pillar_Base",
      "rotation": 3
    },
    {
      "x": -7,
      "y": 9,
      "z": 1,
      "name": "Rock_Marble_Brick_Pillar_Middle",
      "rotation": 3
    },
    {
      "x": -7,
      "y": 10,
      "z": 1,
      "name": "Rock_Marble_Brick_Pillar_Middle",
      "rotation": 3
    },
    {
      "x": -7,
      "y": 11,
      "z": 1,
      "name": "Rock_Marble_Brick_Pillar_Middle",
      "rotation": 3
    },
    {
      "x": -7,
      "y": 12,
      "z": 1,
      "name": "Rock_Marble_Brick_Pillar_Base",
      "rotation": 33
    },
    {
      "x": -7,
      "y": 13,
      "z": 1,
      "name": "Rock_Marble_Brick_Ornate",
      "rotation": 3
    },
    {
      "x": -7,
      "y": 14,
      "z": 1,
      "name": "Rock_Marble_Brick_Smooth",
      "rotation": 3
    },
    {
      "x": -7,
      "y": 15,
      "z": 1,
      "name": "Rock_Marble_Brick_Pillar_Base",
      "rotation": 3
    },
    {
      "x": -7,
      "y": 16,
      "z": 1,
      "name": "Rock_Marble_Brick_Pillar_Middle",
      "rotation": 3
    },
    {
      "x": -7,
      "y": 17,
      "z": 1,
      "name": "Rock_Marble_Brick_Pillar_Middle",
      "rotation": 3
    },
    {
      "x": -7,
      "y": 18,
      "z": 1,
      "name": "Rock_Marble_Brick_Pillar_Middle",
      "rotation": 3
    },
    {
      "x": -7,
      "y": 19,
      "z": 1,
      "name": "Rock_Marble_Brick_Pillar_Base",
      "rotation": 33
    },
    {
      "x": -7,
      "y": 20,
      "z": 1,
      "name": "Rock_Marble_Brick_Ornate",
      "rotation": 3
    },
    {
      "x": -7,
      "y": 21,
      "z": 1,
      "name": "Rock_Marble_Brick_Decorative",
      "rotation": 2
    },
    {
      "x": -7,
      "y": 22,
      "z": 1,
      "name": "Rock_Marble_Brick_Pillar_Base",
      "rotation": 3
    },
    {
      "x": -7,
      "y": 23,
      "z": 1,
      "name": "Rock_Marble_Brick_Pillar_Middle",
      "rotation": 3
    },
    {
      "x": -7,
      "y": 24,
      "z": 1,
      "name": "Rock_Marble_Brick_Pillar_Middle",
      "rotation": 3
    },
    {
      "x": -7,
      "y": 25,
      "z": 1,
      "name": "Rock_Marble_Brick_Pillar_Middle",
      "rotation": 3
    },
    {
      "x": -7,
      "y": 26,
      "z": 1,
      "name": "Rock_Marble_Brick_Pillar_Base",
      "rotation": 33
    },
    {
      "x": -7,
      "y": 27,
      "z": 1,
      "name": "Rock_Marble_Brick_Ornate",
      "rotation": 3
    },
    {
      "x": -7,
      "y": 28,
      "z": 1,
      "name": "Rock_Marble_Brick_Smooth",
      "rotation": 3
    },
    {
      "x": -7,
      "y": 29,
      "z": 1,
      "name": "Rock_Marble_Brick_Pillar_Base",
      "rotation": 3
    },
    {
      "x": -7,
      "y": 30,
      "z": 1,
      "name": "Rock_Marble_Brick_Pillar_Middle",
      "rotation": 3
    },
    {
      "x": -7,
      "y": 31,
      "z": 1,
      "name": "Rock_Marble_Brick_Pillar_Middle",
      "rotation": 3
    },
    {
      "x": -7,
      "y": 32,
      "z": 1,
      "name": "Rock_Marble_Brick_Pillar_Middle",
      "rotation": 3
    },
    {
      "x": -7,
      "y": 33,
      "z": 1,
      "name": "Rock_Marble_Brick_Pillar_Base",
      "rotation": 33
    },
    {
      "x": -7,
      "y": 34,
      "z": 1,
      "name": "Rock_Marble_Brick_Ornate",
      "rotation": 3
    },
    {
      "x": -7,
      "y": 35,
      "z": 1,
      "name": "Rock_Marble_Brick_Decorative",
      "rotation": 2
    },
    {
      "x": -7,
      "y": 36,
      "z": 1,
      "name": "Rock_Marble_Brick_Pillar_Base",
      "rotation": 3
    },
    {
      "x": -7,
      "y": 37,
      "z": 1,
      "name": "Rock_Marble_Brick_Pillar_Middle",
      "rotation": 3
    },
    {
      "x": -7,
      "y": 38,
      "z": 1,
      "name": "Rock_Marble_Brick_Pillar_Middle",
      "rotation": 3
    },
    {
      "x": -7,
      "y": 39,
      "z": 1,
      "name": "Rock_Marble_Brick_Pillar_Middle",
      "rotation": 3
    },
    {
      "x": -7,
      "y": 40,
      "z": 1,
      "name": "Rock_Marble_Brick_Pillar_Base",
      "rotation": 33
    },
    {
      "x": -7,
      "y": 41,
      "z": 1,
      "name": "Rock_Marble_Brick_Ornate",
      "rotation": 3
    },
    {
      "x": -7,
      "y": 42,
      "z": 1,
      "name": "Rock_Marble_Brick_Pillar_Base"
    },
    {
      "x": -7,
      "y": 43,
      "z": 1,
      "name": "Rock_Marble_Brick_Pillar_Middle"
    },
    {
      "x": -7,
      "y": 44,
      "z": 1,
      "name": "Rock_Marble_Brick_Pillar_Middle"
    },
    {
      "x": -7,
      "y": 45,
      "z": 1,
      "name": "Rock_Marble_Brick_Pillar_Middle"
    },
    {
      "x": -7,
      "y": 46,
      "z": 1,
      "name": "Rock_Marble_Brick_Pillar_Base",
      "rotation": 8
    },
    {
      "x": -7,
      "y": 47,
      "z": 1,
      "name": "Rock_Marble_Brick"
    },
    {
      "x": -7,
      "y": -4,
      "z": 2,
      "name": "Rock_Marble_Brick"
    },
    {
      "x": -7,
      "y": -3,
      "z": 2,
      "name": "Rock_Marble_Brick"
    },
    {
      "x": -7,
      "y": -2,
      "z": 2,
      "name": "Rock_Marble_Brick"
    },
    {
      "x": -7,
      "y": -1,
      "z": 2,
      "name": "Rock_Marble_Brick"
    },
    {
      "x": -7,
      "y": 0,
      "z": 2,
      "name": "Rock_Marble_Brick_Decorative"
    },
    {
      "x": -7,
      "y": 6,
      "z": 2,
      "name": "Rock_Marble_Brick_Decorative"
    },
    {
      "x": -7,
      "y": 7,
      "z": 2,
      "name": "Rock_Marble_Brick_Decorative",
      "rotation": 2
    },
    {
      "x": -7,
      "y": 13,
      "z": 2,
      "name": "Rock_Marble_Brick_Decorative",
      "rotation": 2
    },
    {
      "x": -7,
      "y": 14,
      "z": 2,
      "name": "Rock_Marble_Brick_Decorative"
    },
    {
      "x": -7,
      "y": 20,
      "z": 2,
      "name": "Rock_Marble_Brick_Decorative"
    },
    {
      "x": -7,
      "y": 21,
      "z": 2,
      "name": "Rock_Marble_Brick_Decorative",
      "rotation": 2
    },
    {
      "x": -7,
      "y": 27,
      "z": 2,
      "name": "Rock_Marble_Brick_Decorative",
      "rotation": 2
    },
    {
      "x": -7,
      "y": 28,
      "z": 2,
      "name": "Rock_Marble_Brick_Decorative"
    },
    {
      "x": -7,
      "y": 34,
      "z": 2,
      "name": "Rock_Marble_Brick_Decorative"
    },
    {
      "x": -7,
      "y": 35,
      "z": 2,
      "name": "Rock_Marble_Brick_Decorative",
      "rotation": 2
    },
    {
      "x": -7,
      "y": 41,
      "z": 2,
      "name": "Rock_Marble_Brick_Decorative",
      "rotation": 2
    },
    {
      "x": -6,
      "y": -4,
      "z": -5,
      "name": "Rock_Marble_Brick"
    },
    {
      "x": -6,
      "y": -3,
      "z": -5,
      "name": "Rock_Marble_Brick"
    },
    {
      "x": -6,
      "y": -2,
      "z": -5,
      "name": "Rock_Marble_Brick"
    },
    {
      "x": -6,
      "y": -1,
      "z": -5,
      "name": "Rock_Marble_Brick"
    },
    {
      "x": -6,
      "y": 0,
      "z": -5,
      "name": "Rock_Marble_Brick_Decorative",
      "rotation": 2
    },
    {
      "x": -6,
      "y": 1,
      "z": -5,
      "name": "Rock_Marble_Brick_Pillar_Base",
      "rotation": 2
    },
    {
      "x": -6,
      "y": 2,
      "z": -5,
      "name": "Rock_Marble_Brick_Pillar_Middle",
      "rotation": 3
    },
    {
      "x": -6,
      "y": 3,
      "z": -5,
      "name": "Rock_Marble_Brick_Pillar_Middle",
      "rotation": 3
    },
    {
      "x": -6,
      "y": 4,
      "z": -5,
      "name": "Rock_Marble_Brick_Pillar_Middle",
      "rotation": 3
    },
    {
      "x": -6,
      "y": 5,
      "z": -5,
      "name": "Rock_Marble_Brick_Pillar_Base",
      "rotation": 10
    },
    {
      "x": -6,
      "y": 6,
      "z": -5,
      "name": "Rock_Marble_Brick_Ornate",
      "rotation": 3
    },
    {
      "x": -6,
      "y": 7,
      "z": -5,
      "name": "Rock_Marble_Brick_Decorative",
      "rotation": 2
    },
    {
      "x": -6,
      "y": 8,
      "z": -5,
      "name": "Rock_Marble_Brick_Pillar_Base",
      "rotation": 2
    },
    {
      "x": -6,
      "y": 9,
      "z": -5,
      "name": "Rock_Marble_Brick_Pillar_Middle",
      "rotation": 3
    },
    {
      "x": -6,
      "y": 10,
      "z": -5,
      "name": "Rock_Marble_Brick_Pillar_Middle",
      "rotation": 3
    },
    {
      "x": -6,
      "y": 11,
      "z": -5,
      "name": "Rock_Marble_Brick_Pillar_Middle",
      "rotation": 3
    },
    {
      "x": -6,
      "y": 12,
      "z": -5,
      "name": "Rock_Marble_Brick_Pillar_Base",
      "rotation": 32
    },
    {
      "x": -6,
      "y": 13,
      "z": -5,
      "name": "Rock_Marble_Brick_Ornate",
      "rotation": 3
    },
    {
      "x": -6,
      "y": 14,
      "z": -5,
      "name": "Rock_Marble_Brick_Decorative",
      "rotation": 2
    },
    {
      "x": -6,
      "y": 15,
      "z": -5,
      "name": "Rock_Marble_Brick_Pillar_Base",
      "rotation": 2
    },
    {
      "x": -6,
      "y": 16,
      "z": -5,
      "name": "Rock_Marble_Brick_Pillar_Middle",
      "rotation": 3
    },
    {
      "x": -6,
      "y": 17,
      "z": -5,
      "name": "Rock_Marble_Brick_Pillar_Middle",
      "rotation": 3
    },
    {
      "x": -6,
      "y": 18,
      "z": -5,
      "name": "Rock_Marble_Brick_Pillar_Middle",
      "rotation": 3
    },
    {
      "x": -6,
      "y": 19,
      "z": -5,
      "name": "Rock_Marble_Brick_Pillar_Base",
      "rotation": 32
    },
    {
      "x": -6,
      "y": 20,
      "z": -5,
      "name": "Rock_Marble_Brick_Ornate",
      "rotation": 3
    },
    {
      "x": -6,
      "y": 21,
      "z": -5,
      "name": "Rock_Marble_Brick_Decorative",
      "rotation": 2
    },
    {
      "x": -6,
      "y": 22,
      "z": -5,
      "name": "Rock_Marble_Brick_Pillar_Base",
      "rotation": 2
    },
    {
      "x": -6,
      "y": 23,
      "z": -5,
      "name": "Rock_Marble_Brick_Pillar_Middle",
      "rotation": 3
    },
    {
      "x": -6,
      "y": 24,
      "z": -5,
      "name": "Rock_Marble_Brick_Pillar_Middle",
      "rotation": 3
    },
    {
      "x": -6,
      "y": 25,
      "z": -5,
      "name": "Rock_Marble_Brick_Pillar_Middle",
      "rotation": 3
    },
    {
      "x": -6,
      "y": 26,
      "z": -5,
      "name": "Rock_Marble_Brick_Pillar_Base",
      "rotation": 32
    },
    {
      "x": -6,
      "y": 27,
      "z": -5,
      "name": "Rock_Marble_Brick_Ornate",
      "rotation": 3
    },
    {
      "x": -6,
      "y": 28,
      "z": -5,
      "name": "Rock_Marble_Brick_Decorative",
      "rotation": 2
    },
    {
      "x": -6,
      "y": 29,
      "z": -5,
      "name": "Rock_Marble_Brick_Pillar_Base",
      "rotation": 2
    },
    {
      "x": -6,
      "y": 30,
      "z": -5,
      "name": "Rock_Marble_Brick_Pillar_Middle",
      "rotation": 3
    },
    {
      "x": -6,
      "y": 31,
      "z": -5,
      "name": "Rock_Marble_Brick_Pillar_Middle",
      "rotation": 3
    },
    {
      "x": -6,
      "y": 32,
      "z": -5,
      "name": "Rock_Marble_Brick_Pillar_Middle",
      "rotation": 3
    },
    {
      "x": -6,
      "y": 33,
      "z": -5,
      "name": "Rock_Marble_Brick_Pillar_Base",
      "rotation": 32
    },
    {
      "x": -6,
      "y": 34,
      "z": -5,
      "name": "Rock_Marble_Brick_Ornate",
      "rotation": 3
    },
    {
      "x": -6,
      "y": 35,
      "z": -5,
      "name": "Rock_Marble_Brick_Decorative",
      "rotation": 2
    },
    {
      "x": -6,
      "y": 36,
      "z": -5,
      "name": "Rock_Marble_Brick_Pillar_Base",
      "rotation": 2
    },
    {
      "x": -6,
      "y": 37,
      "z": -5,
      "name": "Rock_Marble_Brick_Pillar_Middle",
      "rotation": 3
    },
    {
      "x": -6,
      "y": 38,
      "z": -5,
      "name": "Rock_Marble_Brick_Pillar_Middle",
      "rotation": 3
    },
    {
      "x": -6,
      "y": 39,
      "z": -5,
      "name": "Rock_Marble_Brick_Pillar_Middle",
      "rotation": 3
    },
    {
      "x": -6,
      "y": 40,
      "z": -5,
      "name": "Rock_Marble_Brick_Pillar_Base",
      "rotation": 32
    },
    {
      "x": -6,
      "y": 41,
      "z": -5,
      "name": "Rock_Marble_Brick_Ornate",
      "rotation": 3
    },
    {
      "x": -6,
      "y": 42,
      "z": -5,
      "name": "Rock_Marble_Brick_Pillar_Base"
    },
    {
      "x": -6,
      "y": 43,
      "z": -5,
      "name": "Rock_Marble_Brick_Pillar_Middle"
    },
    {
      "x": -6,
      "y": 44,
      "z": -5,
      "name": "Rock_Marble_Brick_Pillar_Middle"
    },
    {
      "x": -6,
      "y": 45,
      "z": -5,
      "name": "Rock_Marble_Brick_Pillar_Middle"
    },
    {
      "x": -6,
      "y": 46,
      "z": -5,
      "name": "Rock_Marble_Brick_Pillar_Base",
      "rotation": 8
    },
    {
      "x": -6,
      "y": 47,
      "z": -5,
      "name": "Rock_Marble_SkyGrass"
    },
    {
      "x": -6,
      "y": -4,
      "z": -4,
      "name": "Rock_Marble_Brick"
    },
    {
      "x": -6,
      "y": -3,
      "z": -4,
      "name": "Rock_Marble_Brick"
    },
    {
      "x": -6,
      "y": -2,
      "z": -4,
      "name": "Rock_Marble_Brick"
    },
    {
      "x": -6,
      "y": -1,
      "z": -4,
      "name": "Rock_Marble_Brick"
    },
    {
      "x": -6,
      "y": 0,
      "z": -4,
      "name": "Rock_Marble_Brick_Decorative",
      "rotation": 3
    },
    {
      "x": -6,
      "y": 1,
      "z": -4,
      "name": "Rock_Marble_Brick_Smooth_Half",
      "rotation": 6
    },
    {
      "x": -6,
      "y": 2,
      "z": -4,
      "name": "Rock_Marble_Brick_Smooth_Half",
      "rotation": 6
    },
    {
      "x": -6,
      "y": 3,
      "z": -4,
      "name": "Rock_Marble_Brick_Smooth_Half",
      "rotation": 6
    },
    {
      "x": -6,
      "y": 4,
      "z": -4,
      "name": "Rock_Marble_Brick_Smooth_Half",
      "rotation": 6
    },
    {
      "x": -6,
      "y": 5,
      "z": -4,
      "name": "Rock_Marble_Brick_Smooth_Half",
      "rotation": 6
    },
    {
      "x": -6,
      "y": 6,
      "z": -4,
      "name": "Rock_Marble_Brick"
    },
    {
      "x": -6,
      "y": 7,
      "z": -4,
      "name": "Rock_Marble_Brick_Decorative",
      "rotation": 3
    },
    {
      "x": -6,
      "y": 8,
      "z": -4,
      "name": "Rock_Marble_Brick_Smooth_Half",
      "rotation": 6
    },
    {
      "x": -6,
      "y": 9,
      "z": -4,
      "name": "Rock_Marble_Brick_Smooth_Half",
      "rotation": 6
    },
    {
      "x": -6,
      "y": 10,
      "z": -4,
      "name": "Rock_Marble_Brick_Smooth_Half",
      "rotation": 6
    },
    {
      "x": -6,
      "y": 11,
      "z": -4,
      "name": "Rock_Marble_Brick_Smooth_Half",
      "rotation": 6
    },
    {
      "x": -6,
      "y": 12,
      "z": -4,
      "name": "Rock_Marble_Brick_Smooth_Half",
      "rotation": 6
    },
    {
      "x": -6,
      "y": 13,
      "z": -4,
      "name": "Rock_Marble_Brick_Smooth",
      "rotation": 3
    },
    {
      "x": -6,
      "y": 14,
      "z": -4,
      "name": "Rock_Marble_Brick_Decorative",
      "rotation": 3
    },
    {
      "x": -6,
      "y": 15,
      "z": -4,
      "name": "Rock_Marble_Brick_Smooth_Half",
      "rotation": 6
    },
    {
      "x": -6,
      "y": 16,
      "z": -4,
      "name": "Rock_Marble_Brick_Smooth_Half",
      "rotation": 6
    },
    {
      "x": -6,
      "y": 17,
      "z": -4,
      "name": "Rock_Marble_Brick_Smooth_Half",
      "rotation": 6
    },
    {
      "x": -6,
      "y": 18,
      "z": -4,
      "name": "Rock_Marble_Brick_Smooth_Half",
      "rotation": 6
    },
    {
      "x": -6,
      "y": 19,
      "z": -4,
      "name": "Rock_Marble_Brick_Smooth_Half",
      "rotation": 6
    },
    {
      "x": -6,
      "y": 20,
      "z": -4,
      "name": "Rock_Marble_Brick"
    },
    {
      "x": -6,
      "y": 21,
      "z": -4,
      "name": "Rock_Marble_Brick_Decorative",
      "rotation": 3
    },
    {
      "x": -6,
      "y": 22,
      "z": -4,
      "name": "Rock_Marble_Brick_Smooth_Half",
      "rotation": 6
    },
    {
      "x": -6,
      "y": 23,
      "z": -4,
      "name": "Rock_Marble_Brick_Smooth_Half",
      "rotation": 6
    },
    {
      "x": -6,
      "y": 24,
      "z": -4,
      "name": "Rock_Marble_Brick_Smooth_Half",
      "rotation": 6
    },
    {
      "x": -6,
      "y": 25,
      "z": -4,
      "name": "Rock_Marble_Brick_Smooth_Half",
      "rotation": 6
    },
    {
      "x": -6,
      "y": 26,
      "z": -4,
      "name": "Rock_Marble_Brick_Smooth_Half",
      "rotation": 6
    },
    {
      "x": -6,
      "y": 27,
      "z": -4,
      "name": "Rock_Marble_Brick_Smooth",
      "rotation": 3
    },
    {
      "x": -6,
      "y": 28,
      "z": -4,
      "name": "Rock_Marble_Brick_Decorative",
      "rotation": 3
    },
    {
      "x": -6,
      "y": 29,
      "z": -4,
      "name": "Rock_Marble_Brick_Smooth_Half",
      "rotation": 6
    },
    {
      "x": -6,
      "y": 30,
      "z": -4,
      "name": "Rock_Marble_Brick_Smooth_Half",
      "rotation": 6
    },
    {
      "x": -6,
      "y": 31,
      "z": -4,
      "name": "Rock_Marble_Brick_Smooth_Half",
      "rotation": 6
    },
    {
      "x": -6,
      "y": 32,
      "z": -4,
      "name": "Rock_Marble_Brick_Smooth_Half",
      "rotation": 6
    },
    {
      "x": -6,
      "y": 33,
      "z": -4,
      "name": "Rock_Marble_Brick_Smooth_Half",
      "rotation": 6
    },
    {
      "x": -6,
      "y": 34,
      "z": -4,
      "name": "Rock_Marble_Brick"
    },
    {
      "x": -6,
      "y": 35,
      "z": -4,
      "name": "Rock_Marble_Brick_Decorative",
      "rotation": 3
    },
    {
      "x": -6,
      "y": 36,
      "z": -4,
      "name": "Rock_Marble_Brick_Smooth_Half",
      "rotation": 6
    },
    {
      "x": -6,
      "y": 37,
      "z": -4,
      "name": "Rock_Marble_Brick_Smooth_Half",
      "rotation": 6
    },
    {
      "x": -6,
      "y": 38,
      "z": -4,
      "name": "Rock_Marble_Brick_Smooth_Half",
      "rotation": 6
    },
    {
      "x": -6,
      "y": 39,
      "z": -4,
      "name": "Rock_Marble_Brick_Smooth_Half",
      "rotation": 6
    },
    {
      "x": -6,
      "y": 40,
      "z": -4,
      "name": "Rock_Marble_Brick_Smooth_Half",
      "rotation": 6
    },
    {
      "x": -6,
      "y": 41,
      "z": -4,
      "name": "Rock_Marble_Brick_Smooth",
      "rotation": 3
    },
    {
      "x": -6,
      "y": 42,
      "z": -4,
      "name": "Rock_Marble_Brick_Smooth_Half",
      "rotation": 8
    },
    {
      "x": -6,
      "y": 47,
      "z": -4,
      "name": "Rock_Marble_SkyGrass"
    },
    {
      "x": -6,
      "y": -4,
      "z": -3,
      "name": "Rock_Marble_Brick"
    },
    {
      "x": -6,
      "y": -3,
      "z": -3,
      "name": "Rock_Marble_Brick"
    },
    {
      "x": -6,
      "y": -2,
      "z": -3,
      "name": "Rock_Marble_Brick"
    },
    {
      "x": -6,
      "y": -1,
      "z": -3,
      "name": "Rock_Marble_Brick"
    },
    {
      "x": -6,
      "y": 0,
      "z": -3,
      "name": "Rock_Marble_Brick_Decorative",
      "rotation": 3
    },
    {
      "x": -6,
      "y": 1,
      "z": -3,
      "name": "Rock_Marble_Brick",
      "rotation": 3
    },
    {
      "x": -6,
      "y": 2,
      "z": -3,
      "name": "Rock_Marble_Brick",
      "rotation": 3
    },
    {
      "x": -6,
      "y": 3,
      "z": -3,
      "name": "Rock_Marble_Brick",
      "rotation": 3
    },
    {
      "x": -6,
      "y": 4,
      "z": -3,
      "name": "Rock_Marble_Brick",
      "rotation": 3
    },
    {
      "x": -6,
      "y": 5,
      "z": -3,
      "name": "Rock_Marble_Brick",
      "rotation": 3
    },
    {
      "x": -6,
      "y": 6,
      "z": -3,
      "name": "Rock_Marble_Brick"
    },
    {
      "x": -6,
      "y": 7,
      "z": -3,
      "name": "Rock_Marble_Brick_Decorative",
      "rotation": 3
    },
    {
      "x": -6,
      "y": 8,
      "z": -3,
      "name": "Rock_Marble_Brick",
      "rotation": 3
    },
    {
      "x": -6,
      "y": 9,
      "z": -3,
      "name": "Rock_Marble_Brick",
      "rotation": 3
    },
    {
      "x": -6,
      "y": 10,
      "z": -3,
      "name": "Rock_Marble_Brick",
      "rotation": 3
    },
    {
      "x": -6,
      "y": 11,
      "z": -3,
      "name": "Rock_Marble_Brick",
      "rotation": 3
    },
    {
      "x": -6,
      "y": 12,
      "z": -3,
      "name": "Rock_Marble_Brick",
      "rotation": 3
    },
    {
      "x": -6,
      "y": 13,
      "z": -3,
      "name": "Rock_Marble_Brick_Smooth",
      "rotation": 3
    },
    {
      "x": -6,
      "y": 14,
      "z": -3,
      "name": "Rock_Marble_Brick_Decorative",
      "rotation": 3
    },
    {
      "x": -6,
      "y": 15,
      "z": -3,
      "name": "Rock_Marble_Brick",
      "rotation": 3
    },
    {
      "x": -6,
      "y": 16,
      "z": -3,
      "name": "Rock_Marble_Brick",
      "rotation": 3
    },
    {
      "x": -6,
      "y": 17,
      "z": -3,
      "name": "Rock_Marble_Brick",
      "rotation": 3
    },
    {
      "x": -6,
      "y": 18,
      "z": -3,
      "name": "Rock_Marble_Brick",
      "rotation": 3
    },
    {
      "x": -6,
      "y": 19,
      "z": -3,
      "name": "Rock_Marble_Brick",
      "rotation": 3
    },
    {
      "x": -6,
      "y": 20,
      "z": -3,
      "name": "Rock_Marble_Brick"
    },
    {
      "x": -6,
      "y": 21,
      "z": -3,
      "name": "Rock_Marble_Brick_Decorative",
      "rotation": 3
    },
    {
      "x": -6,
      "y": 22,
      "z": -3,
      "name": "Rock_Marble_Brick",
      "rotation": 3
    },
    {
      "x": -6,
      "y": 23,
      "z": -3,
      "name": "Rock_Marble_Brick",
      "rotation": 3
    },
    {
      "x": -6,
      "y": 24,
      "z": -3,
      "name": "Rock_Marble_Brick",
      "rotation": 3
    },
    {
      "x": -6,
      "y": 25,
      "z": -3,
      "name": "Rock_Marble_Brick",
      "rotation": 3
    },
    {
      "x": -6,
      "y": 26,
      "z": -3,
      "name": "Rock_Marble_Brick",
      "rotation": 3
    },
    {
      "x": -6,
      "y": 27,
      "z": -3,
      "name": "Rock_Marble_Brick_Smooth",
      "rotation": 3
    },
    {
      "x": -6,
      "y": 28,
      "z": -3,
      "name": "Rock_Marble_Brick_Decorative",
      "rotation": 3
    },
    {
      "x": -6,
      "y": 29,
      "z": -3,
      "name": "Rock_Marble_Brick",
      "rotation": 3
    },
    {
      "x": -6,
      "y": 30,
      "z": -3,
      "name": "Rock_Marble_Brick",
      "rotation": 3
    },
    {
      "x": -6,
      "y": 31,
      "z": -3,
      "name": "Rock_Marble_Brick",
      "rotation": 3
    },
    {
      "x": -6,
      "y": 32,
      "z": -3,
      "name": "Rock_Marble_Brick",
      "rotation": 3
    },
    {
      "x": -6,
      "y": 33,
      "z": -3,
      "name": "Rock_Marble_Brick",
      "rotation": 3
    },
    {
      "x": -6,
      "y": 34,
      "z": -3,
      "name": "Rock_Marble_Brick"
    },
    {
      "x": -6,
      "y": 35,
      "z": -3,
      "name": "Rock_Marble_Brick_Decorative",
      "rotation": 3
    },
    {
      "x": -6,
      "y": 36,
      "z": -3,
      "name": "Rock_Marble_Brick",
      "rotation": 3
    },
    {
      "x": -6,
      "y": 37,
      "z": -3,
      "name": "Rock_Marble_Brick",
      "rotation": 3
    },
    {
      "x": -6,
      "y": 38,
      "z": -3,
      "name": "Rock_Marble_Brick",
      "rotation": 3
    },
    {
      "x": -6,
      "y": 39,
      "z": -3,
      "name": "Rock_Marble_Brick",
      "rotation": 3
    },
    {
      "x": -6,
      "y": 40,
      "z": -3,
      "name": "Rock_Marble_Brick",
      "rotation": 3
    },
    {
      "x": -6,
      "y": 41,
      "z": -3,
      "name": "Rock_Marble_Brick_Smooth",
      "rotation": 3
    },
    {
      "x": -6,
      "y": 42,
      "z": -3,
      "name": "Rock_Marble_Brick_Smooth_Half",
      "rotation": 8
    },
    {
      "x": -6,
      "y": 43,
      "z": -3,
      "name": "Furniture_Crude_Torch",
      "rotation": 1
    },
    {
      "x": -6,
      "y": 47,
      "z": -3,
      "name": "Rock_Marble_SkyGrass"
    },
    {
      "x": -6,
      "y": 48,
      "z": -3,
      "name": "Plant_Grass_Sky",
      "support": 15
    },
    {
      "x": -6,
      "y": -4,
      "z": -2,
      "name": "Rock_Marble_Brick"
    },
    {
      "x": -6,
      "y": -3,
      "z": -2,
      "name": "Rock_Marble_Brick"
    },
    {
      "x": -6,
      "y": -2,
      "z": -2,
      "name": "Rock_Marble_Brick"
    },
    {
      "x": -6,
      "y": -1,
      "z": -2,
      "name": "Rock_Marble_Brick"
    },
    {
      "x": -6,
      "y": 0,
      "z": -2,
      "name": "Rock_Marble_Brick_Decorative",
      "rotation": 3
    },
    {
      "x": -6,
      "y": 1,
      "z": -2,
      "name": "Rock_Marble_Brick_Smooth_Half",
      "rotation": 11
    },
    {
      "x": -6,
      "y": 3,
      "z": -2,
      "name": "Rock_Marble_Brick_Smooth_Half",
      "rotation": 4
    },
    {
      "x": -6,
      "y": 4,
      "z": -2,
      "name": "Rock_Marble_Brick_Stairs",
      "rotation": 10
    },
    {
      "x": -6,
      "y": 5,
      "z": -2,
      "name": "Rock_Marble_Brick",
      "rotation": 3
    },
    {
      "x": -6,
      "y": 6,
      "z": -2,
      "name": "Rock_Marble_Brick"
    },
    {
      "x": -6,
      "y": 7,
      "z": -2,
      "name": "Rock_Marble_Brick_Decorative",
      "rotation": 3
    },
    {
      "x": -6,
      "y": 8,
      "z": -2,
      "name": "Rock_Marble_Brick_Smooth_Half",
      "rotation": 33
    },
    {
      "x": -6,
      "y": 10,
      "z": -2,
      "name": "Rock_Marble_Brick_Smooth_Half",
      "rotation": 4
    },
    {
      "x": -6,
      "y": 11,
      "z": -2,
      "name": "Rock_Marble_Brick_Stairs",
      "rotation": 32
    },
    {
      "x": -6,
      "y": 12,
      "z": -2,
      "name": "Rock_Marble_Brick",
      "rotation": 3
    },
    {
      "x": -6,
      "y": 13,
      "z": -2,
      "name": "Rock_Marble_Brick_Smooth",
      "rotation": 3
    },
    {
      "x": -6,
      "y": 14,
      "z": -2,
      "name": "Rock_Marble_Brick_Decorative",
      "rotation": 3
    },
    {
      "x": -6,
      "y": 15,
      "z": -2,
      "name": "Rock_Marble_Brick_Smooth_Half",
      "rotation": 33
    },
    {
      "x": -6,
      "y": 17,
      "z": -2,
      "name": "Rock_Marble_Brick_Smooth_Half",
      "rotation": 4
    },
    {
      "x": -6,
      "y": 18,
      "z": -2,
      "name": "Rock_Marble_Brick_Stairs",
      "rotation": 32
    },
    {
      "x": -6,
      "y": 19,
      "z": -2,
      "name": "Rock_Marble_Brick",
      "rotation": 3
    },
    {
      "x": -6,
      "y": 20,
      "z": -2,
      "name": "Rock_Marble_Brick"
    },
    {
      "x": -6,
      "y": 21,
      "z": -2,
      "name": "Rock_Marble_Brick_Decorative",
      "rotation": 3
    },
    {
      "x": -6,
      "y": 22,
      "z": -2,
      "name": "Rock_Marble_Brick_Smooth_Half",
      "rotation": 33
    },
    {
      "x": -6,
      "y": 24,
      "z": -2,
      "name": "Rock_Marble_Brick_Smooth_Half",
      "rotation": 4
    },
    {
      "x": -6,
      "y": 25,
      "z": -2,
      "name": "Rock_Marble_Brick_Stairs",
      "rotation": 32
    },
    {
      "x": -6,
      "y": 26,
      "z": -2,
      "name": "Rock_Marble_Brick",
      "rotation": 3
    },
    {
      "x": -6,
      "y": 27,
      "z": -2,
      "name": "Rock_Marble_Brick_Smooth",
      "rotation": 3
    },
    {
      "x": -6,
      "y": 28,
      "z": -2,
      "name": "Rock_Marble_Brick_Decorative",
      "rotation": 3
    },
    {
      "x": -6,
      "y": 29,
      "z": -2,
      "name": "Rock_Marble_Brick_Smooth_Half",
      "rotation": 33
    },
    {
      "x": -6,
      "y": 31,
      "z": -2,
      "name": "Rock_Marble_Brick_Smooth_Half",
      "rotation": 4
    },
    {
      "x": -6,
      "y": 32,
      "z": -2,
      "name": "Rock_Marble_Brick_Stairs",
      "rotation": 32
    },
    {
      "x": -6,
      "y": 33,
      "z": -2,
      "name": "Rock_Marble_Brick",
      "rotation": 3
    },
    {
      "x": -6,
      "y": 34,
      "z": -2,
      "name": "Rock_Marble_Brick"
    },
    {
      "x": -6,
      "y": 35,
      "z": -2,
      "name": "Rock_Marble_Brick_Decorative",
      "rotation": 3
    },
    {
      "x": -6,
      "y": 36,
      "z": -2,
      "name": "Rock_Marble_Brick_Smooth_Half",
      "rotation": 33
    },
    {
      "x": -6,
      "y": 38,
      "z": -2,
      "name": "Rock_Marble_Brick_Smooth_Half",
      "rotation": 4
    },
    {
      "x": -6,
      "y": 39,
      "z": -2,
      "name": "Rock_Marble_Brick_Stairs",
      "rotation": 32
    },
    {
      "x": -6,
      "y": 40,
      "z": -2,
      "name": "Rock_Marble_Brick",
      "rotation": 3
    },
    {
      "x": -6,
      "y": 41,
      "z": -2,
      "name": "Rock_Marble_Brick_Smooth",
      "rotation": 3
    },
    {
      "x": -6,
      "y": 42,
      "z": -2,
      "name": "Rock_Marble_Brick_Smooth_Half",
      "rotation": 8
    },
    {
      "x": -6,
      "y": 47,
      "z": -2,
      "name": "Rock_Marble_SkyGrass"
    },
    {
      "x": -6,
      "y": 48,
      "z": -2,
      "name": "Plant_Bush_Sky",
      "support": 15
    },
    {
      "x": -6,
      "y": -4,
      "z": -1,
      "name": "Rock_Marble_Brick"
    },
    {
      "x": -6,
      "y": -3,
      "z": -1,
      "name": "Rock_Marble_Brick"
    },
    {
      "x": -6,
      "y": -2,
      "z": -1,
      "name": "Rock_Marble_Brick"
    },
    {
      "x": -6,
      "y": -1,
      "z": -1,
      "name": "Rock_Marble_Brick"
    },
    {
      "x": -6,
      "y": 0,
      "z": -1,
      "name": "Rock_Marble_Brick_Decorative",
      "rotation": 3
    },
    {
      "x": -6,
      "y": 1,
      "z": -1,
      "name": "Rock_Marble_Brick_Smooth_Half",
      "rotation": 11
    },
    {
      "x": -6,
      "y": 5,
      "z": -1,
      "name": "Rock_Marble_Brick",
      "rotation": 3
    },
    {
      "x": -6,
      "y": 6,
      "z": -1,
      "name": "Rock_Marble_Brick"
    },
    {
      "x": -6,
      "y": 7,
      "z": -1,
      "name": "Rock_Marble_Brick_Decorative",
      "rotation": 3
    },
    {
      "x": -6,
      "y": 8,
      "z": -1,
      "name": "Rock_Marble_Brick_Smooth_Half",
      "rotation": 33
    },
    {
      "x": -6,
      "y": 12,
      "z": -1,
      "name": "Rock_Marble_Brick",
      "rotation": 3
    },
    {
      "x": -6,
      "y": 13,
      "z": -1,
      "name": "Rock_Marble_Brick",
      "rotation": 2
    },
    {
      "x": -6,
      "y": 14,
      "z": -1,
      "name": "Rock_Marble_Brick_Decorative",
      "rotation": 3
    },
    {
      "x": -6,
      "y": 15,
      "z": -1,
      "name": "Rock_Marble_Brick_Smooth_Half",
      "rotation": 33
    },
    {
      "x": -6,
      "y": 19,
      "z": -1,
      "name": "Rock_Marble_Brick",
      "rotation": 3
    },
    {
      "x": -6,
      "y": 20,
      "z": -1,
      "name": "Rock_Marble_Brick"
    },
    {
      "x": -6,
      "y": 21,
      "z": -1,
      "name": "Rock_Marble_Brick_Decorative",
      "rotation": 3
    },
    {
      "x": -6,
      "y": 22,
      "z": -1,
      "name": "Rock_Marble_Brick_Smooth_Half",
      "rotation": 33
    },
    {
      "x": -6,
      "y": 26,
      "z": -1,
      "name": "Rock_Marble_Brick",
      "rotation": 3
    },
    {
      "x": -6,
      "y": 27,
      "z": -1,
      "name": "Rock_Marble_Brick",
      "rotation": 2
    },
    {
      "x": -6,
      "y": 28,
      "z": -1,
      "name": "Rock_Marble_Brick_Decorative",
      "rotation": 3
    },
    {
      "x": -6,
      "y": 29,
      "z": -1,
      "name": "Rock_Marble_Brick_Smooth_Half",
      "rotation": 33
    },
    {
      "x": -6,
      "y": 33,
      "z": -1,
      "name": "Rock_Marble_Brick",
      "rotation": 3
    },
    {
      "x": -6,
      "y": 34,
      "z": -1,
      "name": "Rock_Marble_Brick"
    },
    {
      "x": -6,
      "y": 35,
      "z": -1,
      "name": "Rock_Marble_Brick_Decorative",
      "rotation": 3
    },
    {
      "x": -6,
      "y": 36,
      "z": -1,
      "name": "Rock_Marble_Brick_Smooth_Half",
      "rotation": 33
    },
    {
      "x": -6,
      "y": 40,
      "z": -1,
      "name": "Rock_Marble_Brick",
      "rotation": 3
    },
    {
      "x": -6,
      "y": 41,
      "z": -1,
      "name": "Rock_Marble_Brick",
      "rotation": 2
    },
    {
      "x": -6,
      "y": 42,
      "z": -1,
      "name": "Rock_Marble_Brick_Smooth_Half",
      "rotation": 8
    },
    {
      "x": -6,
      "y": 47,
      "z": -1,
      "name": "Rock_Marble_SkyGrass"
    },
    {
      "x": -6,
      "y": 48,
      "z": -1,
      "name": "Plant_Grass_Sky",
      "support": 15
    },
    {
      "x": -6,
      "y": -4,
      "z": 0,
      "name": "Rock_Marble_Brick"
    },
    {
      "x": -6,
      "y": -3,
      "z": 0,
      "name": "Rock_Marble_Brick"
    },
    {
      "x": -6,
      "y": -2,
      "z": 0,
      "name": "Rock_Marble_Brick"
    },
    {
      "x": -6,
      "y": -1,
      "z": 0,
      "name": "Rock_Marble_Brick"
    },
    {
      "x": -6,
      "y": 0,
      "z": 0,
      "name": "Rock_Marble_Brick_Decorative",
      "rotation": 3
    },
    {
      "x": -6,
      "y": 1,
      "z": 0,
      "name": "Rock_Marble_Brick_Smooth_Half",
      "rotation": 11
    },
    {
      "x": -6,
      "y": 3,
      "z": 0,
      "name": "Rock_Marble_Brick_Smooth_Half",
      "rotation": 6
    },
    {
      "x": -6,
      "y": 4,
      "z": 0,
      "name": "Rock_Marble_Brick_Stairs",
      "rotation": 8
    },
    {
      "x": -6,
      "y": 5,
      "z": 0,
      "name": "Rock_Marble_Brick",
      "rotation": 3
    },
    {
      "x": -6,
      "y": 6,
      "z": 0,
      "name": "Rock_Marble_Brick"
    },
    {
      "x": -6,
      "y": 7,
      "z": 0,
      "name": "Rock_Marble_Brick_Decorative",
      "rotation": 3
    },
    {
      "x": -6,
      "y": 8,
      "z": 0,
      "name": "Rock_Marble_Brick_Smooth_Half",
      "rotation": 33
    },
    {
      "x": -6,
      "y": 10,
      "z": 0,
      "name": "Rock_Marble_Brick_Smooth_Half",
      "rotation": 6
    },
    {
      "x": -6,
      "y": 11,
      "z": 0,
      "name": "Rock_Marble_Brick_Stairs",
      "rotation": 34
    },
    {
      "x": -6,
      "y": 12,
      "z": 0,
      "name": "Rock_Marble_Brick",
      "rotation": 3
    },
    {
      "x": -6,
      "y": 13,
      "z": 0,
      "name": "Rock_Marble_Brick",
      "rotation": 2
    },
    {
      "x": -6,
      "y": 14,
      "z": 0,
      "name": "Rock_Marble_Brick_Decorative",
      "rotation": 3
    },
    {
      "x": -6,
      "y": 15,
      "z": 0,
      "name": "Rock_Marble_Brick_Smooth_Half",
      "rotation": 33
    },
    {
      "x": -6,
      "y": 17,
      "z": 0,
      "name": "Rock_Marble_Brick_Smooth_Half",
      "rotation": 6
    },
    {
      "x": -6,
      "y": 18,
      "z": 0,
      "name": "Rock_Marble_Brick_Stairs",
      "rotation": 34
    },
    {
      "x": -6,
      "y": 19,
      "z": 0,
      "name": "Rock_Marble_Brick",
      "rotation": 3
    },
    {
      "x": -6,
      "y": 20,
      "z": 0,
      "name": "Rock_Marble_Brick"
    },
    {
      "x": -6,
      "y": 21,
      "z": 0,
      "name": "Rock_Marble_Brick_Decorative",
      "rotation": 3
    },
    {
      "x": -6,
      "y": 22,
      "z": 0,
      "name": "Rock_Marble_Brick_Smooth_Half",
      "rotation": 33
    },
    {
      "x": -6,
      "y": 24,
      "z": 0,
      "name": "Rock_Marble_Brick_Smooth_Half",
      "rotation": 6
    },
    {
      "x": -6,
      "y": 25,
      "z": 0,
      "name": "Rock_Marble_Brick_Stairs",
      "rotation": 34
    },
    {
      "x": -6,
      "y": 26,
      "z": 0,
      "name": "Rock_Marble_Brick",
      "rotation": 3
    },
    {
      "x": -6,
      "y": 27,
      "z": 0,
      "name": "Rock_Marble_Brick",
      "rotation": 2
    },
    {
      "x": -6,
      "y": 28,
      "z": 0,
      "name": "Rock_Marble_Brick_Decorative",
      "rotation": 3
    },
    {
      "x": -6,
      "y": 29,
      "z": 0,
      "name": "Rock_Marble_Brick_Smooth_Half",
      "rotation": 33
    },
    {
      "x": -6,
      "y": 31,
      "z": 0,
      "name": "Rock_Marble_Brick_Smooth_Half",
      "rotation": 6
    },
    {
      "x": -6,
      "y": 32,
      "z": 0,
      "name": "Rock_Marble_Brick_Stairs",
      "rotation": 34
    },
    {
      "x": -6,
      "y": 33,
      "z": 0,
      "name": "Rock_Marble_Brick",
      "rotation": 3
    },
    {
      "x": -6,
      "y": 34,
      "z": 0,
      "name": "Rock_Marble_Brick"
    },
    {
      "x": -6,
      "y": 35,
      "z": 0,
      "name": "Rock_Marble_Brick_Decorative",
      "rotation": 3
    },
    {
      "x": -6,
      "y": 36,
      "z": 0,
      "name": "Rock_Marble_Brick_Smooth_Half",
      "rotation": 33
    },
    {
      "x": -6,
      "y": 38,
      "z": 0,
      "name": "Rock_Marble_Brick_Smooth_Half",
      "rotation": 6
    },
    {
      "x": -6,
      "y": 39,
      "z": 0,
      "name": "Rock_Marble_Brick_Stairs",
      "rotation": 34
    },
    {
      "x": -6,
      "y": 40,
      "z": 0,
      "name": "Rock_Marble_Brick",
      "rotation": 3
    },
    {
      "x": -6,
      "y": 41,
      "z": 0,
      "name": "Rock_Marble_Brick",
      "rotation": 2
    },
    {
      "x": -6,
      "y": 42,
      "z": 0,
      "name": "Rock_Marble_Brick_Smooth_Half",
      "rotation": 8
    },
    {
      "x": -6,
      "y": 47,
      "z": 0,
      "name": "Rock_Marble_Brick"
    },
    {
      "x": -6,
      "y": -4,
      "z": 1,
      "name": "Rock_Marble_Brick"
    },
    {
      "x": -6,
      "y": -3,
      "z": 1,
      "name": "Rock_Marble_Brick"
    },
    {
      "x": -6,
      "y": -2,
      "z": 1,
      "name": "Rock_Marble_Brick"
    },
    {
      "x": -6,
      "y": -1,
      "z": 1,
      "name": "Rock_Marble_Brick"
    },
    {
      "x": -6,
      "y": 0,
      "z": 1,
      "name": "Rock_Marble_Brick_Decorative",
      "rotation": 3
    },
    {
      "x": -6,
      "y": 1,
      "z": 1,
      "name": "Rock_Marble_Brick",
      "rotation": 3
    },
    {
      "x": -6,
      "y": 2,
      "z": 1,
      "name": "Rock_Marble_Brick",
      "rotation": 3
    },
    {
      "x": -6,
      "y": 3,
      "z": 1,
      "name": "Rock_Marble_Brick",
      "rotation": 3
    },
    {
      "x": -6,
      "y": 4,
      "z": 1,
      "name": "Rock_Marble_Brick",
      "rotation": 3
    },
    {
      "x": -6,
      "y": 5,
      "z": 1,
      "name": "Rock_Marble_Brick",
      "rotation": 3
    },
    {
      "x": -6,
      "y": 6,
      "z": 1,
      "name": "Rock_Marble_Brick"
    },
    {
      "x": -6,
      "y": 7,
      "z": 1,
      "name": "Rock_Marble_Brick_Decorative",
      "rotation": 3
    },
    {
      "x": -6,
      "y": 8,
      "z": 1,
      "name": "Rock_Marble_Brick",
      "rotation": 3
    },
    {
      "x": -6,
      "y": 9,
      "z": 1,
      "name": "Rock_Marble_Brick",
      "rotation": 3
    },
    {
      "x": -6,
      "y": 10,
      "z": 1,
      "name": "Rock_Marble_Brick",
      "rotation": 3
    },
    {
      "x": -6,
      "y": 11,
      "z": 1,
      "name": "Rock_Marble_Brick",
      "rotation": 3
    },
    {
      "x": -6,
      "y": 12,
      "z": 1,
      "name": "Rock_Marble_Brick",
      "rotation": 3
    },
    {
      "x": -6,
      "y": 13,
      "z": 1,
      "name": "Rock_Marble_Brick",
      "rotation": 2
    },
    {
      "x": -6,
      "y": 14,
      "z": 1,
      "name": "Rock_Marble_Brick_Decorative",
      "rotation": 3
    },
    {
      "x": -6,
      "y": 15,
      "z": 1,
      "name": "Rock_Marble_Brick",
      "rotation": 3
    },
    {
      "x": -6,
      "y": 16,
      "z": 1,
      "name": "Rock_Marble_Brick",
      "rotation": 3
    },
    {
      "x": -6,
      "y": 17,
      "z": 1,
      "name": "Rock_Marble_Brick",
      "rotation": 3
    },
    {
      "x": -6,
      "y": 18,
      "z": 1,
      "name": "Rock_Marble_Brick",
      "rotation": 3
    },
    {
      "x": -6,
      "y": 19,
      "z": 1,
      "name": "Rock_Marble_Brick",
      "rotation": 3
    },
    {
      "x": -6,
      "y": 20,
      "z": 1,
      "name": "Rock_Marble_Brick"
    },
    {
      "x": -6,
      "y": 21,
      "z": 1,
      "name": "Rock_Marble_Brick_Decorative",
      "rotation": 3
    },
    {
      "x": -6,
      "y": 22,
      "z": 1,
      "name": "Rock_Marble_Brick",
      "rotation": 3
    },
    {
      "x": -6,
      "y": 23,
      "z": 1,
      "name": "Rock_Marble_Brick",
      "rotation": 3
    },
    {
      "x": -6,
      "y": 24,
      "z": 1,
      "name": "Rock_Marble_Brick",
      "rotation": 3
    },
    {
      "x": -6,
      "y": 25,
      "z": 1,
      "name": "Rock_Marble_Brick",
      "rotation": 3
    },
    {
      "x": -6,
      "y": 26,
      "z": 1,
      "name": "Rock_Marble_Brick",
      "rotation": 3
    },
    {
      "x": -6,
      "y": 27,
      "z": 1,
      "name": "Rock_Marble_Brick",
      "rotation": 2
    },
    {
      "x": -6,
      "y": 28,
      "z": 1,
      "name": "Rock_Marble_Brick_Decorative",
      "rotation": 3
    },
    {
      "x": -6,
      "y": 29,
      "z": 1,
      "name": "Rock_Marble_Brick",
      "rotation": 3
    },
    {
      "x": -6,
      "y": 30,
      "z": 1,
      "name": "Rock_Marble_Brick",
      "rotation": 3
    },
    {
      "x": -6,
      "y": 31,
      "z": 1,
      "name": "Rock_Marble_Brick",
      "rotation": 3
    },
    {
      "x": -6,
      "y": 32,
      "z": 1,
      "name": "Rock_Marble_Brick",
      "rotation": 3
    },
    {
      "x": -6,
      "y": 33,
      "z": 1,
      "name": "Rock_Marble_Brick",
      "rotation": 3
    },
    {
      "x": -6,
      "y": 34,
      "z": 1,
      "name": "Rock_Marble_Brick"
    },
    {
      "x": -6,
      "y": 35,
      "z": 1,
      "name": "Rock_Marble_Brick_Decorative",
      "rotation": 3
    },
    {
      "x": -6,
      "y": 36,
      "z": 1,
      "name": "Rock_Marble_Brick"
    },
    {
      "x": -6,
      "y": 37,
      "z": 1,
      "name": "Rock_Marble_Brick",
      "rotation": 3
    },
    {
      "x": -6,
      "y": 38,
      "z": 1,
      "name": "Rock_Marble_Brick",
      "rotation": 3
    },
    {
      "x": -6,
      "y": 39,
      "z": 1,
      "name": "Rock_Marble_Brick",
      "rotation": 3
    },
    {
      "x": -6,
      "y": 40,
      "z": 1,
      "name": "Rock_Marble_Brick",
      "rotation": 3
    },
    {
      "x": -6,
      "y": 41,
      "z": 1,
      "name": "Rock_Marble_Brick",
      "rotation": 2
    },
    {
      "x": -6,
      "y": 42,
      "z": 1,
      "name": "Rock_Marble_Brick_Smooth_Half",
      "rotation": 8
    },
    {
      "x": -6,
      "y": 43,
      "z": 1,
      "name": "Furniture_Crude_Torch",
      "rotation": 1
    },
    {
      "x": -6,
      "y": 47,
      "z": 1,
      "name": "Rock_Marble_Brick"
    },
    {
      "x": -6,
      "y": -4,
      "z": 2,
      "name": "Rock_Marble_Brick"
    },
    {
      "x": -6,
      "y": -3,
      "z": 2,
      "name": "Rock_Marble_Brick"
    },
    {
      "x": -6,
      "y": -2,
      "z": 2,
      "name": "Rock_Marble_Brick"
    },
    {
      "x": -6,
      "y": -1,
      "z": 2,
      "name": "Rock_Marble_Brick"
    },
    {
      "x": -6,
      "y": 0,
      "z": 2,
      "name": "Rock_Marble_Brick_Decorative"
    },
    {
      "x": -6,
      "y": 1,
      "z": 2,
      "name": "Rock_Marble_Brick_Smooth_Half",
      "rotation": 4
    },
    {
      "x": -6,
      "y": 2,
      "z": 2,
      "name": "Rock_Marble_Brick_Smooth_Half",
      "rotation": 4
    },
    {
      "x": -6,
      "y": 3,
      "z": 2,
      "name": "Rock_Marble_Brick_Smooth_Half",
      "rotation": 4
    },
    {
      "x": -6,
      "y": 4,
      "z": 2,
      "name": "Rock_Marble_Brick_Smooth_Half",
      "rotation": 4
    },
    {
      "x": -6,
      "y": 5,
      "z": 2,
      "name": "Rock_Marble_Brick_Smooth_Half",
      "rotation": 4
    },
    {
      "x": -6,
      "y": 6,
      "z": 2,
      "name": "Rock_Marble_Brick"
    },
    {
      "x": -6,
      "y": 7,
      "z": 2,
      "name": "Rock_Marble_Brick_Decorative"
    },
    {
      "x": -6,
      "y": 8,
      "z": 2,
      "name": "Rock_Marble_Brick_Smooth_Half",
      "rotation": 4
    },
    {
      "x": -6,
      "y": 9,
      "z": 2,
      "name": "Rock_Marble_Brick_Smooth_Half",
      "rotation": 4
    },
    {
      "x": -6,
      "y": 10,
      "z": 2,
      "name": "Rock_Marble_Brick_Smooth_Half",
      "rotation": 4
    },
    {
      "x": -6,
      "y": 11,
      "z": 2,
      "name": "Rock_Marble_Brick_Smooth_Half",
      "rotation": 4
    },
    {
      "x": -6,
      "y": 12,
      "z": 2,
      "name": "Rock_Marble_Brick_Smooth_Half",
      "rotation": 4
    },
    {
      "x": -6,
      "y": 13,
      "z": 2,
      "name": "Rock_Marble_Brick_Smooth"
    },
    {
      "x": -6,
      "y": 14,
      "z": 2,
      "name": "Rock_Marble_Brick_Decorative"
    },
    {
      "x": -6,
      "y": 15,
      "z": 2,
      "name": "Rock_Marble_Brick_Smooth_Half",
      "rotation": 4
    },
    {
      "x": -6,
      "y": 16,
      "z": 2,
      "name": "Rock_Marble_Brick_Smooth_Half",
      "rotation": 4
    },
    {
      "x": -6,
      "y": 17,
      "z": 2,
      "name": "Rock_Marble_Brick_Smooth_Half",
      "rotation": 4
    },
    {
      "x": -6,
      "y": 18,
      "z": 2,
      "name": "Rock_Marble_Brick_Smooth_Half",
      "rotation": 4
    },
    {
      "x": -6,
      "y": 19,
      "z": 2,
      "name": "Rock_Marble_Brick_Smooth_Half",
      "rotation": 4
    },
    {
      "x": -6,
      "y": 20,
      "z": 2,
      "name": "Rock_Marble_Brick"
    },
    {
      "x": -6,
      "y": 21,
      "z": 2,
      "name": "Rock_Marble_Brick_Decorative"
    },
    {
      "x": -6,
      "y": 22,
      "z": 2,
      "name": "Rock_Marble_Brick_Smooth_Half",
      "rotation": 4
    },
    {
      "x": -6,
      "y": 23,
      "z": 2,
      "name": "Rock_Marble_Brick_Smooth_Half",
      "rotation": 4
    },
    {
      "x": -6,
      "y": 24,
      "z": 2,
      "name": "Rock_Marble_Brick_Smooth_Half",
      "rotation": 4
    },
    {
      "x": -6,
      "y": 25,
      "z": 2,
      "name": "Rock_Marble_Brick_Smooth_Half",
      "rotation": 4
    },
    {
      "x": -6,
      "y": 26,
      "z": 2,
      "name": "Rock_Marble_Brick_Smooth_Half",
      "rotation": 4
    },
    {
      "x": -6,
      "y": 27,
      "z": 2,
      "name": "Rock_Marble_Brick_Smooth"
    },
    {
      "x": -6,
      "y": 28,
      "z": 2,
      "name": "Rock_Marble_Brick_Decorative"
    },
    {
      "x": -6,
      "y": 29,
      "z": 2,
      "name": "Rock_Marble_Brick_Smooth_Half",
      "rotation": 4
    },
    {
      "x": -6,
      "y": 30,
      "z": 2,
      "name": "Rock_Marble_Brick_Smooth_Half",
      "rotation": 4
    },
    {
      "x": -6,
      "y": 31,
      "z": 2,
      "name": "Rock_Marble_Brick_Smooth_Half",
      "rotation": 4
    },
    {
      "x": -6,
      "y": 32,
      "z": 2,
      "name": "Rock_Marble_Brick_Smooth_Half",
      "rotation": 4
    },
    {
      "x": -6,
      "y": 33,
      "z": 2,
      "name": "Rock_Marble_Brick_Smooth_Half",
      "rotation": 4
    },
    {
      "x": -6,
      "y": 34,
      "z": 2,
      "name": "Rock_Marble_Brick"
    },
    {
      "x": -6,
      "y": 35,
      "z": 2,
      "name": "Rock_Marble_Brick_Decorative"
    },
    {
      "x": -6,
      "y": 36,
      "z": 2,
      "name": "Rock_Marble_Brick_Smooth_Half",
      "rotation": 4
    },
    {
      "x": -6,
      "y": 37,
      "z": 2,
      "name": "Rock_Marble_Brick_Smooth_Half",
      "rotation": 4
    },
    {
      "x": -6,
      "y": 38,
      "z": 2,
      "name": "Rock_Marble_Brick_Smooth_Half",
      "rotation": 4
    },
    {
      "x": -6,
      "y": 39,
      "z": 2,
      "name": "Rock_Marble_Brick_Smooth_Half",
      "rotation": 4
    },
    {
      "x": -6,
      "y": 40,
      "z": 2,
      "name": "Rock_Marble_Brick_Smooth_Half",
      "rotation": 4
    },
    {
      "x": -6,
      "y": 41,
      "z": 2,
      "name": "Rock_Marble_Brick_Smooth"
    },
    {
      "x": -6,
      "y": 42,
      "z": 2,
      "name": "Rock_Marble_Brick_Smooth_Half",
      "rotation": 8
    },
    {
      "x": -6,
      "y": 47,
      "z": 2,
      "name": "Rock_Marble_Brick"
    },
    {
      "x": -6,
      "y": -4,
      "z": 3,
      "name": "Rock_Marble_Brick"
    },
    {
      "x": -6,
      "y": -3,
      "z": 3,
      "name": "Rock_Marble_Brick"
    },
    {
      "x": -6,
      "y": -2,
      "z": 3,
      "name": "Rock_Marble_Brick"
    },
    {
      "x": -6,
      "y": -1,
      "z": 3,
      "name": "Rock_Marble_Brick"
    },
    {
      "x": -6,
      "y": 0,
      "z": 3,
      "name": "Rock_Marble_Brick_Decorative",
      "rotation": 3
    },
    {
      "x": -6,
      "y": 1,
      "z": 3,
      "name": "Rock_Marble_Brick_Pillar_Base"
    },
    {
      "x": -6,
      "y": 2,
      "z": 3,
      "name": "Rock_Marble_Brick_Pillar_Middle"
    },
    {
      "x": -6,
      "y": 3,
      "z": 3,
      "name": "Rock_Marble_Brick_Pillar_Middle"
    },
    {
      "x": -6,
      "y": 4,
      "z": 3,
      "name": "Rock_Marble_Brick_Pillar_Middle"
    },
    {
      "x": -6,
      "y": 5,
      "z": 3,
      "name": "Rock_Marble_Brick_Pillar_Base",
      "rotation": 11
    },
    {
      "x": -6,
      "y": 6,
      "z": 3,
      "name": "Rock_Marble_Brick_Ornate"
    },
    {
      "x": -6,
      "y": 7,
      "z": 3,
      "name": "Rock_Marble_Brick_Decorative",
      "rotation": 3
    },
    {
      "x": -6,
      "y": 8,
      "z": 3,
      "name": "Rock_Marble_Brick_Pillar_Base"
    },
    {
      "x": -6,
      "y": 9,
      "z": 3,
      "name": "Rock_Marble_Brick_Pillar_Middle"
    },
    {
      "x": -6,
      "y": 10,
      "z": 3,
      "name": "Rock_Marble_Brick_Pillar_Middle"
    },
    {
      "x": -6,
      "y": 11,
      "z": 3,
      "name": "Rock_Marble_Brick_Pillar_Middle"
    },
    {
      "x": -6,
      "y": 12,
      "z": 3,
      "name": "Rock_Marble_Brick_Pillar_Base",
      "rotation": 33
    },
    {
      "x": -6,
      "y": 13,
      "z": 3,
      "name": "Rock_Marble_Brick_Ornate"
    },
    {
      "x": -6,
      "y": 14,
      "z": 3,
      "name": "Rock_Marble_Brick_Decorative",
      "rotation": 3
    },
    {
      "x": -6,
      "y": 15,
      "z": 3,
      "name": "Rock_Marble_Brick_Pillar_Base"
    },
    {
      "x": -6,
      "y": 16,
      "z": 3,
      "name": "Rock_Marble_Brick_Pillar_Middle"
    },
    {
      "x": -6,
      "y": 17,
      "z": 3,
      "name": "Rock_Marble_Brick_Pillar_Middle"
    },
    {
      "x": -6,
      "y": 18,
      "z": 3,
      "name": "Rock_Marble_Brick_Pillar_Middle"
    },
    {
      "x": -6,
      "y": 19,
      "z": 3,
      "name": "Rock_Marble_Brick_Pillar_Base",
      "rotation": 33
    },
    {
      "x": -6,
      "y": 20,
      "z": 3,
      "name": "Rock_Marble_Brick_Ornate"
    },
    {
      "x": -6,
      "y": 21,
      "z": 3,
      "name": "Rock_Marble_Brick_Decorative",
      "rotation": 3
    },
    {
      "x": -6,
      "y": 22,
      "z": 3,
      "name": "Rock_Marble_Brick_Pillar_Base"
    },
    {
      "x": -6,
      "y": 23,
      "z": 3,
      "name": "Rock_Marble_Brick_Pillar_Middle"
    },
    {
      "x": -6,
      "y": 24,
      "z": 3,
      "name": "Rock_Marble_Brick_Pillar_Middle"
    },
    {
      "x": -6,
      "y": 25,
      "z": 3,
      "name": "Rock_Marble_Brick_Pillar_Middle"
    },
    {
      "x": -6,
      "y": 26,
      "z": 3,
      "name": "Rock_Marble_Brick_Pillar_Base",
      "rotation": 33
    },
    {
      "x": -6,
      "y": 27,
      "z": 3,
      "name": "Rock_Marble_Brick_Ornate"
    },
    {
      "x": -6,
      "y": 28,
      "z": 3,
      "name": "Rock_Marble_Brick_Decorative",
      "rotation": 3
    },
    {
      "x": -6,
      "y": 29,
      "z": 3,
      "name": "Rock_Marble_Brick_Pillar_Base"
    },
    {
      "x": -6,
      "y": 30,
      "z": 3,
      "name": "Rock_Marble_Brick_Pillar_Middle"
    },
    {
      "x": -6,
      "y": 31,
      "z": 3,
      "name": "Rock_Marble_Brick_Pillar_Middle"
    },
    {
      "x": -6,
      "y": 32,
      "z": 3,
      "name": "Rock_Marble_Brick_Pillar_Middle"
    },
    {
      "x": -6,
      "y": 33,
      "z": 3,
      "name": "Rock_Marble_Brick_Pillar_Base",
      "rotation": 33
    },
    {
      "x": -6,
      "y": 34,
      "z": 3,
      "name": "Rock_Marble_Brick_Ornate"
    },
    {
      "x": -6,
      "y": 35,
      "z": 3,
      "name": "Rock_Marble_Brick_Decorative",
      "rotation": 3
    },
    {
      "x": -6,
      "y": 36,
      "z": 3,
      "name": "Rock_Marble_Brick_Pillar_Base"
    },
    {
      "x": -6,
      "y": 37,
      "z": 3,
      "name": "Rock_Marble_Brick_Pillar_Middle"
    },
    {
      "x": -6,
      "y": 38,
      "z": 3,
      "name": "Rock_Marble_Brick_Pillar_Middle"
    },
    {
      "x": -6,
      "y": 39,
      "z": 3,
      "name": "Rock_Marble_Brick_Pillar_Middle"
    },
    {
      "x": -6,
      "y": 40,
      "z": 3,
      "name": "Rock_Marble_Brick_Pillar_Base",
      "rotation": 33
    },
    {
      "x": -6,
      "y": 41,
      "z": 3,
      "name": "Rock_Marble_Brick_Ornate"
    },
    {
      "x": -6,
      "y": 42,
      "z": 3,
      "name": "Rock_Marble_Brick_Pillar_Base"
    },
    {
      "x": -6,
      "y": 43,
      "z": 3,
      "name": "Rock_Marble_Brick_Pillar_Middle"
    },
    {
      "x": -6,
      "y": 44,
      "z": 3,
      "name": "Rock_Marble_Brick_Pillar_Middle"
    },
    {
      "x": -6,
      "y": 45,
      "z": 3,
      "name": "Rock_Marble_Brick_Pillar_Middle"
    },
    {
      "x": -6,
      "y": 46,
      "z": 3,
      "name": "Rock_Marble_Brick_Pillar_Base",
      "rotation": 8
    },
    {
      "x": -6,
      "y": 47,
      "z": 3,
      "name": "Rock_Marble_Brick"
    },
    {
      "x": -5,
      "y": -4,
      "z": -6,
      "name": "Rock_Marble_Brick"
    },
    {
      "x": -5,
      "y": -3,
      "z": -6,
      "name": "Rock_Marble_Brick"
    },
    {
      "x": -5,
      "y": -2,
      "z": -6,
      "name": "Rock_Marble_Brick"
    },
    {
      "x": -5,
      "y": -1,
      "z": -6,
      "name": "Rock_Marble_Brick"
    },
    {
      "x": -5,
      "y": 0,
      "z": -6,
      "name": "Rock_Marble_Brick_Decorative",
      "rotation": 2
    },
    {
      "x": -5,
      "y": 1,
      "z": -6,
      "name": "Rock_Marble_Brick_Smooth_Half",
      "rotation": 10
    },
    {
      "x": -5,
      "y": 5,
      "z": -6,
      "name": "Rock_Marble_Brick_Smooth_Half",
      "rotation": 10
    },
    {
      "x": -5,
      "y": 6,
      "z": -6,
      "name": "Rock_Marble_Brick_Decorative",
      "rotation": 3
    },
    {
      "x": -5,
      "y": 7,
      "z": -6,
      "name": "Rock_Marble_Brick_Decorative",
      "rotation": 2
    },
    {
      "x": -5,
      "y": 8,
      "z": -6,
      "name": "Rock_Marble_Brick_Smooth_Half",
      "rotation": 32
    },
    {
      "x": -5,
      "y": 12,
      "z": -6,
      "name": "Rock_Marble_Brick_Smooth_Half",
      "rotation": 32
    },
    {
      "x": -5,
      "y": 13,
      "z": -6,
      "name": "Rock_Marble_Brick_Decorative",
      "rotation": 3
    },
    {
      "x": -5,
      "y": 14,
      "z": -6,
      "name": "Rock_Marble_Brick_Decorative",
      "rotation": 2
    },
    {
      "x": -5,
      "y": 15,
      "z": -6,
      "name": "Rock_Marble_Brick_Smooth_Half",
      "rotation": 32
    },
    {
      "x": -5,
      "y": 19,
      "z": -6,
      "name": "Rock_Marble_Brick_Smooth_Half",
      "rotation": 32
    },
    {
      "x": -5,
      "y": 20,
      "z": -6,
      "name": "Rock_Marble_Brick_Decorative",
      "rotation": 3
    },
    {
      "x": -5,
      "y": 21,
      "z": -6,
      "name": "Rock_Marble_Brick_Decorative",
      "rotation": 2
    },
    {
      "x": -5,
      "y": 22,
      "z": -6,
      "name": "Rock_Marble_Brick_Smooth_Half",
      "rotation": 32
    },
    {
      "x": -5,
      "y": 26,
      "z": -6,
      "name": "Rock_Marble_Brick_Smooth_Half",
      "rotation": 32
    },
    {
      "x": -5,
      "y": 27,
      "z": -6,
      "name": "Rock_Marble_Brick_Decorative",
      "rotation": 3
    },
    {
      "x": -5,
      "y": 28,
      "z": -6,
      "name": "Rock_Marble_Brick_Decorative",
      "rotation": 2
    },
    {
      "x": -5,
      "y": 29,
      "z": -6,
      "name": "Rock_Marble_Brick_Smooth_Half",
      "rotation": 32
    },
    {
      "x": -5,
      "y": 33,
      "z": -6,
      "name": "Rock_Marble_Brick_Smooth_Half",
      "rotation": 32
    },
    {
      "x": -5,
      "y": 34,
      "z": -6,
      "name": "Rock_Marble_Brick_Decorative",
      "rotation": 3
    },
    {
      "x": -5,
      "y": 35,
      "z": -6,
      "name": "Rock_Marble_Brick_Decorative",
      "rotation": 2
    },
    {
      "x": -5,
      "y": 36,
      "z": -6,
      "name": "Rock_Marble_Brick_Smooth_Half",
      "rotation": 32
    },
    {
      "x": -5,
      "y": 40,
      "z": -6,
      "name": "Rock_Marble_Brick_Smooth_Half",
      "rotation": 32
    },
    {
      "x": -5,
      "y": 41,
      "z": -6,
      "name": "Rock_Marble_Brick_Decorative",
      "rotation": 3
    },
    {
      "x": -5,
      "y": 47,
      "z": -6,
      "name": "Rock_Marble_SkyGrass"
    },
    {
      "x": -5,
      "y": -4,
      "z": -5,
      "name": "Rock_Marble_Brick"
    },
    {
      "x": -5,
      "y": -3,
      "z": -5,
      "name": "Rock_Marble_Brick"
    },
    {
      "x": -5,
      "y": -2,
      "z": -5,
      "name": "Rock_Marble_Brick"
    },
    {
      "x": -5,
      "y": -1,
      "z": -5,
      "name": "Rock_Marble_Brick"
    },
    {
      "x": -5,
      "y": 0,
      "z": -5,
      "name": "Rock_Marble_Brick",
      "rotation": 2
    },
    {
      "x": -5,
      "y": 1,
      "z": -5,
      "name": "Rock_Marble_Brick_Stairs",
      "rotation": 8
    },
    {
      "x": -5,
      "y": 5,
      "z": -5,
      "name": "Rock_Marble_Brick_Stairs",
      "rotation": 8
    },
    {
      "x": -5,
      "y": 6,
      "z": -5,
      "name": "Rock_Marble_Brick"
    },
    {
      "x": -5,
      "y": 7,
      "z": -5,
      "name": "Rock_Marble_Brick",
      "rotation": 2
    },
    {
      "x": -5,
      "y": 8,
      "z": -5,
      "name": "Rock_Marble_Brick_Stairs",
      "rotation": 34
    },
    {
      "x": -5,
      "y": 12,
      "z": -5,
      "name": "Rock_Marble_Brick_Stairs",
      "rotation": 34
    },
    {
      "x": -5,
      "y": 13,
      "z": -5,
      "name": "Rock_Marble_Brick_Smooth",
      "rotation": 2
    },
    {
      "x": -5,
      "y": 14,
      "z": -5,
      "name": "Rock_Marble_Brick",
      "rotation": 2
    },
    {
      "x": -5,
      "y": 15,
      "z": -5,
      "name": "Rock_Marble_Brick_Stairs",
      "rotation": 34
    },
    {
      "x": -5,
      "y": 19,
      "z": -5,
      "name": "Rock_Marble_Brick_Stairs",
      "rotation": 34
    },
    {
      "x": -5,
      "y": 20,
      "z": -5,
      "name": "Rock_Marble_Brick"
    },
    {
      "x": -5,
      "y": 21,
      "z": -5,
      "name": "Rock_Marble_Brick",
      "rotation": 2
    },
    {
      "x": -5,
      "y": 22,
      "z": -5,
      "name": "Rock_Marble_Brick_Stairs",
      "rotation": 34
    },
    {
      "x": -5,
      "y": 26,
      "z": -5,
      "name": "Rock_Marble_Brick_Stairs",
      "rotation": 34
    },
    {
      "x": -5,
      "y": 27,
      "z": -5,
      "name": "Rock_Marble_Brick_Smooth",
      "rotation": 2
    },
    {
      "x": -5,
      "y": 28,
      "z": -5,
      "name": "Rock_Marble_Brick",
      "rotation": 2
    },
    {
      "x": -5,
      "y": 29,
      "z": -5,
      "name": "Rock_Marble_Brick_Stairs",
      "rotation": 34
    },
    {
      "x": -5,
      "y": 33,
      "z": -5,
      "name": "Rock_Marble_Brick_Stairs",
      "rotation": 34
    },
    {
      "x": -5,
      "y": 34,
      "z": -5,
      "name": "Rock_Marble_Brick"
    },
    {
      "x": -5,
      "y": 35,
      "z": -5,
      "name": "Rock_Marble_Brick",
      "rotation": 2
    },
    {
      "x": -5,
      "y": 36,
      "z": -5,
      "name": "Rock_Marble_Brick_Stairs",
      "rotation": 34
    },
    {
      "x": -5,
      "y": 40,
      "z": -5,
      "name": "Rock_Marble_Brick_Stairs",
      "rotation": 34
    },
    {
      "x": -5,
      "y": 41,
      "z": -5,
      "name": "Rock_Marble_Brick_Smooth",
      "rotation": 2
    },
    {
      "x": -5,
      "y": 42,
      "z": -5,
      "name": "Rock_Marble_Brick_Smooth_Half",
      "rotation": 8
    },
    {
      "x": -5,
      "y": 47,
      "z": -5,
      "name": "Rock_Marble_SkyGrass"
    },
    {
      "x": -5,
      "y": 48,
      "z": -5,
      "name": "Plant_Bush_Sky",
      "support": 15
    },
    {
      "x": -5,
      "y": -4,
      "z": -4,
      "name": "Rock_Marble_Brick"
    },
    {
      "x": -5,
      "y": -3,
      "z": -4,
      "name": "Rock_Marble_Brick"
    },
    {
      "x": -5,
      "y": -2,
      "z": -4,
      "name": "Rock_Marble_Brick"
    },
    {
      "x": -5,
      "y": -1,
      "z": -4,
      "name": "Rock_Marble_Brick"
    },
    {
      "x": -5,
      "y": 0,
      "z": -4,
      "name": "Rock_Marble_Brick",
      "rotation": 2
    },
    {
      "x": -5,
      "y": 1,
      "z": -4,
      "name": "Rock_Marble_Brick",
      "rotation": 2
    },
    {
      "x": -5,
      "y": 2,
      "z": -4,
      "name": "Rock_Marble_Brick",
      "rotation": 2
    },
    {
      "x": -5,
      "y": 3,
      "z": -4,
      "name": "Rock_Marble_Brick",
      "rotation": 2
    },
    {
      "x": -5,
      "y": 4,
      "z": -4,
      "name": "Rock_Marble_Brick",
      "rotation": 2
    },
    {
      "x": -5,
      "y": 5,
      "z": -4,
      "name": "Rock_Marble_Brick",
      "rotation": 3
    },
    {
      "x": -5,
      "y": 6,
      "z": -4,
      "name": "Rock_Marble_Brick"
    },
    {
      "x": -5,
      "y": 7,
      "z": -4,
      "name": "Rock_Marble_Brick",
      "rotation": 2
    },
    {
      "x": -5,
      "y": 8,
      "z": -4,
      "name": "Rock_Marble_Brick",
      "rotation": 2
    },
    {
      "x": -5,
      "y": 9,
      "z": -4,
      "name": "Rock_Marble_Brick",
      "rotation": 2
    },
    {
      "x": -5,
      "y": 10,
      "z": -4,
      "name": "Rock_Marble_Brick",
      "rotation": 2
    },
    {
      "x": -5,
      "y": 11,
      "z": -4,
      "name": "Rock_Marble_Brick",
      "rotation": 2
    },
    {
      "x": -5,
      "y": 12,
      "z": -4,
      "name": "Rock_Marble_Brick",
      "rotation": 3
    },
    {
      "x": -5,
      "y": 13,
      "z": -4,
      "name": "Rock_Marble_Brick",
      "rotation": 2
    },
    {
      "x": -5,
      "y": 14,
      "z": -4,
      "name": "Rock_Marble_Brick",
      "rotation": 2
    },
    {
      "x": -5,
      "y": 15,
      "z": -4,
      "name": "Rock_Marble_Brick",
      "rotation": 2
    },
    {
      "x": -5,
      "y": 16,
      "z": -4,
      "name": "Rock_Marble_Brick",
      "rotation": 2
    },
    {
      "x": -5,
      "y": 17,
      "z": -4,
      "name": "Rock_Marble_Brick",
      "rotation": 2
    },
    {
      "x": -5,
      "y": 18,
      "z": -4,
      "name": "Rock_Marble_Brick",
      "rotation": 2
    },
    {
      "x": -5,
      "y": 19,
      "z": -4,
      "name": "Rock_Marble_Brick",
      "rotation": 3
    },
    {
      "x": -5,
      "y": 20,
      "z": -4,
      "name": "Rock_Marble_Brick"
    },
    {
      "x": -5,
      "y": 21,
      "z": -4,
      "name": "Rock_Marble_Brick",
      "rotation": 2
    },
    {
      "x": -5,
      "y": 22,
      "z": -4,
      "name": "Rock_Marble_Brick",
      "rotation": 2
    },
    {
      "x": -5,
      "y": 23,
      "z": -4,
      "name": "Rock_Marble_Brick",
      "rotation": 2
    },
    {
      "x": -5,
      "y": 24,
      "z": -4,
      "name": "Rock_Marble_Brick",
      "rotation": 2
    },
    {
      "x": -5,
      "y": 25,
      "z": -4,
      "name": "Rock_Marble_Brick",
      "rotation": 2
    },
    {
      "x": -5,
      "y": 26,
      "z": -4,
      "name": "Rock_Marble_Brick",
      "rotation": 3
    },
    {
      "x": -5,
      "y": 27,
      "z": -4,
      "name": "Rock_Marble_Brick",
      "rotation": 2
    },
    {
      "x": -5,
      "y": 28,
      "z": -4,
      "name": "Rock_Marble_Brick",
      "rotation": 2
    },
    {
      "x": -5,
      "y": 29,
      "z": -4,
      "name": "Rock_Marble_Brick",
      "rotation": 2
    },
    {
      "x": -5,
      "y": 30,
      "z": -4,
      "name": "Rock_Marble_Brick",
      "rotation": 2
    },
    {
      "x": -5,
      "y": 31,
      "z": -4,
      "name": "Rock_Marble_Brick",
      "rotation": 2
    },
    {
      "x": -5,
      "y": 32,
      "z": -4,
      "name": "Rock_Marble_Brick",
      "rotation": 2
    },
    {
      "x": -5,
      "y": 33,
      "z": -4,
      "name": "Rock_Marble_Brick",
      "rotation": 3
    },
    {
      "x": -5,
      "y": 34,
      "z": -4,
      "name": "Rock_Marble_Brick"
    },
    {
      "x": -5,
      "y": 35,
      "z": -4,
      "name": "Rock_Marble_Brick",
      "rotation": 2
    },
    {
      "x": -5,
      "y": 36,
      "z": -4,
      "name": "Rock_Marble_Brick",
      "rotation": 2
    },
    {
      "x": -5,
      "y": 37,
      "z": -4,
      "name": "Rock_Marble_Brick",
      "rotation": 2
    },
    {
      "x": -5,
      "y": 38,
      "z": -4,
      "name": "Rock_Marble_Brick",
      "rotation": 2
    },
    {
      "x": -5,
      "y": 39,
      "z": -4,
      "name": "Rock_Marble_Brick",
      "rotation": 2
    },
    {
      "x": -5,
      "y": 40,
      "z": -4,
      "name": "Rock_Marble_Brick",
      "rotation": 3
    },
    {
      "x": -5,
      "y": 41,
      "z": -4,
      "name": "Rock_Marble_Brick",
      "rotation": 2
    },
    {
      "x": -5,
      "y": 47,
      "z": -4,
      "name": "Rock_Marble_SkyGrass"
    },
    {
      "x": -5,
      "y": 48,
      "z": -4,
      "name": "Plant_Bush_Sky",
      "support": 15
    },
    {
      "x": -5,
      "y": -4,
      "z": -3,
      "name": "Rock_Marble_Brick"
    },
    {
      "x": -5,
      "y": -3,
      "z": -3,
      "name": "Rock_Marble_Brick"
    },
    {
      "x": -5,
      "y": -2,
      "z": -3,
      "name": "Rock_Marble_Brick"
    },
    {
      "x": -5,
      "y": -1,
      "z": -3,
      "name": "Rock_Marble_Brick"
    },
    {
      "x": -5,
      "y": 0,
      "z": -3,
      "name": "Rock_Marble_Brick"
    },
    {
      "x": -5,
      "y": 1,
      "z": -3,
      "name": "Furniture_Temple_Light_Pot"
    },
    {
      "x": -5,
      "y": 6,
      "z": -3,
      "name": "Rock_Marble_Brick"
    },
    {
      "x": -5,
      "y": 7,
      "z": -3,
      "name": "Rock_Marble_Brick",
      "rotation": 2
    },
    {
      "x": -5,
      "y": 13,
      "z": -3,
      "name": "Rock_Marble_Brick",
      "rotation": 2
    },
    {
      "x": -5,
      "y": 14,
      "z": -3,
      "name": "Rock_Marble_Brick"
    },
    {
      "x": -5,
      "y": 20,
      "z": -3,
      "name": "Rock_Marble_Brick"
    },
    {
      "x": -5,
      "y": 21,
      "z": -3,
      "name": "Rock_Marble_Brick",
      "rotation": 2
    },
    {
      "x": -5,
      "y": 27,
      "z": -3,
      "name": "Rock_Marble_Brick",
      "rotation": 2
    },
    {
      "x": -5,
      "y": 28,
      "z": -3,
      "name": "Rock_Marble_Brick"
    },
    {
      "x": -5,
      "y": 34,
      "z": -3,
      "name": "Rock_Marble_Brick"
    },
    {
      "x": -5,
      "y": 35,
      "z": -3,
      "name": "Rock_Marble_Brick",
      "rotation": 2
    },
    {
      "x": -5,
      "y": 41,
      "z": -3,
      "name": "Rock_Marble_Brick",
      "rotation": 2
    },
    {
      "x": -5,
      "y": 42,
      "z": -3,
      "name": "Furniture_Temple_Light_Pot"
    },
    {
      "x": -5,
      "y": -4,
      "z": -2,
      "name": "Rock_Marble_Brick"
    },
    {
      "x": -5,
      "y": -3,
      "z": -2,
      "name": "Rock_Marble_Brick"
    },
    {
      "x": -5,
      "y": -2,
      "z": -2,
      "name": "Rock_Marble_Brick"
    },
    {
      "x": -5,
      "y": -1,
      "z": -2,
      "name": "Rock_Marble_Brick"
    },
    {
      "x": -5,
      "y": 0,
      "z": -2,
      "name": "Rock_Marble_Brick"
    },
    {
      "x": -5,
      "y": 1,
      "z": -2,
      "name": "Furniture_Temple_Light_Pot"
    },
    {
      "x": -5,
      "y": 6,
      "z": -2,
      "name": "Rock_Marble_Brick"
    },
    {
      "x": -5,
      "y": 7,
      "z": -2,
      "name": "Rock_Marble_Brick",
      "rotation": 2
    },
    {
      "x": -5,
      "y": 8,
      "z": -2,
      "name": "Furniture_Temple_Light_Pot"
    },
    {
      "x": -5,
      "y": 13,
      "z": -2,
      "name": "Rock_Marble_Brick",
      "rotation": 2
    },
    {
      "x": -5,
      "y": 14,
      "z": -2,
      "name": "Rock_Marble_Brick"
    },
    {
      "x": -5,
      "y": 20,
      "z": -2,
      "name": "Rock_Marble_Brick"
    },
    {
      "x": -5,
      "y": 21,
      "z": -2,
      "name": "Rock_Marble_Brick",
      "rotation": 2
    },
    {
      "x": -5,
      "y": 27,
      "z": -2,
      "name": "Rock_Marble_Brick",
      "rotation": 2
    },
    {
      "x": -5,
      "y": 28,
      "z": -2,
      "name": "Rock_Marble_SkyGrass"
    },
    {
      "x": -5,
      "y": 34,
      "z": -2,
      "name": "Rock_Marble_Brick"
    },
    {
      "x": -5,
      "y": 35,
      "z": -2,
      "name": "Rock_Marble_SkyGrass"
    },
    {
      "x": -5,
      "y": 36,
      "z": -2,
      "name": "Plant_Bush_Sky"
    },
    {
      "x": -5,
      "y": 37,
      "z": -2,
      "name": "Plant_Bush_Sky",
      "support": 15
    },
    {
      "x": -5,
      "y": 41,
      "z": -2,
      "name": "Rock_Marble_Brick",
      "rotation": 2
    },
    {
      "x": -5,
      "y": -4,
      "z": -1,
      "name": "Rock_Marble_Brick"
    },
    {
      "x": -5,
      "y": -3,
      "z": -1,
      "name": "Rock_Marble_Brick"
    },
    {
      "x": -5,
      "y": -2,
      "z": -1,
      "name": "Rock_Marble_Brick"
    },
    {
      "x": -5,
      "y": -1,
      "z": -1,
      "name": "Rock_Marble_Brick"
    },
    {
      "x": -5,
      "y": 0,
      "z": -1,
      "name": "Rock_Marble_Brick"
    },
    {
      "x": -5,
      "y": 1,
      "z": -1,
      "name": "Furniture_Temple_Light_Pot"
    },
    {
      "x": -5,
      "y": 5,
      "z": -1,
      "name": "Wood_Torch_Wall",
      "rotation": 1
    },
    {
      "x": -5,
      "y": 6,
      "z": -1,
      "name": "Rock_Marble_Brick"
    },
    {
      "x": -5,
      "y": 7,
      "z": -1,
      "name": "Rock_Marble_Brick",
      "rotation": 2
    },
    {
      "x": -5,
      "y": 12,
      "z": -1,
      "name": "Wood_Torch_Wall",
      "rotation": 1
    },
    {
      "x": -5,
      "y": 13,
      "z": -1,
      "name": "Rock_Marble_Brick",
      "rotation": 2
    },
    {
      "x": -5,
      "y": 14,
      "z": -1,
      "name": "Rock_Marble_Brick"
    },
    {
      "x": -5,
      "y": 15,
      "z": -1,
      "name": "Furniture_Temple_Light_Chest_Small",
      "components": {
        "Components": {
          "PlacedByInteraction": {
            "WhoPlacedUuid": {
              "$binary": "rmwkrpH8RVykTc7XnK4YBA==",
              "$type": "04"
            }
          },
          "ItemContainerBlock": {
            "ItemContainer": {
              "Capacity": 18,
              "Items": {}
            },
            "Capacity": 18
          }
        }
      },
      "rotation": 1
    },
    {
      "x": -5,
      "y": 19,
      "z": -1,
      "name": "Wood_Torch_Wall",
      "rotation": 1
    },
    {
      "x": -5,
      "y": 20,
      "z": -1,
      "name": "Rock_Marble_Brick"
    },
    {
      "x": -5,
      "y": 21,
      "z": -1,
      "name": "Rock_Marble_Brick",
      "rotation": 2
    },
    {
      "x": -5,
      "y": 26,
      "z": -1,
      "name": "Wood_Torch_Wall",
      "rotation": 1
    },
    {
      "x": -5,
      "y": 27,
      "z": -1,
      "name": "Rock_Marble_Brick",
      "rotation": 2
    },
    {
      "x": -5,
      "y": 28,
      "z": -1,
      "name": "Rock_Marble_Brick"
    },
    {
      "x": -5,
      "y": 33,
      "z": -1,
      "name": "Wood_Torch_Wall",
      "rotation": 1
    },
    {
      "x": -5,
      "y": 34,
      "z": -1,
      "name": "Rock_Marble_Brick"
    },
    {
      "x": -5,
      "y": 35,
      "z": -1,
      "name": "Rock_Marble_SkyGrass"
    },
    {
      "x": -5,
      "y": 36,
      "z": -1,
      "name": "Plant_Grass_Sky",
      "support": 15
    },
    {
      "x": -5,
      "y": 40,
      "z": -1,
      "name": "Wood_Torch_Wall",
      "rotation": 1
    },
    {
      "x": -5,
      "y": 41,
      "z": -1,
      "name": "Rock_Marble_Brick",
      "rotation": 2
    },
    {
      "x": -5,
      "y": -4,
      "z": 0,
      "name": "Rock_Marble_Brick"
    },
    {
      "x": -5,
      "y": -3,
      "z": 0,
      "name": "Rock_Marble_Brick"
    },
    {
      "x": -5,
      "y": -2,
      "z": 0,
      "name": "Rock_Marble_Brick"
    },
    {
      "x": -5,
      "y": -1,
      "z": 0,
      "name": "Rock_Marble_Brick"
    },
    {
      "x": -5,
      "y": 0,
      "z": 0,
      "name": "Rock_Marble_Brick"
    },
    {
      "x": -5,
      "y": 6,
      "z": 0,
      "name": "Rock_Marble_Brick"
    },
    {
      "x": -5,
      "y": 7,
      "z": 0,
      "name": "Rock_Marble_Brick",
      "rotation": 2
    },
    {
      "x": -5,
      "y": 13,
      "z": 0,
      "name": "Rock_Marble_Brick",
      "rotation": 2
    },
    {
      "x": -5,
      "y": 14,
      "z": 0,
      "name": "Rock_Marble_Brick"
    },
    {
      "x": -5,
      "y": 20,
      "z": 0,
      "name": "Rock_Marble_Brick"
    },
    {
      "x": -5,
      "y": 21,
      "z": 0,
      "name": "Rock_Marble_Brick",
      "rotation": 2
    },
    {
      "x": -5,
      "y": 27,
      "z": 0,
      "name": "Rock_Marble_Brick",
      "rotation": 2
    },
    {
      "x": -5,
      "y": 28,
      "z": 0,
      "name": "Rock_Marble_Brick"
    },
    {
      "x": -5,
      "y": 34,
      "z": 0,
      "name": "Rock_Marble_Brick"
    },
    {
      "x": -5,
      "y": 35,
      "z": 0,
      "name": "Rock_Marble_SkyGrass"
    },
    {
      "x": -5,
      "y": 36,
      "z": 0,
      "name": "Plant_Bush_Sky",
      "support": 15
    },
    {
      "x": -5,
      "y": 41,
      "z": 0,
      "name": "Rock_Marble_Brick"
    },
    {
      "x": -5,
      "y": -4,
      "z": 1,
      "name": "Rock_Marble_Brick"
    },
    {
      "x": -5,
      "y": -3,
      "z": 1,
      "name": "Rock_Marble_Brick"
    },
    {
      "x": -5,
      "y": -2,
      "z": 1,
      "name": "Rock_Marble_Brick"
    },
    {
      "x": -5,
      "y": -1,
      "z": 1,
      "name": "Rock_Marble_Brick"
    },
    {
      "x": -5,
      "y": 0,
      "z": 1,
      "name": "Rock_Marble_Brick"
    },
    {
      "x": -5,
      "y": 6,
      "z": 1,
      "name": "Rock_Marble_Brick"
    },
    {
      "x": -5,
      "y": 7,
      "z": 1,
      "name": "Rock_Marble_Brick",
      "rotation": 2
    },
    {
      "x": -5,
      "y": 13,
      "z": 1,
      "name": "Rock_Marble_Brick",
      "rotation": 2
    },
    {
      "x": -5,
      "y": 14,
      "z": 1,
      "name": "Rock_Marble_Brick"
    },
    {
      "x": -5,
      "y": 15,
      "z": 1,
      "name": "Furniture_Temple_Light_Pot"
    },
    {
      "x": -5,
      "y": 20,
      "z": 1,
      "name": "Rock_Marble_Brick"
    },
    {
      "x": -5,
      "y": 21,
      "z": 1,
      "name": "Rock_Marble_Brick",
      "rotation": 2
    },
    {
      "x": -5,
      "y": 27,
      "z": 1,
      "name": "Rock_Marble_Brick",
      "rotation": 2
    },
    {
      "x": -5,
      "y": 28,
      "z": 1,
      "name": "Rock_Marble_Brick"
    },
    {
      "x": -5,
      "y": 34,
      "z": 1,
      "name": "Rock_Marble_Brick"
    },
    {
      "x": -5,
      "y": 35,
      "z": 1,
      "name": "Rock_Marble_Brick",
      "rotation": 2
    },
    {
      "x": -5,
      "y": 41,
      "z": 1,
      "name": "Rock_Marble_Brick",
      "rotation": 2
    },
    {
      "x": -5,
      "y": -4,
      "z": 2,
      "name": "Rock_Marble_Brick"
    },
    {
      "x": -5,
      "y": -3,
      "z": 2,
      "name": "Rock_Marble_Brick"
    },
    {
      "x": -5,
      "y": -2,
      "z": 2,
      "name": "Rock_Marble_Brick"
    },
    {
      "x": -5,
      "y": -1,
      "z": 2,
      "name": "Rock_Marble_Brick"
    },
    {
      "x": -5,
      "y": 0,
      "z": 2,
      "name": "Rock_Marble_Brick",
      "rotation": 3
    },
    {
      "x": -5,
      "y": 1,
      "z": 2,
      "name": "Rock_Marble_Brick",
      "rotation": 3
    },
    {
      "x": -5,
      "y": 2,
      "z": 2,
      "name": "Rock_Marble_Brick",
      "rotation": 3
    },
    {
      "x": -5,
      "y": 3,
      "z": 2,
      "name": "Rock_Marble_Brick",
      "rotation": 3
    },
    {
      "x": -5,
      "y": 4,
      "z": 2,
      "name": "Rock_Marble_Brick",
      "rotation": 3
    },
    {
      "x": -5,
      "y": 5,
      "z": 2,
      "name": "Rock_Marble_Brick"
    },
    {
      "x": -5,
      "y": 6,
      "z": 2,
      "name": "Rock_Marble_Brick"
    },
    {
      "x": -5,
      "y": 7,
      "z": 2,
      "name": "Rock_Marble_Brick",
      "rotation": 3
    },
    {
      "x": -5,
      "y": 8,
      "z": 2,
      "name": "Rock_Marble_Brick",
      "rotation": 3
    },
    {
      "x": -5,
      "y": 9,
      "z": 2,
      "name": "Rock_Marble_Brick",
      "rotation": 3
    },
    {
      "x": -5,
      "y": 10,
      "z": 2,
      "name": "Rock_Marble_Brick",
      "rotation": 3
    },
    {
      "x": -5,
      "y": 11,
      "z": 2,
      "name": "Rock_Marble_Brick",
      "rotation": 3
    },
    {
      "x": -5,
      "y": 12,
      "z": 2,
      "name": "Rock_Marble_Brick"
    },
    {
      "x": -5,
      "y": 13,
      "z": 2,
      "name": "Rock_Marble_Brick",
      "rotation": 2
    },
    {
      "x": -5,
      "y": 14,
      "z": 2,
      "name": "Rock_Marble_Brick",
      "rotation": 3
    },
    {
      "x": -5,
      "y": 15,
      "z": 2,
      "name": "Rock_Marble_Brick",
      "rotation": 3
    },
    {
      "x": -5,
      "y": 16,
      "z": 2,
      "name": "Rock_Marble_Brick",
      "rotation": 3
    },
    {
      "x": -5,
      "y": 17,
      "z": 2,
      "name": "Rock_Marble_Brick",
      "rotation": 3
    },
    {
      "x": -5,
      "y": 18,
      "z": 2,
      "name": "Rock_Marble_Brick",
      "rotation": 3
    },
    {
      "x": -5,
      "y": 19,
      "z": 2,
      "name": "Rock_Marble_Brick"
    },
    {
      "x": -5,
      "y": 20,
      "z": 2,
      "name": "Rock_Marble_Brick"
    },
    {
      "x": -5,
      "y": 21,
      "z": 2,
      "name": "Rock_Marble_Brick",
      "rotation": 3
    },
    {
      "x": -5,
      "y": 22,
      "z": 2,
      "name": "Rock_Marble_Brick",
      "rotation": 3
    },
    {
      "x": -5,
      "y": 23,
      "z": 2,
      "name": "Rock_Marble_Brick",
      "rotation": 3
    },
    {
      "x": -5,
      "y": 24,
      "z": 2,
      "name": "Rock_Marble_Brick",
      "rotation": 3
    },
    {
      "x": -5,
      "y": 25,
      "z": 2,
      "name": "Rock_Marble_Brick",
      "rotation": 3
    },
    {
      "x": -5,
      "y": 26,
      "z": 2,
      "name": "Rock_Marble_Brick"
    },
    {
      "x": -5,
      "y": 27,
      "z": 2,
      "name": "Rock_Marble_Brick",
      "rotation": 2
    },
    {
      "x": -5,
      "y": 28,
      "z": 2,
      "name": "Rock_Marble_Brick",
      "rotation": 3
    },
    {
      "x": -5,
      "y": 29,
      "z": 2,
      "name": "Rock_Marble_Brick",
      "rotation": 3
    },
    {
      "x": -5,
      "y": 30,
      "z": 2,
      "name": "Rock_Marble_Brick",
      "rotation": 3
    },
    {
      "x": -5,
      "y": 31,
      "z": 2,
      "name": "Rock_Marble_Brick",
      "rotation": 3
    },
    {
      "x": -5,
      "y": 32,
      "z": 2,
      "name": "Rock_Marble_Brick",
      "rotation": 3
    },
    {
      "x": -5,
      "y": 33,
      "z": 2,
      "name": "Rock_Marble_Brick"
    },
    {
      "x": -5,
      "y": 34,
      "z": 2,
      "name": "Rock_Marble_Brick"
    },
    {
      "x": -5,
      "y": 35,
      "z": 2,
      "name": "Rock_Marble_Brick",
      "rotation": 3
    },
    {
      "x": -5,
      "y": 36,
      "z": 2,
      "name": "Rock_Marble_Brick",
      "rotation": 3
    },
    {
      "x": -5,
      "y": 37,
      "z": 2,
      "name": "Rock_Marble_Brick",
      "rotation": 3
    },
    {
      "x": -5,
      "y": 38,
      "z": 2,
      "name": "Rock_Marble_Brick",
      "rotation": 3
    },
    {
      "x": -5,
      "y": 39,
      "z": 2,
      "name": "Rock_Marble_Brick",
      "rotation": 3
    },
    {
      "x": -5,
      "y": 40,
      "z": 2,
      "name": "Rock_Marble_Brick"
    },
    {
      "x": -5,
      "y": 41,
      "z": 2,
      "name": "Rock_Marble_Brick",
      "rotation": 2
    },
    {
      "x": -5,
      "y": 42,
      "z": 2,
      "name": "Furniture_Temple_Light_Pot"
    },
    {
      "x": -5,
      "y": 47,
      "z": 2,
      "name": "Rock_Marble_Brick"
    },
    {
      "x": -5,
      "y": -4,
      "z": 3,
      "name": "Rock_Marble_Brick"
    },
    {
      "x": -5,
      "y": -3,
      "z": 3,
      "name": "Rock_Marble_Brick"
    },
    {
      "x": -5,
      "y": -2,
      "z": 3,
      "name": "Rock_Marble_Brick"
    },
    {
      "x": -5,
      "y": -1,
      "z": 3,
      "name": "Rock_Marble_Brick"
    },
    {
      "x": -5,
      "y": 0,
      "z": 3,
      "name": "Rock_Marble_Brick",
      "rotation": 3
    },
    {
      "x": -5,
      "y": 1,
      "z": 3,
      "name": "Rock_Marble_Brick_Stairs",
      "rotation": 10
    },
    {
      "x": -5,
      "y": 5,
      "z": 3,
      "name": "Rock_Marble_Brick_Stairs",
      "rotation": 10
    },
    {
      "x": -5,
      "y": 6,
      "z": 3,
      "name": "Rock_Marble_Brick"
    },
    {
      "x": -5,
      "y": 7,
      "z": 3,
      "name": "Rock_Marble_Brick",
      "rotation": 3
    },
    {
      "x": -5,
      "y": 8,
      "z": 3,
      "name": "Rock_Marble_Brick_Stairs",
      "rotation": 32
    },
    {
      "x": -5,
      "y": 12,
      "z": 3,
      "name": "Rock_Marble_Brick_Stairs",
      "rotation": 32
    },
    {
      "x": -5,
      "y": 13,
      "z": 3,
      "name": "Rock_Marble_Brick_Smooth"
    },
    {
      "x": -5,
      "y": 14,
      "z": 3,
      "name": "Rock_Marble_Brick",
      "rotation": 3
    },
    {
      "x": -5,
      "y": 15,
      "z": 3,
      "name": "Rock_Marble_Brick_Stairs",
      "rotation": 32
    },
    {
      "x": -5,
