{
  "version": 8,
  "blockIdVersion": 11,
  "anchorX": 0,
  "anchorY": 19,
  "anchorZ": 0,
  "blocks": [
    {
      "x": -48,
      "y": 25,
      "z": -4,
      "name": "Cloud",
      "support": 15
    },
    {
      "x": -48,
      "y": 25,
      "z": -3,
      "name": "Cloud",
      "support": 15
    },
    {
      "x": -48,
      "y": 25,
      "z": -2,
      "name": "Cloud",
      "support": 15
    },
    {
      "x": -48,
      "y": 25,
      "z": -1,
      "name": "Cloud",
      "support": 15
    },
    {
      "x": -48,
      "y": 26,
      "z": -1,
      "name": "Cloud",
      "support": 15
    },
    {
      "x": -48,
      "y": 25,
      "z": 0,
      "name": "Cloud"
    },
    {
      "x": -48,
      "y": 26,
      "z": 0,
      "name": "Cloud"
    },
    {
      "x": -48,
      "y": 27,
      "z": 0,
      "name": "Cloud"
    },
    {
      "x": -48,
      "y": 24,
      "z": 1,
      "name": "Cloud"
    },
    {
      "x": -48,
      "y": 25,
      "z": 1,
      "name": "Cloud"
    },
    {
      "x": -48,
      "y": 26,
      "z": 1,
      "name": "Cloud"
    },
    {
      "x": -48,
      "y": 24,
      "z": 2,
      "name": "Cloud"
    },
    {
      "x": -48,
      "y": 25,
      "z": 2,
      "name": "Cloud"
    },
    {
      "x": -48,
      "y": 26,
      "z": 2,
      "name": "Cloud"
    },
    {
      "x": -48,
      "y": 24,
      "z": 3,
      "name": "Cloud"
    },
    {
      "x": -48,
      "y": 25,
      "z": 3,
      "name": "Cloud"
    },
    {
      "x": -48,
      "y": 26,
      "z": 3,
      "name": "Cloud"
    },
    {
      "x": -47,
      "y": 25,
      "z": -6,
      "name": "Cloud",
      "support": 15
    },
    {
      "x": -47,
      "y": 25,
      "z": -5,
      "name": "Cloud",
      "support": 15
    },
    {
      "x": -47,
      "y": 25,
      "z": -4,
      "name": "Cloud",
      "support": 15
    },
    {
      "x": -47,
      "y": 25,
      "z": -3,
      "name": "Cloud",
      "support": 15
    },
    {
      "x": -47,
      "y": 24,
      "z": -2,
      "name": "Cloud"
    },
    {
      "x": -47,
      "y": 25,
      "z": -2,
      "name": "Cloud"
    },
    {
      "x": -47,
      "y": 26,
      "z": -2,
      "name": "Cloud"
    },
    {
      "x": -47,
      "y": 25,
      "z": -1,
      "name": "Cloud"
    },
    {
      "x": -47,
      "y": 26,
      "z": -1,
      "name": "Cloud"
    },
    {
      "x": -47,
      "y": 27,
      "z": -1,
      "name": "Cloud"
    },
    {
      "x": -47,
      "y": 24,
      "z": 0,
      "name": "Cloud"
    },
    {
      "x": -47,
      "y": 25,
      "z": 0,
      "name": "Cloud"
    },
    {
      "x": -47,
      "y": 26,
      "z": 0,
      "name": "Cloud"
    },
    {
      "x": -47,
      "y": 27,
      "z": 0,
      "name": "Cloud"
    },
    {
      "x": -47,
      "y": 24,
      "z": 1,
      "name": "Cloud"
    },
    {
      "x": -47,
      "y": 25,
      "z": 1,
      "name": "Cloud"
    },
    {
      "x": -47,
      "y": 26,
      "z": 1,
      "name": "Cloud"
    },
    {
      "x": -47,
      "y": 27,
      "z": 1,
      "name": "Cloud"
    },
    {
      "x": -47,
      "y": 24,
      "z": 2,
      "name": "Cloud"
    },
    {
      "x": -47,
      "y": 25,
      "z": 2,
      "name": "Cloud"
    },
    {
      "x": -47,
      "y": 26,
      "z": 2,
      "name": "Cloud"
    },
    {
      "x": -47,
      "y": 24,
      "z": 3,
      "name": "Cloud"
    },
    {
      "x": -47,
      "y": 25,
      "z": 3,
      "name": "Cloud"
    },
    {
      "x": -47,
      "y": 26,
      "z": 3,
      "name": "Cloud"
    },
    {
      "x": -47,
      "y": 24,
      "z": 4,
      "name": "Cloud"
    },
    {
      "x": -47,
      "y": 25,
      "z": 4,
      "name": "Cloud"
    },
    {
      "x": -47,
      "y": 26,
      "z": 4,
      "name": "Cloud"
    },
    {
      "x": -47,
      "y": 24,
      "z": 5,
      "name": "Cloud"
    },
    {
      "x": -47,
      "y": 25,
      "z": 5,
      "name": "Cloud"
    },
    {
      "x": -47,
      "y": 24,
      "z": 6,
      "name": "Cloud",
      "support": 15
    },
    {
      "x": -47,
      "y": 24,
      "z": 7,
      "name": "Cloud"
    },
    {
      "x": -46,
      "y": 25,
      "z": -8,
      "name": "Cloud",
      "support": 15
    },
    {
      "x": -46,
      "y": 25,
      "z": -7,
      "name": "Cloud",
      "support": 15
    },
    {
      "x": -46,
      "y": 25,
      "z": -6,
      "name": "Cloud",
      "support": 15
    },
    {
      "x": -46,
      "y": 25,
      "z": -5,
      "name": "Cloud",
      "support": 15
    },
    {
      "x": -46,
      "y": 25,
      "z": -4,
      "name": "Cloud",
      "support": 15
    },
    {
      "x": -46,
      "y": 24,
      "z": -3,
      "name": "Cloud"
    },
    {
      "x": -46,
      "y": 25,
      "z": -3,
      "name": "Cloud"
    },
    {
      "x": -46,
      "y": 26,
      "z": -3,
      "name": "Cloud"
    },
    {
      "x": -46,
      "y": 24,
      "z": -2,
      "name": "Cloud"
    },
    {
      "x": -46,
      "y": 25,
      "z": -2,
      "name": "Cloud"
    },
    {
      "x": -46,
      "y": 26,
      "z": -2,
      "name": "Cloud"
    },
    {
      "x": -46,
      "y": 24,
      "z": -1,
      "name": "Cloud"
    },
    {
      "x": -46,
      "y": 25,
      "z": -1,
      "name": "Cloud"
    },
    {
      "x": -46,
      "y": 26,
      "z": -1,
      "name": "Cloud"
    },
    {
      "x": -46,
      "y": 24,
      "z": 0,
      "name": "Cloud"
    },
    {
      "x": -46,
      "y": 25,
      "z": 0,
      "name": "Cloud"
    },
    {
      "x": -46,
      "y": 26,
      "z": 0,
      "name": "Cloud"
    },
    {
      "x": -46,
      "y": 27,
      "z": 0,
      "name": "Cloud"
    },
    {
      "x": -46,
      "y": 24,
      "z": 1,
      "name": "Cloud"
    },
    {
      "x": -46,
      "y": 25,
      "z": 1,
      "name": "Cloud"
    },
    {
      "x": -46,
      "y": 24,
      "z": 2,
      "name": "Cloud"
    },
    {
      "x": -46,
      "y": 25,
      "z": 2,
      "name": "Cloud"
    },
    {
      "x": -46,
      "y": 24,
      "z": 3,
      "name": "Cloud"
    },
    {
      "x": -46,
      "y": 25,
      "z": 3,
      "name": "Cloud"
    },
    {
      "x": -46,
      "y": 26,
      "z": 3,
      "name": "Cloud",
      "support": 15
    },
    {
      "x": -46,
      "y": 24,
      "z": 4,
      "name": "Cloud"
    },
    {
      "x": -46,
      "y": 25,
      "z": 4,
      "name": "Cloud"
    },
    {
      "x": -46,
      "y": 26,
      "z": 4,
      "name": "Cloud",
      "support": 15
    },
    {
      "x": -46,
      "y": 24,
      "z": 5,
      "name": "Cloud"
    },
    {
      "x": -46,
      "y": 25,
      "z": 5,
      "name": "Cloud"
    },
    {
      "x": -46,
      "y": 26,
      "z": 5,
      "name": "Cloud",
      "support": 15
    },
    {
      "x": -46,
      "y": 24,
      "z": 6,
      "name": "Cloud"
    },
    {
      "x": -46,
      "y": 25,
      "z": 6,
      "name": "Cloud"
    },
    {
      "x": -46,
      "y": 24,
      "z": 7,
      "name": "Cloud"
    },
    {
      "x": -46,
      "y": 25,
      "z": 7,
      "name": "Cloud"
    },
    {
      "x": -46,
      "y": 24,
      "z": 8,
      "name": "Cloud"
    },
    {
      "x": -46,
      "y": 25,
      "z": 8,
      "name": "Cloud"
    },
    {
      "x": -46,
      "y": 25,
      "z": 9,
      "name": "Cloud",
      "support": 15
    },
    {
      "x": -46,
      "y": 25,
      "z": 10,
      "name": "Cloud",
      "support": 15
    },
    {
      "x": -45,
      "y": 25,
      "z": -11,
      "name": "Cloud",
      "support": 15
    },
    {
      "x": -45,
      "y": 25,
      "z": -9,
      "name": "Cloud",
      "support": 15
    },
    {
      "x": -45,
      "y": 25,
      "z": -8,
      "name": "Cloud",
      "support": 15
    },
    {
      "x": -45,
      "y": 25,
      "z": 3,
      "name": "Cloud",
      "support": 15
    },
    {
      "x": -45,
      "y": 24,
      "z": 4,
      "name": "Cloud",
      "support": 15
    },
    {
      "x": -45,
      "y": 25,
      "z": 4,
      "name": "Cloud",
      "support": 15
    },
    {
      "x": -45,
      "y": 24,
      "z": 5,
      "name": "Cloud",
      "support": 15
    },
    {
      "x": -45,
      "y": 25,
      "z": 5,
      "name": "Cloud",
      "support": 15
    },
    {
      "x": -45,
      "y": 25,
      "z": 6,
      "name": "Cloud",
      "support": 15
    },
    {
      "x": -45,
      "y": 25,
      "z": 10,
      "name": "Cloud",
      "support": 15
    },
    {
      "x": -45,
      "y": 25,
      "z": 11,
      "name": "Cloud",
      "support": 15
    },
    {
      "x": -45,
      "y": 25,
      "z": 12,
      "name": "Cloud",
      "support": 15
    },
    {
      "x": -45,
      "y": 25,
      "z": 13,
      "name": "Cloud",
      "support": 15
    },
    {
      "x": -44,
      "y": 25,
      "z": -14,
      "name": "Cloud",
      "support": 15
    },
    {
      "x": -44,
      "y": 25,
      "z": 15,
      "name": "Cloud",
      "support": 15
    },
    {
      "x": -44,
      "y": 25,
      "z": 16,
      "name": "Cloud",
      "support": 15
    },
    {
      "x": -41,
      "y": 25,
      "z": -23,
      "name": "Cloud",
      "support": 15
    },
    {
      "x": -41,
      "y": 25,
      "z": -22,
      "name": "Cloud",
      "support": 15
    },
    {
      "x": -40,
      "y": 25,
      "z": -24,
      "name": "Cloud",
      "support": 15
    },
    {
      "x": -40,
      "y": 25,
      "z": -23,
      "name": "Cloud",
      "support": 15
    },
    {
      "x": -39,
      "y": 25,
      "z": -28,
      "name": "Cloud",
      "support": 15
    },
    {
      "x": -39,
      "y": 25,
      "z": -27,
      "name": "Cloud",
      "support": 15
    },
    {
      "x": -39,
      "y": 25,
      "z": -26,
      "name": "Cloud",
      "support": 15
    },
    {
      "x": -38,
      "y": 25,
      "z": -30,
      "name": "Cloud",
      "support": 15
    },
    {
      "x": -38,
      "y": 25,
      "z": -29,
      "name": "Cloud",
      "support": 15
    },
    {
      "x": -38,
      "y": 25,
      "z": -28,
      "name": "Cloud",
      "support": 15
    },
    {
      "x": -37,
      "y": 25,
      "z": -31,
      "name": "Cloud",
      "support": 15
    },
    {
      "x": -37,
      "y": 24,
      "z": -30,
      "name": "Cloud"
    },
    {
      "x": -37,
      "y": 25,
      "z": -30,
      "name": "Cloud"
    },
    {
      "x": -37,
      "y": 25,
      "z": -29,
      "name": "Cloud",
      "support": 15
    },
    {
      "x": -36,
      "y": 25,
      "z": -33,
      "name": "Cloud",
      "support": 15
    },
    {
      "x": -36,
      "y": 26,
      "z": -33,
      "name": "Cloud",
      "support": 15
    },
    {
      "x": -36,
      "y": 24,
      "z": -32,
      "name": "Cloud"
    },
    {
      "x": -36,
      "y": 25,
      "z": -32,
      "name": "Cloud"
    },
    {
      "x": -36,
      "y": 26,
      "z": -32,
      "name": "Cloud",
      "support": 15
    },
    {
      "x": -36,
      "y": 24,
      "z": -31,
      "name": "Cloud"
    },
    {
      "x": -36,
      "y": 25,
      "z": -31,
      "name": "Cloud"
    },
    {
      "x": -36,
      "y": 24,
      "z": -30,
      "name": "Cloud"
    },
    {
      "x": -36,
      "y": 25,
      "z": -30,
      "name": "Cloud"
    },
    {
      "x": -35,
      "y": 25,
      "z": -34,
      "name": "Cloud",
      "support": 15
    },
    {
      "x": -35,
      "y": 24,
      "z": -33,
      "name": "Cloud"
    },
    {
      "x": -35,
      "y": 25,
      "z": -33,
      "name": "Cloud"
    },
    {
      "x": -35,
      "y": 26,
      "z": -33,
      "name": "Cloud",
      "support": 15
    },
    {
      "x": -35,
      "y": 24,
      "z": -32,
      "name": "Cloud"
    },
    {
      "x": -35,
      "y": 25,
      "z": -32,
      "name": "Cloud"
    },
    {
      "x": -35,
      "y": 24,
      "z": -31,
      "name": "Cloud"
    },
    {
      "x": -35,
      "y": 25,
      "z": -31,
      "name": "Cloud"
    },
    {
      "x": -34,
      "y": 25,
      "z": -35,
      "name": "Cloud",
      "support": 15
    },
    {
      "x": -34,
      "y": 24,
      "z": -34,
      "name": "Cloud"
    },
    {
      "x": -34,
      "y": 25,
      "z": -34,
      "name": "Cloud"
    },
    {
      "x": -34,
      "y": 24,
      "z": -33,
      "name": "Cloud"
    },
    {
      "x": -34,
      "y": 25,
      "z": -33,
      "name": "Cloud"
    },
    {
      "x": -34,
      "y": 24,
      "z": -32,
      "name": "Cloud"
    },
    {
      "x": -34,
      "y": 25,
      "z": -32,
      "name": "Cloud"
    },
    {
      "x": -33,
      "y": 24,
      "z": -35,
      "name": "Cloud"
    },
    {
      "x": -33,
      "y": 25,
      "z": -35,
      "name": "Cloud"
    },
    {
      "x": -33,
      "y": 26,
      "z": -35,
      "name": "Cloud"
    },
    {
      "x": -33,
      "y": 24,
      "z": -34,
      "name": "Cloud"
    },
    {
      "x": -33,
      "y": 25,
      "z": -34,
      "name": "Cloud"
    },
    {
      "x": -33,
      "y": 26,
      "z": -34,
      "name": "Cloud"
    },
    {
      "x": -33,
      "y": 24,
      "z": -33,
      "name": "Cloud"
    },
    {
      "x": -33,
      "y": 25,
      "z": -33,
      "name": "Cloud"
    },
    {
      "x": -33,
      "y": 34,
      "z": -7,
      "name": "Cloud",
      "support": 15
    },
    {
      "x": -33,
      "y": 34,
      "z": -6,
      "name": "Cloud"
    },
    {
      "x": -33,
      "y": 35,
      "z": -6,
      "name": "Cloud",
      "support": 15
    },
    {
      "x": -33,
      "y": 34,
      "z": -5,
      "name": "Cloud"
    },
    {
      "x": -33,
      "y": 35,
      "z": -5,
      "name": "Cloud",
      "support": 15
    },
    {
      "x": -33,
      "y": 34,
      "z": -4,
      "name": "Cloud",
      "support": 15
    },
    {
      "x": -33,
      "y": 33,
      "z": -3,
      "name": "Cloud",
      "support": 15
    },
    {
      "x": -33,
      "y": 34,
      "z": -3,
      "name": "Cloud",
      "support": 15
    },
    {
      "x": -33,
      "y": 33,
      "z": -2,
      "name": "Cloud",
      "support": 15
    },
    {
      "x": -33,
      "y": 34,
      "z": -2,
      "name": "Cloud"
    },
    {
      "x": -33,
      "y": 34,
      "z": -1,
      "name": "Cloud"
    },
    {
      "x": -33,
      "y": 34,
      "z": 0,
      "name": "Cloud",
      "support": 15
    },
    {
      "x": -32,
      "y": 25,
      "z": -37,
      "name": "Cloud",
      "support": 15
    },
    {
      "x": -32,
      "y": 24,
      "z": -36,
      "name": "Cloud"
    },
    {
      "x": -32,
      "y": 25,
      "z": -36,
      "name": "Cloud"
    },
    {
      "x": -32,
      "y": 26,
      "z": -36,
      "name": "Cloud",
      "support": 15
    },
    {
      "x": -32,
      "y": 24,
      "z": -35,
      "name": "Cloud"
    },
    {
      "x": -32,
      "y": 25,
      "z": -35,
      "name": "Cloud"
    },
    {
      "x": -32,
      "y": 26,
      "z": -35,
      "name": "Cloud"
    },
    {
      "x": -32,
      "y": 24,
      "z": -34,
      "name": "Cloud"
    },
    {
      "x": -32,
      "y": 25,
      "z": -34,
      "name": "Cloud"
    },
    {
      "x": -32,
      "y": 26,
      "z": -34,
      "name": "Cloud"
    },
    {
      "x": -32,
      "y": 34,
      "z": -9,
      "name": "Cloud",
      "support": 15
    },
    {
      "x": -32,
      "y": 33,
      "z": -8,
      "name": "Cloud"
    },
    {
      "x": -32,
      "y": 34,
      "z": -8,
      "name": "Cloud"
    },
    {
      "x": -32,
      "y": 35,
      "z": -8,
      "name": "Cloud"
    },
    {
      "x": -32,
      "y": 33,
      "z": -7,
      "name": "Cloud"
    },
    {
      "x": -32,
      "y": 34,
      "z": -7,
      "name": "Cloud"
    },
    {
      "x": -32,
      "y": 35,
      "z": -7,
      "name": "Cloud"
    },
    {
      "x": -32,
      "y": 33,
      "z": -6,
      "name": "Cloud"
    },
    {
      "x": -32,
      "y": 34,
      "z": -6,
      "name": "Cloud"
    },
    {
      "x": -32,
      "y": 35,
      "z": -6,
      "name": "Cloud"
    },
    {
      "x": -32,
      "y": 33,
      "z": -5,
      "name": "Cloud"
    },
    {
      "x": -32,
      "y": 34,
      "z": -5,
      "name": "Cloud"
    },
    {
      "x": -32,
      "y": 35,
      "z": -5,
      "name": "Cloud"
    },
    {
      "x": -32,
      "y": 33,
      "z": -4,
      "name": "Cloud"
    },
    {
      "x": -32,
      "y": 34,
      "z": -4,
      "name": "Cloud"
    },
    {
      "x": -32,
      "y": 35,
      "z": -4,
      "name": "Cloud"
    },
    {
      "x": -32,
      "y": 33,
      "z": -3,
      "name": "Cloud"
    },
    {
      "x": -32,
      "y": 34,
      "z": -3,
      "name": "Cloud"
    },
    {
      "x": -32,
      "y": 35,
      "z": -3,
      "name": "Cloud"
    },
    {
      "x": -32,
      "y": 33,
      "z": -2,
      "name": "Cloud"
    },
    {
      "x": -32,
      "y": 34,
      "z": -2,
      "name": "Cloud"
    },
    {
      "x": -32,
      "y": 35,
      "z": -2,
      "name": "Cloud"
    },
    {
      "x": -32,
      "y": 33,
      "z": -1,
      "name": "Cloud"
    },
    {
      "x": -32,
      "y": 34,
      "z": -1,
      "name": "Cloud"
    },
    {
      "x": -32,
      "y": 35,
      "z": -1,
      "name": "Cloud"
    },
    {
      "x": -32,
      "y": 34,
      "z": 0,
      "name": "Cloud",
      "support": 15
    },
    {
      "x": -32,
      "y": 35,
      "z": 0,
      "name": "Cloud"
    },
    {
      "x": -32,
      "y": 34,
      "z": 1,
      "name": "Cloud",
      "support": 15
    },
    {
      "x": -32,
      "y": 35,
      "z": 1,
      "name": "Cloud",
      "support": 15
    },
    {
      "x": -32,
      "y": 34,
      "z": 5,
      "name": "Cloud",
      "support": 15
    },
    {
      "x": -32,
      "y": 33,
      "z": 6,
      "name": "Cloud"
    },
    {
      "x": -32,
      "y": 34,
      "z": 6,
      "name": "Cloud"
    },
    {
      "x": -32,
      "y": 35,
      "z": 6,
      "name": "Cloud"
    },
    {
      "x": -32,
      "y": 33,
      "z": 7,
      "name": "Cloud"
    },
    {
      "x": -32,
      "y": 34,
      "z": 7,
      "name": "Cloud"
    },
    {
      "x": -32,
      "y": 33,
      "z": 8,
      "name": "Cloud"
    },
    {
      "x": -32,
      "y": 34,
      "z": 8,
      "name": "Cloud"
    },
    {
      "x": -31,
      "y": 25,
      "z": -38,
      "name": "Cloud",
      "support": 15
    },
    {
      "x": -31,
      "y": 24,
      "z": -37,
      "name": "Cloud",
      "support": 15
    },
    {
      "x": -31,
      "y": 25,
      "z": -37,
      "name": "Cloud",
      "support": 15
    },
    {
      "x": -31,
      "y": 24,
      "z": -36,
      "name": "Cloud"
    },
    {
      "x": -31,
      "y": 25,
      "z": -36,
      "name": "Cloud"
    },
    {
      "x": -31,
      "y": 26,
      "z": -36,
      "name": "Cloud",
      "support": 15
    },
    {
      "x": -31,
      "y": 24,
      "z": -35,
      "name": "Cloud"
    },
    {
      "x": -31,
      "y": 25,
      "z": -35,
      "name": "Cloud"
    },
    {
      "x": -31,
      "y": 26,
      "z": -35,
      "name": "Cloud",
      "support": 15
    },
    {
      "x": -31,
      "y": 24,
      "z": -34,
      "name": "Cloud"
    },
    {
      "x": -31,
      "y": 25,
      "z": -34,
      "name": "Cloud"
    },
    {
      "x": -31,
      "y": 33,
      "z": -10,
      "name": "Cloud"
    },
    {
      "x": -31,
      "y": 34,
      "z": -10,
      "name": "Cloud"
    },
    {
      "x": -31,
      "y": 35,
      "z": -10,
      "name": "Cloud"
    },
    {
      "x": -31,
      "y": 33,
      "z": -9,
      "name": "Cloud"
    },
    {
      "x": -31,
      "y": 34,
      "z": -9,
      "name": "Cloud"
    },
    {
      "x": -31,
      "y": 35,
      "z": -9,
      "name": "Cloud"
    },
    {
      "x": -31,
      "y": 33,
      "z": -8,
      "name": "Cloud"
    },
    {
      "x": -31,
      "y": 34,
      "z": -8,
      "name": "Cloud"
    },
    {
      "x": -31,
      "y": 35,
      "z": -8,
      "name": "Cloud"
    },
    {
      "x": -31,
      "y": 33,
      "z": -7,
      "name": "Cloud"
    },
    {
      "x": -31,
      "y": 34,
      "z": -7,
      "name": "Cloud"
    },
    {
      "x": -31,
      "y": 35,
      "z": -7,
      "name": "Cloud"
    },
    {
      "x": -31,
      "y": 33,
      "z": -6,
      "name": "Cloud"
    },
    {
      "x": -31,
      "y": 34,
      "z": -6,
      "name": "Cloud"
    },
    {
      "x": -31,
      "y": 35,
      "z": -6,
      "name": "Cloud"
    },
    {
      "x": -31,
      "y": 33,
      "z": -5,
      "name": "Cloud"
    },
    {
      "x": -31,
      "y": 34,
      "z": -5,
      "name": "Cloud"
    },
    {
      "x": -31,
      "y": 35,
      "z": -5,
      "name": "Cloud"
    },
    {
      "x": -31,
      "y": 33,
      "z": -4,
      "name": "Cloud"
    },
    {
      "x": -31,
      "y": 34,
      "z": -4,
      "name": "Cloud"
    },
    {
      "x": -31,
      "y": 35,
      "z": -4,
      "name": "Cloud"
    },
    {
      "x": -31,
      "y": 33,
      "z": -3,
      "name": "Cloud"
    },
    {
      "x": -31,
      "y": 34,
      "z": -3,
      "name": "Cloud"
    },
    {
      "x": -31,
      "y": 35,
      "z": -3,
      "name": "Cloud"
    },
    {
      "x": -31,
      "y": 33,
      "z": -2,
      "name": "Cloud"
    },
    {
      "x": -31,
      "y": 34,
      "z": -2,
      "name": "Cloud"
    },
    {
      "x": -31,
      "y": 35,
      "z": -2,
      "name": "Cloud"
    },
    {
      "x": -31,
      "y": 34,
      "z": -1,
      "name": "Cloud"
    },
    {
      "x": -31,
      "y": 35,
      "z": -1,
      "name": "Cloud"
    },
    {
      "x": -31,
      "y": 34,
      "z": 0,
      "name": "Cloud"
    },
    {
      "x": -31,
      "y": 35,
      "z": 0,
      "name": "Cloud"
    },
    {
      "x": -31,
      "y": 34,
      "z": 1,
      "name": "Cloud",
      "support": 15
    },
    {
      "x": -31,
      "y": 35,
      "z": 1,
      "name": "Cloud",
      "support": 15
    },
    {
      "x": -31,
      "y": 33,
      "z": 3,
      "name": "Cloud",
      "support": 15
    },
    {
      "x": -31,
      "y": 34,
      "z": 3,
      "name": "Cloud"
    },
    {
      "x": -31,
      "y": 33,
      "z": 4,
      "name": "Cloud",
      "support": 15
    },
    {
      "x": -31,
      "y": 34,
      "z": 4,
      "name": "Cloud"
    },
    {
      "x": -31,
      "y": 33,
      "z": 5,
      "name": "Cloud",
      "support": 15
    },
    {
      "x": -31,
      "y": 34,
      "z": 5,
      "name": "Cloud"
    },
    {
      "x": -31,
      "y": 35,
      "z": 5,
      "name": "Cloud"
    },
    {
      "x": -31,
      "y": 33,
      "z": 6,
      "name": "Cloud"
    },
    {
      "x": -31,
      "y": 34,
      "z": 6,
      "name": "Cloud"
    },
    {
      "x": -31,
      "y": 35,
      "z": 6,
      "name": "Cloud"
    },
    {
      "x": -31,
      "y": 33,
      "z": 7,
      "name": "Cloud"
    },
    {
      "x": -31,
      "y": 34,
      "z": 7,
      "name": "Cloud"
    },
    {
      "x": -31,
      "y": 35,
      "z": 7,
      "name": "Cloud"
    },
    {
      "x": -31,
      "y": 33,
      "z": 8,
      "name": "Cloud"
    },
    {
      "x": -31,
      "y": 34,
      "z": 8,
      "name": "Cloud"
    },
    {
      "x": -31,
      "y": 35,
      "z": 8,
      "name": "Cloud"
    },
    {
      "x": -31,
      "y": 33,
      "z": 9,
      "name": "Cloud"
    },
    {
      "x": -31,
      "y": 34,
      "z": 9,
      "name": "Cloud"
    },
    {
      "x": -31,
      "y": 34,
      "z": 10,
      "name": "Cloud",
      "support": 15
    },
    {
      "x": -31,
      "y": 33,
      "z": 11,
      "name": "Cloud"
    },
    {
      "x": -31,
      "y": 34,
      "z": 11,
      "name": "Cloud"
    },
    {
      "x": -31,
      "y": 35,
      "z": 11,
      "name": "Cloud"
    },
    {
      "x": -31,
      "y": 33,
      "z": 12,
      "name": "Cloud"
    },
    {
      "x": -31,
      "y": 34,
      "z": 12,
      "name": "Cloud"
    },
    {
      "x": -31,
      "y": 35,
      "z": 12,
      "name": "Cloud"
    },
    {
      "x": -30,
      "y": 25,
      "z": -39,
      "name": "Cloud"
    },
    {
      "x": -30,
      "y": 25,
      "z": -38,
      "name": "Cloud"
    },
    {
      "x": -30,
      "y": 24,
      "z": -37,
      "name": "Cloud"
    },
    {
      "x": -30,
      "y": 25,
      "z": -37,
      "name": "Cloud"
    },
    {
      "x": -30,
      "y": 24,
      "z": -36,
      "name": "Cloud"
    },
    {
      "x": -30,
      "y": 25,
      "z": -36,
      "name": "Cloud"
    },
    {
      "x": -30,
      "y": 24,
      "z": -35,
      "name": "Cloud"
    },
    {
      "x": -30,
      "y": 25,
      "z": -35,
      "name": "Cloud"
    },
    {
      "x": -30,
      "y": 34,
      "z": -13,
      "name": "Cloud"
    },
    {
      "x": -30,
      "y": 33,
      "z": -12,
      "name": "Cloud"
    },
    {
      "x": -30,
      "y": 34,
      "z": -12,
      "name": "Cloud"
    },
    {
      "x": -30,
      "y": 35,
      "z": -12,
      "name": "Cloud"
    },
    {
      "x": -30,
      "y": 33,
      "z": -11,
      "name": "Cloud"
    },
    {
      "x": -30,
      "y": 34,
      "z": -11,
      "name": "Cloud"
    },
    {
      "x": -30,
      "y": 35,
      "z": -11,
      "name": "Cloud"
    },
    {
      "x": -30,
      "y": 33,
      "z": -10,
      "name": "Cloud"
    },
    {
      "x": -30,
      "y": 34,
      "z": -10,
      "name": "Cloud"
    },
    {
      "x": -30,
      "y": 35,
      "z": -10,
      "name": "Cloud"
    },
    {
      "x": -30,
      "y": 33,
      "z": -9,
      "name": "Cloud"
    },
    {
      "x": -30,
      "y": 34,
      "z": -9,
      "name": "Cloud"
    },
    {
      "x": -30,
      "y": 35,
      "z": -9,
      "name": "Cloud"
    },
    {
      "x": -30,
      "y": 33,
      "z": -8,
      "name": "Cloud"
    },
    {
      "x": -30,
      "y": 34,
      "z": -8,
      "name": "Cloud"
    },
    {
      "x": -30,
      "y": 35,
      "z": -8,
      "name": "Cloud"
    },
    {
      "x": -30,
      "y": 33,
      "z": -7,
      "name": "Cloud"
    },
    {
      "x": -30,
      "y": 34,
      "z": -7,
      "name": "Cloud"
    },
    {
      "x": -30,
      "y": 35,
      "z": -7,
      "name": "Cloud"
    },
    {
      "x": -30,
      "y": 33,
      "z": -6,
      "name": "Cloud"
    },
    {
      "x": -30,
      "y": 34,
      "z": -6,
      "name": "Cloud"
    },
    {
      "x": -30,
      "y": 35,
      "z": -6,
      "name": "Cloud"
    },
    {
      "x": -30,
      "y": 33,
      "z": -5,
      "name": "Cloud"
    },
    {
      "x": -30,
      "y": 34,
      "z": -5,
      "name": "Cloud"
    },
    {
      "x": -30,
      "y": 35,
      "z": -5,
      "name": "Cloud"
    },
    {
      "x": -30,
      "y": 33,
      "z": -4,
      "name": "Cloud"
    },
    {
      "x": -30,
      "y": 34,
      "z": -4,
      "name": "Cloud"
    },
    {
      "x": -30,
      "y": 35,
      "z": -4,
      "name": "Cloud"
    },
    {
      "x": -30,
      "y": 33,
      "z": -3,
      "name": "Cloud"
    },
    {
      "x": -30,
      "y": 34,
      "z": -3,
      "name": "Cloud"
    },
    {
      "x": -30,
      "y": 33,
      "z": -2,
      "name": "Cloud"
    },
    {
      "x": -30,
      "y": 34,
      "z": -2,
      "name": "Cloud"
    },
    {
      "x": -30,
      "y": 35,
      "z": -2,
      "name": "Cloud"
    },
    {
      "x": -30,
      "y": 34,
      "z": -1,
      "name": "Cloud"
    },
    {
      "x": -30,
      "y": 35,
      "z": -1,
      "name": "Cloud"
    },
    {
      "x": -30,
      "y": 34,
      "z": 0,
      "name": "Cloud"
    },
    {
      "x": -30,
      "y": 35,
      "z": 0,
      "name": "Cloud"
    },
    {
      "x": -30,
      "y": 33,
      "z": 4,
      "name": "Cloud",
      "support": 15
    },
    {
      "x": -30,
      "y": 34,
      "z": 4,
      "name": "Cloud"
    },
    {
      "x": -30,
      "y": 33,
      "z": 5,
      "name": "Cloud"
    },
    {
      "x": -30,
      "y": 34,
      "z": 5,
      "name": "Cloud"
    },
    {
      "x": -30,
      "y": 35,
      "z": 5,
      "name": "Cloud"
    },
    {
      "x": -30,
      "y": 33,
      "z": 6,
      "name": "Cloud"
    },
    {
      "x": -30,
      "y": 34,
      "z": 6,
      "name": "Cloud"
    },
    {
      "x": -30,
      "y": 35,
      "z": 6,
      "name": "Cloud"
    },
    {
      "x": -30,
      "y": 33,
      "z": 7,
      "name": "Cloud"
    },
    {
      "x": -30,
      "y": 34,
      "z": 7,
      "name": "Cloud"
    },
    {
      "x": -30,
      "y": 35,
      "z": 7,
      "name": "Cloud"
    },
    {
      "x": -30,
      "y": 33,
      "z": 8,
      "name": "Cloud"
    },
    {
      "x": -30,
      "y": 34,
      "z": 8,
      "name": "Cloud"
    },
    {
      "x": -30,
      "y": 35,
      "z": 8,
      "name": "Cloud"
    },
    {
      "x": -30,
      "y": 33,
      "z": 9,
      "name": "Cloud"
    },
    {
      "x": -30,
      "y": 34,
      "z": 9,
      "name": "Cloud"
    },
    {
      "x": -30,
      "y": 35,
      "z": 9,
      "name": "Cloud"
    },
    {
      "x": -30,
      "y": 33,
      "z": 10,
      "name": "Cloud"
    },
    {
      "x": -30,
      "y": 34,
      "z": 10,
      "name": "Cloud"
    },
    {
      "x": -30,
      "y": 35,
      "z": 10,
      "name": "Cloud"
    },
    {
      "x": -30,
      "y": 33,
      "z": 11,
      "name": "Cloud"
    },
    {
      "x": -30,
      "y": 34,
      "z": 11,
      "name": "Cloud"
    },
    {
      "x": -30,
      "y": 35,
      "z": 11,
      "name": "Cloud"
    },
    {
      "x": -30,
      "y": 33,
      "z": 12,
      "name": "Cloud"
    },
    {
      "x": -30,
      "y": 34,
      "z": 12,
      "name": "Cloud"
    },
    {
      "x": -30,
      "y": 35,
      "z": 12,
      "name": "Cloud"
    },
    {
      "x": -30,
      "y": 33,
      "z": 13,
      "name": "Cloud"
    },
    {
      "x": -30,
      "y": 34,
      "z": 13,
      "name": "Cloud"
    },
    {
      "x": -30,
      "y": 35,
      "z": 13,
      "name": "Cloud"
    },
    {
      "x": -30,
      "y": 33,
      "z": 14,
      "name": "Cloud"
    },
    {
      "x": -30,
      "y": 34,
      "z": 14,
      "name": "Cloud"
    },
    {
      "x": -30,
      "y": 35,
      "z": 14,
      "name": "Cloud"
    },
    {
      "x": -30,
      "y": 34,
      "z": 15,
      "name": "Cloud",
      "support": 15
    },
    {
      "x": -29,
      "y": 31,
      "z": -42,
      "name": "Cloud",
      "support": 15
    },
    {
      "x": -29,
      "y": 31,
      "z": -41,
      "name": "Cloud",
      "support": 15
    },
    {
      "x": -29,
      "y": 24,
      "z": -39,
      "name": "Cloud"
    },
    {
      "x": -29,
      "y": 25,
      "z": -39,
      "name": "Cloud"
    },
    {
      "x": -29,
      "y": 26,
      "z": -39,
      "name": "Cloud"
    },
    {
      "x": -29,
      "y": 25,
      "z": -38,
      "name": "Cloud"
    },
    {
      "x": -29,
      "y": 25,
      "z": -37,
      "name": "Cloud",
      "support": 15
    },
    {
      "x": -29,
      "y": 24,
      "z": -36,
      "name": "Cloud"
    },
    {
      "x": -29,
      "y": 25,
      "z": -36,
      "name": "Cloud"
    },
    {
      "x": -29,
      "y": 34,
      "z": -15,
      "name": "Cloud"
    },
    {
      "x": -29,
      "y": 33,
      "z": -14,
      "name": "Cloud"
    },
    {
      "x": -29,
      "y": 34,
      "z": -14,
      "name": "Cloud"
    },
    {
      "x": -29,
      "y": 32,
      "z": -13,
      "name": "Cloud"
    },
    {
      "x": -29,
      "y": 33,
      "z": -13,
      "name": "Cloud"
    },
    {
      "x": -29,
      "y": 34,
      "z": -13,
      "name": "Cloud"
    },
    {
      "x": -29,
      "y": 32,
      "z": -12,
      "name": "Cloud"
    },
    {
      "x": -29,
      "y": 33,
      "z": -12,
      "name": "Cloud"
    },
    {
      "x": -29,
      "y": 34,
      "z": -12,
      "name": "Cloud"
    },
    {
      "x": -29,
      "y": 35,
      "z": -12,
      "name": "Cloud"
    },
    {
      "x": -29,
      "y": 32,
      "z": -11,
      "name": "Cloud"
    },
    {
      "x": -29,
      "y": 33,
      "z": -11,
      "name": "Cloud"
    },
    {
      "x": -29,
      "y": 34,
      "z": -11,
      "name": "Cloud"
    },
    {
      "x": -29,
      "y": 35,
      "z": -11,
      "name": "Cloud"
    },
    {
      "x": -29,
      "y": 33,
      "z": -10,
      "name": "Cloud"
    },
    {
      "x": -29,
      "y": 34,
      "z": -10,
      "name": "Cloud"
    },
    {
      "x": -29,
      "y": 35,
      "z": -10,
      "name": "Cloud"
    },
    {
      "x": -29,
      "y": 33,
      "z": -9,
      "name": "Cloud"
    },
    {
      "x": -29,
      "y": 34,
      "z": -9,
      "name": "Cloud"
    },
    {
      "x": -29,
      "y": 35,
      "z": -9,
      "name": "Cloud"
    },
    {
      "x": -29,
      "y": 33,
      "z": -8,
      "name": "Cloud"
    },
    {
      "x": -29,
      "y": 34,
      "z": -8,
      "name": "Cloud"
    },
    {
      "x": -29,
      "y": 35,
      "z": -8,
      "name": "Cloud"
    },
    {
      "x": -29,
      "y": 34,
      "z": -7,
      "name": "Cloud"
    },
    {
      "x": -29,
      "y": 33,
      "z": -6,
      "name": "Cloud"
    },
    {
      "x": -29,
      "y": 34,
      "z": 4,
      "name": "Cloud"
    },
    {
      "x": -29,
      "y": 33,
      "z": 5,
      "name": "Cloud"
    },
    {
      "x": -29,
      "y": 34,
      "z": 5,
      "name": "Cloud"
    },
    {
      "x": -29,
      "y": 33,
      "z": 6,
      "name": "Cloud"
    },
    {
      "x": -29,
      "y": 34,
      "z": 6,
      "name": "Cloud"
    },
    {
      "x": -29,
      "y": 35,
      "z": 6,
      "name": "Cloud"
    },
    {
      "x": -29,
      "y": 33,
      "z": 7,
      "name": "Cloud"
    },
    {
      "x": -29,
      "y": 34,
      "z": 7,
      "name": "Cloud"
    },
    {
      "x": -29,
      "y": 35,
      "z": 7,
      "name": "Cloud"
    },
    {
      "x": -29,
      "y": 33,
      "z": 8,
      "name": "Cloud"
    },
    {
      "x": -29,
      "y": 35,
      "z": 8,
      "name": "Cloud"
    },
    {
      "x": -29,
      "y": 33,
      "z": 9,
      "name": "Cloud"
    },
    {
      "x": -29,
      "y": 35,
      "z": 9,
      "name": "Cloud"
    },
    {
      "x": -29,
      "y": 33,
      "z": 10,
      "name": "Cloud"
    },
    {
      "x": -29,
      "y": 35,
      "z": 10,
      "name": "Cloud"
    },
    {
      "x": -29,
      "y": 33,
      "z": 11,
      "name": "Cloud"
    },
    {
      "x": -29,
      "y": 34,
      "z": 11,
      "name": "Cloud"
    },
    {
      "x": -29,
      "y": 35,
      "z": 11,
      "name": "Cloud"
    },
    {
      "x": -29,
      "y": 33,
      "z": 12,
      "name": "Cloud"
    },
    {
      "x": -29,
      "y": 34,
      "z": 12,
      "name": "Cloud"
    },
    {
      "x": -29,
      "y": 35,
      "z": 12,
      "name": "Cloud"
    },
    {
      "x": -29,
      "y": 33,
      "z": 13,
      "name": "Cloud"
    },
    {
      "x": -29,
      "y": 34,
      "z": 13,
      "name": "Cloud"
    },
    {
      "x": -29,
      "y": 35,
      "z": 13,
      "name": "Cloud"
    },
    {
      "x": -29,
      "y": 33,
      "z": 14,
      "name": "Cloud"
    },
    {
      "x": -29,
      "y": 34,
      "z": 14,
      "name": "Cloud"
    },
    {
      "x": -29,
      "y": 35,
      "z": 14,
      "name": "Cloud"
    },
    {
      "x": -29,
      "y": 33,
      "z": 15,
      "name": "Cloud",
      "support": 15
    },
    {
      "x": -29,
      "y": 34,
      "z": 15,
      "name": "Cloud",
      "support": 15
    },
    {
      "x": -29,
      "y": 34,
      "z": 16,
      "name": "Cloud",
      "support": 15
    },
    {
      "x": -29,
      "y": 34,
      "z": 17,
      "name": "Cloud",
      "support": 15
    },
    {
      "x": -29,
      "y": 25,
      "z": 36,
      "name": "Cloud",
      "support": 15
    },
    {
      "x": -28,
      "y": 24,
      "z": -40,
      "name": "Cloud"
    },
    {
      "x": -28,
      "y": 25,
      "z": -40,
      "name": "Cloud"
    },
    {
      "x": -28,
      "y": 26,
      "z": -40,
      "name": "Cloud"
    },
    {
      "x": -28,
      "y": 24,
      "z": -39,
      "name": "Cloud"
    },
    {
      "x": -28,
      "y": 25,
      "z": -39,
      "name": "Cloud"
    },
    {
      "x": -28,
      "y": 26,
      "z": -39,
      "name": "Cloud"
    },
    {
      "x": -28,
      "y": 24,
      "z": -38,
      "name": "Cloud"
    },
    {
      "x": -28,
      "y": 25,
      "z": -38,
      "name": "Cloud"
    },
    {
      "x": -28,
      "y": 26,
      "z": -38,
      "name": "Cloud"
    },
    {
      "x": -28,
      "y": 24,
      "z": -37,
      "name": "Cloud"
    },
    {
      "x": -28,
      "y": 25,
      "z": -37,
      "name": "Cloud"
    },
    {
      "x": -28,
      "y": 30,
      "z": -19,
      "name": "Cloud",
      "support": 15
    },
    {
      "x": -28,
      "y": 33,
      "z": -17,
      "name": "Cloud",
      "support": 15
    },
    {
      "x": -28,
      "y": 33,
      "z": -16,
      "name": "Cloud",
      "support": 15
    },
    {
      "x": -28,
      "y": 33,
      "z": -15,
      "name": "Cloud"
    },
    {
      "x": -28,
      "y": 34,
      "z": -15,
      "name": "Cloud"
    },
    {
      "x": -28,
      "y": 32,
      "z": -14,
      "name": "Cloud"
    },
    {
      "x": -28,
      "y": 33,
      "z": -14,
      "name": "Cloud"
    },
    {
      "x": -28,
      "y": 34,
      "z": -14,
      "name": "Cloud"
    },
    {
      "x": -28,
      "y": 32,
      "z": -13,
      "name": "Cloud"
    },
    {
      "x": -28,
      "y": 33,
      "z": -13,
      "name": "Cloud"
    },
    {
      "x": -28,
      "y": 34,
      "z": -13,
      "name": "Cloud"
    },
    {
      "x": -28,
      "y": 33,
      "z": -12,
      "name": "Cloud"
    },
    {
      "x": -28,
      "y": 34,
      "z": -12,
      "name": "Cloud"
    },
    {
      "x": -28,
      "y": 35,
      "z": -12,
      "name": "Cloud"
    },
    {
      "x": -28,
      "y": 32,
      "z": -11,
      "name": "Cloud"
    },
    {
      "x": -28,
      "y": 33,
      "z": -11,
      "name": "Cloud"
    },
    {
      "x": -28,
      "y": 34,
      "z": -11,
      "name": "Cloud"
    },
    {
      "x": -28,
      "y": 32,
      "z": -10,
      "name": "Cloud"
    },
    {
      "x": -28,
      "y": 33,
      "z": 10,
      "name": "Cloud"
    },
    {
      "x": -28,
      "y": 35,
      "z": 10,
      "name": "Cloud"
    },
    {
      "x": -28,
      "y": 33,
      "z": 11,
      "name": "Cloud"
    },
    {
      "x": -28,
      "y": 35,
      "z": 11,
      "name": "Cloud"
    },
    {
      "x": -28,
      "y": 33,
      "z": 12,
      "name": "Cloud"
    },
    {
      "x": -28,
      "y": 34,
      "z": 12,
      "name": "Cloud"
    },
    {
      "x": -28,
      "y": 35,
      "z": 12,
      "name": "Cloud"
    },
    {
      "x": -28,
      "y": 33,
      "z": 13,
      "name": "Cloud"
    },
    {
      "x": -28,
      "y": 34,
      "z": 13,
      "name": "Cloud"
    },
    {
      "x": -28,
      "y": 35,
      "z": 13,
      "name": "Cloud"
    },
    {
      "x": -28,
      "y": 33,
      "z": 14,
      "name": "Cloud"
    },
    {
      "x": -28,
      "y": 34,
      "z": 14,
      "name": "Cloud"
    },
    {
      "x": -28,
      "y": 35,
      "z": 14,
      "name": "Cloud"
    },
    {
      "x": -28,
      "y": 33,
      "z": 15,
      "name": "Cloud",
      "support": 15
    },
    {
      "x": -28,
      "y": 34,
      "z": 15,
      "name": "Cloud",
      "support": 15
    },
    {
      "x": -28,
      "y": 35,
      "z": 15,
      "name": "Cloud",
      "support": 15
    },
    {
      "x": -28,
      "y": 33,
      "z": 16,
      "name": "Cloud"
    },
    {
      "x": -28,
      "y": 34,
      "z": 16,
      "name": "Cloud"
    },
    {
      "x": -28,
      "y": 35,
      "z": 16,
      "name": "Cloud"
    },
    {
      "x": -28,
      "y": 33,
      "z": 17,
      "name": "Cloud"
    },
    {
      "x": -28,
      "y": 34,
      "z": 17,
      "name": "Cloud"
    },
    {
      "x": -28,
      "y": 35,
      "z": 17,
      "name": "Cloud"
    },
    {
      "x": -28,
      "y": 33,
      "z": 18,
      "name": "Cloud"
    },
    {
      "x": -28,
      "y": 34,
      "z": 18,
      "name": "Cloud"
    },
    {
      "x": -28,
      "y": 35,
      "z": 18,
      "name": "Cloud"
    },
    {
      "x": -27,
      "y": 31,
      "z": -44,
      "name": "Cloud",
      "support": 15
    },
    {
      "x": -27,
      "y": 31,
      "z": -43,
      "name": "Cloud",
      "support": 15
    },
    {
      "x": -27,
      "y": 24,
      "z": -41,
      "name": "Cloud"
    },
    {
      "x": -27,
      "y": 25,
      "z": -41,
      "name": "Cloud"
    },
    {
      "x": -27,
      "y": 26,
      "z": -41,
      "name": "Cloud"
    },
    {
      "x": -27,
      "y": 24,
      "z": -40,
      "name": "Cloud"
    },
    {
      "x": -27,
      "y": 25,
      "z": -40,
      "name": "Cloud"
    },
    {
      "x": -27,
      "y": 26,
      "z": -40,
      "name": "Cloud"
    },
    {
      "x": -27,
      "y": 24,
      "z": -39,
      "name": "Cloud"
    },
    {
      "x": -27,
      "y": 25,
      "z": -39,
      "name": "Cloud"
    },
    {
      "x": -27,
      "y": 24,
      "z": -38,
      "name": "Cloud"
    },
    {
      "x": -27,
      "y": 33,
      "z": -18,
      "name": "Cloud",
      "support": 15
    },
    {
      "x": -27,
      "y": 33,
      "z": -17,
      "name": "Cloud"
    },
    {
      "x": -27,
      "y": 33,
      "z": -16,
      "name": "Cloud"
    },
    {
      "x": -27,
      "y": 33,
      "z": -15,
      "name": "Cloud"
    },
    {
      "x": -27,
      "y": 34,
      "z": -15,
      "name": "Cloud"
    },
    {
      "x": -27,
      "y": 32,
      "z": -14,
      "name": "Cloud"
    },
    {
      "x": -27,
      "y": 33,
      "z": -14,
      "name": "Cloud"
    },
    {
      "x": -27,
      "y": 32,
      "z": -13,
      "name": "Cloud"
    },
    {
      "x": -27,
      "y": 33,
      "z": 13,
      "name": "Cloud"
    },
    {
      "x": -27,
      "y": 33,
      "z": 14,
      "name": "Cloud",
      "support": 15
    },
    {
      "x": -27,
      "y": 35,
      "z": 14,
      "name": "Cloud",
      "support": 15
    },
    {
      "x": -27,
      "y": 33,
      "z": 15,
      "name": "Cloud"
    },
    {
      "x": -27,
      "y": 34,
      "z": 15,
      "name": "Cloud"
    },
    {
      "x": -27,
      "y": 35,
      "z": 15,
      "name": "Cloud"
    },
    {
      "x": -27,
      "y": 33,
      "z": 16,
      "name": "Cloud"
    },
    {
      "x": -27,
      "y": 34,
      "z": 16,
      "name": "Cloud"
    },
    {
      "x": -27,
      "y": 35,
      "z": 16,
      "name": "Cloud"
    },
    {
      "x": -27,
      "y": 33,
      "z": 17,
      "name": "Cloud"
    },
    {
      "x": -27,
      "y": 34,
      "z": 17,
      "name": "Cloud"
    },
    {
      "x": -27,
      "y": 35,
      "z": 17,
      "name": "Cloud"
    },
    {
      "x": -27,
      "y": 33,
      "z": 18,
      "name": "Cloud"
    },
    {
      "x": -27,
      "y": 34,
      "z": 18,
      "name": "Cloud"
    },
    {
      "x": -27,
      "y": 35,
      "z": 18,
      "name": "Cloud"
    },
    {
      "x": -27,
      "y": 33,
      "z": 19,
      "name": "Cloud"
    },
    {
      "x": -27,
      "y": 34,
      "z": 19,
      "name": "Cloud"
    },
    {
      "x": -27,
      "y": 35,
      "z": 19,
      "name": "Cloud"
    },
    {
      "x": -27,
      "y": 33,
      "z": 20,
      "name": "Cloud",
      "support": 15
    },
    {
      "x": -27,
      "y": 34,
      "z": 20,
      "name": "Cloud",
      "support": 15
    },
    {
      "x": -27,
      "y": 25,
      "z": 38,
      "name": "Cloud",
      "support": 15
    },
    {
      "x": -27,
      "y": 25,
      "z": 39,
      "name": "Cloud",
      "support": 15
    },
    {
      "x": -26,
      "y": 31,
      "z": -45,
      "name": "Cloud",
      "support": 15
    },
    {
      "x": -26,
      "y": 31,
      "z": -44,
      "name": "Cloud",
      "support": 15
    },
    {
      "x": -26,
      "y": 24,
      "z": -41,
      "name": "Cloud"
    },
    {
      "x": -26,
      "y": 25,
      "z": -41,
      "name": "Cloud"
    },
    {
      "x": -26,
      "y": 26,
      "z": -41,
      "name": "Cloud"
    },
    {
      "x": -26,
      "y": 24,
      "z": -40,
      "name": "Cloud"
    },
    {
      "x": -26,
      "y": 25,
      "z": -40,
      "name": "Cloud"
    },
    {
      "x": -26,
      "y": 26,
      "z": -40,
      "name": "Cloud"
    },
    {
      "x": -26,
      "y": 24,
      "z": -39,
      "name": "Cloud"
    },
    {
      "x": -26,
      "y": 25,
      "z": -39,
      "name": "Cloud",
      "support": 15
    },
    {
      "x": -26,
      "y": 33,
      "z": -19,
      "name": "Cloud",
      "support": 15
    },
    {
      "x": -26,
      "y": 33,
      "z": -18,
      "name": "Cloud"
    },
    {
      "x": -26,
      "y": 33,
      "z": -17,
      "name": "Cloud"
    },
    {
      "x": -26,
      "y": 33,
      "z": -16,
      "name": "Cloud"
    },
    {
      "x": -26,
      "y": 33,
      "z": 16,
      "name": "Cloud"
    },
    {
      "x": -26,
      "y": 32,
      "z": 17,
      "name": "Cloud",
      "support": 15
    },
    {
      "x": -26,
      "y": 33,
      "z": 17,
      "name": "Cloud"
    },
    {
      "x": -26,
      "y": 34,
      "z": 17,
      "name": "Cloud"
    },
    {
      "x": -26,
      "y": 35,
      "z": 17,
      "name": "Cloud"
    },
    {
      "x": -26,
      "y": 32,
      "z": 18,
      "name": "Cloud",
      "support": 15
    },
    {
      "x": -26,
      "y": 34,
      "z": 18,
      "name": "Cloud"
    },
    {
      "x": -26,
      "y": 35,
      "z": 18,
      "name": "Cloud"
    },
    {
      "x": -26,
      "y": 32,
      "z": 19,
      "name": "Cloud"
    },
    {
      "x": -26,
      "y": 33,
      "z": 19,
      "name": "Cloud"
    },
    {
      "x": -26,
      "y": 34,
      "z": 19,
      "name": "Cloud"
    },
    {
      "x": -26,
      "y": 35,
      "z": 19,
      "name": "Cloud"
    },
    {
      "x": -26,
      "y": 33,
      "z": 20,
      "name": "Cloud",
      "support": 15
    },
    {
      "x": -26,
      "y": 34,
      "z": 20,
      "name": "Cloud",
      "support": 15
    },
    {
      "x": -26,
      "y": 35,
      "z": 20,
      "name": "Cloud",
      "support": 15
    },
    {
      "x": -26,
      "y": 33,
      "z": 21,
      "name": "Cloud",
      "support": 15
    },
    {
      "x": -26,
      "y": 34,
      "z": 21,
      "name": "Cloud",
      "support": 15
    },
    {
      "x": -26,
      "y": 33,
      "z": 22,
      "name": "Cloud",
      "support": 15
    },
    {
      "x": -26,
      "y": 25,
      "z": 39,
      "name": "Cloud",
      "support": 15
    },
    {
      "x": -26,
      "y": 25,
      "z": 40,
      "name": "Cloud",
      "support": 15
    },
    {
      "x": -25,
      "y": 31,
      "z": -45,
      "name": "Cloud",
      "support": 15
    },
    {
      "x": -25,
      "y": 24,
      "z": -41,
      "name": "Cloud"
    },
    {
      "x": -25,
      "y": 25,
      "z": -41,
      "name": "Cloud"
    },
    {
      "x": -25,
      "y": 26,
      "z": -41,
      "name": "Cloud"
    },
    {
      "x": -25,
      "y": 24,
      "z": -40,
      "name": "Cloud"
    },
    {
      "x": -25,
      "y": 25,
      "z": -40,
      "name": "Cloud"
    },
    {
      "x": -25,
      "y": 24,
      "z": -39,
      "name": "Cloud"
    },
    {
      "x": -25,
      "y": 25,
      "z": -39,
      "name": "Cloud"
    },
    {
      "x": -25,
      "y": 33,
      "z": -19,
      "name": "Cloud"
    },
    {
      "x": -25,
      "y": 33,
      "z": -18,
      "name": "Cloud"
    },
    {
      "x": -25,
      "y": 32,
      "z": 19,
      "name": "Cloud",
      "support": 15
    },
    {
      "x": -25,
      "y": 35,
      "z": 19,
      "name": "Cloud"
    },
    {
      "x": -25,
      "y": 32,
      "z": 20,
      "name": "Cloud",
      "support": 15
    },
    {
      "x": -25,
      "y": 33,
      "z": 20,
      "name": "Cloud",
      "support": 15
    },
    {
      "x": -25,
      "y": 34,
      "z": 20,
      "name": "Cloud",
      "support": 15
    },
    {
      "x": -25,
      "y": 33,
      "z": 21,
      "name": "Cloud",
      "support": 15
    },
    {
      "x": -25,
      "y": 33,
      "z": 22,
      "name": "Cloud",
      "support": 15
    },
    {
      "x": -25,
      "y": 33,
      "z": 23,
      "name": "Cloud",
      "support": 15
    },
    {
      "x": -25,
      "y": 25,
      "z": 40,
      "name": "Cloud",
      "support": 15
    },
    {
      "x": -25,
      "y": 25,
      "z": 41,
      "name": "Cloud",
      "support": 15
    },
    {
      "x": -24,
      "y": 31,
      "z": -46,
      "name": "Cloud",
      "support": 15
    },
    {
      "x": -24,
      "y": 31,
      "z": -45,
      "name": "Cloud",
      "support": 15
    },
    {
      "x": -24,
      "y": 24,
      "z": -43,
      "name": "Cloud"
    },
    {
      "x": -24,
      "y": 25,
      "z": -43,
      "name": "Cloud"
    },
    {
      "x": -24,
      "y": 26,
      "z": -43,
      "name": "Cloud"
    },
    {
      "x": -24,
      "y": 24,
      "z": -42,
      "name": "Cloud"
    },
    {
      "x": -24,
      "y": 25,
      "z": -42,
      "name": "Cloud"
    },
    {
      "x": -24,
      "y": 26,
      "z": -42,
      "name": "Cloud"
    },
    {
      "x": -24,
      "y": 24,
      "z": -41,
      "name": "Cloud"
    },
    {
      "x": -24,
      "y": 25,
      "z": -41,
      "name": "Cloud"
    },
    {
      "x": -24,
      "y": 26,
      "z": -41,
      "name": "Cloud"
    },
    {
      "x": -24,
      "y": 24,
      "z": -40,
      "name": "Cloud"
    },
    {
      "x": -24,
      "y": 33,
      "z": -20,
      "name": "Cloud"
    },
    {
      "x": -24,
      "y": 33,
      "z": -19,
      "name": "Cloud"
    },
    {
      "x": -24,
      "y": 32,
      "z": 20,
      "name": "Cloud"
    },
    {
      "x": -24,
      "y": 34,
      "z": 20,
      "name": "Cloud",
      "support": 15
    },
    {
      "x": -24,
      "y": 32,
      "z": 21,
      "name": "Cloud"
    },
    {
      "x": -24,
      "y": 33,
      "z": 21,
      "name": "Cloud"
    },
    {
      "x": -24,
      "y": 32,
      "z": 22,
      "name": "Cloud"
    },
    {
      "x": -24,
      "y": 32,
      "z": 23,
      "name": "Cloud",
      "support": 15
    },
    {
      "x": -24,
      "y": 25,
      "z": 40,
      "name": "Cloud",
      "support": 15
    },
    {
      "x": -24,
      "y": 25,
      "z": 41,
      "name": "Cloud",
      "support": 15
    },
    {
      "x": -23,
      "y": 31,
      "z": -46,
      "name": "Cloud",
      "support": 15
    },
    {
      "x": -23,
      "y": 24,
      "z": -44,
      "name": "Cloud"
    },
    {
      "x": -23,
      "y": 25,
      "z": -44,
      "name": "Cloud"
    },
    {
      "x": -23,
      "y": 26,
      "z": -44,
      "name": "Cloud"
    },
    {
      "x": -23,
      "y": 24,
      "z": -43,
      "name": "Cloud"
    },
    {
      "x": -23,
      "y": 25,
      "z": -43,
      "name": "Cloud"
    },
    {
      "x": -23,
      "y": 26,
      "z": -43,
      "name": "Cloud"
    },
    {
      "x": -23,
      "y": 24,
      "z": -42,
      "name": "Cloud"
    },
    {
      "x": -23,
      "y": 25,
      "z": -42,
      "name": "Cloud"
    },
    {
      "x": -23,
      "y": 26,
      "z": -42,
      "name": "Cloud"
    },
    {
      "x": -23,
      "y": 24,
      "z": -41,
      "name": "Cloud"
    },
    {
      "x": -23,
      "y": 25,
      "z": -41,
      "name": "Cloud"
    },
    {
      "x": -23,
      "y": 26,
      "z": -41,
      "name": "Cloud"
    },
    {
      "x": -23,
      "y": 24,
      "z": -40,
      "name": "Cloud"
    },
    {
      "x": -23,
      "y": 25,
      "z": -40,
      "name": "Cloud"
    },
    {
      "x": -23,
      "y": 33,
      "z": -21,
      "name": "Cloud",
      "support": 15
    },
    {
      "x": -23,
      "y": 33,
      "z": -20,
      "name": "Cloud"
    },
    {
      "x": -23,
      "y": 32,
      "z": 22,
      "name": "Cloud"
    },
    {
      "x": -23,
      "y": 32,
      "z": 23,
      "name": "Cloud"
    },
    {
      "x": -23,
      "y": 32,
      "z": 24,
      "name": "Cloud",
      "support": 15
    },
    {
      "x": -23,
      "y": 25,
      "z": 41,
      "name": "Cloud",
      "support": 15
    },
    {
      "x": -23,
      "y": 25,
      "z": 42,
      "name": "Cloud",
      "support": 15
    },
    {
      "x": -22,
      "y": 31,
      "z": -46,
      "name": "Cloud",
      "support": 15
    },
    {
      "x": -22,
      "y": 24,
      "z": -44,
      "name": "Cloud"
    },
    {
      "x": -22,
      "y": 25,
      "z": -44,
      "name": "Cloud"
    },
    {
      "x": -22,
      "y": 26,
      "z": -44,
      "name": "Cloud"
    },
    {
      "x": -22,
      "y": 24,
      "z": -43,
      "name": "Cloud"
    },
    {
      "x": -22,
      "y": 25,
      "z": -43,
      "name": "Cloud"
    },
    {
      "x": -22,
      "y": 26,
      "z": -43,
      "name": "Cloud"
    },
    {
      "x": -22,
      "y": 24,
      "z": -42,
      "name": "Cloud"
    },
    {
      "x": -22,
      "y": 25,
      "z": -42,
      "name": "Cloud"
    },
    {
      "x": -22,
      "y": 26,
      "z": -42,
      "name": "Cloud"
    },
    {
      "x": -22,
      "y": 24,
      "z": -41,
      "name": "Cloud"
    },
    {
      "x": -22,
      "y": 25,
      "z": -41,
      "name": "Cloud"
    },
    {
      "x": -22,
      "y": 26,
      "z": -41,
      "name": "Cloud"
    },
    {
      "x": -22,
      "y": 24,
      "z": -40,
      "name": "Cloud"
    },
    {
      "x": -22,
      "y": 25,
      "z": -40,
      "name": "Cloud"
    },
    {
      "x": -22,
      "y": 33,
      "z": -22,
      "name": "Cloud",
      "support": 15
    },
    {
      "x": -22,
      "y": 33,
      "z": -21,
      "name": "Cloud",
      "support": 15
    },
    {
      "x": -22,
      "y": 32,
      "z": 22,
      "name": "Cloud"
    },
    {
      "x": -22,
      "y": 32,
      "z": 23,
      "name": "Cloud"
    },
    {
      "x": -22,
      "y": 33,
      "z": 23,
      "name": "Cloud"
    },
    {
      "x": -22,
      "y": 32,
      "z": 24,
      "name": "Cloud"
    },
    {
      "x": -22,
      "y": 32,
      "z": 25,
      "name": "Cloud"
    },
    {
      "x": -22,
      "y": 25,
      "z": 41,
      "name": "Cloud",
      "support": 15
    },
    {
      "x": -22,
      "y": 26,
      "z": 41,
      "name": "Cloud",
      "support": 15
    },
    {
      "x": -22,
      "y": 25,
      "z": 42,
      "name": "Cloud",
      "support": 15
    },
    {
      "x": -22,
      "y": 26,
      "z": 42,
      "name": "Cloud",
      "support": 15
    },
    {
      "x": -21,
      "y": 31,
      "z": -47,
      "name": "Cloud",
      "support": 15
    },
    {
      "x": -21,
      "y": 24,
      "z": -44,
      "name": "Cloud"
    },
    {
      "x": -21,
      "y": 25,
      "z": -44,
      "name": "Cloud"
    },
    {
      "x": -21,
      "y": 26,
      "z": -44,
      "name": "Cloud"
    },
    {
      "x": -21,
      "y": 24,
      "z": -43,
      "name": "Cloud"
    },
    {
      "x": -21,
      "y": 25,
      "z": -43,
      "name": "Cloud"
    },
    {
      "x": -21,
      "y": 26,
      "z": -43,
      "name": "Cloud"
    },
    {
      "x": -21,
      "y": 24,
      "z": -42,
      "name": "Cloud"
    },
    {
      "x": -21,
      "y": 25,
      "z": -42,
      "name": "Cloud"
    },
    {
      "x": -21,
      "y": 26,
      "z": -42,
      "name": "Cloud"
    },
    {
      "x": -21,
      "y": 24,
      "z": -41,
      "name": "Cloud"
    },
    {
      "x": -21,
      "y": 25,
      "z": -41,
      "name": "Cloud"
    },
    {
      "x": -21,
      "y": 26,
      "z": -41,
      "name": "Cloud"
    },
    {
      "x": -21,
      "y": 33,
      "z": -23,
      "name": "Cloud",
      "support": 15
    },
    {
      "x": -21,
      "y": 32,
      "z": 24,
      "name": "Cloud"
    },
    {
      "x": -21,
      "y": 33,
      "z": 24,
      "name": "Cloud"
    },
    {
      "x": -21,
      "y": 32,
      "z": 25,
      "name": "Cloud"
    },
    {
      "x": -21,
      "y": 32,
      "z": 26,
      "name": "Cloud"
    },
    {
      "x": -21,
      "y": 25,
      "z": 41,
      "name": "Cloud",
      "support": 15
    },
    {
      "x": -21,
      "y": 26,
      "z": 41,
      "name": "Cloud",
      "support": 15
    },
    {
      "x": -21,
      "y": 25,
      "z": 42,
      "name": "Cloud",
      "support": 15
    },
    {
      "x": -21,
      "y": 26,
      "z": 42,
      "name": "Cloud",
      "support": 15
    },
    {
      "x": -21,
      "y": 25,
      "z": 43,
      "name": "Cloud",
      "support": 15
    },
    {
      "x": -20,
      "y": 31,
      "z": -47,
      "name": "Cloud",
      "support": 15
    },
    {
      "x": -20,
      "y": 24,
      "z": -45,
      "name": "Cloud",
      "support": 15
    },
    {
      "x": -20,
      "y": 25,
      "z": -45,
      "name": "Cloud",
      "support": 15
    },
    {
      "x": -20,
      "y": 26,
      "z": -45,
      "name": "Cloud",
      "support": 15
    },
    {
      "x": -20,
      "y": 24,
      "z": -44,
      "name": "Cloud",
      "support": 15
    },
    {
      "x": -20,
      "y": 25,
      "z": -44,
      "name": "Cloud",
      "support": 15
    },
    {
      "x": -20,
      "y": 26,
      "z": -44,
      "name": "Cloud",
      "support": 15
    },
    {
      "x": -20,
      "y": 24,
      "z": -43,
      "name": "Cloud"
    },
    {
      "x": -20,
      "y": 25,
      "z": -43,
      "name": "Cloud"
    },
    {
      "x": -20,
      "y": 26,
      "z": -43,
      "name": "Cloud"
    },
    {
      "x": -20,
      "y": 24,
      "z": -42,
      "name": "Cloud"
    },
    {
      "x": -20,
      "y": 25,
      "z": -42,
      "name": "Cloud"
    },
    {
      "x": -20,
      "y": 26,
      "z": -42,
      "name": "Cloud"
    },
    {
      "x": -20,
      "y": 24,
      "z": -41,
      "name": "Cloud"
    },
    {
      "x": -20,
      "y": 25,
      "z": -41,
      "name": "Cloud"
    },
    {
      "x": -20,
      "y": 33,
      "z": -23,
      "name": "Cloud",
      "support": 15
    },
    {
      "x": -20,
      "y": 32,
      "z": 26,
      "name": "Cloud",
      "support": 15
    },
    {
      "x": -20,
      "y": 25,
      "z": 42,
      "name": "Cloud",
      "support": 15
    },
    {
      "x": -20,
      "y": 25,
      "z": 43,
      "name": "Cloud",
      "support": 15
    },
    {
      "x": -20,
      "y": 25,
      "z": 44,
      "name": "Cloud",
      "support": 15
    },
    {
      "x": -19,
      "y": 31,
      "z": -47,
      "name": "Cloud",
      "support": 15
    },
    {
      "x": -19,
      "y": 24,
      "z": -45,
      "name": "Cloud"
    },
    {
      "x": -19,
      "y": 25,
      "z": -45,
      "name": "Cloud"
    },
    {
      "x": -19,
      "y": 26,
      "z": -45,
      "name": "Cloud"
    },
    {
      "x": -19,
      "y": 24,
      "z": -44,
      "name": "Cloud"
    },
    {
      "x": -19,
      "y": 25,
      "z": -44,
      "name": "Cloud"
    },
    {
      "x": -19,
      "y": 26,
      "z": -44,
      "name": "Cloud"
    },
    {
      "x": -19,
      "y": 24,
      "z": -43,
      "name": "Cloud"
    },
    {
      "x": -19,
      "y": 25,
      "z": -43,
      "name": "Cloud"
    },
    {
      "x": -19,
      "y": 26,
      "z": -43,
      "name": "Cloud"
    },
    {
      "x": -19,
      "y": 24,
      "z": -42,
      "name": "Cloud",
      "support": 15
    },
    {
      "x": -19,
      "y": 25,
      "z": -42,
      "name": "Cloud",
      "support": 15
    },
    {
      "x": -19,
      "y": 33,
      "z": -25,
      "name": "Cloud",
      "support": 15
    },
    {
      "x": -19,
      "y": 32,
      "z": 27,
      "name": "Cloud",
      "support": 15
    },
    {
      "x": -19,
      "y": 25,
      "z": 42,
      "name": "Cloud",
      "support": 15
    },
    {
      "x": -19,
      "y": 24,
      "z": 43,
      "name": "Cloud"
    },
    {
      "x": -19,
      "y": 25,
      "z": 43,
      "name": "Cloud"
    },
    {
      "x": -19,
      "y": 24,
      "z": 44,
      "name": "Cloud"
    },
    {
      "x": -19,
      "y": 25,
      "z": 44,
      "name": "Cloud"
    },
    {
      "x": -19,
      "y": 24,
      "z": 45,
      "name": "Cloud"
    },
    {
      "x": -19,
      "y": 25,
      "z": 45,
      "name": "Cloud"
    },
    {
      "x": -18,
      "y": 24,
      "z": -46,
      "name": "Cloud"
    },
    {
      "x": -18,
      "y": 25,
      "z": -46,
      "name": "Cloud"
    },
    {
      "x": -18,
      "y": 26,
      "z": -46,
      "name": "Cloud"
    },
    {
      "x": -18,
      "y": 24,
      "z": -45,
      "name": "Cloud"
    },
    {
      "x": -18,
      "y": 25,
      "z": -45,
      "name": "Cloud"
    },
    {
      "x": -18,
      "y": 26,
      "z": -45,
      "name": "Cloud"
    },
    {
      "x": -18,
      "y": 24,
      "z": -44,
      "name": "Cloud"
    },
    {
      "x": -18,
      "y": 25,
      "z": -44,
      "name": "Cloud"
    },
    {
      "x": -18,
      "y": 26,
      "z": -44,
      "name": "Cloud"
    },
    {
      "x": -18,
      "y": 24,
      "z": -43,
      "name": "Cloud"
    },
    {
      "x": -18,
      "y": 25,
      "z": -43,
      "name": "Cloud"
    },
    {
      "x": -18,
      "y": 33,
      "z": -25,
      "name": "Cloud",
      "support": 15
    },
    {
      "x": -18,
      "y": 32,
      "z": 27,
      "name": "Cloud",
      "support": 15
    },
    {
      "x": -18,
      "y": 24,
      "z": 42,
      "name": "Cloud"
    },
    {
      "x": -18,
      "y": 25,
      "z": 42,
      "name": "Cloud"
    },
    {
      "x": -18,
      "y": 24,
      "z": 43,
      "name": "Cloud"
    },
    {
      "x": -18,
      "y": 25,
      "z": 43,
      "name": "Cloud"
    },
    {
      "x": -18,
      "y": 24,
      "z": 44,
      "name": "Cloud"
    },
    {
      "x": -18,
      "y": 25,
      "z": 44,
      "name": "Cloud"
    },
    {
      "x": -18,
      "y": 26,
      "z": 44,
      "name": "Cloud"
    },
    {
      "x": -18,
      "y": 24,
      "z": 45,
      "name": "Cloud"
    },
    {
      "x": -18,
      "y": 25,
      "z": 45,
      "name": "Cloud"
    },
    {
      "x": -18,
      "y": 26,
      "z": 45,
      "name": "Cloud"
    },
    {
      "x": -18,
      "y": 24,
      "z": 46,
      "name": "Cloud"
    },
    {
      "x": -18,
      "y": 25,
      "z": 46,
      "name": "Cloud"
    },
    {
      "x": -18,
      "y": 26,
      "z": 46,
      "name": "Cloud"
    },
    {
      "x": -17,
      "y": 24,
      "z": -46,
      "name": "Cloud"
    },
    {
      "x": -17,
      "y": 25,
      "z": -46,
      "name": "Cloud"
    },
    {
      "x": -17,
      "y": 26,
      "z": -46,
      "name": "Cloud"
    },
    {
      "x": -17,
      "y": 24,
      "z": -45,
      "name": "Cloud"
    },
    {
      "x": -17,
      "y": 25,
      "z": -45,
      "name": "Cloud"
    },
    {
      "x": -17,
      "y": 26,
      "z": -45,
      "name": "Cloud"
    },
    {
      "x": -17,
      "y": 24,
      "z": -44,
      "name": "Cloud"
    },
    {
      "x": -17,
      "y": 25,
      "z": -44,
      "name": "Cloud"
    },
    {
      "x": -17,
      "y": 26,
      "z": -44,
      "name": "Cloud"
    },
    {
      "x": -17,
      "y": 24,
      "z": -43,
      "name": "Cloud"
    },
    {
      "x": -17,
      "y": 25,
      "z": -43,
      "name": "Cloud"
    },
    {
      "x": -17,
      "y": 17,
      "z": 3,
      "name": "Soil_Clay_Red"
    },
    {
      "x": -17,
      "y": 18,
      "z": 3,
      "name": "Soil_Clay_Red"
    },
    {
      "x": -17,
      "y": 19,
      "z": 3,
      "name": "Soil_Clay_Red"
    },
    {
      "x": -17,
      "y": 20,
      "z": 3,
      "name": "Soil_Clay_Red"
    },
    {
      "x": -17,
      "y": 21,
      "z": 3,
      "name": "Soil_Snow"
    },
    {
      "x": -17,
      "y": 17,
      "z": 4,
      "name": "Soil_Clay_Red"
    },
    {
      "x": -17,
      "y": 18,
      "z": 4,
      "name": "Soil_Clay_Red"
    },
    {
      "x": -17,
      "y": 19,
      "z": 4,
      "name": "Soil_Clay_Red"
    },
    {
      "x": -17,
      "y": 20,
      "z": 4,
      "name": "Soil_Clay_Red"
    },
    {
      "x": -17,
      "y": 21,
      "z": 4,
      "name": "Soil_Snow"
    },
    {
      "x": -17,
      "y": 17,
      "z": 5,
      "name": "Soil_Clay_Red"
    },
    {
      "x": -17,
      "y": 18,
      "z": 5,
      "name": "Soil_Clay_Red"
    },
    {
      "x": -17,
      "y": 19,
      "z": 5,
      "name": "Soil_Clay_Red"
    },
    {
      "x": -17,
      "y": 20,
      "z": 5,
      "name": "Soil_Clay_Red"
    },
    {
      "x": -17,
      "y": 21,
      "z": 5,
      "name": "Soil_Snow"
    },
    {
      "x": -17,
      "y": 40,
      "z": 6,
      "name": "Cloud",
      "support": 15
    },
    {
      "x": -17,
      "y": 24,
      "z": 42,
      "name": "Cloud"
    },
    {
      "x": -17,
      "y": 25,
      "z": 42,
      "name": "Cloud"
    },
    {
      "x": -17,
      "y": 26,
      "z": 42,
      "name": "Cloud"
    },
    {
      "x": -17,
      "y": 24,
      "z": 43,
      "name": "Cloud"
    },
    {
      "x": -17,
      "y": 25,
      "z": 43,
      "name": "Cloud"
    },
    {
      "x": -17,
      "y": 24,
      "z": 44,
      "name": "Cloud"
    },
    {
      "x": -17,
      "y": 25,
      "z": 44,
      "name": "Cloud"
    },
    {
      "x": -17,
      "y": 26,
      "z": 44,
      "name": "Cloud"
    },
    {
      "x": -17,
      "y": 24,
      "z": 45,
      "name": "Cloud"
    },
    {
      "x": -17,
      "y": 25,
      "z": 45,
      "name": "Cloud"
    },
    {
      "x": -17,
      "y": 26,
      "z": 45,
      "name": "Cloud"
    },
    {
      "x": -17,
      "y": 24,
      "z": 46,
      "name": "Cloud"
    },
    {
      "x": -17,
      "y": 25,
      "z": 46,
      "name": "Cloud"
    },
    {
      "x": -16,
      "y": 24,
      "z": -47,
      "name": "Cloud",
      "support": 15
    },
    {
      "x": -16,
      "y": 26,
      "z": -47,
      "name": "Cloud",
      "support": 15
    },
    {
      "x": -16,
      "y": 24,
      "z": -46,
      "name": "Cloud"
    },
    {
      "x": -16,
      "y": 25,
      "z": -46,
      "name": "Cloud"
    },
    {
      "x": -16,
      "y": 26,
      "z": -46,
      "name": "Cloud"
    },
    {
      "x": -16,
      "y": 24,
      "z": -45,
      "name": "Cloud"
    },
    {
      "x": -16,
      "y": 25,
      "z": -45,
      "name": "Cloud"
    },
    {
      "x": -16,
      "y": 26,
      "z": -45,
      "name": "Cloud"
    },
    {
      "x": -16,
      "y": 24,
      "z": -44,
      "name": "Cloud"
    },
    {
      "x": -16,
      "y": 25,
      "z": -44,
      "name": "Cloud"
    },
    {
      "x": -16,
      "y": 26,
      "z": -44,
      "name": "Cloud"
    },
    {
      "x": -16,
      "y": 24,
      "z": -43,
      "name": "Cloud"
    },
    {
      "x": -16,
      "y": 25,
      "z": -43,
      "name": "Cloud"
    },
    {
      "x": -16,
      "y": 17,
      "z": 2,
      "name": "Soil_Clay_Red"
    },
    {
      "x": -16,
      "y": 18,
      "z": 2,
      "name": "Soil_Clay_Red"
    },
    {
      "x": -16,
      "y": 19,
      "z": 2,
      "name": "Soil_Clay_Red"
    },
    {
      "x": -16,
      "y": 20,
      "z": 2,
      "name": "Soil_Snow"
    },
    {
      "x": -16,
      "y": 21,
      "z": 2,
      "name": "Soil_Snow"
    },
    {
      "x": -16,
      "y": 17,
      "z": 3,
      "name": "Soil_Clay_Red"
    },
    {
      "x": -16,
      "y": 18,
      "z": 3,
      "name": "Soil_Clay_Red"
    },
    {
      "x": -16,
      "y": 19,
      "z": 3,
      "name": "Soil_Clay_Red"
    },
    {
      "x": -16,
      "y": 20,
      "z": 3,
      "name": "Soil_Clay_Red"
    },
    {
      "x": -16,
      "y": 21,
      "z": 3,
      "name": "Soil_Snow"
    },
    {
      "x": -16,
      "y": 17,
      "z": 4,
      "name": "Soil_Clay_Red"
    },
    {
      "x": -16,
      "y": 18,
      "z": 4,
      "name": "Soil_Clay_Red"
    },
    {
      "x": -16,
      "y": 19,
      "z": 4,
      "name": "Soil_Clay_Red"
    },
    {
      "x": -16,
      "y": 20,
      "z": 4,
      "name": "Soil_Clay_Red"
    },
    {
      "x": -16,
      "y": 21,
      "z": 4,
      "name": "Soil_Snow"
    },
    {
      "x": -16,
      "y": 17,
      "z": 5,
      "name": "Soil_Clay_Red"
    },
    {
      "x": -16,
      "y": 18,
      "z": 5,
      "name": "Soil_Clay_Red"
    },
    {
      "x": -16,
      "y": 19,
      "z": 5,
      "name": "Soil_Clay_Red"
    },
    {
      "x": -16,
      "y": 20,
      "z": 5,
      "name": "Soil_Clay_Red"
    },
    {
      "x": -16,
      "y": 21,
      "z": 5,
      "name": "Soil_Snow"
    },
    {
      "x": -16,
      "y": 17,
      "z": 6,
      "name": "Soil_Clay_Red"
    },
    {
      "x": -16,
      "y": 18,
      "z": 6,
      "name": "Soil_Clay_Red"
    },
    {
      "x": -16,
      "y": 19,
      "z": 6,
      "name": "Soil_Clay_Red"
    },
    {
      "x": -16,
      "y": 20,
      "z": 6,
      "name": "Soil_Clay_Red"
    },
    {
      "x": -16,
      "y": 21,
      "z": 6,
      "name": "Soil_Snow"
    },
    {
      "x": -16,
      "y": 40,
      "z": 9,
      "name": "Cloud",
      "support": 15
    },
    {
      "x": -16,
      "y": 40,
      "z": 10,
      "name": "Cloud",
      "support": 15
    },
    {
      "x": -16,
      "y": 40,
      "z": 11,
      "name": "Cloud",
      "support": 15
    },
    {
      "x": -16,
      "y": 32,
      "z": 28,
      "name": "Cloud",
      "support": 15
    },
    {
      "x": -16,
      "y": 24,
      "z": 42,
      "name": "Cloud"
    },
    {
      "x": -16,
      "y": 25,
      "z": 42,
      "name": "Cloud"
    },
    {
      "x": -16,
      "y": 24,
      "z": 43,
      "name": "Cloud"
    },
    {
      "x": -16,
      "y": 25,
      "z": 43,
      "name": "Cloud"
    },
    {
      "x": -16,
      "y": 23,
      "z": 44,
      "name": "Cloud",
      "support": 15
    },
    {
      "x": -16,
      "y": 24,
      "z": 44,
      "name": "Cloud"
    },
    {
      "x": -16,
      "y": 25,
      "z": 44,
      "name": "Cloud"
    },
    {
      "x": -16,
      "y": 26,
      "z": 44,
      "name": "Cloud"
    },
    {
      "x": -16,
      "y": 23,
      "z": 45,
      "name": "Cloud",
      "support": 15
    },
    {
      "x": -16,
      "y": 24,
      "z": 45,
      "name": "Cloud"
    },
    {
      "x": -16,
      "y": 25,
      "z": 45,
      "name": "Cloud"
    },
    {
      "x": -16,
      "y": 26,
      "z": 45,
      "name": "Cloud"
    },
    {
      "x": -16,
      "y": 24,
      "z": 46,
      "name": "Cloud"
    },
    {
      "x": -16,
      "y": 25,
      "z": 46,
      "name": "Cloud"
    },
    {
      "x": -15,
      "y": 24,
      "z": -47,
      "name": "Cloud",
      "support": 15
    },
    {
      "x": -15,
      "y": 25,
      "z": -47,
      "name": "Cloud",
      "support": 15
    },
    {
      "x": -15,
      "y": 24,
      "z": -46,
      "name": "Cloud",
      "support": 15
    },
    {
      "x": -15,
      "y": 25,
      "z": -46,
      "name": "Cloud",
      "support": 15
    },
    {
      "x": -15,
      "y": 24,
      "z": -45,
      "name": "Cloud"
    },
    {
      "x": -15,
      "y": 25,
      "z": -45,
      "name": "Cloud"
    },
    {
      "x": -15,
      "y": 26,
      "z": -45,
      "name": "Cloud"
    },
    {
      "x": -15,
      "y": 24,
      "z": -44,
      "name": "Cloud"
    },
    {
      "x": -15,
      "y": 25,
      "z": -44,
      "name": "Cloud"
    },
    {
      "x": -15,
      "y": 26,
      "z": -44,
      "name": "Cloud"
    },
    {
      "x": -15,
      "y": 17,
      "z": 2,
      "name": "Soil_Clay_Red"
    },
    {
      "x": -15,
      "y": 18,
      "z": 2,
      "name": "Soil_Clay_Red"
    },
    {
      "x": -15,
      "y": 19,
      "z": 2,
      "name": "Soil_Clay_Red"
    },
    {
      "x": -15,
      "y": 20,
      "z": 2,
      "name": "Soil_Clay_Red"
    },
    {
      "x": -15,
      "y": 21,
      "z": 2,
      "name": "Soil_Snow"
    },
    {
      "x": -15,
      "y": 17,
      "z": 3,
      "name": "Soil_Clay_Red"
    },
    {
      "x": -15,
      "y": 18,
      "z": 3,
      "name": "Soil_Clay_Red"
    },
    {
      "x": -15,
      "y": 19,
      "z": 3,
      "name": "Soil_Clay_Red"
    },
    {
      "x": -15,
      "y": 20,
      "z": 3,
      "name": "Soil_Clay_Red"
    },
    {
      "x": -15,
      "y": 21,
      "z": 3,
      "name": "Soil_Snow"
    },
    {
      "x": -15,
      "y": 17,
      "z": 4,
      "name": "Soil_Clay_Red"
    },
    {
      "x": -15,
      "y": 18,
      "z": 4,
      "name": "Soil_Clay_Red"
    },
    {
      "x": -15,
      "y": 19,
      "z": 4,
      "name": "Soil_Clay_Red"
    },
    {
      "x": -15,
      "y": 20,
      "z": 4,
      "name": "Soil_Clay_Red"
    },
    {
      "x": -15,
      "y": 21,
      "z": 4,
      "name": "Soil_Snow"
    },
    {
      "x": -15,
      "y": 17,
      "z": 5,
      "name": "Soil_Clay_Red"
    },
    {
      "x": -15,
      "y": 18,
      "z": 5,
      "name": "Soil_Clay_Red"
    },
    {
      "x": -15,
      "y": 19,
      "z": 5,
      "name": "Soil_Clay_Red"
    },
    {
      "x": -15,
      "y": 20,
      "z": 5,
      "name": "Soil_Clay_Red"
    },
    {
      "x": -15,
      "y": 21,
      "z": 5,
      "name": "Soil_Snow"
    },
    {
      "x": -15,
      "y": 17,
      "z": 6,
      "name": "Soil_Clay_Red"
    },
    {
      "x": -15,
      "y": 18,
      "z": 6,
      "name": "Soil_Clay_Red"
    },
    {
      "x": -15,
      "y": 19,
      "z": 6,
      "name": "Soil_Clay_Red"
    },
    {
      "x": -15,
      "y": 20,
      "z": 6,
      "name": "Soil_Clay_Red"
    },
    {
      "x": -15,
      "y": 21,
      "z": 6,
      "name": "Soil_Snow"
    },
    {
      "x": -15,
      "y": 40,
      "z": 10,
      "name": "Cloud",
      "support": 15
    },
    {
      "x": -15,
      "y": 40,
      "z": 11,
      "name": "Cloud",
      "support": 15
    },
    {
      "x": -15,
      "y": 41,
      "z": 11,
      "name": "Cloud",
      "support": 15
    },
    {
      "x": -15,
      "y": 40,
      "z": 12,
      "name": "Cloud",
      "support": 15
    },
    {
      "x": -15,
      "y": 32,
      "z": 28,
      "name": "Cloud",
      "support": 15
    },
    {
      "x": -15,
      "y": 32,
      "z": 29,
      "name": "Cloud",
      "support": 15
    },
    {
      "x": -15,
      "y": 24,
      "z": 43,
      "name": "Cloud"
    },
    {
      "x": -15,
      "y": 25,
      "z": 43,
      "name": "Cloud"
    },
    {
      "x": -15,
      "y": 23,
      "z": 44,
      "name": "Cloud",
      "support": 15
    },
    {
      "x": -15,
      "y": 24,
      "z": 44,
      "name": "Cloud"
    },
    {
      "x": -15,
      "y": 25,
      "z": 44,
      "name": "Cloud"
    },
    {
      "x": -15,
      "y": 26,
      "z": 44,
      "name": "Cloud"
    },
    {
      "x": -15,
      "y": 23,
      "z": 45,
      "name": "Cloud",
      "support": 15
    },
    {
      "x": -15,
      "y": 24,
      "z": 45,
      "name": "Cloud"
    },
    {
      "x": -15,
      "y": 25,
      "z": 45,
      "name": "Cloud"
    },
    {
      "x": -15,
      "y": 26,
      "z": 45,
      "name": "Cloud"
    },
    {
      "x": -15,
      "y": 24,
      "z": 46,
      "name": "Cloud"
    },
    {
      "x": -15,
      "y": 25,
      "z": 46,
      "name": "Cloud"
    },
    {
      "x": -15,
      "y": 26,
      "z": 46,
      "name": "Cloud"
    },
    {
      "x": -15,
      "y": 24,
      "z": 47,
      "name": "Cloud"
    },
    {
      "x": -15,
      "y": 25,
      "z": 47,
      "name": "Cloud"
    },
    {
      "x": -14,
      "y": 24,
      "z": -47,
      "name": "Cloud"
    },
    {
      "x": -14,
      "y": 25,
      "z": -47,
      "name": "Cloud"
    },
    {
      "x": -14,
      "y": 24,
      "z": -46,
      "name": "Cloud"
    },
    {
      "x": -14,
      "y": 25,
      "z": -46,
      "name": "Cloud"
    },
    {
      "x": -14,
      "y": 26,
      "z": -46,
      "name": "Cloud"
    },
    {
      "x": -14,
      "y": 24,
      "z": -45,
      "name": "Cloud"
    },
    {
      "x": -14,
      "y": 25,
      "z": -45,
      "name": "Cloud"
    },
    {
      "x": -14,
      "y": 26,
      "z": -45,
      "name": "Cloud"
    },
    {
      "x": -14,
      "y": 25,
      "z": -44,
      "name": "Cloud",
      "support": 15
    },
    {
      "x": -14,
      "y": 18,
      "z": -3,
      "name": "Soil_Snow"
    },
    {
      "x": -14,
      "y": 19,
      "z": -3,
      "name": "Soil_Snow"
    },
    {
      "x": -14,
      "y": 20,
      "z": -3,
      "name": "Soil_Snow"
    },
    {
      "x": -14,
      "y": 21,
      "z": -3,
      "name": "Soil_Snow"
    },
    {
      "x": -14,
      "y": 18,
      "z": -2,
      "name": "Soil_Snow"
    },
    {
      "x": -14,
      "y": 19,
      "z": -2,
      "name": "Soil_Snow"
    },
    {
      "x": -14,
      "y": 20,
      "z": -2,
      "name": "Soil_Snow"
    },
    {
      "x": -14,
      "y": 21,
      "z": -2,
      "name": "Soil_Snow"
    },
    {
      "x": -14,
      "y": 22,
      "z": -2,
      "name": "Soil_Snow"
    },
    {
      "x": -14,
      "y": 18,
      "z": -1,
      "name": "Soil_Snow"
    },
    {
      "x": -14,
      "y": 19,
      "z": -1,
      "name": "Soil_Snow"
    },
    {
      "x": -14,
      "y": 20,
      "z": -1,
      "name": "Soil_Snow"
    },
    {
      "x": -14,
      "y": 21,
      "z": -1,
      "name": "Soil_Snow"
    },
    {
      "x": -14,
      "y": 17,
      "z": 2,
      "name": "Soil_Clay_Red"
    },
    {
      "x": -14,
      "y": 18,
      "z": 2,
      "name": "Soil_Clay_Red"
    },
    {
      "x": -14,
      "y": 19,
      "z": 2,
      "name": "Soil_Clay_Red"
    },
    {
      "x": -14,
      "y": 20,
      "z": 2,
      "name": "Soil_Clay_Red"
    },
    {
      "x": -14,
      "y": 21,
      "z": 2,
      "name": "Soil_Snow"
    },
    {
      "x": -14,
      "y": 17,
      "z": 3,
      "name": "Soil_Clay_Red"
    },
    {
      "x": -14,
      "y": 18,
      "z": 3,
      "name": "Soil_Clay_Red"
    },
    {
      "x": -14,
      "y": 19,
      "z": 3,
      "name": "Soil_Clay_Red"
    },
    {
      "x": -14,
      "y": 20,
      "z": 3,
      "name": "Soil_Clay_Red"
    },
    {
      "x": -14,
      "y": 21,
      "z": 3,
      "name": "Soil_Snow"
    },
    {
      "x": -14,
      "y": 17,
      "z": 4,
      "name": "Soil_Clay_Red"
    },
    {
      "x": -14,
      "y": 18,
      "z": 4,
      "name": "Soil_Clay_Red"
    },
    {
      "x": -14,
      "y": 19,
      "z": 4,
      "name": "Soil_Clay_Red"
    },
    {
      "x": -14,
      "y": 20,
      "z": 4,
      "name": "Soil_Clay_Red"
    },
    {
      "x": -14,
      "y": 21,
      "z": 4,
      "name": "Soil_Snow"
    },
    {
      "x": -14,
      "y": 17,
      "z": 5,
      "name": "Soil_Clay_Red"
    },
    {
      "x": -14,
      "y": 18,
      "z": 5,
      "name": "Soil_Clay_Red"
    },
    {
      "x": -14,
      "y": 19,
      "z": 5,
      "name": "Soil_Clay_Red"
    },
    {
      "x": -14,
      "y": 20,
      "z": 5,
      "name": "Soil_Clay_Red"
    },
    {
      "x": -14,
      "y": 21,
      "z": 5,
      "name": "Soil_Snow"
    },
    {
      "x": -14,
      "y": 17,
      "z": 6,
      "name": "Soil_Clay_Red"
    },
    {
      "x": -14,
      "y": 18,
      "z": 6,
      "name": "Soil_Clay_Red"
    },
    {
      "x": -14,
      "y": 19,
      "z": 6,
      "name": "Soil_Clay_Red"
    },
    {
      "x": -14,
      "y": 20,
      "z": 6,
      "name": "Soil_Clay_Red"
    },
    {
      "x": -14,
      "y": 21,
      "z": 6,
      "name": "Soil_Snow"
    },
    {
      "x": -14,
      "y": 40,
      "z": 12,
      "name": "Cloud",
      "support": 15
    },
    {
      "x": -14,
      "y": 40,
      "z": 13,
      "name": "Cloud",
      "support": 15
    },
    {
      "x": -14,
      "y": 40,
      "z": 14,
      "name": "Cloud",
      "support": 15
    },
    {
      "x": -14,
      "y": 41,
      "z": 14,
      "name": "Cloud",
      "support": 15
    },
    {
      "x": -14,
      "y": 32,
      "z": 29,
      "name": "Cloud",
      "support": 15
    },
    {
      "x": -14,
      "y": 24,
      "z": 43,
      "name": "Cloud"
    },
    {
      "x": -14,
      "y": 25,
      "z": 43,
      "name": "Cloud"
    },
    {
      "x": -14,
      "y": 24,
      "z": 44,
      "name": "Cloud"
    },
    {
      "x": -14,
      "y": 25,
      "z": 44,
      "name": "Cloud"
    },
    {
      "x": -14,
      "y": 26,
      "z": 44,
      "name": "Cloud"
    },
    {
      "x": -14,
      "y": 24,
      "z": 45,
      "name": "Cloud"
    },
    {
      "x": -14,
      "y": 25,
      "z": 45,
      "name": "Cloud"
    },
    {
      "x": -14,
      "y": 26,
      "z": 45,
      "name": "Cloud"
    },
    {
      "x": -14,
      "y": 24,
      "z": 46,
      "name": "Cloud"
    },
    {
      "x": -14,
      "y": 25,
      "z": 46,
      "name": "Cloud"
    },
    {
      "x": -14,
      "y": 24,
      "z": 47,
      "name": "Cloud"
    },
    {
      "x": -14,
      "y": 25,
      "z": 47,
      "name": "Cloud"
    },
    {
      "x": -13,
      "y": 24,
      "z": -47,
      "name": "Cloud"
    },
    {
      "x": -13,
      "y": 25,
      "z": -47,
      "name": "Cloud"
    },
    {
      "x": -13,
      "y": 24,
      "z": -46,
      "name": "Cloud"
    },
    {
      "x": -13,
      "y": 25,
      "z": -46,
      "name": "Cloud"
    },
    {
      "x": -13,
      "y": 26,
      "z": -46,
      "name": "Cloud"
    },
    {
      "x": -13,
      "y": 24,
      "z": -45,
      "name": "Cloud"
    },
    {
      "x": -13,
      "y": 25,
      "z": -45,
      "name": "Cloud"
    },
    {
      "x": -13,
      "y": 26,
      "z": -45,
      "name": "Cloud"
    },
    {
      "x": -13,
      "y": 24,
      "z": -44,
      "name": "Cloud"
    },
    {
      "x": -13,
      "y": 26,
      "z": -44,
      "name": "Cloud",
      "support": 15
    },
    {
      "x": -13,
      "y": 18,
      "z": -4,
      "name": "Soil_Snow"
    },
    {
      "x": -13,
      "y": 19,
      "z": -4,
      "name": "Soil_Snow"
    },
    {
      "x": -13,
      "y": 20,
      "z": -4,
      "name": "Soil_Snow"
    },
    {
      "x": -13,
      "y": 21,
      "z": -4,
      "name": "Soil_Snow"
    },
    {
      "x": -13,
      "y": 13,
      "z": -3,
      "name": "Soil_Clay_Red"
    },
    {
      "x": -13,
      "y": 14,
      "z": -3,
      "name": "Soil_Clay_Red"
    },
    {
      "x": -13,
      "y": 15,
      "z": -3,
      "name": "Soil_Clay_Purple"
    },
    {
      "x": -13,
      "y": 16,
      "z": -3,
      "name": "Soil_Clay_Red"
    },
    {
      "x": -13,
      "y": 17,
      "z": -3,
      "name": "Soil_Clay_Red"
    },
    {
      "x": -13,
      "y": 18,
      "z": -3,
      "name": "Soil_Clay_Red"
    },
    {
      "x": -13,
      "y": 19,
      "z": -3,
      "name": "Soil_Snow"
    },
    {
      "x": -13,
      "y": 20,
      "z": -3,
      "name": "Soil_Snow"
    },
    {
      "x": -13,
      "y": 21,
      "z": -3,
      "name": "Soil_Snow"
    },
    {
      "x": -13,
      "y": 22,
      "z": -3,
      "name": "Soil_Snow"
    },
    {
      "x": -13,
      "y": 13,
      "z": -2,
      "name": "Soil_Clay_Red"
    },
    {
      "x": -13,
      "y": 14,
      "z": -2,
      "name": "Soil_Clay_Red"
    },
    {
      "x": -13,
      "y": 15,
      "z": -2,
      "name": "Soil_Clay_Red"
    },
    {
      "x": -13,
      "y": 16,
      "z": -2,
      "name": "Soil_Clay_Red"
    },
    {
      "x": -13,
      "y": 17,
      "z": -2,
      "name": "Soil_Clay_Red"
    },
    {
      "x": -13,
      "y": 18,
      "z": -2,
      "name": "Soil_Clay_Red"
    },
    {
      "x": -13,
      "y": 19,
      "z": -2,
      "name": "Soil_Snow"
    },
    {
      "x": -13,
      "y": 20,
      "z": -2,
      "name": "Soil_Snow"
    },
    {
      "x": -13,
      "y": 21,
      "z": -2,
      "name": "Soil_Snow"
    },
    {
      "x": -13,
      "y": 22,
      "z": -2,
      "name": "Soil_Snow"
    },
    {
      "x": -13,
      "y": 13,
      "z": -1,
      "name": "Soil_Clay_Red"
    },
    {
      "x": -13,
      "y": 14,
      "z": -1,
      "name": "Soil_Clay_Purple"
    },
    {
      "x": -13,
      "y": 15,
      "z": -1,
      "name": "Soil_Clay_Purple"
    },
    {
      "x": -13,
      "y": 16,
      "z": -1,
      "name": "Soil_Clay_Purple"
    },
    {
      "x": -13,
      "y": 17,
      "z": -1,
      "name": "Soil_Clay_Red"
    },
    {
      "x": -13,
      "y": 18,
      "z": -1,
      "name": "Soil_Clay_Red"
    },
    {
      "x": -13,
      "y": 19,
      "z": -1,
      "name": "Soil_Snow"
    },
    {
      "x": -13,
      "y": 20,
      "z": -1,
      "name": "Soil_Snow"
    },
    {
      "x": -13,
      "y": 21,
      "z": -1,
      "name": "Soil_Snow"
    },
    {
      "x": -13,
      "y": 22,
      "z": -1,
      "name": "Soil_Snow"
    },
    {
      "x": -13,
      "y": 8,
      "z": 0,
      "name": "Soil_Clay_Red"
    },
    {
      "x": -13,
      "y": 9,
      "z": 0,
      "name": "Soil_Clay_Red"
    },
    {
      "x": -13,
      "y": 10,
      "z": 0,
      "name": "Soil_Clay_Red"
    },
    {
      "x": -13,
      "y": 11,
      "z": 0,
      "name": "Soil_Clay_Purple"
    },
    {
      "x": -13,
      "y": 12,
      "z": 0,
      "name": "Soil_Clay_Red"
    },
    {
      "x": -13,
      "y": 13,
      "z": 0,
      "name": "Soil_Clay_Purple"
    },
    {
      "x": -13,
      "y": 14,
      "z": 0,
      "name": "Soil_Clay_Purple"
    },
    {
      "x": -13,
      "y": 15,
      "z": 0,
      "name": "Soil_Clay_Purple"
    },
    {
      "x": -13,
      "y": 16,
      "z": 0,
      "name": "Soil_Clay_Purple"
    },
    {
      "x": -13,
      "y": 17,
      "z": 0,
      "name": "Soil_Clay_Red"
    },
    {
      "x": -13,
      "y": 18,
      "z": 0,
      "name": "Soil_Clay_Red"
    },
    {
      "x": -13,
      "y": 19,
      "z": 0,
      "name": "Soil_Snow"
    },
    {
      "x": -13,
      "y": 20,
      "z": 0,
      "name": "Soil_Snow"
    },
    {
      "x": -13,
      "y": 21,
      "z": 0,
      "name": "Soil_Snow"
    },
    {
      "x": -13,
      "y": 22,
      "z": 0,
      "name": "Soil_Snow"
    },
    {
      "x": -13,
      "y": 8,
      "z": 1,
      "name": "Soil_Clay_Red"
    },
    {
      "x": -13,
      "y": 9,
      "z": 1,
      "name": "Soil_Clay_Red"
    },
    {
      "x": -13,
      "y": 10,
      "z": 1,
      "name": "Soil_Clay_Red"
    },
    {
      "x": -13,
      "y": 11,
      "z": 1,
      "name": "Soil_Clay_Purple"
    },
    {
      "x": -13,
      "y": 12,
      "z": 1,
      "name": "Soil_Clay_Red"
    },
    {
      "x": -13,
      "y": 13,
      "z": 1,
      "name": "Soil_Clay_Purple"
    },
    {
      "x": -13,
      "y": 14,
      "z": 1,
      "name": "Soil_Clay_Purple"
    },
    {
      "x": -13,
      "y": 15,
      "z": 1,
      "name": "Soil_Clay_Purple"
    },
    {
      "x": -13,
      "y": 16,
      "z": 1,
      "name": "Soil_Clay_Purple"
    },
    {
      "x": -13,
      "y": 17,
      "z": 1,
      "name": "Soil_Clay_Red"
    },
    {
      "x": -13,
      "y": 18,
      "z": 1,
      "name": "Soil_Clay_Red"
    },
    {
      "x": -13,
      "y": 19,
      "z": 1,
      "name": "Soil_Snow"
    },
    {
      "x": -13,
      "y": 20,
      "z": 1,
      "name": "Soil_Snow"
    },
    {
      "x": -13,
      "y": 21,
      "z": 1,
      "name": "Soil_Snow"
    },
    {
      "x": -13,
      "y": 22,
      "z": 1,
      "name": "Soil_Snow"
    },
    {
      "x": -13,
      "y": 8,
      "z": 2,
      "name": "Soil_Clay_Red"
    },
    {
      "x": -13,
      "y": 9,
      "z": 2,
      "name": "Soil_Clay_Red"
    },
    {
      "x": -13,
      "y": 10,
      "z": 2,
      "name": "Soil_Clay_Red"
    },
    {
      "x": -13,
      "y": 11,
      "z": 2,
      "name": "Soil_Clay_Purple"
    },
    {
      "x": -13,
      "y": 12,
      "z": 2,
      "name": "Soil_Clay_Red"
    },
    {
      "x": -13,
      "y": 13,
      "z": 2,
      "name": "Soil_Clay_Purple"
    },
    {
      "x": -13,
      "y": 14,
      "z": 2,
      "name": "Soil_Clay_Purple"
    },
    {
      "x": -13,
      "y": 15,
      "z": 2,
      "name": "Soil_Clay_Purple"
    },
    {
      "x": -13,
      "y": 16,
      "z": 2,
      "name": "Soil_Clay_Red"
    },
    {
      "x": -13,
      "y": 17,
      "z": 2,
      "name": "Soil_Clay_Red"
    },
    {
      "x": -13,
      "y": 18,
      "z": 2,
      "name": "Soil_Clay_Red"
    },
    {
      "x": -13,
      "y": 19,
      "z": 2,
      "name": "Soil_Snow"
    },
    {
      "x": -13,
      "y": 20,
      "z": 2,
      "name": "Soil_Snow"
    },
    {
      "x": -13,
      "y": 21,
      "z": 2,
      "name": "Soil_Snow"
    },
    {
      "x": -13,
      "y": 22,
      "z": 2,
      "name": "Soil_Snow"
    },
    {
      "x": -13,
      "y": 8,
      "z": 3,
      "name": "Soil_Clay_Red"
    },
    {
      "x": -13,
      "y": 9,
      "z": 3,
      "name": "Soil_Clay_Red"
    },
    {
      "x": -13,
      "y": 10,
      "z": 3,
      "name": "Soil_Clay_Red"
    },
    {
      "x": -13,
      "y": 11,
      "z": 3,
      "name": "Soil_Clay_Purple"
    },
    {
      "x": -13,
      "y": 12,
      "z": 3,
      "name": "Soil_Clay_Red"
    },
    {
      "x": -13,
      "y": 13,
      "z": 3,
      "name": "Soil_Clay_Purple"
    },
    {
      "x": -13,
      "y": 14,
      "z": 3,
      "name": "Soil_Clay_Purple"
    },
    {
      "x": -13,
      "y": 15,
      "z": 3,
      "name": "Soil_Clay_Purple"
    },
    {
      "x": -13,
      "y": 16,
      "z": 3,
      "name": "Soil_Clay_Red"
    },
    {
      "x": -13,
      "y": 17,
      "z": 3,
      "name": "Soil_Clay_Red"
    },
    {
      "x": -13,
      "y": 18,
      "z": 3,
      "name": "Soil_Clay_Red"
    },
    {
      "x": -13,
      "y": 19,
      "z": 3,
      "name": "Soil_Clay_Red"
    },
    {
      "x": -13,
      "y": 20,
      "z": 3,
      "name": "Soil_Clay_Red"
    },
    {
      "x": -13,
      "y": 21,
      "z": 3,
      "name": "Soil_Snow"
    },
    {
      "x": -13,
      "y": 22,
      "z": 3,
      "name": "Soil_Snow"
    },
    {
      "x": -13,
      "y": 17,
      "z": 4,
      "name": "Soil_Clay_Red"
    },
    {
      "x": -13,
      "y": 18,
      "z": 4,
      "name": "Soil_Clay_Red"
    },
    {
      "x": -13,
      "y": 19,
      "z": 4,
      "name": "Soil_Clay_Red"
    },
    {
      "x": -13,
      "y": 20,
      "z": 4,
      "name": "Soil_Clay_Red"
    },
    {
      "x": -13,
      "y": 21,
      "z": 4,
      "name": "Soil_Snow"
    },
    {
      "x": -13,
      "y": 17,
      "z": 5,
      "name": "Soil_Clay_Red"
    },
    {
      "x": -13,
      "y": 18,
      "z": 5,
      "name": "Soil_Clay_Red"
    },
    {
      "x": -13,
      "y": 19,
      "z": 5,
      "name": "Soil_Clay_Red"
    },
    {
      "x": -13,
      "y": 20,
      "z": 5,
      "name": "Soil_Clay_Red"
    },
    {
      "x": -13,
      "y": 21,
      "z": 5,
      "name": "Soil_Snow"
    },
    {
      "x": -13,
      "y": 40,
      "z": 14,
      "name": "Cloud",
      "support": 15
    },
    {
      "x": -13,
      "y": 41,
      "z": 14,
      "name": "Cloud",
      "support": 15
    },
    {
      "x": -13,
      "y": 40,
      "z": 15,
      "name": "Cloud",
      "support": 15
    },
    {
      "x": -13,
      "y": 41,
      "z": 15,
      "name": "Cloud",
      "support": 15
    },
    {
      "x": -13,
      "y": 24,
      "z": 43,
      "name": "Cloud"
    },
    {
      "x": -13,
      "y": 25,
      "z": 43,
      "name": "Cloud"
    },
    {
      "x": -13,
      "y": 24,
      "z": 44,
      "name": "Cloud"
    },
    {
      "x": -13,
      "y": 25,
      "z": 44,
      "name": "Cloud"
    },
    {
      "x": -13,
      "y": 26,
      "z": 44,
      "name": "Cloud"
    },
    {
      "x": -13,
      "y": 24,
      "z": 45,
      "name": "Cloud"
    },
    {
      "x": -13,
      "y": 25,
      "z": 45,
      "name": "Cloud"
    },
    {
      "x": -13,
      "y": 26,
      "z": 45,
      "name": "Cloud"
    },
    {
      "x": -13,
      "y": 24,
      "z": 46,
      "name": "Cloud"
    },
    {
      "x": -13,
      "y": 25,
      "z": 46,
      "name": "Cloud"
    },
    {
      "x": -13,
      "y": 26,
      "z": 46,
      "name": "Cloud"
    },
    {
      "x": -13,
      "y": 24,
      "z": 47,
      "name": "Cloud"
    },
    {
      "x": -13,
      "y": 25,
      "z": 47,
      "name": "Cloud"
    },
    {
      "x": -12,
      "y": 24,
      "z": -48,
      "name": "Cloud"
    },
    {
      "x": -12,
      "y": 25,
      "z": -48,
      "name": "Cloud"
    },
    {
      "x": -12,
      "y": 24,
      "z": -47,
      "name": "Cloud"
    },
    {
      "x": -12,
      "y": 25,
      "z": -47,
      "name": "Cloud"
    },
    {
      "x": -12,
      "y": 26,
      "z": -47,
      "name": "Cloud"
    },
    {
      "x": -12,
      "y": 24,
      "z": -46,
      "name": "Cloud"
    },
    {
      "x": -12,
      "y": 25,
      "z": -46,
      "name": "Cloud"
    },
    {
      "x": -12,
      "y": 26,
      "z": -46,
      "name": "Cloud"
    },
    {
      "x": -12,
      "y": 24,
      "z": -45,
      "name": "Cloud"
    },
    {
      "x": -12,
      "y": 25,
      "z": -45,
      "name": "Cloud"
    },
    {
      "x": -12,
      "y": 26,
      "z": -45,
      "name": "Cloud"
    },
    {
      "x": -12,
      "y": 17,
      "z": -10,
      "name": "Soil_Clay_Purple"
    },
    {
      "x": -12,
      "y": 18,
      "z": -10,
      "name": "Soil_Clay_Red"
    },
    {
      "x": -12,
      "y": 19,
      "z": -10,
      "name": "Soil_Clay_Red"
    },
    {
      "x": -12,
      "y": 20,
      "z": -10,
      "name": "Soil_Snow"
    },
    {
      "x": -12,
      "y": 21,
      "z": -10,
      "name": "Soil_Snow"
    },
    {
      "x": -12,
      "y": 17,
      "z": -9,
      "name": "Soil_Clay_Purple"
    },
    {
      "x": -12,
      "y": 18,
      "z": -9,
      "name": "Soil_Clay_Red"
    },
    {
      "x": -12,
      "y": 19,
      "z": -9,
      "name": "Soil_Clay_Red"
    },
    {
      "x": -12,
      "y": 20,
      "z": -9,
      "name": "Soil_Clay_Red"
    },
    {
      "x": -12,
      "y": 21,
      "z": -9,
      "name": "Soil_Snow"
    },
    {
      "x": -12,
      "y": 17,
      "z": -8,
      "name": "Soil_Clay_Red"
    },
    {
      "x": -12,
      "y": 18,
      "z": -8,
      "name": "Soil_Clay_Red"
    },
    {
      "x": -12,
      "y": 19,
      "z": -8,
      "name": "Soil_Clay_Red"
    },
    {
      "x": -12,
      "y": 20,
      "z": -8,
      "name": "Soil_Clay_Red"
    },
    {
      "x": -12,
      "y": 21,
      "z": -8,
      "name": "Soil_Snow"
    },
    {
      "x": -12,
      "y": 12,
      "z": -5,
      "name": "Soil_Clay_Purple"
    },
    {
      "x": -12,
      "y": 13,
      "z": -5,
      "name": "Soil_Clay_Red"
    },
    {
      "x": -12,
      "y": 14,
      "z": -5,
      "name": "Soil_Clay_Red"
    },
    {
      "x": -12,
      "y": 15,
      "z": -5,
      "name": "Soil_Clay_Red"
    },
    {
      "x": -12,
      "y": 16,
      "z": -5,
      "name": "Soil_Clay_Red"
    },
    {
      "x": -12,
      "y": 17,
      "z": -5,
      "name": "Soil_Clay_Red"
    },
    {
      "x": -12,
      "y": 18,
      "z": -5,
      "name": "Soil_Clay_Red"
    },
    {
      "x": -12,
      "y": 19,
      "z": -5,
      "name": "Soil_Snow"
    },
    {
      "x": -12,
      "y": 20,
      "z": -5,
      "name": "Soil_Snow"
    },
    {
      "x": -12,
      "y": 21,
      "z": -5,
      "name": "Soil_Snow"
    },
    {
      "x": -12,
      "y": 22,
      "z": -5,
      "name": "Soil_Snow"
    },
    {
      "x": -12,
      "y": 12,
      "z": -4,
      "name": "Soil_Clay_Purple"
    },
    {
      "x": -12,
      "y": 13,
      "z": -4,
      "name": "Soil_Clay_Red"
    },
    {
      "x": -12,
      "y": 14,
      "z": -4,
      "name": "Soil_Clay_Red"
    },
    {
      "x": -12,
      "y": 15,
      "z": -4,
      "name": "Soil_Clay_Red"
    },
    {
      "x": -12,
      "y": 16,
      "z": -4,
      "name": "Soil_Clay_Red"
    },
    {
      "x": -12,
      "y": 17,
      "z": -4,
      "name": "Soil_Clay_Red"
    },
    {
      "x": -12,
      "y": 18,
      "z": -4,
      "name": "Soil_Clay_Red"
    },
    {
      "x": -12,
      "y": 19,
      "z": -4,
      "name": "Soil_Snow"
    },
    {
      "x": -12,
      "y": 20,
      "z": -4,
      "name": "Soil_Snow"
    },
    {
      "x": -12,
      "y": 21,
      "z": -4,
      "name": "Soil_Snow"
    },
    {
      "x": -12,
      "y": 22,
      "z": -4,
      "name": "Soil_Snow"
    },
    {
      "x": -12,
      "y": 12,
      "z": -3,
      "name": "Soil_Clay_Red"
    },
    {
      "x": -12,
      "y": 13,
      "z": -3,
      "name": "Soil_Clay_Red"
    },
    {
      "x": -12,
      "y": 14,
      "z": -3,
      "name": "Soil_Clay_Red"
    },
    {
      "x": -12,
      "y": 15,
      "z": -3,
      "name": "Soil_Clay_Red"
    },
    {
      "x": -12,
      "y": 16,
      "z": -3,
      "name": "Soil_Clay_Red"
    },
    {
      "x": -12,
      "y": 17,
      "z": -3,
      "name": "Soil_Clay_Red"
    },
    {
      "x": -12,
      "y": 18,
      "z": -3,
      "name": "Soil_Clay_Red"
    },
    {
      "x": -12,
      "y": 19,
      "z": -3,
      "name": "Soil_Snow"
    },
    {
      "x": -12,
      "y": 20,
      "z": -3,
      "name": "Soil_Snow"
    },
    {
      "x": -12,
      "y": 21,
      "z": -3,
      "name": "Soil_Snow"
    },
    {
      "x": -12,
      "y": 22,
      "z": -3,
      "name": "Soil_Snow"
    },
    {
      "x": -12,
      "y": 8,
      "z": -2,
      "name": "Soil_Clay_Red"
    },
    {
      "x": -12,
      "y": 9,
      "z": -2,
      "name": "Soil_Clay_Red"
    },
    {
      "x": -12,
      "y": 10,
      "z": -2,
      "name": "Soil_Clay_Red"
    },
    {
      "x": -12,
      "y": 11,
      "z": -2,
      "name": "Soil_Clay_Red"
    },
    {
      "x": -12,
      "y": 12,
      "z": -2,
      "name": "Soil_Clay_Red"
    },
    {
      "x": -12,
      "y": 13,
      "z": -2,
      "name": "Soil_Clay_Red"
    },
    {
      "x": -12,
      "y": 14,
      "z": -2,
      "name": "Soil_Clay_Red"
    },
    {
      "x": -12,
      "y": 15,
      "z": -2,
      "name": "Soil_Clay_Red"
    },
    {
      "x": -12,
      "y": 16,
      "z": -2,
      "name": "Soil_Clay_Red"
    },
    {
      "x": -12,
      "y": 17,
      "z": -2,
      "name": "Soil_Clay_Red"
    },
    {
      "x": -12,
      "y": 18,
      "z": -2,
      "name": "Soil_Clay_Red"
    },
    {
      "x": -12,
      "y": 19,
      "z": -2,
      "name": "Soil_Snow"
    },
    {
      "x": -12,
      "y": 20,
      "z": -2,
      "name": "Soil_Snow"
    },
    {
      "x": -12,
      "y": 21,
      "z": -2,
      "name": "Soil_Snow"
    },
    {
      "x": -12,
      "y": 22,
      "z": -2,
      "name": "Soil_Snow"
    },
    {
      "x": -12,
      "y": 8,
      "z": -1,
      "name": "Soil_Clay_Red"
    },
    {
      "x": -12,
      "y": 9,
      "z": -1,
      "name": "Soil_Clay_Red"
    },
    {
      "x": -12,
      "y": 10,
      "z": -1,
      "name": "Soil_Clay_Red"
    },
    {
      "x": -12,
      "y": 11,
      "z": -1,
      "name": "Soil_Clay_Purple"
    },
    {
