{
  "version": 8,
  "blockIdVersion": 11,
  "anchorX": 0,
  "anchorY": 0,
  "anchorZ": 0,
  "blocks": [
    {
      "x": -5,
      "y": 0,
      "z": -2,
      "name": "Rock_Sandstone_White"
    },
    {
      "x": -5,
      "y": -1,
      "z": -1,
      "name": "Rock_Sandstone_White"
    },
    {
      "x": -5,
      "y": 0,
      "z": -1,
      "name": "Rock_Sandstone_White"
    },
    {
      "x": -5,
      "y": -1,
      "z": 0,
      "name": "Rock_Sandstone_White"
    },
    {
      "x": -5,
      "y": 0,
      "z": 0,
      "name": "Soil_Clay_White"
    },
    {
      "x": -5,
      "y": 0,
      "z": 1,
      "name": "Soil_Clay_White"
    },
    {
      "x": -5,
      "y": 0,
      "z": 2,
      "name": "Rock_Sandstone_White"
    },
    {
      "x": -4,
      "y": 0,
      "z": -3,
      "name": "Soil_Clay_White"
    },
    {
      "x": -4,
      "y": -1,
      "z": -2,
      "name": "Rock_Sandstone"
    },
    {
      "x": -4,
      "y": 0,
      "z": -2,
      "name": "Soil_Clay_White"
    },
    {
      "x": -4,
      "y": 3,
      "z": -2,
      "name": "Soil_Clay_White"
    },
    {
      "x": -4,
      "y": 4,
      "z": -2,
      "name": "Soil_Clay_White"
    },
    {
      "x": -4,
      "y": 5,
      "z": -2,
      "name": "Soil_Clay_White"
    },
    {
      "x": -4,
      "y": 6,
      "z": -2,
      "name": "Soil_Clay_White"
    },
    {
      "x": -4,
      "y": -1,
      "z": -1,
      "name": "Rock_Sandstone"
    },
    {
      "x": -4,
      "y": 3,
      "z": -1,
      "name": "Soil_Clay_White"
    },
    {
      "x": -4,
      "y": 4,
      "z": -1,
      "name": "Soil_Clay_White"
    },
    {
      "x": -4,
      "y": 5,
      "z": -1,
      "name": "Soil_Clay_White"
    },
    {
      "x": -4,
      "y": 6,
      "z": -1,
      "name": "Soil_Clay_White"
    },
    {
      "x": -4,
      "y": -1,
      "z": 0,
      "name": "Rock_Sandstone"
    },
    {
      "x": -4,
      "y": -1,
      "z": 1,
      "name": "Rock_Sandstone"
    },
    {
      "x": -4,
      "y": 5,
      "z": 1,
      "name": "Rock_Sandstone_White"
    },
    {
      "x": -4,
      "y": 6,
      "z": 1,
      "name": "Rock_Sandstone_White"
    },
    {
      "x": -4,
      "y": -1,
      "z": 2,
      "name": "Rock_Sandstone_White"
    },
    {
      "x": -4,
      "y": 0,
      "z": 2,
      "name": "Rock_Sandstone_White"
    },
    {
      "x": -4,
      "y": 0,
      "z": 3,
      "name": "Rock_Sandstone_White"
    },
    {
      "x": -3,
      "y": -1,
      "z": -3,
      "name": "Rock_Sandstone"
    },
    {
      "x": -3,
      "y": 0,
      "z": -3,
      "name": "Soil_Clay_White"
    },
    {
      "x": -3,
      "y": 5,
      "z": -3,
      "name": "Soil_Clay_White"
    },
    {
      "x": -3,
      "y": 6,
      "z": -3,
      "name": "Soil_Clay_White"
    },
    {
      "x": -3,
      "y": -1,
      "z": -2,
      "name": "Rock_Sandstone"
    },
    {
      "x": -3,
      "y": 3,
      "z": -2,
      "name": "Rock_Sandstone"
    },
    {
      "x": -3,
      "y": 4,
      "z": -2,
      "name": "Rock_Sandstone"
    },
    {
      "x": -3,
      "y": 5,
      "z": -2,
      "name": "Rock_Sandstone_White"
    },
    {
      "x": -3,
      "y": 6,
      "z": -2,
      "name": "Soil_Clay_White"
    },
    {
      "x": -3,
      "y": -1,
      "z": -1,
      "name": "Rock_Sandstone"
    },
    {
      "x": -3,
      "y": 3,
      "z": -1,
      "name": "Rock_Sandstone"
    },
    {
      "x": -3,
      "y": 4,
      "z": -1,
      "name": "Rock_Sandstone"
    },
    {
      "x": -3,
      "y": 5,
      "z": -1,
      "name": "Rock_Sandstone_White"
    },
    {
      "x": -3,
      "y": -1,
      "z": 0,
      "name": "Rock_Sandstone"
    },
    {
      "x": -3,
      "y": 3,
      "z": 0,
      "name": "Rock_Sandstone"
    },
    {
      "x": -3,
      "y": 4,
      "z": 0,
      "name": "Rock_Sandstone"
    },
    {
      "x": -3,
      "y": 5,
      "z": 0,
      "name": "Rock_Sandstone_White"
    },
    {
      "x": -3,
      "y": -1,
      "z": 1,
      "name": "Rock_Sandstone"
    },
    {
      "x": -3,
      "y": 3,
      "z": 1,
      "name": "Rock_Sandstone"
    },
    {
      "x": -3,
      "y": 5,
      "z": 1,
      "name": "Rock_Sandstone_White"
    },
    {
      "x": -3,
      "y": 6,
      "z": 1,
      "name": "Rock_Sandstone_White"
    },
    {
      "x": -3,
      "y": -1,
      "z": 2,
      "name": "Rock_Sandstone"
    },
    {
      "x": -3,
      "y": 5,
      "z": 2,
      "name": "Rock_Sandstone_White"
    },
    {
      "x": -3,
      "y": 6,
      "z": 2,
      "name": "Rock_Sandstone_White"
    },
    {
      "x": -3,
      "y": -1,
      "z": 3,
      "name": "Rock_Sandstone"
    },
    {
      "x": -3,
      "y": 0,
      "z": 3,
      "name": "Rock_Sandstone"
    },
    {
      "x": -3,
      "y": 4,
      "z": 3,
      "name": "Soil_Clay_White"
    },
    {
      "x": -3,
      "y": 5,
      "z": 3,
      "name": "Soil_Clay_White"
    },
    {
      "x": -3,
      "y": 6,
      "z": 3,
      "name": "Soil_Clay_White"
    },
    {
      "x": -3,
      "y": 4,
      "z": 4,
      "name": "Soil_Clay_White"
    },
    {
      "x": -3,
      "y": 5,
      "z": 4,
      "name": "Soil_Clay_White"
    },
    {
      "x": -3,
      "y": 6,
      "z": 4,
      "name": "Soil_Clay_White"
    },
    {
      "x": -2,
      "y": -1,
      "z": -3,
      "name": "Rock_Sandstone"
    },
    {
      "x": -2,
      "y": 0,
      "z": -3,
      "name": "Rock_Sandstone"
    },
    {
      "x": -2,
      "y": 4,
      "z": -3,
      "name": "Rock_Sandstone_White"
    },
    {
      "x": -2,
      "y": 5,
      "z": -3,
      "name": "Rock_Sandstone_White"
    },
    {
      "x": -2,
      "y": 6,
      "z": -3,
      "name": "Soil_Clay_White"
    },
    {
      "x": -2,
      "y": -1,
      "z": -2,
      "name": "Rock_Sandstone"
    },
    {
      "x": -2,
      "y": 3,
      "z": -2,
      "name": "Rock_Sandstone"
    },
    {
      "x": -2,
      "y": 4,
      "z": -2,
      "name": "Rock_Sandstone"
    },
    {
      "x": -2,
      "y": 5,
      "z": -2,
      "name": "Rock_Sandstone_White"
    },
    {
      "x": -2,
      "y": -1,
      "z": -1,
      "name": "Rock_Sandstone"
    },
    {
      "x": -2,
      "y": 3,
      "z": -1,
      "name": "Rock_Sandstone"
    },
    {
      "x": -2,
      "y": 4,
      "z": -1,
      "name": "Rock_Sandstone"
    },
    {
      "x": -2,
      "y": 5,
      "z": -1,
      "name": "Rock_Sandstone_White"
    },
    {
      "x": -2,
      "y": -1,
      "z": 0,
      "name": "Rock_Sandstone"
    },
    {
      "x": -2,
      "y": 0,
      "z": 0,
      "name": "Rock_Sandstone"
    },
    {
      "x": -2,
      "y": 1,
      "z": 0,
      "name": "Rock_Sandstone"
    },
    {
      "x": -2,
      "y": 2,
      "z": 0,
      "name": "Rock_Sandstone"
    },
    {
      "x": -2,
      "y": 3,
      "z": 0,
      "name": "Rock_Sandstone"
    },
    {
      "x": -2,
      "y": 4,
      "z": 0,
      "name": "Rock_Sandstone"
    },
    {
      "x": -2,
      "y": 5,
      "z": 0,
      "name": "Rock_Sandstone_White"
    },
    {
      "x": -2,
      "y": -1,
      "z": 1,
      "name": "Rock_Sandstone"
    },
    {
      "x": -2,
      "y": 0,
      "z": 1,
      "name": "Rock_Sandstone"
    },
    {
      "x": -2,
      "y": 1,
      "z": 1,
      "name": "Rock_Sandstone"
    },
    {
      "x": -2,
      "y": 2,
      "z": 1,
      "name": "Rock_Sandstone"
    },
    {
      "x": -2,
      "y": 3,
      "z": 1,
      "name": "Rock_Sandstone"
    },
    {
      "x": -2,
      "y": 4,
      "z": 1,
      "name": "Rock_Sandstone"
    },
    {
      "x": -2,
      "y": 5,
      "z": 1,
      "name": "Rock_Sandstone_White"
    },
    {
      "x": -2,
      "y": -1,
      "z": 2,
      "name": "Rock_Sandstone"
    },
    {
      "x": -2,
      "y": 0,
      "z": 2,
      "name": "Rock_Sandstone"
    },
    {
      "x": -2,
      "y": 1,
      "z": 2,
      "name": "Rock_Sandstone"
    },
    {
      "x": -2,
      "y": 2,
      "z": 2,
      "name": "Rock_Sandstone"
    },
    {
      "x": -2,
      "y": 3,
      "z": 2,
      "name": "Rock_Sandstone"
    },
    {
      "x": -2,
      "y": 4,
      "z": 2,
      "name": "Rock_Sandstone"
    },
    {
      "x": -2,
      "y": 5,
      "z": 2,
      "name": "Rock_Sandstone_White"
    },
    {
      "x": -2,
      "y": -1,
      "z": 3,
      "name": "Rock_Sandstone"
    },
    {
      "x": -2,
      "y": 0,
      "z": 3,
      "name": "Rock_Sandstone"
    },
    {
      "x": -2,
      "y": 3,
      "z": 3,
      "name": "Rock_Sandstone"
    },
    {
      "x": -2,
      "y": 4,
      "z": 3,
      "name": "Rock_Sandstone"
    },
    {
      "x": -2,
      "y": 5,
      "z": 3,
      "name": "Rock_Sandstone_White"
    },
    {
      "x": -2,
      "y": -1,
      "z": 4,
      "name": "Rock_Sandstone_White"
    },
    {
      "x": -2,
      "y": 5,
      "z": 4,
      "name": "Rock_Sandstone_White"
    },
    {
      "x": -2,
      "y": 6,
      "z": 4,
      "name": "Soil_Clay_White"
    },
    {
      "x": -2,
      "y": 5,
      "z": 5,
      "name": "Rock_Sandstone_White"
    },
    {
      "x": -2,
      "y": 6,
      "z": 5,
      "name": "Soil_Clay_White"
    },
    {
      "x": -1,
      "y": -1,
      "z": -3,
      "name": "Rock_Sandstone"
    },
    {
      "x": -1,
      "y": 0,
      "z": -3,
      "name": "Rock_Sandstone"
    },
    {
      "x": -1,
      "y": 3,
      "z": -3,
      "name": "Rock_Sandstone_White"
    },
    {
      "x": -1,
      "y": 4,
      "z": -3,
      "name": "Rock_Sandstone_White"
    },
    {
      "x": -1,
      "y": 5,
      "z": -3,
      "name": "Rock_Sandstone_White"
    },
    {
      "x": -1,
      "y": 6,
      "z": -3,
      "name": "Soil_Clay_White"
    },
    {
      "x": -1,
      "y": -1,
      "z": -2,
      "name": "Rock_Sandstone"
    },
    {
      "x": -1,
      "y": 3,
      "z": -2,
      "name": "Rock_Sandstone"
    },
    {
      "x": -1,
      "y": 4,
      "z": -2,
      "name": "Rock_Sandstone"
    },
    {
      "x": -1,
      "y": 5,
      "z": -2,
      "name": "Rock_Sandstone_White"
    },
    {
      "x": -1,
      "y": -1,
      "z": -1,
      "name": "Rock_Sandstone"
    },
    {
      "x": -1,
      "y": 0,
      "z": -1,
      "name": "Rock_Sandstone"
    },
    {
      "x": -1,
      "y": 1,
      "z": -1,
      "name": "Rock_Sandstone"
    },
    {
      "x": -1,
      "y": 2,
      "z": -1,
      "name": "Rock_Sandstone"
    },
    {
      "x": -1,
      "y": 3,
      "z": -1,
      "name": "Rock_Sandstone"
    },
    {
      "x": -1,
      "y": 4,
      "z": -1,
      "name": "Rock_Sandstone"
    },
    {
      "x": -1,
      "y": 5,
      "z": -1,
      "name": "Rock_Sandstone_White"
    },
    {
      "x": -1,
      "y": -1,
      "z": 0,
      "name": "Rock_Sandstone"
    },
    {
      "x": -1,
      "y": 0,
      "z": 0,
      "name": "Rock_Sandstone"
    },
    {
      "x": -1,
      "y": 1,
      "z": 0,
      "name": "Rock_Sandstone"
    },
    {
      "x": -1,
      "y": 2,
      "z": 0,
      "name": "Rock_Sandstone"
    },
    {
      "x": -1,
      "y": 3,
      "z": 0,
      "name": "Rock_Sandstone"
    },
    {
      "x": -1,
      "y": 4,
      "z": 0,
      "name": "Rock_Sandstone"
    },
    {
      "x": -1,
      "y": -1,
      "z": 1,
      "name": "Rock_Sandstone"
    },
    {
      "x": -1,
      "y": 0,
      "z": 1,
      "name": "Rock_Sandstone"
    },
    {
      "x": -1,
      "y": 1,
      "z": 1,
      "name": "Rock_Sandstone"
    },
    {
      "x": -1,
      "y": 2,
      "z": 1,
      "name": "Rock_Sandstone"
    },
    {
      "x": -1,
      "y": 3,
      "z": 1,
      "name": "Rock_Sandstone"
    },
    {
      "x": -1,
      "y": 4,
      "z": 1,
      "name": "Rock_Sandstone"
    },
    {
      "x": -1,
      "y": -1,
      "z": 2,
      "name": "Rock_Sandstone"
    },
    {
      "x": -1,
      "y": 0,
      "z": 2,
      "name": "Rock_Sandstone"
    },
    {
      "x": -1,
      "y": 1,
      "z": 2,
      "name": "Rock_Sandstone"
    },
    {
      "x": -1,
      "y": 2,
      "z": 2,
      "name": "Rock_Sandstone"
    },
    {
      "x": -1,
      "y": 3,
      "z": 2,
      "name": "Rock_Sandstone"
    },
    {
      "x": -1,
      "y": 4,
      "z": 2,
      "name": "Rock_Sandstone"
    },
    {
      "x": -1,
      "y": -1,
      "z": 3,
      "name": "Rock_Sandstone"
    },
    {
      "x": -1,
      "y": 0,
      "z": 3,
      "name": "Rock_Sandstone"
    },
    {
      "x": -1,
      "y": 1,
      "z": 3,
      "name": "Rock_Sandstone"
    },
    {
      "x": -1,
      "y": 2,
      "z": 3,
      "name": "Rock_Sandstone"
    },
    {
      "x": -1,
      "y": 3,
      "z": 3,
      "name": "Rock_Sandstone"
    },
    {
      "x": -1,
      "y": 4,
      "z": 3,
      "name": "Rock_Sandstone"
    },
    {
      "x": -1,
      "y": -1,
      "z": 4,
      "name": "Rock_Sandstone_White"
    },
    {
      "x": -1,
      "y": 0,
      "z": 4,
      "name": "Rock_Sandstone_White"
    },
    {
      "x": -1,
      "y": 3,
      "z": 4,
      "name": "Rock_Sandstone"
    },
    {
      "x": -1,
      "y": 4,
      "z": 4,
      "name": "Rock_Sandstone"
    },
    {
      "x": -1,
      "y": 5,
      "z": 4,
      "name": "Rock_Sandstone_White"
    },
    {
      "x": -1,
      "y": 4,
      "z": 5,
      "name": "Rock_Sandstone_White"
    },
    {
      "x": -1,
      "y": 5,
      "z": 5,
      "name": "Rock_Sandstone_White"
    },
    {
      "x": -1,
      "y": 6,
      "z": 5,
      "name": "Rock_Sandstone_White"
    },
    {
      "x": -1,
      "y": 4,
      "z": 6,
      "name": "Rock_Sandstone_White"
    },
    {
      "x": -1,
      "y": 5,
      "z": 6,
      "name": "Rock_Sandstone_White"
    },
    {
      "x": -1,
      "y": 6,
      "z": 6,
      "name": "Rock_Sandstone_White"
    },
    {
      "x": 0,
      "y": 3,
      "z": -4,
      "name": "Rock_Sandstone_White"
    },
    {
      "x": 0,
      "y": 4,
      "z": -4,
      "name": "Rock_Sandstone_White"
    },
    {
      "x": 0,
      "y": 5,
      "z": -4,
      "name": "Rock_Sandstone_White"
    },
    {
      "x": 0,
      "y": 6,
      "z": -4,
      "name": "Soil_Clay_White"
    },
    {
      "x": 0,
      "y": 0,
      "z": -3,
      "name": "Rock_Sandstone"
    },
    {
      "x": 0,
      "y": 3,
      "z": -3,
      "name": "Rock_Sandstone"
    },
    {
      "x": 0,
      "y": 4,
      "z": -3,
      "name": "Rock_Sandstone"
    },
    {
      "x": 0,
      "y": 5,
      "z": -3,
      "name": "Rock_Sandstone_White"
    },
    {
      "x": 0,
      "y": 6,
      "z": -3,
      "name": "Soil_Clay_White"
    },
    {
      "x": 0,
      "y": -1,
      "z": -2,
      "name": "Rock_Sandstone"
    },
    {
      "x": 0,
      "y": 0,
      "z": -2,
      "name": "Rock_Sandstone"
    },
    {
      "x": 0,
      "y": 1,
      "z": -2,
      "name": "Rock_Sandstone"
    },
    {
      "x": 0,
      "y": 2,
      "z": -2,
      "name": "Rock_Sandstone"
    },
    {
      "x": 0,
      "y": 3,
      "z": -2,
      "name": "Rock_Sandstone"
    },
    {
      "x": 0,
      "y": 4,
      "z": -2,
      "name": "Rock_Sandstone"
    },
    {
      "x": 0,
      "y": 5,
      "z": -2,
      "name": "Rock_Sandstone_White"
    },
    {
      "x": 0,
      "y": -1,
      "z": -1,
      "name": "Rock_Sandstone"
    },
    {
      "x": 0,
      "y": 0,
      "z": -1,
      "name": "Rock_Sandstone"
    },
    {
      "x": 0,
      "y": 1,
      "z": -1,
      "name": "Rock_Sandstone"
    },
    {
      "x": 0,
      "y": 2,
      "z": -1,
      "name": "Rock_Sandstone"
    },
    {
      "x": 0,
      "y": 3,
      "z": -1,
      "name": "Rock_Sandstone"
    },
    {
      "x": 0,
      "y": 4,
      "z": -1,
      "name": "Rock_Sandstone"
    },
    {
      "x": 0,
      "y": -1,
      "z": 0,
      "name": "Rock_Sandstone"
    },
    {
      "x": 0,
      "y": 0,
      "z": 0,
      "name": "Rock_Sandstone"
    },
    {
      "x": 0,
      "y": 1,
      "z": 0,
      "name": "Rock_Sandstone"
    },
    {
      "x": 0,
      "y": 2,
      "z": 0,
      "name": "Rock_Sandstone"
    },
    {
      "x": 0,
      "y": 3,
      "z": 0,
      "name": "Rock_Sandstone"
    },
    {
      "x": 0,
      "y": 4,
      "z": 0,
      "name": "Rock_Sandstone"
    },
    {
      "x": 0,
      "y": -1,
      "z": 1,
      "name": "Rock_Sandstone"
    },
    {
      "x": 0,
      "y": 0,
      "z": 1,
      "name": "Rock_Sandstone"
    },
    {
      "x": 0,
      "y": 1,
      "z": 1,
      "name": "Rock_Sandstone"
    },
    {
      "x": 0,
      "y": 2,
      "z": 1,
      "name": "Rock_Sandstone"
    },
    {
      "x": 0,
      "y": 3,
      "z": 1,
      "name": "Rock_Sandstone"
    },
    {
      "x": 0,
      "y": 4,
      "z": 1,
      "name": "Rock_Sandstone"
    },
    {
      "x": 0,
      "y": -1,
      "z": 2,
      "name": "Rock_Sandstone"
    },
    {
      "x": 0,
      "y": 0,
      "z": 2,
      "name": "Rock_Sandstone"
    },
    {
      "x": 0,
      "y": 1,
      "z": 2,
      "name": "Rock_Sandstone"
    },
    {
      "x": 0,
      "y": 2,
      "z": 2,
      "name": "Rock_Sandstone"
    },
    {
      "x": 0,
      "y": 3,
      "z": 2,
      "name": "Rock_Sandstone"
    },
    {
      "x": 0,
      "y": 4,
      "z": 2,
      "name": "Rock_Sandstone"
    },
    {
      "x": 0,
      "y": -1,
      "z": 3,
      "name": "Rock_Sandstone"
    },
    {
      "x": 0,
      "y": 0,
      "z": 3,
      "name": "Rock_Sandstone"
    },
    {
      "x": 0,
      "y": 1,
      "z": 3,
      "name": "Rock_Sandstone"
    },
    {
      "x": 0,
      "y": 2,
      "z": 3,
      "name": "Rock_Sandstone"
    },
    {
      "x": 0,
      "y": 3,
      "z": 3,
      "name": "Rock_Sandstone"
    },
    {
      "x": 0,
      "y": 4,
      "z": 3,
      "name": "Rock_Sandstone"
    },
    {
      "x": 0,
      "y": -1,
      "z": 4,
      "name": "Rock_Sandstone"
    },
    {
      "x": 0,
      "y": 0,
      "z": 4,
      "name": "Rock_Sandstone"
    },
    {
      "x": 0,
      "y": 1,
      "z": 4,
      "name": "Rock_Sandstone"
    },
    {
      "x": 0,
      "y": 2,
      "z": 4,
      "name": "Rock_Sandstone"
    },
    {
      "x": 0,
      "y": 3,
      "z": 4,
      "name": "Rock_Sandstone"
    },
    {
      "x": 0,
      "y": 4,
      "z": 4,
      "name": "Rock_Sandstone"
    },
    {
      "x": 0,
      "y": 1,
      "z": 5,
      "name": "Rock_Sandstone"
    },
    {
      "x": 0,
      "y": 4,
      "z": 5,
      "name": "Rock_Sandstone_White"
    },
    {
      "x": 0,
      "y": 5,
      "z": 5,
      "name": "Rock_Sandstone_White"
    },
    {
      "x": 0,
      "y": 0,
      "z": 6,
      "name": "Rock_Sandstone_White"
    },
    {
      "x": 0,
      "y": 1,
      "z": 6,
      "name": "Rock_Sandstone_White"
    },
    {
      "x": 0,
      "y": 4,
      "z": 6,
      "name": "Rock_Sandstone_White"
    },
    {
      "x": 0,
      "y": 5,
      "z": 6,
      "name": "Soil_Clay_White"
    },
    {
      "x": 0,
      "y": 6,
      "z": 6,
      "name": "Soil_Clay_White"
    },
    {
      "x": 1,
      "y": 5,
      "z": -4,
      "name": "Rock_Sandstone_White"
    },
    {
      "x": 1,
      "y": 6,
      "z": -4,
      "name": "Soil_Clay_White"
    },
    {
      "x": 1,
      "y": 3,
      "z": -3,
      "name": "Rock_Sandstone"
    },
    {
      "x": 1,
      "y": 4,
      "z": -3,
      "name": "Rock_Sandstone"
    },
    {
      "x": 1,
      "y": 5,
      "z": -3,
      "name": "Rock_Sandstone_White"
    },
    {
      "x": 1,
      "y": -1,
      "z": -2,
      "name": "Rock_Sandstone"
    },
    {
      "x": 1,
      "y": 0,
      "z": -2,
      "name": "Rock_Sandstone"
    },
    {
      "x": 1,
      "y": 1,
      "z": -2,
      "name": "Rock_Sandstone"
    },
    {
      "x": 1,
      "y": 2,
      "z": -2,
      "name": "Rock_Sandstone"
    },
    {
      "x": 1,
      "y": 3,
      "z": -2,
      "name": "Rock_Sandstone"
    },
    {
      "x": 1,
      "y": 4,
      "z": -2,
      "name": "Rock_Sandstone"
    },
    {
      "x": 1,
      "y": 5,
      "z": -2,
      "name": "Rock_Sandstone_White"
    },
    {
      "x": 1,
      "y": -1,
      "z": -1,
      "name": "Rock_Sandstone"
    },
    {
      "x": 1,
      "y": 0,
      "z": -1,
      "name": "Rock_Sandstone"
    },
    {
      "x": 1,
      "y": 1,
      "z": -1,
      "name": "Rock_Sandstone"
    },
    {
      "x": 1,
      "y": 2,
      "z": -1,
      "name": "Rock_Sandstone"
    },
    {
      "x": 1,
      "y": 3,
      "z": -1,
      "name": "Rock_Sandstone"
    },
    {
      "x": 1,
      "y": 4,
      "z": -1,
      "name": "Rock_Sandstone"
    },
    {
      "x": 1,
      "y": -1,
      "z": 0,
      "name": "Rock_Sandstone"
    },
    {
      "x": 1,
      "y": 0,
      "z": 0,
      "name": "Rock_Sandstone"
    },
    {
      "x": 1,
      "y": 1,
      "z": 0,
      "name": "Rock_Sandstone"
    },
    {
      "x": 1,
      "y": 2,
      "z": 0,
      "name": "Rock_Sandstone"
    },
    {
      "x": 1,
      "y": 3,
      "z": 0,
      "name": "Rock_Sandstone"
    },
    {
      "x": 1,
      "y": 4,
      "z": 0,
      "name": "Rock_Sandstone"
    },
    {
      "x": 1,
      "y": -1,
      "z": 1,
      "name": "Rock_Sandstone"
    },
    {
      "x": 1,
      "y": 0,
      "z": 1,
      "name": "Rock_Sandstone"
    },
    {
      "x": 1,
      "y": 1,
      "z": 1,
      "name": "Rock_Sandstone"
    },
    {
      "x": 1,
      "y": 2,
      "z": 1,
      "name": "Rock_Sandstone"
    },
    {
      "x": 1,
      "y": 3,
      "z": 1,
      "name": "Rock_Sandstone"
    },
    {
      "x": 1,
      "y": 4,
      "z": 1,
      "name": "Rock_Sandstone"
    },
    {
      "x": 1,
      "y": -1,
      "z": 2,
      "name": "Rock_Sandstone"
    },
    {
      "x": 1,
      "y": 0,
      "z": 2,
      "name": "Rock_Sandstone"
    },
    {
      "x": 1,
      "y": 1,
      "z": 2,
      "name": "Rock_Sandstone"
    },
    {
      "x": 1,
      "y": 2,
      "z": 2,
      "name": "Rock_Sandstone"
    },
    {
      "x": 1,
      "y": 3,
      "z": 2,
      "name": "Rock_Sandstone"
    },
    {
      "x": 1,
      "y": 4,
      "z": 2,
      "name": "Rock_Sandstone"
    },
    {
      "x": 1,
      "y": -1,
      "z": 3,
      "name": "Rock_Sandstone"
    },
    {
      "x": 1,
      "y": 0,
      "z": 3,
      "name": "Rock_Sandstone"
    },
    {
      "x": 1,
      "y": 1,
      "z": 3,
      "name": "Rock_Sandstone"
    },
    {
      "x": 1,
      "y": 2,
      "z": 3,
      "name": "Rock_Sandstone"
    },
    {
      "x": 1,
      "y": 3,
      "z": 3,
      "name": "Rock_Sandstone"
    },
    {
      "x": 1,
      "y": 4,
      "z": 3,
      "name": "Rock_Sandstone"
    },
    {
      "x": 1,
      "y": -1,
      "z": 4,
      "name": "Rock_Sandstone"
    },
    {
      "x": 1,
      "y": 0,
      "z": 4,
      "name": "Rock_Sandstone"
    },
    {
      "x": 1,
      "y": 1,
      "z": 4,
      "name": "Rock_Sandstone"
    },
    {
      "x": 1,
      "y": 2,
      "z": 4,
      "name": "Rock_Sandstone"
    },
    {
      "x": 1,
      "y": 3,
      "z": 4,
      "name": "Rock_Sandstone"
    },
    {
      "x": 1,
      "y": 4,
      "z": 4,
      "name": "Rock_Sandstone"
    },
    {
      "x": 1,
      "y": -1,
      "z": 5,
      "name": "Rock_Sandstone"
    },
    {
      "x": 1,
      "y": 0,
      "z": 5,
      "name": "Rock_Sandstone"
    },
    {
      "x": 1,
      "y": 4,
      "z": 5,
      "name": "Rock_Sandstone_White"
    },
    {
      "x": 1,
      "y": 5,
      "z": 5,
      "name": "Rock_Sandstone_White"
    },
    {
      "x": 1,
      "y": 0,
      "z": 6,
      "name": "Rock_Sandstone"
    },
    {
      "x": 1,
      "y": 1,
      "z": 6,
      "name": "Rock_Sandstone_White"
    },
    {
      "x": 1,
      "y": 4,
      "z": 6,
      "name": "Rock_Sandstone_White"
    },
    {
      "x": 1,
      "y": 5,
      "z": 6,
      "name": "Rock_Sandstone_White"
    },
    {
      "x": 1,
      "y": 6,
      "z": 6,
      "name": "Soil_Clay_White"
    },
    {
      "x": 1,
      "y": 1,
      "z": 7,
      "name": "Soil_Clay_White"
    },
    {
      "x": 2,
      "y": 0,
      "z": -4,
      "name": "Rock_Sandstone_White"
    },
    {
      "x": 2,
      "y": 4,
      "z": -4,
      "name": "Rock_Sandstone_White"
    },
    {
      "x": 2,
      "y": 5,
      "z": -4,
      "name": "Rock_Sandstone_White"
    },
    {
      "x": 2,
      "y": 6,
      "z": -4,
      "name": "Soil_Clay_White"
    },
    {
      "x": 2,
      "y": -1,
      "z": -3,
      "name": "Rock_Sandstone"
    },
    {
      "x": 2,
      "y": 0,
      "z": -3,
      "name": "Rock_Sandstone"
    },
    {
      "x": 2,
      "y": 3,
      "z": -3,
      "name": "Rock_Sandstone"
    },
    {
      "x": 2,
      "y": 4,
      "z": -3,
      "name": "Rock_Sandstone"
    },
    {
      "x": 2,
      "y": 5,
      "z": -3,
      "name": "Rock_Sandstone_White"
    },
    {
      "x": 2,
      "y": -1,
      "z": -2,
      "name": "Rock_Sandstone"
    },
    {
      "x": 2,
      "y": 0,
      "z": -2,
      "name": "Rock_Sandstone"
    },
    {
      "x": 2,
      "y": 1,
      "z": -2,
      "name": "Rock_Sandstone"
    },
    {
      "x": 2,
      "y": 2,
      "z": -2,
      "name": "Rock_Sandstone"
    },
    {
      "x": 2,
      "y": 3,
      "z": -2,
      "name": "Rock_Sandstone"
    },
    {
      "x": 2,
      "y": 4,
      "z": -2,
      "name": "Rock_Sandstone"
    },
    {
      "x": 2,
      "y": -1,
      "z": -1,
      "name": "Rock_Sandstone"
    },
    {
      "x": 2,
      "y": 0,
      "z": -1,
      "name": "Rock_Sandstone"
    },
    {
      "x": 2,
      "y": 1,
      "z": -1,
      "name": "Rock_Sandstone"
    },
    {
      "x": 2,
      "y": 2,
      "z": -1,
      "name": "Rock_Sandstone"
    },
    {
      "x": 2,
      "y": 3,
      "z": -1,
      "name": "Rock_Sandstone"
    },
    {
      "x": 2,
      "y": 4,
      "z": -1,
      "name": "Rock_Sandstone"
    },
    {
      "x": 2,
      "y": -1,
      "z": 0,
      "name": "Rock_Sandstone"
    },
    {
      "x": 2,
      "y": 0,
      "z": 0,
      "name": "Rock_Sandstone"
    },
    {
      "x": 2,
      "y": 1,
      "z": 0,
      "name": "Rock_Sandstone"
    },
    {
      "x": 2,
      "y": 2,
      "z": 0,
      "name": "Rock_Sandstone"
    },
    {
      "x": 2,
      "y": 3,
      "z": 0,
      "name": "Rock_Sandstone"
    },
    {
      "x": 2,
      "y": 4,
      "z": 0,
      "name": "Rock_Sandstone"
    },
    {
      "x": 2,
      "y": -1,
      "z": 1,
      "name": "Rock_Sandstone"
    },
    {
      "x": 2,
      "y": 0,
      "z": 1,
      "name": "Rock_Sandstone"
    },
    {
      "x": 2,
      "y": 1,
      "z": 1,
      "name": "Rock_Sandstone"
    },
    {
      "x": 2,
      "y": 2,
      "z": 1,
      "name": "Rock_Sandstone"
    },
    {
      "x": 2,
      "y": 3,
      "z": 1,
      "name": "Rock_Sandstone"
    },
    {
      "x": 2,
      "y": 4,
      "z": 1,
      "name": "Rock_Sandstone"
    },
    {
      "x": 2,
      "y": -1,
      "z": 2,
      "name": "Rock_Sandstone"
    },
    {
      "x": 2,
      "y": 0,
      "z": 2,
      "name": "Rock_Sandstone"
    },
    {
      "x": 2,
      "y": 1,
      "z": 2,
      "name": "Rock_Sandstone"
    },
    {
      "x": 2,
      "y": 2,
      "z": 2,
      "name": "Rock_Sandstone"
    },
    {
      "x": 2,
      "y": 3,
      "z": 2,
      "name": "Rock_Sandstone"
    },
    {
      "x": 2,
      "y": 4,
      "z": 2,
      "name": "Rock_Sandstone"
    },
    {
      "x": 2,
      "y": -1,
      "z": 3,
      "name": "Rock_Sandstone"
    },
    {
      "x": 2,
      "y": 0,
      "z": 3,
      "name": "Rock_Sandstone"
    },
    {
      "x": 2,
      "y": 1,
      "z": 3,
      "name": "Rock_Sandstone"
    },
    {
      "x": 2,
      "y": 2,
      "z": 3,
      "name": "Rock_Sandstone"
    },
    {
      "x": 2,
      "y": 3,
      "z": 3,
      "name": "Rock_Sandstone"
    },
    {
      "x": 2,
      "y": 4,
      "z": 3,
      "name": "Rock_Sandstone"
    },
    {
      "x": 2,
      "y": -1,
      "z": 4,
      "name": "Rock_Sandstone"
    },
    {
      "x": 2,
      "y": 0,
      "z": 4,
      "name": "Rock_Sandstone"
    },
    {
      "x": 2,
      "y": 1,
      "z": 4,
      "name": "Rock_Sandstone"
    },
    {
      "x": 2,
      "y": 2,
      "z": 4,
      "name": "Rock_Sandstone"
    },
    {
      "x": 2,
      "y": 3,
      "z": 4,
      "name": "Rock_Sandstone"
    },
    {
      "x": 2,
      "y": 4,
      "z": 4,
      "name": "Rock_Sandstone"
    },
    {
      "x": 2,
      "y": -1,
      "z": 5,
      "name": "Rock_Sandstone"
    },
    {
      "x": 2,
      "y": 0,
      "z": 5,
      "name": "Rock_Sandstone"
    },
    {
      "x": 2,
      "y": 3,
      "z": 5,
      "name": "Rock_Sandstone"
    },
    {
      "x": 2,
      "y": 4,
      "z": 5,
      "name": "Rock_Sandstone"
    },
    {
      "x": 2,
      "y": 5,
      "z": 5,
      "name": "Rock_Sandstone_White"
    },
    {
      "x": 2,
      "y": -1,
      "z": 6,
      "name": "Rock_Sandstone"
    },
    {
      "x": 2,
      "y": 0,
      "z": 6,
      "name": "Rock_Sandstone"
    },
    {
      "x": 2,
      "y": 5,
      "z": 6,
      "name": "Rock_Sandstone_White"
    },
    {
      "x": 2,
      "y": 6,
      "z": 6,
      "name": "Soil_Clay_White"
    },
    {
      "x": 2,
      "y": 0,
      "z": 7,
      "name": "Rock_Sandstone_White"
    },
    {
      "x": 3,
      "y": 0,
      "z": -6,
      "name": "Rock_Sandstone_White"
    },
    {
      "x": 3,
      "y": -1,
      "z": -5,
      "name": "Rock_Sandstone_White"
    },
    {
      "x": 3,
      "y": 0,
      "z": -5,
      "name": "Rock_Sandstone_White"
    },
    {
      "x": 3,
      "y": -1,
      "z": -4,
      "name": "Rock_Sandstone"
    },
    {
      "x": 3,
      "y": 0,
      "z": -4,
      "name": "Rock_Sandstone_White"
    },
    {
      "x": 3,
      "y": 2,
      "z": -4,
      "name": "Rock_Sandstone_White"
    },
    {
      "x": 3,
      "y": 3,
      "z": -4,
      "name": "Rock_Sandstone_White"
    },
    {
      "x": 3,
      "y": 4,
      "z": -4,
      "name": "Rock_Sandstone_White"
    },
    {
      "x": 3,
      "y": 5,
      "z": -4,
      "name": "Rock_Sandstone_White"
    },
    {
      "x": 3,
      "y": 6,
      "z": -4,
      "name": "Rock_Sandstone_White"
    },
    {
      "x": 3,
      "y": -1,
      "z": -3,
      "name": "Rock_Sandstone"
    },
    {
      "x": 3,
      "y": 3,
      "z": -3,
      "name": "Rock_Sandstone_White"
    },
    {
      "x": 3,
      "y": 4,
      "z": -3,
      "name": "Rock_Sandstone"
    },
    {
      "x": 3,
      "y": 5,
      "z": -3,
      "name": "Rock_Sandstone_White"
    },
    {
      "x": 3,
      "y": -1,
      "z": -2,
      "name": "Rock_Sandstone"
    },
    {
      "x": 3,
      "y": 3,
      "z": -2,
      "name": "Rock_Sandstone"
    },
    {
      "x": 3,
      "y": 4,
      "z": -2,
      "name": "Rock_Sandstone"
    },
    {
      "x": 3,
      "y": 5,
      "z": -2,
      "name": "Rock_Sandstone_White"
    },
    {
      "x": 3,
      "y": -1,
      "z": -1,
      "name": "Rock_Sandstone"
    },
    {
      "x": 3,
      "y": 0,
      "z": -1,
      "name": "Rock_Sandstone"
    },
    {
      "x": 3,
      "y": 1,
      "z": -1,
      "name": "Rock_Sandstone"
    },
    {
      "x": 3,
      "y": 2,
      "z": -1,
      "name": "Rock_Sandstone"
    },
    {
      "x": 3,
      "y": 3,
      "z": -1,
      "name": "Rock_Sandstone"
    },
    {
      "x": 3,
      "y": 4,
      "z": -1,
      "name": "Rock_Sandstone"
    },
    {
      "x": 3,
      "y": -1,
      "z": 0,
      "name": "Rock_Sandstone"
    },
    {
      "x": 3,
      "y": 0,
      "z": 0,
      "name": "Rock_Sandstone"
    },
    {
      "x": 3,
      "y": 1,
      "z": 0,
      "name": "Rock_Sandstone"
    },
    {
      "x": 3,
      "y": 2,
      "z": 0,
      "name": "Rock_Sandstone"
    },
    {
      "x": 3,
      "y": 3,
      "z": 0,
      "name": "Rock_Sandstone"
    },
    {
      "x": 3,
      "y": 4,
      "z": 0,
      "name": "Rock_Sandstone"
    },
    {
      "x": 3,
      "y": -1,
      "z": 1,
      "name": "Rock_Sandstone"
    },
    {
      "x": 3,
      "y": 0,
      "z": 1,
      "name": "Rock_Sandstone"
    },
    {
      "x": 3,
      "y": 1,
      "z": 1,
      "name": "Rock_Sandstone"
    },
    {
      "x": 3,
      "y": 2,
      "z": 1,
      "name": "Rock_Sandstone"
    },
    {
      "x": 3,
      "y": 3,
      "z": 1,
      "name": "Rock_Sandstone"
    },
    {
      "x": 3,
      "y": 4,
      "z": 1,
      "name": "Rock_Sandstone"
    },
    {
      "x": 3,
      "y": -1,
      "z": 2,
      "name": "Rock_Sandstone"
    },
    {
      "x": 3,
      "y": 0,
      "z": 2,
      "name": "Rock_Sandstone"
    },
    {
      "x": 3,
      "y": 1,
      "z": 2,
      "name": "Rock_Sandstone"
    },
    {
      "x": 3,
      "y": 2,
      "z": 2,
      "name": "Rock_Sandstone"
    },
    {
      "x": 3,
      "y": 3,
      "z": 2,
      "name": "Rock_Sandstone"
    },
    {
      "x": 3,
      "y": 4,
      "z": 2,
      "name": "Rock_Sandstone"
    },
    {
      "x": 3,
      "y": -1,
      "z": 3,
      "name": "Rock_Sandstone"
    },
    {
      "x": 3,
      "y": 0,
      "z": 3,
      "name": "Rock_Sandstone"
    },
    {
      "x": 3,
      "y": 1,
      "z": 3,
      "name": "Rock_Sandstone"
    },
    {
      "x": 3,
      "y": 2,
      "z": 3,
      "name": "Rock_Sandstone"
    },
    {
      "x": 3,
      "y": 3,
      "z": 3,
      "name": "Rock_Sandstone"
    },
    {
      "x": 3,
      "y": 4,
      "z": 3,
      "name": "Rock_Sandstone"
    },
    {
      "x": 3,
      "y": -1,
      "z": 4,
      "name": "Rock_Sandstone"
    },
    {
      "x": 3,
      "y": 0,
      "z": 4,
      "name": "Rock_Sandstone"
    },
    {
      "x": 3,
      "y": 1,
      "z": 4,
      "name": "Rock_Sandstone_White"
    },
    {
      "x": 3,
      "y": 3,
      "z": 4,
      "name": "Rock_Sandstone"
    },
    {
      "x": 3,
      "y": 4,
      "z": 4,
      "name": "Rock_Sandstone"
    },
    {
      "x": 3,
      "y": 5,
      "z": 4,
      "name": "Rock_Sandstone_White"
    },
    {
      "x": 3,
      "y": -1,
      "z": 5,
      "name": "Rock_Sandstone"
    },
    {
      "x": 3,
      "y": 0,
      "z": 5,
      "name": "Rock_Sandstone"
    },
    {
      "x": 3,
      "y": 4,
      "z": 5,
      "name": "Rock_Sandstone"
    },
    {
      "x": 3,
      "y": 5,
      "z": 5,
      "name": "Rock_Sandstone_White"
    },
    {
      "x": 3,
      "y": -1,
      "z": 6,
      "name": "Rock_Sandstone_White"
    },
    {
      "x": 3,
      "y": 0,
      "z": 6,
      "name": "Rock_Sandstone"
    },
    {
      "x": 3,
      "y": 0,
      "z": 7,
      "name": "Rock_Sandstone_White"
    },
    {
      "x": 4,
      "y": 0,
      "z": -7,
      "name": "Soil_Clay_White"
    },
    {
      "x": 4,
      "y": -1,
      "z": -6,
      "name": "Rock_Sandstone_White"
    },
    {
      "x": 4,
      "y": 0,
      "z": -6,
      "name": "Rock_Sandstone_White"
    },
    {
      "x": 4,
      "y": -1,
      "z": -5,
      "name": "Rock_Sandstone"
    },
    {
      "x": 4,
      "y": -1,
      "z": -4,
      "name": "Rock_Sandstone"
    },
    {
      "x": 4,
      "y": 2,
      "z": -4,
      "name": "Rock_Sandstone_White"
    },
    {
      "x": 4,
      "y": 3,
      "z": -4,
      "name": "Soil_Clay_White"
    },
    {
      "x": 4,
      "y": 4,
      "z": -4,
      "name": "Soil_Clay_White"
    },
    {
      "x": 4,
      "y": 5,
      "z": -4,
      "name": "Soil_Clay_White"
    },
    {
      "x": 4,
      "y": 6,
      "z": -4,
      "name": "Soil_Clay_White"
    },
    {
      "x": 4,
      "y": -1,
      "z": -3,
      "name": "Rock_Sandstone"
    },
    {
      "x": 4,
      "y": 2,
      "z": -3,
      "name": "Rock_Sandstone_White"
    },
    {
      "x": 4,
      "y": 3,
      "z": -3,
      "name": "Rock_Sandstone_White"
    },
    {
      "x": 4,
      "y": 4,
      "z": -3,
      "name": "Rock_Sandstone_White"
    },
    {
      "x": 4,
      "y": 5,
      "z": -3,
      "name": "Rock_Sandstone_White"
    },
    {
      "x": 4,
      "y": 6,
      "z": -3,
      "name": "Soil_Clay_White"
    },
    {
      "x": 4,
      "y": -1,
      "z": -2,
      "name": "Rock_Sandstone"
    },
    {
      "x": 4,
      "y": 3,
      "z": -2,
      "name": "Rock_Sandstone_White"
    },
    {
      "x": 4,
      "y": 4,
      "z": -2,
      "name": "Rock_Sandstone"
    },
    {
      "x": 4,
      "y": 5,
      "z": -2,
      "name": "Rock_Sandstone_White"
    },
    {
      "x": 4,
      "y": -1,
      "z": -1,
      "name": "Rock_Sandstone"
    },
    {
      "x": 4,
      "y": 0,
      "z": -1,
      "name": "Rock_Sandstone"
    },
    {
      "x": 4,
      "y": 1,
      "z": -1,
      "name": "Rock_Sandstone"
    },
    {
      "x": 4,
      "y": 2,
      "z": -1,
      "name": "Rock_Sandstone"
    },
    {
      "x": 4,
      "y": 3,
      "z": -1,
      "name": "Rock_Sandstone"
    },
    {
      "x": 4,
      "y": 4,
      "z": -1,
      "name": "Rock_Sandstone"
    },
    {
      "x": 4,
      "y": 5,
      "z": -1,
      "name": "Rock_Sandstone_White"
    },
    {
      "x": 4,
      "y": -1,
      "z": 0,
      "name": "Rock_Sandstone"
    },
    {
      "x": 4,
      "y": 0,
      "z": 0,
      "name": "Rock_Sandstone"
    },
    {
      "x": 4,
      "y": 1,
      "z": 0,
      "name": "Rock_Sandstone"
    },
    {
      "x": 4,
      "y": 2,
      "z": 0,
      "name": "Rock_Sandstone"
    },
    {
      "x": 4,
      "y": 3,
      "z": 0,
      "name": "Rock_Sandstone"
    },
    {
      "x": 4,
      "y": 4,
      "z": 0,
      "name": "Rock_Sandstone"
    },
    {
      "x": 4,
      "y": -1,
      "z": 1,
      "name": "Rock_Sandstone"
    },
    {
      "x": 4,
      "y": 0,
      "z": 1,
      "name": "Rock_Sandstone"
    },
    {
      "x": 4,
      "y": 1,
      "z": 1,
      "name": "Rock_Sandstone"
    },
    {
      "x": 4,
      "y": 2,
      "z": 1,
      "name": "Rock_Sandstone"
    },
    {
      "x": 4,
      "y": 3,
      "z": 1,
      "name": "Rock_Sandstone"
    },
    {
      "x": 4,
      "y": 4,
      "z": 1,
      "name": "Rock_Sandstone"
    },
    {
      "x": 4,
      "y": -1,
      "z": 2,
      "name": "Rock_Sandstone"
    },
    {
      "x": 4,
      "y": 0,
      "z": 2,
      "name": "Rock_Sandstone"
    },
    {
      "x": 4,
      "y": 1,
      "z": 2,
      "name": "Rock_Sandstone"
    },
    {
      "x": 4,
      "y": 2,
      "z": 2,
      "name": "Rock_Sandstone"
    },
    {
      "x": 4,
      "y": 3,
      "z": 2,
      "name": "Rock_Sandstone"
    },
    {
      "x": 4,
      "y": 4,
      "z": 2,
      "name": "Rock_Sandstone"
    },
    {
      "x": 4,
      "y": 5,
      "z": 2,
      "name": "Rock_Sandstone_White"
    },
    {
      "x": 4,
      "y": -1,
      "z": 3,
      "name": "Rock_Sandstone"
    },
    {
      "x": 4,
      "y": 0,
      "z": 3,
      "name": "Rock_Sandstone"
    },
    {
      "x": 4,
      "y": 1,
      "z": 3,
      "name": "Rock_Sandstone"
    },
    {
      "x": 4,
      "y": 2,
      "z": 3,
      "name": "Rock_Sandstone"
    },
    {
      "x": 4,
      "y": 3,
      "z": 3,
      "name": "Rock_Sandstone"
    },
    {
      "x": 4,
      "y": 4,
      "z": 3,
      "name": "Rock_Sandstone"
    },
    {
      "x": 4,
      "y": 5,
      "z": 3,
      "name": "Rock_Sandstone_White"
    },
    {
      "x": 4,
      "y": -1,
      "z": 4,
      "name": "Rock_Sandstone"
    },
    {
      "x": 4,
      "y": 0,
      "z": 4,
      "name": "Rock_Sandstone"
    },
    {
      "x": 4,
      "y": 3,
      "z": 4,
      "name": "Rock_Sandstone"
    },
    {
      "x": 4,
      "y": 4,
      "z": 4,
      "name": "Rock_Sandstone"
    },
    {
      "x": 4,
      "y": 5,
      "z": 4,
      "name": "Rock_Sandstone_White"
    },
    {
      "x": 4,
      "y": 0,
      "z": 5,
      "name": "Rock_Sandstone"
    },
    {
      "x": 4,
      "y": 4,
      "z": 5,
      "name": "Rock_Sandstone"
    },
    {
      "x": 4,
      "y": 5,
      "z": 5,
      "name": "Rock_Sandstone_White"
    },
    {
      "x": 4,
      "y": 6,
      "z": 5,
      "name": "Rock_Sandstone_White"
    },
    {
      "x": 4,
      "y": 0,
      "z": 6,
      "name": "Rock_Sandstone"
    },
    {
      "x": 4,
      "y": 1,
      "z": 6,
      "name": "Soil_Clay_White"
    },
    {
      "x": 4,
      "y": 5,
      "z": 6,
      "name": "Soil_Clay_White"
    },
    {
      "x": 4,
      "y": 6,
      "z": 6,
      "name": "Soil_Clay_White"
    },
    {
      "x": 4,
      "y": 1,
      "z": 7,
      "name": "Soil_Clay_White"
    },
    {
      "x": 5,
      "y": 0,
      "z": -7,
      "name": "Soil_Clay_White"
    },
    {
      "x": 5,
      "y": -1,
      "z": -6,
      "name": "Rock_Sandstone"
    },
    {
      "x": 5,
      "y": -1,
      "z": -5,
      "name": "Rock_Sandstone"
    },
    {
      "x": 5,
      "y": -1,
      "z": -4,
      "name": "Rock_Sandstone"
    },
    {
      "x": 5,
      "y": -1,
      "z": -3,
      "name": "Rock_Sandstone"
    },
    {
      "x": 5,
      "y": 4,
      "z": -3,
      "name": "Soil_Clay_White"
    },
    {
      "x": 5,
      "y": 5,
      "z": -3,
      "name": "Rock_Sandstone_White"
    },
    {
      "x": 5,
      "y": -1,
      "z": -2,
      "name": "Rock_Sandstone"
    },
    {
      "x": 5,
      "y": 3,
      "z": -2,
      "name": "Rock_Sandstone"
    },
    {
      "x": 5,
      "y": 4,
      "z": -2,
      "name": "Rock_Sandstone"
    },
    {
      "x": 5,
      "y": 5,
      "z": -2,
      "name": "Rock_Sandstone_White"
    },
    {
      "x": 5,
      "y": -1,
      "z": -1,
      "name": "Rock_Sandstone"
    },
    {
      "x": 5,
      "y": 3,
      "z": -1,
      "name": "Rock_Sandstone"
    },
    {
      "x": 5,
      "y": 4,
      "z": -1,
      "name": "Rock_Sandstone"
    },
    {
      "x": 5,
      "y": 5,
      "z": -1,
      "name": "Rock_Sandstone_White"
    },
    {
      "x": 5,
      "y": -1,
      "z": 0,
      "name": "Rock_Sandstone"
    },
    {
      "x": 5,
      "y": 0,
      "z": 0,
      "name": "Rock_Sandstone"
    },
    {
      "x": 5,
      "y": 1,
      "z": 0,
      "name": "Rock_Sandstone"
    },
    {
      "x": 5,
      "y": 2,
      "z": 0,
      "name": "Rock_Sandstone"
    },
    {
      "x": 5,
      "y": 3,
      "z": 0,
      "name": "Rock_Sandstone"
    },
    {
      "x": 5,
      "y": 4,
      "z": 0,
      "name": "Rock_Sandstone"
    },
    {
      "x": 5,
      "y": 5,
      "z": 0,
      "name": "Rock_Sandstone_White"
    },
    {
      "x": 5,
      "y": -1,
      "z": 1,
      "name": "Rock_Sandstone"
    },
    {
      "x": 5,
      "y": 0,
      "z": 1,
      "name": "Rock_Sandstone"
    },
    {
      "x": 5,
      "y": 1,
      "z": 1,
      "name": "Rock_Sandstone"
    },
    {
      "x": 5,
      "y": 2,
      "z": 1,
      "name": "Rock_Sandstone"
    },
    {
      "x": 5,
      "y": 3,
      "z": 1,
      "name": "Rock_Sandstone"
    },
    {
      "x": 5,
      "y": 4,
      "z": 1,
      "name": "Rock_Sandstone"
    },
    {
      "x": 5,
      "y": 5,
      "z": 1,
      "name": "Rock_Sandstone_White"
    },
    {
      "x": 5,
      "y": -1,
      "z": 2,
      "name": "Rock_Sandstone"
    },
    {
      "x": 5,
      "y": 0,
      "z": 2,
      "name": "Rock_Sandstone"
    },
    {
      "x": 5,
      "y": 1,
      "z": 2,
      "name": "Rock_Sandstone"
    },
    {
      "x": 5,
      "y": 2,
      "z": 2,
      "name": "Rock_Sandstone"
    },
    {
      "x": 5,
      "y": 3,
      "z": 2,
      "name": "Rock_Sandstone"
    },
    {
      "x": 5,
      "y": 4,
      "z": 2,
      "name": "Rock_Sandstone"
    },
    {
      "x": 5,
      "y": 5,
      "z": 2,
      "name": "Rock_Sandstone_White"
    },
    {
      "x": 5,
      "y": -1,
      "z": 3,
      "name": "Rock_Sandstone"
    },
    {
      "x": 5,
      "y": 0,
      "z": 3,
      "name": "Rock_Sandstone"
    },
    {
      "x": 5,
      "y": 1,
      "z": 3,
      "name": "Rock_Sandstone"
    },
    {
      "x": 5,
      "y": 3,
      "z": 3,
      "name": "Rock_Sandstone"
    },
    {
      "x": 5,
      "y": 4,
      "z": 3,
      "name": "Rock_Sandstone"
    },
    {
      "x": 5,
      "y": 5,
      "z": 3,
      "name": "Rock_Sandstone_White"
    },
    {
      "x": 5,
      "y": -1,
      "z": 4,
      "name": "Rock_Sandstone"
    },
    {
      "x": 5,
      "y": 0,
      "z": 4,
      "name": "Rock_Sandstone"
    },
    {
      "x": 5,
      "y": 1,
      "z": 4,
      "name": "Rock_Sandstone"
    },
    {
      "x": 5,
      "y": 3,
      "z": 4,
      "name": "Rock_Sandstone_White"
    },
    {
      "x": 5,
      "y": 4,
      "z": 4,
      "name": "Rock_Sandstone"
    },
    {
      "x": 5,
      "y": 5,
      "z": 4,
      "name": "Rock_Sandstone_White"
    },
    {
      "x": 5,
      "y": 6,
      "z": 4,
      "name": "Soil_Clay_White"
    },
    {
      "x": 5,
      "y": 1,
      "z": 5,
      "name": "Soil_Clay_White"
    },
    {
      "x": 5,
      "y": 4,
      "z": 5,
      "name": "Rock_Sandstone_White"
    },
    {
      "x": 5,
      "y": 5,
      "z": 5,
      "name": "Rock_Sandstone_White"
    },
    {
      "x": 5,
      "y": 6,
      "z": 5,
      "name": "Soil_Clay_White"
    },
    {
      "x": 5,
      "y": 0,
      "z": 6,
      "name": "Rock_Sandstone_White"
    },
    {
      "x": 5,
      "y": 1,
      "z": 6,
      "name": "Soil_Clay_White"
    },
    {
      "x": 6,
      "y": -1,
      "z": -7,
      "name": "Rock_Sandstone_White"
    },
    {
      "x": 6,
      "y": 0,
      "z": -7,
      "name": "Rock_Sandstone_White"
    },
    {
      "x": 6,
      "y": -1,
      "z": -6,
      "name": "Rock_Sandstone"
    },
    {
      "x": 6,
      "y": -1,
      "z": -5,
      "name": "Rock_Sandstone"
    },
    {
      "x": 6,
      "y": -1,
      "z": -4,
      "name": "Rock_Sandstone"
    },
    {
      "x": 6,
      "y": -1,
      "z": -3,
      "name": "Rock_Sandstone"
    },
    {
      "x": 6,
      "y": -1,
      "z": -2,
      "name": "Rock_Sandstone"
    },
    {
      "x": 6,
      "y": 3,
      "z": -2,
      "name": "Soil_Clay_White"
    },
    {
      "x": 6,
      "y": 4,
      "z": -2,
      "name": "Rock_Sandstone_White"
    },
    {
      "x": 6,
      "y": 5,
      "z": -2,
      "name": "Rock_Sandstone_White"
    },
    {
      "x": 6,
      "y": -1,
      "z": -1,
      "name": "Rock_Sandstone"
    },
    {
      "x": 6,
      "y": 3,
      "z": -1,
      "name": "Rock_Sandstone"
    },
    {
      "x": 6,
      "y": 4,
      "z": -1,
      "name": "Rock_Sandstone"
    },
    {
      "x": 6,
      "y": 5,
      "z": -1,
      "name": "Rock_Sandstone_White"
    },
    {
      "x": 6,
      "y": -1,
      "z": 0,
      "name": "Rock_Sandstone"
    },
    {
      "x": 6,
      "y": 0,
      "z": 0,
      "name": "Rock_Sandstone_White"
    },
    {
      "x": 6,
      "y": 3,
      "z": 0,
      "name": "Rock_Sandstone"
    },
    {
      "x": 6,
      "y": 4,
      "z": 0,
      "name": "Rock_Sandstone"
    },
    {
      "x": 6,
      "y": 5,
      "z": 0,
      "name": "Rock_Sandstone_White"
    },
    {
      "x": 6,
      "y": -1,
      "z": 1,
      "name": "Rock_Sandstone_White"
    },
    {
      "x": 6,
      "y": 3,
      "z": 1,
      "name": "Rock_Sandstone"
    },
    {
      "x": 6,
      "y": 4,
      "z": 1,
      "name": "Rock_Sandstone"
    },
    {
      "x": 6,
      "y": 5,
      "z": 1,
      "name": "Rock_Sandstone_White"
    },
    {
      "x": 6,
      "y": -1,
      "z": 2,
      "name": "Rock_Sandstone_White"
    },
    {
      "x": 6,
      "y": 0,
      "z": 2,
      "name": "Rock_Sandstone_White"
    },
    {
      "x": 6,
      "y": 3,
      "z": 2,
      "name": "Rock_Sandstone"
    },
    {
      "x": 6,
      "y": 4,
      "z": 2,
      "name": "Rock_Sandstone"
    },
    {
      "x": 6,
      "y": 5,
      "z": 2,
      "name": "Rock_Sandstone_White"
    },
    {
      "x": 6,
      "y": -1,
      "z": 3,
      "name": "Rock_Sandstone_White"
    },
    {
      "x": 6,
      "y": 4,
      "z": 3,
      "name": "Rock_Sandstone"
    },
    {
      "x": 6,
      "y": 5,
      "z": 3,
      "name": "Rock_Sandstone_White"
    },
    {
      "x": 6,
      "y": 6,
      "z": 3,
      "name": "Soil_Clay_White"
    },
    {
      "x": 6,
      "y": 5,
      "z": 4,
      "name": "Soil_Clay_White"
    },
    {
      "x": 6,
      "y": 6,
      "z": 4,
      "name": "Soil_Clay_White"
    },
    {
      "x": 7,
      "y": 0,
      "z": -7,
      "name": "Rock_Sandstone_White"
    },
    {
      "x": 7,
      "y": -1,
      "z": -6,
      "name": "Rock_Sandstone"
    },
    {
      "x": 7,
      "y": 0,
      "z": -6,
      "name": "Soil_Clay_White"
    },
    {
      "x": 7,
      "y": -1,
      "z": -5,
      "name": "Rock_Sandstone"
    },
    {
      "x": 7,
      "y": -1,
      "z": -4,
      "name": "Rock_Sandstone"
    },
    {
      "x": 7,
      "y": -1,
      "z": -3,
      "name": "Rock_Sandstone"
    },
    {
      "x": 7,
      "y": -1,
      "z": -2,
      "name": "Rock_Sandstone"
    },
    {
      "x": 7,
      "y": -1,
      "z": -1,
      "name": "Rock_Sandstone"
    },
    {
      "x": 7,
      "y": 0,
      "z": -1,
      "name": "Rock_Sandstone_White"
    },
    {
      "x": 7,
      "y": 5,
      "z": -1,
      "name": "Soil_Clay_White"
    },
    {
      "x": 7,
      "y": 6,
      "z": -1,
      "name": "Soil_Clay_White"
    },
    {
      "x": 7,
      "y": 0,
      "z": 0,
      "name": "Rock_Sandstone_White"
    },
    {
      "x": 7,
      "y": 2,
      "z": 0,
      "name": "Soil_Clay_White"
    },
    {
      "x": 7,
      "y": 3,
      "z": 0,
      "name": "Soil_Clay_White"
    },
    {
      "x": 7,
      "y": 4,
      "z": 0,
      "name": "Soil_Clay_White"
    },
    {
      "x": 7,
      "y": 5,
      "z": 0,
      "name": "Soil_Clay_White"
    },
    {
      "x": 7,
      "y": 6,
      "z": 0,
      "name": "Soil_Clay_White"
    },
    {
      "x": 7,
      "y": 2,
      "z": 1,
      "name": "Soil_Clay_White"
    },
    {
      "x": 7,
      "y": 3,
      "z": 1,
      "name": "Soil_Clay_White"
    },
    {
      "x": 7,
      "y": 4,
      "z": 1,
      "name": "Soil_Clay_White"
    },
    {
      "x": 7,
      "y": 5,
      "z": 1,
      "name": "Soil_Clay_White"
    },
    {
      "x": 7,
      "y": 6,
      "z": 1,
      "name": "Soil_Clay_White"
    },
    {
      "x": 7,
      "y": 5,
      "z": 2,
      "name": "Rock_Sandstone_White"
    },
    {
      "x": 7,
      "y": 6,
      "z": 2,
      "name": "Rock_Sandstone_White"
    },
    {
      "x": 7,
      "y": 3,
      "z": 3,
      "name": "Soil_Clay_White"
    },
    {
      "x": 7,
      "y": 4,
      "z": 3,
      "name": "Soil_Clay_White"
    },
    {
      "x": 7,
      "y": 5,
      "z": 3,
      "name": "Soil_Clay_White"
    },
    {
      "x": 7,
      "y": 6,
      "z": 3,
      "name": "Soil_Clay_White"
    },
    {
      "x": 8,
      "y": 0,
      "z": -6,
      "name": "Soil_Clay_White"
    },
    {
      "x": 8,
      "y": -1,
      "z": -5,
      "name": "Rock_Sandstone"
    },
    {
      "x": 8,
      "y": 0,
      "z": -5,
      "name": "Soil_Clay_White"
    },
    {
      "x": 8,
      "y": -1,
      "z": -4,
      "name": "Rock_Sandstone"
    },
    {
      "x": 8,
      "y": -1,
      "z": -3,
      "name": "Rock_Sandstone"
    },
    {
      "x": 8,
      "y": -1,
      "z": -2,
      "name": "Rock_Sandstone"
    },
    {
      "x": 8,
      "y": 0,
      "z": -2,
      "name": "Rock_Sandstone"
    },
    {
      "x": 8,
      "y": 0,
      "z": -1,
      "name": "Rock_Sandstone"
    },
    {
      "x": 9,
      "y": 0,
      "z": -5,
      "name": "Soil_Clay_White"
    },
    {
      "x": 9,
      "y": 0,
      "z": -4,
      "name": "Soil_Clay_White"
    },
    {
      "x": 9,
      "y": -1,
      "z": -3,
      "name": "Rock_Sandstone_White"
    },
    {
      "x": 9,
      "y": 0,
      "z": -3,
      "name": "Rock_Sandstone_White"
    },
    {
      "x": 9,
      "y": -1,
      "z": -2,
      "name": "Rock_Sandstone_White"
    },
    {
      "x": 9,
      "y": 0,
      "z": -2,
      "name": "Rock_Sandstone_White"
    }
  ],
  "fluids": [
    {
      "x": -4,
      "y": 0,
      "z": -1,
      "name": "Water_Source",
      "level": 1
    },
    {
      "x": -4,
      "y": 0,
      "z": 0,
      "name": "Water_Source",
      "level": 1
    },
    {
      "x": -4,
      "y": 1,
      "z": 0,
      "name": "Water",
      "level": 8
    },
    {
      "x": -4,
      "y": 2,
      "z": 0,
      "name": "Water",
      "level": 8
    },
    {
      "x": -4,
      "y": 3,
      "z": 0,
      "name": "Water",
      "level": 8
    },
    {
      "x": -4,
      "y": 4,
      "z": 0,
      "name": "Water",
      "level": 8
    },
    {
      "x": -4,
      "y": 5,
      "z": 0,
      "name": "Water",
      "level": 8
    },
    {
      "x": -4,
      "y": 6,
      "z": 0,
      "name": "Water",
      "level": 7
    },
    {
      "x": -4,
      "y": 0,
      "z": 1,
      "name": "Water_Source",
      "level": 1
    },
    {
      "x": -3,
      "y": 0,
      "z": -2,
      "name": "Water_Source",
      "level": 1
    },
    {
      "x": -3,
      "y": 0,
      "z": -1,
      "name": "Water_Source",
      "level": 1
    },
    {
      "x": -3,
      "y": 6,
      "z": -1,
      "name": "Water_Source",
      "level": 1
    },
    {
      "x": -3,
      "y": 0,
      "z": 0,
      "name": "Water_Source",
      "level": 1
    },
    {
      "x": -3,
      "y": 6,
      "z": 0,
      "name": "Water_Source",
      "level": 1
    },
    {
      "x": -3,
      "y": 0,
      "z": 1,
      "name": "Water_Source",
      "level": 1
    },
    {
      "x": -3,
      "y": 0,
      "z": 2,
      "name": "Water_Source",
      "level": 1
    },
    {
      "x": -2,
      "y": 0,
      "z": -2,
      "name": "Water_Source",
      "level": 1
    },
    {
      "x": -2,
      "y": 6,
      "z": -2,
      "name": "Water_Source",
      "level": 1
    },
    {
      "x": -2,
      "y": 0,
      "z": -1,
      "name": "Water_Source",
      "level": 1
    },
    {
      "x": -2,
      "y": 6,
      "z": -1,
      "name": "Water_Source",
      "level": 1
    },
    {
      "x": -2,
      "y": 6,
      "z": 0,
      "name": "Water_Source",
      "level": 1
    },
    {
      "x": -2,
      "y": 6,
      "z": 1,
      "name": "Water_Source",
      "level": 1
    },
    {
      "x": -2,
      "y": 6,
      "z": 2,
      "name": "Water_Source",
      "level": 1
    },
    {
      "x": -2,
      "y": 6,
      "z": 3,
      "name": "Water_Source",
      "level": 1
    },
    {
      "x": -1,
      "y": 0,
      "z": -2,
      "name": "Water_Source",
      "level": 1
    },
    {
      "x": -1,
      "y": 6,
      "z": -2,
      "name": "Water_Source",
      "level": 1
    },
    {
      "x": -1,
      "y": 6,
      "z": -1,
      "name": "Water_Source",
      "level": 1
    },
    {
      "x": -1,
      "y": 5,
      "z": 0,
      "name": "Water",
      "level": 5
    },
    {
      "x": -1,
      "y": 6,
      "z": 0,
      "name": "Water_Source",
      "level": 1
    },
    {
      "x": -1,
      "y": 5,
      "z": 1,
      "name": "Water",
      "level": 6
    },
    {
      "x": -1,
      "y": 6,
      "z": 1,
      "name": "Water_Source",
      "level": 1
    },
    {
      "x": -1,
      "y": 5,
      "z": 2,
      "name": "Water",
      "level": 7
    },
    {
      "x": -1,
      "y": 6,
      "z": 2,
      "name": "Water_Source",
      "level": 1
    },
    {
      "x": -1,
      "y": 5,
      "z": 3,
      "name": "Water",
      "level": 8
    },
    {
      "x": -1,
      "y": 6,
      "z": 3,
      "name": "Water_Source",
      "level": 1
    },
    {
      "x": -1,
      "y": 6,
      "z": 4,
      "name": "Water_Source",
      "level": 1
    },
    {
      "x": 0,
      "y": 6,
      "z": -2,
      "name": "Water_Source",
      "level": 1
    },
    {
      "x": 0,
      "y": 5,
      "z": -1,
      "name": "Water",
      "level": 3
    },
    {
      "x": 0,
      "y": 6,
      "z": -1,
      "name": "Water_Source",
      "level": 1
    },
    {
      "x": 0,
      "y": 5,
      "z": 0,
      "name": "Water",
      "level": 4
    },
    {
      "x": 0,
      "y": 6,
      "z": 0,
      "name": "Water_Source",
      "level": 1
    },
    {
      "x": 0,
      "y": 5,
      "z": 1,
      "name": "Water",
      "level": 5
    },
    {
      "x": 0,
      "y": 6,
      "z": 1,
      "name": "Water_Source",
      "level": 1
    },
    {
      "x": 0,
      "y": 5,
      "z": 2,
      "name": "Water",
      "level": 6
    },
    {
      "x": 0,
      "y": 6,
      "z": 2,
      "name": "Water_Source",
      "level": 1
    },
    {
      "x": 0,
      "y": 5,
      "z": 3,
      "name": "Water",
      "level": 7
    },
    {
      "x": 0,
      "y": 6,
      "z": 3,
      "name": "Water_Source",
      "level": 1
    },
    {
      "x": 0,
      "y": 5,
      "z": 4,
      "name": "Water",
      "level": 6
    },
    {
      "x": 0,
      "y": 6,
      "z": 4,
      "name": "Water_Source",
      "level": 1
    },
    {
      "x": 0,
      "y": 6,
      "z": 5,
      "name": "Water_Source",
      "level": 1
    },
    {
      "x": 1,
      "y": 6,
      "z": -3,
      "name": "Water_Source",
      "level": 1
    },
    {
      "x": 1,
      "y": 6,
      "z": -2,
      "name": "Water_Source",
      "level": 1
    },
    {
      "x": 1,
      "y": 5,
      "z": -1,
      "name": "Water",
      "level": 2
    },
    {
      "x": 1,
      "y": 6,
      "z": -1,
      "name": "Water_Source",
      "level": 1
    },
    {
      "x": 1,
      "y": 5,
      "z": 0,
      "name": "Water",
      "level": 3
    },
    {
      "x": 1,
      "y": 6,
      "z": 0,
      "name": "Water_Source",
      "level": 1
    },
    {
      "x": 1,
      "y": 5,
      "z": 1,
      "name": "Water",
      "level": 4
    },
    {
      "x": 1,
      "y": 6,
      "z": 1,
      "name": "Water_Source",
      "level": 1
    },
    {
      "x": 1,
      "y": 5,
      "z": 2,
      "name": "Water",
      "level": 5
    },
    {
      "x": 1,
      "y": 6,
      "z": 2,
      "name": "Water_Source",
      "level": 1
    },
    {
      "x": 1,
      "y": 5,
      "z": 3,
      "name": "Water",
      "level": 6
    },
    {
      "x": 1,
      "y": 6,
      "z": 3,
      "name": "Water_Source",
      "level": 1
    },
    {
      "x": 1,
      "y": 5,
      "z": 4,
      "name": "Water",
      "level": 5
    },
    {
      "x": 1,
      "y": 6,
      "z": 4,
      "name": "Water_Source",
      "level": 1
    },
    {
      "x": 1,
      "y": 1,
      "z": 5,
      "name": "Water_Source",
      "level": 1
    },
    {
      "x": 1,
      "y": 6,
      "z": 5,
      "name": "Water_Source",
      "level": 1
    },
    {
      "x": 2,
      "y": 6,
      "z": -3,
      "name": "Water_Source",
      "level": 1
    },
    {
      "x": 2,
      "y": 6,
      "z": -2,
      "name": "Water_Source",
      "level": 1
    },
    {
      "x": 2,
      "y": 5,
      "z": -1,
      "name": "Water",
      "level": 1
    },
    {
      "x": 2,
      "y": 6,
      "z": -1,
      "name": "Water_Source",
      "level": 1
    },
    {
      "x": 2,
      "y": 5,
      "z": 0,
      "name": "Water",
      "level": 2
    },
    {
      "x": 2,
      "y": 6,
      "z": 0,
      "name": "Water_Source",
      "level": 1
    },
    {
      "x": 2,
      "y": 5,
      "z": 1,
      "name": "Water",
      "level": 3
    },
    {
      "x": 2,
      "y": 6,
      "z": 1,
      "name": "Water_Source",
      "level": 1
    },
    {
      "x": 2,
      "y": 5,
      "z": 2,
      "name": "Water",
      "level": 4
    },
    {
      "x": 2,
      "y": 6,
      "z": 2,
      "name": "Water_Source",
      "level": 1
    },
    {
      "x": 2,
      "y": 5,
      "z": 3,
      "name": "Water",
      "level": 5
    },
    {
      "x": 2,
      "y": 6,
      "z": 3,
      "name": "Water_Source",
      "level": 1
    },
    {
      "x": 2,
      "y": 5,
      "z": 4,
      "name": "Water",
      "level": 4
    },
    {
      "x": 2,
      "y": 6,
      "z": 4,
      "name": "Water_Source",
      "level": 1
    },
    {
      "x": 2,
      "y": 1,
      "z": 5,
      "name": "Water_Source",
      "level": 1
    },
    {
      "x": 2,
      "y": 6,
      "z": 5,
      "name": "Water_Source",
      "level": 1
    },
    {
      "x": 2,
      "y": 1,
      "z": 6,
      "name": "Water_Source",
      "level": 1
    },
    {
      "x": 2,
      "y": 1,
      "z": 7,
      "name": "Water",
      "level": 7
    },
    {
      "x": 2,
      "y": -1,
      "z": 8,
      "name": "Water",
      "level": 8
    },
    {
      "x": 2,
      "y": 0,
      "z": 8,
      "name": "Water",
      "level": 8
    },
    {
      "x": 2,
      "y": 1,
      "z": 8,
      "name": "Water",
      "level": 6
    },
    {
      "x": 3,
      "y": 0,
      "z": -3,
      "name": "Water_Source",
      "level": 1
    },
    {
      "x": 3,
      "y": 6,
      "z": -3,
      "name": "Water_Source",
      "level": 1
    },
    {
      "x": 3,
      "y": 0,
      "z": -2,
      "name": "Water_Source",
      "level": 1
    },
    {
      "x": 3,
      "y": 6,
      "z": -2,
      "name": "Water_Source",
      "level": 1
    },
    {
      "x": 3,
      "y": 6,
      "z": -1,
      "name": "Water_Source",
      "level": 1
    },
    {
      "x": 3,
      "y": 5,
      "z": 0,
      "name": "Water",
      "level": 1
    },
    {
      "x": 3,
      "y": 6,
      "z": 0,
      "name": "Water_Source",
      "level": 1
    },
    {
      "x": 3,
      "y": 5,
      "z": 1,
      "name": "Water",
      "level": 2
    },
    {
      "x": 3,
      "y": 6,
      "z": 1,
      "name": "Water_Source",
      "level": 1
    },
    {
      "x": 3,
      "y": 5,
      "z": 2,
      "name": "Water",
      "level": 3
    },
    {
      "x": 3,
      "y": 6,
      "z": 2,
      "name": "Water_Source",
      "level": 1
    },
    {
      "x": 3,
      "y": 5,
      "z": 3,
      "name": "Water",
      "level": 4
    },
    {
      "x": 3,
      "y": 6,
      "z": 3,
      "name": "Water_Source",
      "level": 1
    },
    {
      "x": 3,
      "y": 6,
      "z": 4,
      "name": "Water_Source",
      "level": 1
    },
    {
      "x": 3,
      "y": 1,
      "z": 5,
      "name": "Water_Source",
      "level": 1
    },
    {
      "x": 3,
      "y": 6,
      "z": 5,
      "name": "Water_Source",
      "level": 1
    },
    {
      "x": 3,
      "y": 1,
      "z": 6,
      "name": "Water",
      "level": 8
    },
    {
      "x": 3,
      "y": 2,
      "z": 6,
      "name": "Water",
      "level": 8
    },
    {
      "x": 3,
      "y": 3,
      "z": 6,
      "name": "Water",
      "level": 8
    },
    {
      "x": 3,
      "y": 4,
      "z": 6,
      "name": "Water",
      "level": 8
    },
    {
      "x": 3,
      "y": 5,
      "z": 6,
      "name": "Water",
      "level": 8
    },
    {
      "x": 3,
      "y": 6,
      "z": 6,
      "name": "Water",
      "level": 7
    },
    {
      "x": 3,
      "y": 1,
      "z": 7,
      "name": "Water",
      "level": 7
    },
    {
      "x": 3,
      "y": -1,
      "z": 8,
      "name": "Water",
      "level": 8
    },
    {
      "x": 3,
      "y": 0,
      "z": 8,
      "name": "Water",
      "level": 8
    },
    {
      "x": 3,
      "y": 1,
      "z": 8,
      "name": "Water",
      "level": 6
    },
    {
      "x": 4,
      "y": 0,
      "z": -5,
      "name": "Water_Source",
      "level": 1
    },
    {
      "x": 4,
      "y": 0,
      "z": -4,
      "name": "Water_Source",
      "level": 1
    },
    {
      "x": 4,
      "y": 0,
      "z": -3,
      "name": "Water_Source",
      "level": 1
    },
    {
      "x": 4,
      "y": 0,
      "z": -2,
      "name": "Water_Source",
      "level": 1
    },
    {
      "x": 4,
      "y": 6,
      "z": -2,
      "name": "Water_Source",
      "level": 1
    },
    {
      "x": 4,
      "y": 6,
      "z": -1,
      "name": "Water_Source",
      "level": 1
    },
    {
      "x": 4,
      "y": 6,
      "z": 0,
      "name": "Water_Source",
      "level": 1
    },
    {
      "x": 4,
      "y": 5,
      "z": 1,
      "name": "Water",
      "level": 1
    },
    {
      "x": 4,
      "y": 6,
      "z": 1,
      "name": "Water_Source",
      "level": 1
    },
    {
      "x": 4,
      "y": 6,
      "z": 2,
      "name": "Water_Source",
      "level": 1
    },
    {
      "x": 4,
      "y": 6,
      "z": 3,
      "name": "Water_Source",
      "level": 1
    },
    {
      "x": 4,
      "y": 1,
      "z": 4,
      "name": "Water_Source",
      "level": 1
    },
    {
      "x": 4,
      "y": 6,
      "z": 4,
      "name": "Water_Source",
      "level": 1
    },
    {
      "x": 4,
      "y": 1,
      "z": 5,
      "name": "Water",
      "level": 8
    },
    {
      "x": 5,
      "y": 0,
      "z": -6,
      "name": "Water_Source",
      "level": 1
    },
    {
      "x": 5,
      "y": 0,
      "z": -5,
      "name": "Water_Source",
      "level": 1
    },
    {
      "x": 5,
      "y": 0,
      "z": -4,
      "name": "Water_Source",
      "level": 1
    },
    {
      "x": 5,
      "y": 1,
      "z": -4,
      "name": "Water",
      "level": 8
    },
    {
      "x": 5,
      "y": 2,
      "z": -4,
      "name": "Water",
      "level": 8
    },
    {
      "x": 5,
      "y": 3,
      "z": -4,
      "name": "Water",
      "level": 8
    },
    {
      "x": 5,
      "y": 4,
      "z": -4,
      "name": "Water",
      "level": 8
    },
    {
      "x": 5,
      "y": 5,
      "z": -4,
      "name": "Water",
      "level": 8
    },
    {
      "x": 5,
      "y": 6,
      "z": -4,
      "name": "Water",
      "level": 5
    },
    {
      "x": 5,
      "y": 0,
      "z": -3,
      "name": "Water_Source",
      "level": 1
    },
    {
      "x": 5,
      "y": 6,
      "z": -3,
      "name": "Water",
      "level": 6
    },
    {
      "x": 5,
      "y": 0,
      "z": -2,
      "name": "Water_Source",
      "level": 1
    },
    {
      "x": 5,
      "y": 6,
      "z": -2,
      "name": "Water",
      "level": 7
    },
    {
      "x": 5,
      "y": 0,
      "z": -1,
      "name": "Water_Source",
      "level": 1
    },
    {
      "x": 5,
      "y": 6,
      "z": -1,
      "name": "Water_Source",
      "level": 1
    },
    {
      "x": 5,
      "y": 6,
      "z": 0,
      "name": "Water_Source",
      "level": 1
    },
    {
      "x": 5,
      "y": 6,
      "z": 1,
      "name": "Water_Source",
      "level": 1
    },
    {
      "x": 5,
      "y": 6,
      "z": 2,
      "name": "Water_Source",
      "level": 1
    },
    {
      "x": 5,
      "y": 6,
      "z": 3,
      "name": "Water_Source",
      "level": 1
    },
    {
      "x": 6,
      "y": 0,
      "z": -6,
      "name": "Water_Source",
      "level": 1
    },
    {
      "x": 6,
      "y": 0,
      "z": -5,
      "name": "Water_Source",
      "level": 1
    },
    {
      "x": 6,
      "y": 0,
      "z": -4,
      "name": "Water_Source",
      "level": 1
    },
    {
      "x": 6,
      "y": 0,
      "z": -3,
      "name": "Water_Source",
      "level": 1
    },
    {
      "x": 6,
      "y": 1,
      "z": -3,
      "name": "Water",
      "level": 8
    },
    {
      "x": 6,
      "y": 2,
      "z": -3,
      "name": "Water",
      "level": 8
    },
    {
      "x": 6,
      "y": 3,
      "z": -3,
      "name": "Water",
      "level": 8
    },
    {
      "x": 6,
      "y": 4,
      "z": -3,
      "name": "Water",
      "level": 8
    },
    {
      "x": 6,
      "y": 5,
      "z": -3,
      "name": "Water",
      "level": 8
    },
    {
      "x": 6,
      "y": 6,
      "z": -3,
      "name": "Water",
      "level": 5
    },
    {
      "x": 6,
      "y": 0,
      "z": -2,
      "name": "Water_Source",
      "level": 1
    },
    {
      "x": 6,
      "y": 6,
      "z": -2,
      "name": "Water",
      "level": 6
    },
    {
      "x": 6,
      "y": 0,
      "z": -1,
      "name": "Water_Source",
      "level": 1
    },
    {
      "x": 6,
      "y": 6,
      "z": -1,
      "name": "Water",
      "level": 7
    },
    {
      "x": 6,
      "y": 6,
      "z": 0,
      "name": "Water_Source",
      "level": 1
    },
    {
      "x": 6,
      "y": 6,
      "z": 1,
      "name": "Water_Source",
      "level": 1
    },
    {
      "x": 6,
      "y": 6,
      "z": 2,
      "name": "Water_Source",
      "level": 1
    },
    {
      "x": 7,
      "y": 0,
      "z": -5,
      "name": "Water_Source",
      "level": 1
    },
    {
      "x": 7,
      "y": 0,
      "z": -4,
      "name": "Water_Source",
      "level": 1
    },
    {
      "x": 7,
      "y": 0,
      "z": -3,
      "name": "Water_Source",
      "level": 1
    },
    {
      "x": 7,
      "y": 0,
      "z": -2,
      "name": "Water_Source",
      "level": 1
    },
    {
      "x": 7,
      "y": 1,
      "z": -2,
      "name": "Water",
      "level": 8
    },
    {
      "x": 7,
      "y": 2,
      "z": -2,
      "name": "Water",
      "level": 8
    },
    {
      "x": 7,
      "y": 3,
      "z": -2,
      "name": "Water",
      "level": 8
    },
    {
      "x": 7,
      "y": 4,
      "z": -2,
      "name": "Water",
      "level": 8
    },
    {
      "x": 7,
      "y": 5,
      "z": -2,
      "name": "Water",
      "level": 8
    },
    {
      "x": 7,
      "y": 6,
      "z": -2,
      "name": "Water",
      "level": 5
    },
    {
      "x": 8,
      "y": 0,
      "z": -4,
      "name": "Water_Source",
      "level": 1
    },
    {
      "x": 8,
      "y": 0,
      "z": -3,
      "name": "Water_Source",
      "level": 1
    }
  ]
}