{
  "version": 8,
  "blockIdVersion": 11,
  "anchorX": 0,
  "anchorY": 41,
  "anchorZ": 0,
  "blocks": [
    {
      "x": -11,
      "y": 45,
      "z": 1,
      "name": "Wood_Birch_Branch_Long",
      "support": 15,
      "rotation": 5
    },
    {
      "x": -10,
      "y": 41,
      "z": -1,
      "name": "Furniture_Ancient_Platform",
      "rotation": 1
    },
    {
      "x": -10,
      "y": 41,
      "z": 0,
      "name": "Furniture_Ancient_Platform",
      "rotation": 1
    },
    {
      "x": -10,
      "y": 45,
      "z": 1,
      "name": "Wood_Birch_Branch_Long",
      "support": 15,
      "rotation": 5
    },
    {
      "x": -9,
      "y": 41,
      "z": -1,
      "name": "Furniture_Ancient_Platform",
      "rotation": 1
    },
    {
      "x": -9,
      "y": 41,
      "z": 0,
      "name": "Furniture_Ancient_Platform",
      "rotation": 1
    },
    {
      "x": -9,
      "y": 1,
      "z": 1,
      "name": "Deco_Rope"
    },
    {
      "x": -9,
      "y": 2,
      "z": 1,
      "name": "Deco_Rope"
    },
    {
      "x": -9,
      "y": 3,
      "z": 1,
      "name": "Deco_Rope"
    },
    {
      "x": -9,
      "y": 4,
      "z": 1,
      "name": "Deco_Rope"
    },
    {
      "x": -9,
      "y": 5,
      "z": 1,
      "name": "Deco_Rope"
    },
    {
      "x": -9,
      "y": 6,
      "z": 1,
      "name": "Deco_Rope"
    },
    {
      "x": -9,
      "y": 7,
      "z": 1,
      "name": "Deco_Rope"
    },
    {
      "x": -9,
      "y": 8,
      "z": 1,
      "name": "Deco_Rope"
    },
    {
      "x": -9,
      "y": 9,
      "z": 1,
      "name": "Deco_Rope"
    },
    {
      "x": -9,
      "y": 10,
      "z": 1,
      "name": "Deco_Rope"
    },
    {
      "x": -9,
      "y": 11,
      "z": 1,
      "name": "Deco_Rope"
    },
    {
      "x": -9,
      "y": 12,
      "z": 1,
      "name": "Deco_Rope"
    },
    {
      "x": -9,
      "y": 13,
      "z": 1,
      "name": "Deco_Rope"
    },
    {
      "x": -9,
      "y": 14,
      "z": 1,
      "name": "Deco_Rope"
    },
    {
      "x": -9,
      "y": 15,
      "z": 1,
      "name": "Deco_Rope"
    },
    {
      "x": -9,
      "y": 16,
      "z": 1,
      "name": "Deco_Rope"
    },
    {
      "x": -9,
      "y": 17,
      "z": 1,
      "name": "Deco_Rope"
    },
    {
      "x": -9,
      "y": 18,
      "z": 1,
      "name": "Deco_Rope"
    },
    {
      "x": -9,
      "y": 19,
      "z": 1,
      "name": "Deco_Rope"
    },
    {
      "x": -9,
      "y": 20,
      "z": 1,
      "name": "Deco_Rope"
    },
    {
      "x": -9,
      "y": 21,
      "z": 1,
      "name": "Deco_Rope"
    },
    {
      "x": -9,
      "y": 22,
      "z": 1,
      "name": "Deco_Rope"
    },
    {
      "x": -9,
      "y": 23,
      "z": 1,
      "name": "Deco_Rope"
    },
    {
      "x": -9,
      "y": 24,
      "z": 1,
      "name": "Deco_Rope"
    },
    {
      "x": -9,
      "y": 25,
      "z": 1,
      "name": "Deco_Rope"
    },
    {
      "x": -9,
      "y": 26,
      "z": 1,
      "name": "Deco_Rope"
    },
    {
      "x": -9,
      "y": 27,
      "z": 1,
      "name": "Deco_Rope"
    },
    {
      "x": -9,
      "y": 28,
      "z": 1,
      "name": "Deco_Rope"
    },
    {
      "x": -9,
      "y": 29,
      "z": 1,
      "name": "Deco_Rope"
    },
    {
      "x": -9,
      "y": 30,
      "z": 1,
      "name": "Deco_Rope"
    },
    {
      "x": -9,
      "y": 31,
      "z": 1,
      "name": "Deco_Rope"
    },
    {
      "x": -9,
      "y": 32,
      "z": 1,
      "name": "Deco_Rope"
    },
    {
      "x": -9,
      "y": 33,
      "z": 1,
      "name": "Deco_Rope"
    },
    {
      "x": -9,
      "y": 34,
      "z": 1,
      "name": "Deco_Rope"
    },
    {
      "x": -9,
      "y": 35,
      "z": 1,
      "name": "Deco_Rope"
    },
    {
      "x": -9,
      "y": 36,
      "z": 1,
      "name": "Deco_Rope"
    },
    {
      "x": -9,
      "y": 37,
      "z": 1,
      "name": "Deco_Rope"
    },
    {
      "x": -9,
      "y": 38,
      "z": 1,
      "name": "Deco_Rope"
    },
    {
      "x": -9,
      "y": 39,
      "z": 1,
      "name": "Deco_Rope"
    },
    {
      "x": -9,
      "y": 40,
      "z": 1,
      "name": "Deco_Rope"
    },
    {
      "x": -9,
      "y": 41,
      "z": 1,
      "name": "Deco_Rope"
    },
    {
      "x": -9,
      "y": 42,
      "z": 1,
      "name": "Deco_Rope"
    },
    {
      "x": -9,
      "y": 43,
      "z": 1,
      "name": "Deco_Rope"
    },
    {
      "x": -9,
      "y": 44,
      "z": 1,
      "name": "Deco_Rope"
    },
    {
      "x": -9,
      "y": 45,
      "z": 1,
      "name": "Wood_Birch_Trunk",
      "support": 15,
      "rotation": 5
    },
    {
      "x": -8,
      "y": 41,
      "z": -1,
      "name": "Furniture_Ancient_Platform",
      "rotation": 1
    },
    {
      "x": -8,
      "y": 41,
      "z": 0,
      "name": "Furniture_Ancient_Platform",
      "rotation": 1
    },
    {
      "x": -8,
      "y": 41,
      "z": 1,
      "name": "Furniture_Ancient_Platform",
      "rotation": 1
    },
    {
      "x": -8,
      "y": 45,
      "z": 1,
      "name": "Wood_Birch_Trunk",
      "support": 15,
      "rotation": 5
    },
    {
      "x": -8,
      "y": 41,
      "z": 2,
      "name": "Furniture_Ancient_Platform",
      "rotation": 1
    },
    {
      "x": -7,
      "y": 39,
      "z": -2,
      "name": "Rock_Marble"
    },
    {
      "x": -7,
      "y": 40,
      "z": -2,
      "name": "Rock_Marble"
    },
    {
      "x": -7,
      "y": 41,
      "z": -2,
      "name": "Rock_Marble_SkyGrass"
    },
    {
      "x": -7,
      "y": 39,
      "z": -1,
      "name": "Rock_Marble"
    },
    {
      "x": -7,
      "y": 40,
      "z": -1,
      "name": "Rock_Marble"
    },
    {
      "x": -7,
      "y": 41,
      "z": -1,
      "name": "Rock_Marble_SkyGrass"
    },
    {
      "x": -7,
      "y": 39,
      "z": 0,
      "name": "Rock_Marble"
    },
    {
      "x": -7,
      "y": 40,
      "z": 0,
      "name": "Rock_Marble"
    },
    {
      "x": -7,
      "y": 41,
      "z": 0,
      "name": "Rock_Marble_SkyGrass"
    },
    {
      "x": -7,
      "y": 39,
      "z": 1,
      "name": "Rock_Marble"
    },
    {
      "x": -7,
      "y": 40,
      "z": 1,
      "name": "Rock_Marble"
    },
    {
      "x": -7,
      "y": 41,
      "z": 1,
      "name": "Rock_Marble_SkyGrass"
    },
    {
      "x": -7,
      "y": 45,
      "z": 1,
      "name": "Wood_Birch_Trunk",
      "support": 15,
      "rotation": 5
    },
    {
      "x": -7,
      "y": 39,
      "z": 2,
      "name": "Rock_Marble"
    },
    {
      "x": -7,
      "y": 40,
      "z": 2,
      "name": "Rock_Marble"
    },
    {
      "x": -7,
      "y": 41,
      "z": 2,
      "name": "Rock_Marble_SkyGrass"
    },
    {
      "x": -6,
      "y": 39,
      "z": -4,
      "name": "Rock_Marble"
    },
    {
      "x": -6,
      "y": 40,
      "z": -4,
      "name": "Rock_Marble"
    },
    {
      "x": -6,
      "y": 41,
      "z": -4,
      "name": "Rock_Marble_SkyGrass"
    },
    {
      "x": -6,
      "y": 39,
      "z": -3,
      "name": "Rock_Marble"
    },
    {
      "x": -6,
      "y": 40,
      "z": -3,
      "name": "Rock_Marble"
    },
    {
      "x": -6,
      "y": 41,
      "z": -3,
      "name": "Rock_Marble_SkyGrass"
    },
    {
      "x": -6,
      "y": 39,
      "z": -2,
      "name": "Rock_Marble"
    },
    {
      "x": -6,
      "y": 40,
      "z": -2,
      "name": "Rock_Marble"
    },
    {
      "x": -6,
      "y": 41,
      "z": -2,
      "name": "Rock_Marble_SkyGrass"
    },
    {
      "x": -6,
      "y": 39,
      "z": -1,
      "name": "Rock_Marble"
    },
    {
      "x": -6,
      "y": 40,
      "z": -1,
      "name": "Rock_Marble"
    },
    {
      "x": -6,
      "y": 41,
      "z": -1,
      "name": "Rock_Marble_SkyGrass"
    },
    {
      "x": -6,
      "y": 42,
      "z": -1,
      "name": "Plant_Grass_Sky",
      "support": 15
    },
    {
      "x": -6,
      "y": 35,
      "z": 0,
      "name": "Rock_Marble"
    },
    {
      "x": -6,
      "y": 36,
      "z": 0,
      "name": "Rock_Marble"
    },
    {
      "x": -6,
      "y": 37,
      "z": 0,
      "name": "Rock_Marble"
    },
    {
      "x": -6,
      "y": 38,
      "z": 0,
      "name": "Rock_Lime"
    },
    {
      "x": -6,
      "y": 39,
      "z": 0,
      "name": "Rock_Marble"
    },
    {
      "x": -6,
      "y": 40,
      "z": 0,
      "name": "Rock_Marble"
    },
    {
      "x": -6,
      "y": 41,
      "z": 0,
      "name": "Rock_Marble_SkyGrass"
    },
    {
      "x": -6,
      "y": 35,
      "z": 1,
      "name": "Rock_Marble"
    },
    {
      "x": -6,
      "y": 36,
      "z": 1,
      "name": "Rock_Marble"
    },
    {
      "x": -6,
      "y": 37,
      "z": 1,
      "name": "Rock_Marble"
    },
    {
      "x": -6,
      "y": 38,
      "z": 1,
      "name": "Rock_Marble"
    },
    {
      "x": -6,
      "y": 39,
      "z": 1,
      "name": "Rock_Marble"
    },
    {
      "x": -6,
      "y": 40,
      "z": 1,
      "name": "Rock_Marble"
    },
    {
      "x": -6,
      "y": 41,
      "z": 1,
      "name": "Rock_Marble_SkyGrass"
    },
    {
      "x": -6,
      "y": 42,
      "z": 1,
      "name": "Wood_Birch_Trunk",
      "support": 15
    },
    {
      "x": -6,
      "y": 43,
      "z": 1,
      "name": "Wood_Birch_Trunk",
      "support": 15
    },
    {
      "x": -6,
      "y": 44,
      "z": 1,
      "name": "Wood_Birch_Trunk",
      "support": 15
    },
    {
      "x": -6,
      "y": 45,
      "z": 1,
      "name": "Wood_Birch_Trunk",
      "support": 15,
      "rotation": 5
    },
    {
      "x": -6,
      "y": 36,
      "z": 2,
      "name": "Rock_Marble"
    },
    {
      "x": -6,
      "y": 37,
      "z": 2,
      "name": "Rock_Lime"
    },
    {
      "x": -6,
      "y": 38,
      "z": 2,
      "name": "Rock_Marble"
    },
    {
      "x": -6,
      "y": 39,
      "z": 2,
      "name": "Rock_Marble"
    },
    {
      "x": -6,
      "y": 40,
      "z": 2,
      "name": "Rock_Marble"
    },
    {
      "x": -6,
      "y": 41,
      "z": 2,
      "name": "Rock_Marble_SkyGrass"
    },
    {
      "x": -6,
      "y": 42,
      "z": 2,
      "name": "Plant_Grass_Sky",
      "support": 15
    },
    {
      "x": -6,
      "y": 36,
      "z": 3,
      "name": "Rock_Marble"
    },
    {
      "x": -6,
      "y": 37,
      "z": 3,
      "name": "Rock_Lime"
    },
    {
      "x": -6,
      "y": 38,
      "z": 3,
      "name": "Rock_Chalk"
    },
    {
      "x": -6,
      "y": 39,
      "z": 3,
      "name": "Rock_Marble"
    },
    {
      "x": -6,
      "y": 40,
      "z": 3,
      "name": "Rock_Marble"
    },
    {
      "x": -6,
      "y": 41,
      "z": 3,
      "name": "Rock_Marble_SkyGrass"
    },
    {
      "x": -6,
      "y": 42,
      "z": 3,
      "name": "Plant_Grass_Sky",
      "support": 15
    },
    {
      "x": -6,
      "y": 36,
      "z": 4,
      "name": "Rock_Marble"
    },
    {
      "x": -6,
      "y": 37,
      "z": 4,
      "name": "Rock_Lime"
    },
    {
      "x": -6,
      "y": 38,
      "z": 4,
      "name": "Rock_Chalk"
    },
    {
      "x": -6,
      "y": 39,
      "z": 4,
      "name": "Rock_Marble"
    },
    {
      "x": -6,
      "y": 40,
      "z": 4,
      "name": "Rock_Marble"
    },
    {
      "x": -6,
      "y": 41,
      "z": 4,
      "name": "Rock_Marble_SkyGrass"
    },
    {
      "x": -5,
      "y": 37,
      "z": -5,
      "name": "Rock_Marble"
    },
    {
      "x": -5,
      "y": 38,
      "z": -5,
      "name": "Rock_Lime"
    },
    {
      "x": -5,
      "y": 39,
      "z": -5,
      "name": "Rock_Marble"
    },
    {
      "x": -5,
      "y": 40,
      "z": -5,
      "name": "Rock_Marble"
    },
    {
      "x": -5,
      "y": 41,
      "z": -5,
      "name": "Rock_Marble_SkyGrass"
    },
    {
      "x": -5,
      "y": 37,
      "z": -4,
      "name": "Rock_Marble"
    },
    {
      "x": -5,
      "y": 38,
      "z": -4,
      "name": "Rock_Lime"
    },
    {
      "x": -5,
      "y": 39,
      "z": -4,
      "name": "Rock_Marble"
    },
    {
      "x": -5,
      "y": 40,
      "z": -4,
      "name": "Rock_Marble"
    },
    {
      "x": -5,
      "y": 41,
      "z": -4,
      "name": "Rock_Marble_SkyGrass"
    },
    {
      "x": -5,
      "y": 42,
      "z": -4,
      "name": "Plant_Grass_Sky",
      "support": 15
    },
    {
      "x": -5,
      "y": 39,
      "z": -3,
      "name": "Rock_Marble"
    },
    {
      "x": -5,
      "y": 40,
      "z": -3,
      "name": "Rock_Marble"
    },
    {
      "x": -5,
      "y": 41,
      "z": -3,
      "name": "Rock_Marble_SkyGrass"
    },
    {
      "x": -5,
      "y": 42,
      "z": -3,
      "name": "Plant_Bush_Sky",
      "support": 15
    },
    {
      "x": -5,
      "y": 37,
      "z": -2,
      "name": "Rock_Marble"
    },
    {
      "x": -5,
      "y": 38,
      "z": -2,
      "name": "Rock_Lime"
    },
    {
      "x": -5,
      "y": 39,
      "z": -2,
      "name": "Rock_Marble"
    },
    {
      "x": -5,
      "y": 40,
      "z": -2,
      "name": "Rock_Marble"
    },
    {
      "x": -5,
      "y": 41,
      "z": -2,
      "name": "Rock_Marble_SkyGrass"
    },
    {
      "x": -5,
      "y": 37,
      "z": -1,
      "name": "Rock_Marble"
    },
    {
      "x": -5,
      "y": 38,
      "z": -1,
      "name": "Rock_Lime"
    },
    {
      "x": -5,
      "y": 39,
      "z": -1,
      "name": "Rock_Marble"
    },
    {
      "x": -5,
      "y": 40,
      "z": -1,
      "name": "Rock_Marble"
    },
    {
      "x": -5,
      "y": 41,
      "z": -1,
      "name": "Rock_Marble_SkyGrass"
    },
    {
      "x": -5,
      "y": 35,
      "z": 0,
      "name": "Rock_Marble"
    },
    {
      "x": -5,
      "y": 36,
      "z": 0,
      "name": "Rock_Marble"
    },
    {
      "x": -5,
      "y": 37,
      "z": 0,
      "name": "Rock_Marble"
    },
    {
      "x": -5,
      "y": 38,
      "z": 0,
      "name": "Rock_Lime"
    },
    {
      "x": -5,
      "y": 39,
      "z": 0,
      "name": "Rock_Marble"
    },
    {
      "x": -5,
      "y": 40,
      "z": 0,
      "name": "Rock_Marble"
    },
    {
      "x": -5,
      "y": 41,
      "z": 0,
      "name": "Soil_Gravel_Lime",
      "support": 15
    },
    {
      "x": -5,
      "y": 35,
      "z": 1,
      "name": "Rock_Marble"
    },
    {
      "x": -5,
      "y": 36,
      "z": 1,
      "name": "Rock_Marble"
    },
    {
      "x": -5,
      "y": 37,
      "z": 1,
      "name": "Rock_Marble"
    },
    {
      "x": -5,
      "y": 38,
      "z": 1,
      "name": "Rock_Marble"
    },
    {
      "x": -5,
      "y": 39,
      "z": 1,
      "name": "Rock_Marble"
    },
    {
      "x": -5,
      "y": 40,
      "z": 1,
      "name": "Rock_Marble"
    },
    {
      "x": -5,
      "y": 41,
      "z": 1,
      "name": "Rock_Marble_SkyGrass"
    },
    {
      "x": -5,
      "y": 44,
      "z": 1,
      "name": "Deco_Rope_Diagonal",
      "rotation": 3
    },
    {
      "x": -5,
      "y": 45,
      "z": 1,
      "name": "Wood_Birch_Trunk",
      "support": 15,
      "rotation": 5
    },
    {
      "x": -5,
      "y": 36,
      "z": 2,
      "name": "Rock_Marble"
    },
    {
      "x": -5,
      "y": 37,
      "z": 2,
      "name": "Rock_Lime"
    },
    {
      "x": -5,
      "y": 38,
      "z": 2,
      "name": "Rock_Marble"
    },
    {
      "x": -5,
      "y": 39,
      "z": 2,
      "name": "Rock_Marble"
    },
    {
      "x": -5,
      "y": 40,
      "z": 2,
      "name": "Rock_Marble"
    },
    {
      "x": -5,
      "y": 41,
      "z": 2,
      "name": "Rock_Marble_SkyGrass"
    },
    {
      "x": -5,
      "y": 36,
      "z": 3,
      "name": "Rock_Marble"
    },
    {
      "x": -5,
      "y": 37,
      "z": 3,
      "name": "Rock_Lime"
    },
    {
      "x": -5,
      "y": 38,
      "z": 3,
      "name": "Rock_Chalk"
    },
    {
      "x": -5,
      "y": 39,
      "z": 3,
      "name": "Rock_Marble"
    },
    {
      "x": -5,
      "y": 40,
      "z": 3,
      "name": "Rock_Marble"
    },
    {
      "x": -5,
      "y": 41,
      "z": 3,
      "name": "Rock_Marble_SkyGrass"
    },
    {
      "x": -5,
      "y": 42,
      "z": 3,
      "name": "Plant_Grass_Sky",
      "support": 15
    },
    {
      "x": -5,
      "y": 36,
      "z": 4,
      "name": "Rock_Marble"
    },
    {
      "x": -5,
      "y": 37,
      "z": 4,
      "name": "Rock_Lime"
    },
    {
      "x": -5,
      "y": 38,
      "z": 4,
      "name": "Rock_Chalk"
    },
    {
      "x": -5,
      "y": 39,
      "z": 4,
      "name": "Rock_Marble"
    },
    {
      "x": -5,
      "y": 40,
      "z": 4,
      "name": "Rock_Marble"
    },
    {
      "x": -5,
      "y": 41,
      "z": 4,
      "name": "Rock_Marble_SkyGrass"
    },
    {
      "x": -5,
      "y": 39,
      "z": 5,
      "name": "Rock_Marble"
    },
    {
      "x": -5,
      "y": 40,
      "z": 5,
      "name": "Rock_Marble"
    },
    {
      "x": -5,
      "y": 41,
      "z": 5,
      "name": "Rock_Marble_SkyGrass"
    },
    {
      "x": -4,
      "y": 39,
      "z": -6,
      "name": "Rock_Marble"
    },
    {
      "x": -4,
      "y": 40,
      "z": -6,
      "name": "Rock_Marble"
    },
    {
      "x": -4,
      "y": 41,
      "z": -6,
      "name": "Rock_Marble_SkyGrass"
    },
    {
      "x": -4,
      "y": 37,
      "z": -5,
      "name": "Rock_Lime"
    },
    {
      "x": -4,
      "y": 38,
      "z": -5,
      "name": "Rock_Lime"
    },
    {
      "x": -4,
      "y": 39,
      "z": -5,
      "name": "Rock_Marble"
    },
    {
      "x": -4,
      "y": 40,
      "z": -5,
      "name": "Rock_Marble"
    },
    {
      "x": -4,
      "y": 41,
      "z": -5,
      "name": "Rock_Marble_SkyGrass"
    },
    {
      "x": -4,
      "y": 37,
      "z": -4,
      "name": "Rock_Lime"
    },
    {
      "x": -4,
      "y": 38,
      "z": -4,
      "name": "Rock_Lime"
    },
    {
      "x": -4,
      "y": 39,
      "z": -4,
      "name": "Rock_Marble"
    },
    {
      "x": -4,
      "y": 40,
      "z": -4,
      "name": "Rock_Marble"
    },
    {
      "x": -4,
      "y": 41,
      "z": -4,
      "name": "Rock_Marble_SkyGrass"
    },
    {
      "x": -4,
      "y": 42,
      "z": -4,
      "name": "Plant_Bush_Sky",
      "support": 15
    },
    {
      "x": -4,
      "y": 34,
      "z": -3,
      "name": "Rock_Marble"
    },
    {
      "x": -4,
      "y": 35,
      "z": -3,
      "name": "Rock_Marble"
    },
    {
      "x": -4,
      "y": 36,
      "z": -3,
      "name": "Rock_Lime"
    },
    {
      "x": -4,
      "y": 37,
      "z": -3,
      "name": "Rock_Marble"
    },
    {
      "x": -4,
      "y": 38,
      "z": -3,
      "name": "Rock_Lime"
    },
    {
      "x": -4,
      "y": 39,
      "z": -3,
      "name": "Rock_Marble"
    },
    {
      "x": -4,
      "y": 40,
      "z": -3,
      "name": "Rock_Marble"
    },
    {
      "x": -4,
      "y": 41,
      "z": -3,
      "name": "Rock_Marble_SkyGrass"
    },
    {
      "x": -4,
      "y": 42,
      "z": -3,
      "name": "Plant_Bush_Sky",
      "support": 15
    },
    {
      "x": -4,
      "y": 34,
      "z": -2,
      "name": "Rock_Marble"
    },
    {
      "x": -4,
      "y": 35,
      "z": -2,
      "name": "Rock_Marble"
    },
    {
      "x": -4,
      "y": 36,
      "z": -2,
      "name": "Rock_Lime"
    },
    {
      "x": -4,
      "y": 37,
      "z": -2,
      "name": "Rock_Marble"
    },
    {
      "x": -4,
      "y": 38,
      "z": -2,
      "name": "Rock_Lime"
    },
    {
      "x": -4,
      "y": 39,
      "z": -2,
      "name": "Rock_Marble"
    },
    {
      "x": -4,
      "y": 40,
      "z": -2,
      "name": "Rock_Marble"
    },
    {
      "x": -4,
      "y": 41,
      "z": -2,
      "name": "Rock_Marble_SkyGrass"
    },
    {
      "x": -4,
      "y": 36,
      "z": -1,
      "name": "Rock_Lime"
    },
    {
      "x": -4,
      "y": 37,
      "z": -1,
      "name": "Rock_Marble"
    },
    {
      "x": -4,
      "y": 38,
      "z": -1,
      "name": "Rock_Lime"
    },
    {
      "x": -4,
      "y": 39,
      "z": -1,
      "name": "Rock_Marble"
    },
    {
      "x": -4,
      "y": 40,
      "z": -1,
      "name": "Rock_Marble"
    },
    {
      "x": -4,
      "y": 41,
      "z": -1,
      "name": "Rock_Marble_SkyGrass"
    },
    {
      "x": -4,
      "y": 42,
      "z": -1,
      "name": "Furniture_Ancient_Torch",
      "rotation": 1
    },
    {
      "x": -4,
      "y": 36,
      "z": 0,
      "name": "Rock_Lime"
    },
    {
      "x": -4,
      "y": 37,
      "z": 0,
      "name": "Rock_Marble"
    },
    {
      "x": -4,
      "y": 38,
      "z": 0,
      "name": "Rock_Lime"
    },
    {
      "x": -4,
      "y": 39,
      "z": 0,
      "name": "Rock_Marble"
    },
    {
      "x": -4,
      "y": 40,
      "z": 0,
      "name": "Rock_Marble"
    },
    {
      "x": -4,
      "y": 41,
      "z": 0,
      "name": "Rock_Marble_SkyGrass"
    },
    {
      "x": -4,
      "y": 42,
      "z": 0,
      "name": "Plant_Grass_Sky_Short",
      "support": 15
    },
    {
      "x": -4,
      "y": 36,
      "z": 1,
      "name": "Rock_Marble"
    },
    {
      "x": -4,
      "y": 37,
      "z": 1,
      "name": "Rock_Lime"
    },
    {
      "x": -4,
      "y": 38,
      "z": 1,
      "name": "Rock_Marble"
    },
    {
      "x": -4,
      "y": 39,
      "z": 1,
      "name": "Rock_Marble"
    },
    {
      "x": -4,
      "y": 40,
      "z": 1,
      "name": "Rock_Marble"
    },
    {
      "x": -4,
      "y": 41,
      "z": 1,
      "name": "Rock_Marble_SkyGrass"
    },
    {
      "x": -4,
      "y": 45,
      "z": 1,
      "name": "Wood_Birch_Branch_Long",
      "support": 15,
      "rotation": 5
    },
    {
      "x": -4,
      "y": 36,
      "z": 2,
      "name": "Rock_Marble"
    },
    {
      "x": -4,
      "y": 37,
      "z": 2,
      "name": "Rock_Lime"
    },
    {
      "x": -4,
      "y": 38,
      "z": 2,
      "name": "Rock_Chalk"
    },
    {
      "x": -4,
      "y": 39,
      "z": 2,
      "name": "Rock_Marble"
    },
    {
      "x": -4,
      "y": 40,
      "z": 2,
      "name": "Rock_Marble"
    },
    {
      "x": -4,
      "y": 41,
      "z": 2,
      "name": "Rock_Marble_SkyGrass"
    },
    {
      "x": -4,
      "y": 34,
      "z": 3,
      "name": "Rock_Lime"
    },
    {
      "x": -4,
      "y": 35,
      "z": 3,
      "name": "Rock_Marble"
    },
    {
      "x": -4,
      "y": 36,
      "z": 3,
      "name": "Rock_Marble"
    },
    {
      "x": -4,
      "y": 37,
      "z": 3,
      "name": "Rock_Lime"
    },
    {
      "x": -4,
      "y": 38,
      "z": 3,
      "name": "Rock_Chalk"
    },
    {
      "x": -4,
      "y": 39,
      "z": 3,
      "name": "Rock_Marble"
    },
    {
      "x": -4,
      "y": 40,
      "z": 3,
      "name": "Rock_Marble"
    },
    {
      "x": -4,
      "y": 41,
      "z": 3,
      "name": "Rock_Marble_SkyGrass"
    },
    {
      "x": -4,
      "y": 42,
      "z": 3,
      "name": "Plant_Grass_Sky_Short",
      "support": 15
    },
    {
      "x": -4,
      "y": 34,
      "z": 4,
      "name": "Rock_Lime"
    },
    {
      "x": -4,
      "y": 35,
      "z": 4,
      "name": "Rock_Marble"
    },
    {
      "x": -4,
      "y": 36,
      "z": 4,
      "name": "Rock_Marble"
    },
    {
      "x": -4,
      "y": 37,
      "z": 4,
      "name": "Rock_Lime"
    },
    {
      "x": -4,
      "y": 38,
      "z": 4,
      "name": "Rock_Chalk"
    },
    {
      "x": -4,
      "y": 39,
      "z": 4,
      "name": "Rock_Marble"
    },
    {
      "x": -4,
      "y": 40,
      "z": 4,
      "name": "Rock_Marble"
    },
    {
      "x": -4,
      "y": 41,
      "z": 4,
      "name": "Rock_Marble_SkyGrass"
    },
    {
      "x": -4,
      "y": 42,
      "z": 4,
      "name": "Plant_Grass_Sky_Long",
      "support": 15
    },
    {
      "x": -4,
      "y": 43,
      "z": 4,
      "name": "Plant_Grass_Sky_Long",
      "filler": 1024
    },
    {
      "x": -4,
      "y": 37,
      "z": 5,
      "name": "Rock_Lime"
    },
    {
      "x": -4,
      "y": 38,
      "z": 5,
      "name": "Rock_Chalk"
    },
    {
      "x": -4,
      "y": 39,
      "z": 5,
      "name": "Rock_Marble"
    },
    {
      "x": -4,
      "y": 40,
      "z": 5,
      "name": "Rock_Marble"
    },
    {
      "x": -4,
      "y": 41,
      "z": 5,
      "name": "Rock_Marble_SkyGrass"
    },
    {
      "x": -4,
      "y": 39,
      "z": 6,
      "name": "Rock_Marble"
    },
    {
      "x": -4,
      "y": 40,
      "z": 6,
      "name": "Rock_Marble"
    },
    {
      "x": -4,
      "y": 41,
      "z": 6,
      "name": "Rock_Marble_SkyGrass"
    },
    {
      "x": -4,
      "y": 42,
      "z": 6,
      "name": "Plant_Grass_Sky",
      "support": 15
    },
    {
      "x": -3,
      "y": 39,
      "z": -6,
      "name": "Rock_Chalk"
    },
    {
      "x": -3,
      "y": 40,
      "z": -6,
      "name": "Rock_Marble"
    },
    {
      "x": -3,
      "y": 41,
      "z": -6,
      "name": "Rock_Marble_SkyGrass"
    },
    {
      "x": -3,
      "y": 39,
      "z": -5,
      "name": "Rock_Marble"
    },
    {
      "x": -3,
      "y": 40,
      "z": -5,
      "name": "Rock_Marble"
    },
    {
      "x": -3,
      "y": 41,
      "z": -5,
      "name": "Rock_Marble_SkyGrass"
    },
    {
      "x": -3,
      "y": 42,
      "z": -5,
      "name": "Plant_Grass_Sky",
      "support": 15
    },
    {
      "x": -3,
      "y": 34,
      "z": -4,
      "name": "Rock_Marble"
    },
    {
      "x": -3,
      "y": 35,
      "z": -4,
      "name": "Rock_Chalk"
    },
    {
      "x": -3,
      "y": 36,
      "z": -4,
      "name": "Rock_Lime"
    },
    {
      "x": -3,
      "y": 37,
      "z": -4,
      "name": "Rock_Lime"
    },
    {
      "x": -3,
      "y": 38,
      "z": -4,
      "name": "Rock_Lime"
    },
    {
      "x": -3,
      "y": 39,
      "z": -4,
      "name": "Rock_Marble"
    },
    {
      "x": -3,
      "y": 40,
      "z": -4,
      "name": "Rock_Marble"
    },
    {
      "x": -3,
      "y": 41,
      "z": -4,
      "name": "Rock_Lime"
    },
    {
      "x": -3,
      "y": 42,
      "z": -4,
      "name": "Cloth_Roof_Hide",
      "rotation": 3
    },
    {
      "x": -3,
      "y": 34,
      "z": -3,
      "name": "Rock_Marble"
    },
    {
      "x": -3,
      "y": 35,
      "z": -3,
      "name": "Rock_Chalk"
    },
    {
      "x": -3,
      "y": 36,
      "z": -3,
      "name": "Rock_Lime"
    },
    {
      "x": -3,
      "y": 37,
      "z": -3,
      "name": "Rock_Lime"
    },
    {
      "x": -3,
      "y": 38,
      "z": -3,
      "name": "Rock_Lime"
    },
    {
      "x": -3,
      "y": 39,
      "z": -3,
      "name": "Rock_Marble"
    },
    {
      "x": -3,
      "y": 40,
      "z": -3,
      "name": "Rock_Marble"
    },
    {
      "x": -3,
      "y": 41,
      "z": -3,
      "name": "Rock_Lime"
    },
    {
      "x": -3,
      "y": 42,
      "z": -3,
      "name": "Cloth_Roof_Hide",
      "rotation": 3
    },
    {
      "x": -3,
      "y": 34,
      "z": -2,
      "name": "Rock_Marble"
    },
    {
      "x": -3,
      "y": 35,
      "z": -2,
      "name": "Rock_Marble"
    },
    {
      "x": -3,
      "y": 36,
      "z": -2,
      "name": "Rock_Lime"
    },
    {
      "x": -3,
      "y": 37,
      "z": -2,
      "name": "Rock_Lime"
    },
    {
      "x": -3,
      "y": 38,
      "z": -2,
      "name": "Rock_Lime"
    },
    {
      "x": -3,
      "y": 39,
      "z": -2,
      "name": "Rock_Marble"
    },
    {
      "x": -3,
      "y": 40,
      "z": -2,
      "name": "Rock_Marble"
    },
    {
      "x": -3,
      "y": 41,
      "z": -2,
      "name": "Rock_Lime"
    },
    {
      "x": -3,
      "y": 42,
      "z": -2,
      "name": "Cloth_Roof_Hide",
      "rotation": 3
    },
    {
      "x": -3,
      "y": 36,
      "z": -1,
      "name": "Rock_Lime"
    },
    {
      "x": -3,
      "y": 37,
      "z": -1,
      "name": "Rock_Marble"
    },
    {
      "x": -3,
      "y": 38,
      "z": -1,
      "name": "Rock_Lime"
    },
    {
      "x": -3,
      "y": 39,
      "z": -1,
      "name": "Rock_Marble"
    },
    {
      "x": -3,
      "y": 40,
      "z": -1,
      "name": "Rock_Marble"
    },
    {
      "x": -3,
      "y": 41,
      "z": -1,
      "name": "Rock_Marble_SkyGrass"
    },
    {
      "x": -3,
      "y": 36,
      "z": 0,
      "name": "Rock_Lime"
    },
    {
      "x": -3,
      "y": 37,
      "z": 0,
      "name": "Rock_Marble"
    },
    {
      "x": -3,
      "y": 38,
      "z": 0,
      "name": "Rock_Marble"
    },
    {
      "x": -3,
      "y": 39,
      "z": 0,
      "name": "Rock_Marble"
    },
    {
      "x": -3,
      "y": 40,
      "z": 0,
      "name": "Rock_Marble"
    },
    {
      "x": -3,
      "y": 41,
      "z": 0,
      "name": "Soil_Gravel_Lime",
      "support": 15
    },
    {
      "x": -3,
      "y": 42,
      "z": 0,
      "name": "Rubble_Marble_Medium",
      "support": 15
    },
    {
      "x": -3,
      "y": 36,
      "z": 1,
      "name": "Rock_Marble"
    },
    {
      "x": -3,
      "y": 37,
      "z": 1,
      "name": "Rock_Lime"
    },
    {
      "x": -3,
      "y": 38,
      "z": 1,
      "name": "Rock_Marble"
    },
    {
      "x": -3,
      "y": 39,
      "z": 1,
      "name": "Rock_Marble"
    },
    {
      "x": -3,
      "y": 40,
      "z": 1,
      "name": "Rock_Marble"
    },
    {
      "x": -3,
      "y": 41,
      "z": 1,
      "name": "Soil_Gravel_Lime",
      "support": 15
    },
    {
      "x": -3,
      "y": 45,
      "z": 1,
      "name": "Wood_Birch_Branch_Long",
      "support": 15,
      "rotation": 5
    },
    {
      "x": -3,
      "y": 34,
      "z": 2,
      "name": "Rock_Lime"
    },
    {
      "x": -3,
      "y": 35,
      "z": 2,
      "name": "Rock_Marble"
    },
    {
      "x": -3,
      "y": 36,
      "z": 2,
      "name": "Rock_Marble"
    },
    {
      "x": -3,
      "y": 37,
      "z": 2,
      "name": "Rock_Lime"
    },
    {
      "x": -3,
      "y": 38,
      "z": 2,
      "name": "Rock_Chalk"
    },
    {
      "x": -3,
      "y": 39,
      "z": 2,
      "name": "Rock_Marble"
    },
    {
      "x": -3,
      "y": 40,
      "z": 2,
      "name": "Rock_Marble"
    },
    {
      "x": -3,
      "y": 41,
      "z": 2,
      "name": "Rock_Marble_SkyGrass"
    },
    {
      "x": -3,
      "y": 34,
      "z": 3,
      "name": "Rock_Lime"
    },
    {
      "x": -3,
      "y": 35,
      "z": 3,
      "name": "Rock_Marble"
    },
    {
      "x": -3,
      "y": 36,
      "z": 3,
      "name": "Rock_Marble"
    },
    {
      "x": -3,
      "y": 37,
      "z": 3,
      "name": "Rock_Lime"
    },
    {
      "x": -3,
      "y": 38,
      "z": 3,
      "name": "Rock_Chalk"
    },
    {
      "x": -3,
      "y": 39,
      "z": 3,
      "name": "Rock_Marble"
    },
    {
      "x": -3,
      "y": 40,
      "z": 3,
      "name": "Rock_Marble"
    },
    {
      "x": -3,
      "y": 41,
      "z": 3,
      "name": "Rock_Marble_SkyGrass"
    },
    {
      "x": -3,
      "y": 34,
      "z": 4,
      "name": "Rock_Lime"
    },
    {
      "x": -3,
      "y": 35,
      "z": 4,
      "name": "Rock_Marble"
    },
    {
      "x": -3,
      "y": 36,
      "z": 4,
      "name": "Rock_Marble"
    },
    {
      "x": -3,
      "y": 37,
      "z": 4,
      "name": "Rock_Lime"
    },
    {
      "x": -3,
      "y": 38,
      "z": 4,
      "name": "Rock_Chalk"
    },
    {
      "x": -3,
      "y": 39,
      "z": 4,
      "name": "Rock_Marble"
    },
    {
      "x": -3,
      "y": 40,
      "z": 4,
      "name": "Rock_Marble"
    },
    {
      "x": -3,
      "y": 41,
      "z": 4,
      "name": "Rock_Marble_SkyGrass"
    },
    {
      "x": -3,
      "y": 42,
      "z": 4,
      "name": "Plant_Grass_Sky",
      "support": 15
    },
    {
      "x": -3,
      "y": 34,
      "z": 5,
      "name": "Rock_Lime"
    },
    {
      "x": -3,
      "y": 35,
      "z": 5,
      "name": "Rock_Marble"
    },
    {
      "x": -3,
      "y": 36,
      "z": 5,
      "name": "Rock_Marble"
    },
    {
      "x": -3,
      "y": 37,
      "z": 5,
      "name": "Rock_Lime"
    },
    {
      "x": -3,
      "y": 38,
      "z": 5,
      "name": "Rock_Chalk"
    },
    {
      "x": -3,
      "y": 39,
      "z": 5,
      "name": "Rock_Marble"
    },
    {
      "x": -3,
      "y": 40,
      "z": 5,
      "name": "Rock_Marble"
    },
    {
      "x": -3,
      "y": 41,
      "z": 5,
      "name": "Rock_Marble_SkyGrass"
    },
    {
      "x": -3,
      "y": 42,
      "z": 5,
      "name": "Plant_Grass_Sky_Long",
      "support": 15
    },
    {
      "x": -3,
      "y": 43,
      "z": 5,
      "name": "Plant_Grass_Sky_Long",
      "filler": 1024
    },
    {
      "x": -3,
      "y": 38,
      "z": 6,
      "name": "Rock_Chalk"
    },
    {
      "x": -3,
      "y": 39,
      "z": 6,
      "name": "Rock_Marble"
    },
    {
      "x": -3,
      "y": 40,
      "z": 6,
      "name": "Rock_Marble"
    },
    {
      "x": -3,
      "y": 41,
      "z": 6,
      "name": "Rock_Marble_SkyGrass"
    },
    {
      "x": -2,
      "y": 39,
      "z": -7,
      "name": "Rock_Chalk"
    },
    {
      "x": -2,
      "y": 40,
      "z": -7,
      "name": "Rock_Marble"
    },
    {
      "x": -2,
      "y": 41,
      "z": -7,
      "name": "Rock_Marble_SkyGrass"
    },
    {
      "x": -2,
      "y": 39,
      "z": -6,
      "name": "Rock_Chalk"
    },
    {
      "x": -2,
      "y": 40,
      "z": -6,
      "name": "Rock_Marble"
    },
    {
      "x": -2,
      "y": 41,
      "z": -6,
      "name": "Rock_Marble_SkyGrass"
    },
    {
      "x": -2,
      "y": 37,
      "z": -5,
      "name": "Rock_Lime"
    },
    {
      "x": -2,
      "y": 38,
      "z": -5,
      "name": "Rock_Lime"
    },
    {
      "x": -2,
      "y": 39,
      "z": -5,
      "name": "Rock_Chalk"
    },
    {
      "x": -2,
      "y": 40,
      "z": -5,
      "name": "Rock_Marble"
    },
    {
      "x": -2,
      "y": 41,
      "z": -5,
      "name": "Rock_Marble_SkyGrass"
    },
    {
      "x": -2,
      "y": 42,
      "z": -5,
      "name": "Plant_Grass_Sky",
      "support": 15
    },
    {
      "x": -2,
      "y": 34,
      "z": -4,
      "name": "Rock_Marble"
    },
    {
      "x": -2,
      "y": 35,
      "z": -4,
      "name": "Rock_Chalk"
    },
    {
      "x": -2,
      "y": 36,
      "z": -4,
      "name": "Rock_Lime"
    },
    {
      "x": -2,
      "y": 37,
      "z": -4,
      "name": "Rock_Lime"
    },
    {
      "x": -2,
      "y": 38,
      "z": -4,
      "name": "Rock_Lime"
    },
    {
      "x": -2,
      "y": 39,
      "z": -4,
      "name": "Rock_Chalk"
    },
    {
      "x": -2,
      "y": 40,
      "z": -4,
      "name": "Rock_Marble"
    },
    {
      "x": -2,
      "y": 41,
      "z": -4,
      "name": "Rock_Lime"
    },
    {
      "x": -2,
      "y": 43,
      "z": -4,
      "name": "Cloth_Roof_Hide",
      "rotation": 3
    },
    {
      "x": -2,
      "y": 34,
      "z": -3,
      "name": "Rock_Marble"
    },
    {
      "x": -2,
      "y": 35,
      "z": -3,
      "name": "Rock_Chalk"
    },
    {
      "x": -2,
      "y": 36,
      "z": -3,
      "name": "Rock_Lime"
    },
    {
      "x": -2,
      "y": 37,
      "z": -3,
      "name": "Rock_Lime"
    },
    {
      "x": -2,
      "y": 38,
      "z": -3,
      "name": "Rock_Lime"
    },
    {
      "x": -2,
      "y": 39,
      "z": -3,
      "name": "Rock_Marble"
    },
    {
      "x": -2,
      "y": 40,
      "z": -3,
      "name": "Rock_Marble"
    },
    {
      "x": -2,
      "y": 41,
      "z": -3,
      "name": "Rock_Lime"
    },
    {
      "x": -2,
      "y": 42,
      "z": -3,
      "name": "Furniture_Crude_Chest_Small",
      "components": {
        "Components": {
          "PlacedByInteraction": {
            "WhoPlacedUuid": {
              "$binary": "rmwkrpH8RVykTc7XnK4YBA==",
              "$type": "04"
            }
          },
          "container": {
            "Custom": false,
            "AllowViewing": true,
            "ItemContainer": {
              "Capacity": 18,
              "Items": {}
            }
          }
        }
      }
    },
    {
      "x": -2,
      "y": 43,
      "z": -3,
      "name": "Cloth_Roof_Hide",
      "rotation": 3
    },
    {
      "x": -2,
      "y": 35,
      "z": -2,
      "name": "Rock_Chalk"
    },
    {
      "x": -2,
      "y": 36,
      "z": -2,
      "name": "Rock_Lime"
    },
    {
      "x": -2,
      "y": 37,
      "z": -2,
      "name": "Rock_Lime"
    },
    {
      "x": -2,
      "y": 38,
      "z": -2,
      "name": "Rock_Lime"
    },
    {
      "x": -2,
      "y": 39,
      "z": -2,
      "name": "Rock_Marble"
    },
    {
      "x": -2,
      "y": 40,
      "z": -2,
      "name": "Rock_Marble"
    },
    {
      "x": -2,
      "y": 41,
      "z": -2,
      "name": "Rock_Lime"
    },
    {
      "x": -2,
      "y": 42,
      "z": -2,
      "name": "Cloth_Roof_Hide_Flap",
      "rotation": 1
    },
    {
      "x": -2,
      "y": 43,
      "z": -2,
      "name": "Cloth_Roof_Hide",
      "rotation": 3
    },
    {
      "x": -2,
      "y": 35,
      "z": -1,
      "name": "Rock_Chalk"
    },
    {
      "x": -2,
      "y": 36,
      "z": -1,
      "name": "Rock_Lime"
    },
    {
      "x": -2,
      "y": 37,
      "z": -1,
      "name": "Rock_Marble"
    },
    {
      "x": -2,
      "y": 38,
      "z": -1,
      "name": "Rock_Lime"
    },
    {
      "x": -2,
      "y": 39,
      "z": -1,
      "name": "Rock_Marble"
    },
    {
      "x": -2,
      "y": 40,
      "z": -1,
      "name": "Rock_Marble"
    },
    {
      "x": -2,
      "y": 41,
      "z": -1,
      "name": "Soil_Gravel_Lime",
      "support": 15
    },
    {
      "x": -2,
      "y": 35,
      "z": 0,
      "name": "Rock_Marble"
    },
    {
      "x": -2,
      "y": 36,
      "z": 0,
      "name": "Rock_Lime"
    },
    {
      "x": -2,
      "y": 37,
      "z": 0,
      "name": "Rock_Marble"
    },
    {
      "x": -2,
      "y": 38,
      "z": 0,
      "name": "Rock_Marble"
    },
    {
      "x": -2,
      "y": 39,
      "z": 0,
      "name": "Rock_Marble"
    },
    {
      "x": -2,
      "y": 40,
      "z": 0,
      "name": "Rock_Marble"
    },
    {
      "x": -2,
      "y": 41,
      "z": 0,
      "name": "Soil_Gravel_Lime",
      "support": 15
    },
    {
      "x": -2,
      "y": 35,
      "z": 1,
      "name": "Rock_Marble"
    },
    {
      "x": -2,
      "y": 36,
      "z": 1,
      "name": "Rock_Marble"
    },
    {
      "x": -2,
      "y": 37,
      "z": 1,
      "name": "Rock_Lime"
    },
    {
      "x": -2,
      "y": 38,
      "z": 1,
      "name": "Rock_Marble"
    },
    {
      "x": -2,
      "y": 39,
      "z": 1,
      "name": "Rock_Marble"
    },
    {
      "x": -2,
      "y": 40,
      "z": 1,
      "name": "Rock_Marble"
    },
    {
      "x": -2,
      "y": 41,
      "z": 1,
      "name": "Soil_Gravel_Lime",
      "support": 15
    },
    {
      "x": -2,
      "y": 34,
      "z": 2,
      "name": "Rock_Lime"
    },
    {
      "x": -2,
      "y": 35,
      "z": 2,
      "name": "Rock_Marble"
    },
    {
      "x": -2,
      "y": 36,
      "z": 2,
      "name": "Rock_Marble"
    },
    {
      "x": -2,
      "y": 37,
      "z": 2,
      "name": "Rock_Lime"
    },
    {
      "x": -2,
      "y": 38,
      "z": 2,
      "name": "Rock_Chalk"
    },
    {
      "x": -2,
      "y": 39,
      "z": 2,
      "name": "Rock_Marble"
    },
    {
      "x": -2,
      "y": 40,
      "z": 2,
      "name": "Rock_Marble"
    },
    {
      "x": -2,
      "y": 41,
      "z": 2,
      "name": "Soil_Gravel_Lime",
      "support": 15
    },
    {
      "x": -2,
      "y": 34,
      "z": 3,
      "name": "Rock_Lime"
    },
    {
      "x": -2,
      "y": 35,
      "z": 3,
      "name": "Rock_Marble"
    },
    {
      "x": -2,
      "y": 36,
      "z": 3,
      "name": "Rock_Marble"
    },
    {
      "x": -2,
      "y": 37,
      "z": 3,
      "name": "Rock_Lime"
    },
    {
      "x": -2,
      "y": 38,
      "z": 3,
      "name": "Rock_Chalk"
    },
    {
      "x": -2,
      "y": 39,
      "z": 3,
      "name": "Rock_Marble"
    },
    {
      "x": -2,
      "y": 40,
      "z": 3,
      "name": "Rock_Marble"
    },
    {
      "x": -2,
      "y": 41,
      "z": 3,
      "name": "Rock_Marble_SkyGrass"
    },
    {
      "x": -2,
      "y": 42,
      "z": 3,
      "name": "Furniture_Crude_Chest_Small",
      "components": {
        "Components": {
          "PlacedByInteraction": {
            "WhoPlacedUuid": {
              "$binary": "rmwkrpH8RVykTc7XnK4YBA==",
              "$type": "04"
            }
          },
          "container": {
            "Custom": false,
            "AllowViewing": true,
            "ItemContainer": {
              "Capacity": 18,
              "Items": {}
            }
          }
        }
      },
      "rotation": 3
    },
    {
      "x": -2,
      "y": 34,
      "z": 4,
      "name": "Rock_Lime"
    },
    {
      "x": -2,
      "y": 35,
      "z": 4,
      "name": "Rock_Marble"
    },
    {
      "x": -2,
      "y": 36,
      "z": 4,
      "name": "Rock_Marble"
    },
    {
      "x": -2,
      "y": 37,
      "z": 4,
      "name": "Rock_Lime"
    },
    {
      "x": -2,
      "y": 38,
      "z": 4,
      "name": "Rock_Chalk"
    },
    {
      "x": -2,
      "y": 39,
      "z": 4,
      "name": "Rock_Marble"
    },
    {
      "x": -2,
      "y": 40,
      "z": 4,
      "name": "Rock_Marble"
    },
    {
      "x": -2,
      "y": 41,
      "z": 4,
      "name": "Rock_Marble_SkyGrass"
    },
    {
      "x": -2,
      "y": 42,
      "z": 4,
      "name": "Wood_Birch_Trunk",
      "support": 15,
      "rotation": 5
    },
    {
      "x": -2,
      "y": 34,
      "z": 5,
      "name": "Rock_Lime"
    },
    {
      "x": -2,
      "y": 35,
      "z": 5,
      "name": "Rock_Marble"
    },
    {
      "x": -2,
      "y": 36,
      "z": 5,
      "name": "Rock_Lime"
    },
    {
      "x": -2,
      "y": 37,
      "z": 5,
      "name": "Rock_Lime"
    },
    {
      "x": -2,
      "y": 38,
      "z": 5,
      "name": "Rock_Chalk"
    },
    {
      "x": -2,
      "y": 39,
      "z": 5,
      "name": "Rock_Marble"
    },
    {
      "x": -2,
      "y": 40,
      "z": 5,
      "name": "Rock_Marble"
    },
    {
      "x": -2,
      "y": 41,
      "z": 5,
      "name": "Rock_Marble_SkyGrass"
    },
    {
      "x": -2,
      "y": 38,
      "z": 6,
      "name": "Rock_Chalk"
    },
    {
      "x": -2,
      "y": 39,
      "z": 6,
      "name": "Rock_Marble"
    },
    {
      "x": -2,
      "y": 40,
      "z": 6,
      "name": "Rock_Marble"
    },
    {
      "x": -2,
      "y": 41,
      "z": 6,
      "name": "Rock_Marble_SkyGrass"
    },
    {
      "x": -2,
      "y": 42,
      "z": 6,
      "name": "Plant_Grass_Sky_Short",
      "support": 15
    },
    {
      "x": -2,
      "y": 39,
      "z": 7,
      "name": "Rock_Marble"
    },
    {
      "x": -2,
      "y": 40,
      "z": 7,
      "name": "Rock_Marble"
    },
    {
      "x": -2,
      "y": 41,
      "z": 7,
      "name": "Rock_Marble_SkyGrass"
    },
    {
      "x": -1,
      "y": 39,
      "z": -7,
      "name": "Rock_Chalk"
    },
    {
      "x": -1,
      "y": 40,
      "z": -7,
      "name": "Rock_Marble"
    },
    {
      "x": -1,
      "y": 41,
      "z": -7,
      "name": "Rock_Marble_SkyGrass"
    },
    {
      "x": -1,
      "y": 39,
      "z": -6,
      "name": "Rock_Chalk"
    },
    {
      "x": -1,
      "y": 40,
      "z": -6,
      "name": "Rock_Marble"
    },
    {
      "x": -1,
      "y": 41,
      "z": -6,
      "name": "Rock_Marble_SkyGrass"
    },
    {
      "x": -1,
      "y": 42,
      "z": -6,
      "name": "Plant_Grass_Sky_Long",
      "support": 15
    },
    {
      "x": -1,
      "y": 43,
      "z": -6,
      "name": "Plant_Grass_Sky_Long",
      "filler": 1024
    },
    {
      "x": -1,
      "y": 37,
      "z": -5,
      "name": "Rock_Lime"
    },
    {
      "x": -1,
      "y": 38,
      "z": -5,
      "name": "Rock_Lime"
    },
    {
      "x": -1,
      "y": 39,
      "z": -5,
      "name": "Rock_Chalk"
    },
    {
      "x": -1,
      "y": 40,
      "z": -5,
      "name": "Rock_Marble"
    },
    {
      "x": -1,
      "y": 41,
      "z": -5,
      "name": "Rock_Marble_SkyGrass"
    },
    {
      "x": -1,
      "y": 36,
      "z": -4,
      "name": "Rock_Lime"
    },
    {
      "x": -1,
      "y": 37,
      "z": -4,
      "name": "Rock_Lime"
    },
    {
      "x": -1,
      "y": 38,
      "z": -4,
      "name": "Rock_Lime"
    },
    {
      "x": -1,
      "y": 39,
      "z": -4,
      "name": "Rock_Chalk"
    },
    {
      "x": -1,
      "y": 40,
      "z": -4,
      "name": "Rock_Marble"
    },
    {
      "x": -1,
      "y": 41,
      "z": -4,
      "name": "Rock_Lime"
    },
    {
      "x": -1,
      "y": 43,
      "z": -4,
      "name": "Cloth_Roof_Hide",
      "rotation": 1
    },
    {
      "x": -1,
      "y": 35,
      "z": -3,
      "name": "Rock_Chalk"
    },
    {
      "x": -1,
      "y": 36,
      "z": -3,
      "name": "Rock_Lime"
    },
    {
      "x": -1,
      "y": 37,
      "z": -3,
      "name": "Rock_Lime"
    },
    {
      "x": -1,
      "y": 38,
      "z": -3,
      "name": "Rock_Lime"
    },
    {
      "x": -1,
      "y": 39,
      "z": -3,
      "name": "Rock_Marble"
    },
    {
      "x": -1,
      "y": 40,
      "z": -3,
      "name": "Rock_Marble"
    },
    {
      "x": -1,
      "y": 41,
      "z": -3,
      "name": "Rock_Lime"
    },
    {
      "x": -1,
      "y": 42,
      "z": -3,
      "name": "Furniture_Crude_Bed",
      "components": {
        "Components": {
          "PlacedByInteraction": {
            "WhoPlacedUuid": {
              "$binary": "rmwkrpH8RVykTc7XnK4YBA==",
              "$type": "04"
            }
          },
          "RespawnBlock": {}
        }
      }
    },
    {
      "x": -1,
      "y": 43,
      "z": -3,
      "name": "Cloth_Roof_Hide",
      "rotation": 1
    },
    {
      "x": -1,
      "y": 35,
      "z": -2,
      "name": "Rock_Chalk"
    },
    {
      "x": -1,
      "y": 36,
      "z": -2,
      "name": "Rock_Lime"
    },
    {
      "x": -1,
      "y": 37,
      "z": -2,
      "name": "Rock_Lime"
    },
    {
      "x": -1,
      "y": 38,
      "z": -2,
      "name": "Rock_Marble"
    },
    {
      "x": -1,
      "y": 39,
      "z": -2,
      "name": "Rock_Marble"
    },
    {
      "x": -1,
      "y": 40,
      "z": -2,
      "name": "Rock_Marble"
    },
    {
      "x": -1,
      "y": 41,
      "z": -2,
      "name": "Rock_Lime"
    },
    {
      "x": -1,
      "y": 42,
      "z": -2,
      "name": "Furniture_Crude_Bed",
      "filler": 32
    },
    {
      "x": -1,
      "y": 43,
      "z": -2,
      "name": "Cloth_Roof_Hide",
      "rotation": 1
    },
    {
      "x": -1,
      "y": 30,
      "z": -1,
      "name": "Rock_Marble"
    },
    {
      "x": -1,
      "y": 31,
      "z": -1,
      "name": "Rock_Marble"
    },
    {
      "x": -1,
      "y": 32,
      "z": -1,
      "name": "Rock_Chalk"
    },
    {
      "x": -1,
      "y": 33,
      "z": -1,
      "name": "Rock_Marble"
    },
    {
      "x": -1,
      "y": 34,
      "z": -1,
      "name": "Rock_Marble"
    },
    {
      "x": -1,
      "y": 35,
      "z": -1,
      "name": "Rock_Chalk"
    },
    {
      "x": -1,
      "y": 36,
      "z": -1,
      "name": "Rock_Lime"
    },
    {
      "x": -1,
      "y": 37,
      "z": -1,
      "name": "Rock_Lime"
    },
    {
      "x": -1,
      "y": 38,
      "z": -1,
      "name": "Rock_Marble"
    },
    {
      "x": -1,
      "y": 39,
      "z": -1,
      "name": "Rock_Marble"
    },
    {
      "x": -1,
      "y": 40,
      "z": -1,
      "name": "Rock_Marble"
    },
    {
      "x": -1,
      "y": 41,
      "z": -1,
      "name": "Soil_Gravel_Lime",
      "support": 15
    },
    {
      "x": -1,
      "y": 30,
      "z": 0,
      "name": "Rock_Marble"
    },
    {
      "x": -1,
      "y": 31,
      "z": 0,
      "name": "Rock_Marble"
    },
    {
      "x": -1,
      "y": 32,
      "z": 0,
      "name": "Rock_Chalk"
    },
    {
      "x": -1,
      "y": 33,
      "z": 0,
      "name": "Rock_Marble"
    },
    {
      "x": -1,
      "y": 34,
      "z": 0,
      "name": "Rock_Chalk"
    },
    {
      "x": -1,
      "y": 35,
      "z": 0,
      "name": "Rock_Marble"
    },
    {
      "x": -1,
      "y": 36,
      "z": 0,
      "name": "Rock_Marble"
    },
    {
      "x": -1,
      "y": 37,
      "z": 0,
      "name": "Rock_Marble"
    },
    {
      "x": -1,
      "y": 38,
      "z": 0,
      "name": "Rock_Marble"
    },
    {
      "x": -1,
      "y": 39,
      "z": 0,
      "name": "Rock_Marble"
    },
    {
      "x": -1,
      "y": 40,
      "z": 0,
      "name": "Rock_Marble"
    },
    {
      "x": -1,
      "y": 41,
      "z": 0,
      "name": "Rock_Lime"
    },
    {
      "x": -1,
      "y": 42,
      "z": 0,
      "name": "Deco_Campfire_Off"
    },
    {
      "x": -1,
      "y": 30,
      "z": 1,
      "name": "Rock_Marble"
    },
    {
      "x": -1,
      "y": 31,
      "z": 1,
      "name": "Rock_Marble"
    },
    {
      "x": -1,
      "y": 32,
      "z": 1,
      "name": "Rock_Chalk"
    },
    {
      "x": -1,
      "y": 33,
      "z": 1,
      "name": "Rock_Marble"
    },
    {
      "x": -1,
      "y": 34,
      "z": 1,
      "name": "Rock_Lime"
    },
    {
      "x": -1,
      "y": 35,
      "z": 1,
      "name": "Rock_Marble"
    },
    {
      "x": -1,
      "y": 36,
      "z": 1,
      "name": "Rock_Marble"
    },
    {
      "x": -1,
      "y": 37,
      "z": 1,
      "name": "Rock_Marble"
    },
    {
      "x": -1,
      "y": 38,
      "z": 1,
      "name": "Rock_Marble"
    },
    {
      "x": -1,
      "y": 39,
      "z": 1,
      "name": "Rock_Marble"
    },
    {
      "x": -1,
      "y": 40,
      "z": 1,
      "name": "Rock_Marble"
    },
    {
      "x": -1,
      "y": 41,
      "z": 1,
      "name": "Soil_Gravel_Lime",
      "support": 15
    },
    {
      "x": -1,
      "y": 35,
      "z": 2,
      "name": "Rock_Marble"
    },
    {
      "x": -1,
      "y": 36,
      "z": 2,
      "name": "Rock_Marble"
    },
    {
      "x": -1,
      "y": 37,
      "z": 2,
      "name": "Rock_Lime"
    },
    {
      "x": -1,
      "y": 38,
      "z": 2,
      "name": "Rock_Marble"
    },
    {
      "x": -1,
      "y": 39,
      "z": 2,
      "name": "Rock_Marble"
    },
    {
      "x": -1,
      "y": 40,
      "z": 2,
      "name": "Rock_Marble"
    },
    {
      "x": -1,
      "y": 41,
      "z": 2,
      "name": "Soil_Gravel_Lime",
      "support": 15
    },
    {
      "x": -1,
      "y": 34,
      "z": 3,
      "name": "Rock_Lime"
    },
    {
      "x": -1,
      "y": 35,
      "z": 3,
      "name": "Rock_Marble"
    },
    {
      "x": -1,
      "y": 36,
      "z": 3,
      "name": "Rock_Lime"
    },
    {
      "x": -1,
      "y": 37,
      "z": 3,
      "name": "Rock_Lime"
    },
    {
      "x": -1,
      "y": 38,
      "z": 3,
      "name": "Rock_Chalk"
    },
    {
      "x": -1,
      "y": 39,
      "z": 3,
      "name": "Rock_Marble"
    },
    {
      "x": -1,
      "y": 40,
      "z": 3,
      "name": "Rock_Marble"
    },
    {
      "x": -1,
      "y": 41,
      "z": 3,
      "name": "Rock_Marble_SkyGrass"
    },
    {
      "x": -1,
      "y": 42,
      "z": 3,
      "name": "Rubble_Marble",
      "support": 15
    },
    {
      "x": -1,
      "y": 34,
      "z": 4,
      "name": "Rock_Lime"
    },
    {
      "x": -1,
      "y": 35,
      "z": 4,
      "name": "Rock_Marble"
    },
    {
      "x": -1,
      "y": 36,
      "z": 4,
      "name": "Rock_Lime"
    },
    {
      "x": -1,
      "y": 37,
      "z": 4,
      "name": "Rock_Lime"
    },
    {
      "x": -1,
      "y": 38,
      "z": 4,
      "name": "Rock_Chalk"
    },
    {
      "x": -1,
      "y": 39,
      "z": 4,
      "name": "Rock_Marble"
    },
    {
      "x": -1,
      "y": 40,
      "z": 4,
      "name": "Rock_Marble"
    },
    {
      "x": -1,
      "y": 41,
      "z": 4,
      "name": "Rock_Marble_SkyGrass"
    },
    {
      "x": -1,
      "y": 42,
      "z": 4,
      "name": "Wood_Birch_Trunk",
      "support": 15,
      "rotation": 5
    },
    {
      "x": -1,
      "y": 37,
      "z": 5,
      "name": "Rock_Lime"
    },
    {
      "x": -1,
      "y": 38,
      "z": 5,
      "name": "Rock_Chalk"
    },
    {
      "x": -1,
      "y": 39,
      "z": 5,
      "name": "Rock_Marble"
    },
    {
      "x": -1,
      "y": 40,
      "z": 5,
      "name": "Rock_Marble"
    },
    {
      "x": -1,
      "y": 41,
      "z": 5,
      "name": "Rock_Marble_SkyGrass"
    },
    {
      "x": -1,
      "y": 38,
      "z": 6,
      "name": "Rock_Chalk"
    },
    {
      "x": -1,
      "y": 39,
      "z": 6,
      "name": "Rock_Marble"
    },
    {
      "x": -1,
      "y": 40,
      "z": 6,
      "name": "Rock_Marble"
    },
    {
      "x": -1,
      "y": 41,
      "z": 6,
      "name": "Rock_Marble_SkyGrass"
    },
    {
      "x": -1,
      "y": 39,
      "z": 7,
      "name": "Rock_Marble"
    },
    {
      "x": -1,
      "y": 40,
      "z": 7,
      "name": "Rock_Marble"
    },
    {
      "x": -1,
      "y": 41,
      "z": 7,
      "name": "Rock_Marble_SkyGrass"
    },
    {
      "x": 0,
      "y": 39,
      "z": -7,
      "name": "Rock_Chalk"
    },
    {
      "x": 0,
      "y": 40,
      "z": -7,
      "name": "Rock_Marble"
    },
    {
      "x": 0,
      "y": 41,
      "z": -7,
      "name": "Rock_Marble_SkyGrass"
    },
    {
      "x": 0,
      "y": 39,
      "z": -6,
      "name": "Rock_Chalk"
    },
    {
      "x": 0,
      "y": 40,
      "z": -6,
      "name": "Rock_Marble"
    },
    {
      "x": 0,
      "y": 41,
      "z": -6,
      "name": "Rock_Marble_SkyGrass"
    },
    {
      "x": 0,
      "y": 42,
      "z": -6,
      "name": "Plant_Grass_Sky",
      "support": 15
    },
    {
      "x": 0,
      "y": 37,
      "z": -5,
      "name": "Rock_Lime"
    },
    {
      "x": 0,
      "y": 38,
      "z": -5,
      "name": "Rock_Marble"
    },
    {
      "x": 0,
      "y": 39,
      "z": -5,
      "name": "Rock_Chalk"
    },
    {
      "x": 0,
      "y": 40,
      "z": -5,
      "name": "Rock_Marble"
    },
    {
      "x": 0,
      "y": 41,
      "z": -5,
      "name": "Rock_Marble_SkyGrass"
    },
    {
      "x": 0,
      "y": 36,
      "z": -4,
      "name": "Rock_Lime"
    },
    {
      "x": 0,
      "y": 37,
      "z": -4,
      "name": "Rock_Lime"
    },
    {
      "x": 0,
      "y": 38,
      "z": -4,
      "name": "Rock_Marble"
    },
    {
      "x": 0,
      "y": 39,
      "z": -4,
      "name": "Rock_Chalk"
    },
    {
      "x": 0,
      "y": 40,
      "z": -4,
      "name": "Rock_Marble"
    },
    {
      "x": 0,
      "y": 41,
      "z": -4,
      "name": "Rock_Lime"
    },
    {
      "x": 0,
      "y": 42,
      "z": -4,
      "name": "Cloth_Roof_Hide",
      "rotation": 1
    },
    {
      "x": 0,
      "y": 32,
      "z": -3,
      "name": "Rock_Chalk"
    },
    {
      "x": 0,
      "y": 33,
      "z": -3,
      "name": "Rock_Marble"
    },
    {
      "x": 0,
      "y": 34,
      "z": -3,
      "name": "Rock_Marble"
    },
    {
      "x": 0,
      "y": 35,
      "z": -3,
      "name": "Rock_Chalk"
    },
    {
      "x": 0,
      "y": 36,
      "z": -3,
      "name": "Rock_Lime"
    },
    {
      "x": 0,
      "y": 37,
      "z": -3,
      "name": "Rock_Lime"
    },
    {
      "x": 0,
      "y": 38,
      "z": -3,
      "name": "Rock_Marble"
    },
    {
      "x": 0,
      "y": 39,
      "z": -3,
      "name": "Rock_Chalk"
    },
    {
      "x": 0,
      "y": 40,
      "z": -3,
      "name": "Rock_Marble"
    },
    {
      "x": 0,
      "y": 41,
      "z": -3,
      "name": "Rock_Lime"
    },
    {
      "x": 0,
      "y": 42,
      "z": -3,
      "name": "Cloth_Roof_Hide_Flap",
      "rotation": 1
    },
    {
      "x": 0,
      "y": 32,
      "z": -2,
      "name": "Rock_Chalk"
    },
    {
      "x": 0,
      "y": 33,
      "z": -2,
      "name": "Rock_Marble"
    },
    {
      "x": 0,
      "y": 34,
      "z": -2,
      "name": "Rock_Chalk"
    },
    {
      "x": 0,
      "y": 35,
      "z": -2,
      "name": "Rock_Chalk"
    },
    {
      "x": 0,
      "y": 36,
      "z": -2,
      "name": "Rock_Lime"
    },
    {
      "x": 0,
      "y": 37,
      "z": -2,
      "name": "Rock_Lime"
    },
    {
      "x": 0,
      "y": 38,
      "z": -2,
      "name": "Rock_Marble"
    },
    {
      "x": 0,
      "y": 39,
      "z": -2,
      "name": "Rock_Marble"
    },
    {
      "x": 0,
      "y": 40,
      "z": -2,
      "name": "Rock_Marble"
    },
    {
      "x": 0,
      "y": 41,
      "z": -2,
      "name": "Rock_Lime"
    },
    {
      "x": 0,
      "y": 42,
      "z": -2,
      "name": "Cloth_Roof_Hide",
      "rotation": 1
    },
    {
      "x": 0,
      "y": 30,
      "z": -1,
      "name": "Rock_Marble"
    },
    {
      "x": 0,
      "y": 31,
      "z": -1,
      "name": "Rock_Marble"
    },
    {
      "x": 0,
      "y": 32,
      "z": -1,
      "name": "Rock_Chalk"
    },
    {
      "x": 0,
      "y": 33,
      "z": -1,
      "name": "Rock_Marble"
    },
    {
      "x": 0,
      "y": 34,
      "z": -1,
      "name": "Rock_Chalk"
    },
    {
      "x": 0,
      "y": 35,
      "z": -1,
      "name": "Rock_Chalk"
    },
    {
      "x": 0,
      "y": 36,
      "z": -1,
      "name": "Rock_Lime"
    },
    {
      "x": 0,
      "y": 37,
      "z": -1,
      "name": "Rock_Lime"
    },
    {
      "x": 0,
      "y": 38,
      "z": -1,
      "name": "Rock_Marble"
    },
    {
      "x": 0,
      "y": 39,
      "z": -1,
      "name": "Rock_Marble"
    },
    {
      "x": 0,
      "y": 40,
      "z": -1,
      "name": "Rock_Marble"
    },
    {
      "x": 0,
      "y": 41,
      "z": -1,
      "name": "Rock_Lime"
    },
    {
      "x": 0,
      "y": 30,
      "z": 0,
      "name": "Rock_Marble"
    },
    {
      "x": 0,
      "y": 31,
      "z": 0,
      "name": "Rock_Marble"
    },
    {
      "x": 0,
      "y": 32,
      "z": 0,
      "name": "Rock_Chalk"
    },
    {
      "x": 0,
      "y": 33,
      "z": 0,
      "name": "Rock_Marble"
    },
    {
      "x": 0,
      "y": 34,
      "z": 0,
      "name": "Rock_Chalk"
    },
    {
      "x": 0,
      "y": 35,
      "z": 0,
      "name": "Rock_Chalk"
    },
    {
      "x": 0,
      "y": 36,
      "z": 0,
      "name": "Rock_Lime"
    },
    {
      "x": 0,
      "y": 37,
      "z": 0,
      "name": "Rock_Marble"
    },
    {
      "x": 0,
      "y": 38,
      "z": 0,
      "name": "Rock_Marble"
    },
    {
      "x": 0,
      "y": 39,
      "z": 0,
      "name": "Rock_Marble"
    },
    {
      "x": 0,
      "y": 40,
      "z": 0,
      "name": "Rock_Marble"
    },
    {
      "x": 0,
      "y": 41,
      "z": 0,
      "name": "Soil_Gravel_Lime",
      "support": 15
    },
    {
      "x": 0,
      "y": 30,
      "z": 1,
      "name": "Rock_Marble"
    },
    {
      "x": 0,
      "y": 31,
      "z": 1,
      "name": "Rock_Marble"
    },
    {
      "x": 0,
      "y": 32,
      "z": 1,
      "name": "Rock_Chalk"
    },
    {
      "x": 0,
      "y": 33,
      "z": 1,
      "name": "Rock_Marble"
    },
    {
      "x": 0,
      "y": 34,
      "z": 1,
      "name": "Rock_Chalk"
    },
    {
      "x": 0,
      "y": 35,
      "z": 1,
      "name": "Rock_Marble"
    },
    {
      "x": 0,
      "y": 36,
      "z": 1,
      "name": "Rock_Lime"
    },
    {
      "x": 0,
      "y": 37,
      "z": 1,
      "name": "Rock_Marble"
    },
    {
      "x": 0,
      "y": 38,
      "z": 1,
      "name": "Rock_Marble"
    },
    {
      "x": 0,
      "y": 39,
      "z": 1,
      "name": "Rock_Marble"
    },
    {
      "x": 0,
      "y": 40,
      "z": 1,
      "name": "Soil_Gravel_Lime",
      "support": 15
    },
    {
      "x": 0,
      "y": 41,
      "z": 1,
      "name": "Soil_Gravel_Lime",
      "support": 15
    },
    {
      "x": 0,
      "y": 33,
      "z": 2,
      "name": "Rock_Marble"
    },
    {
      "x": 0,
      "y": 34,
      "z": 2,
      "name": "Rock_Chalk"
    },
    {
      "x": 0,
      "y": 35,
      "z": 2,
      "name": "Rock_Marble"
    },
    {
      "x": 0,
      "y": 36,
      "z": 2,
      "name": "Rock_Marble"
    },
    {
      "x": 0,
      "y": 37,
      "z": 2,
      "name": "Rock_Lime"
    },
    {
      "x": 0,
      "y": 38,
      "z": 2,
      "name": "Rock_Marble"
    },
    {
      "x": 0,
      "y": 39,
      "z": 2,
      "name": "Rock_Marble"
    },
    {
      "x": 0,
      "y": 40,
      "z": 2,
      "name": "Rock_Marble"
    },
    {
      "x": 0,
      "y": 41,
      "z": 2,
      "name": "Rock_Marble_SkyGrass"
    },
    {
      "x": 0,
      "y": 35,
      "z": 3,
      "name": "Rock_Marble"
    },
    {
      "x": 0,
      "y": 36,
      "z": 3,
      "name": "Rock_Lime"
    },
    {
      "x": 0,
      "y": 37,
      "z": 3,
      "name": "Rock_Lime"
    },
    {
      "x": 0,
      "y": 38,
      "z": 3,
      "name": "Rock_Chalk"
    },
    {
      "x": 0,
      "y": 39,
      "z": 3,
      "name": "Rock_Marble"
    },
    {
      "x": 0,
      "y": 40,
      "z": 3,
      "name": "Rock_Marble"
    },
    {
      "x": 0,
      "y": 41,
      "z": 3,
      "name": "Rock_Marble_SkyGrass"
    },
    {
      "x": 0,
      "y": 42,
      "z": 3,
      "name": "Plant_Grass_Sky_Long",
      "support": 15
    },
    {
      "x": 0,
      "y": 43,
      "z": 3,
      "name": "Plant_Grass_Sky_Long",
      "filler": 1024
    },
    {
      "x": 0,
      "y": 35,
      "z": 4,
      "name": "Rock_Marble"
    },
    {
      "x": 0,
      "y": 36,
      "z": 4,
      "name": "Rock_Lime"
    },
    {
      "x": 0,
      "y": 37,
      "z": 4,
      "name": "Rock_Lime"
    },
    {
      "x": 0,
      "y": 38,
      "z": 4,
      "name": "Rock_Chalk"
    },
    {
      "x": 0,
      "y": 39,
      "z": 4,
      "name": "Rock_Marble"
    },
    {
      "x": 0,
      "y": 40,
      "z": 4,
      "name": "Rock_Marble"
    },
    {
      "x": 0,
      "y": 41,
      "z": 4,
      "name": "Rock_Marble_SkyGrass"
    },
    {
      "x": 0,
      "y": 42,
      "z": 4,
      "name": "Wood_Birch_Trunk",
      "support": 15,
      "rotation": 5
    },
    {
      "x": 0,
      "y": 37,
      "z": 5,
      "name": "Rock_Lime"
    },
    {
      "x": 0,
      "y": 38,
      "z": 5,
      "name": "Rock_Chalk"
    },
    {
      "x": 0,
      "y": 39,
      "z": 5,
      "name": "Rock_Marble"
    },
    {
      "x": 0,
      "y": 40,
      "z": 5,
      "name": "Rock_Marble"
    },
    {
      "x": 0,
      "y": 41,
      "z": 5,
      "name": "Rock_Marble_SkyGrass"
    },
    {
      "x": 0,
      "y": 42,
      "z": 5,
      "name": "Plant_Bush_Sky",
      "support": 15
    },
    {
      "x": 0,
      "y": 38,
      "z": 6,
      "name": "Rock_Chalk"
    },
    {
      "x": 0,
      "y": 39,
      "z": 6,
      "name": "Rock_Marble"
    },
    {
      "x": 0,
      "y": 40,
      "z": 6,
      "name": "Rock_Marble"
    },
    {
      "x": 0,
      "y": 41,
      "z": 6,
      "name": "Rock_Marble_SkyGrass"
    },
    {
      "x": 0,
      "y": 39,
      "z": 7,
      "name": "Rock_Marble"
    },
    {
      "x": 0,
      "y": 40,
      "z": 7,
      "name": "Rock_Marble"
    },
    {
      "x": 0,
      "y": 41,
      "z": 7,
      "name": "Rock_Marble_SkyGrass"
    },
    {
      "x": 1,
      "y": 39,
      "z": -7,
      "name": "Rock_Chalk"
    },
    {
      "x": 1,
      "y": 40,
      "z": -7,
      "name": "Rock_Marble"
    },
    {
      "x": 1,
      "y": 41,
      "z": -7,
      "name": "Rock_Marble_SkyGrass"
    },
    {
      "x": 1,
      "y": 39,
      "z": -6,
      "name": "Rock_Chalk"
    },
    {
      "x": 1,
      "y": 40,
      "z": -6,
      "name": "Rock_Marble"
    },
    {
      "x": 1,
      "y": 41,
      "z": -6,
      "name": "Rock_Marble_SkyGrass"
    },
    {
      "x": 1,
      "y": 37,
      "z": -5,
      "name": "Rock_Lime"
    },
    {
      "x": 1,
      "y": 38,
      "z": -5,
      "name": "Rock_Marble"
    },
    {
      "x": 1,
      "y": 39,
      "z": -5,
      "name": "Rock_Chalk"
    },
    {
      "x": 1,
      "y": 40,
      "z": -5,
      "name": "Rock_Marble"
    },
    {
      "x": 1,
      "y": 41,
      "z": -5,
      "name": "Rock_Marble_SkyGrass"
    },
    {
      "x": 1,
      "y": 32,
      "z": -4,
      "name": "Rock_Chalk"
    },
    {
      "x": 1,
      "y": 33,
      "z": -4,
      "name": "Rock_Marble"
    },
    {
      "x": 1,
      "y": 34,
      "z": -4,
      "name": "Rock_Marble"
    },
    {
      "x": 1,
      "y": 35,
      "z": -4,
      "name": "Rock_Chalk"
    },
    {
      "x": 1,
      "y": 36,
      "z": -4,
      "name": "Rock_Lime"
    },
    {
      "x": 1,
      "y": 37,
      "z": -4,
      "name": "Rock_Lime"
    },
    {
      "x": 1,
      "y": 38,
      "z": -4,
      "name": "Rock_Marble"
    },
    {
      "x": 1,
      "y": 39,
      "z": -4,
      "name": "Rock_Chalk"
    },
    {
      "x": 1,
      "y": 40,
      "z": -4,
      "name": "Rock_Marble"
    },
    {
      "x": 1,
      "y": 41,
      "z": -4,
      "name": "Rock_Marble_SkyGrass"
    },
    {
      "x": 1,
      "y": 32,
      "z": -3,
      "name": "Rock_Chalk"
    },
    {
      "x": 1,
      "y": 33,
      "z": -3,
      "name": "Rock_Marble"
    },
    {
      "x": 1,
      "y": 34,
      "z": -3,
      "name": "Rock_Marble"
    },
    {
      "x": 1,
      "y": 35,
      "z": -3,
      "name": "Rock_Chalk"
    },
    {
      "x": 1,
      "y": 36,
      "z": -3,
      "name": "Rock_Lime"
    },
    {
      "x": 1,
      "y": 37,
      "z": -3,
      "name": "Rock_Lime"
    },
    {
      "x": 1,
      "y": 38,
      "z": -3,
      "name": "Rock_Chalk"
    },
    {
      "x": 1,
      "y": 39,
      "z": -3,
      "name": "Rock_Chalk"
    },
    {
      "x": 1,
      "y": 40,
      "z": -3,
      "name": "Rock_Marble"
    },
    {
      "x": 1,
      "y": 41,
      "z": -3,
      "name": "Rock_Marble_SkyGrass"
    },
    {
      "x": 1,
      "y": 32,
      "z": -2,
      "name": "Rock_Chalk"
    },
    {
      "x": 1,
      "y": 33,
      "z": -2,
      "name": "Rock_Marble"
    },
    {
      "x": 1,
      "y": 34,
      "z": -2,
      "name": "Rock_Chalk"
    },
    {
      "x": 1,
      "y": 35,
      "z": -2,
      "name": "Rock_Chalk"
    },
    {
      "x": 1,
      "y": 36,
      "z": -2,
      "name": "Rock_Lime"
    },
    {
      "x": 1,
      "y": 37,
      "z": -2,
      "name": "Rock_Lime"
    },
    {
      "x": 1,
      "y": 38,
      "z": -2,
      "name": "Rock_Chalk"
    },
    {
      "x": 1,
      "y": 39,
      "z": -2,
      "name": "Rock_Marble"
    },
    {
      "x": 1,
      "y": 40,
      "z": -2,
      "name": "Rock_Marble"
    },
    {
      "x": 1,
      "y": 41,
      "z": -2,
      "name": "Soil_Gravel_Lime",
      "support": 15
    },
    {
      "x": 1,
      "y": 30,
      "z": -1,
      "name": "Rock_Marble"
    },
    {
      "x": 1,
      "y": 31,
      "z": -1,
      "name": "Rock_Marble"
    },
    {
      "x": 1,
      "y": 32,
      "z": -1,
      "name": "Rock_Chalk"
    },
    {
      "x": 1,
      "y": 33,
      "z": -1,
      "name": "Rock_Marble"
    },
    {
      "x": 1,
      "y": 34,
      "z": -1,
      "name": "Rock_Chalk"
    },
    {
      "x": 1,
      "y": 35,
      "z": -1,
      "name": "Rock_Chalk"
    },
    {
      "x": 1,
      "y": 36,
      "z": -1,
      "name": "Rock_Lime"
    },
    {
      "x": 1,
      "y": 37,
      "z": -1,
      "name": "Rock_Lime"
    },
    {
      "x": 1,
      "y": 38,
      "z": -1,
      "name": "Rock_Chalk"
    },
    {
      "x": 1,
      "y": 39,
      "z": -1,
      "name": "Rock_Marble"
    },
    {
      "x": 1,
      "y": 40,
      "z": -1,
      "name": "Rock_Marble"
    },
    {
      "x": 1,
      "y": 41,
      "z": -1,
      "name": "Soil_Gravel_Lime",
      "support": 15
    },
    {
      "x": 1,
      "y": 42,
      "z": -1,
      "name": "Rubble_Marble",
      "support": 15
    },
    {
      "x": 1,
      "y": 30,
      "z": 0,
      "name": "Rock_Marble"
    },
    {
      "x": 1,
      "y": 31,
      "z": 0,
      "name": "Rock_Marble"
    },
    {
      "x": 1,
      "y": 32,
      "z": 0,
      "name": "Rock_Chalk"
    },
    {
      "x": 1,
      "y": 33,
      "z": 0,
      "name": "Rock_Marble"
    },
    {
      "x": 1,
      "y": 34,
      "z": 0,
      "name": "Rock_Chalk"
    },
    {
      "x": 1,
      "y": 35,
      "z": 0,
      "name": "Rock_Chalk"
    },
    {
      "x": 1,
      "y": 36,
      "z": 0,
      "name": "Rock_Lime"
    },
    {
      "x": 1,
      "y": 37,
      "z": 0,
      "name": "Rock_Marble"
    },
    {
      "x": 1,
      "y": 38,
      "z": 0,
      "name": "Rock_Marble"
    },
    {
      "x": 1,
      "y": 39,
      "z": 0,
      "name": "Rock_Marble"
    },
    {
      "x": 1,
      "y": 40,
      "z": 0,
      "name": "Rock_Marble"
    },
    {
      "x": 1,
      "y": 41,
      "z": 0,
      "name": "Rock_Lime"
    },
    {
      "x": 1,
      "y": 30,
      "z": 1,
      "name": "Rock_Marble"
    },
    {
      "x": 1,
      "y": 31,
      "z": 1,
      "name": "Rock_Marble"
    },
    {
      "x": 1,
      "y": 32,
      "z": 1,
      "name": "Rock_Chalk"
    },
    {
      "x": 1,
      "y": 33,
      "z": 1,
      "name": "Rock_Marble"
    },
    {
      "x": 1,
      "y": 34,
      "z": 1,
      "name": "Rock_Chalk"
    },
    {
      "x": 1,
      "y": 35,
      "z": 1,
      "name": "Rock_Marble"
    },
    {
      "x": 1,
      "y": 36,
      "z": 1,
      "name": "Rock_Lime"
    },
    {
      "x": 1,
      "y": 37,
      "z": 1,
      "name": "Rock_Marble"
    },
    {
      "x": 1,
      "y": 38,
      "z": 1,
      "name": "Rock_Marble"
    },
    {
      "x": 1,
      "y": 39,
      "z": 1,
      "name": "Rock_Marble"
    },
    {
      "x": 1,
      "y": 40,
      "z": 1,
      "name": "Rock_Marble"
    },
    {
      "x": 1,
      "y": 41,
      "z": 1,
      "name": "Soil_Gravel_Lime",
      "support": 15
    },
    {
      "x": 1,
      "y": 33,
      "z": 2,
      "name": "Rock_Marble"
    },
    {
      "x": 1,
      "y": 34,
      "z": 2,
      "name": "Rock_Chalk"
    },
    {
      "x": 1,
      "y": 35,
      "z": 2,
      "name": "Rock_Marble"
    },
    {
      "x": 1,
      "y": 36,
      "z": 2,
      "name": "Rock_Lime"
    },
    {
      "x": 1,
      "y": 37,
      "z": 2,
      "name": "Rock_Marble"
    },
    {
      "x": 1,
      "y": 38,
      "z": 2,
      "name": "Rock_Marble"
    },
    {
      "x": 1,
      "y": 39,
      "z": 2,
      "name": "Rock_Marble"
    },
    {
      "x": 1,
      "y": 40,
      "z": 2,
      "name": "Rock_Marble"
    },
    {
      "x": 1,
      "y": 41,
      "z": 2,
      "name": "Soil_Gravel_Lime",
      "support": 15
    },
    {
      "x": 1,
      "y": 42,
      "z": 2,
      "name": "Rubble_Marble",
      "support": 15
    },
    {
      "x": 1,
      "y": 33,
      "z": 3,
      "name": "Rock_Marble"
    },
    {
      "x": 1,
      "y": 34,
      "z": 3,
      "name": "Rock_Chalk"
    },
    {
      "x": 1,
      "y": 35,
      "z": 3,
      "name": "Rock_Marble"
    },
    {
      "x": 1,
      "y": 36,
      "z": 3,
      "name": "Rock_Lime"
    },
    {
      "x": 1,
      "y": 37,
      "z": 3,
      "name": "Rock_Marble"
    },
    {
      "x": 1,
      "y": 38,
      "z": 3,
      "name": "Rock_Marble"
    },
    {
      "x": 1,
      "y": 39,
      "z": 3,
      "name": "Rock_Marble"
    },
    {
      "x": 1,
      "y": 40,
      "z": 3,
      "name": "Rock_Marble"
    },
    {
      "x": 1,
      "y": 41,
      "z": 3,
      "name": "Rock_Marble_SkyGrass"
    },
    {
      "x": 1,
      "y": 35,
      "z": 4,
      "name": "Rock_Marble"
    },
    {
      "x": 1,
      "y": 36,
      "z": 4,
      "name": "Rock_Lime"
    },
    {
      "x": 1,
      "y": 37,
      "z": 4,
      "name": "Rock_Lime"
    },
    {
      "x": 1,
      "y": 38,
      "z": 4,
      "name": "Rock_Marble"
    },
    {
      "x": 1,
      "y": 39,
      "z": 4,
      "name": "Rock_Marble"
    },
    {
      "x": 1,
      "y": 40,
      "z": 4,
      "name": "Rock_Marble"
    },
    {
      "x": 1,
      "y": 41,
      "z": 4,
      "name": "Rock_Marble_SkyGrass"
    },
    {
      "x": 1,
      "y": 42,
      "z": 4,
      "name": "Wood_Birch_Trunk",
      "support": 15,
      "rotation": 5
    },
    {
      "x": 1,
      "y": 35,
      "z": 5,
      "name": "Rock_Marble"
    },
    {
      "x": 1,
      "y": 36,
      "z": 5,
      "name": "Rock_Lime"
    },
    {
      "x": 1,
      "y": 37,
      "z": 5,
      "name": "Rock_Lime"
    },
    {
      "x": 1,
      "y": 38,
      "z": 5,
      "name": "Rock_Chalk"
    },
    {
      "x": 1,
      "y": 39,
      "z": 5,
      "name": "Rock_Marble"
    },
    {
      "x": 1,
      "y": 40,
      "z": 5,
      "name": "Rock_Marble"
    },
    {
      "x": 1,
      "y": 41,
      "z": 5,
      "name": "Rock_Marble_SkyGrass"
    },
    {
      "x": 1,
      "y": 42,
      "z": 5,
      "name": "Plant_Bush_Sky",
      "support": 15
    },
    {
      "x": 1,
      "y": 38,
      "z": 6,
      "name": "Rock_Chalk"
    },
    {
      "x": 1,
      "y": 39,
      "z": 6,
      "name": "Rock_Marble"
    },
    {
      "x": 1,
      "y": 40,
      "z": 6,
      "name": "Rock_Marble"
    },
    {
      "x": 1,
      "y": 41,
      "z": 6,
      "name": "Rock_Marble_SkyGrass"
    },
    {
      "x": 1,
      "y": 42,
      "z": 6,
      "name": "Plant_Bush_Sky",
      "support": 15
    },
    {
      "x": 1,
      "y": 39,
      "z": 7,
      "name": "Rock_Chalk"
    },
    {
      "x": 1,
      "y": 40,
      "z": 7,
      "name": "Rock_Marble"
    },
    {
      "x": 1,
      "y": 41,
      "z": 7,
      "name": "Rock_Marble_SkyGrass"
    },
    {
      "x": 2,
      "y": 39,
      "z": -7,
      "name": "Rock_Chalk"
    },
    {
      "x": 2,
      "y": 40,
      "z": -7,
      "name": "Rock_Marble"
    },
    {
      "x": 2,
      "y": 41,
      "z": -7,
      "name": "Rock_Marble_SkyGrass"
    },
    {
      "x": 2,
      "y": 38,
      "z": -6,
      "name": "Rock_Marble"
    },
    {
      "x": 2,
      "y": 39,
      "z": -6,
      "name": "Rock_Chalk"
    },
    {
      "x": 2,
      "y": 40,
      "z": -6,
      "name": "Rock_Marble"
    },
    {
      "x": 2,
      "y": 41,
      "z": -6,
      "name": "Rock_Marble_SkyGrass"
    },
    {
      "x": 2,
      "y": 37,
      "z": -5,
      "name": "Rock_Lime"
    },
    {
      "x": 2,
      "y": 38,
      "z": -5,
      "name": "Rock_Chalk"
    },
    {
      "x": 2,
      "y": 39,
      "z": -5,
      "name": "Rock_Chalk"
    },
    {
      "x": 2,
      "y": 40,
      "z": -5,
      "name": "Rock_Marble"
    },
    {
      "x": 2,
      "y": 41,
      "z": -5,
      "name": "Rock_Marble_SkyGrass"
    },
    {
      "x": 2,
      "y": 32,
      "z": -4,
      "name": "Rock_Chalk"
    },
    {
      "x": 2,
      "y": 33,
      "z": -4,
      "name": "Rock_Marble"
    },
    {
      "x": 2,
      "y": 34,
      "z": -4,
      "name": "Rock_Marble"
    },
    {
      "x": 2,
      "y": 35,
      "z": -4,
      "name": "Rock_Chalk"
    },
    {
      "x": 2,
      "y": 36,
      "z": -4,
      "name": "Rock_Marble"
    },
    {
      "x": 2,
      "y": 37,
      "z": -4,
      "name": "Rock_Lime"
    },
    {
      "x": 2,
      "y": 38,
      "z": -4,
      "name": "Rock_Chalk"
    },
    {
      "x": 2,
      "y": 39,
      "z": -4,
      "name": "Rock_Chalk"
    },
    {
      "x": 2,
      "y": 40,
      "z": -4,
      "name": "Rock_Marble"
    },
    {
      "x": 2,
      "y": 41,
      "z": -4,
      "name": "Rock_Marble_SkyGrass"
    },
    {
      "x": 2,
      "y": 32,
      "z": -3,
      "name": "Rock_Chalk"
    },
    {
      "x": 2,
      "y": 33,
      "z": -3,
      "name": "Rock_Marble"
    },
    {
      "x": 2,
      "y": 34,
      "z": -3,
      "name": "Rock_Chalk"
    },
    {
      "x": 2,
      "y": 35,
      "z": -3,
      "name": "Rock_Chalk"
    },
    {
      "x": 2,
      "y": 36,
      "z": -3,
      "name": "Rock_Lime"
    },
    {
      "x": 2,
      "y": 37,
      "z": -3,
      "name": "Rock_Lime"
    },
    {
      "x": 2,
      "y": 38,
      "z": -3,
      "name": "Rock_Chalk"
    },
    {
      "x": 2,
      "y": 39,
      "z": -3,
      "name": "Rock_Chalk"
    },
    {
      "x": 2,
      "y": 40,
      "z": -3,
      "name": "Rock_Marble"
    },
    {
      "x": 2,
      "y": 41,
      "z": -3,
      "name": "Rock_Marble_SkyGrass"
    },
    {
      "x": 2,
      "y": 32,
      "z": -2,
      "name": "Rock_Chalk"
    },
    {
      "x": 2,
      "y": 33,
      "z": -2,
      "name": "Rock_Marble"
    },
    {
      "x": 2,
      "y": 34,
      "z": -2,
      "name": "Rock_Chalk"
    },
    {
      "x": 2,
      "y": 35,
      "z": -2,
      "name": "Rock_Chalk"
    },
    {
      "x": 2,
      "y": 36,
      "z": -2,
      "name": "Rock_Lime"
    },
    {
      "x": 2,
      "y": 37,
      "z": -2,
      "name": "Rock_Lime"
    },
    {
      "x": 2,
      "y": 38,
      "z": -2,
      "name": "Rock_Chalk"
    },
    {
      "x": 2,
      "y": 39,
      "z": -2,
      "name": "Rock_Marble"
    },
    {
      "x": 2,
      "y": 40,
      "z": -2,
      "name": "Rock_Marble"
    },
    {
      "x": 2,
      "y": 41,
      "z": -2,
      "name": "Soil_Gravel_Lime",
      "support": 15
    },
    {
      "x": 2,
      "y": 32,
      "z": -1,
      "name": "Rock_Chalk"
    },
    {
      "x": 2,
      "y": 33,
      "z": -1,
      "name": "Rock_Marble"
    },
    {
      "x": 2,
      "y": 34,
      "z": -1,
      "name": "Rock_Chalk"
    },
    {
      "x": 2,
      "y": 35,
      "z": -1,
      "name": "Rock_Chalk"
    },
    {
      "x": 2,
      "y": 36,
      "z": -1,
      "name": "Rock_Lime"
    },
    {
      "x": 2,
      "y": 37,
      "z": -1,
      "name": "Rock_Lime"
    },
    {
      "x": 2,
      "y": 38,
      "z": -1,
      "name": "Rock_Chalk"
    },
    {
      "x": 2,
      "y": 39,
      "z": -1,
      "name": "Rock_Marble"
    },
    {
      "x": 2,
      "y": 40,
      "z": -1,
      "name": "Rock_Marble"
    },
    {
      "x": 2,
      "y": 41,
      "z": -1,
      "name": "Soil_Gravel_Lime",
      "support": 15
    },
    {
      "x": 2,
      "y": 32,
      "z": 0,
      "name": "Rock_Chalk"
    },
    {
      "x": 2,
      "y": 33,
      "z": 0,
      "name": "Rock_Marble"
    },
    {
      "x": 2,
      "y": 34,
      "z": 0,
      "name": "Rock_Chalk"
    },
    {
      "x": 2,
      "y": 35,
      "z": 0,
      "name": "Rock_Chalk"
    },
    {
      "x": 2,
      "y": 36,
      "z": 0,
      "name": "Rock_Lime"
    },
    {
      "x": 2,
      "y": 37,
      "z": 0,
      "name": "Rock_Lime"
    },
    {
      "x": 2,
      "y": 38,
      "z": 0,
      "name": "Rock_Chalk"
    },
    {
      "x": 2,
      "y": 39,
      "z": 0,
      "name": "Rock_Marble"
    },
    {
      "x": 2,
      "y": 40,
      "z": 0,
      "name": "Rock_Marble"
    },
    {
      "x": 2,
      "y": 41,
      "z": 0,
      "name": "Rock_Marble_SkyGrass"
    },
    {
      "x": 2,
      "y": 42,
      "z": 0,
      "name": "Plant_Grass_Sky_Short",
      "support": 15
    },
    {
      "x": 2,
      "y": 33,
      "z": 1,
      "name": "Rock_Marble"
    },
    {
      "x": 2,
      "y": 34,
      "z": 1,
      "name": "Rock_Chalk"
    },
    {
      "x": 2,
      "y": 35,
      "z": 1,
      "name": "Rock_Marble"
    },
    {
      "x": 2,
      "y": 36,
      "z": 1,
      "name": "Rock_Lime"
    },
    {
      "x": 2,
      "y": 37,
      "z": 1,
      "name": "Rock_Lime"
    },
    {
      "x": 2,
      "y": 38,
      "z": 1,
      "name": "Rock_Chalk"
    },
    {
      "x": 2,
      "y": 39,
      "z": 1,
      "name": "Rock_Marble"
    },
    {
      "x": 2,
      "y": 40,
      "z": 1,
      "name": "Rock_Marble"
    },
    {
      "x": 2,
      "y": 41,
      "z": 1,
      "name": "Soil_Gravel_Lime",
      "support": 15
    },
    {
      "x": 2,
      "y": 33,
      "z": 2,
      "name": "Rock_Marble"
    },
    {
      "x": 2,
      "y": 34,
      "z": 2,
      "name": "Rock_Chalk"
    },
    {
      "x": 2,
      "y": 35,
      "z": 2,
      "name": "Rock_Marble"
    },
    {
      "x": 2,
      "y": 36,
      "z": 2,
      "name": "Rock_Lime"
    },
    {
      "x": 2,
      "y": 37,
      "z": 2,
      "name": "Rock_Marble"
    },
    {
      "x": 2,
      "y": 38,
      "z": 2,
      "name": "Rock_Marble"
    },
    {
      "x": 2,
      "y": 39,
      "z": 2,
      "name": "Rock_Marble"
    },
    {
      "x": 2,
      "y": 40,
      "z": 2,
      "name": "Rock_Marble"
    },
    {
      "x": 2,
      "y": 41,
      "z": 2,
      "name": "Soil_Gravel_Lime",
      "support": 15
    },
    {
      "x": 2,
      "y": 33,
      "z": 3,
      "name": "Rock_Marble"
    },
    {
      "x": 2,
      "y": 34,
      "z": 3,
      "name": "Rock_Chalk"
    },
    {
      "x": 2,
      "y": 35,
      "z": 3,
      "name": "Rock_Marble"
    },
    {
      "x": 2,
      "y": 36,
      "z": 3,
      "name": "Rock_Lime"
    },
    {
      "x": 2,
      "y": 37,
      "z": 3,
      "name": "Rock_Chalk"
    },
    {
      "x": 2,
      "y": 38,
      "z": 3,
      "name": "Rock_Marble"
    },
    {
      "x": 2,
      "y": 39,
      "z": 3,
      "name": "Rock_Marble"
    },
    {
      "x": 2,
      "y": 40,
      "z": 3,
      "name": "Rock_Marble"
    },
    {
      "x": 2,
      "y": 41,
      "z": 3,
      "name": "Rock_Marble_SkyGrass"
    },
    {
      "x": 2,
      "y": 35,
      "z": 4,
      "name": "Rock_Marble"
    },
    {
      "x": 2,
      "y": 36,
      "z": 4,
      "name": "Rock_Lime"
    },
    {
      "x": 2,
      "y": 37,
      "z": 4,
      "name": "Rock_Chalk"
    },
    {
      "x": 2,
      "y": 38,
      "z": 4,
      "name": "Rock_Marble"
    },
    {
      "x": 2,
      "y": 39,
      "z": 4,
      "name": "Rock_Marble"
    },
    {
      "x": 2,
      "y": 40,
      "z": 4,
      "name": "Rock_Marble"
    },
    {
      "x": 2,
      "y": 41,
      "z": 4,
      "name": "Rock_Marble_SkyGrass"
    },
    {
      "x": 2,
      "y": 42,
      "z": 4,
      "name": "Plant_Grass_Sky_Short",
      "support": 15
    },
    {
      "x": 2,
      "y": 35,
      "z": 5,
      "name": "Rock_Marble"
    },
    {
      "x": 2,
      "y": 36,
      "z": 5,
      "name": "Rock_Lime"
    },
    {
      "x": 2,
      "y": 37,
      "z": 5,
      "name": "Rock_Chalk"
    },
    {
      "x": 2,
      "y": 38,
      "z": 5,
      "name": "Rock_Marble"
    },
    {
      "x": 2,
      "y": 39,
      "z": 5,
      "name": "Rock_Marble"
    },
    {
      "x": 2,
      "y": 40,
      "z": 5,
      "name": "Rock_Marble"
    },
    {
      "x": 2,
      "y": 41,
      "z": 5,
      "name": "Rock_Marble_SkyGrass"
    },
    {
      "x": 2,
      "y": 42,
      "z": 5,
      "name": "Plant_Bush_Sky",
      "support": 15
    },
    {
      "x": 2,
      "y": 35,
      "z": 6,
      "name": "Rock_Marble"
    },
    {
      "x": 2,
      "y": 36,
      "z": 6,
      "name": "Rock_Lime"
    },
    {
      "x": 2,
      "y": 37,
      "z": 6,
      "name": "Rock_Marble"
    },
    {
      "x": 2,
      "y": 38,
      "z": 6,
      "name": "Rock_Marble"
    },
    {
      "x": 2,
      "y": 39,
      "z": 6,
      "name": "Rock_Marble"
    },
    {
      "x": 2,
      "y": 40,
      "z": 6,
      "name": "Rock_Marble"
    },
    {
      "x": 2,
      "y": 41,
      "z": 6,
      "name": "Rock_Marble_SkyGrass"
    },
    {
      "x": 2,
      "y": 39,
      "z": 7,
      "name": "Rock_Chalk"
    },
    {
      "x": 2,
      "y": 40,
      "z": 7,
      "name": "Rock_Marble"
    },
    {
      "x": 2,
      "y": 41,
      "z": 7,
      "name": "Rock_Marble_SkyGrass"
    },
    {
      "x": 3,
      "y": 36,
      "z": -6,
      "name": "Rock_Marble"
    },
    {
      "x": 3,
      "y": 37,
      "z": -6,
      "name": "Rock_Lime"
    },
    {
      "x": 3,
      "y": 38,
      "z": -6,
      "name": "Rock_Marble"
    },
    {
      "x": 3,
      "y": 39,
      "z": -6,
      "name": "Rock_Chalk"
    },
    {
      "x": 3,
      "y": 40,
      "z": -6,
      "name": "Rock_Marble"
    },
    {
      "x": 3,
      "y": 41,
      "z": -6,
      "name": "Rock_Marble_SkyGrass"
    },
    {
      "x": 3,
      "y": 36,
      "z": -5,
      "name": "Rock_Marble"
    },
    {
      "x": 3,
      "y": 37,
      "z": -5,
      "name": "Rock_Lime"
    },
    {
      "x": 3,
      "y": 38,
      "z": -5,
      "name": "Rock_Chalk"
    },
    {
      "x": 3,
      "y": 39,
      "z": -5,
      "name": "Rock_Chalk"
    },
    {
      "x": 3,
      "y": 40,
      "z": -5,
      "name": "Rock_Marble"
    },
    {
      "x": 3,
      "y": 41,
      "z": -5,
      "name": "Rock_Marble_SkyGrass"
    },
    {
      "x": 3,
      "y": 42,
      "z": -5,
      "name": "Rubble_Marble",
      "support": 15
    },
    {
      "x": 3,
      "y": 32,
      "z": -4,
      "name": "Rock_Chalk"
    },
    {
      "x": 3,
      "y": 33,
      "z": -4,
      "name": "Rock_Marble"
    },
    {
      "x": 3,
      "y": 34,
      "z": -4,
      "name": "Rock_Marble"
    },
    {
      "x": 3,
      "y": 35,
      "z": -4,
      "name": "Rock_Chalk"
    },
    {
      "x": 3,
      "y": 36,
      "z": -4,
      "name": "Rock_Lime"
    },
    {
      "x": 3,
      "y": 37,
      "z": -4,
      "name": "Rock_Lime"
    },
    {
      "x": 3,
      "y": 38,
      "z": -4,
      "name": "Rock_Chalk"
    },
    {
      "x": 3,
      "y": 39,
      "z": -4,
      "name": "Rock_Chalk"
    },
    {
      "x": 3,
      "y": 40,
      "z": -4,
      "name": "Rock_Marble"
    },
    {
      "x": 3,
      "y": 41,
      "z": -4,
      "name": "Rock_Marble_SkyGrass"
    },
    {
      "x": 3,
      "y": 32,
      "z": -3,
      "name": "Rock_Chalk"
    },
    {
      "x": 3,
      "y": 33,
      "z": -3,
      "name": "Rock_Marble"
    },
    {
      "x": 3,
      "y": 34,
      "z": -3,
      "name": "Rock_Chalk"
    },
    {
      "x": 3,
      "y": 35,
      "z": -3,
      "name": "Rock_Chalk"
    },
    {
      "x": 3,
      "y": 36,
      "z": -3,
      "name": "Rock_Lime"
    },
    {
      "x": 3,
      "y": 37,
      "z": -3,
      "name": "Rock_Lime"
    },
    {
      "x": 3,
      "y": 38,
      "z": -3,
      "name": "Rock_Chalk"
    },
    {
      "x": 3,
      "y": 39,
      "z": -3,
      "name": "Rock_Marble"
    },
    {
      "x": 3,
      "y": 40,
      "z": -3,
      "name": "Rock_Marble"
    },
    {
      "x": 3,
      "y": 41,
      "z": -3,
      "name": "Rock_Marble_SkyGrass"
    },
    {
      "x": 3,
      "y": 42,
      "z": -3,
      "name": "Plant_Grass_Sky",
      "support": 15
    },
    {
      "x": 3,
      "y": 32,
      "z": -2,
      "name": "Rock_Chalk"
    },
    {
      "x": 3,
      "y": 33,
      "z": -2,
      "name": "Rock_Marble"
    },
    {
      "x": 3,
      "y": 34,
      "z": -2,
      "name": "Rock_Chalk"
    },
    {
      "x": 3,
      "y": 35,
      "z": -2,
      "name": "Rock_Chalk"
    },
    {
      "x": 3,
      "y": 36,
      "z": -2,
      "name": "Rock_Lime"
    },
    {
      "x": 3,
      "y": 37,
      "z": -2,
      "name": "Rock_Lime"
    },
    {
      "x": 3,
      "y": 38,
      "z": -2,
      "name": "Rock_Chalk"
    },
    {
      "x": 3,
      "y": 39,
      "z": -2,
      "name": "Rock_Marble"
    },
    {
      "x": 3,
      "y": 40,
      "z": -2,
      "name": "Rock_Marble"
    },
    {
      "x": 3,
      "y": 41,
      "z": -2,
      "name": "Rock_Marble_SkyGrass"
    },
    {
      "x": 3,
      "y": 32,
      "z": -1,
      "name": "Rock_Chalk"
    },
    {
      "x": 3,
      "y": 33,
      "z": -1,
      "name": "Rock_Marble"
    },
    {
      "x": 3,
      "y": 34,
      "z": -1,
      "name": "Rock_Chalk"
    },
    {
      "x": 3,
      "y": 35,
      "z": -1,
      "name": "Rock_Chalk"
    },
    {
      "x": 3,
      "y": 36,
      "z": -1,
      "name": "Rock_Lime"
    },
    {
      "x": 3,
      "y": 37,
      "z": -1,
      "name": "Rock_Lime"
    },
    {
      "x": 3,
      "y": 38,
      "z": -1,
      "name": "Rock_Chalk"
    },
    {
      "x": 3,
      "y": 39,
      "z": -1,
      "name": "Rock_Marble"
    },
    {
      "x": 3,
      "y": 40,
      "z": -1,
      "name": "Rock_Marble"
    },
    {
      "x": 3,
      "y": 41,
      "z": -1,
      "name": "Rock_Marble_SkyGrass"
    },
    {
      "x": 3,
      "y": 42,
      "z": -1,
      "name": "Plant_Grass_Sky_Short",
      "support": 15
    },
    {
      "x": 3,
      "y": 32,
      "z": 0,
      "name": "Rock_Chalk"
    },
    {
      "x": 3,
      "y": 33,
      "z": 0,
      "name": "Rock_Marble"
    },
    {
      "x": 3,
      "y": 34,
      "z": 0,
      "name": "Rock_Chalk"
    },
    {
      "x": 3,
      "y": 35,
      "z": 0,
      "name": "Rock_Marble"
    },
    {
      "x": 3,
      "y": 36,
      "z": 0,
      "name": "Rock_Lime"
    },
    {
      "x": 3,
      "y": 37,
      "z": 0,
      "name": "Rock_Lime"
    },
    {
      "x": 3,
      "y": 38,
      "z": 0,
      "name": "Rock_Chalk"
    },
    {
      "x": 3,
      "y": 39,
      "z": 0,
      "name": "Rock_Marble"
    },
    {
      "x": 3,
      "y": 40,
      "z": 0,
      "name": "Rock_Marble"
    },
    {
      "x": 3,
      "y": 41,
      "z": 0,
      "name": "Rock_Marble_SkyGrass"
    },
    {
      "x": 3,
      "y": 33,
      "z": 1,
      "name": "Rock_Marble"
    },
    {
      "x": 3,
      "y": 34,
      "z": 1,
      "name": "Rock_Chalk"
    },
    {
      "x": 3,
      "y": 35,
      "z": 1,
      "name": "Rock_Marble"
    },
    {
      "x": 3,
      "y": 36,
      "z": 1,
      "name": "Rock_Lime"
    },
    {
      "x": 3,
      "y": 37,
      "z": 1,
      "name": "Rock_Lime"
    },
    {
      "x": 3,
      "y": 38,
      "z": 1,
      "name": "Rock_Chalk"
    },
    {
      "x": 3,
      "y": 39,
      "z": 1,
      "name": "Rock_Lime"
    },
    {
      "x": 3,
      "y": 40,
      "z": 1,
      "name": "Rock_Marble"
    },
    {
      "x": 3,
      "y": 41,
      "z": 1,
      "name": "Rock_Marble_SkyGrass"
    },
    {
      "x": 3,
      "y": 33,
      "z": 2,
      "name": "Rock_Marble"
    },
    {
      "x": 3,
      "y": 34,
      "z": 2,
      "name": "Rock_Chalk"
    },
    {
      "x": 3,
      "y": 35,
      "z": 2,
      "name": "Rock_Marble"
    },
    {
      "x": 3,
      "y": 36,
      "z": 2,
      "name": "Rock_Lime"
    },
    {
      "x": 3,
      "y": 37,
      "z": 2,
      "name": "Rock_Chalk"
    },
    {
      "x": 3,
      "y": 38,
      "z": 2,
      "name": "Rock_Marble"
    },
    {
      "x": 3,
      "y": 39,
      "z": 2,
      "name": "Rock_Lime"
    },
    {
      "x": 3,
      "y": 40,
      "z": 2,
      "name": "Rock_Marble"
    },
    {
      "x": 3,
      "y": 41,
      "z": 2,
      "name": "Rock_Marble_SkyGrass"
    },
    {
      "x": 3,
      "y": 42,
      "z": 2,
      "name": "Furniture_Ancient_Torch",
      "rotation": 1
    },
    {
      "x": 3,
      "y": 35,
      "z": 3,
      "name": "Rock_Marble"
    },
    {
      "x": 3,
      "y": 36,
      "z": 3,
      "name": "Rock_Lime"
    },
    {
      "x": 3,
      "y": 37,
      "z": 3,
      "name": "Rock_Chalk"
    },
    {
      "x": 3,
      "y": 38,
      "z": 3,
      "name": "Rock_Marble"
    },
    {
      "x": 3,
      "y": 39,
      "z": 3,
      "name": "Rock_Lime"
    },
    {
      "x": 3,
      "y": 40,
      "z": 3,
      "name": "Rock_Marble"
    },
    {
      "x": 3,
      "y": 41,
      "z": 3,
      "name": "Rock_Marble_SkyGrass"
    },
    {
      "x": 3,
      "y": 35,
      "z": 4,
      "name": "Rock_Marble"
    },
    {
      "x": 3,
      "y": 36,
      "z": 4,
      "name": "Rock_Lime"
    },
    {
      "x": 3,
      "y": 37,
      "z": 4,
      "name": "Rock_Chalk"
    },
    {
      "x": 3,
      "y": 38,
      "z": 4,
      "name": "Rock_Marble"
    },
    {
      "x": 3,
      "y": 39,
      "z": 4,
      "name": "Rock_Marble"
    },
    {
      "x": 3,
      "y": 40,
      "z": 4,
      "name": "Rock_Marble"
    },
    {
      "x": 3,
      "y": 41,
      "z": 4,
      "name": "Rock_Marble_SkyGrass"
    },
    {
      "x": 3,
      "y": 42,
      "z": 4,
      "name": "Plant_Grass_Sky",
      "support": 15
    },
    {
      "x": 3,
      "y": 35,
      "z": 5,
      "name": "Rock_Marble"
    },
    {
      "x": 3,
      "y": 36,
      "z": 5,
      "name": "Rock_Lime"
    },
    {
      "x": 3,
      "y": 37,
      "z": 5,
      "name": "Rock_Chalk"
    },
    {
      "x": 3,
      "y": 38,
      "z": 5,
      "name": "Rock_Marble"
    },
    {
      "x": 3,
      "y": 39,
      "z": 5,
      "name": "Rock_Marble"
    },
    {
      "x": 3,
      "y": 40,
      "z": 5,
      "name": "Rock_Marble"
    },
    {
      "x": 3,
      "y": 41,
      "z": 5,
      "name": "Rock_Marble_SkyGrass"
    },
    {
      "x": 3,
      "y": 42,
      "z": 5,
      "name": "Plant_Grass_Sky_Short",
      "support": 15
    },
    {
      "x": 3,
      "y": 35,
      "z": 6,
      "name": "Rock_Marble"
    },
    {
      "x": 3,
      "y": 36,
      "z": 6,
      "name": "Rock_Lime"
    },
    {
      "x": 3,
      "y": 37,
      "z": 6,
      "name": "Rock_Chalk"
    },
    {
      "x": 3,
      "y": 38,
      "z": 6,
      "name": "Rock_Marble"
    },
    {
      "x": 3,
      "y": 39,
      "z": 6,
      "name": "Rock_Chalk"
    },
    {
      "x": 3,
      "y": 40,
      "z": 6,
      "name": "Rock_Marble"
    },
    {
      "x": 3,
      "y": 41,
      "z": 6,
      "name": "Rock_Marble_SkyGrass"
    },
    {
      "x": 4,
      "y": 36,
      "z": -6,
      "name": "Rock_Marble"
    },
    {
      "x": 4,
      "y": 37,
      "z": -6,
      "name": "Rock_Lime"
    },
    {
      "x": 4,
      "y": 38,
      "z": -6,
      "name": "Rock_Chalk"
    },
    {
      "x": 4,
      "y": 39,
      "z": -6,
      "name": "Rock_Chalk"
    },
    {
      "x": 4,
      "y": 40,
      "z": -6,
      "name": "Rock_Marble"
    },
    {
      "x": 4,
      "y": 41,
      "z": -6,
      "name": "Rock_Marble_SkyGrass"
    },
    {
      "x": 4,
      "y": 36,
      "z": -5,
      "name": "Rock_Marble"
    },
    {
      "x": 4,
      "y": 37,
      "z": -5,
      "name": "Rock_Lime"
    },
    {
      "x": 4,
      "y": 38,
      "z": -5,
      "name": "Rock_Chalk"
    },
    {
      "x": 4,
      "y": 39,
      "z": -5,
      "name": "Rock_Chalk"
    },
    {
      "x": 4,
      "y": 40,
      "z": -5,
      "name": "Rock_Marble"
    },
    {
      "x": 4,
      "y": 41,
      "z": -5,
      "name": "Rock_Marble_SkyGrass"
    },
    {
      "x": 4,
      "y": 39,
      "z": -4,
      "name": "Rock_Chalk"
    },
    {
      "x": 4,
      "y": 40,
      "z": -4,
      "name": "Rock_Marble"
    },
    {
      "x": 4,
      "y": 41,
      "z": -4,
      "name": "Rock_Marble_SkyGrass"
    },
    {
      "x": 4,
      "y": 32,
      "z": -3,
      "name": "Rock_Chalk"
    },
    {
      "x": 4,
      "y": 33,
      "z": -3,
      "name": "Rock_Marble"
    },
    {
      "x": 4,
      "y": 34,
      "z": -3,
      "name": "Rock_Chalk"
    },
    {
      "x": 4,
      "y": 35,
      "z": -3,
      "name": "Rock_Chalk"
    },
    {
      "x": 4,
      "y": 36,
      "z": -3,
      "name": "Rock_Lime"
    },
    {
      "x": 4,
      "y": 37,
      "z": -3,
      "name": "Rock_Lime"
    },
    {
      "x": 4,
      "y": 38,
      "z": -3,
      "name": "Rock_Chalk"
    },
    {
      "x": 4,
      "y": 39,
      "z": -3,
      "name": "Rock_Marble"
    },
    {
      "x": 4,
      "y": 40,
      "z": -3,
      "name": "Rock_Marble"
    },
    {
      "x": 4,
      "y": 41,
      "z": -3,
      "name": "Rock_Marble_SkyGrass"
    },
    {
      "x": 4,
      "y": 42,
      "z": -3,
      "name": "Wood_Birch_Trunk_Full",
      "support": 15
    },
    {
      "x": 4,
      "y": 32,
      "z": -2,
      "name": "Rock_Chalk"
    },
    {
      "x": 4,
      "y": 33,
      "z": -2,
      "name": "Rock_Marble"
    },
    {
      "x": 4,
      "y": 34,
      "z": -2,
      "name": "Rock_Chalk"
    },
    {
      "x": 4,
      "y": 35,
      "z": -2,
      "name": "Rock_Chalk"
    },
    {
      "x": 4,
      "y": 36,
      "z": -2,
      "name": "Rock_Lime"
    },
    {
      "x": 4,
      "y": 37,
      "z": -2,
      "name": "Rock_Lime"
    },
    {
      "x": 4,
      "y": 38,
      "z": -2,
      "name": "Rock_Chalk"
    },
    {
      "x": 4,
      "y": 39,
      "z": -2,
      "name": "Rock_Marble"
    },
    {
      "x": 4,
      "y": 40,
      "z": -2,
      "name": "Rock_Marble"
    },
    {
      "x": 4,
      "y": 41,
      "z": -2,
      "name": "Rock_Marble_SkyGrass"
    },
    {
      "x": 4,
      "y": 42,
      "z": -2,
      "name": "Wood_Birch_Trunk",
      "support": 15
    },
    {
      "x": 4,
      "y": 43,
      "z": -2,
      "name": "Wood_Birch_Trunk",
      "support": 15
    },
    {
      "x": 4,
      "y": 32,
      "z": -1,
      "name": "Rock_Chalk"
    },
    {
      "x": 4,
      "y": 33,
      "z": -1,
      "name": "Rock_Marble"
    },
    {
      "x": 4,
      "y": 34,
      "z": -1,
      "name": "Rock_Chalk"
    },
    {
      "x": 4,
      "y": 35,
      "z": -1,
      "name": "Rock_Chalk"
    },
    {
      "x": 4,
      "y": 36,
      "z": -1,
      "name": "Rock_Lime"
    },
    {
      "x": 4,
      "y": 37,
      "z": -1,
      "name": "Rock_Lime"
    },
    {
      "x": 4,
      "y": 38,
      "z": -1,
      "name": "Rock_Chalk"
    },
    {
      "x": 4,
      "y": 39,
      "z": -1,
      "name": "Rock_Lime"
    },
    {
      "x": 4,
      "y": 40,
      "z": -1,
      "name": "Rock_Marble"
    },
    {
      "x": 4,
      "y": 41,
      "z": -1,
      "name": "Rock_Marble_SkyGrass"
    },
    {
      "x": 4,
      "y": 35,
      "z": 0,
      "name": "Rock_Marble"
    },
    {
      "x": 4,
      "y": 36,
      "z": 0,
      "name": "Rock_Lime"
    },
    {
      "x": 4,
      "y": 37,
      "z": 0,
      "name": "Rock_Lime"
    },
    {
      "x": 4,
      "y": 38,
      "z": 0,
      "name": "Rock_Chalk"
    },
    {
      "x": 4,
      "y": 39,
      "z": 0,
      "name": "Rock_Lime"
    },
    {
      "x": 4,
      "y": 40,
      "z": 0,
      "name": "Rock_Marble"
    },
    {
      "x": 4,
      "y": 41,
      "z": 0,
      "name": "Rock_Marble_SkyGrass"
    },
    {
      "x": 4,
      "y": 42,
      "z": 0,
      "name": "Plant_Grass_Sky_Short",
      "support": 15
    },
    {
      "x": 4,
      "y": 35,
      "z": 1,
      "name": "Rock_Marble"
    },
    {
      "x": 4,
      "y": 36,
      "z": 1,
      "name": "Rock_Lime"
    },
    {
      "x": 4,
      "y": 37,
      "z": 1,
      "name": "Rock_Lime"
    },
    {
      "x": 4,
      "y": 38,
      "z": 1,
      "name": "Rock_Chalk"
    },
    {
      "x": 4,
      "y": 39,
      "z": 1,
      "name": "Rock_Lime"
    },
    {
      "x": 4,
      "y": 40,
      "z": 1,
      "name": "Rock_Marble"
    },
    {
      "x": 4,
      "y": 41,
      "z": 1,
      "name": "Rock_Marble_SkyGrass"
    },
    {
      "x": 4,
      "y": 35,
      "z": 2,
      "name": "Rock_Marble"
    },
    {
      "x": 4,
      "y": 36,
      "z": 2,
      "name": "Rock_Lime"
    },
    {
      "x": 4,
      "y": 37,
      "z": 2,
      "name": "Rock_Lime"
    },
    {
      "x": 4,
      "y": 38,
      "z": 2,
      "name": "Rock_Chalk"
    },
    {
      "x": 4,
      "y": 39,
      "z": 2,
      "name": "Rock_Lime"
    },
    {
      "x": 4,
      "y": 40,
      "z": 2,
      "name": "Rock_Marble"
    },
    {
      "x": 4,
      "y": 41,
      "z": 2,
      "name": "Soil_Gravel_Lime",
      "support": 15
    },
    {
      "x": 4,
      "y": 35,
      "z": 3,
      "name": "Rock_Marble"
    },
    {
      "x": 4,
      "y": 36,
      "z": 3,
      "name": "Rock_Lime"
    },
    {
      "x": 4,
      "y": 37,
      "z": 3,
      "name": "Rock_Chalk"
    },
    {
