{
  "version": 8,
  "blockIdVersion": 11,
  "anchorX": 0,
  "anchorY": 1,
  "anchorZ": 0,
  "blocks": [
    {
      "x": -4,
      "y": -1,
      "z": 1,
      "name": "Rock_Marble_SkyGrass"
    },
    {
      "x": -4,
      "y": -1,
      "z": 2,
      "name": "Rock_Marble_SkyGrass"
    },
    {
      "x": -3,
      "y": -1,
      "z": -1,
      "name": "Rock_Marble"
    },
    {
      "x": -3,
      "y": 0,
      "z": -1,
      "name": "Rock_Marble_SkyGrass"
    },
    {
      "x": -3,
      "y": 1,
      "z": -1,
      "name": "Plant_Grass_Sky_Short",
      "support": 15
    },
    {
      "x": -3,
      "y": -1,
      "z": 0,
      "name": "Rock_Marble"
    },
    {
      "x": -3,
      "y": 0,
      "z": 0,
      "name": "Rock_Marble_SkyGrass"
    },
    {
      "x": -3,
      "y": -1,
      "z": 1,
      "name": "Rock_Marble"
    },
    {
      "x": -3,
      "y": 0,
      "z": 1,
      "name": "Rock_Marble_SkyGrass"
    },
    {
      "x": -3,
      "y": -1,
      "z": 2,
      "name": "Rock_Marble_SkyGrass"
    },
    {
      "x": -2,
      "y": -1,
      "z": -2,
      "name": "Rock_Marble"
    },
    {
      "x": -2,
      "y": 0,
      "z": -2,
      "name": "Rock_Marble_SkyGrass"
    },
    {
      "x": -2,
      "y": -1,
      "z": -1,
      "name": "Rock_Marble"
    },
    {
      "x": -2,
      "y": 0,
      "z": -1,
      "name": "Rock_Marble_SkyGrass"
    },
    {
      "x": -2,
      "y": -1,
      "z": 0,
      "name": "Rock_Marble"
    },
    {
      "x": -2,
      "y": 0,
      "z": 0,
      "name": "Rock_Marble_SkyGrass"
    },
    {
      "x": -2,
      "y": -1,
      "z": 1,
      "name": "Rock_Marble"
    },
    {
      "x": -2,
      "y": 0,
      "z": 1,
      "name": "Rock_Marble_SkyGrass"
    },
    {
      "x": -2,
      "y": 1,
      "z": 1,
      "name": "Rubble_Marble",
      "support": 15
    },
    {
      "x": -2,
      "y": -1,
      "z": 2,
      "name": "Rock_Marble"
    },
    {
      "x": -2,
      "y": 0,
      "z": 2,
      "name": "Rock_Marble_SkyGrass"
    },
    {
      "x": -2,
      "y": 1,
      "z": 2,
      "name": "Plant_Grass_Sky_Long",
      "support": 15
    },
    {
      "x": -2,
      "y": 2,
      "z": 2,
      "name": "Plant_Grass_Sky_Long",
      "filler": 1024
    },
    {
      "x": -1,
      "y": -1,
      "z": -3,
      "name": "Rock_Marble"
    },
    {
      "x": -1,
      "y": 0,
      "z": -3,
      "name": "Rock_Marble_SkyGrass"
    },
    {
      "x": -1,
      "y": -1,
      "z": -2,
      "name": "Rock_Marble"
    },
    {
      "x": -1,
      "y": 0,
      "z": -2,
      "name": "Rock_Marble_SkyGrass"
    },
    {
      "x": -1,
      "y": 1,
      "z": -2,
      "name": "Plant_Grass_Sky_Long",
      "support": 15
    },
    {
      "x": -1,
      "y": 2,
      "z": -2,
      "name": "Plant_Grass_Sky_Long",
      "filler": 1024
    },
    {
      "x": -1,
      "y": -1,
      "z": -1,
      "name": "Rock_Marble"
    },
    {
      "x": -1,
      "y": 0,
      "z": -1,
      "name": "Rock_Marble_SkyGrass"
    },
    {
      "x": -1,
      "y": 1,
      "z": -1,
      "name": "Rock_Marble_Brick_Half"
    },
    {
      "x": -1,
      "y": -1,
      "z": 0,
      "name": "Rock_Marble"
    },
    {
      "x": -1,
      "y": 0,
      "z": 0,
      "name": "Rock_Marble_SkyGrass"
    },
    {
      "x": -1,
      "y": 1,
      "z": 0,
      "name": "Rubble_Marble_Medium",
      "support": 15
    },
    {
      "x": -1,
      "y": -1,
      "z": 1,
      "name": "Rock_Marble"
    },
    {
      "x": -1,
      "y": 0,
      "z": 1,
      "name": "Rock_Marble_SkyGrass"
    },
    {
      "x": -1,
      "y": 1,
      "z": 1,
      "name": "Plant_Grass_Sky_Long",
      "support": 15
    },
    {
      "x": -1,
      "y": 2,
      "z": 1,
      "name": "Plant_Grass_Sky_Long",
      "filler": 1024
    },
    {
      "x": -1,
      "y": -1,
      "z": 2,
      "name": "Rock_Marble"
    },
    {
      "x": -1,
      "y": 0,
      "z": 2,
      "name": "Rock_Marble_SkyGrass"
    },
    {
      "x": -1,
      "y": -1,
      "z": 3,
      "name": "Rock_Marble"
    },
    {
      "x": -1,
      "y": 0,
      "z": 3,
      "name": "Rock_Marble_SkyGrass"
    },
    {
      "x": 0,
      "y": -1,
      "z": -3,
      "name": "Rock_Marble"
    },
    {
      "x": 0,
      "y": 0,
      "z": -3,
      "name": "Rock_Marble_SkyGrass"
    },
    {
      "x": 0,
      "y": 7,
      "z": -3,
      "name": "Rock_Marble_Brick_Smooth_Half",
      "rotation": 8
    },
    {
      "x": 0,
      "y": -1,
      "z": -2,
      "name": "Rock_Marble"
    },
    {
      "x": 0,
      "y": 0,
      "z": -2,
      "name": "Rock_Marble_SkyGrass"
    },
    {
      "x": 0,
      "y": 1,
      "z": -2,
      "name": "Rock_Marble_Brick"
    },
    {
      "x": 0,
      "y": 2,
      "z": -2,
      "name": "Rock_Marble_Brick_Pillar_Base"
    },
    {
      "x": 0,
      "y": 3,
      "z": -2,
      "name": "Rock_Marble_Brick_Pillar_Middle"
    },
    {
      "x": 0,
      "y": 4,
      "z": -2,
      "name": "Rock_Marble_Brick_Pillar_Middle"
    },
    {
      "x": 0,
      "y": 5,
      "z": -2,
      "name": "Rock_Marble_Brick_Pillar_Middle"
    },
    {
      "x": 0,
      "y": 6,
      "z": -2,
      "name": "Rock_Marble_Brick_Pillar_Base",
      "rotation": 8
    },
    {
      "x": 0,
      "y": 7,
      "z": -2,
      "name": "Rock_Marble_Brick"
    },
    {
      "x": 0,
      "y": -1,
      "z": -1,
      "name": "Rock_Marble"
    },
    {
      "x": 0,
      "y": 0,
      "z": -1,
      "name": "Rock_Marble_SkyGrass"
    },
    {
      "x": 0,
      "y": 1,
      "z": -1,
      "name": "Rock_Marble_Brick"
    },
    {
      "x": 0,
      "y": 7,
      "z": -1,
      "name": "Rock_Marble_Brick_Decorative"
    },
    {
      "x": 0,
      "y": -1,
      "z": 0,
      "name": "Rock_Marble"
    },
    {
      "x": 0,
      "y": 0,
      "z": 0,
      "name": "Rock_Marble_SkyGrass"
    },
    {
      "x": 0,
      "y": 1,
      "z": 0,
      "name": "Rock_Marble_Brick"
    },
    {
      "x": 0,
      "y": 2,
      "z": 0,
      "name": "Rock_Marble_Brick_Pillar_Base"
    },
    {
      "x": 0,
      "y": 3,
      "z": 0,
      "name": "Rock_Marble_Brick_Pillar_Middle"
    },
    {
      "x": 0,
      "y": 4,
      "z": 0,
      "name": "Rock_Marble_Brick_Pillar_Middle"
    },
    {
      "x": 0,
      "y": 5,
      "z": 0,
      "name": "Rock_Marble_Brick_Pillar_Middle"
    },
    {
      "x": 0,
      "y": 6,
      "z": 0,
      "name": "Rock_Marble_Brick_Pillar_Base",
      "rotation": 8
    },
    {
      "x": 0,
      "y": 7,
      "z": 0,
      "name": "Rock_Marble_Brick_Decorative"
    },
    {
      "x": 0,
      "y": 8,
      "z": 0,
      "name": "Rubble_Marble_Medium",
      "support": 15
    },
    {
      "x": 0,
      "y": -1,
      "z": 1,
      "name": "Rock_Marble"
    },
    {
      "x": 0,
      "y": 0,
      "z": 1,
      "name": "Rock_Marble_SkyGrass"
    },
    {
      "x": 0,
      "y": 1,
      "z": 1,
      "name": "Rock_Marble_Brick_Half"
    },
    {
      "x": 0,
      "y": -1,
      "z": 2,
      "name": "Rock_Marble"
    },
    {
      "x": 0,
      "y": 0,
      "z": 2,
      "name": "Rock_Marble_SkyGrass"
    },
    {
      "x": 0,
      "y": 1,
      "z": 2,
      "name": "Rock_Marble_Brick"
    },
    {
      "x": 0,
      "y": 2,
      "z": 2,
      "name": "Rock_Marble_Brick_Pillar_Base"
    },
    {
      "x": 0,
      "y": 3,
      "z": 2,
      "name": "Rock_Marble_Brick_Pillar_Middle"
    },
    {
      "x": 0,
      "y": 4,
      "z": 2,
      "name": "Rubble_Marble",
      "support": 15
    },
    {
      "x": 0,
      "y": -1,
      "z": 3,
      "name": "Rock_Marble"
    },
    {
      "x": 0,
      "y": 0,
      "z": 3,
      "name": "Rock_Marble_SkyGrass"
    },
    {
      "x": 0,
      "y": 1,
      "z": 3,
      "name": "Rock_Marble_Brick_Smooth_Half"
    },
    {
      "x": 1,
      "y": -1,
      "z": -4,
      "name": "Rock_Marble_SkyGrass"
    },
    {
      "x": 1,
      "y": -1,
      "z": -3,
      "name": "Rock_Marble"
    },
    {
      "x": 1,
      "y": 0,
      "z": -3,
      "name": "Rock_Marble_SkyGrass"
    },
    {
      "x": 1,
      "y": 1,
      "z": -3,
      "name": "Plant_Grass_Sky_Short",
      "support": 15
    },
    {
      "x": 1,
      "y": -1,
      "z": -2,
      "name": "Rock_Marble"
    },
    {
      "x": 1,
      "y": 0,
      "z": -2,
      "name": "Rock_Marble_SkyGrass"
    },
    {
      "x": 1,
      "y": 1,
      "z": -2,
      "name": "Plant_Grass_Sky",
      "support": 15
    },
    {
      "x": 1,
      "y": -1,
      "z": -1,
      "name": "Rock_Marble"
    },
    {
      "x": 1,
      "y": 0,
      "z": -1,
      "name": "Rock_Marble_SkyGrass"
    },
    {
      "x": 1,
      "y": -1,
      "z": 0,
      "name": "Rock_Marble"
    },
    {
      "x": 1,
      "y": 0,
      "z": 0,
      "name": "Rock_Marble_SkyGrass"
    },
    {
      "x": 1,
      "y": 1,
      "z": 0,
      "name": "Plant_Grass_Sky_Wild",
      "support": 15
    },
    {
      "x": 1,
      "y": 2,
      "z": 0,
      "name": "Plant_Grass_Sky_Wild",
      "filler": 1024
    },
    {
      "x": 1,
      "y": -1,
      "z": 1,
      "name": "Rock_Marble"
    },
    {
      "x": 1,
      "y": 0,
      "z": 1,
      "name": "Rock_Marble_SkyGrass"
    },
    {
      "x": 1,
      "y": 1,
      "z": 1,
      "name": "Plant_Grass_Sky",
      "support": 15
    },
    {
      "x": 1,
      "y": -1,
      "z": 2,
      "name": "Rock_Marble"
    },
    {
      "x": 1,
      "y": 0,
      "z": 2,
      "name": "Rock_Marble_SkyGrass"
    },
    {
      "x": 1,
      "y": -1,
      "z": 3,
      "name": "Rock_Marble_SkyGrass"
    },
    {
      "x": 2,
      "y": -1,
      "z": -4,
      "name": "Rock_Marble_SkyGrass"
    },
    {
      "x": 2,
      "y": -1,
      "z": -3,
      "name": "Rock_Marble_SkyGrass"
    },
    {
      "x": 2,
      "y": -1,
      "z": -2,
      "name": "Rock_Marble"
    },
    {
      "x": 2,
      "y": 0,
      "z": -2,
      "name": "Rock_Marble_SkyGrass"
    },
    {
      "x": 2,
      "y": -1,
      "z": -1,
      "name": "Rock_Marble"
    },
    {
      "x": 2,
      "y": 0,
      "z": -1,
      "name": "Rock_Marble_SkyGrass"
    },
    {
      "x": 2,
      "y": 1,
      "z": -1,
      "name": "Plant_Grass_Sky",
      "support": 15
    },
    {
      "x": 2,
      "y": -1,
      "z": 0,
      "name": "Rock_Marble"
    },
    {
      "x": 2,
      "y": 0,
      "z": 0,
      "name": "Rock_Marble_SkyGrass"
    },
    {
      "x": 2,
      "y": -1,
      "z": 1,
      "name": "Rock_Marble"
    },
    {
      "x": 2,
      "y": 0,
      "z": 1,
      "name": "Rock_Marble_SkyGrass"
    },
    {
      "x": 2,
      "y": -1,
      "z": 2,
      "name": "Rock_Marble"
    },
    {
      "x": 2,
      "y": 0,
      "z": 2,
      "name": "Rock_Marble_SkyGrass"
    },
    {
      "x": 2,
      "y": 1,
      "z": 2,
      "name": "Plant_Grass_Sky_Short",
      "support": 15
    },
    {
      "x": 3,
      "y": -1,
      "z": -3,
      "name": "Rock_Marble_SkyGrass"
    },
    {
      "x": 3,
      "y": -1,
      "z": -2,
      "name": "Rock_Marble_SkyGrass"
    },
    {
      "x": 3,
      "y": -1,
      "z": -1,
      "name": "Rock_Marble"
    },
    {
      "x": 3,
      "y": 0,
      "z": -1,
      "name": "Rock_Marble_SkyGrass"
    },
    {
      "x": 3,
      "y": -1,
      "z": 0,
      "name": "Rock_Marble"
    },
    {
      "x": 3,
      "y": 0,
      "z": 0,
      "name": "Rock_Marble_SkyGrass"
    },
    {
      "x": 3,
      "y": -1,
      "z": 1,
      "name": "Rock_Marble"
    },
    {
      "x": 3,
      "y": 0,
      "z": 1,
      "name": "Rock_Marble_SkyGrass"
    },
    {
      "x": 4,
      "y": -1,
      "z": -2,
      "name": "Rock_Marble_SkyGrass"
    },
    {
      "x": 4,
      "y": -1,
      "z": -1,
      "name": "Rock_Marble_SkyGrass"
    }
  ]
}