{
  "version": 8,
  "blockIdVersion": 11,
  "anchorX": 0,
  "anchorY": 2,
  "anchorZ": 0,
  "blocks": [
    {
      "x": -3,
      "y": 5,
      "z": -1,
      "name": "Plant_Moss_Block_Yellow",
      "support": 15
    },
    {
      "x": -3,
      "y": 5,
      "z": 0,
      "name": "Plant_Moss_Block_Yellow",
      "support": 15
    },
    {
      "x": -2,
      "y": 5,
      "z": -2,
      "name": "Rock_Stone"
    },
    {
      "x": -2,
      "y": 6,
      "z": -2,
      "name": "Plant_Moss_Rug_Yellow",
      "support": 15
    },
    {
      "x": -2,
      "y": 5,
      "z": -1,
      "name": "Rock_Stone"
    },
    {
      "x": -2,
      "y": 6,
      "z": -1,
      "name": "Plant_Moss_Rug_Yellow",
      "support": 15
    },
    {
      "x": -2,
      "y": 0,
      "z": 0,
      "name": "Rock_Quartzite"
    },
    {
      "x": -2,
      "y": 1,
      "z": 0,
      "name": "Rock_Quartzite"
    },
    {
      "x": -2,
      "y": 2,
      "z": 0,
      "name": "Rock_Quartzite"
    },
    {
      "x": -2,
      "y": 5,
      "z": 0,
      "name": "Plant_Moss_Block_Yellow",
      "support": 15
    },
    {
      "x": -2,
      "y": 5,
      "z": 1,
      "name": "Plant_Moss_Block_Yellow",
      "support": 15
    },
    {
      "x": -2,
      "y": 5,
      "z": 2,
      "name": "Rock_Quartzite"
    },
    {
      "x": -2,
      "y": 6,
      "z": 2,
      "name": "Plant_Moss_Rug_Yellow",
      "support": 15
    },
    {
      "x": -1,
      "y": 5,
      "z": -3,
      "name": "Plant_Moss_Block_Yellow",
      "support": 15
    },
    {
      "x": -1,
      "y": 5,
      "z": -2,
      "name": "Rock_Stone"
    },
    {
      "x": -1,
      "y": 6,
      "z": -2,
      "name": "Plant_Moss_Rug_Yellow",
      "support": 15
    },
    {
      "x": -1,
      "y": 0,
      "z": -1,
      "name": "Rock_Stone"
    },
    {
      "x": -1,
      "y": 1,
      "z": -1,
      "name": "Rock_Stone"
    },
    {
      "x": -1,
      "y": 2,
      "z": -1,
      "name": "Rock_Stone"
    },
    {
      "x": -1,
      "y": 4,
      "z": -1,
      "name": "Rock_Quartzite"
    },
    {
      "x": -1,
      "y": 5,
      "z": -1,
      "name": "Rock_Stone"
    },
    {
      "x": -1,
      "y": 6,
      "z": -1,
      "name": "Plant_Moss_Block_Yellow",
      "support": 15
    },
    {
      "x": -1,
      "y": 0,
      "z": 0,
      "name": "Rock_Quartzite"
    },
    {
      "x": -1,
      "y": 1,
      "z": 0,
      "name": "Rock_Quartzite"
    },
    {
      "x": -1,
      "y": 2,
      "z": 0,
      "name": "Rock_Quartzite"
    },
    {
      "x": -1,
      "y": 3,
      "z": 0,
      "name": "Rock_Quartzite"
    },
    {
      "x": -1,
      "y": 4,
      "z": 0,
      "name": "Rock_Quartzite"
    },
    {
      "x": -1,
      "y": 5,
      "z": 0,
      "name": "Rock_Quartzite"
    },
    {
      "x": -1,
      "y": 6,
      "z": 0,
      "name": "Plant_Moss_Block_Yellow",
      "support": 15
    },
    {
      "x": -1,
      "y": 0,
      "z": 1,
      "name": "Rock_Quartzite"
    },
    {
      "x": -1,
      "y": 1,
      "z": 1,
      "name": "Rock_Quartzite"
    },
    {
      "x": -1,
      "y": 2,
      "z": 1,
      "name": "Rock_Quartzite"
    },
    {
      "x": -1,
      "y": 4,
      "z": 1,
      "name": "Rock_Quartzite"
    },
    {
      "x": -1,
      "y": 5,
      "z": 1,
      "name": "Plant_Moss_Block_Yellow",
      "support": 15
    },
    {
      "x": -1,
      "y": 4,
      "z": 2,
      "name": "Rock_Quartzite"
    },
    {
      "x": -1,
      "y": 5,
      "z": 2,
      "name": "Plant_Moss_Block_Yellow",
      "support": 15
    },
    {
      "x": -1,
      "y": 5,
      "z": 3,
      "name": "Rock_Quartzite"
    },
    {
      "x": -1,
      "y": 6,
      "z": 3,
      "name": "Plant_Moss_Rug_Yellow",
      "support": 15
    },
    {
      "x": 0,
      "y": 5,
      "z": -3,
      "name": "Plant_Moss_Block_Yellow",
      "support": 15
    },
    {
      "x": 0,
      "y": 5,
      "z": -2,
      "name": "Plant_Moss_Block_Yellow",
      "support": 15
    },
    {
      "x": 0,
      "y": 0,
      "z": -1,
      "name": "Rock_Stone"
    },
    {
      "x": 0,
      "y": 1,
      "z": -1,
      "name": "Rock_Stone"
    },
    {
      "x": 0,
      "y": 2,
      "z": -1,
      "name": "Rock_Stone"
    },
    {
      "x": 0,
      "y": 3,
      "z": -1,
      "name": "Rock_Stone"
    },
    {
      "x": 0,
      "y": 4,
      "z": -1,
      "name": "Rock_Stone"
    },
    {
      "x": 0,
      "y": 5,
      "z": -1,
      "name": "Rock_Stone"
    },
    {
      "x": 0,
      "y": 6,
      "z": -1,
      "name": "Plant_Moss_Block_Yellow",
      "support": 15
    },
    {
      "x": 0,
      "y": 0,
      "z": 0,
      "name": "Rock_Quartzite"
    },
    {
      "x": 0,
      "y": 1,
      "z": 0,
      "name": "Rock_Quartzite"
    },
    {
      "x": 0,
      "y": 2,
      "z": 0,
      "name": "Rock_Stone"
    },
    {
      "x": 0,
      "y": 3,
      "z": 0,
      "name": "Rock_Quartzite"
    },
    {
      "x": 0,
      "y": 4,
      "z": 0,
      "name": "Rock_Quartzite"
    },
    {
      "x": 0,
      "y": 5,
      "z": 0,
      "name": "Rock_Quartzite"
    },
    {
      "x": 0,
      "y": 6,
      "z": 0,
      "name": "Plant_Moss_Block_Yellow",
      "support": 15
    },
    {
      "x": 0,
      "y": 0,
      "z": 1,
      "name": "Rock_Quartzite"
    },
    {
      "x": 0,
      "y": 1,
      "z": 1,
      "name": "Rock_Quartzite"
    },
    {
      "x": 0,
      "y": 2,
      "z": 1,
      "name": "Rock_Quartzite"
    },
    {
      "x": 0,
      "y": 4,
      "z": 1,
      "name": "Rock_Quartzite"
    },
    {
      "x": 0,
      "y": 5,
      "z": 1,
      "name": "Plant_Moss_Block_Yellow",
      "support": 15
    },
    {
      "x": 0,
      "y": 5,
      "z": 2,
      "name": "Plant_Moss_Block_Yellow",
      "support": 15
    },
    {
      "x": 0,
      "y": 5,
      "z": 3,
      "name": "Plant_Moss_Block_Yellow",
      "support": 15
    },
    {
      "x": 1,
      "y": 5,
      "z": -3,
      "name": "Rock_Lime"
    },
    {
      "x": 1,
      "y": 6,
      "z": -3,
      "name": "Plant_Moss_Rug_Yellow",
      "support": 15
    },
    {
      "x": 1,
      "y": 5,
      "z": -2,
      "name": "Rock_Stone"
    },
    {
      "x": 1,
      "y": 6,
      "z": -2,
      "name": "Plant_Moss_Rug_Yellow",
      "support": 15
    },
    {
      "x": 1,
      "y": 4,
      "z": -1,
      "name": "Rock_Quartzite"
    },
    {
      "x": 1,
      "y": 5,
      "z": -1,
      "name": "Plant_Moss_Block_Yellow",
      "support": 15
    },
    {
      "x": 1,
      "y": 0,
      "z": 0,
      "name": "Rock_Quartzite"
    },
    {
      "x": 1,
      "y": 1,
      "z": 0,
      "name": "Rock_Quartzite"
    },
    {
      "x": 1,
      "y": 2,
      "z": 0,
      "name": "Rock_Quartzite"
    },
    {
      "x": 1,
      "y": 3,
      "z": 0,
      "name": "Rock_Quartzite"
    },
    {
      "x": 1,
      "y": 4,
      "z": 0,
      "name": "Rock_Quartzite"
    },
    {
      "x": 1,
      "y": 5,
      "z": 0,
      "name": "Plant_Moss_Block_Yellow",
      "support": 15
    },
    {
      "x": 1,
      "y": 4,
      "z": 1,
      "name": "Rock_Quartzite"
    },
    {
      "x": 1,
      "y": 5,
      "z": 1,
      "name": "Plant_Moss_Block_Yellow",
      "support": 15
    },
    {
      "x": 1,
      "y": 5,
      "z": 2,
      "name": "Rock_Lime"
    },
    {
      "x": 1,
      "y": 6,
      "z": 2,
      "name": "Plant_Moss_Rug_Yellow",
      "support": 15
    },
    {
      "x": 1,
      "y": 5,
      "z": 3,
      "name": "Rock_Lime"
    },
    {
      "x": 1,
      "y": 6,
      "z": 3,
      "name": "Plant_Moss_Rug_Yellow",
      "support": 15
    },
    {
      "x": 2,
      "y": 5,
      "z": -2,
      "name": "Rock_Lime"
    },
    {
      "x": 2,
      "y": 6,
      "z": -2,
      "name": "Plant_Moss_Rug_Yellow",
      "support": 15
    },
    {
      "x": 2,
      "y": 5,
      "z": -1,
      "name": "Rock_Quartzite"
    },
    {
      "x": 2,
      "y": 6,
      "z": -1,
      "name": "Plant_Moss_Rug_Yellow",
      "support": 15
    },
    {
      "x": 2,
      "y": 5,
      "z": 0,
      "name": "Plant_Moss_Block_Yellow",
      "support": 15
    },
    {
      "x": 2,
      "y": 5,
      "z": 1,
      "name": "Rock_Quartzite"
    },
    {
      "x": 2,
      "y": 6,
      "z": 1,
      "name": "Plant_Moss_Rug_Yellow",
      "support": 15
    },
    {
      "x": 2,
      "y": 5,
      "z": 2,
      "name": "Plant_Moss_Block_Yellow",
      "support": 15
    },
    {
      "x": 3,
      "y": 5,
      "z": -1,
      "name": "Plant_Moss_Block_Yellow",
      "support": 15
    },
    {
      "x": 3,
      "y": 5,
      "z": 0,
      "name": "Plant_Moss_Block_Yellow",
      "support": 15
    },
    {
      "x": 3,
      "y": 5,
      "z": 1,
      "name": "Rock_Quartzite"
    },
    {
      "x": 3,
      "y": 6,
      "z": 1,
      "name": "Plant_Moss_Rug_Yellow",
      "support": 15
    }
  ]
}