{
  "version": 8,
  "blockIdVersion": 11,
  "anchorX": 0,
  "anchorY": 6,
  "anchorZ": 0,
  "blocks": [
    {
      "x": -5,
      "y": 9,
      "z": -8,
      "name": "Plant_Leaves_Aspen",
      "support": 15
    },
    {
      "x": -5,
      "y": 9,
      "z": -7,
      "name": "Plant_Leaves_Aspen",
      "support": 15
    },
    {
      "x": -4,
      "y": 9,
      "z": -9,
      "name": "Plant_Leaves_Aspen",
      "support": 15
    },
    {
      "x": -4,
      "y": 9,
      "z": -8,
      "name": "Plant_Leaves_Aspen",
      "support": 15
    },
    {
      "x": -4,
      "y": 10,
      "z": -8,
      "name": "Plant_Leaves_Aspen",
      "support": 15
    },
    {
      "x": -4,
      "y": 9,
      "z": -7,
      "name": "Plant_Leaves_Aspen",
      "support": 15
    },
    {
      "x": -3,
      "y": 9,
      "z": -9,
      "name": "Plant_Leaves_Aspen",
      "support": 15
    },
    {
      "x": -3,
      "y": 9,
      "z": -8,
      "name": "Plant_Leaves_Aspen",
      "support": 15
    },
    {
      "x": -3,
      "y": 10,
      "z": -8,
      "name": "Plant_Leaves_Aspen",
      "support": 15
    },
    {
      "x": -3,
      "y": 9,
      "z": -7,
      "name": "Plant_Leaves_Aspen",
      "support": 15
    },
    {
      "x": -3,
      "y": 10,
      "z": -7,
      "name": "Plant_Leaves_Aspen",
      "support": 15
    },
    {
      "x": -2,
      "y": 9,
      "z": -9,
      "name": "Plant_Leaves_Aspen",
      "support": 15
    },
    {
      "x": -2,
      "y": 14,
      "z": -9,
      "name": "Plant_Leaves_Aspen",
      "support": 15
    },
    {
      "x": -2,
      "y": 9,
      "z": -8,
      "name": "Wood_Birch_Branch_Long",
      "support": 15,
      "rotation": 5
    },
    {
      "x": -2,
      "y": 10,
      "z": -8,
      "name": "Plant_Leaves_Aspen",
      "support": 15
    },
    {
      "x": -2,
      "y": 14,
      "z": -8,
      "name": "Plant_Leaves_Aspen",
      "support": 15
    },
    {
      "x": -2,
      "y": 9,
      "z": -7,
      "name": "Plant_Leaves_Aspen",
      "support": 15
    },
    {
      "x": -2,
      "y": 14,
      "z": -7,
      "name": "Plant_Leaves_Aspen",
      "support": 15
    },
    {
      "x": -1,
      "y": 14,
      "z": -10,
      "name": "Plant_Leaves_Aspen",
      "support": 15
    },
    {
      "x": -1,
      "y": 14,
      "z": -9,
      "name": "Plant_Leaves_Aspen",
      "support": 15
    },
    {
      "x": -1,
      "y": 15,
      "z": -9,
      "name": "Plant_Leaves_Aspen",
      "support": 15
    },
    {
      "x": -1,
      "y": 9,
      "z": -8,
      "name": "Wood_Birch_Branch_Long",
      "support": 15,
      "rotation": 5
    },
    {
      "x": -1,
      "y": 14,
      "z": -8,
      "name": "Plant_Leaves_Aspen",
      "support": 15
    },
    {
      "x": -1,
      "y": 15,
      "z": -8,
      "name": "Plant_Leaves_Aspen",
      "support": 15
    },
    {
      "x": -1,
      "y": 8,
      "z": -7,
      "name": "Wood_Birch_Branch_Short",
      "support": 15,
      "rotation": 3
    },
    {
      "x": -1,
      "y": 14,
      "z": -7,
      "name": "Plant_Leaves_Aspen",
      "support": 15
    },
    {
      "x": -1,
      "y": 14,
      "z": -6,
      "name": "Plant_Leaves_Aspen",
      "support": 15
    },
    {
      "x": -1,
      "y": 6,
      "z": 1,
      "name": "Wood_Birch_Trunk_Full",
      "support": 15,
      "rotation": 4
    },
    {
      "x": -1,
      "y": 6,
      "z": 2,
      "name": "Wood_Birch_Trunk",
      "support": 15,
      "rotation": 4
    },
    {
      "x": -1,
      "y": 6,
      "z": 3,
      "name": "Wood_Birch_Trunk",
      "support": 15,
      "rotation": 4
    },
    {
      "x": -1,
      "y": 3,
      "z": 4,
      "name": "Wood_Birch_Trunk_Full",
      "support": 15
    },
    {
      "x": -1,
      "y": 4,
      "z": 4,
      "name": "Wood_Birch_Trunk",
      "support": 15
    },
    {
      "x": -1,
      "y": 5,
      "z": 4,
      "name": "Wood_Birch_Trunk",
      "support": 15
    },
    {
      "x": -1,
      "y": 6,
      "z": 4,
      "name": "Wood_Birch_Trunk_Full",
      "support": 15,
      "rotation": 4
    },
    {
      "x": -1,
      "y": 3,
      "z": 5,
      "name": "Wood_Birch_Trunk",
      "support": 15,
      "rotation": 4
    },
    {
      "x": -1,
      "y": 6,
      "z": 5,
      "name": "Wood_Birch_Branch_Long",
      "support": 15,
      "rotation": 4
    },
    {
      "x": -1,
      "y": 3,
      "z": 6,
      "name": "Wood_Birch_Trunk_Full",
      "support": 15
    },
    {
      "x": -1,
      "y": 4,
      "z": 6,
      "name": "Wood_Birch_Trunk_Full",
      "support": 15
    },
    {
      "x": -1,
      "y": 5,
      "z": 6,
      "name": "Wood_Birch_Branch_Corner",
      "support": 15,
      "rotation": 8
    },
    {
      "x": -1,
      "y": 5,
      "z": 7,
      "name": "Wood_Birch_Branch_Long",
      "support": 15,
      "rotation": 4
    },
    {
      "x": -1,
      "y": 5,
      "z": 8,
      "name": "Wood_Birch_Branch_Long",
      "support": 15,
      "rotation": 4
    },
    {
      "x": -1,
      "y": 4,
      "z": 9,
      "name": "Wood_Birch_Branch_Corner",
      "support": 15,
      "rotation": 2
    },
    {
      "x": -1,
      "y": 5,
      "z": 9,
      "name": "Wood_Birch_Branch_Corner",
      "support": 15,
      "rotation": 10
    },
    {
      "x": 0,
      "y": 14,
      "z": -10,
      "name": "Plant_Leaves_Aspen",
      "support": 15
    },
    {
      "x": 0,
      "y": 6,
      "z": -9,
      "name": "Wood_Birch_Branch_Corner",
      "support": 15,
      "rotation": 2
    },
    {
      "x": 0,
      "y": 7,
      "z": -9,
      "name": "Wood_Birch_Branch_Corner",
      "support": 15,
      "rotation": 8
    },
    {
      "x": 0,
      "y": 11,
      "z": -9,
      "name": "Plant_Leaves_Aspen",
      "support": 15
    },
    {
      "x": 0,
      "y": 14,
      "z": -9,
      "name": "Plant_Leaves_Aspen",
      "support": 15
    },
    {
      "x": 0,
      "y": 15,
      "z": -9,
      "name": "Plant_Leaves_Aspen",
      "support": 15
    },
    {
      "x": 0,
      "y": 7,
      "z": -8,
      "name": "Wood_Birch_Branch_Long",
      "support": 15,
      "rotation": 4
    },
    {
      "x": 0,
      "y": 8,
      "z": -8,
      "name": "Wood_Birch_Trunk_Full",
      "support": 15,
      "rotation": 4
    },
    {
      "x": 0,
      "y": 9,
      "z": -8,
      "name": "Wood_Birch_Trunk",
      "support": 15
    },
    {
      "x": 0,
      "y": 10,
      "z": -8,
      "name": "Wood_Birch_Trunk",
      "support": 15
    },
    {
      "x": 0,
      "y": 11,
      "z": -8,
      "name": "Wood_Birch_Trunk_Full",
      "support": 15
    },
    {
      "x": 0,
      "y": 12,
      "z": -8,
      "name": "Wood_Birch_Branch_Long",
      "support": 15
    },
    {
      "x": 0,
      "y": 13,
      "z": -8,
      "name": "Wood_Birch_Branch_Long",
      "support": 15
    },
    {
      "x": 0,
      "y": 14,
      "z": -8,
      "name": "Wood_Birch_Branch_Long",
      "support": 15
    },
    {
      "x": 0,
      "y": 15,
      "z": -8,
      "name": "Plant_Leaves_Aspen",
      "support": 15
    },
    {
      "x": 0,
      "y": 7,
      "z": -7,
      "name": "Wood_Birch_Trunk_Full",
      "support": 15,
      "rotation": 4
    },
    {
      "x": 0,
      "y": 8,
      "z": -7,
      "name": "Wood_Birch_Trunk_Full",
      "support": 15,
      "rotation": 4
    },
    {
      "x": 0,
      "y": 14,
      "z": -7,
      "name": "Plant_Leaves_Aspen",
      "support": 15
    },
    {
      "x": 0,
      "y": 15,
      "z": -7,
      "name": "Plant_Leaves_Aspen",
      "support": 15
    },
    {
      "x": 0,
      "y": 7,
      "z": -6,
      "name": "Wood_Birch_Trunk",
      "support": 15,
      "rotation": 4
    },
    {
      "x": 0,
      "y": 14,
      "z": -6,
      "name": "Plant_Leaves_Aspen",
      "support": 15
    },
    {
      "x": 0,
      "y": 7,
      "z": -5,
      "name": "Wood_Birch_Trunk",
      "support": 15,
      "rotation": 4
    },
    {
      "x": 0,
      "y": 14,
      "z": -5,
      "name": "Plant_Leaves_Aspen",
      "support": 15
    },
    {
      "x": 0,
      "y": 6,
      "z": -4,
      "name": "Wood_Birch_Trunk_Full",
      "support": 15,
      "rotation": 4
    },
    {
      "x": 0,
      "y": 7,
      "z": -4,
      "name": "Wood_Birch_Trunk_Full",
      "support": 15,
      "rotation": 4
    },
    {
      "x": 0,
      "y": 6,
      "z": -3,
      "name": "Wood_Birch_Trunk",
      "support": 15,
      "rotation": 4
    },
    {
      "x": 0,
      "y": 5,
      "z": -2,
      "name": "Wood_Birch_Trunk_Full",
      "support": 15,
      "rotation": 4
    },
    {
      "x": 0,
      "y": 6,
      "z": -2,
      "name": "Wood_Birch_Trunk",
      "support": 15,
      "rotation": 4
    },
    {
      "x": 0,
      "y": 5,
      "z": -1,
      "name": "Wood_Birch_Trunk",
      "support": 15,
      "rotation": 4
    },
    {
      "x": 0,
      "y": 6,
      "z": -1,
      "name": "Wood_Birch_Trunk",
      "support": 15,
      "rotation": 4
    },
    {
      "x": 0,
      "y": 7,
      "z": -1,
      "name": "Wood_Birch_Trunk_Full",
      "support": 15,
      "rotation": 4
    },
    {
      "x": 0,
      "y": 0,
      "z": 0,
      "name": "Rock_Stone"
    },
    {
      "x": 0,
      "y": 5,
      "z": 0,
      "name": "Wood_Birch_Trunk",
      "support": 15,
      "rotation": 4
    },
    {
      "x": 0,
      "y": 6,
      "z": 0,
      "name": "Wood_Birch_Trunk",
      "support": 15,
      "rotation": 4
    },
    {
      "x": 0,
      "y": 7,
      "z": 0,
      "name": "Wood_Birch_Trunk",
      "support": 15,
      "rotation": 4
    },
    {
      "x": 0,
      "y": 5,
      "z": 1,
      "name": "Wood_Birch_Trunk",
      "support": 15,
      "rotation": 4
    },
    {
      "x": 0,
      "y": 6,
      "z": 1,
      "name": "Wood_Birch_Trunk",
      "support": 15,
      "rotation": 4
    },
    {
      "x": 0,
      "y": 7,
      "z": 1,
      "name": "Wood_Birch_Trunk",
      "support": 15,
      "rotation": 4
    },
    {
      "x": 0,
      "y": 5,
      "z": 2,
      "name": "Wood_Birch_Trunk",
      "support": 15,
      "rotation": 4
    },
    {
      "x": 0,
      "y": 6,
      "z": 2,
      "name": "Wood_Birch_Trunk",
      "support": 15,
      "rotation": 4
    },
    {
      "x": 0,
      "y": 7,
      "z": 2,
      "name": "Wood_Birch_Trunk",
      "support": 15,
      "rotation": 4
    },
    {
      "x": 0,
      "y": 5,
      "z": 3,
      "name": "Wood_Birch_Trunk",
      "support": 15,
      "rotation": 4
    },
    {
      "x": 0,
      "y": 6,
      "z": 3,
      "name": "Wood_Birch_Trunk_Full",
      "support": 15,
      "rotation": 4
    },
    {
      "x": 0,
      "y": 7,
      "z": 3,
      "name": "Wood_Birch_Trunk",
      "support": 15,
      "rotation": 4
    },
    {
      "x": 0,
      "y": 5,
      "z": 4,
      "name": "Wood_Birch_Trunk_Full",
      "support": 15,
      "rotation": 4
    },
    {
      "x": 0,
      "y": 7,
      "z": 4,
      "name": "Wood_Birch_Trunk_Full",
      "support": 15,
      "rotation": 4
    },
    {
      "x": 0,
      "y": 8,
      "z": 4,
      "name": "Wood_Birch_Trunk_Full",
      "support": 15,
      "rotation": 4
    },
    {
      "x": 0,
      "y": 4,
      "z": 5,
      "name": "Wood_Birch_Branch_Corner",
      "support": 15,
      "rotation": 3
    },
    {
      "x": 0,
      "y": 5,
      "z": 5,
      "name": "Wood_Birch_Branch_Corner",
      "support": 15,
      "rotation": 10
    },
    {
      "x": 0,
      "y": 8,
      "z": 5,
      "name": "Wood_Birch_Trunk",
      "support": 15,
      "rotation": 4
    },
    {
      "x": 0,
      "y": 8,
      "z": 6,
      "name": "Wood_Birch_Trunk_Full",
      "support": 15,
      "rotation": 4
    },
    {
      "x": 0,
      "y": 8,
      "z": 7,
      "name": "Wood_Birch_Branch_Long",
      "support": 15,
      "rotation": 4
    },
    {
      "x": 0,
      "y": 8,
      "z": 8,
      "name": "Wood_Birch_Branch_Long",
      "support": 15,
      "rotation": 4
    },
    {
      "x": 0,
      "y": 8,
      "z": 9,
      "name": "Wood_Birch_Branch_Corner",
      "support": 15
    },
    {
      "x": 0,
      "y": 9,
      "z": 9,
      "name": "Wood_Birch_Branch_Long",
      "support": 15
    },
    {
      "x": 0,
      "y": 10,
      "z": 9,
      "name": "Wood_Birch_Branch_Corner",
      "support": 15,
      "rotation": 8
    },
    {
      "x": 0,
      "y": 10,
      "z": 10,
      "name": "Wood_Birch_Branch_Long",
      "support": 15,
      "rotation": 4
    },
    {
      "x": 0,
      "y": 10,
      "z": 11,
      "name": "Wood_Birch_Branch_Corner",
      "support": 15,
      "rotation": 10
    },
    {
      "x": 1,
      "y": 11,
      "z": -10,
      "name": "Plant_Leaves_Aspen",
      "support": 15
    },
    {
      "x": 1,
      "y": 14,
      "z": -10,
      "name": "Plant_Leaves_Aspen",
      "support": 15
    },
    {
      "x": 1,
      "y": 11,
      "z": -9,
      "name": "Plant_Leaves_Aspen",
      "support": 15
    },
    {
      "x": 1,
      "y": 14,
      "z": -9,
      "name": "Plant_Leaves_Aspen",
      "support": 15
    },
    {
      "x": 1,
      "y": 15,
      "z": -9,
      "name": "Plant_Leaves_Aspen",
      "support": 15
    },
    {
      "x": 1,
      "y": 10,
      "z": -8,
      "name": "Wood_Birch_Branch_Long",
      "support": 15,
      "rotation": 5
    },
    {
      "x": 1,
      "y": 11,
      "z": -8,
      "name": "Plant_Leaves_Aspen",
      "support": 15
    },
    {
      "x": 1,
      "y": 14,
      "z": -8,
      "name": "Plant_Leaves_Aspen",
      "support": 15
    },
    {
      "x": 1,
      "y": 15,
      "z": -8,
      "name": "Plant_Leaves_Aspen",
      "support": 15
    },
    {
      "x": 1,
      "y": 11,
      "z": -7,
      "name": "Plant_Leaves_Aspen",
      "support": 15
    },
    {
      "x": 1,
      "y": 14,
      "z": -7,
      "name": "Plant_Leaves_Aspen",
      "support": 15
    },
    {
      "x": 1,
      "y": 15,
      "z": -7,
      "name": "Plant_Leaves_Aspen",
      "support": 15
    },
    {
      "x": 1,
      "y": 14,
      "z": -6,
      "name": "Plant_Leaves_Aspen",
      "support": 15
    },
    {
      "x": 1,
      "y": 7,
      "z": -5,
      "name": "Wood_Birch_Trunk",
      "support": 15,
      "rotation": 5
    },
    {
      "x": 1,
      "y": 14,
      "z": -5,
      "name": "Plant_Leaves_Aspen",
      "support": 15
    },
    {
      "x": 1,
      "y": 6,
      "z": -1,
      "name": "Wood_Birch_Trunk_Full",
      "support": 15,
      "rotation": 4
    },
    {
      "x": 1,
      "y": 6,
      "z": 0,
      "name": "Wood_Birch_Trunk",
      "support": 15,
      "rotation": 4
    },
    {
      "x": 1,
      "y": 6,
      "z": 1,
      "name": "Wood_Birch_Trunk",
      "support": 15,
      "rotation": 4
    },
    {
      "x": 1,
      "y": 6,
      "z": 2,
      "name": "Wood_Birch_Trunk",
      "support": 15,
      "rotation": 4
    },
    {
      "x": 1,
      "y": 6,
      "z": 3,
      "name": "Wood_Birch_Trunk_Full",
      "support": 15,
      "rotation": 4
    },
    {
      "x": 1,
      "y": 4,
      "z": 5,
      "name": "Wood_Birch_Branch_Long",
      "support": 15,
      "rotation": 5
    },
    {
      "x": 1,
      "y": 6,
      "z": 5,
      "name": "Wood_Birch_Branch_Long",
      "support": 15,
      "rotation": 4
    },
    {
      "x": 1,
      "y": 6,
      "z": 6,
      "name": "Wood_Birch_Trunk_Full",
      "support": 15,
      "rotation": 4
    },
    {
      "x": 1,
      "y": 6,
      "z": 7,
      "name": "Wood_Birch_Trunk_Full",
      "support": 15,
      "rotation": 5
    },
    {
      "x": 2,
      "y": 11,
      "z": -11,
      "name": "Plant_Leaves_Aspen",
      "support": 15
    },
    {
      "x": 2,
      "y": 11,
      "z": -10,
      "name": "Plant_Leaves_Aspen",
      "support": 15
    },
    {
      "x": 2,
      "y": 14,
      "z": -10,
      "name": "Plant_Leaves_Aspen",
      "support": 15
    },
    {
      "x": 2,
      "y": 11,
      "z": -9,
      "name": "Plant_Leaves_Aspen",
      "support": 15
    },
    {
      "x": 2,
      "y": 12,
      "z": -9,
      "name": "Plant_Leaves_Aspen",
      "support": 15
    },
    {
      "x": 2,
      "y": 14,
      "z": -9,
      "name": "Plant_Leaves_Aspen",
      "support": 15
    },
    {
      "x": 2,
      "y": 10,
      "z": -8,
      "name": "Wood_Birch_Branch_Long",
      "support": 15,
      "rotation": 5
    },
    {
      "x": 2,
      "y": 11,
      "z": -8,
      "name": "Plant_Leaves_Aspen",
      "support": 15
    },
    {
      "x": 2,
      "y": 12,
      "z": -8,
      "name": "Plant_Leaves_Aspen",
      "support": 15
    },
    {
      "x": 2,
      "y": 14,
      "z": -8,
      "name": "Plant_Leaves_Aspen",
      "support": 15
    },
    {
      "x": 2,
      "y": 11,
      "z": -7,
      "name": "Plant_Leaves_Aspen",
      "support": 15
    },
    {
      "x": 2,
      "y": 12,
      "z": -7,
      "name": "Plant_Leaves_Aspen",
      "support": 15
    },
    {
      "x": 2,
      "y": 14,
      "z": -7,
      "name": "Plant_Leaves_Aspen",
      "support": 15
    },
    {
      "x": 2,
      "y": 14,
      "z": -6,
      "name": "Plant_Leaves_Aspen",
      "support": 15
    },
    {
      "x": 2,
      "y": 7,
      "z": -5,
      "name": "Wood_Birch_Trunk_Full",
      "support": 15,
      "rotation": 5
    },
    {
      "x": 2,
      "y": 8,
      "z": -5,
      "name": "Plant_Leaves_Aspen",
      "support": 15
    },
    {
      "x": 2,
      "y": 8,
      "z": -4,
      "name": "Plant_Leaves_Aspen",
      "support": 15
    },
    {
      "x": 2,
      "y": 6,
      "z": 3,
      "name": "Wood_Birch_Trunk",
      "support": 15,
      "rotation": 5
    },
    {
      "x": 2,
      "y": 3,
      "z": 5,
      "name": "Wood_Birch_Branch_Corner",
      "support": 15,
      "rotation": 2
    },
    {
      "x": 2,
      "y": 4,
      "z": 5,
      "name": "Wood_Birch_Branch_Corner",
      "support": 15,
      "rotation": 11
    },
    {
      "x": 2,
      "y": 3,
      "z": 6,
      "name": "Wood_Birch_Branch_Long",
      "support": 15,
      "rotation": 4
    },
    {
      "x": 2,
      "y": 3,
      "z": 7,
      "name": "Wood_Birch_Branch_Long",
      "support": 15,
      "rotation": 4
    },
    {
      "x": 2,
      "y": 6,
      "z": 7,
      "name": "Wood_Birch_Trunk_Full",
      "support": 15,
      "rotation": 5
    },
    {
      "x": 2,
      "y": 3,
      "z": 8,
      "name": "Wood_Birch_Branch_Long",
      "support": 15,
      "rotation": 4
    },
    {
      "x": 2,
      "y": 1,
      "z": 9,
      "name": "Wood_Birch_Branch_Corner",
      "support": 15,
      "rotation": 2
    },
    {
      "x": 2,
      "y": 2,
      "z": 9,
      "name": "Wood_Birch_Branch_Long",
      "support": 15
    },
    {
      "x": 2,
      "y": 3,
      "z": 9,
      "name": "Wood_Birch_Branch_Corner",
      "support": 15,
      "rotation": 10
    },
    {
      "x": 3,
      "y": 11,
      "z": -11,
      "name": "Plant_Leaves_Aspen",
      "support": 15
    },
    {
      "x": 3,
      "y": 11,
      "z": -10,
      "name": "Plant_Leaves_Aspen",
      "support": 15
    },
    {
      "x": 3,
      "y": 11,
      "z": -9,
      "name": "Plant_Leaves_Aspen",
      "support": 15
    },
    {
      "x": 3,
      "y": 12,
      "z": -9,
      "name": "Plant_Leaves_Aspen",
      "support": 15
    },
    {
      "x": 3,
      "y": 14,
      "z": -9,
      "name": "Plant_Leaves_Aspen",
      "support": 15
    },
    {
      "x": 3,
      "y": 10,
      "z": -8,
      "name": "Wood_Birch_Branch_Corner",
      "support": 15,
      "rotation": 1
    },
    {
      "x": 3,
      "y": 11,
      "z": -8,
      "name": "Wood_Birch_Branch_Long",
      "support": 15
    },
    {
      "x": 3,
      "y": 12,
      "z": -8,
      "name": "Plant_Leaves_Aspen",
      "support": 15
    },
    {
      "x": 3,
      "y": 14,
      "z": -8,
      "name": "Plant_Leaves_Aspen",
      "support": 15
    },
    {
      "x": 3,
      "y": 11,
      "z": -7,
      "name": "Plant_Leaves_Aspen",
      "support": 15
    },
    {
      "x": 3,
      "y": 12,
      "z": -7,
      "name": "Plant_Leaves_Aspen",
      "support": 15
    },
    {
      "x": 3,
      "y": 8,
      "z": -6,
      "name": "Plant_Leaves_Aspen",
      "support": 15
    },
    {
      "x": 3,
      "y": 7,
      "z": -5,
      "name": "Wood_Birch_Branch_Long",
      "support": 15,
      "rotation": 5
    },
    {
      "x": 3,
      "y": 8,
      "z": -5,
      "name": "Plant_Leaves_Aspen",
      "support": 15
    },
    {
      "x": 3,
      "y": 9,
      "z": -5,
      "name": "Plant_Leaves_Aspen",
      "support": 15
    },
    {
      "x": 3,
      "y": 8,
      "z": -4,
      "name": "Plant_Leaves_Aspen",
      "support": 15
    },
    {
      "x": 3,
      "y": 8,
      "z": -3,
      "name": "Plant_Leaves_Aspen",
      "support": 15
    },
    {
      "x": 3,
      "y": 6,
      "z": 3,
      "name": "Wood_Birch_Trunk_Full",
      "support": 15,
      "rotation": 5
    },
    {
      "x": 3,
      "y": 6,
      "z": 4,
      "name": "Wood_Birch_Trunk",
      "support": 15,
      "rotation": 4
    },
    {
      "x": 3,
      "y": 6,
      "z": 5,
      "name": "Wood_Birch_Trunk_Full",
      "support": 15,
      "rotation": 4
    },
    {
      "x": 3,
      "y": 6,
      "z": 6,
      "name": "Wood_Birch_Trunk",
      "support": 15,
      "rotation": 4
    },
    {
      "x": 3,
      "y": 6,
      "z": 7,
      "name": "Wood_Birch_Trunk_Full",
      "support": 15,
      "rotation": 4
    },
    {
      "x": 4,
      "y": 11,
      "z": -10,
      "name": "Plant_Leaves_Aspen",
      "support": 15
    },
    {
      "x": 4,
      "y": 11,
      "z": -9,
      "name": "Plant_Leaves_Aspen",
      "support": 15
    },
    {
      "x": 4,
      "y": 12,
      "z": -9,
      "name": "Plant_Leaves_Aspen",
      "support": 15
    },
    {
      "x": 4,
      "y": 11,
      "z": -8,
      "name": "Plant_Leaves_Aspen",
      "support": 15
    },
    {
      "x": 4,
      "y": 12,
      "z": -8,
      "name": "Plant_Leaves_Aspen",
      "support": 15
    },
    {
      "x": 4,
      "y": 11,
      "z": -7,
      "name": "Plant_Leaves_Aspen",
      "support": 15
    },
    {
      "x": 4,
      "y": 8,
      "z": -6,
      "name": "Plant_Leaves_Aspen",
      "support": 15
    },
    {
      "x": 4,
      "y": 7,
      "z": -5,
      "name": "Wood_Birch_Branch_Corner",
      "support": 15,
      "rotation": 1
    },
    {
      "x": 4,
      "y": 8,
      "z": -5,
      "name": "Wood_Birch_Branch_Long",
      "support": 15
    },
    {
      "x": 4,
      "y": 9,
      "z": -5,
      "name": "Plant_Leaves_Aspen",
      "support": 15
    },
    {
      "x": 4,
      "y": 8,
      "z": -4,
      "name": "Plant_Leaves_Aspen",
      "support": 15
    },
    {
      "x": 4,
      "y": 9,
      "z": -4,
      "name": "Plant_Leaves_Aspen",
      "support": 15
    },
    {
      "x": 4,
      "y": 8,
      "z": -3,
      "name": "Plant_Leaves_Aspen",
      "support": 15
    },
    {
      "x": 5,
      "y": 11,
      "z": -10,
      "name": "Plant_Leaves_Aspen",
      "support": 15
    },
    {
      "x": 5,
      "y": 11,
      "z": -9,
      "name": "Plant_Leaves_Aspen",
      "support": 15
    },
    {
      "x": 5,
      "y": 11,
      "z": -8,
      "name": "Plant_Leaves_Aspen",
      "support": 15
    },
    {
      "x": 5,
      "y": 11,
      "z": -7,
      "name": "Plant_Leaves_Aspen",
      "support": 15
    },
    {
      "x": 5,
      "y": 8,
      "z": -6,
      "name": "Plant_Leaves_Aspen",
      "support": 15
    },
    {
      "x": 5,
      "y": 8,
      "z": -5,
      "name": "Plant_Leaves_Aspen",
      "support": 15
    },
    {
      "x": 5,
      "y": 9,
      "z": -5,
      "name": "Plant_Leaves_Aspen",
      "support": 15
    },
    {
      "x": 5,
      "y": 8,
      "z": -4,
      "name": "Plant_Leaves_Aspen",
      "support": 15
    },
    {
      "x": 5,
      "y": 8,
      "z": -3,
      "name": "Plant_Leaves_Aspen",
      "support": 15
    },
    {
      "x": 6,
      "y": 11,
      "z": -10,
      "name": "Plant_Leaves_Aspen",
      "support": 15
    },
    {
      "x": 6,
      "y": 11,
      "z": -9,
      "name": "Plant_Leaves_Aspen",
      "support": 15
    },
    {
      "x": 6,
      "y": 8,
      "z": -6,
      "name": "Plant_Leaves_Aspen",
      "support": 15
    },
    {
      "x": 6,
      "y": 8,
      "z": -5,
      "name": "Plant_Leaves_Aspen",
      "support": 15
    },
    {
      "x": 6,
      "y": 8,
      "z": -4,
      "name": "Plant_Leaves_Aspen",
      "support": 15
    },
    {
      "x": 6,
      "y": 8,
      "z": -3,
      "name": "Plant_Leaves_Aspen",
      "support": 15
    },
    {
      "x": 7,
      "y": 8,
      "z": -5,
      "name": "Plant_Leaves_Aspen",
      "support": 15
    },
    {
      "x": 7,
      "y": 8,
      "z": -4,
      "name": "Plant_Leaves_Aspen",
      "support": 15
    }
  ]
}