{
  "version": 8,
  "blockIdVersion": 11,
  "anchorX": 0,
  "anchorY": 14,
  "anchorZ": 0,
  "blocks": [
    {
      "x": -14,
      "y": 13,
      "z": -9,
      "name": "Plant_Large_Lilypad"
    },
    {
      "x": -14,
      "y": 14,
      "z": -9,
      "name": "Plant_Large_Lilypad_Half"
    },
    {
      "x": -14,
      "y": 13,
      "z": -8,
      "name": "Plant_Large_Lilypad"
    },
    {
      "x": -14,
      "y": 14,
      "z": -8,
      "name": "Plant_Large_Lilypad_Half"
    },
    {
      "x": -14,
      "y": 13,
      "z": -7,
      "name": "Plant_Large_Lilypad"
    },
    {
      "x": -14,
      "y": 14,
      "z": -7,
      "name": "Plant_Large_Lilypad_Half"
    },
    {
      "x": -14,
      "y": 16,
      "z": -1,
      "name": "Plant_Large_Lilypad_Half"
    },
    {
      "x": -14,
      "y": 16,
      "z": 0,
      "name": "Plant_Large_Lilypad_Half"
    },
    {
      "x": -13,
      "y": 13,
      "z": -11,
      "name": "Plant_Large_Lilypad"
    },
    {
      "x": -13,
      "y": 14,
      "z": -11,
      "name": "Plant_Large_Lilypad_Half"
    },
    {
      "x": -13,
      "y": 13,
      "z": -10,
      "name": "Plant_Large_Lilypad"
    },
    {
      "x": -13,
      "y": 14,
      "z": -10,
      "name": "Plant_Large_Lilypad_Half"
    },
    {
      "x": -13,
      "y": 13,
      "z": -9,
      "name": "Plant_Large_Lilypad"
    },
    {
      "x": -13,
      "y": 14,
      "z": -9,
      "name": "Empty"
    },
    {
      "x": -13,
      "y": 13,
      "z": -8,
      "name": "Plant_Large_Lilypad"
    },
    {
      "x": -13,
      "y": 14,
      "z": -8,
      "name": "Empty"
    },
    {
      "x": -13,
      "y": 13,
      "z": -7,
      "name": "Plant_Large_Lilypad"
    },
    {
      "x": -13,
      "y": 14,
      "z": -7,
      "name": "Empty"
    },
    {
      "x": -13,
      "y": 13,
      "z": -6,
      "name": "Plant_Large_Lilypad"
    },
    {
      "x": -13,
      "y": 14,
      "z": -6,
      "name": "Plant_Large_Lilypad_Half"
    },
    {
      "x": -13,
      "y": 13,
      "z": -5,
      "name": "Plant_Large_Lilypad"
    },
    {
      "x": -13,
      "y": 14,
      "z": -5,
      "name": "Plant_Large_Lilypad_Half"
    },
    {
      "x": -13,
      "y": 16,
      "z": -2,
      "name": "Plant_Large_Lilypad_Half"
    },
    {
      "x": -13,
      "y": 16,
      "z": -1,
      "name": "Plant_Large_Lilypad_Half"
    },
    {
      "x": -13,
      "y": 16,
      "z": 0,
      "name": "Plant_Large_Lilypad_Half"
    },
    {
      "x": -13,
      "y": 16,
      "z": 1,
      "name": "Plant_Large_Lilypad_Half"
    },
    {
      "x": -12,
      "y": 13,
      "z": -12,
      "name": "Plant_Large_Lilypad"
    },
    {
      "x": -12,
      "y": 14,
      "z": -12,
      "name": "Plant_Large_Lilypad_Half"
    },
    {
      "x": -12,
      "y": 13,
      "z": -11,
      "name": "Plant_Large_Lilypad"
    },
    {
      "x": -12,
      "y": 14,
      "z": -11,
      "name": "Empty"
    },
    {
      "x": -12,
      "y": 13,
      "z": -10,
      "name": "Plant_Large_Lilypad"
    },
    {
      "x": -12,
      "y": 14,
      "z": -10,
      "name": "Empty"
    },
    {
      "x": -12,
      "y": 13,
      "z": -9,
      "name": "Plant_Large_Lilypad"
    },
    {
      "x": -12,
      "y": 14,
      "z": -9,
      "name": "Empty"
    },
    {
      "x": -12,
      "y": 13,
      "z": -8,
      "name": "Plant_Large_Lilypad"
    },
    {
      "x": -12,
      "y": 14,
      "z": -8,
      "name": "Empty"
    },
    {
      "x": -12,
      "y": 13,
      "z": -7,
      "name": "Plant_Large_Lilypad"
    },
    {
      "x": -12,
      "y": 14,
      "z": -7,
      "name": "Empty"
    },
    {
      "x": -12,
      "y": 13,
      "z": -6,
      "name": "Plant_Large_Lilypad"
    },
    {
      "x": -12,
      "y": 14,
      "z": -6,
      "name": "Empty"
    },
    {
      "x": -12,
      "y": 13,
      "z": -5,
      "name": "Plant_Large_Lilypad"
    },
    {
      "x": -12,
      "y": 14,
      "z": -5,
      "name": "Empty"
    },
    {
      "x": -12,
      "y": 13,
      "z": -4,
      "name": "Plant_Large_Lilypad"
    },
    {
      "x": -12,
      "y": 14,
      "z": -4,
      "name": "Plant_Large_Lilypad_Half"
    },
    {
      "x": -12,
      "y": 16,
      "z": -2,
      "name": "Plant_Large_Lilypad_Half"
    },
    {
      "x": -12,
      "y": 13,
      "z": -1,
      "name": "Wood_Banyan_Branch_Corner",
      "support": 15,
      "rotation": 3
    },
    {
      "x": -12,
      "y": 14,
      "z": -1,
      "name": "Wood_Banyan_Branch_Long",
      "support": 15
    },
    {
      "x": -12,
      "y": 15,
      "z": -1,
      "name": "Wood_Banyan_Branch_Long",
      "support": 15
    },
    {
      "x": -12,
      "y": 16,
      "z": -1,
      "name": "Plant_Large_Lilypad_Half"
    },
    {
      "x": -12,
      "y": 16,
      "z": 0,
      "name": "Plant_Large_Lilypad_Half"
    },
    {
      "x": -12,
      "y": 16,
      "z": 1,
      "name": "Plant_Large_Lilypad_Half"
    },
    {
      "x": -11,
      "y": 13,
      "z": -12,
      "name": "Plant_Large_Lilypad"
    },
    {
      "x": -11,
      "y": 14,
      "z": -12,
      "name": "Plant_Large_Lilypad_Half"
    },
    {
      "x": -11,
      "y": 13,
      "z": -11,
      "name": "Plant_Large_Lilypad"
    },
    {
      "x": -11,
      "y": 14,
      "z": -11,
      "name": "Plant_Grass_Sharp_Short",
      "support": 15
    },
    {
      "x": -11,
      "y": 12,
      "z": -10,
      "name": "Wood_Banyan_Roots"
    },
    {
      "x": -11,
      "y": 13,
      "z": -10,
      "name": "Plant_Large_Lilypad"
    },
    {
      "x": -11,
      "y": 14,
      "z": -10,
      "name": "Empty"
    },
    {
      "x": -11,
      "y": 13,
      "z": -9,
      "name": "Plant_Large_Lilypad"
    },
    {
      "x": -11,
      "y": 14,
      "z": -9,
      "name": "Empty"
    },
    {
      "x": -11,
      "y": 13,
      "z": -8,
      "name": "Plant_Large_Lilypad"
    },
    {
      "x": -11,
      "y": 14,
      "z": -8,
      "name": "Empty"
    },
    {
      "x": -11,
      "y": 13,
      "z": -7,
      "name": "Plant_Large_Lilypad"
    },
    {
      "x": -11,
      "y": 14,
      "z": -7,
      "name": "Empty"
    },
    {
      "x": -11,
      "y": 13,
      "z": -6,
      "name": "Plant_Large_Lilypad"
    },
    {
      "x": -11,
      "y": 14,
      "z": -6,
      "name": "Empty"
    },
    {
      "x": -11,
      "y": 13,
      "z": -5,
      "name": "Plant_Large_Lilypad"
    },
    {
      "x": -11,
      "y": 14,
      "z": -5,
      "name": "Empty"
    },
    {
      "x": -11,
      "y": 13,
      "z": -4,
      "name": "Plant_Large_Lilypad"
    },
    {
      "x": -11,
      "y": 14,
      "z": -4,
      "name": "Plant_Large_Lilypad_Half"
    },
    {
      "x": -11,
      "y": 13,
      "z": -1,
      "name": "Wood_Banyan_Branch_Long",
      "support": 15,
      "rotation": 5
    },
    {
      "x": -11,
      "y": 16,
      "z": -1,
      "name": "Plant_Large_Lilypad_Half"
    },
    {
      "x": -11,
      "y": 16,
      "z": 0,
      "name": "Plant_Large_Lilypad_Half"
    },
    {
      "x": -11,
      "y": 12,
      "z": 3,
      "name": "Plant_Large_Lilypad"
    },
    {
      "x": -11,
      "y": 13,
      "z": 3,
      "name": "Plant_Reeds_Arid",
      "support": 15
    },
    {
      "x": -11,
      "y": 14,
      "z": 3,
      "name": "Plant_Reeds_Arid",
      "filler": 1024
    },
    {
      "x": -11,
      "y": 12,
      "z": 4,
      "name": "Plant_Large_Lilypad"
    },
    {
      "x": -11,
      "y": 13,
      "z": 4,
      "name": "Plant_Reeds_Water",
      "support": 15
    },
    {
      "x": -11,
      "y": 14,
      "z": 4,
      "name": "Plant_Reeds_Water",
      "filler": 1024
    },
    {
      "x": -10,
      "y": 13,
      "z": -13,
      "name": "Plant_Large_Lilypad"
    },
    {
      "x": -10,
      "y": 14,
      "z": -13,
      "name": "Plant_Large_Lilypad_Half"
    },
    {
      "x": -10,
      "y": 13,
      "z": -12,
      "name": "Plant_Large_Lilypad"
    },
    {
      "x": -10,
      "y": 14,
      "z": -12,
      "name": "Plant_Grass_Sharp_Tall",
      "support": 15
    },
    {
      "x": -10,
      "y": 15,
      "z": -12,
      "name": "Plant_Grass_Sharp_Tall",
      "filler": 1024
    },
    {
      "x": -10,
      "y": 13,
      "z": -11,
      "name": "Plant_Large_Lilypad"
    },
    {
      "x": -10,
      "y": 14,
      "z": -11,
      "name": "Empty"
    },
    {
      "x": -10,
      "y": 13,
      "z": -10,
      "name": "Plant_Large_Lilypad"
    },
    {
      "x": -10,
      "y": 14,
      "z": -10,
      "name": "Empty"
    },
    {
      "x": -10,
      "y": 13,
      "z": -9,
      "name": "Plant_Large_Lilypad"
    },
    {
      "x": -10,
      "y": 14,
      "z": -9,
      "name": "Empty"
    },
    {
      "x": -10,
      "y": 12,
      "z": -8,
      "name": "Wood_Banyan_Roots"
    },
    {
      "x": -10,
      "y": 13,
      "z": -8,
      "name": "Plant_Large_Lilypad"
    },
    {
      "x": -10,
      "y": 14,
      "z": -8,
      "name": "Empty"
    },
    {
      "x": -10,
      "y": 13,
      "z": -7,
      "name": "Plant_Large_Lilypad"
    },
    {
      "x": -10,
      "y": 14,
      "z": -7,
      "name": "Empty"
    },
    {
      "x": -10,
      "y": 13,
      "z": -6,
      "name": "Plant_Large_Lilypad"
    },
    {
      "x": -10,
      "y": 14,
      "z": -6,
      "name": "Empty"
    },
    {
      "x": -10,
      "y": 13,
      "z": -5,
      "name": "Plant_Large_Lilypad"
    },
    {
      "x": -10,
      "y": 14,
      "z": -5,
      "name": "Empty"
    },
    {
      "x": -10,
      "y": 13,
      "z": -4,
      "name": "Plant_Large_Lilypad"
    },
    {
      "x": -10,
      "y": 14,
      "z": -4,
      "name": "Empty"
    },
    {
      "x": -10,
      "y": 13,
      "z": -3,
      "name": "Plant_Large_Lilypad"
    },
    {
      "x": -10,
      "y": 14,
      "z": -3,
      "name": "Plant_Large_Lilypad_Half"
    },
    {
      "x": -10,
      "y": 13,
      "z": -1,
      "name": "Wood_Banyan_Branch_Long",
      "support": 15,
      "rotation": 5
    },
    {
      "x": -10,
      "y": 18,
      "z": 0,
      "name": "Plant_Large_Lilypad_Half"
    },
    {
      "x": -10,
      "y": 18,
      "z": 1,
      "name": "Plant_Large_Lilypad_Half"
    },
    {
      "x": -10,
      "y": 12,
      "z": 2,
      "name": "Plant_Large_Lilypad"
    },
    {
      "x": -10,
      "y": 13,
      "z": 2,
      "name": "Plant_Reeds_Arid",
      "support": 15
    },
    {
      "x": -10,
      "y": 14,
      "z": 2,
      "name": "Plant_Reeds_Arid",
      "filler": 1024
    },
    {
      "x": -10,
      "y": 18,
      "z": 2,
      "name": "Plant_Large_Lilypad_Half"
    },
    {
      "x": -10,
      "y": 11,
      "z": 3,
      "name": "Wood_Banyan_Roots"
    },
    {
      "x": -10,
      "y": 12,
      "z": 3,
      "name": "Plant_Large_Lilypad"
    },
    {
      "x": -10,
      "y": 13,
      "z": 3,
      "name": "Plant_Reeds_Water",
      "support": 15
    },
    {
      "x": -10,
      "y": 14,
      "z": 3,
      "name": "Plant_Reeds_Water",
      "filler": 1024
    },
    {
      "x": -10,
      "y": 12,
      "z": 4,
      "name": "Plant_Large_Lilypad"
    },
    {
      "x": -10,
      "y": 12,
      "z": 5,
      "name": "Plant_Large_Lilypad"
    },
    {
      "x": -10,
      "y": 14,
      "z": 7,
      "name": "Wood_Banyan_Branch_Corner",
      "support": 15,
      "rotation": 2
    },
    {
      "x": -10,
      "y": 15,
      "z": 7,
      "name": "Wood_Banyan_Branch_Long",
      "support": 15
    },
    {
      "x": -10,
      "y": 16,
      "z": 7,
      "name": "Plant_Flower_Lotus_Yellow",
      "support": 15
    },
    {
      "x": -10,
      "y": 11,
      "z": 8,
      "name": "Wood_Banyan_Branch_Corner",
      "support": 15,
      "rotation": 3
    },
    {
      "x": -10,
      "y": 12,
      "z": 8,
      "name": "Wood_Banyan_Branch_Long",
      "support": 15
    },
    {
      "x": -10,
      "y": 13,
      "z": 8,
      "name": "Wood_Banyan_Branch_Long",
      "support": 15
    },
    {
      "x": -10,
      "y": 14,
      "z": 8,
      "name": "Wood_Banyan_Branch_Corner",
      "support": 15,
      "rotation": 10
    },
    {
      "x": -9,
      "y": 13,
      "z": -13,
      "name": "Plant_Large_Lilypad"
    },
    {
      "x": -9,
      "y": 14,
      "z": -13,
      "name": "Plant_Large_Lilypad_Half"
    },
    {
      "x": -9,
      "y": 13,
      "z": -12,
      "name": "Plant_Large_Lilypad"
    },
    {
      "x": -9,
      "y": 14,
      "z": -12,
      "name": "Empty"
    },
    {
      "x": -9,
      "y": 13,
      "z": -11,
      "name": "Plant_Large_Lilypad"
    },
    {
      "x": -9,
      "y": 14,
      "z": -11,
      "name": "Empty"
    },
    {
      "x": -9,
      "y": 13,
      "z": -10,
      "name": "Plant_Large_Lilypad"
    },
    {
      "x": -9,
      "y": 14,
      "z": -10,
      "name": "Empty"
    },
    {
      "x": -9,
      "y": 12,
      "z": -9,
      "name": "Wood_Banyan_Roots"
    },
    {
      "x": -9,
      "y": 13,
      "z": -9,
      "name": "Plant_Large_Lilypad"
    },
    {
      "x": -9,
      "y": 14,
      "z": -9,
      "name": "Empty"
    },
    {
      "x": -9,
      "y": 9,
      "z": -8,
      "name": "Wood_Banyan_Trunk_Full",
      "support": 15
    },
    {
      "x": -9,
      "y": 10,
      "z": -8,
      "name": "Wood_Banyan_Trunk",
      "support": 15
    },
    {
      "x": -9,
      "y": 11,
      "z": -8,
      "name": "Wood_Banyan_Trunk",
      "support": 15
    },
    {
      "x": -9,
      "y": 12,
      "z": -8,
      "name": "Wood_Banyan_Trunk",
      "support": 15
    },
    {
      "x": -9,
      "y": 13,
      "z": -8,
      "name": "Plant_Large_Lilypad"
    },
    {
      "x": -9,
      "y": 14,
      "z": -8,
      "name": "Empty"
    },
    {
      "x": -9,
      "y": 9,
      "z": -7,
      "name": "Wood_Banyan_Trunk_Full",
      "support": 15,
      "rotation": 4
    },
    {
      "x": -9,
      "y": 12,
      "z": -7,
      "name": "Wood_Banyan_Roots"
    },
    {
      "x": -9,
      "y": 13,
      "z": -7,
      "name": "Plant_Large_Lilypad"
    },
    {
      "x": -9,
      "y": 14,
      "z": -7,
      "name": "Empty"
    },
    {
      "x": -9,
      "y": 13,
      "z": -6,
      "name": "Plant_Large_Lilypad"
    },
    {
      "x": -9,
      "y": 14,
      "z": -6,
      "name": "Empty"
    },
    {
      "x": -9,
      "y": 13,
      "z": -5,
      "name": "Plant_Large_Lilypad"
    },
    {
      "x": -9,
      "y": 14,
      "z": -5,
      "name": "Empty"
    },
    {
      "x": -9,
      "y": 20,
      "z": -5,
      "name": "Plant_Large_Lilypad_Half"
    },
    {
      "x": -9,
      "y": 13,
      "z": -4,
      "name": "Plant_Large_Lilypad"
    },
    {
      "x": -9,
      "y": 14,
      "z": -4,
      "name": "Plant_Grass_Sharp_Tall",
      "support": 15
    },
    {
      "x": -9,
      "y": 15,
      "z": -4,
      "name": "Plant_Grass_Sharp_Tall",
      "filler": 1024
    },
    {
      "x": -9,
      "y": 20,
      "z": -4,
      "name": "Plant_Large_Lilypad_Half"
    },
    {
      "x": -9,
      "y": 13,
      "z": -3,
      "name": "Plant_Large_Lilypad"
    },
    {
      "x": -9,
      "y": 14,
      "z": -3,
      "name": "Plant_Large_Lilypad_Half"
    },
    {
      "x": -9,
      "y": 20,
      "z": -3,
      "name": "Plant_Large_Lilypad_Half"
    },
    {
      "x": -9,
      "y": 12,
      "z": -1,
      "name": "Wood_Banyan_Branch_Corner",
      "support": 15,
      "rotation": 3
    },
    {
      "x": -9,
      "y": 13,
      "z": -1,
      "name": "Wood_Banyan_Branch_Corner",
      "support": 15,
      "rotation": 11
    },
    {
      "x": -9,
      "y": 18,
      "z": 0,
      "name": "Plant_Large_Lilypad_Half"
    },
    {
      "x": -9,
      "y": 12,
      "z": 1,
      "name": "Wood_Banyan_Branch_Corner",
      "support": 15,
      "rotation": 3
    },
    {
      "x": -9,
      "y": 13,
      "z": 1,
      "name": "Wood_Banyan_Branch_Long",
      "support": 15
    },
    {
      "x": -9,
      "y": 14,
      "z": 1,
      "name": "Wood_Banyan_Branch_Long",
      "support": 15
    },
    {
      "x": -9,
      "y": 15,
      "z": 1,
      "name": "Wood_Banyan_Branch_Long",
      "support": 15
    },
    {
      "x": -9,
      "y": 16,
      "z": 1,
      "name": "Wood_Banyan_Branch_Long",
      "support": 15
    },
    {
      "x": -9,
      "y": 17,
      "z": 1,
      "name": "Wood_Banyan_Branch_Long",
      "support": 15
    },
    {
      "x": -9,
      "y": 18,
      "z": 1,
      "name": "Plant_Large_Lilypad_Half"
    },
    {
      "x": -9,
      "y": 12,
      "z": 2,
      "name": "Plant_Large_Lilypad"
    },
    {
      "x": -9,
      "y": 18,
      "z": 2,
      "name": "Plant_Large_Lilypad_Half"
    },
    {
      "x": -9,
      "y": 12,
      "z": 3,
      "name": "Plant_Large_Lilypad"
    },
    {
      "x": -9,
      "y": 13,
      "z": 3,
      "name": "Plant_Reeds_Water",
      "support": 15
    },
    {
      "x": -9,
      "y": 14,
      "z": 3,
      "name": "Plant_Reeds_Water",
      "filler": 1024
    },
    {
      "x": -9,
      "y": 10,
      "z": 4,
      "name": "Wood_Banyan_Branch_Corner",
      "support": 15,
      "rotation": 3
    },
    {
      "x": -9,
      "y": 11,
      "z": 4,
      "name": "Wood_Banyan_Branch_Long",
      "support": 15
    },
    {
      "x": -9,
      "y": 12,
      "z": 4,
      "name": "Plant_Large_Lilypad"
    },
    {
      "x": -9,
      "y": 12,
      "z": 5,
      "name": "Plant_Large_Lilypad"
    },
    {
      "x": -9,
      "y": 13,
      "z": 5,
      "name": "Plant_Reeds_Marsh",
      "support": 15
    },
    {
      "x": -9,
      "y": 10,
      "z": 8,
      "name": "Wood_Banyan_Branch_Corner",
      "support": 15,
      "rotation": 3
    },
    {
      "x": -9,
      "y": 11,
      "z": 8,
      "name": "Wood_Banyan_Branch_Corner",
      "support": 15,
      "rotation": 11
    },
    {
      "x": -8,
      "y": 13,
      "z": -13,
      "name": "Plant_Large_Lilypad"
    },
    {
      "x": -8,
      "y": 14,
      "z": -13,
      "name": "Plant_Large_Lilypad_Half"
    },
    {
      "x": -8,
      "y": 13,
      "z": -12,
      "name": "Plant_Large_Lilypad"
    },
    {
      "x": -8,
      "y": 14,
      "z": -12,
      "name": "Empty"
    },
    {
      "x": -8,
      "y": 13,
      "z": -11,
      "name": "Plant_Large_Lilypad"
    },
    {
      "x": -8,
      "y": 14,
      "z": -11,
      "name": "Empty"
    },
    {
      "x": -8,
      "y": 13,
      "z": -10,
      "name": "Plant_Large_Lilypad"
    },
    {
      "x": -8,
      "y": 14,
      "z": -10,
      "name": "Empty"
    },
    {
      "x": -8,
      "y": 13,
      "z": -9,
      "name": "Plant_Large_Lilypad"
    },
    {
      "x": -8,
      "y": 14,
      "z": -9,
      "name": "Empty"
    },
    {
      "x": -8,
      "y": 13,
      "z": -8,
      "name": "Plant_Large_Lilypad"
    },
    {
      "x": -8,
      "y": 14,
      "z": -8,
      "name": "Empty"
    },
    {
      "x": -8,
      "y": 9,
      "z": -7,
      "name": "Wood_Banyan_Trunk_Full",
      "support": 15,
      "rotation": 4
    },
    {
      "x": -8,
      "y": 13,
      "z": -7,
      "name": "Plant_Large_Lilypad"
    },
    {
      "x": -8,
      "y": 14,
      "z": -7,
      "name": "Empty"
    },
    {
      "x": -8,
      "y": 9,
      "z": -6,
      "name": "Wood_Banyan_Trunk_Full",
      "support": 15,
      "rotation": 4
    },
    {
      "x": -8,
      "y": 13,
      "z": -6,
      "name": "Plant_Large_Lilypad"
    },
    {
      "x": -8,
      "y": 14,
      "z": -6,
      "name": "Empty"
    },
    {
      "x": -8,
      "y": 20,
      "z": -6,
      "name": "Plant_Large_Lilypad_Half"
    },
    {
      "x": -8,
      "y": 13,
      "z": -5,
      "name": "Plant_Large_Lilypad"
    },
    {
      "x": -8,
      "y": 14,
      "z": -5,
      "name": "Plant_Grass_Sharp_Short",
      "support": 15
    },
    {
      "x": -8,
      "y": 20,
      "z": -5,
      "name": "Plant_Large_Lilypad_Half"
    },
    {
      "x": -8,
      "y": 13,
      "z": -4,
      "name": "Plant_Large_Lilypad"
    },
    {
      "x": -8,
      "y": 14,
      "z": -4,
      "name": "Plant_Grass_Sharp_Wild",
      "support": 15
    },
    {
      "x": -8,
      "y": 15,
      "z": -4,
      "name": "Plant_Grass_Sharp_Wild",
      "filler": 1024
    },
    {
      "x": -8,
      "y": 20,
      "z": -4,
      "name": "Plant_Large_Lilypad_Half"
    },
    {
      "x": -8,
      "y": 13,
      "z": -3,
      "name": "Plant_Large_Lilypad"
    },
    {
      "x": -8,
      "y": 14,
      "z": -3,
      "name": "Plant_Large_Lilypad_Half"
    },
    {
      "x": -8,
      "y": 20,
      "z": -3,
      "name": "Plant_Large_Lilypad_Half"
    },
    {
      "x": -8,
      "y": 20,
      "z": -2,
      "name": "Plant_Large_Lilypad_Half"
    },
    {
      "x": -8,
      "y": 12,
      "z": -1,
      "name": "Wood_Banyan_Branch_Long",
      "support": 15,
      "rotation": 5
    },
    {
      "x": -8,
      "y": 18,
      "z": 0,
      "name": "Plant_Large_Lilypad_Half"
    },
    {
      "x": -8,
      "y": 12,
      "z": 1,
      "name": "Wood_Banyan_Branch_Long",
      "support": 15,
      "rotation": 5
    },
    {
      "x": -8,
      "y": 18,
      "z": 1,
      "name": "Plant_Large_Lilypad_Half"
    },
    {
      "x": -8,
      "y": 18,
      "z": 2,
      "name": "Plant_Large_Lilypad_Half"
    },
    {
      "x": -8,
      "y": 20,
      "z": 2,
      "name": "Plant_Large_Lilypad",
      "rotation": 3
    },
    {
      "x": -8,
      "y": 21,
      "z": 2,
      "name": "Plant_Large_Lilypad_Half"
    },
    {
      "x": -8,
      "y": 12,
      "z": 3,
      "name": "Plant_Large_Lilypad"
    },
    {
      "x": -8,
      "y": 20,
      "z": 3,
      "name": "Plant_Large_Lilypad",
      "rotation": 3
    },
    {
      "x": -8,
      "y": 21,
      "z": 3,
      "name": "Plant_Large_Lilypad_Half"
    },
    {
      "x": -8,
      "y": 10,
      "z": 4,
      "name": "Wood_Banyan_Branch_Long",
      "support": 15,
      "rotation": 5
    },
    {
      "x": -8,
      "y": 12,
      "z": 4,
      "name": "Plant_Large_Lilypad"
    },
    {
      "x": -8,
      "y": 13,
      "z": 4,
      "name": "Plant_Reeds_Arid",
      "support": 15
    },
    {
      "x": -8,
      "y": 14,
      "z": 4,
      "name": "Plant_Reeds_Arid",
      "filler": 1024
    },
    {
      "x": -8,
      "y": 20,
      "z": 4,
      "name": "Plant_Large_Lilypad",
      "rotation": 3
    },
    {
      "x": -8,
      "y": 21,
      "z": 4,
      "name": "Plant_Large_Lilypad_Half"
    },
    {
      "x": -8,
      "y": 10,
      "z": 8,
      "name": "Wood_Banyan_Branch_Long",
      "support": 15,
      "rotation": 5
    },
    {
      "x": -8,
      "y": 13,
      "z": 9,
      "name": "Plant_Large_Lilypad"
    },
    {
      "x": -8,
      "y": 14,
      "z": 9,
      "name": "Plant_Large_Lilypad_Half"
    },
    {
      "x": -8,
      "y": 13,
      "z": 10,
      "name": "Plant_Large_Lilypad"
    },
    {
      "x": -8,
      "y": 14,
      "z": 10,
      "name": "Plant_Large_Lilypad_Half"
    },
    {
      "x": -8,
      "y": 13,
      "z": 11,
      "name": "Plant_Large_Lilypad"
    },
    {
      "x": -8,
      "y": 14,
      "z": 11,
      "name": "Plant_Large_Lilypad_Half"
    },
    {
      "x": -7,
      "y": 13,
      "z": -12,
      "name": "Plant_Large_Lilypad"
    },
    {
      "x": -7,
      "y": 14,
      "z": -12,
      "name": "Plant_Large_Lilypad_Half"
    },
    {
      "x": -7,
      "y": 13,
      "z": -11,
      "name": "Plant_Large_Lilypad"
    },
    {
      "x": -7,
      "y": 14,
      "z": -11,
      "name": "Plant_Grass_Sharp_Short",
      "support": 15
    },
    {
      "x": -7,
      "y": 12,
      "z": -10,
      "name": "Wood_Banyan_Roots"
    },
    {
      "x": -7,
      "y": 13,
      "z": -10,
      "name": "Plant_Large_Lilypad"
    },
    {
      "x": -7,
      "y": 14,
      "z": -10,
      "name": "Plant_Grass_Sharp_Short",
      "support": 15
    },
    {
      "x": -7,
      "y": 13,
      "z": -9,
      "name": "Plant_Large_Lilypad"
    },
    {
      "x": -7,
      "y": 14,
      "z": -9,
      "name": "Empty"
    },
    {
      "x": -7,
      "y": 12,
      "z": -8,
      "name": "Wood_Banyan_Roots"
    },
    {
      "x": -7,
      "y": 13,
      "z": -8,
      "name": "Plant_Large_Lilypad"
    },
    {
      "x": -7,
      "y": 14,
      "z": -8,
      "name": "Empty"
    },
    {
      "x": -7,
      "y": 13,
      "z": -7,
      "name": "Plant_Large_Lilypad"
    },
    {
      "x": -7,
      "y": 14,
      "z": -7,
      "name": "Empty"
    },
    {
      "x": -7,
      "y": 8,
      "z": -6,
      "name": "Wood_Banyan_Roots"
    },
    {
      "x": -7,
      "y": 9,
      "z": -6,
      "name": "Wood_Banyan_Trunk_Full",
      "support": 15,
      "rotation": 4
    },
    {
      "x": -7,
      "y": 13,
      "z": -6,
      "name": "Plant_Large_Lilypad"
    },
    {
      "x": -7,
      "y": 14,
      "z": -6,
      "name": "Empty"
    },
    {
      "x": -7,
      "y": 20,
      "z": -6,
      "name": "Plant_Large_Lilypad_Half"
    },
    {
      "x": -7,
      "y": 9,
      "z": -5,
      "name": "Wood_Banyan_Trunk",
      "support": 15,
      "rotation": 4
    },
    {
      "x": -7,
      "y": 13,
      "z": -5,
      "name": "Plant_Large_Lilypad"
    },
    {
      "x": -7,
      "y": 14,
      "z": -5,
      "name": "Plant_Grass_Sharp_Tall",
      "support": 15
    },
    {
      "x": -7,
      "y": 15,
      "z": -5,
      "name": "Plant_Grass_Sharp_Tall",
      "filler": 1024
    },
    {
      "x": -7,
      "y": 20,
      "z": -5,
      "name": "Plant_Large_Lilypad_Half"
    },
    {
      "x": -7,
      "y": 9,
      "z": -4,
      "name": "Wood_Banyan_Trunk",
      "support": 15,
      "rotation": 4
    },
    {
      "x": -7,
      "y": 13,
      "z": -4,
      "name": "Plant_Large_Lilypad"
    },
    {
      "x": -7,
      "y": 14,
      "z": -4,
      "name": "Plant_Large_Lilypad_Half"
    },
    {
      "x": -7,
      "y": 17,
      "z": -4,
      "name": "Wood_Banyan_Branch_Corner",
      "support": 15,
      "rotation": 3
    },
    {
      "x": -7,
      "y": 18,
      "z": -4,
      "name": "Wood_Banyan_Branch_Long",
      "support": 15
    },
    {
      "x": -7,
      "y": 19,
      "z": -4,
      "name": "Wood_Banyan_Branch_Long",
      "support": 15
    },
    {
      "x": -7,
      "y": 20,
      "z": -4,
      "name": "Plant_Large_Lilypad_Half"
    },
    {
      "x": -7,
      "y": 9,
      "z": -3,
      "name": "Wood_Banyan_Trunk_Full",
      "support": 15,
      "rotation": 5
    },
    {
      "x": -7,
      "y": 20,
      "z": -3,
      "name": "Plant_Large_Lilypad_Half"
    },
    {
      "x": -7,
      "y": 20,
      "z": -2,
      "name": "Plant_Large_Lilypad_Half"
    },
    {
      "x": -7,
      "y": 11,
      "z": -1,
      "name": "Wood_Banyan_Branch_Corner",
      "support": 15,
      "rotation": 3
    },
    {
      "x": -7,
      "y": 12,
      "z": -1,
      "name": "Wood_Banyan_Branch_Corner",
      "support": 15,
      "rotation": 11
    },
    {
      "x": -7,
      "y": 12,
      "z": 1,
      "name": "Wood_Banyan_Branch_Long",
      "support": 15,
      "rotation": 5
    },
    {
      "x": -7,
      "y": 20,
      "z": 1,
      "name": "Plant_Large_Lilypad",
      "rotation": 3
    },
    {
      "x": -7,
      "y": 21,
      "z": 1,
      "name": "Plant_Large_Lilypad_Half"
    },
    {
      "x": -7,
      "y": 20,
      "z": 2,
      "name": "Plant_Large_Lilypad",
      "rotation": 3
    },
    {
      "x": -7,
      "y": 21,
      "z": 2,
      "name": "Plant_Grass_Sharp_Short",
      "support": 15
    },
    {
      "x": -7,
      "y": 20,
      "z": 3,
      "name": "Plant_Large_Lilypad",
      "rotation": 3
    },
    {
      "x": -7,
      "y": 21,
      "z": 3,
      "name": "Empty"
    },
    {
      "x": -7,
      "y": 10,
      "z": 4,
      "name": "Wood_Banyan_Branch_Long",
      "support": 15,
      "rotation": 5
    },
    {
      "x": -7,
      "y": 20,
      "z": 4,
      "name": "Plant_Large_Lilypad",
      "rotation": 3
    },
    {
      "x": -7,
      "y": 21,
      "z": 4,
      "name": "Empty"
    },
    {
      "x": -7,
      "y": 20,
      "z": 5,
      "name": "Plant_Large_Lilypad",
      "rotation": 3
    },
    {
      "x": -7,
      "y": 21,
      "z": 5,
      "name": "Plant_Large_Lilypad_Half"
    },
    {
      "x": -7,
      "y": 13,
      "z": 7,
      "name": "Plant_Large_Lilypad"
    },
    {
      "x": -7,
      "y": 14,
      "z": 7,
      "name": "Plant_Large_Lilypad_Half"
    },
    {
      "x": -7,
      "y": 10,
      "z": 8,
      "name": "Wood_Banyan_Branch_Long",
      "support": 15,
      "rotation": 5
    },
    {
      "x": -7,
      "y": 13,
      "z": 8,
      "name": "Plant_Large_Lilypad"
    },
    {
      "x": -7,
      "y": 14,
      "z": 8,
      "name": "Plant_Large_Lilypad_Half"
    },
    {
      "x": -7,
      "y": 13,
      "z": 9,
      "name": "Plant_Large_Lilypad"
    },
    {
      "x": -7,
      "y": 14,
      "z": 9,
      "name": "Plant_Grass_Sharp_Wild",
      "support": 15
    },
    {
      "x": -7,
      "y": 15,
      "z": 9,
      "name": "Plant_Grass_Sharp_Wild",
      "filler": 1024
    },
    {
      "x": -7,
      "y": 13,
      "z": 10,
      "name": "Plant_Large_Lilypad"
    },
    {
      "x": -7,
      "y": 14,
      "z": 10,
      "name": "Plant_Grass_Sharp_Tall",
      "support": 15
    },
    {
      "x": -7,
      "y": 15,
      "z": 10,
      "name": "Plant_Grass_Sharp_Tall",
      "filler": 1024
    },
    {
      "x": -7,
      "y": 13,
      "z": 11,
      "name": "Plant_Large_Lilypad"
    },
    {
      "x": -7,
      "y": 14,
      "z": 11,
      "name": "Empty"
    },
    {
      "x": -7,
      "y": 13,
      "z": 12,
      "name": "Plant_Large_Lilypad"
    },
    {
      "x": -7,
      "y": 14,
      "z": 12,
      "name": "Plant_Large_Lilypad_Half"
    },
    {
      "x": -7,
      "y": 13,
      "z": 13,
      "name": "Plant_Large_Lilypad"
    },
    {
      "x": -7,
      "y": 14,
      "z": 13,
      "name": "Plant_Large_Lilypad_Half"
    },
    {
      "x": -6,
      "y": 13,
      "z": -12,
      "name": "Plant_Large_Lilypad"
    },
    {
      "x": -6,
      "y": 14,
      "z": -12,
      "name": "Plant_Large_Lilypad_Half"
    },
    {
      "x": -6,
      "y": 13,
      "z": -11,
      "name": "Plant_Large_Lilypad"
    },
    {
      "x": -6,
      "y": 14,
      "z": -11,
      "name": "Plant_Grass_Sharp_Short",
      "support": 15
    },
    {
      "x": -6,
      "y": 13,
      "z": -10,
      "name": "Plant_Large_Lilypad"
    },
    {
      "x": -6,
      "y": 14,
      "z": -10,
      "name": "Plant_Grass_Sharp_Tall",
      "support": 15
    },
    {
      "x": -6,
      "y": 15,
      "z": -10,
      "name": "Plant_Grass_Sharp_Tall",
      "filler": 1024
    },
    {
      "x": -6,
      "y": 13,
      "z": -9,
      "name": "Plant_Large_Lilypad"
    },
    {
      "x": -6,
      "y": 14,
      "z": -9,
      "name": "Plant_Grass_Sharp_Tall",
      "support": 15
    },
    {
      "x": -6,
      "y": 15,
      "z": -9,
      "name": "Plant_Grass_Sharp_Tall",
      "filler": 1024
    },
    {
      "x": -6,
      "y": 13,
      "z": -8,
      "name": "Plant_Large_Lilypad"
    },
    {
      "x": -6,
      "y": 14,
      "z": -8,
      "name": "Empty"
    },
    {
      "x": -6,
      "y": 13,
      "z": -7,
      "name": "Plant_Large_Lilypad"
    },
    {
      "x": -6,
      "y": 14,
      "z": -7,
      "name": "Empty"
    },
    {
      "x": -6,
      "y": 13,
      "z": -6,
      "name": "Plant_Large_Lilypad"
    },
    {
      "x": -6,
      "y": 14,
      "z": -6,
      "name": "Empty"
    },
    {
      "x": -6,
      "y": 20,
      "z": -6,
      "name": "Plant_Large_Lilypad_Half"
    },
    {
      "x": -6,
      "y": 13,
      "z": -5,
      "name": "Plant_Large_Lilypad"
    },
    {
      "x": -6,
      "y": 14,
      "z": -5,
      "name": "Empty"
    },
    {
      "x": -6,
      "y": 20,
      "z": -5,
      "name": "Plant_Large_Lilypad_Half"
    },
    {
      "x": -6,
      "y": 13,
      "z": -4,
      "name": "Plant_Large_Lilypad"
    },
    {
      "x": -6,
      "y": 14,
      "z": -4,
      "name": "Plant_Large_Lilypad_Half"
    },
    {
      "x": -6,
      "y": 17,
      "z": -4,
      "name": "Wood_Banyan_Branch_Long",
      "support": 15,
      "rotation": 5
    },
    {
      "x": -6,
      "y": 20,
      "z": -4,
      "name": "Plant_Large_Lilypad_Half"
    },
    {
      "x": -6,
      "y": 9,
      "z": -3,
      "name": "Wood_Banyan_Trunk_Full",
      "support": 15,
      "rotation": 4
    },
    {
      "x": -6,
      "y": 20,
      "z": -3,
      "name": "Plant_Large_Lilypad_Half"
    },
    {
      "x": -6,
      "y": 9,
      "z": -2,
      "name": "Wood_Banyan_Trunk_Full",
      "support": 15,
      "rotation": 5
    },
    {
      "x": -6,
      "y": 20,
      "z": -2,
      "name": "Plant_Large_Lilypad_Half"
    },
    {
      "x": -6,
      "y": 9,
      "z": -1,
      "name": "Wood_Banyan_Branch_Long",
      "support": 15,
      "rotation": 4
    },
    {
      "x": -6,
      "y": 11,
      "z": -1,
      "name": "Wood_Banyan_Branch_Long",
      "support": 15,
      "rotation": 5
    },
    {
      "x": -6,
      "y": 9,
      "z": 0,
      "name": "Wood_Banyan_Branch_Long",
      "support": 15,
      "rotation": 4
    },
    {
      "x": -6,
      "y": 20,
      "z": 0,
      "name": "Plant_Large_Lilypad",
      "rotation": 3
    },
    {
      "x": -6,
      "y": 21,
      "z": 0,
      "name": "Plant_Large_Lilypad_Half"
    },
    {
      "x": -6,
      "y": 9,
      "z": 1,
      "name": "Wood_Banyan_Branch_Long",
      "support": 15,
      "rotation": 4
    },
    {
      "x": -6,
      "y": 12,
      "z": 1,
      "name": "Wood_Banyan_Branch_Long",
      "support": 15,
      "rotation": 5
    },
    {
      "x": -6,
      "y": 20,
      "z": 1,
      "name": "Plant_Large_Lilypad",
      "rotation": 3
    },
    {
      "x": -6,
      "y": 21,
      "z": 1,
      "name": "Plant_Grass_Sharp_Tall",
      "support": 15
    },
    {
      "x": -6,
      "y": 22,
      "z": 1,
      "name": "Plant_Grass_Sharp_Tall",
      "filler": 1024
    },
    {
      "x": -6,
      "y": 9,
      "z": 2,
      "name": "Wood_Banyan_Branch_Long",
      "support": 15,
      "rotation": 4
    },
    {
      "x": -6,
      "y": 20,
      "z": 2,
      "name": "Plant_Large_Lilypad",
      "rotation": 3
    },
    {
      "x": -6,
      "y": 21,
      "z": 2,
      "name": "Empty"
    },
    {
      "x": -6,
      "y": 9,
      "z": 3,
      "name": "Wood_Banyan_Branch_Long",
      "support": 15,
      "rotation": 4
    },
    {
      "x": -6,
      "y": 20,
      "z": 3,
      "name": "Plant_Large_Lilypad",
      "rotation": 3
    },
    {
      "x": -6,
      "y": 21,
      "z": 3,
      "name": "Empty"
    },
    {
      "x": -6,
      "y": 9,
      "z": 4,
      "name": "Wood_Banyan_Branch_Corner",
      "support": 15
    },
    {
      "x": -6,
      "y": 10,
      "z": 4,
      "name": "Wood_Banyan_Branch_Corner",
      "support": 15,
      "rotation": 11
    },
    {
      "x": -6,
      "y": 19,
      "z": 4,
      "name": "Wood_Banyan_Roots"
    },
    {
      "x": -6,
      "y": 20,
      "z": 4,
      "name": "Plant_Large_Lilypad",
      "rotation": 3
    },
    {
      "x": -6,
      "y": 21,
      "z": 4,
      "name": "Empty"
    },
    {
      "x": -6,
      "y": 8,
      "z": 5,
      "name": "Wood_Banyan_Branch_Corner",
      "support": 15,
      "rotation": 3
    },
    {
      "x": -6,
      "y": 9,
      "z": 5,
      "name": "Wood_Banyan_Branch_Corner",
      "support": 15,
      "rotation": 8
    },
    {
      "x": -6,
      "y": 20,
      "z": 5,
      "name": "Plant_Large_Lilypad",
      "rotation": 3
    },
    {
      "x": -6,
      "y": 21,
      "z": 5,
      "name": "Empty"
    },
    {
      "x": -6,
      "y": 22,
      "z": 5,
      "name": "Empty"
    },
    {
      "x": -6,
      "y": 9,
      "z": 6,
      "name": "Wood_Banyan_Branch_Long",
      "support": 15,
      "rotation": 4
    },
    {
      "x": -6,
      "y": 13,
      "z": 6,
      "name": "Plant_Large_Lilypad"
    },
    {
      "x": -6,
      "y": 14,
      "z": 6,
      "name": "Plant_Large_Lilypad_Half"
    },
    {
      "x": -6,
      "y": 20,
      "z": 6,
      "name": "Plant_Large_Lilypad",
      "rotation": 3
    },
    {
      "x": -6,
      "y": 21,
      "z": 6,
      "name": "Plant_Large_Lilypad_Half"
    },
    {
      "x": -6,
      "y": 9,
      "z": 7,
      "name": "Wood_Banyan_Branch_Long",
      "support": 15,
      "rotation": 4
    },
    {
      "x": -6,
      "y": 13,
      "z": 7,
      "name": "Plant_Large_Lilypad"
    },
    {
      "x": -6,
      "y": 14,
      "z": 7,
      "name": "Plant_Grass_Sharp_Wild",
      "support": 15
    },
    {
      "x": -6,
      "y": 15,
      "z": 7,
      "name": "Plant_Grass_Sharp_Wild",
      "filler": 1024
    },
    {
      "x": -6,
      "y": 9,
      "z": 8,
      "name": "Wood_Banyan_Branch_Corner",
      "support": 15
    },
    {
      "x": -6,
      "y": 10,
      "z": 8,
      "name": "Wood_Banyan_Branch_Corner",
      "support": 15,
      "rotation": 11
    },
    {
      "x": -6,
      "y": 13,
      "z": 8,
      "name": "Plant_Large_Lilypad"
    },
    {
      "x": -6,
      "y": 14,
      "z": 8,
      "name": "Plant_Grass_Sharp_Tall",
      "support": 15
    },
    {
      "x": -6,
      "y": 15,
      "z": 8,
      "name": "Plant_Grass_Sharp_Tall",
      "filler": 1024
    },
    {
      "x": -6,
      "y": 13,
      "z": 9,
      "name": "Plant_Large_Lilypad"
    },
    {
      "x": -6,
      "y": 14,
      "z": 9,
      "name": "Plant_Grass_Sharp_Short",
      "support": 15
    },
    {
      "x": -6,
      "y": 13,
      "z": 10,
      "name": "Plant_Large_Lilypad"
    },
    {
      "x": -6,
      "y": 14,
      "z": 10,
      "name": "Empty"
    },
    {
      "x": -6,
      "y": 13,
      "z": 11,
      "name": "Plant_Large_Lilypad"
    },
    {
      "x": -6,
      "y": 14,
      "z": 11,
      "name": "Plant_Grass_Sharp_Short",
      "support": 15
    },
    {
      "x": -6,
      "y": 13,
      "z": 12,
      "name": "Plant_Large_Lilypad"
    },
    {
      "x": -6,
      "y": 14,
      "z": 12,
      "name": "Empty"
    },
    {
      "x": -6,
      "y": 13,
      "z": 13,
      "name": "Plant_Large_Lilypad"
    },
    {
      "x": -6,
      "y": 14,
      "z": 13,
      "name": "Empty"
    },
    {
      "x": -6,
      "y": 13,
      "z": 14,
      "name": "Plant_Large_Lilypad"
    },
    {
      "x": -6,
      "y": 14,
      "z": 14,
      "name": "Plant_Large_Lilypad_Half"
    },
    {
      "x": -5,
      "y": 13,
      "z": -11,
      "name": "Plant_Large_Lilypad"
    },
    {
      "x": -5,
      "y": 14,
      "z": -11,
      "name": "Plant_Large_Lilypad_Half"
    },
    {
      "x": -5,
      "y": 13,
      "z": -10,
      "name": "Plant_Large_Lilypad"
    },
    {
      "x": -5,
      "y": 14,
      "z": -10,
      "name": "Plant_Large_Lilypad_Half"
    },
    {
      "x": -5,
      "y": 13,
      "z": -9,
      "name": "Plant_Large_Lilypad"
    },
    {
      "x": -5,
      "y": 14,
      "z": -9,
      "name": "Plant_Grass_Sharp_Tall",
      "support": 15
    },
    {
      "x": -5,
      "y": 15,
      "z": -9,
      "name": "Plant_Grass_Sharp_Tall",
      "filler": 1024
    },
    {
      "x": -5,
      "y": 13,
      "z": -8,
      "name": "Plant_Large_Lilypad"
    },
    {
      "x": -5,
      "y": 14,
      "z": -8,
      "name": "Empty"
    },
    {
      "x": -5,
      "y": 13,
      "z": -7,
      "name": "Plant_Large_Lilypad"
    },
    {
      "x": -5,
      "y": 14,
      "z": -7,
      "name": "Empty"
    },
    {
      "x": -5,
      "y": 13,
      "z": -6,
      "name": "Plant_Large_Lilypad"
    },
    {
      "x": -5,
      "y": 14,
      "z": -6,
      "name": "Plant_Large_Lilypad_Half"
    },
    {
      "x": -5,
      "y": 13,
      "z": -5,
      "name": "Plant_Large_Lilypad"
    },
    {
      "x": -5,
      "y": 14,
      "z": -5,
      "name": "Plant_Large_Lilypad_Half"
    },
    {
      "x": -5,
      "y": 20,
      "z": -5,
      "name": "Plant_Large_Lilypad_Half"
    },
    {
      "x": -5,
      "y": 16,
      "z": -4,
      "name": "Wood_Banyan_Branch_Corner",
      "support": 15,
      "rotation": 2
    },
    {
      "x": -5,
      "y": 17,
      "z": -4,
      "name": "Wood_Banyan_Branch_Corner",
      "support": 15,
      "rotation": 11
    },
    {
      "x": -5,
      "y": 20,
      "z": -4,
      "name": "Plant_Large_Lilypad_Half"
    },
    {
      "x": -5,
      "y": 16,
      "z": -3,
      "name": "Wood_Banyan_Branch_Long",
      "support": 15,
      "rotation": 4
    },
    {
      "x": -5,
      "y": 20,
      "z": -3,
      "name": "Plant_Large_Lilypad_Half"
    },
    {
      "x": -5,
      "y": 8,
      "z": -2,
      "name": "Wood_Banyan_Roots"
    },
    {
      "x": -5,
      "y": 9,
      "z": -2,
      "name": "Wood_Banyan_Trunk_Full",
      "support": 15,
      "rotation": 4
    },
    {
      "x": -5,
      "y": 13,
      "z": -2,
      "name": "Wood_Banyan_Branch_Corner",
      "support": 15,
      "rotation": 2
    },
    {
      "x": -5,
      "y": 14,
      "z": -2,
      "name": "Wood_Banyan_Branch_Long",
      "support": 15
    },
    {
      "x": -5,
      "y": 15,
      "z": -2,
      "name": "Wood_Banyan_Branch_Long",
      "support": 15
    },
    {
      "x": -5,
      "y": 16,
      "z": -2,
      "name": "Wood_Banyan_Branch_Corner",
      "support": 15,
      "rotation": 10
    },
    {
      "x": -5,
      "y": 9,
      "z": -1,
      "name": "Wood_Banyan_Trunk_Full",
      "support": 15,
      "rotation": 5
    },
    {
      "x": -5,
      "y": 10,
      "z": -1,
      "name": "Wood_Banyan_Branch_Long",
      "support": 15
    },
    {
      "x": -5,
      "y": 11,
      "z": -1,
      "name": "Wood_Banyan_Branch_Corner",
      "support": 15,
      "rotation": 11
    },
    {
      "x": -5,
      "y": 12,
      "z": -1,
      "name": "Wood_Banyan_Branch_Corner",
      "support": 15,
      "rotation": 2
    },
    {
      "x": -5,
      "y": 13,
      "z": -1,
      "name": "Wood_Banyan_Branch_Corner",
      "support": 15,
      "rotation": 10
    },
    {
      "x": -5,
      "y": 12,
      "z": 0,
      "name": "Wood_Banyan_Branch_Long",
      "support": 15,
      "rotation": 4
    },
    {
      "x": -5,
      "y": 20,
      "z": 0,
      "name": "Plant_Large_Lilypad",
      "rotation": 3
    },
    {
      "x": -5,
      "y": 21,
      "z": 0,
      "name": "Plant_Large_Lilypad_Half"
    },
    {
      "x": -5,
      "y": 12,
      "z": 1,
      "name": "Wood_Banyan_Trunk_Full",
      "support": 15,
      "rotation": 4
    },
    {
      "x": -5,
      "y": 20,
      "z": 1,
      "name": "Plant_Large_Lilypad",
      "rotation": 3
    },
    {
      "x": -5,
      "y": 21,
      "z": 1,
      "name": "Empty"
    },
    {
      "x": -5,
      "y": 12,
      "z": 2,
      "name": "Wood_Banyan_Trunk",
      "support": 15,
      "rotation": 4
    },
    {
      "x": -5,
      "y": 19,
      "z": 2,
      "name": "Wood_Banyan_Roots"
    },
    {
      "x": -5,
      "y": 20,
      "z": 2,
      "name": "Plant_Large_Lilypad",
      "rotation": 3
    },
    {
      "x": -5,
      "y": 21,
      "z": 2,
      "name": "Empty"
    },
    {
      "x": -5,
      "y": 12,
      "z": 3,
      "name": "Wood_Banyan_Trunk_Full",
      "support": 15
    },
    {
      "x": -5,
      "y": 13,
      "z": 3,
      "name": "Wood_Banyan_Trunk",
      "support": 15
    },
    {
      "x": -5,
      "y": 14,
      "z": 3,
      "name": "Wood_Banyan_Trunk",
      "support": 15
    },
    {
      "x": -5,
      "y": 15,
      "z": 3,
      "name": "Wood_Banyan_Trunk",
      "support": 15
    },
    {
      "x": -5,
      "y": 16,
      "z": 3,
      "name": "Wood_Banyan_Trunk",
      "support": 15
    },
    {
      "x": -5,
      "y": 17,
      "z": 3,
      "name": "Wood_Banyan_Trunk",
      "support": 15
    },
    {
      "x": -5,
      "y": 18,
      "z": 3,
      "name": "Wood_Banyan_Trunk",
      "support": 15
    },
    {
      "x": -5,
      "y": 19,
      "z": 3,
      "name": "Wood_Banyan_Trunk",
      "support": 15
    },
    {
      "x": -5,
      "y": 20,
      "z": 3,
      "name": "Plant_Large_Lilypad",
      "rotation": 3
    },
    {
      "x": -5,
      "y": 21,
      "z": 3,
      "name": "Empty"
    },
    {
      "x": -5,
      "y": 20,
      "z": 4,
      "name": "Plant_Large_Lilypad",
      "rotation": 3
    },
    {
      "x": -5,
      "y": 21,
      "z": 4,
      "name": "Empty"
    },
    {
      "x": -5,
      "y": 8,
      "z": 5,
      "name": "Wood_Banyan_Branch_Long",
      "support": 15,
      "rotation": 5
    },
    {
      "x": -5,
      "y": 20,
      "z": 5,
      "name": "Plant_Large_Lilypad",
      "rotation": 3
    },
    {
      "x": -5,
      "y": 21,
      "z": 5,
      "name": "Plant_Grass_Sharp_Short",
      "support": 15
    },
    {
      "x": -5,
      "y": 13,
      "z": 6,
      "name": "Plant_Large_Lilypad"
    },
    {
      "x": -5,
      "y": 14,
      "z": 6,
      "name": "Plant_Large_Lilypad_Half"
    },
    {
      "x": -5,
      "y": 20,
      "z": 6,
      "name": "Plant_Large_Lilypad",
      "rotation": 3
    },
    {
      "x": -5,
      "y": 21,
      "z": 6,
      "name": "Plant_Large_Lilypad_Half"
    },
    {
      "x": -5,
      "y": 13,
      "z": 7,
      "name": "Plant_Large_Lilypad"
    },
    {
      "x": -5,
      "y": 14,
      "z": 7,
      "name": "Plant_Grass_Sharp_Tall",
      "support": 15
    },
    {
      "x": -5,
      "y": 15,
      "z": 7,
      "name": "Plant_Grass_Sharp_Tall",
      "filler": 1024
    },
    {
      "x": -5,
      "y": 13,
      "z": 8,
      "name": "Plant_Large_Lilypad"
    },
    {
      "x": -5,
      "y": 14,
      "z": 8,
      "name": "Empty"
    },
    {
      "x": -5,
      "y": 13,
      "z": 9,
      "name": "Plant_Large_Lilypad"
    },
    {
      "x": -5,
      "y": 14,
      "z": 9,
      "name": "Empty"
    },
    {
      "x": -5,
      "y": 13,
      "z": 10,
      "name": "Plant_Large_Lilypad"
    },
    {
      "x": -5,
      "y": 14,
      "z": 10,
      "name": "Empty"
    },
    {
      "x": -5,
      "y": 13,
      "z": 11,
      "name": "Plant_Large_Lilypad"
    },
    {
      "x": -5,
      "y": 14,
      "z": 11,
      "name": "Empty"
    },
    {
      "x": -5,
      "y": 13,
      "z": 12,
      "name": "Plant_Large_Lilypad"
    },
    {
      "x": -5,
      "y": 14,
      "z": 12,
      "name": "Empty"
    },
    {
      "x": -5,
      "y": 13,
      "z": 13,
      "name": "Plant_Large_Lilypad"
    },
    {
      "x": -5,
      "y": 14,
      "z": 13,
      "name": "Empty"
    },
    {
      "x": -5,
      "y": 13,
      "z": 14,
      "name": "Plant_Large_Lilypad"
    },
    {
      "x": -5,
      "y": 14,
      "z": 14,
      "name": "Plant_Large_Lilypad_Half"
    },
    {
      "x": -4,
      "y": 15,
      "z": -14,
      "name": "Wood_Banyan_Branch_Corner",
      "support": 15,
      "rotation": 3
    },
    {
      "x": -4,
      "y": 16,
      "z": -14,
      "name": "Plant_Flower_Lotus_Yellow",
      "support": 15
    },
    {
      "x": -4,
      "y": 13,
      "z": -9,
      "name": "Plant_Large_Lilypad"
    },
    {
      "x": -4,
      "y": 14,
      "z": -9,
      "name": "Plant_Large_Lilypad_Half"
    },
    {
      "x": -4,
      "y": 17,
      "z": -9,
      "name": "Plant_Large_Lilypad"
    },
    {
      "x": -4,
      "y": 18,
      "z": -9,
      "name": "Plant_Large_Lilypad_Half"
    },
    {
      "x": -4,
      "y": 13,
      "z": -8,
      "name": "Plant_Large_Lilypad"
    },
    {
      "x": -4,
      "y": 14,
      "z": -8,
      "name": "Plant_Large_Lilypad_Half"
    },
    {
      "x": -4,
      "y": 17,
      "z": -8,
      "name": "Plant_Large_Lilypad"
    },
    {
      "x": -4,
      "y": 18,
      "z": -8,
      "name": "Plant_Large_Lilypad_Half"
    },
    {
      "x": -4,
      "y": 13,
      "z": -7,
      "name": "Plant_Large_Lilypad"
    },
    {
      "x": -4,
      "y": 14,
      "z": -7,
      "name": "Plant_Large_Lilypad_Half"
    },
    {
      "x": -4,
      "y": 17,
      "z": -7,
      "name": "Plant_Large_Lilypad"
    },
    {
      "x": -4,
      "y": 18,
      "z": -7,
      "name": "Plant_Large_Lilypad_Half"
    },
    {
      "x": -4,
      "y": 12,
      "z": -4,
      "name": "Plant_Large_Lilypad"
    },
    {
      "x": -4,
      "y": 12,
      "z": -3,
      "name": "Plant_Large_Lilypad"
    },
    {
      "x": -4,
      "y": 13,
      "z": -3,
      "name": "Plant_Reeds_Arid",
      "support": 15
    },
    {
      "x": -4,
      "y": 14,
      "z": -3,
      "name": "Plant_Reeds_Arid",
      "filler": 1024
    },
    {
      "x": -4,
      "y": 12,
      "z": -2,
      "name": "Plant_Large_Lilypad"
    },
    {
      "x": -4,
      "y": 9,
      "z": -1,
      "name": "Wood_Banyan_Trunk",
      "support": 15,
      "rotation": 5
    },
    {
      "x": -4,
      "y": 20,
      "z": 0,
      "name": "Plant_Large_Lilypad",
      "rotation": 3
    },
    {
      "x": -4,
      "y": 21,
      "z": 0,
      "name": "Plant_Large_Lilypad_Half"
    },
    {
      "x": -4,
      "y": 11,
      "z": 1,
      "name": "Wood_Banyan_Trunk_Full",
      "support": 15
    },
    {
      "x": -4,
      "y": 12,
      "z": 1,
      "name": "Wood_Banyan_Trunk_Full",
      "support": 15
    },
    {
      "x": -4,
      "y": 16,
      "z": 1,
      "name": "Plant_Large_Lilypad_Half"
    },
    {
      "x": -4,
      "y": 20,
      "z": 1,
      "name": "Plant_Large_Lilypad",
      "rotation": 3
    },
    {
      "x": -4,
      "y": 21,
      "z": 1,
      "name": "Empty"
    },
    {
      "x": -4,
      "y": 16,
      "z": 2,
      "name": "Plant_Large_Lilypad_Half"
    },
    {
      "x": -4,
      "y": 20,
      "z": 2,
      "name": "Plant_Large_Lilypad",
      "rotation": 3
    },
    {
      "x": -4,
      "y": 21,
      "z": 2,
      "name": "Empty"
    },
    {
      "x": -4,
      "y": 16,
      "z": 3,
      "name": "Plant_Large_Lilypad_Half"
    },
    {
      "x": -4,
      "y": 19,
      "z": 3,
      "name": "Wood_Banyan_Roots"
    },
    {
      "x": -4,
      "y": 20,
      "z": 3,
      "name": "Plant_Large_Lilypad",
      "rotation": 3
    },
    {
      "x": -4,
      "y": 21,
      "z": 3,
      "name": "Empty"
    },
    {
      "x": -4,
      "y": 20,
      "z": 4,
      "name": "Plant_Large_Lilypad",
      "rotation": 3
    },
    {
      "x": -4,
      "y": 21,
      "z": 4,
      "name": "Plant_Grass_Sharp_Short",
      "support": 15
    },
    {
      "x": -4,
      "y": 8,
      "z": 5,
      "name": "Wood_Banyan_Branch_Long",
      "support": 15,
      "rotation": 5
    },
    {
      "x": -4,
      "y": 13,
      "z": 5,
      "name": "Plant_Large_Lilypad"
    },
    {
      "x": -4,
      "y": 14,
      "z": 5,
      "name": "Plant_Large_Lilypad_Half"
    },
    {
      "x": -4,
      "y": 20,
      "z": 5,
      "name": "Plant_Large_Lilypad",
      "rotation": 3
    },
    {
      "x": -4,
      "y": 21,
      "z": 5,
      "name": "Plant_Grass_Sharp_Tall",
      "support": 15
    },
    {
      "x": -4,
      "y": 22,
      "z": 5,
      "name": "Plant_Grass_Sharp_Tall",
      "filler": 1024
    },
    {
      "x": -4,
      "y": 13,
      "z": 6,
      "name": "Plant_Large_Lilypad"
    },
    {
      "x": -4,
      "y": 14,
      "z": 6,
      "name": "Empty"
    },
    {
      "x": -4,
      "y": 20,
      "z": 6,
      "name": "Plant_Large_Lilypad",
      "rotation": 3
    },
    {
      "x": -4,
      "y": 21,
      "z": 6,
      "name": "Plant_Large_Lilypad_Half"
    },
    {
      "x": -4,
      "y": 13,
      "z": 7,
      "name": "Plant_Large_Lilypad"
    },
    {
      "x": -4,
      "y": 14,
      "z": 7,
      "name": "Empty"
    },
    {
      "x": -4,
      "y": 13,
      "z": 8,
      "name": "Plant_Large_Lilypad"
    },
    {
      "x": -4,
      "y": 14,
      "z": 8,
      "name": "Empty"
    },
    {
      "x": -4,
      "y": 13,
      "z": 9,
      "name": "Plant_Large_Lilypad"
    },
    {
      "x": -4,
      "y": 14,
      "z": 9,
      "name": "Empty"
    },
    {
      "x": -4,
      "y": 11,
      "z": 10,
      "name": "Wood_Banyan_Roots"
    },
    {
      "x": -4,
      "y": 12,
      "z": 10,
      "name": "Wood_Banyan_Trunk",
      "support": 15
    },
    {
      "x": -4,
      "y": 13,
      "z": 10,
      "name": "Plant_Large_Lilypad"
    },
    {
      "x": -4,
      "y": 14,
      "z": 10,
      "name": "Empty"
    },
    {
      "x": -4,
      "y": 13,
      "z": 11,
      "name": "Plant_Large_Lilypad"
    },
    {
      "x": -4,
      "y": 14,
      "z": 11,
      "name": "Empty"
    },
    {
      "x": -4,
      "y": 12,
      "z": 12,
      "name": "Wood_Banyan_Roots"
    },
    {
      "x": -4,
      "y": 13,
      "z": 12,
      "name": "Plant_Large_Lilypad"
    },
    {
      "x": -4,
      "y": 14,
      "z": 12,
      "name": "Empty"
    },
    {
      "x": -4,
      "y": 13,
      "z": 13,
      "name": "Plant_Large_Lilypad"
    },
    {
      "x": -4,
      "y": 14,
      "z": 13,
      "name": "Empty"
    },
    {
      "x": -4,
      "y": 13,
      "z": 14,
      "name": "Plant_Large_Lilypad"
    },
    {
      "x": -4,
      "y": 14,
      "z": 14,
      "name": "Empty"
    },
    {
      "x": -4,
      "y": 13,
      "z": 15,
      "name": "Plant_Large_Lilypad"
    },
    {
      "x": -4,
      "y": 14,
      "z": 15,
      "name": "Plant_Large_Lilypad_Half"
    },
    {
      "x": -3,
      "y": 12,
      "z": -14,
      "name": "Wood_Banyan_Branch_Corner",
      "support": 15,
      "rotation": 2
    },
    {
      "x": -3,
      "y": 13,
      "z": -14,
      "name": "Wood_Banyan_Branch_Long",
      "support": 15
    },
    {
      "x": -3,
      "y": 14,
      "z": -14,
      "name": "Wood_Banyan_Branch_Long",
      "support": 15
    },
    {
      "x": -3,
      "y": 15,
      "z": -14,
      "name": "Wood_Banyan_Branch_Corner",
      "support": 15,
      "rotation": 11
    },
    {
      "x": -3,
      "y": 12,
      "z": -13,
      "name": "Wood_Banyan_Branch_Long",
      "support": 15,
      "rotation": 4
    },
    {
      "x": -3,
      "y": 12,
      "z": -12,
      "name": "Wood_Banyan_Branch_Long",
      "support": 15,
      "rotation": 4
    },
    {
      "x": -3,
      "y": 11,
      "z": -11,
      "name": "Wood_Banyan_Branch_Corner",
      "support": 15,
      "rotation": 3
    },
    {
      "x": -3,
      "y": 12,
      "z": -11,
      "name": "Wood_Banyan_Branch_Corner",
      "support": 15,
      "rotation": 10
    },
    {
      "x": -3,
      "y": 17,
      "z": -10,
      "name": "Plant_Large_Lilypad"
    },
    {
      "x": -3,
      "y": 18,
      "z": -10,
      "name": "Plant_Large_Lilypad_Half"
    },
    {
      "x": -3,
      "y": 17,
      "z": -9,
      "name": "Plant_Large_Lilypad"
    },
    {
      "x": -3,
      "y": 18,
      "z": -9,
      "name": "Plant_Grass_Sharp_Tall",
      "support": 15
    },
    {
      "x": -3,
      "y": 19,
      "z": -9,
      "name": "Plant_Grass_Sharp_Tall",
      "filler": 1024
    },
    {
      "x": -3,
      "y": 17,
      "z": -8,
      "name": "Plant_Large_Lilypad"
    },
    {
      "x": -3,
      "y": 18,
      "z": -8,
      "name": "Empty"
    },
    {
      "x": -3,
      "y": 17,
      "z": -7,
      "name": "Plant_Large_Lilypad"
    },
    {
      "x": -3,
      "y": 18,
      "z": -7,
      "name": "Empty"
    },
    {
      "x": -3,
      "y": 17,
      "z": -6,
      "name": "Plant_Large_Lilypad"
    },
    {
      "x": -3,
      "y": 18,
      "z": -6,
      "name": "Plant_Large_Lilypad_Half"
    },
    {
      "x": -3,
      "y": 12,
      "z": -4,
      "name": "Plant_Large_Lilypad"
    },
    {
      "x": -3,
      "y": 13,
      "z": -4,
      "name": "Plant_Reeds_Marsh",
      "support": 15
    },
    {
      "x": -3,
      "y": 10,
      "z": -3,
      "name": "Wood_Banyan_Branch_Corner",
      "support": 15,
      "rotation": 3
    },
    {
      "x": -3,
      "y": 11,
      "z": -3,
      "name": "Wood_Banyan_Roots"
    },
    {
      "x": -3,
      "y": 12,
      "z": -3,
      "name": "Plant_Large_Lilypad"
    },
    {
      "x": -3,
      "y": 13,
      "z": -3,
      "name": "Plant_Reeds_Water",
      "support": 15
    },
    {
      "x": -3,
      "y": 14,
      "z": -3,
      "name": "Plant_Reeds_Water",
      "filler": 1024
    },
    {
      "x": -3,
      "y": 12,
      "z": -2,
      "name": "Plant_Large_Lilypad"
    },
    {
      "x": -3,
      "y": 13,
      "z": -2,
      "name": "Plant_Reeds_Arid",
      "support": 15
    },
    {
      "x": -3,
      "y": 14,
      "z": -2,
      "name": "Plant_Reeds_Arid",
      "filler": 1024
    },
    {
      "x": -3,
      "y": 9,
      "z": -1,
      "name": "Wood_Banyan_Trunk",
      "support": 15,
      "rotation": 5
    },
    {
      "x": -3,
      "y": 23,
      "z": -1,
      "name": "Plant_Large_Lilypad_Golden_Half"
    },
    {
      "x": -3,
      "y": 16,
      "z": 0,
      "name": "Plant_Large_Lilypad_Half"
    },
    {
      "x": -3,
      "y": 23,
      "z": 0,
      "name": "Plant_Large_Lilypad_Golden_Half"
    },
    {
      "x": -3,
      "y": 11,
      "z": 1,
      "name": "Wood_Banyan_Trunk",
      "support": 15,
      "rotation": 5
    },
    {
      "x": -3,
      "y": 16,
      "z": 1,
      "name": "Plant_Large_Lilypad_Half"
    },
    {
      "x": -3,
      "y": 20,
      "z": 1,
      "name": "Plant_Large_Lilypad",
      "rotation": 3
    },
    {
      "x": -3,
      "y": 21,
      "z": 1,
      "name": "Plant_Large_Lilypad_Half"
    },
    {
      "x": -3,
      "y": 23,
      "z": 1,
      "name": "Plant_Large_Lilypad_Golden_Half"
    },
    {
      "x": -3,
      "y": 16,
      "z": 2,
      "name": "Plant_Large_Lilypad_Half"
    },
    {
      "x": -3,
      "y": 20,
      "z": 2,
      "name": "Plant_Large_Lilypad",
      "rotation": 3
    },
    {
      "x": -3,
      "y": 21,
      "z": 2,
      "name": "Empty"
    },
    {
      "x": -3,
      "y": 16,
      "z": 3,
      "name": "Plant_Large_Lilypad_Half"
    },
    {
      "x": -3,
      "y": 20,
      "z": 3,
      "name": "Plant_Large_Lilypad",
      "rotation": 3
    },
    {
      "x": -3,
      "y": 21,
      "z": 3,
      "name": "Empty"
    },
    {
      "x": -3,
      "y": 16,
      "z": 4,
      "name": "Plant_Large_Lilypad_Half"
    },
    {
      "x": -3,
      "y": 20,
      "z": 4,
      "name": "Plant_Large_Lilypad",
      "rotation": 3
    },
    {
      "x": -3,
      "y": 21,
      "z": 4,
      "name": "Plant_Grass_Sharp_Tall",
      "support": 15
    },
    {
      "x": -3,
      "y": 22,
      "z": 4,
      "name": "Plant_Grass_Sharp_Tall",
      "filler": 1024
    },
    {
      "x": -3,
      "y": 8,
      "z": 5,
      "name": "Wood_Banyan_Branch_Long",
      "support": 15,
      "rotation": 5
    },
    {
      "x": -3,
      "y": 13,
      "z": 5,
      "name": "Plant_Large_Lilypad"
    },
    {
      "x": -3,
      "y": 14,
      "z": 5,
      "name": "Plant_Large_Lilypad_Half"
    },
    {
      "x": -3,
      "y": 20,
      "z": 5,
      "name": "Plant_Large_Lilypad",
      "rotation": 3
    },
    {
      "x": -3,
      "y": 21,
      "z": 5,
      "name": "Plant_Large_Lilypad_Half"
    },
    {
      "x": -3,
      "y": 13,
      "z": 6,
      "name": "Plant_Large_Lilypad"
    },
    {
      "x": -3,
      "y": 14,
      "z": 6,
      "name": "Empty"
    },
    {
      "x": -3,
      "y": 13,
      "z": 7,
      "name": "Plant_Large_Lilypad"
    },
    {
      "x": -3,
      "y": 14,
      "z": 7,
      "name": "Empty"
    },
    {
      "x": -3,
      "y": 13,
      "z": 8,
      "name": "Plant_Large_Lilypad"
    },
    {
      "x": -3,
      "y": 14,
      "z": 8,
      "name": "Empty"
    },
    {
      "x": -3,
      "y": 12,
      "z": 9,
      "name": "Wood_Banyan_Trunk_Full",
      "support": 15
    },
    {
      "x": -3,
      "y": 13,
      "z": 9,
      "name": "Plant_Large_Lilypad"
    },
    {
      "x": -3,
      "y": 14,
      "z": 9,
      "name": "Empty"
    },
    {
      "x": -3,
      "y": 8,
      "z": 10,
      "name": "Wood_Banyan_Roots"
    },
    {
      "x": -3,
      "y": 9,
      "z": 10,
      "name": "Wood_Banyan_Trunk_Full",
      "support": 15
    },
    {
      "x": -3,
      "y": 10,
      "z": 10,
      "name": "Wood_Banyan_Trunk",
      "support": 15
    },
    {
      "x": -3,
      "y": 11,
      "z": 10,
      "name": "Wood_Banyan_Trunk",
      "support": 15
    },
    {
      "x": -3,
      "y": 12,
      "z": 10,
      "name": "Wood_Banyan_Trunk",
      "support": 15
    },
    {
      "x": -3,
      "y": 13,
      "z": 10,
      "name": "Plant_Large_Lilypad"
    },
    {
      "x": -3,
      "y": 14,
      "z": 10,
      "name": "Empty"
    },
    {
      "x": -3,
      "y": 12,
      "z": 11,
      "name": "Wood_Banyan_Roots"
    },
    {
      "x": -3,
      "y": 13,
      "z": 11,
      "name": "Plant_Large_Lilypad"
    },
    {
      "x": -3,
      "y": 14,
      "z": 11,
      "name": "Empty"
    },
    {
      "x": -3,
      "y": 13,
      "z": 12,
      "name": "Plant_Large_Lilypad"
    },
    {
      "x": -3,
      "y": 14,
      "z": 12,
      "name": "Empty"
    },
    {
      "x": -3,
      "y": 13,
      "z": 13,
      "name": "Plant_Large_Lilypad"
    },
    {
      "x": -3,
      "y": 14,
      "z": 13,
      "name": "Empty"
    },
    {
      "x": -3,
      "y": 13,
      "z": 14,
      "name": "Plant_Large_Lilypad"
    },
    {
      "x": -3,
      "y": 14,
      "z": 14,
      "name": "Empty"
    },
    {
      "x": -3,
      "y": 13,
      "z": 15,
      "name": "Plant_Large_Lilypad"
    },
    {
      "x": -3,
      "y": 14,
      "z": 15,
      "name": "Plant_Large_Lilypad_Half"
    },
    {
      "x": -2,
      "y": 11,
      "z": -11,
      "name": "Wood_Banyan_Branch_Long",
      "support": 15,
      "rotation": 5
    },
    {
      "x": -2,
      "y": 17,
      "z": -11,
      "name": "Plant_Large_Lilypad"
    },
    {
      "x": -2,
      "y": 18,
      "z": -11,
      "name": "Plant_Large_Lilypad_Half"
    },
    {
      "x": -2,
      "y": 17,
      "z": -10,
      "name": "Plant_Large_Lilypad"
    },
    {
      "x": -2,
      "y": 18,
      "z": -10,
      "name": "Plant_Grass_Sharp_Tall",
      "support": 15
    },
    {
      "x": -2,
      "y": 19,
      "z": -10,
      "name": "Plant_Grass_Sharp_Tall",
      "filler": 1024
    },
    {
      "x": -2,
      "y": 17,
      "z": -9,
      "name": "Plant_Large_Lilypad"
    },
    {
      "x": -2,
      "y": 18,
      "z": -9,
      "name": "Plant_Grass_Sharp_Short",
      "support": 15
    },
    {
      "x": -2,
      "y": 17,
      "z": -8,
      "name": "Plant_Large_Lilypad"
    },
    {
      "x": -2,
      "y": 18,
      "z": -8,
      "name": "Plant_Grass_Sharp_Tall",
      "support": 15
    },
    {
      "x": -2,
      "y": 19,
      "z": -8,
      "name": "Plant_Grass_Sharp_Tall",
      "filler": 1024
    },
    {
      "x": -2,
      "y": 17,
      "z": -7,
      "name": "Plant_Large_Lilypad"
    },
    {
      "x": -2,
      "y": 18,
      "z": -7,
      "name": "Empty"
    },
    {
      "x": -2,
      "y": 17,
      "z": -6,
      "name": "Plant_Large_Lilypad"
    },
    {
      "x": -2,
      "y": 18,
      "z": -6,
      "name": "Empty"
    },
    {
      "x": -2,
      "y": 17,
      "z": -5,
      "name": "Plant_Large_Lilypad"
    },
    {
      "x": -2,
      "y": 18,
      "z": -5,
      "name": "Plant_Large_Lilypad_Half"
    },
    {
      "x": -2,
      "y": 12,
      "z": -4,
      "name": "Plant_Large_Lilypad"
    },
    {
      "x": -2,
      "y": 9,
      "z": -3,
      "name": "Wood_Banyan_Branch_Corner",
      "support": 15,
      "rotation": 3
    },
    {
      "x": -2,
      "y": 10,
      "z": -3,
      "name": "Wood_Banyan_Branch_Corner",
      "support": 15,
      "rotation": 11
    },
    {
      "x": -2,
      "y": 12,
      "z": -3,
      "name": "Plant_Large_Lilypad"
    },
    {
      "x": -2,
      "y": 13,
      "z": -3,
      "name": "Plant_Reeds_Marsh",
      "support": 15
    },
    {
      "x": -2,
      "y": 12,
      "z": -2,
      "name": "Plant_Large_Lilypad"
    },
    {
      "x": -2,
      "y": 16,
      "z": -2,
      "name": "Wood_Banyan_Branch_Corner",
      "support": 15,
      "rotation": 3
    },
    {
      "x": -2,
      "y": 17,
      "z": -2,
      "name": "Wood_Banyan_Branch_Long",
      "support": 15
    },
    {
      "x": -2,
      "y": 18,
      "z": -2,
      "name": "Wood_Banyan_Branch_Long",
      "support": 15
    },
    {
      "x": -2,
      "y": 19,
      "z": -2,
      "name": "Wood_Banyan_Branch_Long",
      "support": 15
    },
    {
      "x": -2,
      "y": 20,
      "z": -2,
      "name": "Plant_Flower_Lotus_Yellow",
      "support": 15
    },
    {
      "x": -2,
      "y": 23,
      "z": -2,
      "name": "Plant_Large_Lilypad_Golden_Half"
    },
    {
      "x": -2,
      "y": 9,
      "z": -1,
      "name": "Wood_Banyan_Trunk",
      "support": 15,
      "rotation": 5
    },
    {
      "x": -2,
      "y": 23,
      "z": -1,
      "name": "Plant_Large_Lilypad_Golden_Half"
    },
    {
      "x": -2,
      "y": -1,
      "z": 0,
      "name": "Wood_Banyan_Branch_Long",
      "support": 15
    },
    {
      "x": -2,
      "y": 0,
      "z": 0,
      "name": "Wood_Banyan_Branch_Long",
      "support": 15
    },
    {
      "x": -2,
      "y": 1,
      "z": 0,
      "name": "Wood_Banyan_Branch_Long",
      "support": 15
    },
    {
      "x": -2,
      "y": 2,
      "z": 0,
      "name": "Wood_Banyan_Branch_Long",
      "support": 15
    },
    {
      "x": -2,
      "y": 3,
      "z": 0,
      "name": "Wood_Banyan_Branch_Long",
      "support": 15
    },
    {
      "x": -2,
      "y": 4,
      "z": 0,
      "name": "Wood_Banyan_Branch_Corner",
      "support": 15,
      "rotation": 9
    },
    {
      "x": -2,
      "y": 16,
      "z": 0,
      "name": "Plant_Large_Lilypad_Half"
    },
    {
      "x": -2,
      "y": 23,
      "z": 0,
      "name": "Plant_Large_Lilypad_Golden_Half"
    },
    {
      "x": -2,
      "y": 11,
      "z": 1,
      "name": "Wood_Banyan_Trunk",
      "support": 15,
      "rotation": 5
    },
    {
      "x": -2,
      "y": 12,
      "z": 1,
      "name": "Wood_Banyan_Trunk_Full",
      "support": 15
    },
    {
      "x": -2,
      "y": 16,
      "z": 1,
      "name": "Plant_Large_Lilypad_Half"
    },
    {
      "x": -2,
      "y": 23,
      "z": 1,
      "name": "Plant_Large_Lilypad_Golden_Half"
    },
    {
      "x": -2,
      "y": 12,
      "z": 2,
      "name": "Wood_Banyan_Trunk_Full",
      "support": 15
    },
    {
      "x": -2,
      "y": 13,
      "z": 2,
      "name": "Wood_Banyan_Trunk",
      "support": 15
    },
    {
      "x": -2,
      "y": 14,
      "z": 2,
      "name": "Wood_Banyan_Trunk",
      "support": 15
    },
    {
      "x": -2,
      "y": 15,
      "z": 2,
      "name": "Wood_Banyan_Trunk",
      "support": 15
    },
    {
      "x": -2,
      "y": 16,
      "z": 2,
      "name": "Plant_Large_Lilypad_Half"
    },
    {
      "x": -2,
      "y": 20,
      "z": 2,
      "name": "Plant_Large_Lilypad",
      "rotation": 3
    },
    {
      "x": -2,
      "y": 21,
      "z": 2,
      "name": "Plant_Large_Lilypad_Half"
    },
    {
      "x": -2,
      "y": 23,
      "z": 2,
      "name": "Plant_Large_Lilypad_Golden_Half"
    },
    {
      "x": -2,
      "y": 16,
      "z": 3,
      "name": "Plant_Large_Lilypad_Half"
    },
    {
      "x": -2,
      "y": 20,
      "z": 3,
      "name": "Plant_Large_Lilypad",
      "rotation": 3
    },
    {
      "x": -2,
      "y": 21,
      "z": 3,
      "name": "Plant_Large_Lilypad_Half"
    },
    {
      "x": -2,
      "y": 16,
      "z": 4,
      "name": "Plant_Large_Lilypad_Half"
    },
    {
      "x": -2,
      "y": 20,
      "z": 4,
      "name": "Plant_Large_Lilypad",
      "rotation": 3
    },
    {
      "x": -2,
      "y": 21,
      "z": 4,
      "name": "Plant_Large_Lilypad_Half"
    },
    {
      "x": -2,
      "y": 7,
      "z": 5,
      "name": "Wood_Banyan_Branch_Corner",
      "support": 15,
      "rotation": 3
    },
    {
      "x": -2,
      "y": 8,
      "z": 5,
      "name": "Wood_Banyan_Branch_Corner",
      "support": 15,
      "rotation": 11
    },
    {
      "x": -2,
      "y": 13,
      "z": 5,
      "name": "Plant_Large_Lilypad"
    },
    {
      "x": -2,
      "y": 14,
      "z": 5,
      "name": "Plant_Large_Lilypad_Half"
    },
    {
      "x": -2,
      "y": 13,
      "z": 6,
      "name": "Plant_Large_Lilypad"
    },
    {
      "x": -2,
      "y": 14,
      "z": 6,
      "name": "Empty"
    },
    {
      "x": -2,
      "y": 13,
      "z": 7,
      "name": "Plant_Large_Lilypad"
    },
    {
      "x": -2,
      "y": 14,
      "z": 7,
      "name": "Plant_Grass_Sharp_Short",
      "support": 15
    },
    {
      "x": -2,
      "y": 13,
      "z": 8,
      "name": "Plant_Large_Lilypad"
    },
    {
      "x": -2,
      "y": 14,
      "z": 8,
      "name": "Empty"
    },
    {
      "x": -2,
      "y": 9,
      "z": 9,
      "name": "Wood_Banyan_Trunk_Full",
      "support": 15,
      "rotation": 4
    },
    {
      "x": -2,
      "y": 13,
      "z": 9,
      "name": "Plant_Large_Lilypad"
    },
    {
      "x": -2,
      "y": 14,
      "z": 9,
      "name": "Empty"
    },
    {
      "x": -2,
      "y": 9,
      "z": 10,
      "name": "Wood_Banyan_Trunk_Full",
      "support": 15,
      "rotation": 5
    },
    {
      "x": -2,
      "y": 12,
      "z": 10,
      "name": "Wood_Banyan_Roots"
    },
    {
      "x": -2,
      "y": 13,
      "z": 10,
      "name": "Plant_Large_Lilypad"
    },
    {
      "x": -2,
      "y": 14,
      "z": 10,
      "name": "Empty"
    },
    {
      "x": -2,
      "y": 13,
      "z": 11,
      "name": "Plant_Large_Lilypad"
    },
    {
      "x": -2,
      "y": 14,
      "z": 11,
      "name": "Empty"
    },
    {
      "x": -2,
      "y": 13,
      "z": 12,
      "name": "Plant_Large_Lilypad"
    },
    {
      "x": -2,
      "y": 14,
      "z": 12,
      "name": "Empty"
    },
    {
      "x": -2,
      "y": 13,
      "z": 13,
      "name": "Plant_Large_Lilypad"
    },
    {
      "x": -2,
      "y": 14,
      "z": 13,
      "name": "Empty"
    },
    {
      "x": -2,
      "y": 13,
      "z": 14,
      "name": "Plant_Large_Lilypad"
    },
    {
      "x": -2,
      "y": 14,
      "z": 14,
      "name": "Plant_Grass_Sharp_Tall",
      "support": 15
    },
    {
      "x": -2,
      "y": 15,
      "z": 14,
      "name": "Plant_Grass_Sharp_Tall",
      "filler": 1024
    },
    {
      "x": -2,
      "y": 13,
      "z": 15,
      "name": "Plant_Large_Lilypad"
    },
    {
      "x": -2,
      "y": 14,
      "z": 15,
      "name": "Plant_Large_Lilypad_Half"
    },
    {
      "x": -1,
      "y": 17,
      "z": -12,
      "name": "Plant_Large_Lilypad"
    },
    {
      "x": -1,
      "y": 18,
      "z": -12,
      "name": "Plant_Large_Lilypad_Half"
    },
    {
      "x": -1,
      "y": 11,
      "z": -11,
      "name": "Wood_Banyan_Branch_Long",
      "support": 15,
      "rotation": 5
    },
    {
      "x": -1,
      "y": 17,
      "z": -11,
      "name": "Plant_Large_Lilypad"
    },
    {
      "x": -1,
      "y": 18,
      "z": -11,
      "name": "Empty"
    },
    {
      "x": -1,
      "y": 17,
      "z": -10,
      "name": "Plant_Large_Lilypad"
    },
    {
      "x": -1,
      "y": 18,
      "z": -10,
      "name": "Plant_Grass_Sharp_Short",
      "support": 15
    },
    {
      "x": -1,
      "y": 17,
      "z": -9,
      "name": "Plant_Large_Lilypad"
    },
    {
      "x": -1,
      "y": 18,
      "z": -9,
      "name": "Empty"
    },
    {
      "x": -1,
      "y": 17,
      "z": -8,
      "name": "Plant_Large_Lilypad"
    },
    {
      "x": -1,
      "y": 18,
      "z": -8,
      "name": "Empty"
    },
    {
      "x": -1,
      "y": 16,
      "z": -7,
      "name": "Wood_Banyan_Roots"
    },
    {
      "x": -1,
      "y": 17,
      "z": -7,
      "name": "Plant_Large_Lilypad"
    },
    {
      "x": -1,
      "y": 18,
      "z": -7,
      "name": "Empty"
    },
    {
      "x": -1,
      "y": 17,
      "z": -6,
      "name": "Plant_Large_Lilypad"
    },
    {
      "x": -1,
      "y": 18,
      "z": -6,
      "name": "Empty"
    },
    {
      "x": -1,
      "y": 17,
      "z": -5,
      "name": "Plant_Large_Lilypad"
    },
    {
      "x": -1,
      "y": 18,
      "z": -5,
      "name": "Plant_Grass_Sharp_Tall",
      "support": 15
    },
    {
      "x": -1,
      "y": 19,
      "z": -5,
      "name": "Plant_Grass_Sharp_Tall",
      "filler": 1024
    },
    {
      "x": -1,
      "y": 17,
      "z": -4,
      "name": "Plant_Large_Lilypad"
    },
    {
      "x": -1,
      "y": 18,
      "z": -4,
      "name": "Plant_Large_Lilypad_Half"
    },
    {
      "x": -1,
      "y": 9,
      "z": -3,
      "name": "Wood_Banyan_Branch_Long",
      "support": 15,
      "rotation": 5
    },
    {
      "x": -1,
      "y": 23,
      "z": -3,
      "name": "Plant_Large_Lilypad_Golden_Half"
    },
    {
      "x": -1,
      "y": 16,
      "z": -2,
      "name": "Wood_Banyan_Branch_Long",
      "support": 15,
      "rotation": 5
    },
    {
      "x": -1,
      "y": 23,
      "z": -2,
      "name": "Plant_Large_Lilypad_Golden_Half"
    },
    {
      "x": -1,
      "y": 9,
      "z": -1,
      "name": "Wood_Banyan_Trunk",
      "support": 15,
      "rotation": 5
    },
    {
      "x": -1,
      "y": 23,
      "z": -1,
      "name": "Plant_Large_Lilypad_Golden_Half"
    },
    {
      "x": -1,
      "y": -1,
      "z": 0,
      "name": "Wood_Banyan_Trunk",
      "support": 15
    },
    {
      "x": -1,
      "y": 4,
      "z": 0,
      "name": "Wood_Banyan_Branch_Long",
      "support": 15,
      "rotation": 5
    },
    {
      "x": -1,
      "y": 16,
      "z": 0,
      "name": "Plant_Large_Lilypad_Half"
    },
    {
      "x": -1,
      "y": 23,
      "z": 0,
      "name": "Plant_Large_Lilypad_Golden_Half"
    },
    {
      "x": -1,
      "y": 10,
      "z": 1,
      "name": "Wood_Banyan_Trunk_Full",
      "support": 15
    },
    {
      "x": -1,
      "y": 11,
      "z": 1,
      "name": "Wood_Banyan_Trunk",
      "support": 15
    },
    {
      "x": -1,
      "y": 12,
      "z": 1,
      "name": "Wood_Banyan_Trunk_Full",
      "support": 15
    },
    {
      "x": -1,
      "y": 16,
      "z": 1,
      "name": "Plant_Large_Lilypad_Half"
    },
    {
      "x": -1,
      "y": 23,
      "z": 1,
      "name": "Plant_Large_Lilypad_Golden_Half"
    },
    {
      "x": -1,
      "y": 2,
      "z": 2,
      "name": "Wood_Banyan_Branch_Long",
      "support": 15
    },
    {
      "x": -1,
      "y": 3,
      "z": 2,
      "name": "Wood_Banyan_Branch_Long",
      "support": 15
    },
    {
      "x": -1,
      "y": 4,
      "z": 2,
      "name": "Wood_Banyan_Branch_Long",
      "support": 15
    },
    {
      "x": -1,
      "y": 5,
      "z": 2,
      "name": "Wood_Banyan_Branch_Long",
      "support": 15
    },
    {
      "x": -1,
      "y": 6,
      "z": 2,
      "name": "Wood_Banyan_Branch_Long",
      "support": 15
    },
    {
      "x": -1,
      "y": 7,
      "z": 2,
      "name": "Wood_Banyan_Branch_Corner",
      "support": 15,
      "rotation": 9
    },
    {
      "x": -1,
      "y": 16,
      "z": 2,
      "name": "Plant_Large_Lilypad_Half"
    },
    {
      "x": -1,
      "y": 23,
      "z": 2,
      "name": "Plant_Large_Lilypad_Golden_Half"
    },
    {
      "x": -1,
      "y": 16,
      "z": 3,
      "name": "Plant_Large_Lilypad_Half"
    },
    {
      "x": -1,
      "y": 23,
      "z": 3,
      "name": "Plant_Large_Lilypad_Golden_Half"
    },
    {
      "x": -1,
      "y": 16,
      "z": 4,
      "name": "Plant_Large_Lilypad_Half"
    },
    {
      "x": -1,
      "y": 7,
      "z": 5,
      "name": "Wood_Banyan_Branch_Long",
      "support": 15,
      "rotation": 5
    },
    {
      "x": -1,
      "y": 13,
      "z": 6,
      "name": "Plant_Large_Lilypad"
    },
    {
      "x": -1,
      "y": 14,
      "z": 6,
      "name": "Plant_Large_Lilypad_Half"
    },
    {
      "x": -1,
      "y": 13,
      "z": 7,
      "name": "Plant_Large_Lilypad"
    },
    {
      "x": -1,
      "y": 14,
      "z": 7,
      "name": "Empty"
    },
    {
      "x": -1,
      "y": 13,
      "z": 8,
      "name": "Plant_Large_Lilypad"
    },
    {
      "x": -1,
      "y": 14,
      "z": 8,
      "name": "Empty"
    },
    {
      "x": -1,
      "y": 9,
      "z": 9,
      "name": "Wood_Banyan_Trunk",
      "support": 15,
      "rotation": 5
    },
    {
      "x": -1,
      "y": 13,
      "z": 9,
      "name": "Plant_Large_Lilypad"
    },
    {
      "x": -1,
      "y": 14,
      "z": 9,
      "name": "Plant_Grass_Sharp_Tall",
      "support": 15
    },
    {
      "x": -1,
      "y": 15,
      "z": 9,
      "name": "Plant_Grass_Sharp_Tall",
      "filler": 1024
    },
    {
      "x": -1,
      "y": 13,
      "z": 10,
      "name": "Plant_Large_Lilypad"
    },
    {
      "x": -1,
      "y": 14,
      "z": 10,
      "name": "Empty"
    },
    {
      "x": -1,
      "y": 13,
      "z": 11,
      "name": "Plant_Large_Lilypad"
    },
    {
      "x": -1,
      "y": 14,
      "z": 11,
      "name": "Empty"
    },
    {
      "x": -1,
      "y": 13,
      "z": 12,
      "name": "Plant_Large_Lilypad"
    },
    {
      "x": -1,
      "y": 14,
      "z": 12,
      "name": "Empty"
    },
    {
      "x": -1,
      "y": 13,
      "z": 13,
      "name": "Plant_Large_Lilypad"
    },
    {
      "x": -1,
      "y": 14,
      "z": 13,
      "name": "Plant_Grass_Sharp_Short",
      "support": 15
    },
    {
      "x": -1,
      "y": 13,
      "z": 14,
      "name": "Plant_Large_Lilypad"
    },
    {
      "x": -1,
      "y": 14,
      "z": 14,
      "name": "Plant_Large_Lilypad_Half"
    },
    {
      "x": 0,
      "y": 17,
      "z": -12,
      "name": "Plant_Large_Lilypad"
    },
    {
      "x": 0,
      "y": 18,
      "z": -12,
      "name": "Plant_Large_Lilypad_Half"
    },
    {
      "x": 0,
      "y": 10,
      "z": -11,
      "name": "Wood_Banyan_Branch_Corner",
      "support": 15,
      "rotation": 2
    },
    {
      "x": 0,
      "y": 11,
      "z": -11,
      "name": "Wood_Banyan_Branch_Corner",
      "support": 15,
      "rotation": 11
    },
    {
      "x": 0,
      "y": 17,
      "z": -11,
      "name": "Plant_Large_Lilypad"
    },
    {
      "x": 0,
      "y": 18,
      "z": -11,
      "name": "Empty"
    },
    {
      "x": 0,
      "y": 10,
      "z": -10,
      "name": "Wood_Banyan_Branch_Long",
      "support": 15,
      "rotation": 4
    },
    {
      "x": 0,
      "y": 17,
      "z": -10,
      "name": "Plant_Large_Lilypad"
    },
    {
      "x": 0,
      "y": 18,
      "z": -10,
      "name": "Empty"
    },
    {
      "x": 0,
      "y": 10,
      "z": -9,
      "name": "Wood_Banyan_Branch_Long",
      "support": 15,
      "rotation": 4
    },
    {
      "x": 0,
      "y": 16,
      "z": -9,
      "name": "Wood_Banyan_Roots"
    },
    {
      "x": 0,
      "y": 17,
      "z": -9,
      "name": "Plant_Large_Lilypad"
    },
    {
      "x": 0,
      "y": 18,
      "z": -9,
      "name": "Empty"
    },
    {
      "x": 0,
      "y": 10,
      "z": -8,
      "name": "Wood_Banyan_Branch_Long",
      "support": 15,
      "rotation": 4
    },
    {
      "x": 0,
      "y": 11,
      "z": -8,
      "name": "Wood_Banyan_Trunk_Full",
      "support": 15,
      "rotation": 4
    },
    {
      "x": 0,
      "y": 12,
      "z": -8,
      "name": "Wood_Banyan_Trunk",
      "support": 15
    },
    {
      "x": 0,
      "y": 13,
      "z": -8,
      "name": "Wood_Banyan_Trunk",
      "support": 15
    },
    {
      "x": 0,
      "y": 14,
      "z": -8,
      "name": "Wood_Banyan_Trunk",
      "support": 15
    },
    {
      "x": 0,
      "y": 15,
      "z": -8,
      "name": "Wood_Banyan_Trunk",
      "support": 15
    },
    {
      "x": 0,
      "y": 16,
      "z": -8,
      "name": "Wood_Banyan_Trunk",
      "support": 15
    },
    {
      "x": 0,
      "y": 17,
      "z": -8,
      "name": "Plant_Large_Lilypad"
    },
    {
      "x": 0,
      "y": 18,
      "z": -8,
      "name": "Empty"
    },
    {
      "x": 0,
      "y": 9,
      "z": -7,
      "name": "Wood_Banyan_Roots"
    },
    {
      "x": 0,
      "y": 10,
      "z": -7,
      "name": "Wood_Banyan_Trunk_Full",
      "support": 15,
      "rotation": 4
    },
    {
      "x": 0,
      "y": 11,
      "z": -7,
      "name": "Wood_Banyan_Trunk_Full",
      "support": 15,
      "rotation": 4
    },
    {
      "x": 0,
      "y": 17,
      "z": -7,
      "name": "Plant_Large_Lilypad"
    },
    {
      "x": 0,
      "y": 18,
      "z": -7,
      "name": "Empty"
    },
    {
      "x": 0,
      "y": 9,
      "z": -6,
      "name": "Wood_Banyan_Trunk_Full",
      "support": 15,
      "rotation": 4
    },
    {
      "x": 0,
      "y": 10,
      "z": -6,
      "name": "Wood_Banyan_Trunk_Full",
      "support": 15,
      "rotation": 4
    },
    {
      "x": 0,
      "y": 17,
      "z": -6,
      "name": "Plant_Large_Lilypad"
    },
    {
      "x": 0,
      "y": 18,
      "z": -6,
      "name": "Empty"
    },
    {
      "x": 0,
      "y": 9,
      "z": -5,
      "name": "Wood_Banyan_Trunk",
      "support": 15,
      "rotation": 4
    },
    {
      "x": 0,
      "y": 17,
      "z": -5,
      "name": "Plant_Large_Lilypad"
    },
    {
      "x": 0,
      "y": 18,
      "z": -5,
      "name": "Empty"
    },
    {
      "x": 0,
      "y": 9,
      "z": -4,
      "name": "Wood_Banyan_Trunk",
      "support": 15,
      "rotation": 4
    },
    {
      "x": 0,
      "y": 17,
      "z": -4,
      "name": "Plant_Large_Lilypad"
    },
    {
      "x": 0,
      "y": 18,
      "z": -4,
      "name": "Plant_Large_Lilypad_Half"
    },
    {
      "x": 0,
      "y": 9,
      "z": -3,
      "name": "Wood_Banyan_Trunk",
      "support": 15,
      "rotation": 4
    },
    {
      "x": 0,
      "y": 23,
      "z": -3,
      "name": "Plant_Large_Lilypad_Golden_Half"
    },
    {
      "x": 0,
      "y": -1,
      "z": -2,
      "name": "Wood_Banyan_Branch_Long",
      "support": 15
    },
    {
      "x": 0,
      "y": 0,
      "z": -2,
      "name": "Wood_Banyan_Branch_Long",
      "support": 15
    },
    {
      "x": 0,
      "y": 1,
      "z": -2,
      "name": "Wood_Banyan_Branch_Long",
      "support": 15
    },
    {
      "x": 0,
      "y": 2,
      "z": -2,
      "name": "Wood_Banyan_Branch_Corner",
      "support": 15,
      "rotation": 8
    },
    {
      "x": 0,
      "y": 9,
      "z": -2,
      "name": "Wood_Banyan_Trunk",
      "support": 15,
      "rotation": 4
    },
    {
      "x": 0,
      "y": 15,
      "z": -2,
      "name": "Wood_Banyan_Branch_Corner",
      "support": 15,
      "rotation": 2
    },
    {
      "x": 0,
      "y": 16,
      "z": -2,
      "name": "Wood_Banyan_Branch_Corner",
      "support": 15,
      "rotation": 11
    },
    {
      "x": 0,
      "y": 23,
      "z": -2,
      "name": "Plant_Large_Lilypad_Golden_Half"
    },
    {
      "x": 0,
      "y": 2,
      "z": -1,
      "name": "Wood_Banyan_Branch_Long",
      "support": 15,
      "rotation": 4
    },
    {
      "x": 0,
      "y": 5,
      "z": -1,
      "name": "Wood_Banyan_Roots"
    },
    {
      "x": 0,
      "y": 6,
      "z": -1,
      "name": "Wood_Banyan_Trunk_Full",
      "support": 15,
      "rotation": 4
    },
    {
      "x": 0,
      "y": 8,
      "z": -1,
      "name": "Wood_Banyan_Roots"
    },
    {
      "x": 0,
      "y": 9,
      "z": -1,
      "name": "Wood_Banyan_Trunk",
      "support": 15,
      "rotation": 4
    },
    {
      "x": 0,
      "y": 15,
      "z": -1,
      "name": "Wood_Banyan_Branch_Long",
      "support": 15,
      "rotation": 4
    },
    {
      "x": 0,
      "y": 20,
      "z": -1,
      "name": "Wood_Banyan_Branch_Corner",
      "support": 15,
      "rotation": 2
    },
    {
      "x": 0,
      "y": 21,
      "z": -1,
      "name": "Wood_Banyan_Branch_Long",
      "support": 15
    },
    {
      "x": 0,
      "y": 22,
      "z": -1,
      "name": "Wood_Banyan_Branch_Long",
      "support": 15
    },
    {
      "x": 0,
      "y": 23,
      "z": -1,
      "name": "Plant_Large_Lilypad_Golden_Half"
    },
    {
      "x": 0,
      "y": -1,
      "z": 0,
      "name": "Wood_Banyan_Trunk",
      "support": 15
    },
    {
      "x": 0,
      "y": 0,
      "z": 0,
      "name": "Wood_Banyan_Trunk",
      "support": 15
    },
    {
      "x": 0,
      "y": 1,
      "z": 0,
      "name": "Wood_Banyan_Trunk",
      "support": 15
    },
    {
      "x": 0,
      "y": 2,
      "z": 0,
      "name": "Wood_Banyan_Trunk",
      "support": 15
    },
    {
      "x": 0,
      "y": 3,
      "z": 0,
      "name": "Wood_Banyan_Trunk",
      "support": 15
    },
    {
      "x": 0,
      "y": 4,
      "z": 0,
      "name": "Wood_Banyan_Trunk",
      "support": 15
    },
    {
      "x": 0,
      "y": 5,
      "z": 0,
      "name": "Wood_Banyan_Trunk",
      "support": 15
    },
    {
      "x": 0,
      "y": 6,
      "z": 0,
      "name": "Wood_Banyan_Trunk",
      "support": 15
    },
    {
      "x": 0,
      "y": 7,
      "z": 0,
      "name": "Wood_Banyan_Trunk",
      "support": 15
    },
    {
      "x": 0,
      "y": 8,
      "z": 0,
      "name": "Wood_Banyan_Trunk",
      "support": 15
    },
    {
      "x": 0,
      "y": 9,
      "z": 0,
      "name": "Wood_Banyan_Trunk",
      "support": 15
    },
    {
      "x": 0,
      "y": 10,
      "z": 0,
      "name": "Wood_Banyan_Trunk",
      "support": 15
    },
    {
      "x": 0,
      "y": 11,
      "z": 0,
      "name": "Wood_Banyan_Trunk",
      "support": 15
    },
    {
      "x": 0,
      "y": 12,
      "z": 0,
      "name": "Wood_Banyan_Trunk",
      "support": 15
    },
    {
      "x": 0,
      "y": 13,
      "z": 0,
      "name": "Wood_Banyan_Trunk",
      "support": 15
    },
    {
      "x": 0,
      "y": 14,
      "z": 0,
      "name": "Wood_Banyan_Trunk",
      "support": 15
    },
    {
      "x": 0,
      "y": 15,
      "z": 0,
      "name": "Wood_Banyan_Trunk",
      "support": 15
    },
    {
      "x": 0,
      "y": 16,
      "z": 0,
      "name": "Wood_Banyan_Trunk",
      "support": 15
    },
    {
      "x": 0,
      "y": 17,
      "z": 0,
      "name": "Wood_Banyan_Trunk",
      "support": 15
    },
    {
      "x": 0,
      "y": 18,
      "z": 0,
      "name": "Wood_Banyan_Trunk",
      "support": 15
    },
    {
      "x": 0,
      "y": 19,
      "z": 0,
      "name": "Wood_Banyan_Trunk",
      "support": 15
    },
    {
      "x": 0,
      "y": 20,
      "z": 0,
      "name": "Wood_Banyan_Trunk",
      "support": 15
    },
    {
      "x": 0,
      "y": 21,
      "z": 0,
      "name": "Wood_Banyan_Trunk",
      "support": 15
    },
    {
      "x": 0,
      "y": 22,
      "z": 0,
      "name": "Wood_Banyan_Trunk",
      "support": 15
    },
    {
      "x": 0,
      "y": 23,
      "z": 0,
      "name": "Plant_Large_Lilypad_Golden_Half"
    },
    {
      "x": 0,
      "y": -1,
      "z": 1,
      "name": "Wood_Banyan_Trunk",
      "support": 15
    },
    {
      "x": 0,
      "y": 0,
      "z": 1,
      "name": "Wood_Banyan_Trunk",
      "support": 15
    },
    {
      "x": 0,
      "y": 1,
      "z": 1,
      "name": "Wood_Banyan_Trunk",
      "support": 15
    },
    {
      "x": 0,
      "y": 7,
      "z": 1,
      "name": "Wood_Banyan_Trunk",
      "support": 15,
      "rotation": 4
    },
    {
      "x": 0,
      "y": 10,
      "z": 1,
      "name": "Wood_Banyan_Trunk_Full",
      "support": 15,
      "rotation": 4
    },
    {
      "x": 0,
      "y": 16,
      "z": 1,
      "name": "Plant_Large_Lilypad_Half"
    },
    {
      "x": 0,
      "y": 21,
      "z": 1,
      "name": "Wood_Banyan_Branch_Long",
      "support": 15,
      "rotation": 4
    },
    {
      "x": 0,
      "y": 23,
      "z": 1,
      "name": "Plant_Large_Lilypad_Golden_Half"
    },
    {
      "x": 0,
      "y": 7,
      "z": 2,
      "name": "Wood_Banyan_Trunk",
      "support": 15,
      "rotation": 4
    },
    {
      "x": 0,
      "y": 16,
      "z": 2,
      "name": "Plant_Large_Lilypad_Half"
    },
    {
      "x": 0,
      "y": 21,
      "z": 2,
      "name": "Wood_Banyan_Branch_Corner",
      "support": 15
    },
    {
      "x": 0,
      "y": 22,
      "z": 2,
      "name": "Wood_Banyan_Branch_Long",
      "support": 15
    },
    {
      "x": 0,
      "y": 23,
      "z": 2,
      "name": "Plant_Large_Lilypad_Golden_Half"
    },
    {
      "x": 0,
      "y": 6,
      "z": 3,
      "name": "Wood_Banyan_Roots"
    },
    {
      "x": 0,
      "y": 7,
      "z": 3,
      "name": "Wood_Banyan_Trunk",
      "support": 15,
      "rotation": 4
    },
    {
      "x": 0,
      "y": 16,
      "z": 3,
      "name": "Plant_Large_Lilypad_Half"
    },
    {
      "x": 0,
      "y": 23,
      "z": 3,
      "name": "Plant_Large_Lilypad_Golden_Half"
    },
    {
      "x": 0,
      "y": 7,
      "z": 4,
      "name": "Wood_Banyan_Trunk",
      "support": 15,
      "rotation": 4
    },
    {
      "x": 0,
      "y": 7,
      "z": 5,
      "name": "Wood_Banyan_Trunk",
      "support": 15,
      "rotation": 4
    },
    {
      "x": 0,
      "y": 7,
      "z": 6,
      "name": "Wood_Banyan_Trunk_Full",
      "support": 15,
      "rotation": 4
    },
    {
      "x": 0,
      "y": 8,
      "z": 6,
      "name": "Wood_Banyan_Trunk_Full",
      "support": 15,
      "rotation": 4
    },
    {
      "x": 0,
      "y": 13,
      "z": 6,
      "name": "Plant_Large_Lilypad"
    },
    {
      "x": 0,
      "y": 14,
      "z": 6,
      "name": "Plant_Large_Lilypad_Half"
    },
    {
      "x": 0,
      "y": 7,
      "z": 7,
      "name": "Wood_Banyan_Roots"
    },
    {
      "x": 0,
      "y": 8,
      "z": 7,
      "name": "Wood_Banyan_Trunk",
      "support": 15,
      "rotation": 4
    },
    {
      "x": 0,
      "y": 13,
      "z": 7,
      "name": "Plant_Large_Lilypad"
    },
    {
      "x": 0,
      "y": 14,
      "z": 7,
      "name": "Empty"
    },
    {
      "x": 0,
      "y": 8,
      "z": 8,
      "name": "Wood_Banyan_Trunk_Full",
      "support": 15,
      "rotation": 4
    },
    {
      "x": 0,
      "y": 9,
      "z": 8,
      "name": "Wood_Banyan_Trunk_Full",
      "support": 15,
      "rotation": 4
    },
    {
      "x": 0,
      "y": 13,
      "z": 8,
      "name": "Plant_Large_Lilypad"
    },
    {
      "x": 0,
      "y": 14,
      "z": 8,
      "name": "Empty"
    },
    {
      "x": 0,
      "y": 9,
      "z": 9,
      "name": "Wood_Banyan_Trunk_Full",
      "support": 15,
      "rotation": 5
    },
    {
      "x": 0,
      "y": 13,
      "z": 9,
      "name": "Plant_Large_Lilypad"
    },
    {
      "x": 0,
      "y": 14,
      "z": 9,
      "name": "Empty"
    },
    {
      "x": 0,
      "y": 13,
      "z": 10,
      "name": "Plant_Large_Lilypad"
    },
    {
      "x": 0,
      "y": 14,
      "z": 10,
      "name": "Plant_Grass_Sharp_Short",
      "support": 15
    },
    {
      "x": 0,
      "y": 13,
      "z": 11,
      "name": "Plant_Large_Lilypad"
    },
    {
      "x": 0,
      "y": 14,
      "z": 11,
      "name": "Plant_Grass_Sharp_Tall",
      "support": 15
    },
    {
      "x": 0,
      "y": 15,
      "z": 11,
      "name": "Plant_Grass_Sharp_Tall",
      "filler": 1024
    },
    {
      "x": 0,
      "y": 13,
      "z": 12,
      "name": "Plant_Large_Lilypad"
    },
    {
      "x": 0,
      "y": 14,
      "z": 12,
      "name": "Plant_Grass_Sharp_Short",
      "support": 15
    },
    {
      "x": 0,
      "y": 13,
      "z": 13,
      "name": "Plant_Large_Lilypad"
    },
    {
      "x": 0,
      "y": 14,
      "z": 13,
      "name": "Plant_Grass_Sharp_Tall",
      "support": 15
    },
    {
      "x": 0,
      "y": 15,
      "z": 13,
      "name": "Plant_Grass_Sharp_Tall",
      "filler": 1024
    },
    {
      "x": 0,
      "y": 13,
      "z": 14,
      "name": "Plant_Large_Lilypad"
    },
    {
      "x": 0,
      "y": 14,
      "z": 14,
      "name": "Plant_Large_Lilypad_Half"
    },
    {
      "x": 1,
      "y": 17,
      "z": -12,
      "name": "Plant_Large_Lilypad"
    },
    {
      "x": 1,
      "y": 18,
      "z": -12,
      "name": "Plant_Large_Lilypad_Half"
    },
    {
      "x": 1,
      "y": 17,
      "z": -11,
      "name": "Plant_Large_Lilypad"
    },
    {
      "x": 1,
      "y": 18,
      "z": -11,
      "name": "Empty"
    },
    {
      "x": 1,
      "y": 17,
      "z": -10,
      "name": "Plant_Large_Lilypad"
    },
    {
      "x": 1,
      "y": 18,
      "z": -10,
      "name": "Empty"
    },
    {
      "x": 1,
      "y": 17,
      "z": -9,
      "name": "Plant_Large_Lilypad"
    },
    {
      "x": 1,
      "y": 18,
      "z": -9,
      "name": "Empty"
    },
    {
      "x": 1,
      "y": 15,
      "z": -8,
      "name": "Wood_Banyan_Roots"
    },
    {
      "x": 1,
      "y": 16,
      "z": -8,
      "name": "Wood_Banyan_Trunk_Full",
      "support": 15
    },
    {
      "x": 1,
      "y": 17,
      "z": -8,
      "name": "Plant_Large_Lilypad"
    },
    {
      "x": 1,
      "y": 18,
      "z": -8,
      "name": "Empty"
    },
    {
      "x": 1,
      "y": 17,
      "z": -7,
      "name": "Plant_Large_Lilypad"
    },
    {
      "x": 1,
      "y": 18,
      "z": -7,
      "name": "Empty"
    },
    {
      "x": 1,
      "y": 17,
      "z": -6,
      "name": "Plant_Large_Lilypad"
    },
    {
      "x": 1,
      "y": 18,
      "z": -6,
      "name": "Empty"
    },
    {
      "x": 1,
      "y": 17,
      "z": -5,
      "name": "Plant_Large_Lilypad"
    },
    {
      "x": 1,
      "y": 18,
      "z": -5,
      "name": "Empty"
    },
    {
      "x": 1,
      "y": 17,
      "z": -4,
      "name": "Plant_Large_Lilypad"
    },
    {
      "x": 1,
      "y": 18,
      "z": -4,
      "name": "Plant_Large_Lilypad_Half"
    },
    {
      "x": 1,
      "y": 23,
      "z": -3,
      "name": "Plant_Large_Lilypad_Golden_Half"
    },
    {
      "x": 1,
      "y": 23,
      "z": -2,
      "name": "Plant_Large_Lilypad_Golden_Half"
    },
    {
      "x": 1,
      "y": 6,
      "z": -1,
      "name": "Wood_Banyan_Trunk",
      "support": 15,
      "rotation": 5
    },
    {
      "x": 1,
      "y": 23,
      "z": -1,
      "name": "Plant_Large_Lilypad_Golden_Half"
    },
    {
      "x": 1,
      "y": -1,
      "z": 0,
      "name": "Wood_Banyan_Trunk",
      "support": 15
    },
    {
      "x": 1,
      "y": 0,
      "z": 0,
      "name": "Wood_Banyan_Trunk",
      "support": 15
    },
    {
      "x": 1,
      "y": 1,
      "z": 0,
      "name": "Wood_Banyan_Trunk",
      "support": 15
    },
    {
      "x": 1,
      "y": 2,
      "z": 0,
      "name": "Wood_Banyan_Trunk",
      "support": 15
    },
    {
      "x": 1,
      "y": 8,
      "z": 0,
      "name": "Wood_Banyan_Trunk",
      "support": 15,
      "rotation": 5
    },
    {
      "x": 1,
      "y": 17,
      "z": 0,
      "name": "Wood_Banyan_Branch_Long",
      "support": 15,
      "rotation": 5
    },
    {
      "x": 1,
      "y": 23,
      "z": 0,
      "name": "Plant_Large_Lilypad_Golden_Half"
    },
    {
      "x": 1,
      "y": 10,
      "z": 1,
      "name": "Wood_Banyan_Trunk_Full",
      "support": 15
    },
    {
      "x": 1,
      "y": 11,
      "z": 1,
      "name": "Wood_Banyan_Trunk_Full",
      "support": 15,
      "rotation": 5
    },
    {
      "x": 1,
      "y": 23,
      "z": 1,
      "name": "Plant_Large_Lilypad_Golden_Half"
    },
    {
      "x": 1,
      "y": 23,
      "z": 2,
      "name": "Plant_Large_Lilypad_Golden_Half"
    },
    {
      "x": 1,
      "y": 23,
      "z": 3,
      "name": "Plant_Large_Lilypad_Golden_Half"
    },
    {
      "x": 1,
      "y": 13,
      "z": 7,
      "name": "Plant_Large_Lilypad"
    },
    {
      "x": 1,
      "y": 14,
      "z": 7,
      "name": "Plant_Large_Lilypad_Half"
    },
    {
      "x": 1,
      "y": 9,
      "z": 8,
      "name": "Wood_Banyan_Branch_Corner",
      "support": 15,
      "rotation": 1
    },
    {
      "x": 1,
      "y": 10,
      "z": 8,
      "name": "Wood_Banyan_Branch_Long",
      "support": 15
    },
    {
      "x": 1,
      "y": 11,
      "z": 8,
      "name": "Wood_Banyan_Branch_Corner",
      "support": 15,
      "rotation": 9
    },
    {
      "x": 1,
      "y": 13,
      "z": 8,
      "name": "Plant_Large_Lilypad"
    },
    {
      "x": 1,
      "y": 14,
      "z": 8,
      "name": "Plant_Large_Lilypad_Half"
    },
    {
      "x": 1,
      "y": 15,
      "z": 8,
      "name": "Wood_Banyan_Branch_Corner",
      "support": 15,
      "rotation": 3
    },
    {
      "x": 1,
      "y": 16,
      "z": 8,
      "name": "Wood_Banyan_Branch_Long",
      "support": 15
    },
    {
      "x": 1,
      "y": 17,
      "z": 8,
      "name": "Wood_Banyan_Branch_Long",
      "support": 15
    },
    {
      "x": 1,
      "y": 18,
      "z": 8,
      "name": "Plant_Flower_Lotus_Yellow",
      "support": 15
    },
    {
      "x": 1,
      "y": 13,
      "z": 9,
      "name": "Plant_Large_Lilypad"
    },
    {
      "x": 1,
      "y": 14,
      "z": 9,
      "name": "Plant_Grass_Sharp_Tall",
      "support": 15
    },
    {
      "x": 1,
      "y": 15,
      "z": 9,
      "name": "Plant_Grass_Sharp_Tall",
      "filler": 1024
    },
    {
      "x": 1,
      "y": 13,
      "z": 10,
      "name": "Plant_Large_Lilypad"
    },
    {
      "x": 1,
      "y": 14,
      "z": 10,
      "name": "Empty"
    },
    {
      "x": 1,
      "y": 13,
      "z": 11,
      "name": "Plant_Large_Lilypad"
    },
    {
      "x": 1,
      "y": 14,
      "z": 11,
      "name": "Empty"
    },
    {
      "x": 1,
      "y": 13,
      "z": 12,
      "name": "Plant_Large_Lilypad"
    },
    {
      "x": 1,
      "y": 14,
      "z": 12,
      "name": "Plant_Large_Lilypad_Half"
    },
    {
      "x": 1,
      "y": 13,
      "z": 13,
      "name": "Plant_Large_Lilypad"
    },
    {
      "x": 1,
      "y": 14,
      "z": 13,
      "name": "Plant_Large_Lilypad_Half"
    },
    {
      "x": 2,
      "y": 17,
      "z": -11,
      "name": "Plant_Large_Lilypad"
    },
    {
      "x": 2,
      "y": 18,
      "z": -11,
      "name": "Plant_Large_Lilypad_Half"
    },
    {
      "x": 2,
      "y": 17,
      "z": -10,
      "name": "Plant_Large_Lilypad"
    },
    {
      "x": 2,
      "y": 18,
      "z": -10,
      "name": "Empty"
    },
    {
      "x": 2,
      "y": 17,
      "z": -9,
      "name": "Plant_Large_Lilypad"
    },
    {
      "x": 2,
      "y": 18,
      "z": -9,
      "name": "Empty"
    },
    {
      "x": 2,
      "y": 17,
      "z": -8,
      "name": "Plant_Large_Lilypad"
    },
    {
      "x": 2,
      "y": 18,
      "z": -8,
      "name": "Empty"
    },
    {
      "x": 2,
      "y": 17,
      "z": -7,
      "name": "Plant_Large_Lilypad"
    },
    {
      "x": 2,
      "y": 18,
      "z": -7,
      "name": "Empty"
    },
    {
      "x": 2,
      "y": 17,
      "z": -6,
      "name": "Plant_Large_Lilypad"
    },
    {
      "x": 2,
      "y": 18,
      "z": -6,
      "name": "Plant_Grass_Sharp_Wild",
      "support": 15
    },
    {
      "x": 2,
      "y": 19,
      "z": -6,
      "name": "Plant_Grass_Sharp_Wild",
      "filler": 1024
    },
    {
      "x": 2,
      "y": 17,
      "z": -5,
      "name": "Plant_Large_Lilypad"
    },
    {
      "x": 2,
      "y": 18,
      "z": -5,
      "name": "Plant_Large_Lilypad_Half"
    },
    {
      "x": 2,
      "y": 13,
      "z": -4,
