{
  "version": 8,
  "blockIdVersion": 11,
  "anchorX": 0,
  "anchorY": 0,
  "anchorZ": 0,
  "blocks": [
    {
      "x": -2,
      "y": 0,
      "z": -1,
      "name": "Plant_Coral_Block_Violet"
    },
    {
      "x": -2,
      "y": 1,
      "z": -1,
      "name": "Plant_Coral_Block_Violet"
    },
    {
      "x": -1,
      "y": 0,
      "z": 1,
      "name": "Plant_Coral_Block_Violet"
    },
    {
      "x": -1,
      "y": 1,
      "z": 1,
      "name": "Plant_Coral_Block_Violet"
    },
    {
      "x": -1,
      "y": 2,
      "z": 1,
      "name": "Plant_Coral_Block_Violet"
    },
    {
      "x": -1,
      "y": 3,
      "z": 1,
      "name": "Plant_Coral_Model_Violet"
    },
    {
      "x": 0,
      "y": 0,
      "z": -2,
      "name": "Plant_Coral_Block_Violet"
    },
    {
      "x": 0,
      "y": 1,
      "z": -2,
      "name": "Plant_Coral_Block_Violet"
    },
    {
      "x": 0,
      "y": 2,
      "z": -2,
      "name": "Plant_Coral_Block_Violet"
    },
    {
      "x": 0,
      "y": 3,
      "z": -2,
      "name": "Plant_Coral_Bush_Violet"
    },
    {
      "x": 0,
      "y": 0,
      "z": -1,
      "name": "Plant_Coral_Block_Violet"
    },
    {
      "x": 0,
      "y": 1,
      "z": -1,
      "name": "Plant_Coral_Block_Violet"
    },
    {
      "x": 0,
      "y": 2,
      "z": -1,
      "name": "Plant_Coral_Block_Violet"
    },
    {
      "x": 0,
      "y": 0,
      "z": 1,
      "name": "Plant_Coral_Block_Violet"
    },
    {
      "x": 0,
      "y": 0,
      "z": 2,
      "name": "Plant_Coral_Block_Violet"
    },
    {
      "x": 0,
      "y": 1,
      "z": 2,
      "name": "Plant_Coral_Bush_Violet"
    },
    {
      "x": 1,
      "y": 0,
      "z": -2,
      "name": "Plant_Coral_Block_Violet"
    },
    {
      "x": 1,
      "y": 1,
      "z": -2,
      "name": "Plant_Coral_Block_Violet"
    },
    {
      "x": 1,
      "y": 2,
      "z": -2,
      "name": "Plant_Coral_Block_Violet"
    },
    {
      "x": 1,
      "y": 0,
      "z": -1,
      "name": "Plant_Coral_Block_Violet"
    },
    {
      "x": 1,
      "y": 1,
      "z": -1,
      "name": "Plant_Coral_Block_Violet"
    },
    {
      "x": 1,
      "y": 2,
      "z": -1,
      "name": "Plant_Coral_Block_Violet"
    },
    {
      "x": 1,
      "y": 3,
      "z": -1,
      "name": "Plant_Coral_Bush_Violet"
    },
    {
      "x": 1,
      "y": 0,
      "z": 0,
      "name": "Plant_Coral_Block_Violet"
    },
    {
      "x": 1,
      "y": 1,
      "z": 0,
      "name": "Plant_Coral_Bush_Violet"
    },
    {
      "x": 1,
      "y": 0,
      "z": 1,
      "name": "Plant_Coral_Block_Violet"
    },
    {
      "x": 1,
      "y": 1,
      "z": 1,
      "name": "Plant_Coral_Block_Violet"
    },
    {
      "x": 1,
      "y": 2,
      "z": 1,
      "name": "Plant_Coral_Block_Violet"
    },
    {
      "x": 1,
      "y": 3,
      "z": 1,
      "name": "Plant_Coral_Block_Violet"
    },
    {
      "x": 1,
      "y": 0,
      "z": 2,
      "name": "Plant_Coral_Block_Violet"
    },
    {
      "x": 1,
      "y": 1,
      "z": 2,
      "name": "Plant_Coral_Block_Violet"
    },
    {
      "x": 1,
      "y": 2,
      "z": 2,
      "name": "Plant_Coral_Block_Violet"
    },
    {
      "x": 1,
      "y": 3,
      "z": 2,
      "name": "Plant_Coral_Block_Violet"
    },
    {
      "x": 1,
      "y": 4,
      "z": 2,
      "name": "Plant_Coral_Model_Violet"
    },
    {
      "x": 2,
      "y": 0,
      "z": 0,
      "name": "Plant_Coral_Block_Violet"
    },
    {
      "x": 2,
      "y": 1,
      "z": 0,
      "name": "Plant_Coral_Model_Violet"
    },
    {
      "x": 2,
      "y": 0,
      "z": 1,
      "name": "Plant_Coral_Block_Violet"
    },
    {
      "x": 2,
      "y": 1,
      "z": 1,
      "name": "Plant_Coral_Block_Violet"
    },
    {
      "x": 2,
      "y": 2,
      "z": 1,
      "name": "Plant_Coral_Block_Violet"
    },
    {
      "x": 2,
      "y": 3,
      "z": 1,
      "name": "Plant_Coral_Block_Violet"
    },
    {
      "x": 2,
      "y": 4,
      "z": 1,
      "name": "Plant_Coral_Bush_Violet"
    },
    {
      "x": 2,
      "y": 0,
      "z": 2,
      "name": "Plant_Coral_Block_Violet"
    },
    {
      "x": 2,
      "y": 1,
      "z": 2,
      "name": "Plant_Coral_Bush_Violet"
    },
    {
      "x": 2,
      "y": 2,
      "z": 2,
      "name": "Plant_Coral_Block_Violet"
    },
    {
      "x": 2,
      "y": 3,
      "z": 2,
      "name": "Plant_Coral_Block_Violet"
    }
  ]
}