{
  "version": 8,
  "blockIdVersion": 11,
  "anchorX": 0,
  "anchorY": 1,
  "anchorZ": 0,
  "blocks": [
    {
      "x": -1,
      "y": 1,
      "z": -1,
      "name": "Wood_Poisoned_Trunk_Full",
      "support": 15
    },
    {
      "x": -1,
      "y": 2,
      "z": -1,
      "name": "Wood_Poisoned_Trunk_Full",
      "support": 15
    },
    {
      "x": -1,
      "y": 0,
      "z": 0,
      "name": "Wood_Poisoned_Trunk_Full",
      "support": 15
    },
    {
      "x": -1,
      "y": 1,
      "z": 0,
      "name": "Wood_Poisoned_Trunk_Full",
      "support": 15
    },
    {
      "x": -1,
      "y": 2,
      "z": 0,
      "name": "Wood_Poisoned_Trunk_Full",
      "support": 15
    },
    {
      "x": -1,
      "y": 3,
      "z": 0,
      "name": "Wood_Poisoned_Trunk_Full",
      "support": 15
    },
    {
      "x": -1,
      "y": 4,
      "z": 0,
      "name": "Rock_Crystal_Red_Large",
      "rotation": 7
    },
    {
      "x": -1,
      "y": 5,
      "z": 0,
      "name": "Rock_Crystal_Red_Medium",
      "rotation": 7
    },
    {
      "x": -1,
      "y": 1,
      "z": 1,
      "name": "Wood_Poisoned_Trunk_Full",
      "support": 15
    },
    {
      "x": 0,
      "y": 0,
      "z": -1,
      "name": "Wood_Poisoned_Trunk_Full",
      "support": 15
    },
    {
      "x": 0,
      "y": 1,
      "z": -1,
      "name": "Wood_Poisoned_Trunk_Full",
      "support": 15
    },
    {
      "x": 0,
      "y": 2,
      "z": -1,
      "name": "Wood_Poisoned_Trunk_Full",
      "support": 15
    },
    {
      "x": 0,
      "y": 3,
      "z": -1,
      "name": "Rock_Crystal_Red_Block"
    },
    {
      "x": 0,
      "y": 4,
      "z": -1,
      "name": "Rock_Crystal_Red_Medium",
      "rotation": 6
    },
    {
      "x": 0,
      "y": 0,
      "z": 0,
      "name": "Wood_Poisoned_Trunk_Full",
      "support": 15
    },
    {
      "x": 0,
      "y": 1,
      "z": 0,
      "name": "Wood_Poisoned_Trunk_Full",
      "support": 15
    },
    {
      "x": 0,
      "y": 2,
      "z": 0,
      "name": "Wood_Poisoned_Trunk_Full",
      "support": 15
    },
    {
      "x": 0,
      "y": 3,
      "z": 0,
      "name": "Wood_Poisoned_Trunk_Full",
      "support": 15
    },
    {
      "x": 0,
      "y": 4,
      "z": 0,
      "name": "Rock_Crystal_Red_Block"
    },
    {
      "x": 0,
      "y": 5,
      "z": 0,
      "name": "Rock_Crystal_Red_Block"
    },
    {
      "x": 0,
      "y": 6,
      "z": 0,
      "name": "Rock_Crystal_Red_Block"
    },
    {
      "x": 0,
      "y": 7,
      "z": 0,
      "name": "Rock_Crystal_Red_Medium"
    },
    {
      "x": 0,
      "y": 0,
      "z": 1,
      "name": "Wood_Poisoned_Trunk_Full",
      "support": 15
    },
    {
      "x": 0,
      "y": 1,
      "z": 1,
      "name": "Wood_Poisoned_Trunk_Full",
      "support": 15
    },
    {
      "x": 0,
      "y": 2,
      "z": 1,
      "name": "Wood_Poisoned_Trunk_Full",
      "support": 15
    },
    {
      "x": 0,
      "y": 3,
      "z": 1,
      "name": "Rock_Crystal_Red_Block"
    },
    {
      "x": 0,
      "y": 4,
      "z": 1,
      "name": "Rock_Crystal_Red_Block"
    },
    {
      "x": 0,
      "y": 5,
      "z": 1,
      "name": "Rock_Crystal_Red_Medium",
      "rotation": 4
    },
    {
      "x": 1,
      "y": 1,
      "z": -1,
      "name": "Wood_Poisoned_Trunk_Full",
      "support": 15
    },
    {
      "x": 1,
      "y": 0,
      "z": 0,
      "name": "Wood_Poisoned_Trunk_Full",
      "support": 15
    },
    {
      "x": 1,
      "y": 1,
      "z": 0,
      "name": "Wood_Poisoned_Trunk_Full",
      "support": 15
    },
    {
      "x": 1,
      "y": 2,
      "z": 0,
      "name": "Wood_Poisoned_Trunk_Full",
      "support": 15
    },
    {
      "x": 1,
      "y": 3,
      "z": 0,
      "name": "Wood_Poisoned_Trunk_Half",
      "rotation": 5
    },
    {
      "x": 1,
      "y": 4,
      "z": 0,
      "name": "Rock_Crystal_Red_Medium",
      "rotation": 5
    },
    {
      "x": 1,
      "y": 1,
      "z": 1,
      "name": "Wood_Poisoned_Trunk_Full",
      "support": 15
    },
    {
      "x": 1,
      "y": 2,
      "z": 1,
      "name": "Wood_Poisoned_Trunk_Full",
      "support": 15
    },
    {
      "x": 1,
      "y": 3,
      "z": 1,
      "name": "Rock_Crystal_Red_Block"
    }
  ]
}