{
  "version": 8,
  "blockIdVersion": 11,
  "anchorX": -3,
  "anchorY": 9,
  "anchorZ": -3,
  "blocks": [
    {
      "x": -9,
      "y": 6,
      "z": -7,
      "name": "Soil_Clay_Pink"
    },
    {
      "x": -9,
      "y": 7,
      "z": -7,
      "name": "Soil_Clay_Pink"
    },
    {
      "x": -9,
      "y": 8,
      "z": -7,
      "name": "Soil_Clay_Red"
    },
    {
      "x": -9,
      "y": 9,
      "z": -7,
      "name": "Soil_Snow"
    },
    {
      "x": -9,
      "y": 6,
      "z": -6,
      "name": "Soil_Clay_Pink"
    },
    {
      "x": -9,
      "y": 7,
      "z": -6,
      "name": "Soil_Clay_Pink"
    },
    {
      "x": -9,
      "y": 8,
      "z": -6,
      "name": "Soil_Clay_Red"
    },
    {
      "x": -9,
      "y": 9,
      "z": -6,
      "name": "Soil_Snow"
    },
    {
      "x": -9,
      "y": 0,
      "z": -5,
      "name": "Rock_Sandstone_Red"
    },
    {
      "x": -9,
      "y": 1,
      "z": -5,
      "name": "Rock_Sandstone_Red"
    },
    {
      "x": -9,
      "y": 2,
      "z": -5,
      "name": "Soil_Clay_Red"
    },
    {
      "x": -9,
      "y": 3,
      "z": -5,
      "name": "Rock_Sandstone_Red"
    },
    {
      "x": -9,
      "y": 4,
      "z": -5,
      "name": "Soil_Clay_Red"
    },
    {
      "x": -9,
      "y": 5,
      "z": -5,
      "name": "Soil_Clay_Pink"
    },
    {
      "x": -9,
      "y": 6,
      "z": -5,
      "name": "Soil_Clay_Pink"
    },
    {
      "x": -9,
      "y": 7,
      "z": -5,
      "name": "Soil_Clay_Pink"
    },
    {
      "x": -9,
      "y": 8,
      "z": -5,
      "name": "Soil_Clay_Red"
    },
    {
      "x": -9,
      "y": 9,
      "z": -5,
      "name": "Soil_Snow"
    },
    {
      "x": -9,
      "y": 0,
      "z": -4,
      "name": "Rock_Sandstone_Red"
    },
    {
      "x": -9,
      "y": 1,
      "z": -4,
      "name": "Rock_Sandstone_Red"
    },
    {
      "x": -9,
      "y": 2,
      "z": -4,
      "name": "Soil_Clay_Red"
    },
    {
      "x": -9,
      "y": 3,
      "z": -4,
      "name": "Rock_Sandstone_Red"
    },
    {
      "x": -9,
      "y": 4,
      "z": -4,
      "name": "Soil_Clay_Red"
    },
    {
      "x": -9,
      "y": 5,
      "z": -4,
      "name": "Soil_Clay_Pink"
    },
    {
      "x": -9,
      "y": 6,
      "z": -4,
      "name": "Soil_Clay_Pink"
    },
    {
      "x": -9,
      "y": 7,
      "z": -4,
      "name": "Soil_Clay_Pink"
    },
    {
      "x": -9,
      "y": 8,
      "z": -4,
      "name": "Soil_Clay_Red"
    },
    {
      "x": -9,
      "y": 9,
      "z": -4,
      "name": "Soil_Snow"
    },
    {
      "x": -9,
      "y": 0,
      "z": -3,
      "name": "Rock_Sandstone_Red"
    },
    {
      "x": -9,
      "y": 1,
      "z": -3,
      "name": "Rock_Sandstone_Red"
    },
    {
      "x": -9,
      "y": 2,
      "z": -3,
      "name": "Soil_Clay_Red"
    },
    {
      "x": -9,
      "y": 3,
      "z": -3,
      "name": "Rock_Sandstone_Red"
    },
    {
      "x": -9,
      "y": 6,
      "z": -3,
      "name": "Soil_Clay_Pink"
    },
    {
      "x": -9,
      "y": 7,
      "z": -3,
      "name": "Soil_Clay_Red"
    },
    {
      "x": -9,
      "y": 8,
      "z": -3,
      "name": "Soil_Clay_Red"
    },
    {
      "x": -9,
      "y": 9,
      "z": -3,
      "name": "Soil_Snow"
    },
    {
      "x": -9,
      "y": 7,
      "z": -2,
      "name": "Soil_Clay_Red"
    },
    {
      "x": -9,
      "y": 8,
      "z": -2,
      "name": "Soil_Clay_Red"
    },
    {
      "x": -9,
      "y": 9,
      "z": -2,
      "name": "Soil_Snow"
    },
    {
      "x": -9,
      "y": 6,
      "z": 2,
      "name": "Soil_Clay_Red"
    },
    {
      "x": -9,
      "y": 7,
      "z": 2,
      "name": "Soil_Clay_Red"
    },
    {
      "x": -9,
      "y": 8,
      "z": 2,
      "name": "Soil_Snow"
    },
    {
      "x": -9,
      "y": 4,
      "z": 3,
      "name": "Soil_Clay_Red"
    },
    {
      "x": -9,
      "y": 5,
      "z": 3,
      "name": "Soil_Clay_Red"
    },
    {
      "x": -9,
      "y": 6,
      "z": 3,
      "name": "Soil_Clay_Red"
    },
    {
      "x": -9,
      "y": 7,
      "z": 3,
      "name": "Soil_Clay_Red"
    },
    {
      "x": -9,
      "y": 8,
      "z": 3,
      "name": "Soil_Snow"
    },
    {
      "x": -9,
      "y": 9,
      "z": 3,
      "name": "Plant_Grass_Sky_Snowy_Tall",
      "support": 15
    },
    {
      "x": -9,
      "y": 10,
      "z": 3,
      "name": "Plant_Grass_Sky_Snowy_Tall",
      "filler": 1024
    },
    {
      "x": -8,
      "y": 6,
      "z": -8,
      "name": "Soil_Clay_Pink"
    },
    {
      "x": -8,
      "y": 7,
      "z": -8,
      "name": "Soil_Clay_Pink"
    },
    {
      "x": -8,
      "y": 8,
      "z": -8,
      "name": "Soil_Clay_Red"
    },
    {
      "x": -8,
      "y": 9,
      "z": -8,
      "name": "Soil_Snow"
    },
    {
      "x": -8,
      "y": 4,
      "z": -7,
      "name": "Soil_Clay_Red"
    },
    {
      "x": -8,
      "y": 5,
      "z": -7,
      "name": "Soil_Clay_Pink"
    },
    {
      "x": -8,
      "y": 6,
      "z": -7,
      "name": "Soil_Clay_Pink"
    },
    {
      "x": -8,
      "y": 7,
      "z": -7,
      "name": "Soil_Clay_Pink"
    },
    {
      "x": -8,
      "y": 8,
      "z": -7,
      "name": "Soil_Clay_Red"
    },
    {
      "x": -8,
      "y": 9,
      "z": -7,
      "name": "Soil_Snow"
    },
    {
      "x": -8,
      "y": 0,
      "z": -6,
      "name": "Rock_Sandstone_Red"
    },
    {
      "x": -8,
      "y": 1,
      "z": -6,
      "name": "Rock_Sandstone_Red"
    },
    {
      "x": -8,
      "y": 2,
      "z": -6,
      "name": "Soil_Clay_Red"
    },
    {
      "x": -8,
      "y": 3,
      "z": -6,
      "name": "Rock_Sandstone_Red"
    },
    {
      "x": -8,
      "y": 4,
      "z": -6,
      "name": "Soil_Clay_Red"
    },
    {
      "x": -8,
      "y": 5,
      "z": -6,
      "name": "Soil_Clay_Pink"
    },
    {
      "x": -8,
      "y": 6,
      "z": -6,
      "name": "Soil_Clay_Pink"
    },
    {
      "x": -8,
      "y": 7,
      "z": -6,
      "name": "Soil_Clay_Pink"
    },
    {
      "x": -8,
      "y": 8,
      "z": -6,
      "name": "Soil_Clay_Red"
    },
    {
      "x": -8,
      "y": 9,
      "z": -6,
      "name": "Soil_Snow"
    },
    {
      "x": -8,
      "y": 0,
      "z": -5,
      "name": "Rock_Sandstone_Red"
    },
    {
      "x": -8,
      "y": 1,
      "z": -5,
      "name": "Rock_Sandstone_Red"
    },
    {
      "x": -8,
      "y": 2,
      "z": -5,
      "name": "Soil_Clay_Red"
    },
    {
      "x": -8,
      "y": 3,
      "z": -5,
      "name": "Rock_Sandstone_Red"
    },
    {
      "x": -8,
      "y": 4,
      "z": -5,
      "name": "Soil_Clay_Red"
    },
    {
      "x": -8,
      "y": 5,
      "z": -5,
      "name": "Soil_Clay_Pink"
    },
    {
      "x": -8,
      "y": 6,
      "z": -5,
      "name": "Soil_Clay_Pink"
    },
    {
      "x": -8,
      "y": 7,
      "z": -5,
      "name": "Soil_Clay_Pink"
    },
    {
      "x": -8,
      "y": 8,
      "z": -5,
      "name": "Soil_Clay_Red"
    },
    {
      "x": -8,
      "y": 9,
      "z": -5,
      "name": "Soil_Snow"
    },
    {
      "x": -8,
      "y": 10,
      "z": -5,
      "name": "Plant_Grass_Sky_Snowy_Tall",
      "support": 15
    },
    {
      "x": -8,
      "y": 11,
      "z": -5,
      "name": "Plant_Grass_Sky_Snowy_Tall",
      "filler": 1024
    },
    {
      "x": -8,
      "y": 0,
      "z": -4,
      "name": "Rock_Sandstone_Red"
    },
    {
      "x": -8,
      "y": 1,
      "z": -4,
      "name": "Rock_Sandstone_Red"
    },
    {
      "x": -8,
      "y": 2,
      "z": -4,
      "name": "Soil_Clay_Red"
    },
    {
      "x": -8,
      "y": 3,
      "z": -4,
      "name": "Rock_Sandstone_Red"
    },
    {
      "x": -8,
      "y": 4,
      "z": -4,
      "name": "Soil_Clay_Red"
    },
    {
      "x": -8,
      "y": 5,
      "z": -4,
      "name": "Soil_Clay_Pink"
    },
    {
      "x": -8,
      "y": 6,
      "z": -4,
      "name": "Soil_Clay_Pink"
    },
    {
      "x": -8,
      "y": 7,
      "z": -4,
      "name": "Soil_Clay_Pink"
    },
    {
      "x": -8,
      "y": 8,
      "z": -4,
      "name": "Soil_Clay_Red"
    },
    {
      "x": -8,
      "y": 9,
      "z": -4,
      "name": "Soil_Snow"
    },
    {
      "x": -8,
      "y": 0,
      "z": -3,
      "name": "Rock_Sandstone_Red"
    },
    {
      "x": -8,
      "y": 1,
      "z": -3,
      "name": "Rock_Sandstone_Red"
    },
    {
      "x": -8,
      "y": 2,
      "z": -3,
      "name": "Soil_Clay_Red"
    },
    {
      "x": -8,
      "y": 3,
      "z": -3,
      "name": "Rock_Sandstone_Red"
    },
    {
      "x": -8,
      "y": 4,
      "z": -3,
      "name": "Soil_Clay_Red"
    },
    {
      "x": -8,
      "y": 5,
      "z": -3,
      "name": "Soil_Clay_Pink"
    },
    {
      "x": -8,
      "y": 6,
      "z": -3,
      "name": "Soil_Clay_Pink"
    },
    {
      "x": -8,
      "y": 7,
      "z": -3,
      "name": "Soil_Clay_Red"
    },
    {
      "x": -8,
      "y": 8,
      "z": -3,
      "name": "Soil_Clay_Red"
    },
    {
      "x": -8,
      "y": 9,
      "z": -3,
      "name": "Soil_Snow"
    },
    {
      "x": -8,
      "y": 10,
      "z": -3,
      "name": "Plant_Grass_Sky_Snowy_Short",
      "support": 15
    },
    {
      "x": -8,
      "y": 0,
      "z": -2,
      "name": "Rock_Sandstone_Red"
    },
    {
      "x": -8,
      "y": 1,
      "z": -2,
      "name": "Rock_Sandstone_Red"
    },
    {
      "x": -8,
      "y": 2,
      "z": -2,
      "name": "Soil_Clay_Red"
    },
    {
      "x": -8,
      "y": 3,
      "z": -2,
      "name": "Rock_Sandstone_Red"
    },
    {
      "x": -8,
      "y": 4,
      "z": -2,
      "name": "Soil_Clay_Red"
    },
    {
      "x": -8,
      "y": 5,
      "z": -2,
      "name": "Soil_Clay_Pink"
    },
    {
      "x": -8,
      "y": 6,
      "z": -2,
      "name": "Soil_Clay_Pink"
    },
    {
      "x": -8,
      "y": 7,
      "z": -2,
      "name": "Soil_Clay_Red"
    },
    {
      "x": -8,
      "y": 8,
      "z": -2,
      "name": "Soil_Clay_Red"
    },
    {
      "x": -8,
      "y": 9,
      "z": -2,
      "name": "Soil_Snow"
    },
    {
      "x": -8,
      "y": 10,
      "z": -2,
      "name": "Plant_Crop_Mushroom_Cap_White",
      "components": {
        "Components": {
          "FarmingBlock": {
            "LastTickGameTime": "0001-01-01T12:00:00Z"
          },
          "PlacedByInteraction": {
            "WhoPlacedUuid": {
              "$binary": "rmwkrpH8RVykTc7XnK4YBA==",
              "$type": "04"
            }
          }
        }
      }
    },
    {
      "x": -8,
      "y": 6,
      "z": -1,
      "name": "Soil_Clay_Red"
    },
    {
      "x": -8,
      "y": 7,
      "z": -1,
      "name": "Soil_Clay_Red"
    },
    {
      "x": -8,
      "y": 8,
      "z": -1,
      "name": "Soil_Clay_Red"
    },
    {
      "x": -8,
      "y": 9,
      "z": -1,
      "name": "Soil_Snow"
    },
    {
      "x": -8,
      "y": 2,
      "z": 3,
      "name": "Soil_Clay_Red"
    },
    {
      "x": -8,
      "y": 3,
      "z": 3,
      "name": "Soil_Clay_Red"
    },
    {
      "x": -8,
      "y": 4,
      "z": 3,
      "name": "Soil_Clay_Red"
    },
    {
      "x": -8,
      "y": 5,
      "z": 3,
      "name": "Soil_Clay_Red"
    },
    {
      "x": -8,
      "y": 6,
      "z": 3,
      "name": "Soil_Clay_Red"
    },
    {
      "x": -8,
      "y": 7,
      "z": 3,
      "name": "Soil_Clay_Red"
    },
    {
      "x": -8,
      "y": 8,
      "z": 3,
      "name": "Soil_Snow"
    },
    {
      "x": -8,
      "y": 5,
      "z": 4,
      "name": "Soil_Clay_Red"
    },
    {
      "x": -8,
      "y": 6,
      "z": 4,
      "name": "Soil_Clay_Red"
    },
    {
      "x": -8,
      "y": 7,
      "z": 4,
      "name": "Soil_Clay_Red"
    },
    {
      "x": -8,
      "y": 8,
      "z": 4,
      "name": "Soil_Snow"
    },
    {
      "x": -7,
      "y": 7,
      "z": -9,
      "name": "Soil_Clay_Pink"
    },
    {
      "x": -7,
      "y": 8,
      "z": -9,
      "name": "Soil_Clay_Red"
    },
    {
      "x": -7,
      "y": 9,
      "z": -9,
      "name": "Soil_Snow"
    },
    {
      "x": -7,
      "y": 4,
      "z": -8,
      "name": "Soil_Clay_Red"
    },
    {
      "x": -7,
      "y": 5,
      "z": -8,
      "name": "Soil_Clay_Pink"
    },
    {
      "x": -7,
      "y": 6,
      "z": -8,
      "name": "Soil_Clay_Pink"
    },
    {
      "x": -7,
      "y": 7,
      "z": -8,
      "name": "Soil_Clay_Pink"
    },
    {
      "x": -7,
      "y": 8,
      "z": -8,
      "name": "Soil_Clay_Red"
    },
    {
      "x": -7,
      "y": 9,
      "z": -8,
      "name": "Soil_Snow"
    },
    {
      "x": -7,
      "y": 4,
      "z": -7,
      "name": "Soil_Clay_Red"
    },
    {
      "x": -7,
      "y": 5,
      "z": -7,
      "name": "Soil_Clay_Pink"
    },
    {
      "x": -7,
      "y": 6,
      "z": -7,
      "name": "Soil_Clay_Pink"
    },
    {
      "x": -7,
      "y": 7,
      "z": -7,
      "name": "Soil_Clay_Pink"
    },
    {
      "x": -7,
      "y": 8,
      "z": -7,
      "name": "Soil_Clay_Red"
    },
    {
      "x": -7,
      "y": 9,
      "z": -7,
      "name": "Soil_Snow"
    },
    {
      "x": -7,
      "y": 0,
      "z": -6,
      "name": "Rock_Sandstone_Red"
    },
    {
      "x": -7,
      "y": 1,
      "z": -6,
      "name": "Rock_Sandstone_Red"
    },
    {
      "x": -7,
      "y": 2,
      "z": -6,
      "name": "Soil_Clay_Red"
    },
    {
      "x": -7,
      "y": 3,
      "z": -6,
      "name": "Soil_Clay_Red"
    },
    {
      "x": -7,
      "y": 4,
      "z": -6,
      "name": "Soil_Clay_Red"
    },
    {
      "x": -7,
      "y": 5,
      "z": -6,
      "name": "Soil_Clay_Pink"
    },
    {
      "x": -7,
      "y": 6,
      "z": -6,
      "name": "Soil_Clay_Pink"
    },
    {
      "x": -7,
      "y": 7,
      "z": -6,
      "name": "Soil_Clay_Pink"
    },
    {
      "x": -7,
      "y": 8,
      "z": -6,
      "name": "Soil_Clay_Red"
    },
    {
      "x": -7,
      "y": 9,
      "z": -6,
      "name": "Soil_Snow"
    },
    {
      "x": -7,
      "y": 10,
      "z": -6,
      "name": "Soil_Snow"
    },
    {
      "x": -7,
      "y": 0,
      "z": -5,
      "name": "Rock_Sandstone_Red"
    },
    {
      "x": -7,
      "y": 1,
      "z": -5,
      "name": "Rock_Sandstone_Red"
    },
    {
      "x": -7,
      "y": 2,
      "z": -5,
      "name": "Soil_Clay_Red"
    },
    {
      "x": -7,
      "y": 3,
      "z": -5,
      "name": "Rock_Sandstone_Red"
    },
    {
      "x": -7,
      "y": 4,
      "z": -5,
      "name": "Soil_Clay_Red"
    },
    {
      "x": -7,
      "y": 5,
      "z": -5,
      "name": "Soil_Clay_Pink"
    },
    {
      "x": -7,
      "y": 6,
      "z": -5,
      "name": "Soil_Clay_Pink"
    },
    {
      "x": -7,
      "y": 7,
      "z": -5,
      "name": "Soil_Clay_Pink"
    },
    {
      "x": -7,
      "y": 8,
      "z": -5,
      "name": "Soil_Clay_Red"
    },
    {
      "x": -7,
      "y": 9,
      "z": -5,
      "name": "Soil_Snow"
    },
    {
      "x": -7,
      "y": 10,
      "z": -5,
      "name": "Soil_Snow"
    },
    {
      "x": -7,
      "y": 0,
      "z": -4,
      "name": "Rock_Sandstone_Red"
    },
    {
      "x": -7,
      "y": 1,
      "z": -4,
      "name": "Rock_Sandstone_Red"
    },
    {
      "x": -7,
      "y": 2,
      "z": -4,
      "name": "Soil_Clay_Red"
    },
    {
      "x": -7,
      "y": 3,
      "z": -4,
      "name": "Rock_Sandstone_Red"
    },
    {
      "x": -7,
      "y": 4,
      "z": -4,
      "name": "Soil_Clay_Red"
    },
    {
      "x": -7,
      "y": 5,
      "z": -4,
      "name": "Soil_Clay_Pink"
    },
    {
      "x": -7,
      "y": 6,
      "z": -4,
      "name": "Soil_Clay_Pink"
    },
    {
      "x": -7,
      "y": 7,
      "z": -4,
      "name": "Soil_Clay_Pink"
    },
    {
      "x": -7,
      "y": 8,
      "z": -4,
      "name": "Soil_Clay_Red"
    },
    {
      "x": -7,
      "y": 9,
      "z": -4,
      "name": "Soil_Snow"
    },
    {
      "x": -7,
      "y": 0,
      "z": -3,
      "name": "Rock_Sandstone_Red"
    },
    {
      "x": -7,
      "y": 1,
      "z": -3,
      "name": "Rock_Sandstone_Red"
    },
    {
      "x": -7,
      "y": 2,
      "z": -3,
      "name": "Soil_Clay_Red"
    },
    {
      "x": -7,
      "y": 3,
      "z": -3,
      "name": "Rock_Sandstone_Red"
    },
    {
      "x": -7,
      "y": 4,
      "z": -3,
      "name": "Soil_Clay_Red"
    },
    {
      "x": -7,
      "y": 5,
      "z": -3,
      "name": "Soil_Clay_Pink"
    },
    {
      "x": -7,
      "y": 6,
      "z": -3,
      "name": "Soil_Clay_Pink"
    },
    {
      "x": -7,
      "y": 7,
      "z": -3,
      "name": "Soil_Clay_Red"
    },
    {
      "x": -7,
      "y": 8,
      "z": -3,
      "name": "Soil_Clay_Red"
    },
    {
      "x": -7,
      "y": 9,
      "z": -3,
      "name": "Soil_Snow"
    },
    {
      "x": -7,
      "y": 0,
      "z": -2,
      "name": "Rock_Sandstone_Red"
    },
    {
      "x": -7,
      "y": 1,
      "z": -2,
      "name": "Rock_Sandstone_Red"
    },
    {
      "x": -7,
      "y": 2,
      "z": -2,
      "name": "Soil_Clay_Red"
    },
    {
      "x": -7,
      "y": 3,
      "z": -2,
      "name": "Rock_Sandstone_Red"
    },
    {
      "x": -7,
      "y": 4,
      "z": -2,
      "name": "Soil_Clay_Red"
    },
    {
      "x": -7,
      "y": 5,
      "z": -2,
      "name": "Soil_Clay_Pink"
    },
    {
      "x": -7,
      "y": 6,
      "z": -2,
      "name": "Soil_Clay_Pink"
    },
    {
      "x": -7,
      "y": 7,
      "z": -2,
      "name": "Soil_Clay_Red"
    },
    {
      "x": -7,
      "y": 8,
      "z": -2,
      "name": "Soil_Clay_Red"
    },
    {
      "x": -7,
      "y": 9,
      "z": -2,
      "name": "Soil_Snow"
    },
    {
      "x": -7,
      "y": 4,
      "z": -1,
      "name": "Soil_Clay_Red"
    },
    {
      "x": -7,
      "y": 5,
      "z": -1,
      "name": "Soil_Clay_Red"
    },
    {
      "x": -7,
      "y": 6,
      "z": -1,
      "name": "Soil_Clay_Red"
    },
    {
      "x": -7,
      "y": 7,
      "z": -1,
      "name": "Soil_Clay_Red"
    },
    {
      "x": -7,
      "y": 8,
      "z": -1,
      "name": "Soil_Clay_Red"
    },
    {
      "x": -7,
      "y": 9,
      "z": -1,
      "name": "Soil_Snow"
    },
    {
      "x": -7,
      "y": 4,
      "z": 0,
      "name": "Soil_Clay_Red"
    },
    {
      "x": -7,
      "y": 5,
      "z": 0,
      "name": "Soil_Snow"
    },
    {
      "x": -7,
      "y": 7,
      "z": 0,
      "name": "Soil_Clay_Red"
    },
    {
      "x": -7,
      "y": 8,
      "z": 0,
      "name": "Soil_Clay_Red"
    },
    {
      "x": -7,
      "y": 9,
      "z": 0,
      "name": "Soil_Snow"
    },
    {
      "x": -7,
      "y": 4,
      "z": 1,
      "name": "Rock_Sandstone_Red"
    },
    {
      "x": -7,
      "y": 5,
      "z": 1,
      "name": "Soil_Snow"
    },
    {
      "x": -7,
      "y": 6,
      "z": 4,
      "name": "Soil_Clay_Red"
    },
    {
      "x": -7,
      "y": 7,
      "z": 4,
      "name": "Soil_Clay_Red"
    },
    {
      "x": -7,
      "y": 8,
      "z": 4,
      "name": "Soil_Snow"
    },
    {
      "x": -6,
      "y": 7,
      "z": -9,
      "name": "Soil_Clay_Pink"
    },
    {
      "x": -6,
      "y": 8,
      "z": -9,
      "name": "Soil_Clay_Red"
    },
    {
      "x": -6,
      "y": 9,
      "z": -9,
      "name": "Soil_Snow"
    },
    {
      "x": -6,
      "y": 4,
      "z": -8,
      "name": "Soil_Clay_Red"
    },
    {
      "x": -6,
      "y": 5,
      "z": -8,
      "name": "Soil_Clay_Pink"
    },
    {
      "x": -6,
      "y": 6,
      "z": -8,
      "name": "Soil_Clay_Pink"
    },
    {
      "x": -6,
      "y": 7,
      "z": -8,
      "name": "Soil_Clay_Pink"
    },
    {
      "x": -6,
      "y": 8,
      "z": -8,
      "name": "Soil_Clay_Red"
    },
    {
      "x": -6,
      "y": 9,
      "z": -8,
      "name": "Soil_Snow"
    },
    {
      "x": -6,
      "y": 10,
      "z": -8,
      "name": "Plant_Grass_Sky_Snowy_Short",
      "support": 15
    },
    {
      "x": -6,
      "y": 4,
      "z": -7,
      "name": "Soil_Clay_Red"
    },
    {
      "x": -6,
      "y": 5,
      "z": -7,
      "name": "Soil_Clay_Pink"
    },
    {
      "x": -6,
      "y": 6,
      "z": -7,
      "name": "Soil_Clay_Pink"
    },
    {
      "x": -6,
      "y": 7,
      "z": -7,
      "name": "Soil_Clay_Pink"
    },
    {
      "x": -6,
      "y": 8,
      "z": -7,
      "name": "Soil_Clay_Red"
    },
    {
      "x": -6,
      "y": 9,
      "z": -7,
      "name": "Soil_Snow"
    },
    {
      "x": -6,
      "y": 10,
      "z": -7,
      "name": "Soil_Snow"
    },
    {
      "x": -6,
      "y": 0,
      "z": -6,
      "name": "Rock_Sandstone_Red"
    },
    {
      "x": -6,
      "y": 1,
      "z": -6,
      "name": "Rock_Sandstone_Red"
    },
    {
      "x": -6,
      "y": 2,
      "z": -6,
      "name": "Soil_Clay_Red"
    },
    {
      "x": -6,
      "y": 3,
      "z": -6,
      "name": "Soil_Clay_Red"
    },
    {
      "x": -6,
      "y": 4,
      "z": -6,
      "name": "Soil_Clay_Red"
    },
    {
      "x": -6,
      "y": 5,
      "z": -6,
      "name": "Soil_Clay_Pink"
    },
    {
      "x": -6,
      "y": 6,
      "z": -6,
      "name": "Soil_Clay_Pink"
    },
    {
      "x": -6,
      "y": 7,
      "z": -6,
      "name": "Soil_Clay_Pink"
    },
    {
      "x": -6,
      "y": 8,
      "z": -6,
      "name": "Soil_Clay_Red"
    },
    {
      "x": -6,
      "y": 9,
      "z": -6,
      "name": "Soil_Snow"
    },
    {
      "x": -6,
      "y": 10,
      "z": -6,
      "name": "Soil_Snow"
    },
    {
      "x": -6,
      "y": 0,
      "z": -5,
      "name": "Rock_Sandstone_Red"
    },
    {
      "x": -6,
      "y": 1,
      "z": -5,
      "name": "Rock_Sandstone_Red"
    },
    {
      "x": -6,
      "y": 2,
      "z": -5,
      "name": "Soil_Clay_Red"
    },
    {
      "x": -6,
      "y": 3,
      "z": -5,
      "name": "Soil_Clay_Red"
    },
    {
      "x": -6,
      "y": 4,
      "z": -5,
      "name": "Soil_Clay_Red"
    },
    {
      "x": -6,
      "y": 5,
      "z": -5,
      "name": "Soil_Clay_Pink"
    },
    {
      "x": -6,
      "y": 6,
      "z": -5,
      "name": "Soil_Clay_Pink"
    },
    {
      "x": -6,
      "y": 7,
      "z": -5,
      "name": "Soil_Clay_Pink"
    },
    {
      "x": -6,
      "y": 8,
      "z": -5,
      "name": "Soil_Clay_Red"
    },
    {
      "x": -6,
      "y": 9,
      "z": -5,
      "name": "Soil_Snow"
    },
    {
      "x": -6,
      "y": 0,
      "z": -4,
      "name": "Rock_Sandstone_Red"
    },
    {
      "x": -6,
      "y": 1,
      "z": -4,
      "name": "Rock_Sandstone_Red"
    },
    {
      "x": -6,
      "y": 2,
      "z": -4,
      "name": "Soil_Clay_Red"
    },
    {
      "x": -6,
      "y": 3,
      "z": -4,
      "name": "Soil_Clay_Red"
    },
    {
      "x": -6,
      "y": 4,
      "z": -4,
      "name": "Soil_Clay_Red"
    },
    {
      "x": -6,
      "y": 5,
      "z": -4,
      "name": "Soil_Clay_Pink"
    },
    {
      "x": -6,
      "y": 6,
      "z": -4,
      "name": "Soil_Clay_Pink"
    },
    {
      "x": -6,
      "y": 7,
      "z": -4,
      "name": "Soil_Clay_Pink"
    },
    {
      "x": -6,
      "y": 8,
      "z": -4,
      "name": "Soil_Clay_Red"
    },
    {
      "x": -6,
      "y": 9,
      "z": -4,
      "name": "Soil_Snow"
    },
    {
      "x": -6,
      "y": 0,
      "z": -3,
      "name": "Rock_Sandstone_Red"
    },
    {
      "x": -6,
      "y": 1,
      "z": -3,
      "name": "Rock_Sandstone_Red"
    },
    {
      "x": -6,
      "y": 2,
      "z": -3,
      "name": "Soil_Clay_Red"
    },
    {
      "x": -6,
      "y": 3,
      "z": -3,
      "name": "Soil_Clay_Red"
    },
    {
      "x": -6,
      "y": 4,
      "z": -3,
      "name": "Soil_Clay_Red"
    },
    {
      "x": -6,
      "y": 5,
      "z": -3,
      "name": "Soil_Clay_Pink"
    },
    {
      "x": -6,
      "y": 6,
      "z": -3,
      "name": "Soil_Clay_Pink"
    },
    {
      "x": -6,
      "y": 7,
      "z": -3,
      "name": "Soil_Clay_Red"
    },
    {
      "x": -6,
      "y": 8,
      "z": -3,
      "name": "Soil_Clay_Red"
    },
    {
      "x": -6,
      "y": 9,
      "z": -3,
      "name": "Soil_Snow"
    },
    {
      "x": -6,
      "y": 0,
      "z": -2,
      "name": "Rock_Sandstone_Red"
    },
    {
      "x": -6,
      "y": 1,
      "z": -2,
      "name": "Rock_Sandstone_Red"
    },
    {
      "x": -6,
      "y": 2,
      "z": -2,
      "name": "Soil_Clay_Red"
    },
    {
      "x": -6,
      "y": 3,
      "z": -2,
      "name": "Soil_Clay_Red"
    },
    {
      "x": -6,
      "y": 4,
      "z": -2,
      "name": "Soil_Clay_Red"
    },
    {
      "x": -6,
      "y": 5,
      "z": -2,
      "name": "Soil_Clay_Pink"
    },
    {
      "x": -6,
      "y": 6,
      "z": -2,
      "name": "Soil_Clay_Red"
    },
    {
      "x": -6,
      "y": 7,
      "z": -2,
      "name": "Soil_Clay_Red"
    },
    {
      "x": -6,
      "y": 8,
      "z": -2,
      "name": "Soil_Clay_Red"
    },
    {
      "x": -6,
      "y": 9,
      "z": -2,
      "name": "Soil_Snow"
    },
    {
      "x": -6,
      "y": 4,
      "z": -1,
      "name": "Soil_Clay_Red"
    },
    {
      "x": -6,
      "y": 5,
      "z": -1,
      "name": "Soil_Clay_Red"
    },
    {
      "x": -6,
      "y": 6,
      "z": -1,
      "name": "Soil_Clay_Red"
    },
    {
      "x": -6,
      "y": 7,
      "z": -1,
      "name": "Soil_Clay_Red"
    },
    {
      "x": -6,
      "y": 8,
      "z": -1,
      "name": "Soil_Clay_Red"
    },
    {
      "x": -6,
      "y": 9,
      "z": -1,
      "name": "Soil_Snow"
    },
    {
      "x": -6,
      "y": 10,
      "z": -1,
      "name": "Plant_Grass_Sky_Snowy_Tall",
      "support": 15
    },
    {
      "x": -6,
      "y": 11,
      "z": -1,
      "name": "Plant_Grass_Sky_Snowy_Tall",
      "filler": 1024
    },
    {
      "x": -6,
      "y": 4,
      "z": 0,
      "name": "Rock_Sandstone_Red"
    },
    {
      "x": -6,
      "y": 5,
      "z": 0,
      "name": "Soil_Clay_Red"
    },
    {
      "x": -6,
      "y": 6,
      "z": 0,
      "name": "Soil_Clay_Red"
    },
    {
      "x": -6,
      "y": 7,
      "z": 0,
      "name": "Soil_Clay_Red"
    },
    {
      "x": -6,
      "y": 8,
      "z": 0,
      "name": "Soil_Clay_Red"
    },
    {
      "x": -6,
      "y": 9,
      "z": 0,
      "name": "Soil_Snow"
    },
    {
      "x": -6,
      "y": 4,
      "z": 1,
      "name": "Rock_Sandstone_Red"
    },
    {
      "x": -6,
      "y": 5,
      "z": 1,
      "name": "Soil_Snow"
    },
    {
      "x": -6,
      "y": 4,
      "z": 2,
      "name": "Rock_Sandstone_Red"
    },
    {
      "x": -6,
      "y": 5,
      "z": 2,
      "name": "Soil_Snow"
    },
    {
      "x": -5,
      "y": 7,
      "z": -9,
      "name": "Soil_Clay_Pink"
    },
    {
      "x": -5,
      "y": 8,
      "z": -9,
      "name": "Soil_Clay_Red"
    },
    {
      "x": -5,
      "y": 9,
      "z": -9,
      "name": "Soil_Snow"
    },
    {
      "x": -5,
      "y": 7,
      "z": -8,
      "name": "Soil_Clay_Pink"
    },
    {
      "x": -5,
      "y": 8,
      "z": -8,
      "name": "Soil_Clay_Red"
    },
    {
      "x": -5,
      "y": 9,
      "z": -8,
      "name": "Soil_Snow"
    },
    {
      "x": -5,
      "y": 4,
      "z": -7,
      "name": "Soil_Clay_Red"
    },
    {
      "x": -5,
      "y": 5,
      "z": -7,
      "name": "Soil_Clay_Pink"
    },
    {
      "x": -5,
      "y": 6,
      "z": -7,
      "name": "Soil_Clay_Pink"
    },
    {
      "x": -5,
      "y": 7,
      "z": -7,
      "name": "Soil_Clay_Pink"
    },
    {
      "x": -5,
      "y": 8,
      "z": -7,
      "name": "Soil_Clay_Red"
    },
    {
      "x": -5,
      "y": 9,
      "z": -7,
      "name": "Soil_Snow"
    },
    {
      "x": -5,
      "y": 10,
      "z": -7,
      "name": "Soil_Snow"
    },
    {
      "x": -5,
      "y": 4,
      "z": -6,
      "name": "Soil_Clay_Red"
    },
    {
      "x": -5,
      "y": 5,
      "z": -6,
      "name": "Soil_Clay_Pink"
    },
    {
      "x": -5,
      "y": 6,
      "z": -6,
      "name": "Soil_Clay_Pink"
    },
    {
      "x": -5,
      "y": 7,
      "z": -6,
      "name": "Soil_Clay_Pink"
    },
    {
      "x": -5,
      "y": 8,
      "z": -6,
      "name": "Soil_Clay_Red"
    },
    {
      "x": -5,
      "y": 9,
      "z": -6,
      "name": "Soil_Snow"
    },
    {
      "x": -5,
      "y": 10,
      "z": -6,
      "name": "Soil_Snow"
    },
    {
      "x": -5,
      "y": 0,
      "z": -5,
      "name": "Rock_Sandstone_Red"
    },
    {
      "x": -5,
      "y": 1,
      "z": -5,
      "name": "Rock_Sandstone_Red"
    },
    {
      "x": -5,
      "y": 2,
      "z": -5,
      "name": "Soil_Clay_Red"
    },
    {
      "x": -5,
      "y": 3,
      "z": -5,
      "name": "Soil_Clay_Red"
    },
    {
      "x": -5,
      "y": 4,
      "z": -5,
      "name": "Soil_Clay_Red"
    },
    {
      "x": -5,
      "y": 5,
      "z": -5,
      "name": "Soil_Clay_Pink"
    },
    {
      "x": -5,
      "y": 6,
      "z": -5,
      "name": "Soil_Clay_Pink"
    },
    {
      "x": -5,
      "y": 7,
      "z": -5,
      "name": "Soil_Clay_Pink"
    },
    {
      "x": -5,
      "y": 8,
      "z": -5,
      "name": "Soil_Clay_Red"
    },
    {
      "x": -5,
      "y": 9,
      "z": -5,
      "name": "Soil_Snow"
    },
    {
      "x": -5,
      "y": 0,
      "z": -4,
      "name": "Rock_Sandstone_Red"
    },
    {
      "x": -5,
      "y": 1,
      "z": -4,
      "name": "Rock_Sandstone_Red"
    },
    {
      "x": -5,
      "y": 2,
      "z": -4,
      "name": "Soil_Clay_Red"
    },
    {
      "x": -5,
      "y": 3,
      "z": -4,
      "name": "Soil_Clay_Red"
    },
    {
      "x": -5,
      "y": 6,
      "z": -4,
      "name": "Soil_Clay_Pink"
    },
    {
      "x": -5,
      "y": 7,
      "z": -4,
      "name": "Soil_Clay_Red"
    },
    {
      "x": -5,
      "y": 8,
      "z": -4,
      "name": "Soil_Clay_Red"
    },
    {
      "x": -5,
      "y": 9,
      "z": -4,
      "name": "Soil_Snow"
    },
    {
      "x": -5,
      "y": 10,
      "z": -4,
      "name": "Plant_Bush_Sky_Snowy",
      "support": 15
    },
    {
      "x": -5,
      "y": 0,
      "z": -3,
      "name": "Rock_Sandstone_Red"
    },
    {
      "x": -5,
      "y": 1,
      "z": -3,
      "name": "Rock_Sandstone_Red"
    },
    {
      "x": -5,
      "y": 2,
      "z": -3,
      "name": "Soil_Clay_Red"
    },
    {
      "x": -5,
      "y": 3,
      "z": -3,
      "name": "Soil_Clay_Red"
    },
    {
      "x": -5,
      "y": 4,
      "z": -3,
      "name": "Soil_Clay_Red"
    },
    {
      "x": -5,
      "y": 5,
      "z": -3,
      "name": "Soil_Clay_Pink"
    },
    {
      "x": -5,
      "y": 6,
      "z": -3,
      "name": "Soil_Clay_Red"
    },
    {
      "x": -5,
      "y": 7,
      "z": -3,
      "name": "Soil_Clay_Red"
    },
    {
      "x": -5,
      "y": 8,
      "z": -3,
      "name": "Soil_Clay_Red"
    },
    {
      "x": -5,
      "y": 9,
      "z": -3,
      "name": "Soil_Snow"
    },
    {
      "x": -5,
      "y": 4,
      "z": -2,
      "name": "Soil_Clay_Red"
    },
    {
      "x": -5,
      "y": 5,
      "z": -2,
      "name": "Soil_Clay_Red"
    },
    {
      "x": -5,
      "y": 6,
      "z": -2,
      "name": "Soil_Clay_Red"
    },
    {
      "x": -5,
      "y": 7,
      "z": -2,
      "name": "Soil_Clay_Red"
    },
    {
      "x": -5,
      "y": 8,
      "z": -2,
      "name": "Soil_Clay_Red"
    },
    {
      "x": -5,
      "y": 9,
      "z": -2,
      "name": "Soil_Snow"
    },
    {
      "x": -5,
      "y": 4,
      "z": -1,
      "name": "Rock_Sandstone_Red"
    },
    {
      "x": -5,
      "y": 5,
      "z": -1,
      "name": "Soil_Clay_Red"
    },
    {
      "x": -5,
      "y": 6,
      "z": -1,
      "name": "Soil_Clay_Red"
    },
    {
      "x": -5,
      "y": 7,
      "z": -1,
      "name": "Soil_Clay_Red"
    },
    {
      "x": -5,
      "y": 8,
      "z": -1,
      "name": "Soil_Clay_Red"
    },
    {
      "x": -5,
      "y": 9,
      "z": -1,
      "name": "Soil_Snow"
    },
    {
      "x": -5,
      "y": 10,
      "z": -1,
      "name": "Soil_Snow"
    },
    {
      "x": -5,
      "y": 4,
      "z": 0,
      "name": "Rock_Sandstone_Red"
    },
    {
      "x": -5,
      "y": 5,
      "z": 0,
      "name": "Soil_Clay_Red"
    },
    {
      "x": -5,
      "y": 6,
      "z": 0,
      "name": "Soil_Clay_Red"
    },
    {
      "x": -5,
      "y": 7,
      "z": 0,
      "name": "Soil_Clay_Red"
    },
    {
      "x": -5,
      "y": 8,
      "z": 0,
      "name": "Soil_Clay_Red"
    },
    {
      "x": -5,
      "y": 9,
      "z": 0,
      "name": "Soil_Snow"
    },
    {
      "x": -5,
      "y": 10,
      "z": 0,
      "name": "Soil_Snow"
    },
    {
      "x": -5,
      "y": 1,
      "z": 1,
      "name": "Rock_Sandstone_Red"
    },
    {
      "x": -5,
      "y": 2,
      "z": 1,
      "name": "Rock_Sandstone_Red"
    },
    {
      "x": -5,
      "y": 3,
      "z": 1,
      "name": "Rock_Sandstone_Red"
    },
    {
      "x": -5,
      "y": 4,
      "z": 1,
      "name": "Soil_Pebbles",
      "support": 15
    },
    {
      "x": -5,
      "y": 5,
      "z": 1,
      "name": "Soil_Snow"
    },
    {
      "x": -5,
      "y": 6,
      "z": 1,
      "name": "Soil_Clay_Red"
    },
    {
      "x": -5,
      "y": 7,
      "z": 1,
      "name": "Soil_Clay_Red"
    },
    {
      "x": -5,
      "y": 8,
      "z": 1,
      "name": "Soil_Clay_Red"
    },
    {
      "x": -5,
      "y": 9,
      "z": 1,
      "name": "Soil_Snow"
    },
    {
      "x": -5,
      "y": 1,
      "z": 2,
      "name": "Rock_Sandstone_Red"
    },
    {
      "x": -5,
      "y": 2,
      "z": 2,
      "name": "Rock_Sandstone_Red"
    },
    {
      "x": -5,
      "y": 3,
      "z": 2,
      "name": "Rock_Sandstone_Red"
    },
    {
      "x": -5,
      "y": 4,
      "z": 2,
      "name": "Rock_Sandstone_Red"
    },
    {
      "x": -5,
      "y": 5,
      "z": 2,
      "name": "Soil_Snow"
    },
    {
      "x": -5,
      "y": 1,
      "z": 3,
      "name": "Soil_Clay_Red"
    },
    {
      "x": -5,
      "y": 2,
      "z": 3,
      "name": "Rock_Sandstone_Red"
    },
    {
      "x": -5,
      "y": 3,
      "z": 3,
      "name": "Rock_Sandstone_Red"
    },
    {
      "x": -5,
      "y": 4,
      "z": 3,
      "name": "Rock_Sandstone_Red"
    },
    {
      "x": -5,
      "y": 5,
      "z": 3,
      "name": "Soil_Snow"
    },
    {
      "x": -4,
      "y": 7,
      "z": -9,
      "name": "Soil_Clay_Pink"
    },
    {
      "x": -4,
      "y": 8,
      "z": -9,
      "name": "Soil_Clay_Red"
    },
    {
      "x": -4,
      "y": 9,
      "z": -9,
      "name": "Soil_Snow"
    },
    {
      "x": -4,
      "y": 7,
      "z": -8,
      "name": "Soil_Clay_Pink"
    },
    {
      "x": -4,
      "y": 8,
      "z": -8,
      "name": "Soil_Clay_Red"
    },
    {
      "x": -4,
      "y": 9,
      "z": -8,
      "name": "Soil_Snow"
    },
    {
      "x": -4,
      "y": 10,
      "z": -8,
      "name": "Plant_Crop_Mushroom_Cap_White",
      "components": {
        "Components": {
          "FarmingBlock": {
            "LastTickGameTime": "0001-01-01T12:00:00Z"
          },
          "PlacedByInteraction": {
            "WhoPlacedUuid": {
              "$binary": "rmwkrpH8RVykTc7XnK4YBA==",
              "$type": "04"
            }
          }
        }
      }
    },
    {
      "x": -4,
      "y": 6,
      "z": -7,
      "name": "Soil_Clay_Pink"
    },
    {
      "x": -4,
      "y": 7,
      "z": -7,
      "name": "Soil_Clay_Pink"
    },
    {
      "x": -4,
      "y": 8,
      "z": -7,
      "name": "Soil_Clay_Red"
    },
    {
      "x": -4,
      "y": 9,
      "z": -7,
      "name": "Soil_Snow"
    },
    {
      "x": -4,
      "y": 5,
      "z": -6,
      "name": "Soil_Clay_Pink"
    },
    {
      "x": -4,
      "y": 6,
      "z": -6,
      "name": "Soil_Clay_Pink"
    },
    {
      "x": -4,
      "y": 7,
      "z": -6,
      "name": "Soil_Clay_Pink"
    },
    {
      "x": -4,
      "y": 8,
      "z": -6,
      "name": "Soil_Clay_Red"
    },
    {
      "x": -4,
      "y": 9,
      "z": -6,
      "name": "Soil_Snow"
    },
    {
      "x": -4,
      "y": 5,
      "z": -5,
      "name": "Soil_Clay_Pink"
    },
    {
      "x": -4,
      "y": 6,
      "z": -5,
      "name": "Soil_Clay_Pink"
    },
    {
      "x": -4,
      "y": 7,
      "z": -5,
      "name": "Soil_Clay_Red"
    },
    {
      "x": -4,
      "y": 8,
      "z": -5,
      "name": "Soil_Clay_Red"
    },
    {
      "x": -4,
      "y": 9,
      "z": -5,
      "name": "Soil_Snow"
    },
    {
      "x": -4,
      "y": 10,
      "z": -5,
      "name": "Plant_Bush_Sky_Snowy",
      "support": 15
    },
    {
      "x": -4,
      "y": 4,
      "z": -4,
      "name": "Soil_Clay_Red"
    },
    {
      "x": -4,
      "y": 5,
      "z": -4,
      "name": "Soil_Clay_Pink"
    },
    {
      "x": -4,
      "y": 6,
      "z": -4,
      "name": "Soil_Clay_Red"
    },
    {
      "x": -4,
      "y": 7,
      "z": -4,
      "name": "Soil_Clay_Red"
    },
    {
      "x": -4,
      "y": 8,
      "z": -4,
      "name": "Soil_Clay_Red"
    },
    {
      "x": -4,
      "y": 9,
      "z": -4,
      "name": "Soil_Snow"
    },
    {
      "x": -4,
      "y": 10,
      "z": -4,
      "name": "Plant_Bush_Sky_Snowy",
      "support": 15
    },
    {
      "x": -4,
      "y": 11,
      "z": -4,
      "name": "Plant_Bush_Sky_Snowy",
      "support": 15
    },
    {
      "x": -4,
      "y": 3,
      "z": -3,
      "name": "Soil_Clay_Red"
    },
    {
      "x": -4,
      "y": 4,
      "z": -3,
      "name": "Soil_Clay_Red"
    },
    {
      "x": -4,
      "y": 5,
      "z": -3,
      "name": "Soil_Clay_Red"
    },
    {
      "x": -4,
      "y": 6,
      "z": -3,
      "name": "Soil_Clay_Red"
    },
    {
      "x": -4,
      "y": 7,
      "z": -3,
      "name": "Soil_Clay_Red"
    },
    {
      "x": -4,
      "y": 8,
      "z": -3,
      "name": "Soil_Clay_Red"
    },
    {
      "x": -4,
      "y": 9,
      "z": -3,
      "name": "Soil_Snow"
    },
    {
      "x": -4,
      "y": 10,
      "z": -3,
      "name": "Plant_Bush_Sky_Snowy",
      "support": 15
    },
    {
      "x": -4,
      "y": 3,
      "z": -2,
      "name": "Soil_Clay_Red"
    },
    {
      "x": -4,
      "y": 4,
      "z": -2,
      "name": "Soil_Clay_Red"
    },
    {
      "x": -4,
      "y": 5,
      "z": -2,
      "name": "Soil_Clay_Red"
    },
    {
      "x": -4,
      "y": 6,
      "z": -2,
      "name": "Soil_Clay_Red"
    },
    {
      "x": -4,
      "y": 7,
      "z": -2,
      "name": "Soil_Clay_Red"
    },
    {
      "x": -4,
      "y": 8,
      "z": -2,
      "name": "Soil_Clay_Red"
    },
    {
      "x": -4,
      "y": 9,
      "z": -2,
      "name": "Soil_Snow"
    },
    {
      "x": -4,
      "y": 3,
      "z": -1,
      "name": "Rock_Sandstone_Red"
    },
    {
      "x": -4,
      "y": 4,
      "z": -1,
      "name": "Rock_Sandstone_Red"
    },
    {
      "x": -4,
      "y": 5,
      "z": -1,
      "name": "Soil_Clay_Red"
    },
    {
      "x": -4,
      "y": 6,
      "z": -1,
      "name": "Soil_Clay_Red"
    },
    {
      "x": -4,
      "y": 7,
      "z": -1,
      "name": "Soil_Clay_Red"
    },
    {
      "x": -4,
      "y": 8,
      "z": -1,
      "name": "Soil_Clay_Red"
    },
    {
      "x": -4,
      "y": 9,
      "z": -1,
      "name": "Soil_Snow"
    },
    {
      "x": -4,
      "y": 10,
      "z": -1,
      "name": "Soil_Snow"
    },
    {
      "x": -4,
      "y": 11,
      "z": -1,
      "name": "Plant_Grass_Sky_Snowy",
      "support": 15
    },
    {
      "x": -4,
      "y": 1,
      "z": 0,
      "name": "Rock_Sandstone_Red"
    },
    {
      "x": -4,
      "y": 2,
      "z": 0,
      "name": "Rock_Sandstone_Red"
    },
    {
      "x": -4,
      "y": 3,
      "z": 0,
      "name": "Rock_Sandstone_Red"
    },
    {
      "x": -4,
      "y": 4,
      "z": 0,
      "name": "Rock_Sandstone_Red"
    },
    {
      "x": -4,
      "y": 5,
      "z": 0,
      "name": "Soil_Snow"
    },
    {
      "x": -4,
      "y": 6,
      "z": 0,
      "name": "Soil_Clay_Red"
    },
    {
      "x": -4,
      "y": 7,
      "z": 0,
      "name": "Soil_Clay_Red"
    },
    {
      "x": -4,
      "y": 8,
      "z": 0,
      "name": "Soil_Clay_Red"
    },
    {
      "x": -4,
      "y": 9,
      "z": 0,
      "name": "Soil_Snow"
    },
    {
      "x": -4,
      "y": 10,
      "z": 0,
      "name": "Soil_Snow"
    },
    {
      "x": -4,
      "y": 1,
      "z": 1,
      "name": "Rock_Sandstone_Red"
    },
    {
      "x": -4,
      "y": 2,
      "z": 1,
      "name": "Rock_Sandstone_Red"
    },
    {
      "x": -4,
      "y": 3,
      "z": 1,
      "name": "Rock_Sandstone_Red"
    },
    {
      "x": -4,
      "y": 4,
      "z": 1,
      "name": "Rock_Sandstone_Red"
    },
    {
      "x": -4,
      "y": 5,
      "z": 1,
      "name": "Soil_Snow"
    },
    {
      "x": -4,
      "y": 6,
      "z": 1,
      "name": "Soil_Clay_Red"
    },
    {
      "x": -4,
      "y": 7,
      "z": 1,
      "name": "Soil_Clay_Red"
    },
    {
      "x": -4,
      "y": 8,
      "z": 1,
      "name": "Soil_Snow"
    },
    {
      "x": -4,
      "y": 9,
      "z": 1,
      "name": "Soil_Snow"
    },
    {
      "x": -4,
      "y": 1,
      "z": 2,
      "name": "Soil_Clay_Red"
    },
    {
      "x": -4,
      "y": 2,
      "z": 2,
      "name": "Rock_Sandstone_Red"
    },
    {
      "x": -4,
      "y": 3,
      "z": 2,
      "name": "Rock_Sandstone_Red"
    },
    {
      "x": -4,
      "y": 4,
      "z": 2,
      "name": "Rock_Sandstone_Red"
    },
    {
      "x": -4,
      "y": 5,
      "z": 2,
      "name": "Soil_Snow"
    },
    {
      "x": -4,
      "y": 6,
      "z": 2,
      "name": "Plant_Grass_Sky_Snowy_Tall",
      "support": 15
    },
    {
      "x": -4,
      "y": 7,
      "z": 2,
      "name": "Plant_Grass_Sky_Snowy_Tall",
      "filler": 1024
    },
    {
      "x": -4,
      "y": 1,
      "z": 3,
      "name": "Soil_Clay_Red"
    },
    {
      "x": -4,
      "y": 2,
      "z": 3,
      "name": "Rock_Sandstone_Red"
    },
    {
      "x": -4,
      "y": 3,
      "z": 3,
      "name": "Rock_Sandstone_Red"
    },
    {
      "x": -4,
      "y": 4,
      "z": 3,
      "name": "Rock_Sandstone_Red"
    },
    {
      "x": -4,
      "y": 5,
      "z": 3,
      "name": "Soil_Snow"
    },
    {
      "x": -4,
      "y": 6,
      "z": 3,
      "name": "Plant_Grass_Sky_Snowy",
      "support": 15
    },
    {
      "x": -4,
      "y": 1,
      "z": 4,
      "name": "Soil_Clay_Red"
    },
    {
      "x": -4,
      "y": 2,
      "z": 4,
      "name": "Rock_Sandstone_Red"
    },
    {
      "x": -4,
      "y": 3,
      "z": 4,
      "name": "Rock_Sandstone_Red"
    },
    {
      "x": -4,
      "y": 4,
      "z": 4,
      "name": "Rock_Sandstone_Red"
    },
    {
      "x": -4,
      "y": 5,
      "z": 4,
      "name": "Soil_Snow"
    },
    {
      "x": -3,
      "y": 7,
      "z": -9,
      "name": "Soil_Clay_Pink"
    },
    {
      "x": -3,
      "y": 8,
      "z": -9,
      "name": "Soil_Clay_Red"
    },
    {
      "x": -3,
      "y": 9,
      "z": -9,
      "name": "Soil_Snow"
    },
    {
      "x": -3,
      "y": 4,
      "z": -8,
      "name": "Soil_Clay_Red"
    },
    {
      "x": -3,
      "y": 5,
      "z": -8,
      "name": "Soil_Clay_Pink"
    },
    {
      "x": -3,
      "y": 6,
      "z": -8,
      "name": "Soil_Clay_Red"
    },
    {
      "x": -3,
      "y": 7,
      "z": -8,
      "name": "Soil_Clay_Pink"
    },
    {
      "x": -3,
      "y": 8,
      "z": -8,
      "name": "Soil_Clay_Red"
    },
    {
      "x": -3,
      "y": 9,
      "z": -8,
      "name": "Soil_Snow"
    },
    {
      "x": -3,
      "y": 4,
      "z": -7,
      "name": "Soil_Clay_Red"
    },
    {
      "x": -3,
      "y": 5,
      "z": -7,
      "name": "Soil_Clay_Pink"
    },
    {
      "x": -3,
      "y": 6,
      "z": -7,
      "name": "Soil_Clay_Red"
    },
    {
      "x": -3,
      "y": 7,
      "z": -7,
      "name": "Soil_Clay_Pink"
    },
    {
      "x": -3,
      "y": 8,
      "z": -7,
      "name": "Soil_Pebbles",
      "support": 15,
      "rotation": 3
    },
    {
      "x": -3,
      "y": 9,
      "z": -7,
      "name": "Soil_Snow"
    },
    {
      "x": -3,
      "y": 10,
      "z": -7,
      "name": "Plant_Grass_Sky_Snowy_Tall",
      "support": 15
    },
    {
      "x": -3,
      "y": 11,
      "z": -7,
      "name": "Plant_Grass_Sky_Snowy_Tall",
      "filler": 1024
    },
    {
      "x": -3,
      "y": 5,
      "z": -6,
      "name": "Soil_Clay_Pink"
    },
    {
      "x": -3,
      "y": 6,
      "z": -6,
      "name": "Soil_Clay_Red"
    },
    {
      "x": -3,
      "y": 7,
      "z": -6,
      "name": "Soil_Clay_Red"
    },
    {
      "x": -3,
      "y": 8,
      "z": -6,
      "name": "Soil_Clay_Red"
    },
    {
      "x": -3,
      "y": 9,
      "z": -6,
      "name": "Soil_Snow"
    },
    {
      "x": -3,
      "y": 5,
      "z": -5,
      "name": "Soil_Clay_Pink"
    },
    {
      "x": -3,
      "y": 6,
      "z": -5,
      "name": "Soil_Clay_Red"
    },
    {
      "x": -3,
      "y": 7,
      "z": -5,
      "name": "Soil_Clay_Red"
    },
    {
      "x": -3,
      "y": 8,
      "z": -5,
      "name": "Soil_Clay_Red"
    },
    {
      "x": -3,
      "y": 9,
      "z": -5,
      "name": "Soil_Snow"
    },
    {
      "x": -3,
      "y": 3,
      "z": -4,
      "name": "Soil_Clay_Red"
    },
    {
      "x": -3,
      "y": 4,
      "z": -4,
      "name": "Soil_Clay_Red"
    },
    {
      "x": -3,
      "y": 5,
      "z": -4,
      "name": "Soil_Clay_Red"
    },
    {
      "x": -3,
      "y": 6,
      "z": -4,
      "name": "Soil_Clay_Red"
    },
    {
      "x": -3,
      "y": 7,
      "z": -4,
      "name": "Soil_Clay_Red"
    },
    {
      "x": -3,
      "y": 8,
      "z": -4,
      "name": "Rock_Sandstone_Red"
    },
    {
      "x": -3,
      "y": 9,
      "z": -4,
      "name": "Soil_Snow"
    },
    {
      "x": -3,
      "y": 10,
      "z": -4,
      "name": "Plant_Bush_Sky_Snowy",
      "support": 15
    },
    {
      "x": -3,
      "y": 3,
      "z": -3,
      "name": "Soil_Clay_Red"
    },
    {
      "x": -3,
      "y": 4,
      "z": -3,
      "name": "Soil_Clay_Red"
    },
    {
      "x": -3,
      "y": 5,
      "z": -3,
      "name": "Soil_Clay_Red"
    },
    {
      "x": -3,
      "y": 6,
      "z": -3,
      "name": "Soil_Clay_Red"
    },
    {
      "x": -3,
      "y": 7,
      "z": -3,
      "name": "Soil_Clay_Red"
    },
    {
      "x": -3,
      "y": 8,
      "z": -3,
      "name": "Soil_Clay_Red"
    },
    {
      "x": -3,
      "y": 9,
      "z": -3,
      "name": "Soil_Snow"
    },
    {
      "x": -3,
      "y": 3,
      "z": -2,
      "name": "Soil_Clay_Red"
    },
    {
      "x": -3,
      "y": 4,
      "z": -2,
      "name": "Soil_Clay_Red"
    },
    {
      "x": -3,
      "y": 5,
      "z": -2,
      "name": "Soil_Clay_Red"
    },
    {
      "x": -3,
      "y": 6,
      "z": -2,
      "name": "Soil_Clay_Red"
    },
    {
      "x": -3,
      "y": 7,
      "z": -2,
      "name": "Soil_Clay_Red"
    },
    {
      "x": -3,
      "y": 8,
      "z": -2,
      "name": "Soil_Clay_Red"
    },
    {
      "x": -3,
      "y": 9,
      "z": -2,
      "name": "Soil_Snow"
    },
    {
      "x": -3,
      "y": 3,
      "z": -1,
      "name": "Rock_Sandstone_Red"
    },
    {
      "x": -3,
      "y": 4,
      "z": -1,
      "name": "Rock_Sandstone_Red"
    },
    {
      "x": -3,
      "y": 5,
      "z": -1,
      "name": "Soil_Clay_Red"
    },
    {
      "x": -3,
      "y": 6,
      "z": -1,
      "name": "Soil_Clay_Red"
    },
    {
      "x": -3,
      "y": 7,
      "z": -1,
      "name": "Soil_Clay_Red"
    },
    {
      "x": -3,
      "y": 8,
      "z": -1,
      "name": "Soil_Clay_Red"
    },
    {
      "x": -3,
      "y": 9,
      "z": -1,
      "name": "Soil_Snow"
    },
    {
      "x": -3,
      "y": 10,
      "z": -1,
      "name": "Soil_Snow"
    },
    {
      "x": -3,
      "y": 11,
      "z": -1,
      "name": "Plant_Grass_Sky_Snowy_Short",
      "support": 15
    },
    {
      "x": -3,
      "y": 1,
      "z": 0,
      "name": "Rock_Sandstone_Red"
    },
    {
      "x": -3,
      "y": 2,
      "z": 0,
      "name": "Rock_Sandstone_Red"
    },
    {
      "x": -3,
      "y": 3,
      "z": 0,
      "name": "Rock_Sandstone_Red"
    },
    {
      "x": -3,
      "y": 4,
      "z": 0,
      "name": "Rock_Sandstone_Red"
    },
    {
      "x": -3,
      "y": 5,
      "z": 0,
      "name": "Soil_Snow"
    },
    {
      "x": -3,
      "y": 6,
      "z": 0,
      "name": "Soil_Clay_Red"
    },
    {
      "x": -3,
      "y": 7,
      "z": 0,
      "name": "Soil_Clay_Red"
    },
    {
      "x": -3,
      "y": 8,
      "z": 0,
      "name": "Soil_Clay_Red"
    },
    {
      "x": -3,
      "y": 9,
      "z": 0,
      "name": "Soil_Snow"
    },
    {
      "x": -3,
      "y": 10,
      "z": 0,
      "name": "Soil_Snow"
    },
    {
      "x": -3,
      "y": 1,
      "z": 1,
      "name": "Rock_Sandstone_Red"
    },
    {
      "x": -3,
      "y": 2,
      "z": 1,
      "name": "Rock_Sandstone_Red"
    },
    {
      "x": -3,
      "y": 3,
      "z": 1,
      "name": "Rock_Sandstone_Red"
    },
    {
      "x": -3,
      "y": 4,
      "z": 1,
      "name": "Rock_Sandstone_Red"
    },
    {
      "x": -3,
      "y": 5,
      "z": 1,
      "name": "Soil_Snow"
    },
    {
      "x": -3,
      "y": 7,
      "z": 1,
      "name": "Soil_Clay_Red"
    },
    {
      "x": -3,
      "y": 8,
      "z": 1,
      "name": "Soil_Clay_Red"
    },
    {
      "x": -3,
      "y": 9,
      "z": 1,
      "name": "Soil_Snow"
    },
    {
      "x": -3,
      "y": 1,
      "z": 2,
      "name": "Rock_Sandstone_Red"
    },
    {
      "x": -3,
      "y": 2,
      "z": 2,
      "name": "Rock_Sandstone_Red"
    },
    {
      "x": -3,
      "y": 3,
      "z": 2,
      "name": "Rock_Sandstone_Red"
    },
    {
      "x": -3,
      "y": 4,
      "z": 2,
      "name": "Rock_Sandstone_Red"
    },
    {
      "x": -3,
      "y": 5,
      "z": 2,
      "name": "Soil_Snow"
    },
    {
      "x": -3,
      "y": 1,
      "z": 3,
      "name": "Rock_Sandstone_Red"
    },
    {
      "x": -3,
      "y": 2,
      "z": 3,
      "name": "Rock_Sandstone_Red"
    },
    {
      "x": -3,
      "y": 3,
      "z": 3,
      "name": "Rock_Sandstone_Red"
    },
    {
      "x": -3,
      "y": 4,
      "z": 3,
      "name": "Rock_Sandstone_Red"
    },
    {
      "x": -3,
      "y": 5,
      "z": 3,
      "name": "Soil_Snow"
    },
    {
      "x": -3,
      "y": 1,
      "z": 4,
      "name": "Soil_Clay_Red"
    },
    {
      "x": -3,
      "y": 2,
      "z": 4,
      "name": "Rock_Sandstone_Red"
    },
    {
      "x": -3,
      "y": 3,
      "z": 4,
      "name": "Rock_Sandstone_Red"
    },
    {
      "x": -3,
      "y": 4,
      "z": 4,
      "name": "Rock_Sandstone_Red"
    },
    {
      "x": -3,
      "y": 5,
      "z": 4,
      "name": "Soil_Snow"
    },
    {
      "x": -2,
      "y": 4,
      "z": -8,
      "name": "Soil_Clay_Red"
    },
    {
      "x": -2,
      "y": 5,
      "z": -8,
      "name": "Soil_Clay_Red"
    },
    {
      "x": -2,
      "y": 6,
      "z": -8,
      "name": "Soil_Clay_Red"
    },
    {
      "x": -2,
      "y": 7,
      "z": -8,
      "name": "Soil_Clay_Red"
    },
    {
      "x": -2,
      "y": 8,
      "z": -8,
      "name": "Soil_Clay_Red"
    },
    {
      "x": -2,
      "y": 9,
      "z": -8,
      "name": "Soil_Snow"
    },
    {
      "x": -2,
      "y": 4,
      "z": -7,
      "name": "Soil_Clay_Red"
    },
    {
      "x": -2,
      "y": 5,
      "z": -7,
      "name": "Soil_Clay_Red"
    },
    {
      "x": -2,
      "y": 6,
      "z": -7,
      "name": "Soil_Clay_Red"
    },
    {
      "x": -2,
      "y": 7,
      "z": -7,
      "name": "Soil_Clay_Red"
    },
    {
      "x": -2,
      "y": 8,
      "z": -7,
      "name": "Soil_Pebbles",
      "support": 15,
      "rotation": 3
    },
    {
      "x": -2,
      "y": 9,
      "z": -7,
      "name": "Soil_Snow"
    },
    {
      "x": -2,
      "y": 4,
      "z": -6,
      "name": "Soil_Clay_Red"
    },
    {
      "x": -2,
      "y": 5,
      "z": -6,
      "name": "Soil_Clay_Red"
    },
    {
      "x": -2,
      "y": 6,
      "z": -6,
      "name": "Soil_Clay_Red"
    },
    {
      "x": -2,
      "y": 7,
      "z": -6,
      "name": "Soil_Clay_Red"
    },
    {
      "x": -2,
      "y": 8,
      "z": -6,
      "name": "Soil_Clay_Red"
    },
    {
      "x": -2,
      "y": 9,
      "z": -6,
      "name": "Soil_Snow"
    },
    {
      "x": -2,
      "y": 10,
      "z": -6,
      "name": "Plant_Grass_Sky_Snowy",
      "support": 15
    },
    {
      "x": -2,
      "y": 2,
      "z": -5,
      "name": "Soil_Clay_Red"
    },
    {
      "x": -2,
      "y": 3,
      "z": -5,
      "name": "Soil_Clay_Red"
    },
    {
      "x": -2,
      "y": 4,
      "z": -5,
      "name": "Soil_Clay_Red"
    },
    {
      "x": -2,
      "y": 5,
      "z": -5,
      "name": "Soil_Clay_Red"
    },
    {
      "x": -2,
      "y": 6,
      "z": -5,
      "name": "Soil_Clay_Red"
    },
    {
      "x": -2,
      "y": 7,
      "z": -5,
      "name": "Soil_Snow"
    },
    {
      "x": -2,
      "y": 8,
      "z": -5,
      "name": "Rock_Sandstone_Red"
    },
    {
      "x": -2,
      "y": 9,
      "z": -5,
      "name": "Soil_Snow"
    },
    {
      "x": -2,
      "y": 2,
      "z": -4,
      "name": "Soil_Clay_Red"
    },
    {
      "x": -2,
      "y": 3,
      "z": -4,
      "name": "Soil_Clay_Red"
    },
    {
      "x": -2,
      "y": 4,
      "z": -4,
      "name": "Soil_Clay_Red"
    },
    {
      "x": -2,
      "y": 5,
      "z": -4,
      "name": "Soil_Clay_Red"
    },
    {
      "x": -2,
      "y": 6,
      "z": -4,
      "name": "Soil_Clay_Red"
    },
    {
      "x": -2,
      "y": 7,
      "z": -4,
      "name": "Soil_Snow"
    },
    {
      "x": -2,
      "y": 8,
      "z": -4,
      "name": "Rock_Sandstone_Red"
    },
    {
      "x": -2,
      "y": 9,
      "z": -4,
      "name": "Soil_Snow"
    },
    {
      "x": -2,
      "y": 2,
      "z": -3,
      "name": "Soil_Clay_Red"
    },
    {
      "x": -2,
      "y": 3,
      "z": -3,
      "name": "Soil_Clay_Red"
    },
    {
      "x": -2,
      "y": 4,
      "z": -3,
      "name": "Soil_Clay_Red"
    },
    {
      "x": -2,
      "y": 5,
      "z": -3,
      "name": "Soil_Clay_Red"
    },
    {
      "x": -2,
      "y": 6,
      "z": -3,
      "name": "Soil_Clay_Red"
    },
    {
      "x": -2,
      "y": 7,
      "z": -3,
      "name": "Soil_Snow"
    },
    {
      "x": -2,
      "y": 8,
      "z": -3,
      "name": "Soil_Clay_Red"
    },
    {
      "x": -2,
      "y": 9,
      "z": -3,
      "name": "Soil_Snow"
    },
    {
      "x": -2,
      "y": 2,
      "z": -2,
      "name": "Soil_Clay_Red"
    },
    {
      "x": -2,
      "y": 3,
      "z": -2,
      "name": "Soil_Clay_Red"
    },
    {
      "x": -2,
      "y": 4,
      "z": -2,
      "name": "Soil_Clay_Red"
    },
    {
      "x": -2,
      "y": 5,
      "z": -2,
      "name": "Soil_Clay_Red"
    },
    {
      "x": -2,
      "y": 6,
      "z": -2,
      "name": "Soil_Clay_Red"
    },
    {
      "x": -2,
      "y": 7,
      "z": -2,
      "name": "Soil_Clay_Red"
    },
    {
      "x": -2,
      "y": 8,
      "z": -2,
      "name": "Soil_Clay_Red"
    },
    {
      "x": -2,
      "y": 9,
      "z": -2,
      "name": "Soil_Snow"
    },
    {
      "x": -2,
      "y": 2,
      "z": -1,
      "name": "Rock_Sandstone_Red"
    },
    {
      "x": -2,
      "y": 3,
      "z": -1,
      "name": "Rock_Sandstone_Red"
    },
    {
      "x": -2,
      "y": 4,
      "z": -1,
      "name": "Rock_Sandstone_Red"
    },
    {
      "x": -2,
      "y": 5,
      "z": -1,
      "name": "Soil_Clay_Red"
    },
    {
      "x": -2,
      "y": 6,
      "z": -1,
      "name": "Soil_Clay_Red"
    },
    {
      "x": -2,
      "y": 7,
      "z": -1,
      "name": "Soil_Clay_Red"
    },
    {
      "x": -2,
      "y": 8,
      "z": -1,
      "name": "Soil_Clay_Red"
    },
    {
      "x": -2,
      "y": 9,
      "z": -1,
      "name": "Soil_Snow"
    },
    {
      "x": -2,
      "y": 1,
      "z": 0,
      "name": "Rock_Sandstone_Red"
    },
    {
      "x": -2,
      "y": 2,
      "z": 0,
      "name": "Rock_Sandstone_Red"
    },
    {
      "x": -2,
      "y": 3,
      "z": 0,
      "name": "Rock_Sandstone_Red"
    },
    {
      "x": -2,
      "y": 4,
      "z": 0,
      "name": "Rock_Sandstone_Red"
    },
    {
      "x": -2,
      "y": 5,
      "z": 0,
      "name": "Soil_Snow"
    },
    {
      "x": -2,
      "y": 7,
      "z": 0,
      "name": "Soil_Clay_Red"
    },
    {
      "x": -2,
      "y": 8,
      "z": 0,
      "name": "Soil_Clay_Red"
    },
    {
      "x": -2,
      "y": 9,
      "z": 0,
      "name": "Soil_Snow"
    },
    {
      "x": -2,
      "y": 1,
      "z": 1,
      "name": "Rock_Sandstone_Red"
    },
    {
      "x": -2,
      "y": 2,
      "z": 1,
      "name": "Rock_Sandstone_Red"
    },
    {
      "x": -2,
      "y": 3,
      "z": 1,
      "name": "Rock_Sandstone_Red"
    },
    {
      "x": -2,
      "y": 4,
      "z": 1,
      "name": "Rock_Sandstone_Red"
    },
    {
      "x": -2,
      "y": 5,
      "z": 1,
      "name": "Soil_Snow"
    },
    {
      "x": -2,
      "y": 6,
      "z": 1,
      "name": "Soil_Snow"
    },
    {
      "x": -2,
      "y": 7,
      "z": 1,
      "name": "Soil_Snow"
    },
    {
      "x": -2,
      "y": 1,
      "z": 2,
      "name": "Rock_Sandstone_Red"
    },
    {
      "x": -2,
      "y": 2,
      "z": 2,
      "name": "Rock_Sandstone_Red"
    },
    {
      "x": -2,
      "y": 3,
      "z": 2,
      "name": "Rock_Sandstone_Red"
    },
    {
      "x": -2,
      "y": 4,
      "z": 2,
      "name": "Rock_Sandstone_Red"
    },
    {
      "x": -2,
      "y": 5,
      "z": 2,
      "name": "Soil_Snow"
    },
    {
      "x": -2,
      "y": 6,
      "z": 2,
      "name": "Soil_Snow"
    },
    {
      "x": -2,
      "y": 1,
      "z": 3,
      "name": "Rock_Sandstone_Red"
    },
    {
      "x": -2,
      "y": 2,
      "z": 3,
      "name": "Rock_Sandstone_Red"
    },
    {
      "x": -2,
      "y": 3,
      "z": 3,
      "name": "Rock_Sandstone_Red"
    },
    {
      "x": -2,
      "y": 4,
      "z": 3,
      "name": "Rock_Sandstone_Red"
    },
    {
      "x": -2,
      "y": 5,
      "z": 3,
      "name": "Soil_Snow"
    },
    {
      "x": -2,
      "y": 1,
      "z": 4,
      "name": "Rock_Sandstone_Red"
    },
    {
      "x": -2,
      "y": 2,
      "z": 4,
      "name": "Rock_Sandstone_Red"
    },
    {
      "x": -2,
      "y": 3,
      "z": 4,
      "name": "Rock_Sandstone_Red"
    },
    {
      "x": -2,
      "y": 4,
      "z": 4,
      "name": "Rock_Sandstone_Red"
    },
    {
      "x": -2,
      "y": 5,
      "z": 4,
      "name": "Soil_Snow"
    },
    {
      "x": -1,
      "y": 5,
      "z": -9,
      "name": "Soil_Clay_Red"
    },
    {
      "x": -1,
      "y": 6,
      "z": -9,
      "name": "Soil_Clay_Red"
    },
    {
      "x": -1,
      "y": 7,
      "z": -9,
      "name": "Soil_Clay_Red"
    },
    {
      "x": -1,
      "y": 8,
      "z": -9,
      "name": "Soil_Snow"
    },
    {
      "x": -1,
      "y": 4,
      "z": -7,
      "name": "Soil_Clay_Red"
    },
    {
      "x": -1,
      "y": 5,
      "z": -7,
      "name": "Soil_Clay_Red"
    },
    {
      "x": -1,
      "y": 6,
      "z": -7,
      "name": "Soil_Clay_Red"
    },
    {
      "x": -1,
      "y": 7,
      "z": -7,
      "name": "Soil_Clay_Red"
    },
    {
      "x": -1,
      "y": 8,
      "z": -7,
      "name": "Rock_Sandstone_Red"
    },
    {
      "x": -1,
      "y": 9,
      "z": -7,
      "name": "Soil_Snow"
    },
    {
      "x": -1,
      "y": 2,
      "z": -6,
      "name": "Soil_Clay_Red"
    },
    {
      "x": -1,
      "y": 3,
      "z": -6,
      "name": "Soil_Clay_Red"
    },
    {
      "x": -1,
      "y": 4,
      "z": -6,
      "name": "Soil_Clay_Red"
    },
    {
      "x": -1,
      "y": 5,
      "z": -6,
      "name": "Soil_Clay_Red"
    },
    {
      "x": -1,
      "y": 6,
      "z": -6,
      "name": "Soil_Clay_Red"
    },
    {
      "x": -1,
      "y": 7,
      "z": -6,
      "name": "Soil_Snow"
    },
    {
      "x": -1,
      "y": 8,
      "z": -6,
      "name": "Rock_Sandstone_Red"
    },
    {
      "x": -1,
      "y": 9,
      "z": -6,
      "name": "Soil_Snow"
    },
    {
      "x": -1,
      "y": 2,
      "z": -5,
      "name": "Soil_Clay_Red"
    },
    {
      "x": -1,
      "y": 3,
      "z": -5,
      "name": "Soil_Clay_Red"
    },
    {
      "x": -1,
      "y": 4,
      "z": -5,
      "name": "Soil_Clay_Red"
    },
    {
      "x": -1,
      "y": 5,
      "z": -5,
      "name": "Soil_Clay_Red"
    },
    {
      "x": -1,
      "y": 6,
      "z": -5,
      "name": "Soil_Clay_Red"
    },
    {
      "x": -1,
      "y": 7,
      "z": -5,
      "name": "Soil_Snow"
    },
    {
      "x": -1,
      "y": 8,
      "z": -5,
      "name": "Rock_Sandstone_Red"
    },
    {
      "x": -1,
      "y": 9,
      "z": -5,
      "name": "Soil_Snow"
    },
    {
      "x": -1,
      "y": 2,
      "z": -4,
      "name": "Soil_Clay_Red"
    },
    {
      "x": -1,
      "y": 3,
      "z": -4,
      "name": "Soil_Clay_Red"
    },
    {
      "x": -1,
      "y": 4,
      "z": -4,
      "name": "Soil_Clay_Red"
    },
    {
      "x": -1,
      "y": 5,
      "z": -4,
      "name": "Soil_Clay_Red"
    },
    {
      "x": -1,
      "y": 6,
      "z": -4,
      "name": "Soil_Clay_Red"
    },
    {
      "x": -1,
      "y": 7,
      "z": -4,
      "name": "Soil_Snow"
    },
    {
      "x": -1,
      "y": 8,
      "z": -4,
      "name": "Rock_Sandstone_Red"
    },
    {
      "x": -1,
      "y": 9,
      "z": -4,
      "name": "Soil_Snow"
    },
    {
      "x": -1,
      "y": 2,
      "z": -3,
      "name": "Soil_Clay_Red"
    },
    {
      "x": -1,
      "y": 3,
      "z": -3,
      "name": "Soil_Clay_Red"
    },
    {
      "x": -1,
      "y": 4,
      "z": -3,
      "name": "Soil_Clay_Red"
    },
    {
      "x": -1,
      "y": 5,
      "z": -3,
      "name": "Soil_Clay_Red"
    },
    {
      "x": -1,
      "y": 6,
      "z": -3,
      "name": "Soil_Clay_Red"
    },
    {
      "x": -1,
      "y": 7,
      "z": -3,
      "name": "Soil_Snow"
    },
    {
      "x": -1,
      "y": 8,
      "z": -3,
      "name": "Rock_Sandstone_Red"
    },
    {
      "x": -1,
      "y": 9,
      "z": -3,
      "name": "Soil_Snow"
    },
    {
      "x": -1,
      "y": 2,
      "z": -2,
      "name": "Rock_Sandstone_Red"
    },
    {
      "x": -1,
      "y": 3,
      "z": -2,
      "name": "Soil_Clay_Red"
    },
    {
      "x": -1,
      "y": 4,
      "z": -2,
      "name": "Soil_Clay_Red"
    },
    {
      "x": -1,
      "y": 5,
      "z": -2,
      "name": "Soil_Clay_Red"
    },
    {
      "x": -1,
      "y": 6,
      "z": -2,
      "name": "Soil_Clay_Red"
    },
    {
      "x": -1,
      "y": 7,
      "z": -2,
      "name": "Soil_Snow"
    },
    {
      "x": -1,
      "y": 2,
      "z": -1,
      "name": "Rock_Sandstone_Red"
    },
    {
      "x": -1,
      "y": 3,
      "z": -1,
      "name": "Soil_Clay_Red"
    },
    {
      "x": -1,
      "y": 4,
      "z": -1,
      "name": "Rock_Sandstone_Red"
    },
    {
      "x": -1,
      "y": 5,
      "z": -1,
      "name": "Soil_Snow"
    },
    {
      "x": -1,
      "y": 2,
      "z": 0,
      "name": "Rock_Sandstone_Red"
    },
    {
      "x": -1,
      "y": 3,
      "z": 0,
      "name": "Rock_Sandstone_Red"
    },
    {
      "x": -1,
      "y": 4,
      "z": 0,
      "name": "Rock_Sandstone_Red"
    },
    {
      "x": -1,
      "y": 5,
      "z": 0,
      "name": "Soil_Snow"
    },
    {
      "x": -1,
      "y": 1,
      "z": 1,
      "name": "Rock_Sandstone_Red"
    },
    {
      "x": -1,
      "y": 2,
      "z": 1,
      "name": "Rock_Sandstone_Red"
    },
    {
      "x": -1,
      "y": 3,
      "z": 1,
      "name": "Rock_Sandstone_Red"
    },
    {
      "x": -1,
      "y": 4,
      "z": 1,
      "name": "Rock_Sandstone_Red"
    },
    {
      "x": -1,
      "y": 5,
      "z": 1,
      "name": "Soil_Snow"
    },
    {
      "x": -1,
      "y": 6,
      "z": 1,
      "name": "Soil_Snow"
    },
    {
      "x": -1,
      "y": 1,
      "z": 2,
      "name": "Rock_Sandstone_Red"
    },
    {
      "x": -1,
      "y": 2,
      "z": 2,
      "name": "Rock_Sandstone_Red"
    },
    {
      "x": -1,
      "y": 3,
      "z": 2,
      "name": "Rock_Sandstone_Red"
    },
    {
      "x": -1,
      "y": 4,
      "z": 2,
      "name": "Rock_Sandstone_Red"
    },
    {
      "x": -1,
      "y": 5,
      "z": 2,
      "name": "Soil_Snow"
    },
    {
      "x": -1,
      "y": 6,
      "z": 2,
      "name": "Soil_Snow"
    },
    {
      "x": -1,
      "y": 1,
      "z": 3,
      "name": "Rock_Sandstone_Red"
    },
    {
      "x": -1,
      "y": 2,
      "z": 3,
      "name": "Rock_Sandstone_Red"
    },
    {
      "x": -1,
      "y": 3,
      "z": 3,
      "name": "Rock_Sandstone_Red"
    },
    {
      "x": -1,
      "y": 4,
      "z": 3,
      "name": "Rock_Sandstone_Red"
    },
    {
      "x": -1,
      "y": 5,
      "z": 3,
      "name": "Soil_Snow"
    },
    {
      "x": 0,
      "y": 4,
      "z": -9,
      "name": "Soil_Clay_Red"
    },
    {
      "x": 0,
      "y": 5,
      "z": -9,
      "name": "Soil_Clay_Red"
    },
    {
      "x": 0,
      "y": 6,
      "z": -9,
      "name": "Soil_Clay_Red"
    },
    {
      "x": 0,
      "y": 7,
      "z": -9,
      "name": "Soil_Clay_Red"
    },
    {
      "x": 0,
      "y": 8,
      "z": -9,
      "name": "Soil_Snow"
    },
    {
      "x": 0,
      "y": 3,
      "z": -8,
      "name": "Soil_Clay_Red"
    },
    {
      "x": 0,
      "y": 4,
      "z": -8,
      "name": "Soil_Clay_Red"
    },
    {
      "x": 0,
      "y": 5,
      "z": -8,
      "name": "Soil_Clay_Red"
    },
    {
      "x": 0,
      "y": 6,
      "z": -8,
      "name": "Soil_Clay_Red"
    },
    {
      "x": 0,
      "y": 7,
      "z": -8,
      "name": "Soil_Clay_Red"
    },
    {
      "x": 0,
      "y": 8,
      "z": -8,
      "name": "Soil_Snow"
    },
    {
      "x": 0,
      "y": 2,
      "z": -6,
      "name": "Soil_Clay_Red"
    },
    {
      "x": 0,
      "y": 3,
      "z": -6,
      "name": "Soil_Clay_Red"
    },
    {
      "x": 0,
      "y": 4,
      "z": -6,
      "name": "Soil_Clay_Red"
    },
    {
      "x": 0,
      "y": 5,
      "z": -6,
      "name": "Soil_Clay_Red"
    },
    {
      "x": 0,
      "y": 6,
      "z": -6,
      "name": "Soil_Clay_Red"
    },
    {
      "x": 0,
      "y": 7,
      "z": -6,
      "name": "Soil_Snow"
    },
    {
      "x": 0,
      "y": 2,
      "z": -5,
      "name": "Soil_Clay_Red"
    },
    {
      "x": 0,
      "y": 3,
      "z": -5,
      "name": "Soil_Clay_Red"
    },
    {
      "x": 0,
      "y": 4,
      "z": -5,
      "name": "Soil_Clay_Red"
    },
    {
      "x": 0,
      "y": 5,
      "z": -5,
      "name": "Soil_Clay_Red"
    },
    {
      "x": 0,
      "y": 6,
      "z": -5,
      "name": "Soil_Clay_Red"
    },
    {
      "x": 0,
      "y": 7,
      "z": -5,
      "name": "Soil_Snow"
    },
    {
      "x": 0,
      "y": 2,
      "z": -4,
      "name": "Soil_Clay_Red"
    },
    {
      "x": 0,
      "y": 3,
      "z": -4,
      "name": "Soil_Clay_Red"
    },
    {
      "x": 0,
      "y": 4,
      "z": -4,
      "name": "Soil_Clay_Red"
    },
    {
      "x": 0,
      "y": 5,
      "z": -4,
      "name": "Soil_Clay_Red"
    },
    {
      "x": 0,
      "y": 6,
      "z": -4,
      "name": "Soil_Clay_Red"
    },
    {
      "x": 0,
      "y": 7,
      "z": -4,
      "name": "Soil_Snow"
    },
    {
      "x": 0,
      "y": 2,
      "z": -3,
      "name": "Rock_Sandstone_Red"
    },
    {
      "x": 0,
      "y": 3,
      "z": -3,
      "name": "Soil_Clay_Red"
    },
    {
      "x": 0,
      "y": 4,
      "z": -3,
      "name": "Soil_Clay_Red"
    },
    {
      "x": 0,
      "y": 5,
      "z": -3,
      "name": "Soil_Clay_Red"
    },
    {
      "x": 0,
      "y": 6,
      "z": -3,
      "name": "Rock_Sandstone_Red"
    },
    {
      "x": 0,
      "y": 7,
      "z": -3,
      "name": "Soil_Snow"
    },
    {
      "x": 0,
      "y": 0,
      "z": -2,
      "name": "Rock_Sandstone_Red"
    },
    {
      "x": 0,
      "y": 1,
      "z": -2,
      "name": "Rock_Sandstone_Red"
    },
    {
      "x": 0,
      "y": 2,
      "z": -2,
      "name": "Rock_Sandstone_Red"
    },
    {
      "x": 0,
      "y": 3,
      "z": -2,
      "name": "Soil_Clay_Red"
    },
    {
      "x": 0,
      "y": 4,
      "z": -2,
      "name": "Soil_Clay_Red"
    },
    {
      "x": 0,
      "y": 5,
      "z": -2,
      "name": "Soil_Snow"
    },
    {
      "x": 0,
      "y": 6,
      "z": -2,
      "name": "Rock_Sandstone_Red"
    },
    {
      "x": 0,
      "y": 7,
      "z": -2,
      "name": "Soil_Snow"
    },
    {
      "x": 0,
      "y": 0,
      "z": -1,
      "name": "Rock_Sandstone_Red"
    },
    {
      "x": 0,
      "y": 1,
      "z": -1,
      "name": "Rock_Sandstone_Red"
    },
    {
      "x": 0,
      "y": 2,
      "z": -1,
      "name": "Rock_Sandstone_Red"
    },
    {
      "x": 0,
      "y": 3,
      "z": -1,
      "name": "Soil_Clay_Red"
    },
    {
      "x": 0,
      "y": 4,
      "z": -1,
      "name": "Soil_Clay_Red"
    },
    {
      "x": 0,
      "y": 5,
      "z": -1,
      "name": "Soil_Snow"
    },
    {
      "x": 0,
      "y": 6,
      "z": -1,
      "name": "Plant_Crop_Mushroom_Glowing_Blue"
    },
    {
      "x": 0,
      "y": 0,
      "z": 0,
      "name": "Rock_Sandstone_Red"
    },
    {
      "x": 0,
      "y": 1,
      "z": 0,
      "name": "Rock_Sandstone_Red"
    },
    {
      "x": 0,
      "y": 2,
      "z": 0,
      "name": "Rock_Sandstone_Red"
    },
    {
      "x": 0,
      "y": 3,
      "z": 0,
      "name": "Soil_Clay_Red"
    },
    {
      "x": 0,
      "y": 4,
      "z": 0,
      "name": "Rock_Sandstone_Red"
    },
    {
      "x": 0,
      "y": 5,
      "z": 0,
      "name": "Soil_Snow"
    },
    {
      "x": 0,
      "y": 6,
      "z": 0,
      "name": "Plant_Grass_Sky_Snowy",
      "support": 15
    },
    {
      "x": 0,
      "y": 0,
      "z": 1,
      "name": "Rock_Sandstone_Red"
    },
    {
      "x": 0,
      "y": 1,
      "z": 1,
      "name": "Rock_Sandstone_Red"
    },
    {
      "x": 0,
      "y": 3,
      "z": 1,
      "name": "Rock_Sandstone_Red"
    },
    {
      "x": 0,
      "y": 4,
      "z": 1,
      "name": "Rock_Sandstone_Red"
    },
    {
      "x": 0,
      "y": 5,
      "z": 1,
      "name": "Soil_Snow"
    },
    {
      "x": 0,
      "y": 6,
      "z": 1,
      "name": "Plant_Grass_Sky_Snowy_Tall",
      "support": 15
    },
    {
      "x": 0,
      "y": 7,
      "z": 1,
      "name": "Plant_Grass_Sky_Snowy_Tall",
      "filler": 1024
    },
    {
      "x": 0,
      "y": 1,
      "z": 2,
      "name": "Rock_Sandstone_Red"
    },
    {
      "x": 0,
      "y": 2,
      "z": 2,
      "name": "Rock_Sandstone_Red"
    },
    {
      "x": 0,
      "y": 3,
      "z": 2,
      "name": "Rock_Sandstone_Red"
    },
    {
      "x": 0,
      "y": 4,
      "z": 2,
      "name": "Rock_Sandstone_Red"
    },
    {
      "x": 0,
      "y": 5,
      "z": 2,
      "name": "Soil_Snow"
    },
    {
      "x": 0,
      "y": 1,
      "z": 3,
      "name": "Rock_Sandstone_Red"
    },
    {
      "x": 0,
      "y": 2,
      "z": 3,
      "name": "Rock_Sandstone_Red"
    },
    {
      "x": 0,
      "y": 3,
      "z": 3,
      "name": "Rock_Sandstone_Red"
    },
    {
      "x": 0,
      "y": 4,
      "z": 3,
      "name": "Rock_Sandstone_Red"
    },
    {
      "x": 0,
      "y": 5,
      "z": 3,
      "name": "Soil_Snow"
    },
    {
      "x": 1,
      "y": 6,
      "z": -8,
      "name": "Soil_Clay_Red"
    },
    {
      "x": 1,
      "y": 7,
      "z": -8,
      "name": "Soil_Clay_Red"
    },
    {
      "x": 1,
      "y": 8,
      "z": -8,
      "name": "Soil_Snow"
    },
    {
      "x": 1,
      "y": 2,
      "z": -6,
      "name": "Soil_Clay_Red"
    },
    {
      "x": 1,
      "y": 3,
      "z": -6,
      "name": "Soil_Clay_Red"
    },
    {
      "x": 1,
      "y": 4,
      "z": -6,
      "name": "Soil_Clay_Red"
    },
    {
      "x": 1,
      "y": 5,
      "z": -6,
      "name": "Soil_Clay_Red"
    },
    {
      "x": 1,
      "y": 6,
      "z": -6,
      "name": "Soil_Clay_Red"
    },
    {
      "x": 1,
      "y": 7,
      "z": -6,
      "name": "Soil_Snow"
    },
    {
      "x": 1,
      "y": 2,
      "z": -5,
      "name": "Soil_Clay_Red"
    },
    {
      "x": 1,
      "y": 3,
      "z": -5,
      "name": "Soil_Clay_Red"
    },
    {
      "x": 1,
      "y": 4,
      "z": -5,
      "name": "Soil_Clay_Red"
    },
    {
      "x": 1,
      "y": 5,
      "z": -5,
      "name": "Soil_Clay_Red"
    },
    {
      "x": 1,
      "y": 6,
      "z": -5,
      "name": "Soil_Clay_Red"
    },
    {
      "x": 1,
      "y": 7,
      "z": -5,
      "name": "Soil_Snow"
    },
    {
      "x": 1,
      "y": 2,
      "z": -4,
      "name": "Rock_Sandstone_Red"
    },
    {
      "x": 1,
      "y": 3,
      "z": -4,
      "name": "Soil_Clay_Red"
    },
    {
      "x": 1,
      "y": 4,
      "z": -4,
      "name": "Soil_Clay_Red"
    },
    {
      "x": 1,
      "y": 5,
      "z": -4,
      "name": "Soil_Clay_Red"
    },
    {
      "x": 1,
      "y": 6,
      "z": -4,
      "name": "Rock_Sandstone_Red"
    },
    {
      "x": 1,
      "y": 7,
      "z": -4,
      "name": "Soil_Snow"
    },
    {
      "x": 1,
      "y": 0,
      "z": -3,
      "name": "Rock_Sandstone_Red"
    },
    {
      "x": 1,
      "y": 1,
      "z": -3,
      "name": "Rock_Sandstone_Red"
    },
    {
      "x": 1,
      "y": 2,
      "z": -3,
      "name": "Rock_Sandstone_Red"
    },
    {
      "x": 1,
      "y": 3,
      "z": -3,
      "name": "Soil_Clay_Red"
    },
    {
      "x": 1,
      "y": 4,
      "z": -3,
      "name": "Soil_Clay_Red"
    },
    {
      "x": 1,
      "y": 5,
      "z": -3,
      "name": "Soil_Snow"
    },
    {
      "x": 1,
      "y": 6,
      "z": -3,
      "name": "Rock_Sandstone_Red"
    },
    {
      "x": 1,
      "y": 7,
      "z": -3,
      "name": "Soil_Snow"
    },
    {
      "x": 1,
      "y": 8,
      "z": -3,
      "name": "Plant_Grass_Sky_Snowy_Tall",
      "support": 15
    },
    {
      "x": 1,
      "y": 9,
      "z": -3,
      "name": "Plant_Grass_Sky_Snowy_Tall",
      "filler": 1024
    },
    {
      "x": 1,
      "y": 0,
      "z": -2,
      "name": "Rock_Sandstone_Red"
    },
    {
      "x": 1,
      "y": 1,
      "z": -2,
      "name": "Rock_Sandstone_Red"
    },
    {
      "x": 1,
      "y": 2,
      "z": -2,
      "name": "Rock_Sandstone_Red"
    },
    {
      "x": 1,
      "y": 3,
      "z": -2,
      "name": "Soil_Clay_Red"
    },
    {
      "x": 1,
      "y": 4,
      "z": -2,
      "name": "Soil_Clay_Red"
    },
    {
      "x": 1,
      "y": 5,
      "z": -2,
      "name": "Soil_Snow"
    },
    {
      "x": 1,
      "y": 6,
      "z": -2,
      "name": "Rock_Sandstone_Red"
    },
    {
      "x": 1,
      "y": 7,
      "z": -2,
      "name": "Soil_Snow"
    },
    {
      "x": 1,
      "y": 8,
      "z": -2,
      "name": "Plant_Grass_Sky_Snowy_Short",
      "support": 15
    },
    {
      "x": 1,
      "y": 0,
      "z": -1,
      "name": "Rock_Sandstone_Red"
    },
    {
      "x": 1,
      "y": 1,
      "z": -1,
      "name": "Rock_Sandstone_Red"
    },
    {
      "x": 1,
      "y": 2,
      "z": -1,
      "name": "Rock_Sandstone_Red"
    },
    {
      "x": 1,
      "y": 3,
      "z": -1,
      "name": "Soil_Clay_Red"
    },
    {
      "x": 1,
      "y": 4,
      "z": -1,
      "name": "Soil_Clay_Red"
    },
    {
      "x": 1,
      "y": 5,
      "z": -1,
      "name": "Soil_Snow"
    },
    {
      "x": 1,
      "y": 0,
      "z": 0,
      "name": "Rock_Sandstone_Red"
    },
    {
      "x": 1,
      "y": 1,
      "z": 0,
      "name": "Rock_Sandstone_Red"
    },
    {
      "x": 1,
      "y": 2,
      "z": 0,
      "name": "Rock_Sandstone_Red"
    },
    {
      "x": 1,
      "y": 3,
      "z": 0,
      "name": "Soil_Clay_Red"
    },
    {
      "x": 1,
      "y": 4,
      "z": 0,
      "name": "Soil_Clay_Red"
    },
    {
      "x": 1,
      "y": 5,
      "z": 0,
      "name": "Soil_Snow"
    },
    {
      "x": 1,
      "y": 0,
      "z": 1,
      "name": "Rock_Sandstone_Red"
    },
    {
      "x": 1,
      "y": 1,
      "z": 1,
      "name": "Rock_Sandstone_Red"
    },
    {
      "x": 1,
      "y": 2,
      "z": 1,
      "name": "Rock_Sandstone_Red"
    },
    {
      "x": 1,
      "y": 3,
      "z": 1,
      "name": "Soil_Clay_Red"
    },
    {
      "x": 1,
      "y": 4,
      "z": 1,
      "name": "Rock_Sandstone_Red"
    },
    {
      "x": 1,
      "y": 5,
      "z": 1,
      "name": "Soil_Snow"
    },
    {
      "x": 1,
      "y": 1,
      "z": 2,
      "name": "Rock_Sandstone_Red"
    },
    {
      "x": 1,
      "y": 2,
      "z": 2,
      "name": "Rock_Sandstone_Red"
    },
    {
      "x": 1,
      "y": 3,
      "z": 2,
      "name": "Rock_Sandstone_Red"
    },
    {
      "x": 1,
      "y": 4,
      "z": 2,
      "name": "Rock_Sandstone_Red"
    },
    {
      "x": 1,
      "y": 5,
      "z": 2,
      "name": "Soil_Snow"
    },
    {
      "x": 1,
      "y": 1,
      "z": 3,
      "name": "Rock_Sandstone_Red"
    },
    {
      "x": 1,
      "y": 2,
      "z": 3,
      "name": "Rock_Sandstone_Red"
    },
    {
      "x": 1,
      "y": 3,
      "z": 3,
      "name": "Rock_Sandstone_Red"
    },
    {
      "x": 1,
      "y": 4,
      "z": 3,
      "name": "Rock_Sandstone_Red"
    },
    {
      "x": 1,
      "y": 5,
      "z": 3,
      "name": "Soil_Snow"
    },
    {
      "x": 2,
      "y": 2,
      "z": -5,
      "name": "Soil_Clay_Red"
    },
    {
      "x": 2,
      "y": 3,
      "z": -5,
      "name": "Soil_Clay_Red"
    },
    {
      "x": 2,
      "y": 4,
      "z": -5,
      "name": "Soil_Clay_Red"
    },
    {
      "x": 2,
      "y": 5,
      "z": -5,
      "name": "Soil_Clay_Red"
    },
    {
      "x": 2,
      "y": 6,
      "z": -5,
      "name": "Rock_Sandstone_Red"
    },
    {
      "x": 2,
      "y": 7,
      "z": -5,
      "name": "Soil_Snow"
    },
    {
      "x": 2,
      "y": 2,
      "z": -4,
      "name": "Rock_Sandstone_Red"
    },
    {
      "x": 2,
      "y": 3,
      "z": -4,
      "name": "Soil_Clay_Red"
    },
    {
      "x": 2,
      "y": 4,
      "z": -4,
      "name": "Soil_Clay_Red"
    },
    {
      "x": 2,
      "y": 5,
      "z": -4,
      "name": "Soil_Clay_Red"
    },
    {
      "x": 2,
      "y": 6,
      "z": -4,
      "name": "Rock_Sandstone_Red"
    },
    {
      "x": 2,
      "y": 7,
      "z": -4,
      "name": "Soil_Snow"
    },
    {
      "x": 2,
      "y": 0,
      "z": -3,
      "name": "Rock_Sandstone_Red"
    },
    {
      "x": 2,
      "y": 1,
      "z": -3,
      "name": "Rock_Sandstone_Red"
    },
    {
      "x": 2,
      "y": 2,
      "z": -3,
      "name": "Rock_Sandstone_Red"
    },
    {
      "x": 2,
      "y": 3,
      "z": -3,
      "name": "Soil_Clay_Red"
    },
    {
      "x": 2,
      "y": 4,
      "z": -3,
      "name": "Soil_Clay_Red"
    },
    {
      "x": 2,
      "y": 5,
      "z": -3,
      "name": "Soil_Snow"
    },
    {
      "x": 2,
      "y": 6,
      "z": -3,
      "name": "Rock_Sandstone_Red"
    },
    {
      "x": 2,
      "y": 7,
      "z": -3,
      "name": "Soil_Snow"
    },
    {
      "x": 2,
      "y": 0,
      "z": -2,
      "name": "Rock_Sandstone_Red"
    },
    {
      "x": 2,
      "y": 1,
      "z": -2,
      "name": "Rock_Sandstone_Red"
    },
    {
      "x": 2,
      "y": 2,
      "z": -2,
      "name": "Rock_Sandstone_Red"
    },
    {
      "x": 2,
      "y": 3,
      "z": -2,
      "name": "Soil_Clay_Red"
    },
    {
      "x": 2,
      "y": 4,
      "z": -2,
      "name": "Soil_Clay_Red"
    },
    {
      "x": 2,
      "y": 5,
      "z": -2,
      "name": "Soil_Snow"
    },
    {
      "x": 2,
      "y": 0,
      "z": -1,
      "name": "Rock_Sandstone_Red"
    },
    {
      "x": 2,
      "y": 1,
      "z": -1,
      "name": "Rock_Sandstone_Red"
    },
    {
      "x": 2,
      "y": 2,
      "z": -1,
      "name": "Rock_Sandstone_Red"
    },
    {
      "x": 2,
      "y": 3,
      "z": -1,
      "name": "Soil_Clay_Red"
    },
    {
      "x": 2,
      "y": 4,
      "z": -1,
      "name": "Soil_Clay_Red"
    },
    {
      "x": 2,
      "y": 5,
      "z": -1,
      "name": "Soil_Snow"
    },
    {
      "x": 2,
      "y": 6,
      "z": -1,
      "name": "Plant_Grass_Sky_Snowy",
      "support": 15
    },
    {
      "x": 2,
      "y": 0,
      "z": 0,
      "name": "Rock_Sandstone_Red"
    },
    {
      "x": 2,
      "y": 1,
      "z": 0,
      "name": "Rock_Sandstone_Red"
    },
    {
      "x": 2,
      "y": 2,
      "z": 0,
      "name": "Rock_Sandstone_Red"
    },
    {
      "x": 2,
      "y": 3,
      "z": 0,
      "name": "Soil_Clay_Red"
    },
    {
      "x": 2,
      "y": 4,
      "z": 0,
      "name": "Soil_Clay_Red"
    },
    {
      "x": 2,
      "y": 5,
      "z": 0,
      "name": "Soil_Snow"
    },
    {
      "x": 2,
      "y": 0,
      "z": 1,
      "name": "Rock_Sandstone_Red"
    },
    {
      "x": 2,
      "y": 1,
      "z": 1,
      "name": "Rock_Sandstone_Red"
    },
    {
      "x": 2,
      "y": 2,
      "z": 1,
      "name": "Rock_Sandstone_Red"
    },
    {
      "x": 2,
      "y": 3,
      "z": 1,
      "name": "Soil_Clay_Red"
    },
    {
      "x": 2,
      "y": 4,
      "z": 1,
      "name": "Soil_Clay_Red"
    },
    {
      "x": 2,
      "y": 5,
      "z": 1,
      "name": "Soil_Snow"
    },
    {
      "x": 2,
      "y": 2,
      "z": 2,
      "name": "Rock_Sandstone_Red"
    },
    {
      "x": 2,
      "y": 3,
      "z": 2,
      "name": "Soil_Clay_Red"
    },
    {
      "x": 2,
      "y": 4,
      "z": 2,
      "name": "Rock_Sandstone_Red"
    },
    {
      "x": 2,
      "y": 5,
      "z": 2,
      "name": "Soil_Snow"
    },
    {
      "x": 3,
      "y": 3,
      "z": -4,
      "name": "Soil_Clay_Red"
    },
    {
      "x": 3,
      "y": 4,
      "z": -4,
      "name": "Soil_Clay_Red"
    },
    {
      "x": 3,
      "y": 5,
      "z": -4,
      "name": "Soil_Snow"
    },
    {
      "x": 3,
      "y": 0,
      "z": -3,
      "name": "Rock_Sandstone_Red"
    },
    {
      "x": 3,
      "y": 1,
      "z": -3,
      "name": "Rock_Sandstone_Red"
    },
    {
      "x": 3,
      "y": 2,
      "z": -3,
      "name": "Rock_Sandstone_Red"
    },
    {
      "x": 3,
      "y": 3,
      "z": -3,
      "name": "Soil_Clay_Red"
    },
    {
      "x": 3,
      "y": 4,
      "z": -3,
      "name": "Soil_Clay_Red"
    },
    {
      "x": 3,
      "y": 5,
      "z": -3,
      "name": "Soil_Snow"
    },
    {
      "x": 3,
      "y": 0,
      "z": -2,
      "name": "Rock_Sandstone_Red"
    },
    {
      "x": 3,
      "y": 1,
      "z": -2,
      "name": "Rock_Sandstone_Red"
    },
    {
      "x": 3,
      "y": 2,
      "z": -2,
      "name": "Rock_Sandstone_Red"
    },
    {
      "x": 3,
      "y": 3,
      "z": -2,
      "name": "Soil_Clay_Red"
    },
    {
      "x": 3,
      "y": 4,
      "z": -2,
      "name": "Soil_Clay_Red"
    },
    {
      "x": 3,
      "y": 5,
      "z": -2,
      "name": "Soil_Snow"
    },
    {
      "x": 3,
      "y": 0,
      "z": -1,
      "name": "Rock_Sandstone_Red"
    },
    {
      "x": 3,
      "y": 1,
      "z": -1,
      "name": "Rock_Sandstone_Red"
    },
    {
      "x": 3,
      "y": 2,
      "z": -1,
      "name": "Rock_Sandstone_Red"
    },
    {
      "x": 3,
      "y": 3,
      "z": -1,
      "name": "Soil_Clay_Red"
    },
    {
      "x": 3,
      "y": 4,
      "z": -1,
      "name": "Soil_Clay_Red"
    },
    {
      "x": 3,
      "y": 5,
      "z": -1,
      "name": "Soil_Snow"
    },
    {
      "x": 3,
      "y": 6,
      "z": -1,
      "name": "Plant_Grass_Sky_Snowy",
      "support": 15
    },
    {
      "x": 3,
      "y": 0,
      "z": 0,
      "name": "Rock_Sandstone_Red"
    },
    {
      "x": 3,
      "y": 1,
      "z": 0,
      "name": "Rock_Sandstone_Red"
    },
    {
      "x": 3,
      "y": 2,
      "z": 0,
      "name": "Rock_Sandstone_Red"
    },
    {
      "x": 3,
      "y": 3,
      "z": 0,
      "name": "Soil_Clay_Red"
    },
    {
      "x": 3,
      "y": 4,
      "z": 0,
      "name": "Soil_Clay_Red"
    },
    {
      "x": 3,
      "y": 5,
      "z": 0,
      "name": "Soil_Snow"
    },
    {
      "x": 3,
      "y": 6,
      "z": 0,
      "name": "Plant_Grass_Sky_Snowy_Tall",
      "support": 15
    },
    {
      "x": 3,
      "y": 7,
      "z": 0,
      "name": "Plant_Grass_Sky_Snowy_Tall",
      "filler": 1024
    },
    {
      "x": 3,
      "y": 0,
      "z": 1,
      "name": "Rock_Sandstone_Red"
    },
    {
      "x": 3,
      "y": 1,
      "z": 1,
      "name": "Rock_Sandstone_Red"
    },
    {
      "x": 3,
      "y": 2,
      "z": 1,
      "name": "Rock_Sandstone_Red"
    },
    {
      "x": 3,
      "y": 3,
      "z": 1,
      "name": "Soil_Clay_Red"
    },
    {
      "x": 3,
      "y": 4,
      "z": 1,
      "name": "Soil_Clay_Red"
    },
    {
      "x": 3,
      "y": 5,
      "z": 1,
      "name": "Soil_Snow"
    },
    {
      "x": 3,
      "y": 3,
      "z": 2,
      "name": "Soil_Clay_Red"
    },
    {
      "x": 3,
      "y": 4,
      "z": 2,
      "name": "Soil_Clay_Red"
    },
    {
      "x": 3,
      "y": 5,
      "z": 2,
      "name": "Soil_Snow"
    },
    {
      "x": 4,
      "y": 0,
      "z": -2,
      "name": "Rock_Sandstone_Red"
    },
    {
      "x": 4,
      "y": 1,
      "z": -2,
      "name": "Rock_Sandstone_Red"
    },
    {
      "x": 4,
      "y": 2,
      "z": -2,
      "name": "Rock_Sandstone_Red"
    },
    {
      "x": 4,
      "y": 3,
      "z": -2,
      "name": "Soil_Clay_Red"
    },
    {
      "x": 4,
      "y": 4,
      "z": -2,
      "name": "Soil_Snow"
    },
    {
      "x": 4,
      "y": 5,
      "z": -2,
      "name": "Soil_Snow"
    },
    {
      "x": 4,
      "y": 0,
      "z": -1,
      "name": "Rock_Sandstone_Red"
    },
    {
      "x": 4,
      "y": 1,
      "z": -1,
      "name": "Rock_Sandstone_Red"
    },
    {
      "x": 4,
      "y": 2,
      "z": -1,
      "name": "Rock_Sandstone_Red"
    },
    {
      "x": 4,
      "y": 3,
      "z": -1,
      "name": "Soil_Clay_Red"
    },
    {
      "x": 4,
      "y": 4,
      "z": -1,
      "name": "Soil_Clay_Red"
    },
    {
      "x": 4,
      "y": 5,
      "z": -1,
      "name": "Soil_Snow"
    },
    {
      "x": 4,
      "y": 0,
      "z": 0,
      "name": "Rock_Sandstone_Red"
    },
    {
      "x": 4,
      "y": 1,
      "z": 0,
      "name": "Rock_Sandstone_Red"
    },
    {
      "x": 4,
      "y": 2,
      "z": 0,
      "name": "Rock_Sandstone_Red"
    },
    {
      "x": 4,
      "y": 3,
      "z": 0,
      "name": "Soil_Clay_Red"
    },
    {
      "x": 4,
      "y": 4,
      "z": 0,
      "name": "Soil_Clay_Red"
    },
    {
      "x": 4,
      "y": 5,
      "z": 0,
      "name": "Soil_Snow"
    }
  ]
}