{
  "version": 8,
  "blockIdVersion": 11,
  "anchorX": 0,
  "anchorY": 6,
  "anchorZ": 1,
  "blocks": [
    {
      "x": -2,
      "y": 0,
      "z": 1,
      "name": "Wood_Banyan_Branch_Corner",
      "support": 15,
      "rotation": 1
    },
    {
      "x": -2,
      "y": 1,
      "z": 1,
      "name": "Wood_Banyan_Branch_Long",
      "support": 15
    },
    {
      "x": -2,
      "y": 2,
      "z": 1,
      "name": "Wood_Banyan_Branch_Corner",
      "support": 15,
      "rotation": 9
    },
    {
      "x": -1,
      "y": 7,
      "z": 0,
      "name": "Plant_Large_Lilypad_Half"
    },
    {
      "x": -1,
      "y": 2,
      "z": 1,
      "name": "Wood_Banyan_Branch_Long",
      "support": 15,
      "rotation": 5
    },
    {
      "x": -1,
      "y": 7,
      "z": 1,
      "name": "Plant_Large_Lilypad_Half"
    },
    {
      "x": -1,
      "y": 7,
      "z": 2,
      "name": "Plant_Large_Lilypad_Half"
    },
    {
      "x": 0,
      "y": 2,
      "z": -1,
      "name": "Wood_Banyan_Branch_Corner",
      "support": 15,
      "rotation": 2
    },
    {
      "x": 0,
      "y": 3,
      "z": -1,
      "name": "Wood_Banyan_Branch_Corner",
      "support": 15,
      "rotation": 9
    },
    {
      "x": 0,
      "y": 2,
      "z": 0,
      "name": "Wood_Banyan_Branch_Long",
      "support": 15,
      "rotation": 4
    },
    {
      "x": 0,
      "y": 7,
      "z": 0,
      "name": "Plant_Large_Lilypad_Half"
    },
    {
      "x": 0,
      "y": 0,
      "z": 1,
      "name": "Wood_Banyan_Branch_Long",
      "support": 15
    },
    {
      "x": 0,
      "y": 1,
      "z": 1,
      "name": "Wood_Banyan_Branch_Long",
      "support": 15
    },
    {
      "x": 0,
      "y": 2,
      "z": 1,
      "name": "Wood_Banyan_Roots",
      "support": 15
    },
    {
      "x": 0,
      "y": 3,
      "z": 1,
      "name": "Wood_Banyan_Branch_Long",
      "support": 15
    },
    {
      "x": 0,
      "y": 4,
      "z": 1,
      "name": "Wood_Banyan_Branch_Long",
      "support": 15
    },
    {
      "x": 0,
      "y": 5,
      "z": 1,
      "name": "Wood_Banyan_Branch_Long",
      "support": 15
    },
    {
      "x": 0,
      "y": 6,
      "z": 1,
      "name": "Wood_Banyan_Roots",
      "support": 15
    },
    {
      "x": 0,
      "y": 7,
      "z": 1,
      "name": "Plant_Large_Lilypad_Half"
    },
    {
      "x": 0,
      "y": 2,
      "z": 2,
      "name": "Wood_Banyan_Branch_Long",
      "support": 15,
      "rotation": 4
    },
    {
      "x": 0,
      "y": 7,
      "z": 2,
      "name": "Plant_Large_Lilypad_Half"
    },
    {
      "x": 0,
      "y": 1,
      "z": 3,
      "name": "Wood_Banyan_Branch_Corner",
      "support": 15,
      "rotation": 3
    },
    {
      "x": 0,
      "y": 2,
      "z": 3,
      "name": "Wood_Banyan_Branch_Corner",
      "support": 15,
      "rotation": 10
    },
    {
      "x": 1,
      "y": 3,
      "z": -1,
      "name": "Wood_Banyan_Branch_Corner",
      "support": 15,
      "rotation": 1
    },
    {
      "x": 1,
      "y": 4,
      "z": -1,
      "name": "Wood_Banyan_Branch_Long",
      "support": 15
    },
    {
      "x": 1,
      "y": 5,
      "z": -1,
      "name": "Wood_Banyan_Branch_Long",
      "support": 15
    },
    {
      "x": 1,
      "y": 6,
      "z": -1,
      "name": "Plant_Large_Lilypad_Half"
    },
    {
      "x": 1,
      "y": 7,
      "z": 0,
      "name": "Plant_Large_Lilypad_Half"
    },
    {
      "x": 1,
      "y": 1,
      "z": 1,
      "name": "Wood_Banyan_Branch_Long",
      "support": 15
    },
    {
      "x": 1,
      "y": 2,
      "z": 1,
      "name": "Wood_Banyan_Branch_Corner",
      "support": 15,
      "rotation": 11
    },
    {
      "x": 1,
      "y": 7,
      "z": 1,
      "name": "Plant_Large_Lilypad_Half"
    },
    {
      "x": 1,
      "y": 0,
      "z": 2,
      "name": "Wood_Banyan_Branch_Corner",
      "support": 15,
      "rotation": 2
    },
    {
      "x": 1,
      "y": 7,
      "z": 2,
      "name": "Plant_Large_Lilypad_Half"
    },
    {
      "x": 1,
      "y": 0,
      "z": 3,
      "name": "Wood_Banyan_Branch_Corner",
      "support": 15
    },
    {
      "x": 1,
      "y": 1,
      "z": 3,
      "name": "Wood_Banyan_Branch_Corner",
      "support": 15,
      "rotation": 11
    }
  ],
  "fluids": [
    {
      "x": -2,
      "y": 0,
      "z": 1,
      "name": "Water_Source",
      "level": 1
    },
    {
      "x": -2,
      "y": 1,
      "z": 1,
      "name": "Water_Source",
      "level": 1
    },
    {
      "x": -2,
      "y": 2,
      "z": 1,
      "name": "Water_Source",
      "level": 1
    },
    {
      "x": -1,
      "y": 2,
      "z": 1,
      "name": "Water_Source",
      "level": 1
    },
    {
      "x": 0,
      "y": 2,
      "z": -1,
      "name": "Water_Source",
      "level": 1
    },
    {
      "x": 0,
      "y": 3,
      "z": -1,
      "name": "Water_Source",
      "level": 1
    },
    {
      "x": 0,
      "y": 2,
      "z": 0,
      "name": "Water_Source",
      "level": 1
    },
    {
      "x": 0,
      "y": 0,
      "z": 1,
      "name": "Water_Source",
      "level": 1
    },
    {
      "x": 0,
      "y": 1,
      "z": 1,
      "name": "Water_Source",
      "level": 1
    },
    {
      "x": 0,
      "y": 2,
      "z": 1,
      "name": "Water_Source",
      "level": 1
    },
    {
      "x": 0,
      "y": 3,
      "z": 1,
      "name": "Water_Source",
      "level": 1
    },
    {
      "x": 0,
      "y": 4,
      "z": 1,
      "name": "Water_Source",
      "level": 1
    },
    {
      "x": 0,
      "y": 2,
      "z": 2,
      "name": "Water_Source",
      "level": 1
    },
    {
      "x": 0,
      "y": 1,
      "z": 3,
      "name": "Water_Source",
      "level": 1
    },
    {
      "x": 0,
      "y": 2,
      "z": 3,
      "name": "Water_Source",
      "level": 1
    },
    {
      "x": 1,
      "y": 3,
      "z": -1,
      "name": "Water_Source",
      "level": 1
    },
    {
      "x": 1,
      "y": 4,
      "z": -1,
      "name": "Water_Source",
      "level": 1
    },
    {
      "x": 1,
      "y": 1,
      "z": 1,
      "name": "Water_Source",
      "level": 1
    },
    {
      "x": 1,
      "y": 2,
      "z": 1,
      "name": "Water_Source",
      "level": 1
    },
    {
      "x": 1,
      "y": 0,
      "z": 2,
      "name": "Water_Source",
      "level": 1
    },
    {
      "x": 1,
      "y": 0,
      "z": 3,
      "name": "Water_Source",
      "level": 1
    },
    {
      "x": 1,
      "y": 1,
      "z": 3,
      "name": "Water_Source",
      "level": 1
    }
  ]
}