{
  "version": 8,
  "blockIdVersion": 11,
  "anchorX": 21,
  "anchorY": 9,
  "anchorZ": 13,
  "blocks": [
    {
      "x": 15,
      "y": 0,
      "z": 13,
      "name": "Wood_Birch_Branch_Corner",
      "support": 15,
      "rotation": 3
    },
    {
      "x": 15,
      "y": 1,
      "z": 13,
      "name": "Wood_Birch_Branch_Long",
      "support": 15
    },
    {
      "x": 16,
      "y": 19,
      "z": 11,
      "name": "Plant_Leaves_Aspen",
      "support": 15
    },
    {
      "x": 16,
      "y": 11,
      "z": 12,
      "name": "Plant_Leaves_Aspen",
      "support": 15
    },
    {
      "x": 16,
      "y": 19,
      "z": 12,
      "name": "Plant_Leaves_Aspen",
      "support": 15
    },
    {
      "x": 16,
      "y": 0,
      "z": 13,
      "name": "Wood_Birch_Branch_Long",
      "support": 15,
      "rotation": 5
    },
    {
      "x": 16,
      "y": 19,
      "z": 13,
      "name": "Plant_Leaves_Aspen",
      "support": 15
    },
    {
      "x": 17,
      "y": 19,
      "z": 10,
      "name": "Plant_Leaves_Aspen",
      "support": 15
    },
    {
      "x": 17,
      "y": 11,
      "z": 11,
      "name": "Plant_Leaves_Aspen",
      "support": 15
    },
    {
      "x": 17,
      "y": 19,
      "z": 11,
      "name": "Plant_Leaves_Aspen",
      "support": 15
    },
    {
      "x": 17,
      "y": 20,
      "z": 11,
      "name": "Plant_Leaves_Aspen",
      "support": 15
    },
    {
      "x": 17,
      "y": 11,
      "z": 12,
      "name": "Plant_Leaves_Aspen",
      "support": 15
    },
    {
      "x": 17,
      "y": 12,
      "z": 12,
      "name": "Plant_Leaves_Aspen",
      "support": 15
    },
    {
      "x": 17,
      "y": 18,
      "z": 12,
      "name": "Wood_Birch_Branch_Corner",
      "support": 15,
      "rotation": 3
    },
    {
      "x": 17,
      "y": 19,
      "z": 12,
      "name": "Wood_Birch_Branch_Long",
      "support": 15
    },
    {
      "x": 17,
      "y": 20,
      "z": 12,
      "name": "Plant_Leaves_Aspen",
      "support": 15
    },
    {
      "x": 17,
      "y": 0,
      "z": 13,
      "name": "Wood_Birch_Branch_Corner",
      "support": 15,
      "rotation": 1
    },
    {
      "x": 17,
      "y": 1,
      "z": 13,
      "name": "Wood_Birch_Branch_Long",
      "support": 15
    },
    {
      "x": 17,
      "y": 2,
      "z": 13,
      "name": "Wood_Birch_Branch_Long",
      "support": 15
    },
    {
      "x": 17,
      "y": 3,
      "z": 13,
      "name": "Wood_Birch_Branch_Corner",
      "support": 15,
      "rotation": 9
    },
    {
      "x": 17,
      "y": 11,
      "z": 13,
      "name": "Plant_Leaves_Aspen",
      "support": 15
    },
    {
      "x": 17,
      "y": 19,
      "z": 13,
      "name": "Plant_Leaves_Aspen",
      "support": 15
    },
    {
      "x": 17,
      "y": 25,
      "z": 19,
      "name": "Plant_Leaves_Aspen",
      "support": 15
    },
    {
      "x": 17,
      "y": 25,
      "z": 20,
      "name": "Plant_Leaves_Aspen",
      "support": 15
    },
    {
      "x": 17,
      "y": 25,
      "z": 21,
      "name": "Plant_Leaves_Aspen",
      "support": 15
    },
    {
      "x": 17,
      "y": 25,
      "z": 22,
      "name": "Plant_Leaves_Aspen",
      "support": 15
    },
    {
      "x": 18,
      "y": 2,
      "z": 7,
      "name": "Wood_Birch_Branch_Corner",
      "support": 15,
      "rotation": 2
    },
    {
      "x": 18,
      "y": 3,
      "z": 7,
      "name": "Wood_Birch_Branch_Long",
      "support": 15
    },
    {
      "x": 18,
      "y": 1,
      "z": 8,
      "name": "Wood_Birch_Branch_Corner",
      "support": 15,
      "rotation": 2
    },
    {
      "x": 18,
      "y": 2,
      "z": 8,
      "name": "Wood_Birch_Branch_Corner",
      "support": 15,
      "rotation": 10
    },
    {
      "x": 18,
      "y": 1,
      "z": 9,
      "name": "Wood_Birch_Branch_Long",
      "support": 15,
      "rotation": 4
    },
    {
      "x": 18,
      "y": 1,
      "z": 10,
      "name": "Wood_Birch_Branch_Corner",
      "support": 15
    },
    {
      "x": 18,
      "y": 2,
      "z": 10,
      "name": "Wood_Birch_Trunk_Full",
      "support": 15
    },
    {
      "x": 18,
      "y": 3,
      "z": 10,
      "name": "Wood_Birch_Trunk_Full",
      "support": 15
    },
    {
      "x": 18,
      "y": 4,
      "z": 10,
      "name": "Wood_Birch_Trunk_Full",
      "support": 15
    },
    {
      "x": 18,
      "y": 5,
      "z": 10,
      "name": "Wood_Birch_Trunk_Full",
      "support": 15
    },
    {
      "x": 18,
      "y": 19,
      "z": 10,
      "name": "Plant_Leaves_Aspen",
      "support": 15
    },
    {
      "x": 18,
      "y": 11,
      "z": 11,
      "name": "Plant_Leaves_Aspen",
      "support": 15
    },
    {
      "x": 18,
      "y": 19,
      "z": 11,
      "name": "Plant_Leaves_Aspen",
      "support": 15
    },
    {
      "x": 18,
      "y": 20,
      "z": 11,
      "name": "Plant_Leaves_Aspen",
      "support": 15
    },
    {
      "x": 18,
      "y": 10,
      "z": 12,
      "name": "Wood_Birch_Branch_Corner",
      "support": 15,
      "rotation": 3
    },
    {
      "x": 18,
      "y": 11,
      "z": 12,
      "name": "Wood_Birch_Branch_Long",
      "support": 15
    },
    {
      "x": 18,
      "y": 12,
      "z": 12,
      "name": "Plant_Leaves_Aspen",
      "support": 15
    },
    {
      "x": 18,
      "y": 18,
      "z": 12,
      "name": "Wood_Birch_Branch_Long",
      "support": 15,
      "rotation": 5
    },
    {
      "x": 18,
      "y": 19,
      "z": 12,
      "name": "Plant_Leaves_Aspen",
      "support": 15
    },
    {
      "x": 18,
      "y": 20,
      "z": 12,
      "name": "Plant_Leaves_Aspen",
      "support": 15
    },
    {
      "x": 18,
      "y": 28,
      "z": 12,
      "name": "Plant_Leaves_Aspen",
      "support": 15
    },
    {
      "x": 18,
      "y": 3,
      "z": 13,
      "name": "Wood_Birch_Branch_Long",
      "support": 15,
      "rotation": 5
    },
    {
      "x": 18,
      "y": 11,
      "z": 13,
      "name": "Plant_Leaves_Aspen",
      "support": 15
    },
    {
      "x": 18,
      "y": 19,
      "z": 13,
      "name": "Plant_Leaves_Aspen",
      "support": 15
    },
    {
      "x": 18,
      "y": 28,
      "z": 13,
      "name": "Plant_Leaves_Aspen",
      "support": 15
    },
    {
      "x": 18,
      "y": 28,
      "z": 14,
      "name": "Plant_Leaves_Aspen",
      "support": 15
    },
    {
      "x": 18,
      "y": 26,
      "z": 17,
      "name": "Plant_Leaves_Aspen",
      "support": 15
    },
    {
      "x": 18,
      "y": 26,
      "z": 18,
      "name": "Plant_Leaves_Aspen",
      "support": 15
    },
    {
      "x": 18,
      "y": 25,
      "z": 19,
      "name": "Plant_Leaves_Aspen",
      "support": 15
    },
    {
      "x": 18,
      "y": 26,
      "z": 19,
      "name": "Plant_Leaves_Aspen",
      "support": 15
    },
    {
      "x": 18,
      "y": 25,
      "z": 20,
      "name": "Plant_Leaves_Aspen",
      "support": 15
    },
    {
      "x": 18,
      "y": 26,
      "z": 20,
      "name": "Plant_Leaves_Aspen",
      "support": 15
    },
    {
      "x": 18,
      "y": 25,
      "z": 21,
      "name": "Plant_Leaves_Aspen",
      "support": 15
    },
    {
      "x": 18,
      "y": 26,
      "z": 21,
      "name": "Plant_Leaves_Aspen",
      "support": 15
    },
    {
      "x": 18,
      "y": 25,
      "z": 22,
      "name": "Plant_Leaves_Aspen",
      "support": 15
    },
    {
      "x": 18,
      "y": 26,
      "z": 22,
      "name": "Plant_Leaves_Aspen",
      "support": 15
    },
    {
      "x": 18,
      "y": 25,
      "z": 23,
      "name": "Plant_Leaves_Aspen",
      "support": 15
    },
    {
      "x": 19,
      "y": 19,
      "z": 8,
      "name": "Plant_Leaves_Aspen",
      "support": 15
    },
    {
      "x": 19,
      "y": 19,
      "z": 9,
      "name": "Plant_Leaves_Aspen",
      "support": 15
    },
    {
      "x": 19,
      "y": 5,
      "z": 10,
      "name": "Wood_Birch_Trunk_Full",
      "support": 15,
      "rotation": 5
    },
    {
      "x": 19,
      "y": 19,
      "z": 10,
      "name": "Plant_Leaves_Aspen",
      "support": 15
    },
    {
      "x": 19,
      "y": 20,
      "z": 10,
      "name": "Plant_Leaves_Aspen",
      "support": 15
    },
    {
      "x": 19,
      "y": 5,
      "z": 11,
      "name": "Wood_Birch_Trunk_Full",
      "support": 15
    },
    {
      "x": 19,
      "y": 6,
      "z": 11,
      "name": "Wood_Birch_Trunk_Full",
      "support": 15
    },
    {
      "x": 19,
      "y": 7,
      "z": 11,
      "name": "Wood_Birch_Trunk_Full",
      "support": 15
    },
    {
      "x": 19,
      "y": 11,
      "z": 11,
      "name": "Plant_Leaves_Aspen",
      "support": 15
    },
    {
      "x": 19,
      "y": 19,
      "z": 11,
      "name": "Plant_Leaves_Aspen",
      "support": 15
    },
    {
      "x": 19,
      "y": 20,
      "z": 11,
      "name": "Plant_Leaves_Aspen",
      "support": 15
    },
    {
      "x": 19,
      "y": 28,
      "z": 11,
      "name": "Plant_Leaves_Aspen",
      "support": 15
    },
    {
      "x": 19,
      "y": 5,
      "z": 12,
      "name": "Wood_Birch_Trunk_Full",
      "support": 15
    },
    {
      "x": 19,
      "y": 6,
      "z": 12,
      "name": "Wood_Birch_Trunk_Full",
      "support": 15
    },
    {
      "x": 19,
      "y": 10,
      "z": 12,
      "name": "Wood_Birch_Branch_Long",
      "support": 15,
      "rotation": 5
    },
    {
      "x": 19,
      "y": 11,
      "z": 12,
      "name": "Plant_Leaves_Aspen",
      "support": 15
    },
    {
      "x": 19,
      "y": 18,
      "z": 12,
      "name": "Wood_Birch_Branch_Long",
      "support": 15,
      "rotation": 5
    },
    {
      "x": 19,
      "y": 19,
      "z": 12,
      "name": "Plant_Leaves_Aspen",
      "support": 15
    },
    {
      "x": 19,
      "y": 28,
      "z": 12,
      "name": "Plant_Leaves_Aspen",
      "support": 15
    },
    {
      "x": 19,
      "y": 29,
      "z": 12,
      "name": "Plant_Leaves_Aspen",
      "support": 15
    },
    {
      "x": 19,
      "y": 0,
      "z": 13,
      "name": "Wood_Birch_Branch_Long",
      "support": 15
    },
    {
      "x": 19,
      "y": 1,
      "z": 13,
      "name": "Wood_Birch_Branch_Long",
      "support": 15
    },
    {
      "x": 19,
      "y": 2,
      "z": 13,
      "name": "Wood_Birch_Trunk_Full",
      "support": 15
    },
    {
      "x": 19,
      "y": 3,
      "z": 13,
      "name": "Wood_Birch_Trunk_Full",
      "support": 15
    },
    {
      "x": 19,
      "y": 4,
      "z": 13,
      "name": "Wood_Birch_Trunk_Full",
      "support": 15
    },
    {
      "x": 19,
      "y": 5,
      "z": 13,
      "name": "Wood_Birch_Trunk_Full",
      "support": 15
    },
    {
      "x": 19,
      "y": 11,
      "z": 13,
      "name": "Plant_Leaves_Aspen",
      "support": 15
    },
    {
      "x": 19,
      "y": 19,
      "z": 13,
      "name": "Plant_Leaves_Aspen",
      "support": 15
    },
    {
      "x": 19,
      "y": 28,
      "z": 13,
      "name": "Plant_Leaves_Aspen",
      "support": 15
    },
    {
      "x": 19,
      "y": 29,
      "z": 13,
      "name": "Plant_Leaves_Aspen",
      "support": 15
    },
    {
      "x": 19,
      "y": 21,
      "z": 14,
      "name": "Plant_Leaves_Aspen",
      "support": 15
    },
    {
      "x": 19,
      "y": 26,
      "z": 14,
      "name": "Plant_Leaves_Aspen",
      "support": 15
    },
    {
      "x": 19,
      "y": 28,
      "z": 14,
      "name": "Plant_Leaves_Aspen",
      "support": 15
    },
    {
      "x": 19,
      "y": 21,
      "z": 15,
      "name": "Plant_Leaves_Aspen",
      "support": 15
    },
    {
      "x": 19,
      "y": 26,
      "z": 15,
      "name": "Plant_Leaves_Aspen",
      "support": 15
    },
    {
      "x": 19,
      "y": 28,
      "z": 15,
      "name": "Plant_Leaves_Aspen",
      "support": 15
    },
    {
      "x": 19,
      "y": 21,
      "z": 16,
      "name": "Plant_Leaves_Aspen",
      "support": 15
    },
    {
      "x": 19,
      "y": 26,
      "z": 16,
      "name": "Plant_Leaves_Aspen",
      "support": 15
    },
    {
      "x": 19,
      "y": 26,
      "z": 17,
      "name": "Plant_Leaves_Aspen",
      "support": 15
    },
    {
      "x": 19,
      "y": 27,
      "z": 17,
      "name": "Plant_Leaves_Aspen",
      "support": 15
    },
    {
      "x": 19,
      "y": 26,
      "z": 18,
      "name": "Plant_Leaves_Aspen",
      "support": 15
    },
    {
      "x": 19,
      "y": 27,
      "z": 18,
      "name": "Plant_Leaves_Aspen",
      "support": 15
    },
    {
      "x": 19,
      "y": 26,
      "z": 19,
      "name": "Plant_Leaves_Aspen",
      "support": 15
    },
    {
      "x": 19,
      "y": 20,
      "z": 20,
      "name": "Plant_Leaves_Aspen",
      "support": 15
    },
    {
      "x": 19,
      "y": 25,
      "z": 20,
      "name": "Plant_Leaves_Aspen",
      "support": 15
    },
    {
      "x": 19,
      "y": 26,
      "z": 20,
      "name": "Plant_Leaves_Aspen",
      "support": 15
    },
    {
      "x": 19,
      "y": 20,
      "z": 21,
      "name": "Plant_Leaves_Aspen",
      "support": 15
    },
    {
      "x": 19,
      "y": 25,
      "z": 21,
      "name": "Plant_Leaves_Aspen",
      "support": 15
    },
    {
      "x": 19,
      "y": 26,
      "z": 21,
      "name": "Plant_Leaves_Aspen",
      "support": 15
    },
    {
      "x": 19,
      "y": 25,
      "z": 22,
      "name": "Plant_Leaves_Aspen",
      "support": 15
    },
    {
      "x": 19,
      "y": 26,
      "z": 22,
      "name": "Plant_Leaves_Aspen",
      "support": 15
    },
    {
      "x": 19,
      "y": 25,
      "z": 23,
      "name": "Plant_Leaves_Aspen",
      "support": 15
    },
    {
      "x": 19,
      "y": 25,
      "z": 24,
      "name": "Plant_Leaves_Aspen",
      "support": 15
    },
    {
      "x": 20,
      "y": 19,
      "z": 8,
      "name": "Plant_Leaves_Aspen",
      "support": 15
    },
    {
      "x": 20,
      "y": 19,
      "z": 9,
      "name": "Plant_Leaves_Aspen",
      "support": 15
    },
    {
      "x": 20,
      "y": 17,
      "z": 10,
      "name": "Wood_Birch_Branch_Corner",
      "support": 15,
      "rotation": 2
    },
    {
      "x": 20,
      "y": 18,
      "z": 10,
      "name": "Wood_Birch_Branch_Long",
      "support": 15
    },
    {
      "x": 20,
      "y": 19,
      "z": 10,
      "name": "Wood_Birch_Branch_Long",
      "support": 15
    },
    {
      "x": 20,
      "y": 20,
      "z": 10,
      "name": "Plant_Leaves_Aspen",
      "support": 15
    },
    {
      "x": 20,
      "y": 7,
      "z": 11,
      "name": "Wood_Birch_Trunk_Full",
      "support": 15
    },
    {
      "x": 20,
      "y": 8,
      "z": 11,
      "name": "Wood_Birch_Trunk",
      "support": 15
    },
    {
      "x": 20,
      "y": 9,
      "z": 11,
      "name": "Wood_Birch_Trunk_Full",
      "support": 15
    },
    {
      "x": 20,
      "y": 17,
      "z": 11,
      "name": "Wood_Birch_Branch_Long",
      "support": 15,
      "rotation": 4
    },
    {
      "x": 20,
      "y": 19,
      "z": 11,
      "name": "Plant_Leaves_Aspen",
      "support": 15
    },
    {
      "x": 20,
      "y": 20,
      "z": 11,
      "name": "Plant_Leaves_Aspen",
      "support": 15
    },
    {
      "x": 20,
      "y": 28,
      "z": 11,
      "name": "Plant_Leaves_Aspen",
      "support": 15
    },
    {
      "x": 20,
      "y": 8,
      "z": 12,
      "name": "Wood_Birch_Trunk_Full",
      "support": 15
    },
    {
      "x": 20,
      "y": 9,
      "z": 12,
      "name": "Wood_Birch_Trunk",
      "support": 15
    },
    {
      "x": 20,
      "y": 10,
      "z": 12,
      "name": "Wood_Birch_Trunk_Full",
      "support": 15
    },
    {
      "x": 20,
      "y": 17,
      "z": 12,
      "name": "Wood_Birch_Trunk_Full",
      "support": 15
    },
    {
      "x": 20,
      "y": 18,
      "z": 12,
      "name": "Wood_Birch_Trunk",
      "support": 15
    },
    {
      "x": 20,
      "y": 19,
      "z": 12,
      "name": "Wood_Birch_Trunk",
      "support": 15
    },
    {
      "x": 20,
      "y": 20,
      "z": 12,
      "name": "Wood_Birch_Trunk",
      "support": 15
    },
    {
      "x": 20,
      "y": 21,
      "z": 12,
      "name": "Wood_Birch_Trunk_Full",
      "support": 15
    },
    {
      "x": 20,
      "y": 23,
      "z": 12,
      "name": "Wood_Birch_Branch_Corner",
      "support": 15,
      "rotation": 2
    },
    {
      "x": 20,
      "y": 24,
      "z": 12,
      "name": "Wood_Birch_Branch_Long",
      "support": 15
    },
    {
      "x": 20,
      "y": 25,
      "z": 12,
      "name": "Wood_Birch_Branch_Long",
      "support": 15
    },
    {
      "x": 20,
      "y": 26,
      "z": 12,
      "name": "Wood_Birch_Branch_Corner",
      "support": 15,
      "rotation": 8
    },
    {
      "x": 20,
      "y": 28,
      "z": 12,
      "name": "Plant_Leaves_Aspen",
      "support": 15
    },
    {
      "x": 20,
      "y": 29,
      "z": 12,
      "name": "Plant_Leaves_Aspen",
      "support": 15
    },
    {
      "x": 20,
      "y": 21,
      "z": 13,
      "name": "Wood_Birch_Trunk_Full",
      "support": 15
    },
    {
      "x": 20,
      "y": 22,
      "z": 13,
      "name": "Wood_Birch_Trunk",
      "support": 15
    },
    {
      "x": 20,
      "y": 23,
      "z": 13,
      "name": "Wood_Birch_Trunk_Full",
      "support": 15
    },
    {
      "x": 20,
      "y": 26,
      "z": 13,
      "name": "Wood_Birch_Branch_Corner",
      "support": 15
    },
    {
      "x": 20,
      "y": 27,
      "z": 13,
      "name": "Wood_Birch_Branch_Long",
      "support": 15
    },
    {
      "x": 20,
      "y": 28,
      "z": 13,
      "name": "Wood_Birch_Branch_Long",
      "support": 15
    },
    {
      "x": 20,
      "y": 29,
      "z": 13,
      "name": "Plant_Leaves_Aspen",
      "support": 15
    },
    {
      "x": 20,
      "y": 21,
      "z": 14,
      "name": "Plant_Leaves_Aspen",
      "support": 15
    },
    {
      "x": 20,
      "y": 23,
      "z": 14,
      "name": "Wood_Birch_Trunk_Full",
      "support": 15,
      "rotation": 4
    },
    {
      "x": 20,
      "y": 24,
      "z": 14,
      "name": "Wood_Birch_Trunk_Full",
      "support": 15,
      "rotation": 4
    },
    {
      "x": 20,
      "y": 25,
      "z": 14,
      "name": "Wood_Birch_Branch_Corner",
      "support": 15,
      "rotation": 8
    },
    {
      "x": 20,
      "y": 26,
      "z": 14,
      "name": "Plant_Leaves_Aspen",
      "support": 15
    },
    {
      "x": 20,
      "y": 27,
      "z": 14,
      "name": "Plant_Leaves_Aspen",
      "support": 15
    },
    {
      "x": 20,
      "y": 28,
      "z": 14,
      "name": "Plant_Leaves_Aspen",
      "support": 15
    },
    {
      "x": 20,
      "y": 29,
      "z": 14,
      "name": "Plant_Leaves_Aspen",
      "support": 15
    },
    {
      "x": 20,
      "y": 19,
      "z": 15,
      "name": "Wood_Birch_Trunk_Full",
      "support": 15
    },
    {
      "x": 20,
      "y": 20,
      "z": 15,
      "name": "Wood_Birch_Trunk_Full",
      "support": 15
    },
    {
      "x": 20,
      "y": 21,
      "z": 15,
      "name": "Wood_Birch_Branch_Corner",
      "support": 15,
      "rotation": 8
    },
    {
      "x": 20,
      "y": 24,
      "z": 15,
      "name": "Wood_Birch_Trunk_Full",
      "support": 15,
      "rotation": 4
    },
    {
      "x": 20,
      "y": 25,
      "z": 15,
      "name": "Wood_Birch_Branch_Corner",
      "support": 15
    },
    {
      "x": 20,
      "y": 26,
      "z": 15,
      "name": "Wood_Birch_Branch_Long",
      "support": 15
    },
    {
      "x": 20,
      "y": 27,
      "z": 15,
      "name": "Plant_Leaves_Aspen",
      "support": 15
    },
    {
      "x": 20,
      "y": 28,
      "z": 15,
      "name": "Plant_Leaves_Aspen",
      "support": 15
    },
    {
      "x": 20,
      "y": 18,
      "z": 16,
      "name": "Wood_Birch_Trunk_Full",
      "support": 15
    },
    {
      "x": 20,
      "y": 19,
      "z": 16,
      "name": "Wood_Birch_Trunk_Full",
      "support": 15
    },
    {
      "x": 20,
      "y": 21,
      "z": 16,
      "name": "Wood_Birch_Branch_Corner",
      "support": 15
    },
    {
      "x": 20,
      "y": 22,
      "z": 16,
      "name": "Wood_Birch_Branch_Corner",
      "support": 15,
      "rotation": 8
    },
    {
      "x": 20,
      "y": 24,
      "z": 16,
      "name": "Wood_Birch_Trunk_Full",
      "support": 15,
      "rotation": 4
    },
    {
      "x": 20,
      "y": 26,
      "z": 16,
      "name": "Plant_Leaves_Aspen",
      "support": 15
    },
    {
      "x": 20,
      "y": 27,
      "z": 16,
      "name": "Plant_Leaves_Aspen",
      "support": 15
    },
    {
      "x": 20,
      "y": 18,
      "z": 17,
      "name": "Wood_Birch_Trunk_Full",
      "support": 15,
      "rotation": 4
    },
    {
      "x": 20,
      "y": 20,
      "z": 17,
      "name": "Wood_Birch_Branch_Corner",
      "support": 15,
      "rotation": 2
    },
    {
      "x": 20,
      "y": 22,
      "z": 17,
      "name": "Wood_Birch_Branch_Long",
      "support": 15,
      "rotation": 4
    },
    {
      "x": 20,
      "y": 24,
      "z": 17,
      "name": "Wood_Birch_Trunk_Full",
      "support": 15,
      "rotation": 4
    },
    {
      "x": 20,
      "y": 26,
      "z": 17,
      "name": "Plant_Leaves_Aspen",
      "support": 15
    },
    {
      "x": 20,
      "y": 27,
      "z": 17,
      "name": "Plant_Leaves_Aspen",
      "support": 15
    },
    {
      "x": 20,
      "y": 18,
      "z": 18,
      "name": "Wood_Birch_Trunk_Full",
      "support": 15,
      "rotation": 4
    },
    {
      "x": 20,
      "y": 20,
      "z": 18,
      "name": "Wood_Birch_Branch_Corner",
      "support": 15
    },
    {
      "x": 20,
      "y": 21,
      "z": 18,
      "name": "Wood_Birch_Branch_Long",
      "support": 15
    },
    {
      "x": 20,
      "y": 22,
      "z": 18,
      "name": "Wood_Birch_Branch_Corner",
      "support": 15,
      "rotation": 10
    },
    {
      "x": 20,
      "y": 24,
      "z": 18,
      "name": "Wood_Birch_Trunk_Full",
      "support": 15,
      "rotation": 4
    },
    {
      "x": 20,
      "y": 26,
      "z": 18,
      "name": "Plant_Leaves_Aspen",
      "support": 15
    },
    {
      "x": 20,
      "y": 27,
      "z": 18,
      "name": "Plant_Leaves_Aspen",
      "support": 15
    },
    {
      "x": 20,
      "y": 18,
      "z": 19,
      "name": "Wood_Birch_Trunk_Full",
      "support": 15
    },
    {
      "x": 20,
      "y": 19,
      "z": 19,
      "name": "Wood_Birch_Trunk_Full",
      "support": 15
    },
    {
      "x": 20,
      "y": 23,
      "z": 19,
      "name": "Wood_Birch_Trunk_Full",
      "support": 15,
      "rotation": 4
    },
    {
      "x": 20,
      "y": 24,
      "z": 19,
      "name": "Wood_Birch_Trunk_Full",
      "support": 15,
      "rotation": 4
    },
    {
      "x": 20,
      "y": 25,
      "z": 19,
      "name": "Wood_Birch_Branch_Long",
      "support": 15
    },
    {
      "x": 20,
      "y": 26,
      "z": 19,
      "name": "Wood_Birch_Branch_Long",
      "support": 15
    },
    {
      "x": 20,
      "y": 27,
      "z": 19,
      "name": "Plant_Leaves_Aspen",
      "support": 15
    },
    {
      "x": 20,
      "y": 19,
      "z": 20,
      "name": "Wood_Birch_Trunk_Full",
      "support": 15
    },
    {
      "x": 20,
      "y": 20,
      "z": 20,
      "name": "Wood_Birch_Trunk_Full",
      "support": 15
    },
    {
      "x": 20,
      "y": 21,
      "z": 20,
      "name": "Wood_Birch_Trunk_Full",
      "support": 15
    },
    {
      "x": 20,
      "y": 22,
      "z": 20,
      "name": "Wood_Birch_Trunk_Full",
      "support": 15
    },
    {
      "x": 20,
      "y": 23,
      "z": 20,
      "name": "Wood_Birch_Trunk_Full",
      "support": 15
    },
    {
      "x": 20,
      "y": 25,
      "z": 20,
      "name": "Plant_Leaves_Aspen",
      "support": 15
    },
    {
      "x": 20,
      "y": 26,
      "z": 20,
      "name": "Plant_Leaves_Aspen",
      "support": 15
    },
    {
      "x": 20,
      "y": 19,
      "z": 21,
      "name": "Wood_Birch_Branch_Corner",
      "support": 15
    },
    {
      "x": 20,
      "y": 20,
      "z": 21,
      "name": "Plant_Leaves_Aspen",
      "support": 15
    },
    {
      "x": 20,
      "y": 25,
      "z": 21,
      "name": "Plant_Leaves_Aspen",
      "support": 15
    },
    {
      "x": 20,
      "y": 26,
      "z": 21,
      "name": "Plant_Leaves_Aspen",
      "support": 15
    },
    {
      "x": 20,
      "y": 20,
      "z": 22,
      "name": "Plant_Leaves_Aspen",
      "support": 15
    },
    {
      "x": 20,
      "y": 25,
      "z": 22,
      "name": "Plant_Leaves_Aspen",
      "support": 15
    },
    {
      "x": 20,
      "y": 26,
      "z": 22,
      "name": "Plant_Leaves_Aspen",
      "support": 15
    },
    {
      "x": 20,
      "y": 25,
      "z": 23,
      "name": "Plant_Leaves_Aspen",
      "support": 15
    },
    {
      "x": 20,
      "y": 25,
      "z": 24,
      "name": "Plant_Leaves_Aspen",
      "support": 15
    },
    {
      "x": 21,
      "y": 0,
      "z": 6,
      "name": "Wood_Birch_Trunk_Full",
      "support": 15,
      "rotation": 4
    },
    {
      "x": 21,
      "y": 1,
      "z": 6,
      "name": "Wood_Birch_Branch_Corner",
      "support": 15
    },
    {
      "x": 21,
      "y": 2,
      "z": 6,
      "name": "Wood_Birch_Branch_Corner",
      "support": 15,
      "rotation": 8
    },
    {
      "x": 21,
      "y": 0,
      "z": 7,
      "name": "Wood_Birch_Trunk_Full",
      "support": 15,
      "rotation": 4
    },
    {
      "x": 21,
      "y": 2,
      "z": 7,
      "name": "Wood_Birch_Branch_Corner",
      "support": 15,
      "rotation": 10
    },
    {
      "x": 21,
      "y": 0,
      "z": 8,
      "name": "Wood_Birch_Trunk_Full",
      "support": 15
    },
    {
      "x": 21,
      "y": 1,
      "z": 8,
      "name": "Wood_Birch_Trunk_Full",
      "support": 15
    },
    {
      "x": 21,
      "y": 2,
      "z": 8,
      "name": "Wood_Birch_Trunk_Full",
      "support": 15
    },
    {
      "x": 21,
      "y": 3,
      "z": 8,
      "name": "Wood_Birch_Trunk_Full",
      "support": 15
    },
    {
      "x": 21,
      "y": 4,
      "z": 8,
      "name": "Wood_Birch_Trunk_Full",
      "support": 15
    },
    {
      "x": 21,
      "y": 19,
      "z": 8,
      "name": "Plant_Leaves_Aspen",
      "support": 15
    },
    {
      "x": 21,
      "y": 4,
      "z": 9,
      "name": "Wood_Birch_Trunk_Full",
      "support": 15
    },
    {
      "x": 21,
      "y": 5,
      "z": 9,
      "name": "Wood_Birch_Trunk_Full",
      "support": 15
    },
    {
      "x": 21,
      "y": 6,
      "z": 9,
      "name": "Wood_Birch_Trunk_Full",
      "support": 15
    },
    {
      "x": 21,
      "y": 7,
      "z": 9,
      "name": "Wood_Birch_Trunk_Full",
      "support": 15
    },
    {
      "x": 21,
      "y": 19,
      "z": 9,
      "name": "Plant_Leaves_Aspen",
      "support": 15
    },
    {
      "x": 21,
      "y": 20,
      "z": 9,
      "name": "Plant_Leaves_Aspen",
      "support": 15
    },
    {
      "x": 21,
      "y": 7,
      "z": 10,
      "name": "Wood_Birch_Trunk_Full",
      "support": 15,
      "rotation": 4
    },
    {
      "x": 21,
      "y": 19,
      "z": 10,
      "name": "Plant_Leaves_Aspen",
      "support": 15
    },
    {
      "x": 21,
      "y": 20,
      "z": 10,
      "name": "Plant_Leaves_Aspen",
      "support": 15
    },
    {
      "x": 21,
      "y": 0,
      "z": 11,
      "name": "Wood_Birch_Branch_Long",
      "support": 15
    },
    {
      "x": 21,
      "y": 1,
      "z": 11,
      "name": "Wood_Birch_Branch_Long",
      "support": 15
    },
    {
      "x": 21,
      "y": 2,
      "z": 11,
      "name": "Wood_Birch_Branch_Long",
      "support": 15
    },
    {
      "x": 21,
      "y": 3,
      "z": 11,
      "name": "Wood_Birch_Trunk_Full",
      "support": 15
    },
    {
      "x": 21,
      "y": 4,
      "z": 11,
      "name": "Wood_Birch_Trunk",
      "support": 15
    },
    {
      "x": 21,
      "y": 5,
      "z": 11,
      "name": "Wood_Birch_Trunk",
      "support": 15
    },
    {
      "x": 21,
      "y": 6,
      "z": 11,
      "name": "Wood_Birch_Trunk",
      "support": 15
    },
    {
      "x": 21,
      "y": 7,
      "z": 11,
      "name": "Wood_Birch_Trunk",
      "support": 15
    },
    {
      "x": 21,
      "y": 8,
      "z": 11,
      "name": "Wood_Birch_Trunk",
      "support": 15
    },
    {
      "x": 21,
      "y": 9,
      "z": 11,
      "name": "Wood_Birch_Trunk",
      "support": 15
    },
    {
      "x": 21,
      "y": 10,
      "z": 11,
      "name": "Wood_Birch_Trunk_Full",
      "support": 15
    },
    {
      "x": 21,
      "y": 11,
      "z": 11,
      "name": "Wood_Birch_Trunk_Full",
      "support": 15
    },
    {
      "x": 21,
      "y": 19,
      "z": 11,
      "name": "Plant_Leaves_Aspen",
      "support": 15
    },
    {
      "x": 21,
      "y": 20,
      "z": 11,
      "name": "Plant_Leaves_Aspen",
      "support": 15
    },
    {
      "x": 21,
      "y": 28,
      "z": 11,
      "name": "Plant_Leaves_Aspen",
      "support": 15
    },
    {
      "x": 21,
      "y": 5,
      "z": 12,
      "name": "Wood_Birch_Trunk_Full",
      "support": 15,
      "rotation": 4
    },
    {
      "x": 21,
      "y": 7,
      "z": 12,
      "name": "Wood_Birch_Trunk_Full",
      "support": 15
    },
    {
      "x": 21,
      "y": 8,
      "z": 12,
      "name": "Wood_Birch_Trunk",
      "support": 15
    },
    {
      "x": 21,
      "y": 9,
      "z": 12,
      "name": "Wood_Birch_Trunk",
      "support": 15
    },
    {
      "x": 21,
      "y": 10,
      "z": 12,
      "name": "Wood_Birch_Trunk",
      "support": 15
    },
    {
      "x": 21,
      "y": 11,
      "z": 12,
      "name": "Wood_Birch_Trunk",
      "support": 15
    },
    {
      "x": 21,
      "y": 12,
      "z": 12,
      "name": "Wood_Birch_Trunk",
      "support": 15
    },
    {
      "x": 21,
      "y": 13,
      "z": 12,
      "name": "Wood_Birch_Trunk",
      "support": 15
    },
    {
      "x": 21,
      "y": 14,
      "z": 12,
      "name": "Wood_Birch_Trunk",
      "support": 15
    },
    {
      "x": 21,
      "y": 15,
      "z": 12,
      "name": "Wood_Birch_Trunk",
      "support": 15
    },
    {
      "x": 21,
      "y": 16,
      "z": 12,
      "name": "Wood_Birch_Trunk",
      "support": 15
    },
    {
      "x": 21,
      "y": 17,
      "z": 12,
      "name": "Wood_Birch_Trunk",
      "support": 15
    },
    {
      "x": 21,
      "y": 18,
      "z": 12,
      "name": "Plant_Leaves_Aspen",
      "support": 15
    },
    {
      "x": 21,
      "y": 19,
      "z": 12,
      "name": "Plant_Leaves_Aspen",
      "support": 15
    },
    {
      "x": 21,
      "y": 20,
      "z": 12,
      "name": "Plant_Leaves_Aspen",
      "support": 15
    },
    {
      "x": 21,
      "y": 28,
      "z": 12,
      "name": "Plant_Leaves_Aspen",
      "support": 15
    },
    {
      "x": 21,
      "y": 5,
      "z": 13,
      "name": "Wood_Birch_Trunk_Full",
      "support": 15,
      "rotation": 4
    },
    {
      "x": 21,
      "y": 8,
      "z": 13,
      "name": "Wood_Birch_Trunk_Full",
      "support": 15
    },
    {
      "x": 21,
      "y": 9,
      "z": 13,
      "name": "Wood_Birch_Trunk_Full",
      "support": 15
    },
    {
      "x": 21,
      "y": 10,
      "z": 13,
      "name": "Wood_Birch_Trunk_Full",
      "support": 15
    },
    {
      "x": 21,
      "y": 11,
      "z": 13,
      "name": "Wood_Birch_Trunk",
      "support": 15
    },
    {
      "x": 21,
      "y": 12,
      "z": 13,
      "name": "Wood_Birch_Trunk_Full",
      "support": 15
    },
    {
      "x": 21,
      "y": 26,
      "z": 13,
      "name": "Plant_Leaves_Aspen",
      "support": 15
    },
    {
      "x": 21,
      "y": 28,
      "z": 13,
      "name": "Plant_Leaves_Aspen",
      "support": 15
    },
    {
      "x": 21,
      "y": 29,
      "z": 13,
      "name": "Plant_Leaves_Aspen",
      "support": 15
    },
    {
      "x": 21,
      "y": 0,
      "z": 14,
      "name": "Wood_Birch_Branch_Corner",
      "support": 15,
      "rotation": 2
    },
    {
      "x": 21,
      "y": 1,
      "z": 14,
      "name": "Wood_Birch_Branch_Long",
      "support": 15
    },
    {
      "x": 21,
      "y": 2,
      "z": 14,
      "name": "Wood_Birch_Trunk_Full",
      "support": 15
    },
    {
      "x": 21,
      "y": 3,
      "z": 14,
      "name": "Wood_Birch_Trunk_Full",
      "support": 15
    },
    {
      "x": 21,
      "y": 4,
      "z": 14,
      "name": "Wood_Birch_Trunk_Full",
      "support": 15
    },
    {
      "x": 21,
      "y": 5,
      "z": 14,
      "name": "Wood_Birch_Trunk_Full",
      "support": 15
    },
    {
      "x": 21,
      "y": 21,
      "z": 14,
      "name": "Plant_Leaves_Aspen",
      "support": 15
    },
    {
      "x": 21,
      "y": 26,
      "z": 14,
      "name": "Plant_Leaves_Aspen",
      "support": 15
    },
    {
      "x": 21,
      "y": 27,
      "z": 14,
      "name": "Plant_Leaves_Aspen",
      "support": 15
    },
    {
      "x": 21,
      "y": 28,
      "z": 14,
      "name": "Plant_Leaves_Aspen",
      "support": 15
    },
    {
      "x": 21,
      "y": 29,
      "z": 14,
      "name": "Plant_Leaves_Aspen",
      "support": 15
    },
    {
      "x": 21,
      "y": 0,
      "z": 15,
      "name": "Wood_Birch_Branch_Long",
      "support": 15,
      "rotation": 4
    },
    {
      "x": 21,
      "y": 21,
      "z": 15,
      "name": "Plant_Leaves_Aspen",
      "support": 15
    },
    {
      "x": 21,
      "y": 26,
      "z": 15,
      "name": "Plant_Leaves_Aspen",
      "support": 15
    },
    {
      "x": 21,
      "y": 27,
      "z": 15,
      "name": "Plant_Leaves_Aspen",
      "support": 15
    },
    {
      "x": 21,
      "y": 28,
      "z": 15,
      "name": "Plant_Leaves_Aspen",
      "support": 15
    },
    {
      "x": 21,
      "y": -1,
      "z": 16,
      "name": "Wood_Birch_Branch_Corner",
      "support": 15,
      "rotation": 2
    },
    {
      "x": 21,
      "y": 0,
      "z": 16,
      "name": "Wood_Birch_Branch_Corner",
      "support": 15,
      "rotation": 10
    },
    {
      "x": 21,
      "y": 21,
      "z": 16,
      "name": "Plant_Leaves_Aspen",
      "support": 15
    },
    {
      "x": 21,
      "y": 26,
      "z": 16,
      "name": "Plant_Leaves_Aspen",
      "support": 15
    },
    {
      "x": 21,
      "y": -1,
      "z": 17,
      "name": "Wood_Birch_Branch_Corner",
      "support": 15
    },
    {
      "x": 21,
      "y": 26,
      "z": 17,
      "name": "Plant_Leaves_Aspen",
      "support": 15
    },
    {
      "x": 21,
      "y": 26,
      "z": 18,
      "name": "Plant_Leaves_Aspen",
      "support": 15
    },
    {
      "x": 21,
      "y": 25,
      "z": 19,
      "name": "Plant_Leaves_Aspen",
      "support": 15
    },
    {
      "x": 21,
      "y": 26,
      "z": 19,
      "name": "Plant_Leaves_Aspen",
      "support": 15
    },
    {
      "x": 21,
      "y": 20,
      "z": 20,
      "name": "Plant_Leaves_Aspen",
      "support": 15
    },
    {
      "x": 21,
      "y": 25,
      "z": 20,
      "name": "Plant_Leaves_Aspen",
      "support": 15
    },
    {
      "x": 21,
      "y": 26,
      "z": 20,
      "name": "Plant_Leaves_Aspen",
      "support": 15
    },
    {
      "x": 21,
      "y": 20,
      "z": 21,
      "name": "Plant_Leaves_Aspen",
      "support": 15
    },
    {
      "x": 21,
      "y": 25,
      "z": 21,
      "name": "Plant_Leaves_Aspen",
      "support": 15
    },
    {
      "x": 21,
      "y": 20,
      "z": 22,
      "name": "Plant_Leaves_Aspen",
      "support": 15
    },
    {
      "x": 21,
      "y": 25,
      "z": 22,
      "name": "Plant_Leaves_Aspen",
      "support": 15
    },
    {
      "x": 22,
      "y": 19,
      "z": 9,
      "name": "Plant_Leaves_Aspen",
      "support": 15
    },
    {
      "x": 22,
      "y": 19,
      "z": 10,
      "name": "Plant_Leaves_Aspen",
      "support": 15
    },
    {
      "x": 22,
      "y": 20,
      "z": 10,
      "name": "Plant_Leaves_Aspen",
      "support": 15
    },
    {
      "x": 22,
      "y": 4,
      "z": 11,
      "name": "Wood_Birch_Trunk_Full",
      "support": 15
    },
    {
      "x": 22,
      "y": 5,
      "z": 11,
      "name": "Wood_Birch_Trunk_Full",
      "support": 15
    },
    {
      "x": 22,
      "y": 6,
      "z": 11,
      "name": "Wood_Birch_Trunk_Full",
      "support": 15
    },
    {
      "x": 22,
      "y": 7,
      "z": 11,
      "name": "Wood_Birch_Trunk_Full",
      "support": 15
    },
    {
      "x": 22,
      "y": 8,
      "z": 11,
      "name": "Wood_Birch_Trunk_Full",
      "support": 15
    },
    {
      "x": 22,
      "y": 19,
      "z": 11,
      "name": "Plant_Leaves_Aspen",
      "support": 15
    },
    {
      "x": 22,
      "y": 20,
      "z": 11,
      "name": "Plant_Leaves_Aspen",
      "support": 15
    },
    {
      "x": 22,
      "y": 8,
      "z": 12,
      "name": "Wood_Birch_Trunk_Full",
      "support": 15
    },
    {
      "x": 22,
      "y": 9,
      "z": 12,
      "name": "Wood_Birch_Trunk_Full",
      "support": 15
    },
    {
      "x": 22,
      "y": 10,
      "z": 12,
      "name": "Wood_Birch_Trunk",
      "support": 15
    },
    {
      "x": 22,
      "y": 11,
      "z": 12,
      "name": "Wood_Birch_Trunk",
      "support": 15
    },
    {
      "x": 22,
      "y": 12,
      "z": 12,
      "name": "Wood_Birch_Trunk_Full",
      "support": 15
    },
    {
      "x": 22,
      "y": 13,
      "z": 12,
      "name": "Wood_Birch_Trunk_Full",
      "support": 15
    },
    {
      "x": 22,
      "y": 17,
      "z": 12,
      "name": "Wood_Birch_Branch_Long",
      "support": 15,
      "rotation": 5
    },
    {
      "x": 22,
      "y": 19,
      "z": 12,
      "name": "Plant_Leaves_Aspen",
      "support": 15
    },
    {
      "x": 22,
      "y": 20,
      "z": 12,
      "name": "Plant_Leaves_Aspen",
      "support": 15
    },
    {
      "x": 22,
      "y": 28,
      "z": 12,
      "name": "Plant_Leaves_Aspen",
      "support": 15
    },
    {
      "x": 22,
      "y": 10,
      "z": 13,
      "name": "Wood_Birch_Trunk_Full",
      "support": 15
    },
    {
      "x": 22,
      "y": 11,
      "z": 13,
      "name": "Wood_Birch_Trunk_Full",
      "support": 15
    },
    {
      "x": 22,
      "y": 19,
      "z": 13,
      "name": "Plant_Leaves_Aspen",
      "support": 15
    },
    {
      "x": 22,
      "y": 28,
      "z": 13,
      "name": "Plant_Leaves_Aspen",
      "support": 15
    },
    {
      "x": 22,
      "y": 26,
      "z": 14,
      "name": "Plant_Leaves_Aspen",
      "support": 15
    },
    {
      "x": 22,
      "y": 27,
      "z": 14,
      "name": "Plant_Leaves_Aspen",
      "support": 15
    },
    {
      "x": 22,
      "y": 28,
      "z": 14,
      "name": "Plant_Leaves_Aspen",
      "support": 15
    },
    {
      "x": 22,
      "y": 26,
      "z": 15,
      "name": "Plant_Leaves_Aspen",
      "support": 15
    },
    {
      "x": 22,
      "y": 26,
      "z": 16,
      "name": "Plant_Leaves_Aspen",
      "support": 15
    },
    {
      "x": 22,
      "y": 26,
      "z": 17,
      "name": "Plant_Leaves_Aspen",
      "support": 15
    },
    {
      "x": 22,
      "y": 25,
      "z": 19,
      "name": "Plant_Leaves_Aspen",
      "support": 15
    },
    {
      "x": 22,
      "y": 25,
      "z": 20,
      "name": "Plant_Leaves_Aspen",
      "support": 15
    },
    {
      "x": 22,
      "y": 25,
      "z": 21,
      "name": "Plant_Leaves_Aspen",
      "support": 15
    },
    {
      "x": 23,
      "y": 19,
      "z": 10,
      "name": "Plant_Leaves_Aspen",
      "support": 15
    },
    {
      "x": 23,
      "y": 4,
      "z": 11,
      "name": "Wood_Birch_Branch_Corner",
      "support": 15,
      "rotation": 3
    },
    {
      "x": 23,
      "y": 5,
      "z": 11,
      "name": "Wood_Birch_Branch_Corner",
      "support": 15,
      "rotation": 11
    },
    {
      "x": 23,
      "y": 19,
      "z": 11,
      "name": "Plant_Leaves_Aspen",
      "support": 15
    },
    {
      "x": 23,
      "y": 12,
      "z": 12,
      "name": "Wood_Birch_Trunk",
      "support": 15,
      "rotation": 5
    },
    {
      "x": 23,
      "y": 16,
      "z": 12,
      "name": "Plant_Leaves_Aspen",
      "support": 15
    },
    {
      "x": 23,
      "y": 17,
      "z": 12,
      "name": "Wood_Birch_Branch_Corner",
      "support": 15,
      "rotation": 1
    },
    {
      "x": 23,
      "y": 18,
      "z": 12,
      "name": "Wood_Birch_Branch_Long",
      "support": 15
    },
    {
      "x": 23,
      "y": 19,
      "z": 12,
      "name": "Wood_Birch_Branch_Long",
      "support": 15
    },
    {
      "x": 23,
      "y": 20,
      "z": 12,
      "name": "Plant_Leaves_Aspen",
      "support": 15
    },
    {
      "x": 23,
      "y": 16,
      "z": 13,
      "name": "Plant_Leaves_Aspen",
      "support": 15
    },
    {
      "x": 23,
      "y": 19,
      "z": 13,
      "name": "Plant_Leaves_Aspen",
      "support": 15
    },
    {
      "x": 23,
      "y": 20,
      "z": 13,
      "name": "Plant_Leaves_Aspen",
      "support": 15
    },
    {
      "x": 23,
      "y": 16,
      "z": 17,
      "name": "Wood_Birch_Branch_Corner",
      "support": 15
    },
    {
      "x": 23,
      "y": 25,
      "z": 19,
      "name": "Plant_Leaves_Aspen",
      "support": 15
    },
    {
      "x": 23,
      "y": 25,
      "z": 20,
      "name": "Plant_Leaves_Aspen",
      "support": 15
    },
    {
      "x": 23,
      "y": 25,
      "z": 21,
      "name": "Plant_Leaves_Aspen",
      "support": 15
    },
    {
      "x": 24,
      "y": 14,
      "z": 9,
      "name": "Plant_Leaves_Aspen",
      "support": 15
    },
    {
      "x": 24,
      "y": 14,
      "z": 10,
      "name": "Plant_Leaves_Aspen",
      "support": 15
    },
    {
      "x": 24,
      "y": 0,
      "z": 11,
      "name": "Wood_Birch_Branch_Corner",
      "support": 15,
      "rotation": 3
    },
    {
      "x": 24,
      "y": 1,
      "z": 11,
      "name": "Wood_Birch_Branch_Long",
      "support": 15
    },
    {
      "x": 24,
      "y": 2,
      "z": 11,
      "name": "Wood_Birch_Branch_Long",
      "support": 15
    },
    {
      "x": 24,
      "y": 3,
      "z": 11,
      "name": "Wood_Birch_Branch_Long",
      "support": 15
    },
    {
      "x": 24,
      "y": 4,
      "z": 11,
      "name": "Wood_Birch_Branch_Corner",
      "support": 15,
      "rotation": 11
    },
    {
      "x": 24,
      "y": 14,
      "z": 11,
      "name": "Plant_Leaves_Aspen",
      "support": 15
    },
    {
      "x": 24,
      "y": 15,
      "z": 11,
      "name": "Plant_Leaves_Aspen",
      "support": 15
    },
    {
      "x": 24,
      "y": 16,
      "z": 11,
      "name": "Plant_Leaves_Aspen",
      "support": 15
    },
    {
      "x": 24,
      "y": 19,
      "z": 11,
      "name": "Plant_Leaves_Aspen",
      "support": 15
    },
    {
      "x": 24,
      "y": 12,
      "z": 12,
      "name": "Wood_Birch_Trunk",
      "support": 15,
      "rotation": 5
    },
    {
      "x": 24,
      "y": 14,
      "z": 12,
      "name": "Plant_Leaves_Aspen",
      "support": 15
    },
    {
      "x": 24,
      "y": 16,
      "z": 12,
      "name": "Plant_Leaves_Aspen",
      "support": 15
    },
    {
      "x": 24,
      "y": 19,
      "z": 12,
      "name": "Plant_Leaves_Aspen",
      "support": 15
    },
    {
      "x": 24,
      "y": 20,
      "z": 12,
      "name": "Plant_Leaves_Aspen",
      "support": 15
    },
    {
      "x": 24,
      "y": 16,
      "z": 13,
      "name": "Plant_Leaves_Aspen",
      "support": 15
    },
    {
      "x": 24,
      "y": 19,
      "z": 13,
      "name": "Plant_Leaves_Aspen",
      "support": 15
    },
    {
      "x": 25,
      "y": 14,
      "z": 9,
      "name": "Plant_Leaves_Aspen",
      "support": 15
    },
    {
      "x": 25,
      "y": 13,
      "z": 10,
      "name": "Wood_Birch_Branch_Corner",
      "support": 15,
      "rotation": 2
    },
    {
      "x": 25,
      "y": 14,
      "z": 10,
      "name": "Wood_Birch_Branch_Long",
      "support": 15
    },
    {
      "x": 25,
      "y": 15,
      "z": 10,
      "name": "Plant_Leaves_Aspen",
      "support": 15
    },
    {
      "x": 25,
      "y": 0,
      "z": 11,
      "name": "Wood_Birch_Branch_Long",
      "support": 15,
      "rotation": 5
    },
    {
      "x": 25,
      "y": 13,
      "z": 11,
      "name": "Wood_Birch_Branch_Long",
      "support": 15,
      "rotation": 4
    },
    {
      "x": 25,
      "y": 14,
      "z": 11,
      "name": "Plant_Leaves_Aspen",
      "support": 15
    },
    {
      "x": 25,
      "y": 15,
      "z": 11,
      "name": "Plant_Leaves_Aspen",
      "support": 15
    },
    {
      "x": 25,
      "y": 16,
      "z": 11,
      "name": "Plant_Leaves_Aspen",
      "support": 15
    },
    {
      "x": 25,
      "y": 17,
      "z": 11,
      "name": "Plant_Leaves_Aspen",
      "support": 15
    },
    {
      "x": 25,
      "y": 12,
      "z": 12,
      "name": "Wood_Birch_Trunk_Full",
      "support": 15,
      "rotation": 5
    },
    {
      "x": 25,
      "y": 13,
      "z": 12,
      "name": "Wood_Birch_Trunk",
      "support": 15
    },
    {
      "x": 25,
      "y": 14,
      "z": 12,
      "name": "Wood_Birch_Trunk",
      "support": 15
    },
    {
      "x": 25,
      "y": 15,
      "z": 12,
      "name": "Wood_Birch_Branch_Long",
      "support": 15
    },
    {
      "x": 25,
      "y": 16,
      "z": 12,
      "name": "Wood_Birch_Branch_Long",
      "support": 15
    },
    {
      "x": 25,
      "y": 17,
      "z": 12,
      "name": "Plant_Leaves_Aspen",
      "support": 15
    },
    {
      "x": 25,
      "y": 19,
      "z": 12,
      "name": "Plant_Leaves_Aspen",
      "support": 15
    },
    {
      "x": 25,
      "y": 14,
      "z": 13,
      "name": "Plant_Leaves_Aspen",
      "support": 15
    },
    {
      "x": 25,
      "y": 16,
      "z": 13,
      "name": "Plant_Leaves_Aspen",
      "support": 15
    },
    {
      "x": 25,
      "y": 17,
      "z": 13,
      "name": "Plant_Leaves_Aspen",
      "support": 15
    },
    {
      "x": 25,
      "y": 16,
      "z": 14,
      "name": "Plant_Leaves_Aspen",
      "support": 15
    },
    {
      "x": 26,
      "y": 14,
      "z": 9,
      "name": "Plant_Leaves_Aspen",
      "support": 15
    },
    {
      "x": 26,
      "y": 14,
      "z": 10,
      "name": "Plant_Leaves_Aspen",
      "support": 15
    },
    {
      "x": 26,
      "y": 0,
      "z": 11,
      "name": "Wood_Birch_Branch_Long",
      "support": 15,
      "rotation": 5
    },
    {
      "x": 26,
      "y": 14,
      "z": 11,
      "name": "Plant_Leaves_Aspen",
      "support": 15
    },
    {
      "x": 26,
      "y": 16,
      "z": 11,
      "name": "Plant_Leaves_Aspen",
      "support": 15
    },
    {
      "x": 26,
      "y": 17,
      "z": 11,
      "name": "Plant_Leaves_Aspen",
      "support": 15
    },
    {
      "x": 26,
      "y": 14,
      "z": 12,
      "name": "Plant_Leaves_Aspen",
      "support": 15
    },
    {
      "x": 26,
      "y": 16,
      "z": 12,
      "name": "Plant_Leaves_Aspen",
      "support": 15
    },
    {
      "x": 26,
      "y": 17,
      "z": 12,
      "name": "Plant_Leaves_Aspen",
      "support": 15
    },
    {
      "x": 26,
      "y": 14,
      "z": 13,
      "name": "Plant_Leaves_Aspen",
      "support": 15
    },
    {
      "x": 26,
      "y": 16,
      "z": 13,
      "name": "Plant_Leaves_Aspen",
      "support": 15
    },
    {
      "x": 26,
      "y": 17,
      "z": 13,
      "name": "Plant_Leaves_Aspen",
      "support": 15
    },
    {
      "x": 26,
      "y": 16,
      "z": 14,
      "name": "Plant_Leaves_Aspen",
      "support": 15
    },
    {
      "x": 27,
      "y": 14,
      "z": 9,
      "name": "Plant_Leaves_Aspen",
      "support": 15
    },
    {
      "x": 27,
      "y": 14,
      "z": 10,
      "name": "Plant_Leaves_Aspen",
      "support": 15
    },
    {
      "x": 27,
      "y": 0,
      "z": 11,
      "name": "Wood_Birch_Branch_Corner",
      "support": 15,
      "rotation": 1
    },
    {
      "x": 27,
      "y": 1,
      "z": 11,
      "name": "Wood_Birch_Branch_Long",
      "support": 15
    },
    {
      "x": 27,
      "y": 2,
      "z": 11,
      "name": "Wood_Birch_Branch_Corner",
      "support": 15,
      "rotation": 8
    },
    {
      "x": 27,
      "y": 14,
      "z": 11,
      "name": "Plant_Leaves_Aspen",
      "support": 15
    },
    {
      "x": 27,
      "y": 16,
      "z": 11,
      "name": "Plant_Leaves_Aspen",
      "support": 15
    },
    {
      "x": 27,
      "y": 1,
      "z": 12,
      "name": "Wood_Birch_Branch_Corner",
      "support": 15,
      "rotation": 3
    },
    {
      "x": 27,
      "y": 2,
      "z": 12,
      "name": "Wood_Birch_Branch_Corner",
      "support": 15,
      "rotation": 10
    },
    {
      "x": 27,
      "y": 16,
      "z": 12,
      "name": "Plant_Leaves_Aspen",
      "support": 15
    },
    {
      "x": 27,
      "y": 17,
      "z": 12,
      "name": "Plant_Leaves_Aspen",
      "support": 15
    },
    {
      "x": 27,
      "y": 16,
      "z": 13,
      "name": "Plant_Leaves_Aspen",
      "support": 15
    },
    {
      "x": 28,
      "y": 1,
      "z": 12,
      "name": "Wood_Birch_Branch_Long",
      "support": 15,
      "rotation": 5
    },
    {
      "x": 28,
      "y": 16,
      "z": 12,
      "name": "Plant_Leaves_Aspen",
      "support": 15
    },
    {
      "x": 28,
      "y": 16,
      "z": 13,
      "name": "Plant_Leaves_Aspen",
      "support": 15
    },
    {
      "x": 29,
      "y": 1,
      "z": 12,
      "name": "Wood_Birch_Branch_Corner",
      "support": 15,
      "rotation": 11
    }
  ]
}