{
  "version": 8,
  "blockIdVersion": 11,
  "anchorX": 0,
  "anchorY": 1,
  "anchorZ": 0,
  "blocks": [
    {
      "x": -4,
      "y": 0,
      "z": -5,
      "name": "Rock_Marble_Brick"
    },
    {
      "x": -4,
      "y": 1,
      "z": -5,
      "name": "Rock_Marble_Brick"
    },
    {
      "x": -4,
      "y": 7,
      "z": -5,
      "name": "Rock_Marble_Brick",
      "rotation": 1
    },
    {
      "x": -4,
      "y": 8,
      "z": -5,
      "name": "Rock_Marble_Brick_Roof_Shallow",
      "rotation": 3
    },
    {
      "x": -4,
      "y": 0,
      "z": -4,
      "name": "Rock_Marble_Brick"
    },
    {
      "x": -4,
      "y": 1,
      "z": -4,
      "name": "Rock_Marble_Brick"
    },
    {
      "x": -4,
      "y": 7,
      "z": -4,
      "name": "Rock_Marble_Brick",
      "rotation": 1
    },
    {
      "x": -4,
      "y": 8,
      "z": -4,
      "name": "Rock_Marble_Brick_Roof_Shallow",
      "rotation": 3
    },
    {
      "x": -4,
      "y": 0,
      "z": -3,
      "name": "Rock_Marble_Brick"
    },
    {
      "x": -4,
      "y": 1,
      "z": -3,
      "name": "Rock_Marble_Brick"
    },
    {
      "x": -4,
      "y": 7,
      "z": -3,
      "name": "Rock_Marble_Brick",
      "rotation": 1
    },
    {
      "x": -4,
      "y": 8,
      "z": -3,
      "name": "Rock_Marble_Brick_Roof_Shallow",
      "rotation": 3
    },
    {
      "x": -4,
      "y": 0,
      "z": -2,
      "name": "Rock_Marble_Brick"
    },
    {
      "x": -4,
      "y": 1,
      "z": -2,
      "name": "Rock_Marble_Brick"
    },
    {
      "x": -4,
      "y": 7,
      "z": -2,
      "name": "Rock_Marble_Brick",
      "rotation": 1
    },
    {
      "x": -4,
      "y": 8,
      "z": -2,
      "name": "Rock_Marble_Brick_Roof_Shallow",
      "rotation": 3
    },
    {
      "x": -4,
      "y": 0,
      "z": -1,
      "name": "Rock_Marble_Brick"
    },
    {
      "x": -4,
      "y": 1,
      "z": -1,
      "name": "Rock_Marble_Brick"
    },
    {
      "x": -4,
      "y": 7,
      "z": -1,
      "name": "Rock_Marble_Brick",
      "rotation": 1
    },
    {
      "x": -4,
      "y": 8,
      "z": -1,
      "name": "Rock_Marble_Brick_Roof_Shallow",
      "rotation": 3
    },
    {
      "x": -4,
      "y": 0,
      "z": 0,
      "name": "Rock_Marble_Brick"
    },
    {
      "x": -4,
      "y": 1,
      "z": 0,
      "name": "Rock_Marble_Brick"
    },
    {
      "x": -4,
      "y": 7,
      "z": 0,
      "name": "Rock_Marble_Brick",
      "rotation": 1
    },
    {
      "x": -4,
      "y": 8,
      "z": 0,
      "name": "Rock_Marble_Brick_Roof_Shallow",
      "rotation": 3
    },
    {
      "x": -4,
      "y": 0,
      "z": 1,
      "name": "Rock_Marble_Brick"
    },
    {
      "x": -4,
      "y": 1,
      "z": 1,
      "name": "Rock_Marble_Brick"
    },
    {
      "x": -4,
      "y": 7,
      "z": 1,
      "name": "Rock_Marble_Brick",
      "rotation": 1
    },
    {
      "x": -4,
      "y": 8,
      "z": 1,
      "name": "Rock_Marble_Brick_Roof_Shallow",
      "rotation": 3
    },
    {
      "x": -4,
      "y": 0,
      "z": 2,
      "name": "Rock_Marble_Brick"
    },
    {
      "x": -4,
      "y": 1,
      "z": 2,
      "name": "Rock_Marble_Brick"
    },
    {
      "x": -4,
      "y": 7,
      "z": 2,
      "name": "Rock_Marble_Brick",
      "rotation": 1
    },
    {
      "x": -4,
      "y": 8,
      "z": 2,
      "name": "Rock_Marble_Brick_Roof_Shallow",
      "rotation": 3
    },
    {
      "x": -4,
      "y": 0,
      "z": 3,
      "name": "Rock_Marble_Brick"
    },
    {
      "x": -4,
      "y": 1,
      "z": 3,
      "name": "Rock_Marble_Brick"
    },
    {
      "x": -4,
      "y": 7,
      "z": 3,
      "name": "Rock_Marble_Brick",
      "rotation": 1
    },
    {
      "x": -4,
      "y": 8,
      "z": 3,
      "name": "Rock_Marble_Brick_Roof_Shallow",
      "rotation": 3
    },
    {
      "x": -4,
      "y": 0,
      "z": 4,
      "name": "Rock_Marble_Brick"
    },
    {
      "x": -4,
      "y": 1,
      "z": 4,
      "name": "Rock_Marble_Brick",
      "rotation": 1
    },
    {
      "x": -4,
      "y": 7,
      "z": 4,
      "name": "Rock_Marble_Brick",
      "rotation": 1
    },
    {
      "x": -4,
      "y": 8,
      "z": 4,
      "name": "Rock_Marble_Brick_Roof_Shallow",
      "rotation": 3
    },
    {
      "x": -4,
      "y": 0,
      "z": 5,
      "name": "Rock_Marble_Brick"
    },
    {
      "x": -4,
      "y": 1,
      "z": 5,
      "name": "Rock_Marble_Brick",
      "rotation": 1
    },
    {
      "x": -4,
      "y": 7,
      "z": 5,
      "name": "Rock_Marble_Brick",
      "rotation": 1
    },
    {
      "x": -4,
      "y": 8,
      "z": 5,
      "name": "Rock_Marble_Brick_Roof_Shallow",
      "rotation": 3
    },
    {
      "x": -3,
      "y": 0,
      "z": -5,
      "name": "Rock_Marble_Brick"
    },
    {
      "x": -3,
      "y": 1,
      "z": -5,
      "name": "Rock_Marble_Brick"
    },
    {
      "x": -3,
      "y": 7,
      "z": -5,
      "name": "Rock_Marble_Brick",
      "rotation": 1
    },
    {
      "x": -3,
      "y": 8,
      "z": -5,
      "name": "Rock_Marble_Brick_Roof_Shallow",
      "filler": 1,
      "rotation": 3
    },
    {
      "x": -3,
      "y": 0,
      "z": -4,
      "name": "Rock_Marble_Brick"
    },
    {
      "x": -3,
      "y": 1,
      "z": -4,
      "name": "Rock_Marble_Brick"
    },
    {
      "x": -3,
      "y": 2,
      "z": -4,
      "name": "Rock_Marble_Brick_Pillar_Base",
      "rotation": 1
    },
    {
      "x": -3,
      "y": 3,
      "z": -4,
      "name": "Rock_Marble_Brick_Pillar_Middle",
      "rotation": 1
    },
    {
      "x": -3,
      "y": 4,
      "z": -4,
      "name": "Rock_Marble_Brick_Pillar_Middle",
      "rotation": 1
    },
    {
      "x": -3,
      "y": 5,
      "z": -4,
      "name": "Rock_Marble_Brick_Pillar_Middle",
      "rotation": 1
    },
    {
      "x": -3,
      "y": 6,
      "z": -4,
      "name": "Rock_Marble_Brick_Pillar_Base",
      "rotation": 9
    },
    {
      "x": -3,
      "y": 7,
      "z": -4,
      "name": "Rock_Marble_Brick",
      "rotation": 1
    },
    {
      "x": -3,
      "y": 8,
      "z": -4,
      "name": "Rock_Marble_Brick_Roof_Shallow",
      "filler": 1,
      "rotation": 3
    },
    {
      "x": -3,
      "y": 0,
      "z": -3,
      "name": "Rock_Marble_Brick"
    },
    {
      "x": -3,
      "y": 1,
      "z": -3,
      "name": "Rock_Marble_Brick"
    },
    {
      "x": -3,
      "y": 7,
      "z": -3,
      "name": "Rock_Marble_Brick",
      "rotation": 1
    },
    {
      "x": -3,
      "y": 8,
      "z": -3,
      "name": "Rock_Marble_Brick_Roof_Shallow",
      "filler": 1,
      "rotation": 3
    },
    {
      "x": -3,
      "y": 0,
      "z": -2,
      "name": "Rock_Marble_Brick"
    },
    {
      "x": -3,
      "y": 1,
      "z": -2,
      "name": "Rock_Marble_Brick"
    },
    {
      "x": -3,
      "y": 2,
      "z": -2,
      "name": "Rock_Marble_Brick_Pillar_Base",
      "rotation": 1
    },
    {
      "x": -3,
      "y": 3,
      "z": -2,
      "name": "Rock_Marble_Brick_Pillar_Middle",
      "rotation": 1
    },
    {
      "x": -3,
      "y": 4,
      "z": -2,
      "name": "Rock_Marble_Brick_Pillar_Middle",
      "rotation": 1
    },
    {
      "x": -3,
      "y": 5,
      "z": -2,
      "name": "Rock_Marble_Brick_Pillar_Middle",
      "rotation": 1
    },
    {
      "x": -3,
      "y": 6,
      "z": -2,
      "name": "Rock_Marble_Brick_Pillar_Base",
      "rotation": 9
    },
    {
      "x": -3,
      "y": 7,
      "z": -2,
      "name": "Rock_Marble_Brick",
      "rotation": 1
    },
    {
      "x": -3,
      "y": 8,
      "z": -2,
      "name": "Rock_Marble_Brick_Roof_Shallow",
      "filler": 1,
      "rotation": 3
    },
    {
      "x": -3,
      "y": 0,
      "z": -1,
      "name": "Rock_Marble_Brick"
    },
    {
      "x": -3,
      "y": 1,
      "z": -1,
      "name": "Rock_Marble_Brick"
    },
    {
      "x": -3,
      "y": 7,
      "z": -1,
      "name": "Rock_Marble_Brick",
      "rotation": 1
    },
    {
      "x": -3,
      "y": 8,
      "z": -1,
      "name": "Rock_Marble_Brick_Roof_Shallow",
      "filler": 1,
      "rotation": 3
    },
    {
      "x": -3,
      "y": 0,
      "z": 0,
      "name": "Rock_Marble_Brick"
    },
    {
      "x": -3,
      "y": 1,
      "z": 0,
      "name": "Rock_Marble_Brick"
    },
    {
      "x": -3,
      "y": 2,
      "z": 0,
      "name": "Rock_Marble_Brick_Pillar_Base",
      "rotation": 1
    },
    {
      "x": -3,
      "y": 3,
      "z": 0,
      "name": "Rock_Marble_Brick_Pillar_Middle",
      "rotation": 1
    },
    {
      "x": -3,
      "y": 4,
      "z": 0,
      "name": "Rock_Marble_Brick_Pillar_Middle",
      "rotation": 1
    },
    {
      "x": -3,
      "y": 5,
      "z": 0,
      "name": "Rock_Marble_Brick_Pillar_Middle",
      "rotation": 1
    },
    {
      "x": -3,
      "y": 6,
      "z": 0,
      "name": "Rock_Marble_Brick_Pillar_Base",
      "rotation": 9
    },
    {
      "x": -3,
      "y": 7,
      "z": 0,
      "name": "Rock_Marble_Brick",
      "rotation": 1
    },
    {
      "x": -3,
      "y": 8,
      "z": 0,
      "name": "Rock_Marble_Brick_Roof_Shallow",
      "filler": 1,
      "rotation": 3
    },
    {
      "x": -3,
      "y": 0,
      "z": 1,
      "name": "Rock_Marble_Brick"
    },
    {
      "x": -3,
      "y": 1,
      "z": 1,
      "name": "Rock_Marble_Brick"
    },
    {
      "x": -3,
      "y": 7,
      "z": 1,
      "name": "Rock_Marble_Brick",
      "rotation": 1
    },
    {
      "x": -3,
      "y": 8,
      "z": 1,
      "name": "Rock_Marble_Brick_Roof_Shallow",
      "filler": 1,
      "rotation": 3
    },
    {
      "x": -3,
      "y": 0,
      "z": 2,
      "name": "Rock_Marble_Brick"
    },
    {
      "x": -3,
      "y": 1,
      "z": 2,
      "name": "Rock_Marble_Brick"
    },
    {
      "x": -3,
      "y": 2,
      "z": 2,
      "name": "Rock_Marble_Brick_Pillar_Base",
      "rotation": 1
    },
    {
      "x": -3,
      "y": 3,
      "z": 2,
      "name": "Rock_Marble_Brick_Pillar_Middle",
      "rotation": 1
    },
    {
      "x": -3,
      "y": 4,
      "z": 2,
      "name": "Rock_Marble_Brick_Pillar_Middle",
      "rotation": 1
    },
    {
      "x": -3,
      "y": 5,
      "z": 2,
      "name": "Rock_Marble_Brick_Pillar_Middle",
      "rotation": 1
    },
    {
      "x": -3,
      "y": 6,
      "z": 2,
      "name": "Rock_Marble_Brick_Pillar_Base",
      "rotation": 9
    },
    {
      "x": -3,
      "y": 7,
      "z": 2,
      "name": "Rock_Marble_Brick",
      "rotation": 1
    },
    {
      "x": -3,
      "y": 8,
      "z": 2,
      "name": "Rock_Marble_Brick_Roof_Shallow",
      "filler": 1,
      "rotation": 3
    },
    {
      "x": -3,
      "y": 0,
      "z": 3,
      "name": "Rock_Marble_Brick"
    },
    {
      "x": -3,
      "y": 1,
      "z": 3,
      "name": "Rock_Marble_Brick"
    },
    {
      "x": -3,
      "y": 7,
      "z": 3,
      "name": "Rock_Marble_Brick",
      "rotation": 1
    },
    {
      "x": -3,
      "y": 8,
      "z": 3,
      "name": "Rock_Marble_Brick_Roof_Shallow",
      "filler": 1,
      "rotation": 3
    },
    {
      "x": -3,
      "y": 0,
      "z": 4,
      "name": "Rock_Marble_Brick"
    },
    {
      "x": -3,
      "y": 1,
      "z": 4,
      "name": "Rock_Marble_Brick",
      "rotation": 1
    },
    {
      "x": -3,
      "y": 2,
      "z": 4,
      "name": "Rock_Marble_Brick_Pillar_Base",
      "rotation": 1
    },
    {
      "x": -3,
      "y": 3,
      "z": 4,
      "name": "Rock_Marble_Brick_Pillar_Middle",
      "rotation": 1
    },
    {
      "x": -3,
      "y": 4,
      "z": 4,
      "name": "Rock_Marble_Brick_Pillar_Middle",
      "rotation": 1
    },
    {
      "x": -3,
      "y": 5,
      "z": 4,
      "name": "Rock_Marble_Brick_Pillar_Middle",
      "rotation": 1
    },
    {
      "x": -3,
      "y": 6,
      "z": 4,
      "name": "Rock_Marble_Brick_Pillar_Base",
      "rotation": 9
    },
    {
      "x": -3,
      "y": 7,
      "z": 4,
      "name": "Rock_Marble_Brick",
      "rotation": 1
    },
    {
      "x": -3,
      "y": 8,
      "z": 4,
      "name": "Rock_Marble_Brick_Roof_Shallow",
      "filler": 1,
      "rotation": 3
    },
    {
      "x": -3,
      "y": 0,
      "z": 5,
      "name": "Rock_Marble_Brick"
    },
    {
      "x": -3,
      "y": 1,
      "z": 5,
      "name": "Rock_Marble_Brick",
      "rotation": 1
    },
    {
      "x": -3,
      "y": 7,
      "z": 5,
      "name": "Rock_Marble_Brick",
      "rotation": 1
    },
    {
      "x": -3,
      "y": 8,
      "z": 5,
      "name": "Rock_Marble_Brick_Roof_Shallow",
      "filler": 1,
      "rotation": 3
    },
    {
      "x": -2,
      "y": 0,
      "z": -5,
      "name": "Rock_Marble_Brick"
    },
    {
      "x": -2,
      "y": 1,
      "z": -5,
      "name": "Rock_Marble_Brick"
    },
    {
      "x": -2,
      "y": 7,
      "z": -5,
      "name": "Rock_Marble_Brick",
      "rotation": 1
    },
    {
      "x": -2,
      "y": 8,
      "z": -5,
      "name": "Rock_Marble_Brick_Smooth_Half",
      "rotation": 9
    },
    {
      "x": -2,
      "y": 9,
      "z": -5,
      "name": "Rock_Marble_Brick_Roof_Shallow",
      "rotation": 3
    },
    {
      "x": -2,
      "y": 0,
      "z": -4,
      "name": "Rock_Marble_Brick"
    },
    {
      "x": -2,
      "y": 1,
      "z": -4,
      "name": "Rock_Marble_Brick"
    },
    {
      "x": -2,
      "y": 7,
      "z": -4,
      "name": "Rock_Marble_Brick",
      "rotation": 1
    },
    {
      "x": -2,
      "y": 8,
      "z": -4,
      "name": "Rock_Marble_Brick",
      "rotation": 1
    },
    {
      "x": -2,
      "y": 9,
      "z": -4,
      "name": "Rock_Marble_Brick_Roof_Shallow",
      "rotation": 3
    },
    {
      "x": -2,
      "y": 0,
      "z": -3,
      "name": "Rock_Marble_Brick"
    },
    {
      "x": -2,
      "y": 1,
      "z": -3,
      "name": "Rock_Marble_Brick"
    },
    {
      "x": -2,
      "y": 7,
      "z": -3,
      "name": "Rock_Marble_Brick",
      "rotation": 1
    },
    {
      "x": -2,
      "y": 8,
      "z": -3,
      "name": "Rock_Marble_Brick",
      "rotation": 1
    },
    {
      "x": -2,
      "y": 9,
      "z": -3,
      "name": "Rock_Marble_Brick_Roof_Shallow",
      "rotation": 3
    },
    {
      "x": -2,
      "y": 0,
      "z": -2,
      "name": "Rock_Marble_Brick"
    },
    {
      "x": -2,
      "y": 1,
      "z": -2,
      "name": "Rock_Marble_Brick"
    },
    {
      "x": -2,
      "y": 7,
      "z": -2,
      "name": "Rock_Marble_Brick",
      "rotation": 1
    },
    {
      "x": -2,
      "y": 8,
      "z": -2,
      "name": "Rock_Marble_Brick",
      "rotation": 1
    },
    {
      "x": -2,
      "y": 9,
      "z": -2,
      "name": "Rock_Marble_Brick_Roof_Shallow",
      "rotation": 3
    },
    {
      "x": -2,
      "y": 0,
      "z": -1,
      "name": "Rock_Marble_Brick"
    },
    {
      "x": -2,
      "y": 1,
      "z": -1,
      "name": "Rock_Marble_Brick"
    },
    {
      "x": -2,
      "y": 7,
      "z": -1,
      "name": "Rock_Marble_Brick",
      "rotation": 1
    },
    {
      "x": -2,
      "y": 8,
      "z": -1,
      "name": "Rock_Marble_Brick",
      "rotation": 1
    },
    {
      "x": -2,
      "y": 9,
      "z": -1,
      "name": "Rock_Marble_Brick_Roof_Shallow",
      "rotation": 3
    },
    {
      "x": -2,
      "y": 0,
      "z": 0,
      "name": "Rock_Marble_Brick"
    },
    {
      "x": -2,
      "y": 1,
      "z": 0,
      "name": "Rock_Marble_Brick"
    },
    {
      "x": -2,
      "y": 7,
      "z": 0,
      "name": "Rock_Marble_Brick",
      "rotation": 1
    },
    {
      "x": -2,
      "y": 8,
      "z": 0,
      "name": "Rock_Marble_Brick",
      "rotation": 1
    },
    {
      "x": -2,
      "y": 9,
      "z": 0,
      "name": "Rock_Marble_Brick_Roof_Shallow",
      "rotation": 3
    },
    {
      "x": -2,
      "y": 0,
      "z": 1,
      "name": "Rock_Marble_Brick"
    },
    {
      "x": -2,
      "y": 1,
      "z": 1,
      "name": "Rock_Marble_Brick"
    },
    {
      "x": -2,
      "y": 7,
      "z": 1,
      "name": "Rock_Marble_Brick",
      "rotation": 1
    },
    {
      "x": -2,
      "y": 8,
      "z": 1,
      "name": "Rock_Marble_Brick",
      "rotation": 1
    },
    {
      "x": -2,
      "y": 9,
      "z": 1,
      "name": "Rock_Marble_Brick_Roof_Shallow",
      "rotation": 3
    },
    {
      "x": -2,
      "y": 0,
      "z": 2,
      "name": "Rock_Marble_Brick"
    },
    {
      "x": -2,
      "y": 1,
      "z": 2,
      "name": "Rock_Marble_Brick"
    },
    {
      "x": -2,
      "y": 7,
      "z": 2,
      "name": "Rock_Marble_Brick",
      "rotation": 1
    },
    {
      "x": -2,
      "y": 8,
      "z": 2,
      "name": "Rock_Marble_Brick",
      "rotation": 1
    },
    {
      "x": -2,
      "y": 9,
      "z": 2,
      "name": "Rock_Marble_Brick_Roof_Shallow",
      "rotation": 3
    },
    {
      "x": -2,
      "y": 0,
      "z": 3,
      "name": "Rock_Marble_Brick"
    },
    {
      "x": -2,
      "y": 1,
      "z": 3,
      "name": "Rock_Marble_Brick"
    },
    {
      "x": -2,
      "y": 7,
      "z": 3,
      "name": "Rock_Marble_Brick",
      "rotation": 1
    },
    {
      "x": -2,
      "y": 8,
      "z": 3,
      "name": "Rock_Marble_Brick",
      "rotation": 1
    },
    {
      "x": -2,
      "y": 9,
      "z": 3,
      "name": "Rock_Marble_Brick_Roof_Shallow",
      "rotation": 3
    },
    {
      "x": -2,
      "y": 0,
      "z": 4,
      "name": "Rock_Marble_Brick"
    },
    {
      "x": -2,
      "y": 1,
      "z": 4,
      "name": "Rock_Marble_Brick",
      "rotation": 1
    },
    {
      "x": -2,
      "y": 7,
      "z": 4,
      "name": "Rock_Marble_Brick",
      "rotation": 1
    },
    {
      "x": -2,
      "y": 8,
      "z": 4,
      "name": "Rock_Marble_Brick",
      "rotation": 1
    },
    {
      "x": -2,
      "y": 9,
      "z": 4,
      "name": "Rock_Marble_Brick_Roof_Shallow",
      "rotation": 3
    },
    {
      "x": -2,
      "y": 0,
      "z": 5,
      "name": "Rock_Marble_Brick"
    },
    {
      "x": -2,
      "y": 1,
      "z": 5,
      "name": "Rock_Marble_Brick",
      "rotation": 1
    },
    {
      "x": -2,
      "y": 7,
      "z": 5,
      "name": "Rock_Marble_Brick",
      "rotation": 1
    },
    {
      "x": -2,
      "y": 8,
      "z": 5,
      "name": "Rock_Marble_Brick_Smooth_Half",
      "rotation": 9
    },
    {
      "x": -2,
      "y": 9,
      "z": 5,
      "name": "Rock_Marble_Brick_Roof_Shallow",
      "rotation": 3
    },
    {
      "x": -1,
      "y": 0,
      "z": -5,
      "name": "Rock_Marble_Brick"
    },
    {
      "x": -1,
      "y": 1,
      "z": -5,
      "name": "Rock_Marble_Brick"
    },
    {
      "x": -1,
      "y": 7,
      "z": -5,
      "name": "Rock_Marble_Brick",
      "rotation": 1
    },
    {
      "x": -1,
      "y": 9,
      "z": -5,
      "name": "Rock_Marble_Brick_Roof_Shallow",
      "filler": 1,
      "rotation": 3
    },
    {
      "x": -1,
      "y": 0,
      "z": -4,
      "name": "Rock_Marble_Brick"
    },
    {
      "x": -1,
      "y": 1,
      "z": -4,
      "name": "Rock_Marble_Brick"
    },
    {
      "x": -1,
      "y": 2,
      "z": -4,
      "name": "Rock_Marble_Brick_Pillar_Base",
      "rotation": 1
    },
    {
      "x": -1,
      "y": 3,
      "z": -4,
      "name": "Rock_Marble_Brick_Pillar_Middle",
      "rotation": 1
    },
    {
      "x": -1,
      "y": 4,
      "z": -4,
      "name": "Rock_Marble_Brick_Pillar_Middle",
      "rotation": 1
    },
    {
      "x": -1,
      "y": 5,
      "z": -4,
      "name": "Rock_Marble_Brick_Pillar_Middle",
      "rotation": 1
    },
    {
      "x": -1,
      "y": 6,
      "z": -4,
      "name": "Rock_Marble_Brick_Pillar_Base",
      "rotation": 9
    },
    {
      "x": -1,
      "y": 7,
      "z": -4,
      "name": "Rock_Marble_Brick",
      "rotation": 1
    },
    {
      "x": -1,
      "y": 8,
      "z": -4,
      "name": "Rock_Marble_Brick",
      "rotation": 1
    },
    {
      "x": -1,
      "y": 9,
      "z": -4,
      "name": "Rock_Marble_Brick_Roof_Shallow",
      "filler": 1,
      "rotation": 3
    },
    {
      "x": -1,
      "y": 0,
      "z": -3,
      "name": "Rock_Marble_Brick"
    },
    {
      "x": -1,
      "y": 1,
      "z": -3,
      "name": "Rock_Marble_Brick"
    },
    {
      "x": -1,
      "y": 7,
      "z": -3,
      "name": "Rock_Marble_Brick",
      "rotation": 1
    },
    {
      "x": -1,
      "y": 8,
      "z": -3,
      "name": "Rock_Marble_Brick",
      "rotation": 1
    },
    {
      "x": -1,
      "y": 9,
      "z": -3,
      "name": "Rock_Marble_Brick_Roof_Shallow",
      "filler": 1,
      "rotation": 3
    },
    {
      "x": -1,
      "y": 0,
      "z": -2,
      "name": "Rock_Marble_Brick"
    },
    {
      "x": -1,
      "y": 1,
      "z": -2,
      "name": "Rock_Marble_Brick"
    },
    {
      "x": -1,
      "y": 7,
      "z": -2,
      "name": "Rock_Marble_Brick",
      "rotation": 1
    },
    {
      "x": -1,
      "y": 8,
      "z": -2,
      "name": "Rock_Marble_Brick",
      "rotation": 1
    },
    {
      "x": -1,
      "y": 9,
      "z": -2,
      "name": "Rock_Marble_Brick_Roof_Shallow",
      "filler": 1,
      "rotation": 3
    },
    {
      "x": -1,
      "y": 0,
      "z": -1,
      "name": "Rock_Marble_Brick"
    },
    {
      "x": -1,
      "y": 1,
      "z": -1,
      "name": "Rock_Marble_Brick"
    },
    {
      "x": -1,
      "y": 7,
      "z": -1,
      "name": "Rock_Marble_Brick",
      "rotation": 1
    },
    {
      "x": -1,
      "y": 8,
      "z": -1,
      "name": "Rock_Marble_Brick",
      "rotation": 1
    },
    {
      "x": -1,
      "y": 9,
      "z": -1,
      "name": "Rock_Marble_Brick_Roof_Shallow",
      "filler": 1,
      "rotation": 3
    },
    {
      "x": -1,
      "y": 0,
      "z": 0,
      "name": "Rock_Marble_Brick"
    },
    {
      "x": -1,
      "y": 1,
      "z": 0,
      "name": "Rock_Marble_Brick"
    },
    {
      "x": -1,
      "y": 7,
      "z": 0,
      "name": "Rock_Marble_Brick",
      "rotation": 1
    },
    {
      "x": -1,
      "y": 8,
      "z": 0,
      "name": "Rock_Marble_Brick",
      "rotation": 1
    },
    {
      "x": -1,
      "y": 9,
      "z": 0,
      "name": "Rock_Marble_Brick_Roof_Shallow",
      "filler": 1,
      "rotation": 3
    },
    {
      "x": -1,
      "y": 0,
      "z": 1,
      "name": "Rock_Marble_Brick"
    },
    {
      "x": -1,
      "y": 1,
      "z": 1,
      "name": "Rock_Marble_Brick"
    },
    {
      "x": -1,
      "y": 7,
      "z": 1,
      "name": "Rock_Marble_Brick",
      "rotation": 1
    },
    {
      "x": -1,
      "y": 8,
      "z": 1,
      "name": "Rock_Marble_Brick",
      "rotation": 1
    },
    {
      "x": -1,
      "y": 9,
      "z": 1,
      "name": "Rock_Marble_Brick_Roof_Shallow",
      "filler": 1,
      "rotation": 3
    },
    {
      "x": -1,
      "y": 0,
      "z": 2,
      "name": "Rock_Marble_Brick"
    },
    {
      "x": -1,
      "y": 1,
      "z": 2,
      "name": "Rock_Marble_Brick"
    },
    {
      "x": -1,
      "y": 7,
      "z": 2,
      "name": "Rock_Marble_Brick",
      "rotation": 1
    },
    {
      "x": -1,
      "y": 8,
      "z": 2,
      "name": "Rock_Marble_Brick",
      "rotation": 1
    },
    {
      "x": -1,
      "y": 9,
      "z": 2,
      "name": "Rock_Marble_Brick_Roof_Shallow",
      "filler": 1,
      "rotation": 3
    },
    {
      "x": -1,
      "y": 0,
      "z": 3,
      "name": "Rock_Marble_Brick"
    },
    {
      "x": -1,
      "y": 1,
      "z": 3,
      "name": "Rock_Marble_Brick"
    },
    {
      "x": -1,
      "y": 7,
      "z": 3,
      "name": "Rock_Marble_Brick",
      "rotation": 1
    },
    {
      "x": -1,
      "y": 8,
      "z": 3,
      "name": "Rock_Marble_Brick",
      "rotation": 1
    },
    {
      "x": -1,
      "y": 9,
      "z": 3,
      "name": "Rock_Marble_Brick_Roof_Shallow",
      "filler": 1,
      "rotation": 3
    },
    {
      "x": -1,
      "y": 0,
      "z": 4,
      "name": "Rock_Marble_Brick"
    },
    {
      "x": -1,
      "y": 1,
      "z": 4,
      "name": "Rock_Marble_Brick",
      "rotation": 1
    },
    {
      "x": -1,
      "y": 2,
      "z": 4,
      "name": "Rock_Marble_Brick_Pillar_Base",
      "rotation": 1
    },
    {
      "x": -1,
      "y": 3,
      "z": 4,
      "name": "Rock_Marble_Brick_Pillar_Middle",
      "rotation": 1
    },
    {
      "x": -1,
      "y": 4,
      "z": 4,
      "name": "Rock_Marble_Brick_Pillar_Middle",
      "rotation": 1
    },
    {
      "x": -1,
      "y": 5,
      "z": 4,
      "name": "Rock_Marble_Brick_Pillar_Middle",
      "rotation": 1
    },
    {
      "x": -1,
      "y": 6,
      "z": 4,
      "name": "Rock_Marble_Brick_Pillar_Base",
      "rotation": 9
    },
    {
      "x": -1,
      "y": 7,
      "z": 4,
      "name": "Rock_Marble_Brick",
      "rotation": 1
    },
    {
      "x": -1,
      "y": 8,
      "z": 4,
      "name": "Rock_Marble_Brick",
      "rotation": 1
    },
    {
      "x": -1,
      "y": 9,
      "z": 4,
      "name": "Rock_Marble_Brick_Roof_Shallow",
      "filler": 1,
      "rotation": 3
    },
    {
      "x": -1,
      "y": 0,
      "z": 5,
      "name": "Rock_Marble_Brick"
    },
    {
      "x": -1,
      "y": 1,
      "z": 5,
      "name": "Rock_Marble_Brick",
      "rotation": 1
    },
    {
      "x": -1,
      "y": 7,
      "z": 5,
      "name": "Rock_Marble_Brick",
      "rotation": 1
    },
    {
      "x": -1,
      "y": 9,
      "z": 5,
      "name": "Rock_Marble_Brick_Roof_Shallow",
      "filler": 1,
      "rotation": 3
    },
    {
      "x": 0,
      "y": 0,
      "z": -5,
      "name": "Rock_Marble_Brick"
    },
    {
      "x": 0,
      "y": 1,
      "z": -5,
      "name": "Rock_Marble_Brick"
    },
    {
      "x": 0,
      "y": 7,
      "z": -5,
      "name": "Rock_Marble_Brick",
      "rotation": 1
    },
    {
      "x": 0,
      "y": 9,
      "z": -5,
      "name": "Rock_Marble_Brick_Smooth_Half",
      "rotation": 9
    },
    {
      "x": 0,
      "y": 10,
      "z": -5,
      "name": "Rock_Marble_Brick_Roof_Flat",
      "rotation": 1
    },
    {
      "x": 0,
      "y": 0,
      "z": -4,
      "name": "Rock_Marble_Brick"
    },
    {
      "x": 0,
      "y": 1,
      "z": -4,
      "name": "Rock_Marble_Brick"
    },
    {
      "x": 0,
      "y": 7,
      "z": -4,
      "name": "Rock_Marble_Brick",
      "rotation": 1
    },
    {
      "x": 0,
      "y": 8,
      "z": -4,
      "name": "Rock_Marble_Brick",
      "rotation": 1
    },
    {
      "x": 0,
      "y": 9,
      "z": -4,
      "name": "Rock_Marble_Brick",
      "rotation": 1
    },
    {
      "x": 0,
      "y": 10,
      "z": -4,
      "name": "Rock_Marble_Brick_Roof_Flat",
      "rotation": 1
    },
    {
      "x": 0,
      "y": 0,
      "z": -3,
      "name": "Rock_Marble_Brick"
    },
    {
      "x": 0,
      "y": 1,
      "z": -3,
      "name": "Rock_Marble_Brick"
    },
    {
      "x": 0,
      "y": 7,
      "z": -3,
      "name": "Rock_Marble_Brick",
      "rotation": 1
    },
    {
      "x": 0,
      "y": 8,
      "z": -3,
      "name": "Rock_Marble_Brick",
      "rotation": 1
    },
    {
      "x": 0,
      "y": 9,
      "z": -3,
      "name": "Rock_Marble_Brick",
      "rotation": 1
    },
    {
      "x": 0,
      "y": 10,
      "z": -3,
      "name": "Rock_Marble_Brick_Roof_Flat",
      "rotation": 1
    },
    {
      "x": 0,
      "y": 0,
      "z": -2,
      "name": "Rock_Marble_Brick"
    },
    {
      "x": 0,
      "y": 1,
      "z": -2,
      "name": "Rock_Marble_Brick"
    },
    {
      "x": 0,
      "y": 7,
      "z": -2,
      "name": "Rock_Marble_Brick",
      "rotation": 1
    },
    {
      "x": 0,
      "y": 8,
      "z": -2,
      "name": "Rock_Marble_Brick",
      "rotation": 1
    },
    {
      "x": 0,
      "y": 9,
      "z": -2,
      "name": "Rock_Marble_Brick",
      "rotation": 1
    },
    {
      "x": 0,
      "y": 10,
      "z": -2,
      "name": "Rock_Marble_Brick_Roof_Flat",
      "rotation": 1
    },
    {
      "x": 0,
      "y": 0,
      "z": -1,
      "name": "Rock_Marble_Brick"
    },
    {
      "x": 0,
      "y": 1,
      "z": -1,
      "name": "Rock_Marble_Brick"
    },
    {
      "x": 0,
      "y": 7,
      "z": -1,
      "name": "Rock_Marble_Brick",
      "rotation": 1
    },
    {
      "x": 0,
      "y": 8,
      "z": -1,
      "name": "Rock_Marble_Brick",
      "rotation": 1
    },
    {
      "x": 0,
      "y": 9,
      "z": -1,
      "name": "Rock_Marble_Brick",
      "rotation": 1
    },
    {
      "x": 0,
      "y": 10,
      "z": -1,
      "name": "Rock_Marble_Brick_Roof_Flat",
      "rotation": 1
    },
    {
      "x": 0,
      "y": 0,
      "z": 0,
      "name": "Rock_Marble_Brick"
    },
    {
      "x": 0,
      "y": 1,
      "z": 0,
      "name": "Rock_Marble_Brick"
    },
    {
      "x": 0,
      "y": 7,
      "z": 0,
      "name": "Rock_Marble_Brick",
      "rotation": 1
    },
    {
      "x": 0,
      "y": 8,
      "z": 0,
      "name": "Rock_Marble_Brick",
      "rotation": 1
    },
    {
      "x": 0,
      "y": 9,
      "z": 0,
      "name": "Rock_Marble_Brick",
      "rotation": 1
    },
    {
      "x": 0,
      "y": 10,
      "z": 0,
      "name": "Rock_Marble_Brick_Roof_Flat",
      "rotation": 1
    },
    {
      "x": 0,
      "y": 0,
      "z": 1,
      "name": "Rock_Marble_Brick"
    },
    {
      "x": 0,
      "y": 1,
      "z": 1,
      "name": "Rock_Marble_Brick"
    },
    {
      "x": 0,
      "y": 7,
      "z": 1,
      "name": "Rock_Marble_Brick",
      "rotation": 1
    },
    {
      "x": 0,
      "y": 8,
      "z": 1,
      "name": "Rock_Marble_Brick",
      "rotation": 1
    },
    {
      "x": 0,
      "y": 9,
      "z": 1,
      "name": "Rock_Marble_Brick",
      "rotation": 1
    },
    {
      "x": 0,
      "y": 10,
      "z": 1,
      "name": "Rock_Marble_Brick_Roof_Flat",
      "rotation": 1
    },
    {
      "x": 0,
      "y": 0,
      "z": 2,
      "name": "Rock_Marble_Brick"
    },
    {
      "x": 0,
      "y": 1,
      "z": 2,
      "name": "Rock_Marble_Brick"
    },
    {
      "x": 0,
      "y": 7,
      "z": 2,
      "name": "Rock_Marble_Brick",
      "rotation": 1
    },
    {
      "x": 0,
      "y": 8,
      "z": 2,
      "name": "Rock_Marble_Brick",
      "rotation": 1
    },
    {
      "x": 0,
      "y": 9,
      "z": 2,
      "name": "Rock_Marble_Brick",
      "rotation": 1
    },
    {
      "x": 0,
      "y": 10,
      "z": 2,
      "name": "Rock_Marble_Brick_Roof_Flat",
      "rotation": 1
    },
    {
      "x": 0,
      "y": 0,
      "z": 3,
      "name": "Rock_Marble_Brick"
    },
    {
      "x": 0,
      "y": 1,
      "z": 3,
      "name": "Rock_Marble_Brick"
    },
    {
      "x": 0,
      "y": 7,
      "z": 3,
      "name": "Rock_Marble_Brick",
      "rotation": 1
    },
    {
      "x": 0,
      "y": 8,
      "z": 3,
      "name": "Rock_Marble_Brick",
      "rotation": 1
    },
    {
      "x": 0,
      "y": 9,
      "z": 3,
      "name": "Rock_Marble_Brick",
      "rotation": 1
    },
    {
      "x": 0,
      "y": 10,
      "z": 3,
      "name": "Rock_Marble_Brick_Roof_Flat",
      "rotation": 1
    },
    {
      "x": 0,
      "y": 0,
      "z": 4,
      "name": "Rock_Marble_Brick"
    },
    {
      "x": 0,
      "y": 1,
      "z": 4,
      "name": "Rock_Marble_Brick",
      "rotation": 1
    },
    {
      "x": 0,
      "y": 7,
      "z": 4,
      "name": "Rock_Marble_Brick",
      "rotation": 1
    },
    {
      "x": 0,
      "y": 8,
      "z": 4,
      "name": "Rock_Marble_Brick",
      "rotation": 1
    },
    {
      "x": 0,
      "y": 9,
      "z": 4,
      "name": "Rock_Marble_Brick",
      "rotation": 1
    },
    {
      "x": 0,
      "y": 10,
      "z": 4,
      "name": "Rock_Marble_Brick_Roof_Flat",
      "rotation": 1
    },
    {
      "x": 0,
      "y": 0,
      "z": 5,
      "name": "Rock_Marble_Brick"
    },
    {
      "x": 0,
      "y": 1,
      "z": 5,
      "name": "Rock_Marble_Brick",
      "rotation": 1
    },
    {
      "x": 0,
      "y": 7,
      "z": 5,
      "name": "Rock_Marble_Brick",
      "rotation": 1
    },
    {
      "x": 0,
      "y": 9,
      "z": 5,
      "name": "Rock_Marble_Brick_Smooth_Half",
      "rotation": 9
    },
    {
      "x": 0,
      "y": 10,
      "z": 5,
      "name": "Rock_Marble_Brick_Roof_Flat",
      "rotation": 1
    },
    {
      "x": 1,
      "y": 0,
      "z": -5,
      "name": "Rock_Marble_Brick"
    },
    {
      "x": 1,
      "y": 1,
      "z": -5,
      "name": "Rock_Marble_Brick"
    },
    {
      "x": 1,
      "y": 7,
      "z": -5,
      "name": "Rock_Marble_Brick",
      "rotation": 1
    },
    {
      "x": 1,
      "y": 9,
      "z": -5,
      "name": "Rock_Marble_Brick_Roof_Shallow",
      "filler": 31,
      "rotation": 1
    },
    {
      "x": 1,
      "y": 0,
      "z": -4,
      "name": "Rock_Marble_Brick"
    },
    {
      "x": 1,
      "y": 1,
      "z": -4,
      "name": "Rock_Marble_Brick"
    },
    {
      "x": 1,
      "y": 2,
      "z": -4,
      "name": "Rock_Marble_Brick_Pillar_Base",
      "rotation": 1
    },
    {
      "x": 1,
      "y": 3,
      "z": -4,
      "name": "Rock_Marble_Brick_Pillar_Middle",
      "rotation": 1
    },
    {
      "x": 1,
      "y": 4,
      "z": -4,
      "name": "Rock_Marble_Brick_Pillar_Middle",
      "rotation": 1
    },
    {
      "x": 1,
      "y": 5,
      "z": -4,
      "name": "Rock_Marble_Brick_Pillar_Middle",
      "rotation": 1
    },
    {
      "x": 1,
      "y": 6,
      "z": -4,
      "name": "Rock_Marble_Brick_Pillar_Base",
      "rotation": 9
    },
    {
      "x": 1,
      "y": 7,
      "z": -4,
      "name": "Rock_Marble_Brick",
      "rotation": 1
    },
    {
      "x": 1,
      "y": 8,
      "z": -4,
      "name": "Rock_Marble_Brick",
      "rotation": 1
    },
    {
      "x": 1,
      "y": 9,
      "z": -4,
      "name": "Rock_Marble_Brick_Roof_Shallow",
      "filler": 31,
      "rotation": 1
    },
    {
      "x": 1,
      "y": 0,
      "z": -3,
      "name": "Rock_Marble_Brick"
    },
    {
      "x": 1,
      "y": 1,
      "z": -3,
      "name": "Rock_Marble_Brick"
    },
    {
      "x": 1,
      "y": 7,
      "z": -3,
      "name": "Rock_Marble_Brick",
      "rotation": 1
    },
    {
      "x": 1,
      "y": 8,
      "z": -3,
      "name": "Rock_Marble_Brick",
      "rotation": 1
    },
    {
      "x": 1,
      "y": 9,
      "z": -3,
      "name": "Rock_Marble_Brick_Roof_Shallow",
      "filler": 31,
      "rotation": 1
    },
    {
      "x": 1,
      "y": 0,
      "z": -2,
      "name": "Rock_Marble_Brick"
    },
    {
      "x": 1,
      "y": 1,
      "z": -2,
      "name": "Rock_Marble_Brick"
    },
    {
      "x": 1,
      "y": 7,
      "z": -2,
      "name": "Rock_Marble_Brick",
      "rotation": 1
    },
    {
      "x": 1,
      "y": 8,
      "z": -2,
      "name": "Rock_Marble_Brick",
      "rotation": 1
    },
    {
      "x": 1,
      "y": 9,
      "z": -2,
      "name": "Rock_Marble_Brick_Roof_Shallow",
      "filler": 31,
      "rotation": 1
    },
    {
      "x": 1,
      "y": 0,
      "z": -1,
      "name": "Rock_Marble_Brick"
    },
    {
      "x": 1,
      "y": 1,
      "z": -1,
      "name": "Rock_Marble_Brick"
    },
    {
      "x": 1,
      "y": 7,
      "z": -1,
      "name": "Rock_Marble_Brick",
      "rotation": 1
    },
    {
      "x": 1,
      "y": 8,
      "z": -1,
      "name": "Rock_Marble_Brick",
      "rotation": 1
    },
    {
      "x": 1,
      "y": 9,
      "z": -1,
      "name": "Rock_Marble_Brick_Roof_Shallow",
      "filler": 31,
      "rotation": 1
    },
    {
      "x": 1,
      "y": 0,
      "z": 0,
      "name": "Rock_Marble_Brick"
    },
    {
      "x": 1,
      "y": 1,
      "z": 0,
      "name": "Rock_Marble_Brick"
    },
    {
      "x": 1,
      "y": 7,
      "z": 0,
      "name": "Rock_Marble_Brick",
      "rotation": 1
    },
    {
      "x": 1,
      "y": 8,
      "z": 0,
      "name": "Rock_Marble_Brick",
      "rotation": 1
    },
    {
      "x": 1,
      "y": 9,
      "z": 0,
      "name": "Rock_Marble_Brick_Roof_Shallow",
      "filler": 31,
      "rotation": 1
    },
    {
      "x": 1,
      "y": 0,
      "z": 1,
      "name": "Rock_Marble_Brick"
    },
    {
      "x": 1,
      "y": 1,
      "z": 1,
      "name": "Rock_Marble_Brick"
    },
    {
      "x": 1,
      "y": 7,
      "z": 1,
      "name": "Rock_Marble_Brick",
      "rotation": 1
    },
    {
      "x": 1,
      "y": 8,
      "z": 1,
      "name": "Rock_Marble_Brick",
      "rotation": 1
    },
    {
      "x": 1,
      "y": 9,
      "z": 1,
      "name": "Rock_Marble_Brick_Roof_Shallow",
      "filler": 31,
      "rotation": 1
    },
    {
      "x": 1,
      "y": 0,
      "z": 2,
      "name": "Rock_Marble_Brick"
    },
    {
      "x": 1,
      "y": 1,
      "z": 2,
      "name": "Rock_Marble_Brick"
    },
    {
      "x": 1,
      "y": 7,
      "z": 2,
      "name": "Rock_Marble_Brick",
      "rotation": 1
    },
    {
      "x": 1,
      "y": 8,
      "z": 2,
      "name": "Rock_Marble_Brick",
      "rotation": 1
    },
    {
      "x": 1,
      "y": 9,
      "z": 2,
      "name": "Rock_Marble_Brick_Roof_Shallow",
      "filler": 31,
      "rotation": 1
    },
    {
      "x": 1,
      "y": 0,
      "z": 3,
      "name": "Rock_Marble_Brick"
    },
    {
      "x": 1,
      "y": 1,
      "z": 3,
      "name": "Rock_Marble_Brick"
    },
    {
      "x": 1,
      "y": 7,
      "z": 3,
      "name": "Rock_Marble_Brick",
      "rotation": 1
    },
    {
      "x": 1,
      "y": 8,
      "z": 3,
      "name": "Rock_Marble_Brick",
      "rotation": 1
    },
    {
      "x": 1,
      "y": 9,
      "z": 3,
      "name": "Rock_Marble_Brick_Roof_Shallow",
      "filler": 31,
      "rotation": 1
    },
    {
      "x": 1,
      "y": 0,
      "z": 4,
      "name": "Rock_Marble_Brick"
    },
    {
      "x": 1,
      "y": 1,
      "z": 4,
      "name": "Rock_Marble_Brick",
      "rotation": 1
    },
    {
      "x": 1,
      "y": 2,
      "z": 4,
      "name": "Rock_Marble_Brick_Pillar_Base",
      "rotation": 1
    },
    {
      "x": 1,
      "y": 3,
      "z": 4,
      "name": "Rock_Marble_Brick_Pillar_Middle",
      "rotation": 1
    },
    {
      "x": 1,
      "y": 4,
      "z": 4,
      "name": "Rock_Marble_Brick_Pillar_Middle",
      "rotation": 1
    },
    {
      "x": 1,
      "y": 5,
      "z": 4,
      "name": "Rock_Marble_Brick_Pillar_Middle",
      "rotation": 1
    },
    {
      "x": 1,
      "y": 6,
      "z": 4,
      "name": "Rock_Marble_Brick_Pillar_Base",
      "rotation": 9
    },
    {
      "x": 1,
      "y": 7,
      "z": 4,
      "name": "Rock_Marble_Brick",
      "rotation": 1
    },
    {
      "x": 1,
      "y": 8,
      "z": 4,
      "name": "Rock_Marble_Brick",
      "rotation": 1
    },
    {
      "x": 1,
      "y": 9,
      "z": 4,
      "name": "Rock_Marble_Brick_Roof_Shallow",
      "filler": 31,
      "rotation": 1
    },
    {
      "x": 1,
      "y": 0,
      "z": 5,
      "name": "Rock_Marble_Brick"
    },
    {
      "x": 1,
      "y": 1,
      "z": 5,
      "name": "Rock_Marble_Brick",
      "rotation": 1
    },
    {
      "x": 1,
      "y": 7,
      "z": 5,
      "name": "Rock_Marble_Brick",
      "rotation": 1
    },
    {
      "x": 1,
      "y": 9,
      "z": 5,
      "name": "Rock_Marble_Brick_Roof_Shallow",
      "filler": 31,
      "rotation": 1
    },
    {
      "x": 2,
      "y": 0,
      "z": -5,
      "name": "Rock_Marble_Brick"
    },
    {
      "x": 2,
      "y": 1,
      "z": -5,
      "name": "Rock_Marble_Brick"
    },
    {
      "x": 2,
      "y": 7,
      "z": -5,
      "name": "Rock_Marble_Brick",
      "rotation": 1
    },
    {
      "x": 2,
      "y": 8,
      "z": -5,
      "name": "Rock_Marble_Brick_Smooth_Half",
      "rotation": 9
    },
    {
      "x": 2,
      "y": 9,
      "z": -5,
      "name": "Rock_Marble_Brick_Roof_Shallow",
      "rotation": 1
    },
    {
      "x": 2,
      "y": 0,
      "z": -4,
      "name": "Rock_Marble_Brick"
    },
    {
      "x": 2,
      "y": 1,
      "z": -4,
      "name": "Rock_Marble_Brick"
    },
    {
      "x": 2,
      "y": 7,
      "z": -4,
      "name": "Rock_Marble_Brick",
      "rotation": 1
    },
    {
      "x": 2,
      "y": 8,
      "z": -4,
      "name": "Rock_Marble_Brick",
      "rotation": 1
    },
    {
      "x": 2,
      "y": 9,
      "z": -4,
      "name": "Rock_Marble_Brick_Roof_Shallow",
      "rotation": 1
    },
    {
      "x": 2,
      "y": 0,
      "z": -3,
      "name": "Rock_Marble_Brick"
    },
    {
      "x": 2,
      "y": 1,
      "z": -3,
      "name": "Rock_Marble_Brick"
    },
    {
      "x": 2,
      "y": 7,
      "z": -3,
      "name": "Rock_Marble_Brick",
      "rotation": 1
    },
    {
      "x": 2,
      "y": 8,
      "z": -3,
      "name": "Rock_Marble_Brick",
      "rotation": 1
    },
    {
      "x": 2,
      "y": 9,
      "z": -3,
      "name": "Rock_Marble_Brick_Roof_Shallow",
      "rotation": 1
    },
    {
      "x": 2,
      "y": 0,
      "z": -2,
      "name": "Rock_Marble_Brick"
    },
    {
      "x": 2,
      "y": 1,
      "z": -2,
      "name": "Rock_Marble_Brick"
    },
    {
      "x": 2,
      "y": 7,
      "z": -2,
      "name": "Rock_Marble_Brick",
      "rotation": 1
    },
    {
      "x": 2,
      "y": 8,
      "z": -2,
      "name": "Rock_Marble_Brick",
      "rotation": 1
    },
    {
      "x": 2,
      "y": 9,
      "z": -2,
      "name": "Rock_Marble_Brick_Roof_Shallow",
      "rotation": 1
    },
    {
      "x": 2,
      "y": 0,
      "z": -1,
      "name": "Rock_Marble_Brick"
    },
    {
      "x": 2,
      "y": 1,
      "z": -1,
      "name": "Rock_Marble_Brick"
    },
    {
      "x": 2,
      "y": 7,
      "z": -1,
      "name": "Rock_Marble_Brick",
      "rotation": 1
    },
    {
      "x": 2,
      "y": 8,
      "z": -1,
      "name": "Rock_Marble_Brick",
      "rotation": 1
    },
    {
      "x": 2,
      "y": 9,
      "z": -1,
      "name": "Rock_Marble_Brick_Roof_Shallow",
      "rotation": 1
    },
    {
      "x": 2,
      "y": 0,
      "z": 0,
      "name": "Rock_Marble_Brick"
    },
    {
      "x": 2,
      "y": 1,
      "z": 0,
      "name": "Rock_Marble_Brick"
    },
    {
      "x": 2,
      "y": 7,
      "z": 0,
      "name": "Rock_Marble_Brick",
      "rotation": 1
    },
    {
      "x": 2,
      "y": 8,
      "z": 0,
      "name": "Rock_Marble_Brick",
      "rotation": 1
    },
    {
      "x": 2,
      "y": 9,
      "z": 0,
      "name": "Rock_Marble_Brick_Roof_Shallow",
      "rotation": 1
    },
    {
      "x": 2,
      "y": 0,
      "z": 1,
      "name": "Rock_Marble_Brick"
    },
    {
      "x": 2,
      "y": 1,
      "z": 1,
      "name": "Rock_Marble_Brick"
    },
    {
      "x": 2,
      "y": 7,
      "z": 1,
      "name": "Rock_Marble_Brick",
      "rotation": 1
    },
    {
      "x": 2,
      "y": 8,
      "z": 1,
      "name": "Rock_Marble_Brick",
      "rotation": 1
    },
    {
      "x": 2,
      "y": 9,
      "z": 1,
      "name": "Rock_Marble_Brick_Roof_Shallow",
      "rotation": 1
    },
    {
      "x": 2,
      "y": 0,
      "z": 2,
      "name": "Rock_Marble_Brick"
    },
    {
      "x": 2,
      "y": 1,
      "z": 2,
      "name": "Rock_Marble_Brick"
    },
    {
      "x": 2,
      "y": 7,
      "z": 2,
      "name": "Rock_Marble_Brick",
      "rotation": 1
    },
    {
      "x": 2,
      "y": 8,
      "z": 2,
      "name": "Rock_Marble_Brick",
      "rotation": 1
    },
    {
      "x": 2,
      "y": 9,
      "z": 2,
      "name": "Rock_Marble_Brick_Roof_Shallow",
      "rotation": 1
    },
    {
      "x": 2,
      "y": 0,
      "z": 3,
      "name": "Rock_Marble_Brick"
    },
    {
      "x": 2,
      "y": 1,
      "z": 3,
      "name": "Rock_Marble_Brick"
    },
    {
      "x": 2,
      "y": 7,
      "z": 3,
      "name": "Rock_Marble_Brick",
      "rotation": 1
    },
    {
      "x": 2,
      "y": 8,
      "z": 3,
      "name": "Rock_Marble_Brick",
      "rotation": 1
    },
    {
      "x": 2,
      "y": 9,
      "z": 3,
      "name": "Rock_Marble_Brick_Roof_Shallow",
      "rotation": 1
    },
    {
      "x": 2,
      "y": 0,
      "z": 4,
      "name": "Rock_Marble_Brick"
    },
    {
      "x": 2,
      "y": 1,
      "z": 4,
      "name": "Rock_Marble_Brick",
      "rotation": 1
    },
    {
      "x": 2,
      "y": 7,
      "z": 4,
      "name": "Rock_Marble_Brick",
      "rotation": 1
    },
    {
      "x": 2,
      "y": 8,
      "z": 4,
      "name": "Rock_Marble_Brick",
      "rotation": 1
    },
    {
      "x": 2,
      "y": 9,
      "z": 4,
      "name": "Rock_Marble_Brick_Roof_Shallow",
      "rotation": 1
    },
    {
      "x": 2,
      "y": 0,
      "z": 5,
      "name": "Rock_Marble_Brick"
    },
    {
      "x": 2,
      "y": 1,
      "z": 5,
      "name": "Rock_Marble_Brick",
      "rotation": 1
    },
    {
      "x": 2,
      "y": 7,
      "z": 5,
      "name": "Rock_Marble_Brick",
      "rotation": 1
    },
    {
      "x": 2,
      "y": 8,
      "z": 5,
      "name": "Rock_Marble_Brick_Smooth_Half",
      "rotation": 9
    },
    {
      "x": 2,
      "y": 9,
      "z": 5,
      "name": "Rock_Marble_Brick_Roof_Shallow",
      "rotation": 1
    },
    {
      "x": 3,
      "y": 0,
      "z": -5,
      "name": "Rock_Marble_Brick"
    },
    {
      "x": 3,
      "y": 1,
      "z": -5,
      "name": "Rock_Marble_Brick"
    },
    {
      "x": 3,
      "y": 7,
      "z": -5,
      "name": "Rock_Marble_Brick",
      "rotation": 1
    },
    {
      "x": 3,
      "y": 8,
      "z": -5,
      "name": "Rock_Marble_Brick_Roof_Shallow",
      "filler": 31,
      "rotation": 1
    },
    {
      "x": 3,
      "y": 0,
      "z": -4,
      "name": "Rock_Marble_Brick"
    },
    {
      "x": 3,
      "y": 1,
      "z": -4,
      "name": "Rock_Marble_Brick"
    },
    {
      "x": 3,
      "y": 2,
      "z": -4,
      "name": "Rock_Marble_Brick_Pillar_Base",
      "rotation": 1
    },
    {
      "x": 3,
      "y": 3,
      "z": -4,
      "name": "Rock_Marble_Brick_Pillar_Middle",
      "rotation": 1
    },
    {
      "x": 3,
      "y": 4,
      "z": -4,
      "name": "Rock_Marble_Brick_Pillar_Middle",
      "rotation": 1
    },
    {
      "x": 3,
      "y": 5,
      "z": -4,
      "name": "Rock_Marble_Brick_Pillar_Middle",
      "rotation": 1
    },
    {
      "x": 3,
      "y": 6,
      "z": -4,
      "name": "Rock_Marble_Brick_Pillar_Base",
      "rotation": 9
    },
    {
      "x": 3,
      "y": 7,
      "z": -4,
      "name": "Rock_Marble_Brick",
      "rotation": 1
    },
    {
      "x": 3,
      "y": 8,
      "z": -4,
      "name": "Rock_Marble_Brick_Roof_Shallow",
      "filler": 31,
      "rotation": 1
    },
    {
      "x": 3,
      "y": 0,
      "z": -3,
      "name": "Rock_Marble_Brick"
    },
    {
      "x": 3,
      "y": 1,
      "z": -3,
      "name": "Rock_Marble_Brick"
    },
    {
      "x": 3,
      "y": 7,
      "z": -3,
      "name": "Rock_Marble_Brick",
      "rotation": 1
    },
    {
      "x": 3,
      "y": 8,
      "z": -3,
      "name": "Rock_Marble_Brick_Roof_Shallow",
      "filler": 31,
      "rotation": 1
    },
    {
      "x": 3,
      "y": 0,
      "z": -2,
      "name": "Rock_Marble_Brick"
    },
    {
      "x": 3,
      "y": 1,
      "z": -2,
      "name": "Rock_Marble_Brick"
    },
    {
      "x": 3,
      "y": 2,
      "z": -2,
      "name": "Rock_Marble_Brick_Pillar_Base",
      "rotation": 1
    },
    {
      "x": 3,
      "y": 3,
      "z": -2,
      "name": "Rock_Marble_Brick_Pillar_Middle",
      "rotation": 1
    },
    {
      "x": 3,
      "y": 4,
      "z": -2,
      "name": "Rock_Marble_Brick_Pillar_Middle",
      "rotation": 1
    },
    {
      "x": 3,
      "y": 5,
      "z": -2,
      "name": "Rock_Marble_Brick_Pillar_Middle",
      "rotation": 1
    },
    {
      "x": 3,
      "y": 6,
      "z": -2,
      "name": "Rock_Marble_Brick_Pillar_Base",
      "rotation": 9
    },
    {
      "x": 3,
      "y": 7,
      "z": -2,
      "name": "Rock_Marble_Brick",
      "rotation": 1
    },
    {
      "x": 3,
      "y": 8,
      "z": -2,
      "name": "Rock_Marble_Brick_Roof_Shallow",
      "filler": 31,
      "rotation": 1
    },
    {
      "x": 3,
      "y": 0,
      "z": -1,
      "name": "Rock_Marble_Brick"
    },
    {
      "x": 3,
      "y": 1,
      "z": -1,
      "name": "Rock_Marble_Brick"
    },
    {
      "x": 3,
      "y": 7,
      "z": -1,
      "name": "Rock_Marble_Brick",
      "rotation": 1
    },
    {
      "x": 3,
      "y": 8,
      "z": -1,
      "name": "Rock_Marble_Brick_Roof_Shallow",
      "filler": 31,
      "rotation": 1
    },
    {
      "x": 3,
      "y": 0,
      "z": 0,
      "name": "Rock_Marble_Brick"
    },
    {
      "x": 3,
      "y": 1,
      "z": 0,
      "name": "Rock_Marble_Brick"
    },
    {
      "x": 3,
      "y": 2,
      "z": 0,
      "name": "Rock_Marble_Brick_Pillar_Base",
      "rotation": 1
    },
    {
      "x": 3,
      "y": 3,
      "z": 0,
      "name": "Rock_Marble_Brick_Pillar_Middle",
      "rotation": 1
    },
    {
      "x": 3,
      "y": 4,
      "z": 0,
      "name": "Rock_Marble_Brick_Pillar_Middle",
      "rotation": 1
    },
    {
      "x": 3,
      "y": 5,
      "z": 0,
      "name": "Rock_Marble_Brick_Pillar_Middle",
      "rotation": 1
    },
    {
      "x": 3,
      "y": 6,
      "z": 0,
      "name": "Rock_Marble_Brick_Pillar_Base",
      "rotation": 9
    },
    {
      "x": 3,
      "y": 7,
      "z": 0,
      "name": "Rock_Marble_Brick",
      "rotation": 1
    },
    {
      "x": 3,
      "y": 8,
      "z": 0,
      "name": "Rock_Marble_Brick_Roof_Shallow",
      "filler": 31,
      "rotation": 1
    },
    {
      "x": 3,
      "y": 0,
      "z": 1,
      "name": "Rock_Marble_Brick"
    },
    {
      "x": 3,
      "y": 1,
      "z": 1,
      "name": "Rock_Marble_Brick"
    },
    {
      "x": 3,
      "y": 7,
      "z": 1,
      "name": "Rock_Marble_Brick",
      "rotation": 1
    },
    {
      "x": 3,
      "y": 8,
      "z": 1,
      "name": "Rock_Marble_Brick_Roof_Shallow",
      "filler": 31,
      "rotation": 1
    },
    {
      "x": 3,
      "y": 0,
      "z": 2,
      "name": "Rock_Marble_Brick"
    },
    {
      "x": 3,
      "y": 1,
      "z": 2,
      "name": "Rock_Marble_Brick"
    },
    {
      "x": 3,
      "y": 2,
      "z": 2,
      "name": "Rock_Marble_Brick_Pillar_Base",
      "rotation": 1
    },
    {
      "x": 3,
      "y": 3,
      "z": 2,
      "name": "Rock_Marble_Brick_Pillar_Middle",
      "rotation": 1
    },
    {
      "x": 3,
      "y": 4,
      "z": 2,
      "name": "Rock_Marble_Brick_Pillar_Middle",
      "rotation": 1
    },
    {
      "x": 3,
      "y": 5,
      "z": 2,
      "name": "Rock_Marble_Brick_Pillar_Middle",
      "rotation": 1
    },
    {
      "x": 3,
      "y": 6,
      "z": 2,
      "name": "Rock_Marble_Brick_Pillar_Base",
      "rotation": 9
    },
    {
      "x": 3,
      "y": 7,
      "z": 2,
      "name": "Rock_Marble_Brick",
      "rotation": 1
    },
    {
      "x": 3,
      "y": 8,
      "z": 2,
      "name": "Rock_Marble_Brick_Roof_Shallow",
      "filler": 31,
      "rotation": 1
    },
    {
      "x": 3,
      "y": 0,
      "z": 3,
      "name": "Rock_Marble_Brick"
    },
    {
      "x": 3,
      "y": 1,
      "z": 3,
      "name": "Rock_Marble_Brick"
    },
    {
      "x": 3,
      "y": 7,
      "z": 3,
      "name": "Rock_Marble_Brick",
      "rotation": 1
    },
    {
      "x": 3,
      "y": 8,
      "z": 3,
      "name": "Rock_Marble_Brick_Roof_Shallow",
      "filler": 31,
      "rotation": 1
    },
    {
      "x": 3,
      "y": 0,
      "z": 4,
      "name": "Rock_Marble_Brick"
    },
    {
      "x": 3,
      "y": 1,
      "z": 4,
      "name": "Rock_Marble_Brick",
      "rotation": 1
    },
    {
      "x": 3,
      "y": 2,
      "z": 4,
      "name": "Rock_Marble_Brick_Pillar_Base",
      "rotation": 1
    },
    {
      "x": 3,
      "y": 3,
      "z": 4,
      "name": "Rock_Marble_Brick_Pillar_Middle",
      "rotation": 1
    },
    {
      "x": 3,
      "y": 4,
      "z": 4,
      "name": "Rock_Marble_Brick_Pillar_Middle",
      "rotation": 1
    },
    {
      "x": 3,
      "y": 5,
      "z": 4,
      "name": "Rock_Marble_Brick_Pillar_Middle",
      "rotation": 1
    },
    {
      "x": 3,
      "y": 6,
      "z": 4,
      "name": "Rock_Marble_Brick_Pillar_Base",
      "rotation": 9
    },
    {
      "x": 3,
      "y": 7,
      "z": 4,
      "name": "Rock_Marble_Brick",
      "rotation": 1
    },
    {
      "x": 3,
      "y": 8,
      "z": 4,
      "name": "Rock_Marble_Brick_Roof_Shallow",
      "filler": 31,
      "rotation": 1
    },
    {
      "x": 3,
      "y": 0,
      "z": 5,
      "name": "Rock_Marble_Brick"
    },
    {
      "x": 3,
      "y": 1,
      "z": 5,
      "name": "Rock_Marble_Brick",
      "rotation": 1
    },
    {
      "x": 3,
      "y": 7,
      "z": 5,
      "name": "Rock_Marble_Brick",
      "rotation": 1
    },
    {
      "x": 3,
      "y": 8,
      "z": 5,
      "name": "Rock_Marble_Brick_Roof_Shallow",
      "filler": 31,
      "rotation": 1
    },
    {
      "x": 4,
      "y": 0,
      "z": -5,
      "name": "Rock_Marble_Brick"
    },
    {
      "x": 4,
      "y": 1,
      "z": -5,
      "name": "Rock_Marble_Brick"
    },
    {
      "x": 4,
      "y": 7,
      "z": -5,
      "name": "Rock_Marble_Brick",
      "rotation": 1
    },
    {
      "x": 4,
      "y": 8,
      "z": -5,
      "name": "Rock_Marble_Brick_Roof_Shallow",
      "rotation": 1
    },
    {
      "x": 4,
      "y": 0,
      "z": -4,
      "name": "Rock_Marble_Brick"
    },
    {
      "x": 4,
      "y": 1,
      "z": -4,
      "name": "Rock_Marble_Brick"
    },
    {
      "x": 4,
      "y": 7,
      "z": -4,
      "name": "Rock_Marble_Brick",
      "rotation": 1
    },
    {
      "x": 4,
      "y": 8,
      "z": -4,
      "name": "Rock_Marble_Brick_Roof_Shallow",
      "rotation": 1
    },
    {
      "x": 4,
      "y": 0,
      "z": -3,
      "name": "Rock_Marble_Brick"
    },
    {
      "x": 4,
      "y": 1,
      "z": -3,
      "name": "Rock_Marble_Brick"
    },
    {
      "x": 4,
      "y": 7,
      "z": -3,
      "name": "Rock_Marble_Brick",
      "rotation": 1
    },
    {
      "x": 4,
      "y": 8,
      "z": -3,
      "name": "Rock_Marble_Brick_Roof_Shallow",
      "rotation": 1
    },
    {
      "x": 4,
      "y": 0,
      "z": -2,
      "name": "Rock_Marble_Brick"
    },
    {
      "x": 4,
      "y": 1,
      "z": -2,
      "name": "Rock_Marble_Brick"
    },
    {
      "x": 4,
      "y": 7,
      "z": -2,
      "name": "Rock_Marble_Brick",
      "rotation": 1
    },
    {
      "x": 4,
      "y": 8,
      "z": -2,
      "name": "Rock_Marble_Brick_Roof_Shallow",
      "rotation": 1
    },
    {
      "x": 4,
      "y": 0,
      "z": -1,
      "name": "Rock_Marble_Brick"
    },
    {
      "x": 4,
      "y": 1,
      "z": -1,
      "name": "Rock_Marble_Brick"
    },
    {
      "x": 4,
      "y": 7,
      "z": -1,
      "name": "Rock_Marble_Brick",
      "rotation": 1
    },
    {
      "x": 4,
      "y": 8,
      "z": -1,
      "name": "Rock_Marble_Brick_Roof_Shallow",
      "rotation": 1
    },
    {
      "x": 4,
      "y": 0,
      "z": 0,
      "name": "Rock_Marble_Brick"
    },
    {
      "x": 4,
      "y": 1,
      "z": 0,
      "name": "Rock_Marble_Brick"
    },
    {
      "x": 4,
      "y": 7,
      "z": 0,
      "name": "Rock_Marble_Brick",
      "rotation": 1
    },
    {
      "x": 4,
      "y": 8,
      "z": 0,
      "name": "Rock_Marble_Brick_Roof_Shallow",
      "rotation": 1
    },
    {
      "x": 4,
      "y": 0,
      "z": 1,
      "name": "Rock_Marble_Brick"
    },
    {
      "x": 4,
      "y": 1,
      "z": 1,
      "name": "Rock_Marble_Brick"
    },
    {
      "x": 4,
      "y": 7,
      "z": 1,
      "name": "Rock_Marble_Brick",
      "rotation": 1
    },
    {
      "x": 4,
      "y": 8,
      "z": 1,
      "name": "Rock_Marble_Brick_Roof_Shallow",
      "rotation": 1
    },
    {
      "x": 4,
      "y": 0,
      "z": 2,
      "name": "Rock_Marble_Brick"
    },
    {
      "x": 4,
      "y": 1,
      "z": 2,
      "name": "Rock_Marble_Brick"
    },
    {
      "x": 4,
      "y": 7,
      "z": 2,
      "name": "Rock_Marble_Brick",
      "rotation": 1
    },
    {
      "x": 4,
      "y": 8,
      "z": 2,
      "name": "Rock_Marble_Brick_Roof_Shallow",
      "rotation": 1
    },
    {
      "x": 4,
      "y": 0,
      "z": 3,
      "name": "Rock_Marble_Brick"
    },
    {
      "x": 4,
      "y": 1,
      "z": 3,
      "name": "Rock_Marble_Brick"
    },
    {
      "x": 4,
      "y": 7,
      "z": 3,
      "name": "Rock_Marble_Brick",
      "rotation": 1
    },
    {
      "x": 4,
      "y": 8,
      "z": 3,
      "name": "Rock_Marble_Brick_Roof_Shallow",
      "rotation": 1
    },
    {
      "x": 4,
      "y": 0,
      "z": 4,
      "name": "Rock_Marble_Brick"
    },
    {
      "x": 4,
      "y": 1,
      "z": 4,
      "name": "Rock_Marble_Brick",
      "rotation": 1
    },
    {
      "x": 4,
      "y": 7,
      "z": 4,
      "name": "Rock_Marble_Brick",
      "rotation": 1
    },
    {
      "x": 4,
      "y": 8,
      "z": 4,
      "name": "Rock_Marble_Brick_Roof_Shallow",
      "rotation": 1
    },
    {
      "x": 4,
      "y": 0,
      "z": 5,
      "name": "Rock_Marble_Brick"
    },
    {
      "x": 4,
      "y": 1,
      "z": 5,
      "name": "Rock_Marble_Brick",
      "rotation": 1
    },
    {
      "x": 4,
      "y": 7,
      "z": 5,
      "name": "Rock_Marble_Brick",
      "rotation": 1
    },
    {
      "x": 4,
      "y": 8,
      "z": 5,
      "name": "Rock_Marble_Brick_Roof_Shallow",
      "rotation": 1
    }
  ]
}