{
  "version": 8,
  "blockIdVersion": 11,
  "anchorX": 0,
  "anchorY": 1,
  "anchorZ": 0,
  "blocks": [
    {
      "x": -10,
      "y": 12,
      "z": -8,
      "name": "Plant_Leaves_Aspen",
      "support": 15,
      "rotation": 1
    },
    {
      "x": -10,
      "y": 12,
      "z": -7,
      "name": "Plant_Leaves_Aspen",
      "support": 15,
      "rotation": 1
    },
    {
      "x": -10,
      "y": 13,
      "z": -7,
      "name": "Plant_Leaves_Aspen",
      "support": 15,
      "rotation": 1
    },
    {
      "x": -10,
      "y": 12,
      "z": -6,
      "name": "Plant_Leaves_Aspen",
      "support": 15,
      "rotation": 1
    },
    {
      "x": -10,
      "y": 17,
      "z": 2,
      "name": "Plant_Leaves_Aspen",
      "support": 15,
      "rotation": 1
    },
    {
      "x": -10,
      "y": 17,
      "z": 3,
      "name": "Plant_Leaves_Aspen",
      "support": 15,
      "rotation": 1
    },
    {
      "x": -9,
      "y": 12,
      "z": -8,
      "name": "Plant_Leaves_Aspen",
      "support": 15,
      "rotation": 1
    },
    {
      "x": -9,
      "y": 13,
      "z": -8,
      "name": "Plant_Leaves_Aspen",
      "support": 15,
      "rotation": 1
    },
    {
      "x": -9,
      "y": 12,
      "z": -7,
      "name": "Plant_Leaves_Aspen",
      "support": 15,
      "rotation": 1
    },
    {
      "x": -9,
      "y": 13,
      "z": -7,
      "name": "Plant_Leaves_Aspen",
      "support": 15,
      "rotation": 1
    },
    {
      "x": -9,
      "y": 11,
      "z": -6,
      "name": "Plant_Leaves_Aspen",
      "support": 15,
      "rotation": 1
    },
    {
      "x": -9,
      "y": 12,
      "z": -6,
      "name": "Plant_Leaves_Aspen",
      "support": 15,
      "rotation": 1
    },
    {
      "x": -9,
      "y": 13,
      "z": -6,
      "name": "Plant_Leaves_Aspen",
      "support": 15,
      "rotation": 1
    },
    {
      "x": -9,
      "y": 12,
      "z": -5,
      "name": "Plant_Leaves_Aspen",
      "support": 15,
      "rotation": 1
    },
    {
      "x": -9,
      "y": 12,
      "z": -4,
      "name": "Plant_Leaves_Aspen",
      "support": 15,
      "rotation": 1
    },
    {
      "x": -9,
      "y": 17,
      "z": 0,
      "name": "Plant_Leaves_Aspen",
      "support": 15,
      "rotation": 1
    },
    {
      "x": -9,
      "y": 17,
      "z": 1,
      "name": "Plant_Leaves_Aspen",
      "support": 15,
      "rotation": 1
    },
    {
      "x": -9,
      "y": 17,
      "z": 2,
      "name": "Plant_Leaves_Aspen",
      "support": 15,
      "rotation": 1
    },
    {
      "x": -9,
      "y": 17,
      "z": 3,
      "name": "Plant_Leaves_Aspen",
      "support": 15,
      "rotation": 1
    },
    {
      "x": -9,
      "y": 17,
      "z": 4,
      "name": "Plant_Leaves_Aspen",
      "support": 15,
      "rotation": 1
    },
    {
      "x": -8,
      "y": 12,
      "z": -8,
      "name": "Plant_Leaves_Aspen",
      "support": 15,
      "rotation": 1
    },
    {
      "x": -8,
      "y": 11,
      "z": -7,
      "name": "Plant_Leaves_Aspen",
      "support": 15,
      "rotation": 1
    },
    {
      "x": -8,
      "y": 12,
      "z": -7,
      "name": "Plant_Leaves_Aspen",
      "support": 15,
      "rotation": 1
    },
    {
      "x": -8,
      "y": 13,
      "z": -7,
      "name": "Plant_Leaves_Aspen",
      "support": 15,
      "rotation": 1
    },
    {
      "x": -8,
      "y": 10,
      "z": -6,
      "name": "Wood_Birch_Branch_Corner",
      "support": 15,
      "rotation": 2
    },
    {
      "x": -8,
      "y": 11,
      "z": -6,
      "name": "Wood_Birch_Branch_Long",
      "support": 15,
      "rotation": 1
    },
    {
      "x": -8,
      "y": 12,
      "z": -6,
      "name": "Wood_Birch_Branch_Long",
      "support": 15,
      "rotation": 1
    },
    {
      "x": -8,
      "y": 13,
      "z": -6,
      "name": "Plant_Leaves_Aspen",
      "support": 15,
      "rotation": 1
    },
    {
      "x": -8,
      "y": 14,
      "z": -6,
      "name": "Plant_Leaves_Aspen",
      "support": 15,
      "rotation": 1
    },
    {
      "x": -8,
      "y": 10,
      "z": -5,
      "name": "Wood_Birch_Branch_Long",
      "support": 15,
      "rotation": 6
    },
    {
      "x": -8,
      "y": 12,
      "z": -5,
      "name": "Plant_Leaves_Aspen",
      "support": 15,
      "rotation": 1
    },
    {
      "x": -8,
      "y": 13,
      "z": -5,
      "name": "Plant_Leaves_Aspen",
      "support": 15,
      "rotation": 1
    },
    {
      "x": -8,
      "y": 9,
      "z": -4,
      "name": "Wood_Birch_Branch_Corner",
      "support": 15,
      "rotation": 3
    },
    {
      "x": -8,
      "y": 10,
      "z": -4,
      "name": "Wood_Birch_Branch_Corner",
      "support": 15,
      "rotation": 32
    },
    {
      "x": -8,
      "y": 12,
      "z": -4,
      "name": "Plant_Leaves_Aspen",
      "support": 15,
      "rotation": 1
    },
    {
      "x": -8,
      "y": 12,
      "z": -3,
      "name": "Plant_Leaves_Aspen",
      "support": 15,
      "rotation": 1
    },
    {
      "x": -8,
      "y": 17,
      "z": -1,
      "name": "Plant_Leaves_Aspen",
      "support": 15,
      "rotation": 1
    },
    {
      "x": -8,
      "y": 17,
      "z": 0,
      "name": "Plant_Leaves_Aspen",
      "support": 15,
      "rotation": 1
    },
    {
      "x": -8,
      "y": 18,
      "z": 0,
      "name": "Plant_Leaves_Aspen",
      "support": 15,
      "rotation": 1
    },
    {
      "x": -8,
      "y": 16,
      "z": 1,
      "name": "Plant_Leaves_Aspen",
      "support": 15,
      "rotation": 1
    },
    {
      "x": -8,
      "y": 17,
      "z": 1,
      "name": "Plant_Leaves_Aspen",
      "support": 15,
      "rotation": 1
    },
    {
      "x": -8,
      "y": 18,
      "z": 1,
      "name": "Plant_Leaves_Aspen",
      "support": 15,
      "rotation": 1
    },
    {
      "x": -8,
      "y": 17,
      "z": 2,
      "name": "Plant_Leaves_Aspen",
      "support": 15,
      "rotation": 1
    },
    {
      "x": -8,
      "y": 18,
      "z": 2,
      "name": "Plant_Leaves_Aspen",
      "support": 15,
      "rotation": 1
    },
    {
      "x": -8,
      "y": 17,
      "z": 3,
      "name": "Plant_Leaves_Aspen",
      "support": 15,
      "rotation": 1
    },
    {
      "x": -8,
      "y": 17,
      "z": 4,
      "name": "Plant_Leaves_Aspen",
      "support": 15,
      "rotation": 1
    },
    {
      "x": -7,
      "y": 12,
      "z": -8,
      "name": "Plant_Leaves_Aspen",
      "support": 15,
      "rotation": 1
    },
    {
      "x": -7,
      "y": 12,
      "z": -7,
      "name": "Plant_Leaves_Aspen",
      "support": 15,
      "rotation": 1
    },
    {
      "x": -7,
      "y": 13,
      "z": -7,
      "name": "Plant_Leaves_Aspen",
      "support": 15,
      "rotation": 1
    },
    {
      "x": -7,
      "y": 12,
      "z": -6,
      "name": "Plant_Leaves_Aspen",
      "support": 15,
      "rotation": 1
    },
    {
      "x": -7,
      "y": 13,
      "z": -6,
      "name": "Plant_Leaves_Aspen",
      "support": 15,
      "rotation": 1
    },
    {
      "x": -7,
      "y": 14,
      "z": -6,
      "name": "Plant_Leaves_Aspen",
      "support": 15,
      "rotation": 1
    },
    {
      "x": -7,
      "y": 12,
      "z": -5,
      "name": "Plant_Leaves_Aspen",
      "support": 15,
      "rotation": 1
    },
    {
      "x": -7,
      "y": 13,
      "z": -5,
      "name": "Plant_Leaves_Aspen",
      "support": 15,
      "rotation": 1
    },
    {
      "x": -7,
      "y": 14,
      "z": -5,
      "name": "Plant_Leaves_Aspen",
      "support": 15,
      "rotation": 1
    },
    {
      "x": -7,
      "y": 9,
      "z": -4,
      "name": "Wood_Birch_Branch_Long",
      "support": 15,
      "rotation": 5
    },
    {
      "x": -7,
      "y": 11,
      "z": -4,
      "name": "Plant_Leaves_Aspen",
      "support": 15,
      "rotation": 1
    },
    {
      "x": -7,
      "y": 12,
      "z": -4,
      "name": "Plant_Leaves_Aspen",
      "support": 15,
      "rotation": 1
    },
    {
      "x": -7,
      "y": 13,
      "z": -4,
      "name": "Plant_Leaves_Aspen",
      "support": 15,
      "rotation": 1
    },
    {
      "x": -7,
      "y": 14,
      "z": -4,
      "name": "Plant_Leaves_Aspen",
      "support": 15,
      "rotation": 1
    },
    {
      "x": -7,
      "y": 12,
      "z": -3,
      "name": "Plant_Leaves_Aspen",
      "support": 15,
      "rotation": 1
    },
    {
      "x": -7,
      "y": 13,
      "z": -3,
      "name": "Plant_Leaves_Aspen",
      "support": 15,
      "rotation": 1
    },
    {
      "x": -7,
      "y": 14,
      "z": -3,
      "name": "Plant_Leaves_Aspen",
      "support": 15,
      "rotation": 1
    },
    {
      "x": -7,
      "y": 12,
      "z": -2,
      "name": "Plant_Leaves_Aspen",
      "support": 15,
      "rotation": 1
    },
    {
      "x": -7,
      "y": 17,
      "z": -1,
      "name": "Plant_Leaves_Aspen",
      "support": 15,
      "rotation": 1
    },
    {
      "x": -7,
      "y": 17,
      "z": 0,
      "name": "Plant_Leaves_Aspen",
      "support": 15,
      "rotation": 1
    },
    {
      "x": -7,
      "y": 18,
      "z": 0,
      "name": "Plant_Leaves_Aspen",
      "support": 15,
      "rotation": 1
    },
    {
      "x": -7,
      "y": 15,
      "z": 1,
      "name": "Wood_Birch_Branch_Corner",
      "support": 15,
      "rotation": 3
    },
    {
      "x": -7,
      "y": 16,
      "z": 1,
      "name": "Wood_Birch_Branch_Long",
      "support": 15,
      "rotation": 1
    },
    {
      "x": -7,
      "y": 17,
      "z": 1,
      "name": "Wood_Birch_Branch_Long",
      "support": 15,
      "rotation": 1
    },
    {
      "x": -7,
      "y": 18,
      "z": 1,
      "name": "Plant_Leaves_Aspen",
      "support": 15,
      "rotation": 1
    },
    {
      "x": -7,
      "y": 16,
      "z": 2,
      "name": "Plant_Leaves_Aspen",
      "support": 15,
      "rotation": 1
    },
    {
      "x": -7,
      "y": 17,
      "z": 2,
      "name": "Plant_Leaves_Aspen",
      "support": 15,
      "rotation": 1
    },
    {
      "x": -7,
      "y": 18,
      "z": 2,
      "name": "Plant_Leaves_Aspen",
      "support": 15,
      "rotation": 1
    },
    {
      "x": -7,
      "y": 16,
      "z": 3,
      "name": "Plant_Leaves_Aspen",
      "support": 15,
      "rotation": 1
    },
    {
      "x": -7,
      "y": 17,
      "z": 3,
      "name": "Plant_Leaves_Aspen",
      "support": 15,
      "rotation": 1
    },
    {
      "x": -6,
      "y": 12,
      "z": -7,
      "name": "Plant_Leaves_Aspen",
      "support": 15,
      "rotation": 1
    },
    {
      "x": -6,
      "y": 12,
      "z": -6,
      "name": "Plant_Leaves_Aspen",
      "support": 15,
      "rotation": 1
    },
    {
      "x": -6,
      "y": 13,
      "z": -6,
      "name": "Plant_Leaves_Aspen",
      "support": 15,
      "rotation": 1
    },
    {
      "x": -6,
      "y": 12,
      "z": -5,
      "name": "Plant_Leaves_Aspen",
      "support": 15,
      "rotation": 1
    },
    {
      "x": -6,
      "y": 13,
      "z": -5,
      "name": "Plant_Leaves_Aspen",
      "support": 15,
      "rotation": 1
    },
    {
      "x": -6,
      "y": 14,
      "z": -5,
      "name": "Plant_Leaves_Aspen",
      "support": 15,
      "rotation": 1
    },
    {
      "x": -6,
      "y": 7,
      "z": -4,
      "name": "Wood_Birch_Trunk_Full",
      "support": 15,
      "rotation": 1
    },
    {
      "x": -6,
      "y": 8,
      "z": -4,
      "name": "Wood_Birch_Trunk",
      "support": 15,
      "rotation": 1
    },
    {
      "x": -6,
      "y": 9,
      "z": -4,
      "name": "Wood_Birch_Trunk",
      "support": 15,
      "rotation": 1
    },
    {
      "x": -6,
      "y": 10,
      "z": -4,
      "name": "Wood_Birch_Trunk",
      "support": 15,
      "rotation": 1
    },
    {
      "x": -6,
      "y": 11,
      "z": -4,
      "name": "Wood_Birch_Trunk",
      "support": 15,
      "rotation": 1
    },
    {
      "x": -6,
      "y": 12,
      "z": -4,
      "name": "Wood_Birch_Trunk",
      "support": 15,
      "rotation": 1
    },
    {
      "x": -6,
      "y": 13,
      "z": -4,
      "name": "Wood_Birch_Trunk_Full",
      "support": 15,
      "rotation": 1
    },
    {
      "x": -6,
      "y": 14,
      "z": -4,
      "name": "Plant_Leaves_Aspen",
      "support": 15,
      "rotation": 1
    },
    {
      "x": -6,
      "y": 6,
      "z": -3,
      "name": "Wood_Birch_Trunk_Full",
      "support": 15
    },
    {
      "x": -6,
      "y": 7,
      "z": -3,
      "name": "Wood_Birch_Trunk_Full",
      "support": 15,
      "rotation": 1
    },
    {
      "x": -6,
      "y": 12,
      "z": -3,
      "name": "Plant_Leaves_Aspen",
      "support": 15,
      "rotation": 1
    },
    {
      "x": -6,
      "y": 13,
      "z": -3,
      "name": "Wood_Birch_Trunk_Full",
      "support": 15,
      "rotation": 5
    },
    {
      "x": -6,
      "y": 14,
      "z": -3,
      "name": "Plant_Leaves_Aspen",
      "support": 15,
      "rotation": 1
    },
    {
      "x": -6,
      "y": 7,
      "z": -2,
      "name": "Plant_Leaves_Aspen",
      "support": 15,
      "rotation": 1
    },
    {
      "x": -6,
      "y": 12,
      "z": -2,
      "name": "Plant_Leaves_Aspen",
      "support": 15,
      "rotation": 1
    },
    {
      "x": -6,
      "y": 13,
      "z": -2,
      "name": "Plant_Leaves_Aspen",
      "support": 15,
      "rotation": 1
    },
    {
      "x": -6,
      "y": 7,
      "z": -1,
      "name": "Plant_Leaves_Aspen",
      "support": 15,
      "rotation": 1
    },
    {
      "x": -6,
      "y": 17,
      "z": -1,
      "name": "Plant_Leaves_Aspen",
      "support": 15,
      "rotation": 1
    },
    {
      "x": -6,
      "y": 17,
      "z": 0,
      "name": "Plant_Leaves_Aspen",
      "support": 15,
      "rotation": 1
    },
    {
      "x": -6,
      "y": 15,
      "z": 1,
      "name": "Wood_Birch_Branch_Long",
      "support": 15,
      "rotation": 5
    },
    {
      "x": -6,
      "y": 17,
      "z": 1,
      "name": "Plant_Leaves_Aspen",
      "support": 15,
      "rotation": 1
    },
    {
      "x": -6,
      "y": 17,
      "z": 2,
      "name": "Plant_Leaves_Aspen",
      "support": 15,
      "rotation": 1
    },
    {
      "x": -6,
      "y": 17,
      "z": 3,
      "name": "Plant_Leaves_Aspen",
      "support": 15,
      "rotation": 1
    },
    {
      "x": -5,
      "y": 13,
      "z": -6,
      "name": "Plant_Leaves_Aspen",
      "support": 15,
      "rotation": 1
    },
    {
      "x": -5,
      "y": 0,
      "z": -5,
      "name": "Rock_Marble_Brick"
    },
    {
      "x": -5,
      "y": 1,
      "z": -5,
      "name": "Rock_Marble_Brick"
    },
    {
      "x": -5,
      "y": 2,
      "z": -5,
      "name": "Rock_Marble_Brick"
    },
    {
      "x": -5,
      "y": 3,
      "z": -5,
      "name": "Rock_Marble_Brick"
    },
    {
      "x": -5,
      "y": 4,
      "z": -5,
      "name": "Rock_Marble_Brick"
    },
    {
      "x": -5,
      "y": 12,
      "z": -5,
      "name": "Plant_Leaves_Aspen",
      "support": 15,
      "rotation": 1
    },
    {
      "x": -5,
      "y": 13,
      "z": -5,
      "name": "Plant_Leaves_Aspen",
      "support": 15,
      "rotation": 1
    },
    {
      "x": -5,
      "y": 14,
      "z": -5,
      "name": "Plant_Leaves_Aspen",
      "support": 15,
      "rotation": 1
    },
    {
      "x": -5,
      "y": 16,
      "z": -5,
      "name": "Plant_Leaves_Aspen",
      "support": 15,
      "rotation": 1
    },
    {
      "x": -5,
      "y": 0,
      "z": -4,
      "name": "Rock_Marble_Brick"
    },
    {
      "x": -5,
      "y": 1,
      "z": -4,
      "name": "Rock_Marble_Brick"
    },
    {
      "x": -5,
      "y": 2,
      "z": -4,
      "name": "Rock_Marble_Brick"
    },
    {
      "x": -5,
      "y": 4,
      "z": -4,
      "name": "Rock_Marble_Brick"
    },
    {
      "x": -5,
      "y": 5,
      "z": -4,
      "name": "Rock_Marble_Brick"
    },
    {
      "x": -5,
      "y": 7,
      "z": -4,
      "name": "Wood_Birch_Trunk_Full",
      "support": 15,
      "rotation": 1
    },
    {
      "x": -5,
      "y": 12,
      "z": -4,
      "name": "Plant_Leaves_Aspen",
      "support": 15,
      "rotation": 1
    },
    {
      "x": -5,
      "y": 13,
      "z": -4,
      "name": "Wood_Birch_Trunk_Full",
      "support": 15,
      "rotation": 5
    },
    {
      "x": -5,
      "y": 14,
      "z": -4,
      "name": "Plant_Leaves_Aspen",
      "support": 15,
      "rotation": 1
    },
    {
      "x": -5,
      "y": 16,
      "z": -4,
      "name": "Plant_Leaves_Aspen",
      "support": 15,
      "rotation": 1
    },
    {
      "x": -5,
      "y": 0,
      "z": -3,
      "name": "Rock_Marble_Brick"
    },
    {
      "x": -5,
      "y": 1,
      "z": -3,
      "name": "Rock_Marble_Brick"
    },
    {
      "x": -5,
      "y": 2,
      "z": -3,
      "name": "Rock_Marble_Brick"
    },
    {
      "x": -5,
      "y": 5,
      "z": -3,
      "name": "Wood_Birch_Trunk_Full",
      "support": 15
    },
    {
      "x": -5,
      "y": 6,
      "z": -3,
      "name": "Wood_Birch_Trunk_Full",
      "support": 15,
      "rotation": 1
    },
    {
      "x": -5,
      "y": 7,
      "z": -3,
      "name": "Wood_Birch_Trunk",
      "support": 15,
      "rotation": 1
    },
    {
      "x": -5,
      "y": 8,
      "z": -3,
      "name": "Wood_Birch_Trunk_Full",
      "support": 15,
      "rotation": 1
    },
    {
      "x": -5,
      "y": 12,
      "z": -3,
      "name": "Plant_Leaves_Aspen",
      "support": 15,
      "rotation": 1
    },
    {
      "x": -5,
      "y": 13,
      "z": -3,
      "name": "Wood_Birch_Trunk",
      "support": 15,
      "rotation": 6
    },
    {
      "x": -5,
      "y": 14,
      "z": -3,
      "name": "Wood_Birch_Trunk_Full",
      "support": 15,
      "rotation": 6
    },
    {
      "x": -5,
      "y": 16,
      "z": -3,
      "name": "Plant_Leaves_Aspen",
      "support": 15,
      "rotation": 1
    },
    {
      "x": -5,
      "y": 0,
      "z": -2,
      "name": "Rock_Marble_Brick"
    },
    {
      "x": -5,
      "y": 1,
      "z": -2,
      "name": "Rock_Marble_Brick"
    },
    {
      "x": -5,
      "y": 2,
      "z": -2,
      "name": "Rock_Marble_Brick"
    },
    {
      "x": -5,
      "y": 4,
      "z": -2,
      "name": "Wood_Birch_Trunk_Full",
      "support": 15
    },
    {
      "x": -5,
      "y": 5,
      "z": -2,
      "name": "Wood_Birch_Trunk_Full",
      "support": 15,
      "rotation": 1
    },
    {
      "x": -5,
      "y": 6,
      "z": -2,
      "name": "Wood_Birch_Trunk",
      "support": 15,
      "rotation": 1
    },
    {
      "x": -5,
      "y": 7,
      "z": -2,
      "name": "Wood_Birch_Trunk_Full",
      "support": 15,
      "rotation": 1
    },
    {
      "x": -5,
      "y": 8,
      "z": -2,
      "name": "Rock_Marble_Brick_Stairs",
      "rotation": 8
    },
    {
      "x": -5,
      "y": 9,
      "z": -2,
      "name": "Rock_Marble_Brick_Decorative"
    },
    {
      "x": -5,
      "y": 10,
      "z": -2,
      "name": "Rock_Marble_Brick_Smooth_Half"
    },
    {
      "x": -5,
      "y": 13,
      "z": -2,
      "name": "Plant_Leaves_Aspen",
      "support": 15,
      "rotation": 1
    },
    {
      "x": -5,
      "y": 14,
      "z": -2,
      "name": "Wood_Birch_Trunk_Full",
      "support": 15,
      "rotation": 6
    },
    {
      "x": -5,
      "y": 0,
      "z": -1,
      "name": "Rock_Marble_Brick"
    },
    {
      "x": -5,
      "y": 1,
      "z": -1,
      "name": "Rock_Marble_Brick"
    },
    {
      "x": -5,
      "y": 2,
      "z": -1,
      "name": "Rock_Marble_Brick"
    },
    {
      "x": -5,
      "y": 3,
      "z": -1,
      "name": "Rock_Marble_Brick"
    },
    {
      "x": -5,
      "y": 4,
      "z": -1,
      "name": "Rock_Marble_Brick"
    },
    {
      "x": -5,
      "y": 5,
      "z": -1,
      "name": "Rock_Marble_Brick"
    },
    {
      "x": -5,
      "y": 6,
      "z": -1,
      "name": "Rock_Marble_Brick"
    },
    {
      "x": -5,
      "y": 7,
      "z": -1,
      "name": "Plant_Leaves_Aspen",
      "support": 15,
      "rotation": 1
    },
    {
      "x": -5,
      "y": 8,
      "z": -1,
      "name": "Rock_Marble_Brick"
    },
    {
      "x": -5,
      "y": 9,
      "z": -1,
      "name": "Rock_Marble_Brick_Decorative"
    },
    {
      "x": -5,
      "y": 10,
      "z": -1,
      "name": "Rock_Marble_Brick_Smooth_Half"
    },
    {
      "x": -5,
      "y": 14,
      "z": -1,
      "name": "Wood_Birch_Branch_Long",
      "support": 15,
      "rotation": 6
    },
    {
      "x": -5,
      "y": 0,
      "z": 0,
      "name": "Rock_Marble_Brick"
    },
    {
      "x": -5,
      "y": 1,
      "z": 0,
      "name": "Rock_Marble_Brick"
    },
    {
      "x": -5,
      "y": 2,
      "z": 0,
      "name": "Rock_Marble_Brick"
    },
    {
      "x": -5,
      "y": 3,
      "z": 0,
      "name": "Rock_Marble_Brick"
    },
    {
      "x": -5,
      "y": 4,
      "z": 0,
      "name": "Rock_Marble_Brick"
    },
    {
      "x": -5,
      "y": 5,
      "z": 0,
      "name": "Rock_Marble_Brick"
    },
    {
      "x": -5,
      "y": 6,
      "z": 0,
      "name": "Rock_Marble_Brick"
    },
    {
      "x": -5,
      "y": 7,
      "z": 0,
      "name": "Rock_Marble_Brick"
    },
    {
      "x": -5,
      "y": 8,
      "z": 0,
      "name": "Rock_Marble_Brick"
    },
    {
      "x": -5,
      "y": 9,
      "z": 0,
      "name": "Rock_Marble_Brick_Decorative"
    },
    {
      "x": -5,
      "y": 10,
      "z": 0,
      "name": "Rock_Marble_Brick_Smooth_Half"
    },
    {
      "x": -5,
      "y": 14,
      "z": 0,
      "name": "Wood_Birch_Branch_Long",
      "support": 15,
      "rotation": 6
    },
    {
      "x": -5,
      "y": 17,
      "z": 0,
      "name": "Plant_Leaves_Aspen",
      "support": 15,
      "rotation": 1
    },
    {
      "x": -5,
      "y": 0,
      "z": 1,
      "name": "Rock_Marble_Brick"
    },
    {
      "x": -5,
      "y": 1,
      "z": 1,
      "name": "Rock_Marble_Brick"
    },
    {
      "x": -5,
      "y": 2,
      "z": 1,
      "name": "Rock_Marble_Brick_Pillar_Base"
    },
    {
      "x": -5,
      "y": 3,
      "z": 1,
      "name": "Rock_Marble_Brick_Pillar_Middle"
    },
    {
      "x": -5,
      "y": 4,
      "z": 1,
      "name": "Rock_Marble_Brick_Pillar_Base",
      "rotation": 8
    },
    {
      "x": -5,
      "y": 5,
      "z": 1,
      "name": "Rock_Marble_Brick_Decorative"
    },
    {
      "x": -5,
      "y": 14,
      "z": 1,
      "name": "Wood_Birch_Branch_Corner",
      "support": 15
    },
    {
      "x": -5,
      "y": 15,
      "z": 1,
      "name": "Wood_Birch_Branch_Corner",
      "support": 15,
      "rotation": 33
    },
    {
      "x": -5,
      "y": 17,
      "z": 1,
      "name": "Plant_Leaves_Aspen",
      "support": 15,
      "rotation": 1
    },
    {
      "x": -5,
      "y": 0,
      "z": 2,
      "name": "Rock_Marble_Brick"
    },
    {
      "x": -5,
      "y": 1,
      "z": 2,
      "name": "Rock_Marble_Brick"
    },
    {
      "x": -5,
      "y": 5,
      "z": 2,
      "name": "Rock_Marble_Brick_Decorative"
    },
    {
      "x": -5,
      "y": 17,
      "z": 2,
      "name": "Plant_Leaves_Aspen",
      "support": 15,
      "rotation": 1
    },
    {
      "x": -5,
      "y": 0,
      "z": 3,
      "name": "Rock_Marble_Brick"
    },
    {
      "x": -5,
      "y": 1,
      "z": 3,
      "name": "Rock_Marble_Brick"
    },
    {
      "x": -5,
      "y": 2,
      "z": 3,
      "name": "Rock_Marble_Brick_Pillar_Base"
    },
    {
      "x": -5,
      "y": 3,
      "z": 3,
      "name": "Rock_Marble_Brick_Pillar_Middle"
    },
    {
      "x": -5,
      "y": 4,
      "z": 3,
      "name": "Rock_Marble_Brick_Pillar_Base",
      "rotation": 8
    },
    {
      "x": -5,
      "y": 5,
      "z": 3,
      "name": "Rock_Marble_Brick_Decorative"
    },
    {
      "x": -5,
      "y": 17,
      "z": 3,
      "name": "Plant_Leaves_Aspen",
      "support": 15,
      "rotation": 1
    },
    {
      "x": -5,
      "y": 0,
      "z": 4,
      "name": "Rock_Marble_Brick"
    },
    {
      "x": -5,
      "y": 1,
      "z": 4,
      "name": "Rock_Marble_Brick"
    },
    {
      "x": -5,
      "y": 5,
      "z": 4,
      "name": "Rock_Marble_Brick_Decorative"
    },
    {
      "x": -5,
      "y": 0,
      "z": 5,
      "name": "Rock_Marble_Brick"
    },
    {
      "x": -5,
      "y": 1,
      "z": 5,
      "name": "Rock_Marble_Brick"
    },
    {
      "x": -5,
      "y": 2,
      "z": 5,
      "name": "Rock_Marble_Brick_Pillar_Base"
    },
    {
      "x": -5,
      "y": 3,
      "z": 5,
      "name": "Rock_Marble_Brick_Pillar_Middle"
    },
    {
      "x": -4,
      "y": 0,
      "z": -5,
      "name": "Rock_Marble_Brick"
    },
    {
      "x": -4,
      "y": 1,
      "z": -5,
      "name": "Rock_Marble_Brick"
    },
    {
      "x": -4,
      "y": 2,
      "z": -5,
      "name": "Rock_Marble_Brick"
    },
    {
      "x": -4,
      "y": 3,
      "z": -5,
      "name": "Rock_Marble_Brick"
    },
    {
      "x": -4,
      "y": 4,
      "z": -5,
      "name": "Rock_Marble_Brick"
    },
    {
      "x": -4,
      "y": 5,
      "z": -5,
      "name": "Rock_Marble_Brick"
    },
    {
      "x": -4,
      "y": 13,
      "z": -5,
      "name": "Plant_Leaves_Aspen",
      "support": 15,
      "rotation": 1
    },
    {
      "x": -4,
      "y": 14,
      "z": -5,
      "name": "Plant_Leaves_Aspen",
      "support": 15,
      "rotation": 1
    },
    {
      "x": -4,
      "y": 16,
      "z": -5,
      "name": "Plant_Leaves_Aspen",
      "support": 15,
      "rotation": 1
    },
    {
      "x": -4,
      "y": 0,
      "z": -4,
      "name": "Wood_Birch_Trunk_Full",
      "support": 15,
      "rotation": 1
    },
    {
      "x": -4,
      "y": 1,
      "z": -4,
      "name": "Wood_Birch_Trunk_Full",
      "support": 15,
      "rotation": 1
    },
    {
      "x": -4,
      "y": 13,
      "z": -4,
      "name": "Plant_Leaves_Aspen",
      "support": 15,
      "rotation": 1
    },
    {
      "x": -4,
      "y": 14,
      "z": -4,
      "name": "Plant_Leaves_Aspen",
      "support": 15,
      "rotation": 1
    },
    {
      "x": -4,
      "y": 16,
      "z": -4,
      "name": "Plant_Leaves_Aspen",
      "support": 15,
      "rotation": 1
    },
    {
      "x": -4,
      "y": 17,
      "z": -4,
      "name": "Plant_Leaves_Aspen",
      "support": 15,
      "rotation": 1
    },
    {
      "x": -4,
      "y": 0,
      "z": -3,
      "name": "Rock_Marble_Brick"
    },
    {
      "x": -4,
      "y": 1,
      "z": -3,
      "name": "Rock_Marble_SkyGrass"
    },
    {
      "x": -4,
      "y": 2,
      "z": -3,
      "name": "Plant_Bush_Sky",
      "support": 15
    },
    {
      "x": -4,
      "y": 6,
      "z": -3,
      "name": "Wood_Birch_Trunk_Full",
      "support": 15,
      "rotation": 1
    },
    {
      "x": -4,
      "y": 13,
      "z": -3,
      "name": "Wood_Birch_Trunk_Full",
      "support": 15,
      "rotation": 5
    },
    {
      "x": -4,
      "y": 14,
      "z": -3,
      "name": "Plant_Leaves_Aspen",
      "support": 15,
      "rotation": 1
    },
    {
      "x": -4,
      "y": 16,
      "z": -3,
      "name": "Plant_Leaves_Aspen",
      "support": 15,
      "rotation": 1
    },
    {
      "x": -4,
      "y": 17,
      "z": -3,
      "name": "Plant_Leaves_Aspen",
      "support": 15,
      "rotation": 1
    },
    {
      "x": -4,
      "y": 0,
      "z": -2,
      "name": "Wood_Birch_Trunk",
      "support": 15,
      "rotation": 1
    },
    {
      "x": -4,
      "y": 1,
      "z": -2,
      "name": "Wood_Birch_Trunk",
      "support": 15,
      "rotation": 1
    },
    {
      "x": -4,
      "y": 2,
      "z": -2,
      "name": "Wood_Birch_Trunk",
      "support": 15,
      "rotation": 1
    },
    {
      "x": -4,
      "y": 3,
      "z": -2,
      "name": "Wood_Birch_Trunk_Full",
      "support": 15,
      "rotation": 1
    },
    {
      "x": -4,
      "y": 4,
      "z": -2,
      "name": "Wood_Birch_Trunk",
      "support": 15,
      "rotation": 1
    },
    {
      "x": -4,
      "y": 5,
      "z": -2,
      "name": "Wood_Birch_Trunk",
      "support": 15,
      "rotation": 1
    },
    {
      "x": -4,
      "y": 6,
      "z": -2,
      "name": "Wood_Birch_Trunk_Full",
      "support": 15,
      "rotation": 1
    },
    {
      "x": -4,
      "y": 7,
      "z": -2,
      "name": "Plant_Leaves_Aspen",
      "support": 15,
      "rotation": 1
    },
    {
      "x": -4,
      "y": 14,
      "z": -2,
      "name": "Wood_Birch_Trunk",
      "support": 15,
      "rotation": 5
    },
    {
      "x": -4,
      "y": 16,
      "z": -2,
      "name": "Plant_Leaves_Aspen",
      "support": 15,
      "rotation": 1
    },
    {
      "x": -4,
      "y": 0,
      "z": -1,
      "name": "Rock_Marble_Brick"
    },
    {
      "x": -4,
      "y": 1,
      "z": -1,
      "name": "Rock_Marble_Brick"
    },
    {
      "x": -4,
      "y": 2,
      "z": -1,
      "name": "Wood_Birch_Trunk_Full",
      "support": 15,
      "rotation": 1
    },
    {
      "x": -4,
      "y": 3,
      "z": -1,
      "name": "Wood_Birch_Trunk",
      "support": 15,
      "rotation": 1
    },
    {
      "x": -4,
      "y": 4,
      "z": -1,
      "name": "Wood_Birch_Trunk_Full",
      "support": 15,
      "rotation": 1
    },
    {
      "x": -4,
      "y": 7,
      "z": -1,
      "name": "Plant_Leaves_Aspen",
      "support": 15,
      "rotation": 1
    },
    {
      "x": -4,
      "y": 9,
      "z": -1,
      "name": "Rock_Marble_Brick"
    },
    {
      "x": -4,
      "y": 0,
      "z": 0,
      "name": "Rock_Marble_Brick"
    },
    {
      "x": -4,
      "y": 1,
      "z": 0,
      "name": "Rock_Marble_Brick"
    },
    {
      "x": -4,
      "y": 3,
      "z": 0,
      "name": "Wood_Birch_Trunk_Full",
      "support": 15,
      "rotation": 4
    },
    {
      "x": -4,
      "y": 4,
      "z": 0,
      "name": "Rock_Marble_Brick"
    },
    {
      "x": -4,
      "y": 5,
      "z": 0,
      "name": "Rock_Marble_Brick"
    },
    {
      "x": -4,
      "y": 6,
      "z": 0,
      "name": "Rock_Marble_Brick"
    },
    {
      "x": -4,
      "y": 7,
      "z": 0,
      "name": "Rock_Marble_Brick_Smooth_Half",
      "rotation": 8
    },
    {
      "x": -4,
      "y": 8,
      "z": 0,
      "name": "Rock_Marble_Brick"
    },
    {
      "x": -4,
      "y": 9,
      "z": 0,
      "name": "Rock_Marble_Brick_Decorative"
    },
    {
      "x": -4,
      "y": 10,
      "z": 0,
      "name": "Rock_Marble_Brick_Smooth_Half"
    },
    {
      "x": -4,
      "y": 0,
      "z": 1,
      "name": "Rock_Marble_Brick"
    },
    {
      "x": -4,
      "y": 1,
      "z": 1,
      "name": "Rock_Marble_Brick"
    },
    {
      "x": -4,
      "y": 2,
      "z": 1,
      "name": "Wood_Birch_Trunk_Full",
      "support": 15
    },
    {
      "x": -4,
      "y": 3,
      "z": 1,
      "name": "Wood_Birch_Trunk_Full",
      "support": 15,
      "rotation": 4
    },
    {
      "x": -4,
      "y": 5,
      "z": 1,
      "name": "Rock_Marble_Brick_Smooth_Half"
    },
    {
      "x": -4,
      "y": 0,
      "z": 2,
      "name": "Rock_Marble_Brick"
    },
    {
      "x": -4,
      "y": 1,
      "z": 2,
      "name": "Rock_Marble_Brick"
    },
    {
      "x": -4,
      "y": 2,
      "z": 2,
      "name": "Wood_Birch_Trunk_Full",
      "support": 15
    },
    {
      "x": -4,
      "y": 5,
      "z": 2,
      "name": "Rock_Marble_Brick_Smooth_Half"
    },
    {
      "x": -4,
      "y": 0,
      "z": 3,
      "name": "Rock_Marble_Brick"
    },
    {
      "x": -4,
      "y": 1,
      "z": 3,
      "name": "Rock_Marble_Brick"
    },
    {
      "x": -4,
      "y": 5,
      "z": 3,
      "name": "Rock_Marble_Brick_Smooth_Half"
    },
    {
      "x": -4,
      "y": 0,
      "z": 4,
      "name": "Rock_Marble_Brick"
    },
    {
      "x": -4,
      "y": 1,
      "z": 4,
      "name": "Rock_Marble_Brick",
      "rotation": 1
    },
    {
      "x": -4,
      "y": 5,
      "z": 4,
      "name": "Rock_Marble_Brick_Smooth_Half"
    },
    {
      "x": -4,
      "y": 0,
      "z": 5,
      "name": "Rock_Marble_Brick"
    },
    {
      "x": -4,
      "y": 1,
      "z": 5,
      "name": "Rock_Marble_Brick",
      "rotation": 1
    },
    {
      "x": -3,
      "y": 0,
      "z": -5,
      "name": "Rock_Marble_Brick"
    },
    {
      "x": -3,
      "y": 1,
      "z": -5,
      "name": "Rock_Marble_Brick"
    },
    {
      "x": -3,
      "y": 2,
      "z": -5,
      "name": "Rock_Marble_Brick"
    },
    {
      "x": -3,
      "y": 3,
      "z": -5,
      "name": "Rock_Marble_Brick"
    },
    {
      "x": -3,
      "y": 4,
      "z": -5,
      "name": "Rock_Marble_Brick"
    },
    {
      "x": -3,
      "y": 5,
      "z": -5,
      "name": "Rock_Marble_Brick"
    },
    {
      "x": -3,
      "y": 6,
      "z": -5,
      "name": "Rock_Marble_Brick"
    },
    {
      "x": -3,
      "y": 0,
      "z": -4,
      "name": "Rock_Marble_Brick"
    },
    {
      "x": -3,
      "y": 1,
      "z": -4,
      "name": "Wood_Birch_Trunk_Full",
      "support": 15,
      "rotation": 6
    },
    {
      "x": -3,
      "y": 2,
      "z": -4,
      "name": "Rock_Marble_Brick_Stairs",
      "rotation": 3
    },
    {
      "x": -3,
      "y": 16,
      "z": -4,
      "name": "Plant_Leaves_Aspen",
      "support": 15,
      "rotation": 1
    },
    {
      "x": -3,
      "y": 17,
      "z": -4,
      "name": "Plant_Leaves_Aspen",
      "support": 15,
      "rotation": 1
    },
    {
      "x": -3,
      "y": 0,
      "z": -3,
      "name": "Rock_Marble_Brick"
    },
    {
      "x": -3,
      "y": 1,
      "z": -3,
      "name": "Wood_Birch_Trunk_Full",
      "support": 15,
      "rotation": 1
    },
    {
      "x": -3,
      "y": 14,
      "z": -3,
      "name": "Wood_Birch_Branch_Corner",
      "support": 15,
      "rotation": 2
    },
    {
      "x": -3,
      "y": 15,
      "z": -3,
      "name": "Wood_Birch_Branch_Long",
      "support": 15,
      "rotation": 1
    },
    {
      "x": -3,
      "y": 16,
      "z": -3,
      "name": "Wood_Birch_Branch_Long",
      "support": 15,
      "rotation": 1
    },
    {
      "x": -3,
      "y": 17,
      "z": -3,
      "name": "Plant_Leaves_Aspen",
      "support": 15,
      "rotation": 1
    },
    {
      "x": -3,
      "y": 0,
      "z": -2,
      "name": "Rock_Marble_Brick"
    },
    {
      "x": -3,
      "y": 1,
      "z": -2,
      "name": "Rock_Marble_SkyGrass"
    },
    {
      "x": -3,
      "y": 2,
      "z": -2,
      "name": "Rock_Marble_SkyGrass"
    },
    {
      "x": -3,
      "y": 3,
      "z": -2,
      "name": "Plant_Grass_Sky_Long",
      "support": 15
    },
    {
      "x": -3,
      "y": 4,
      "z": -2,
      "name": "Plant_Grass_Sky_Long",
      "filler": 1024
    },
    {
      "x": -3,
      "y": 14,
      "z": -2,
      "name": "Wood_Birch_Trunk_Full",
      "support": 15,
      "rotation": 5
    },
    {
      "x": -3,
      "y": 16,
      "z": -2,
      "name": "Plant_Leaves_Aspen",
      "support": 15,
      "rotation": 1
    },
    {
      "x": -3,
      "y": 0,
      "z": -1,
      "name": "Wood_Birch_Branch_Long",
      "support": 15,
      "rotation": 1
    },
    {
      "x": -3,
      "y": 1,
      "z": -1,
      "name": "Wood_Birch_Trunk",
      "support": 15,
      "rotation": 5
    },
    {
      "x": -3,
      "y": 2,
      "z": -1,
      "name": "Wood_Birch_Trunk",
      "support": 15,
      "rotation": 5
    },
    {
      "x": -3,
      "y": 4,
      "z": -1,
      "name": "Furniture_Ancient_Bookshelf",
      "rotation": 2
    },
    {
      "x": -3,
      "y": 14,
      "z": -1,
      "name": "Wood_Birch_Trunk_Full",
      "support": 15,
      "rotation": 5
    },
    {
      "x": -3,
      "y": 16,
      "z": -1,
      "name": "Plant_Leaves_Aspen",
      "support": 15,
      "rotation": 1
    },
    {
      "x": -3,
      "y": 0,
      "z": 0,
      "name": "Rock_Marble_Brick"
    },
    {
      "x": -3,
      "y": 1,
      "z": 0,
      "name": "Rock_Marble_Brick"
    },
    {
      "x": -3,
      "y": 2,
      "z": 0,
      "name": "Rock_Marble_Brick"
    },
    {
      "x": -3,
      "y": 3,
      "z": 0,
      "name": "Rock_Marble_Brick_Smooth_Half"
    },
    {
      "x": -3,
      "y": 4,
      "z": 0,
      "name": "Rock_Marble_Brick"
    },
    {
      "x": -3,
      "y": 5,
      "z": 0,
      "name": "Rock_Marble_Brick"
    },
    {
      "x": -3,
      "y": 6,
      "z": 0,
      "name": "Rock_Marble_Brick"
    },
    {
      "x": -3,
      "y": 7,
      "z": 0,
      "name": "Rock_Marble_Brick"
    },
    {
      "x": -3,
      "y": 8,
      "z": 0,
      "name": "Rock_Marble_Brick_Ornate"
    },
    {
      "x": -3,
      "y": 10,
      "z": 0,
      "name": "Rock_Marble_Brick_Smooth_Half"
    },
    {
      "x": -3,
      "y": 13,
      "z": 0,
      "name": "Wood_Birch_Trunk_Full",
      "support": 15,
      "rotation": 5
    },
    {
      "x": -3,
      "y": 16,
      "z": 0,
      "name": "Plant_Leaves_Aspen",
      "support": 15,
      "rotation": 1
    },
    {
      "x": -3,
      "y": 0,
      "z": 1,
      "name": "Rock_Marble_Brick"
    },
    {
      "x": -3,
      "y": 1,
      "z": 1,
      "name": "Rock_Marble_Brick"
    },
    {
      "x": -3,
      "y": 5,
      "z": 1,
      "name": "Rock_Marble_Brick_Smooth_Half"
    },
    {
      "x": -3,
      "y": 16,
      "z": 1,
      "name": "Plant_Leaves_Aspen",
      "support": 15,
      "rotation": 1
    },
    {
      "x": -3,
      "y": 0,
      "z": 2,
      "name": "Rock_Marble_Brick"
    },
    {
      "x": -3,
      "y": 1,
      "z": 2,
      "name": "Rock_Marble_Brick"
    },
    {
      "x": -3,
      "y": 5,
      "z": 2,
      "name": "Rock_Marble_Brick_Smooth_Half"
    },
    {
      "x": -3,
      "y": 16,
      "z": 2,
      "name": "Plant_Leaves_Aspen",
      "support": 15,
      "rotation": 1
    },
    {
      "x": -3,
      "y": 0,
      "z": 3,
      "name": "Rock_Marble_Brick"
    },
    {
      "x": -3,
      "y": 1,
      "z": 3,
      "name": "Rock_Marble_Brick"
    },
    {
      "x": -3,
      "y": 2,
      "z": 3,
      "name": "Rock_Marble_Brick_Pillar_Middle",
      "rotation": 4
    },
    {
      "x": -3,
      "y": 0,
      "z": 4,
      "name": "Rock_Marble_Brick"
    },
    {
      "x": -3,
      "y": 1,
      "z": 4,
      "name": "Rock_Marble_Brick",
      "rotation": 1
    },
    {
      "x": -3,
      "y": 2,
      "z": 4,
      "name": "Rock_Marble_Brick_Pillar_Middle",
      "rotation": 4
    },
    {
      "x": -3,
      "y": 0,
      "z": 5,
      "name": "Rock_Marble_Brick"
    },
    {
      "x": -3,
      "y": 1,
      "z": 5,
      "name": "Rock_Marble_Brick"
    },
    {
      "x": -2,
      "y": 0,
      "z": -5,
      "name": "Rock_Marble_Brick"
    },
    {
      "x": -2,
      "y": 1,
      "z": -5,
      "name": "Rock_Marble_Brick"
    },
    {
      "x": -2,
      "y": 2,
      "z": -5,
      "name": "Rock_Marble_Brick"
    },
    {
      "x": -2,
      "y": 3,
      "z": -5,
      "name": "Rock_Marble_Brick"
    },
    {
      "x": -2,
      "y": 4,
      "z": -5,
      "name": "Rock_Marble_Brick"
    },
    {
      "x": -2,
      "y": 7,
      "z": -5,
      "name": "Rock_Marble_Brick_Smooth_Half",
      "rotation": 5
    },
    {
      "x": -2,
      "y": 8,
      "z": -5,
      "name": "Rock_Marble_Brick_Stairs",
      "rotation": 11
    },
    {
      "x": -2,
      "y": 9,
      "z": -5,
      "name": "Rock_Marble_Brick_Decorative"
    },
    {
      "x": -2,
      "y": 10,
      "z": -5,
      "name": "Rock_Marble_Brick_Smooth_Half"
    },
    {
      "x": -2,
      "y": 0,
      "z": -4,
      "name": "Rock_Marble_Brick"
    },
    {
      "x": -2,
      "y": 1,
      "z": -4,
      "name": "Rock_Marble_Brick"
    },
    {
      "x": -2,
      "y": 2,
      "z": -4,
      "name": "Rock_Marble_Brick"
    },
    {
      "x": -2,
      "y": 3,
      "z": -4,
      "name": "Rock_Marble_Brick_Stairs",
      "rotation": 3
    },
    {
      "x": -2,
      "y": 9,
      "z": -4,
      "name": "Rock_Marble_Brick"
    },
    {
      "x": -2,
      "y": 16,
      "z": -4,
      "name": "Plant_Leaves_Aspen",
      "support": 15,
      "rotation": 1
    },
    {
      "x": -2,
      "y": 0,
      "z": -3,
      "name": "Rock_Marble_Brick"
    },
    {
      "x": -2,
      "y": 1,
      "z": -3,
      "name": "Wood_Birch_Trunk_Full",
      "support": 15,
      "rotation": 1
    },
    {
      "x": -2,
      "y": 9,
      "z": -3,
      "name": "Rock_Marble_Brick"
    },
    {
      "x": -2,
      "y": 16,
      "z": -3,
      "name": "Plant_Leaves_Aspen",
      "support": 15,
      "rotation": 1
    },
    {
      "x": -2,
      "y": 17,
      "z": -3,
      "name": "Plant_Leaves_Aspen",
      "support": 15,
      "rotation": 1
    },
    {
      "x": -2,
      "y": 0,
      "z": -2,
      "name": "Rock_Marble_Brick"
    },
    {
      "x": -2,
      "y": 1,
      "z": -2,
      "name": "Wood_Birch_Trunk_Full",
      "support": 15,
      "rotation": 1
    },
    {
      "x": -2,
      "y": 9,
      "z": -2,
      "name": "Rock_Marble_Brick"
    },
    {
      "x": -2,
      "y": 16,
      "z": -2,
      "name": "Plant_Leaves_Aspen",
      "support": 15,
      "rotation": 1
    },
    {
      "x": -2,
      "y": 17,
      "z": -2,
      "name": "Plant_Leaves_Aspen",
      "support": 15,
      "rotation": 1
    },
    {
      "x": -2,
      "y": 0,
      "z": -1,
      "name": "Rock_Marble_Brick"
    },
    {
      "x": -2,
      "y": 1,
      "z": -1,
      "name": "Rock_Marble_Brick"
    },
    {
      "x": -2,
      "y": 2,
      "z": -1,
      "name": "Wood_Birch_Trunk_Full",
      "support": 15,
      "rotation": 5
    },
    {
      "x": -2,
      "y": 4,
      "z": -1,
      "name": "Furniture_Ancient_Bookshelf",
      "rotation": 2
    },
    {
      "x": -2,
      "y": 5,
      "z": -1,
      "name": "Rock_Marble_Brick"
    },
    {
      "x": -2,
      "y": 9,
      "z": -1,
      "name": "Rock_Marble_Brick"
    },
    {
      "x": -2,
      "y": 14,
      "z": -1,
      "name": "Wood_Birch_Trunk_Full",
      "support": 15,
      "rotation": 5
    },
    {
      "x": -2,
      "y": 16,
      "z": -1,
      "name": "Plant_Leaves_Aspen",
      "support": 15,
      "rotation": 1
    },
    {
      "x": -2,
      "y": 0,
      "z": 0,
      "name": "Rock_Marble_Brick"
    },
    {
      "x": -2,
      "y": 1,
      "z": 0,
      "name": "Rock_Marble_Brick"
    },
    {
      "x": -2,
      "y": 2,
      "z": 0,
      "name": "Rock_Marble_Brick"
    },
    {
      "x": -2,
      "y": 4,
      "z": 0,
      "name": "Rock_Marble_Brick"
    },
    {
      "x": -2,
      "y": 5,
      "z": 0,
      "name": "Rock_Marble_Brick"
    },
    {
      "x": -2,
      "y": 8,
      "z": 0,
      "name": "Rock_Marble_Brick_Stairs",
      "rotation": 11
    },
    {
      "x": -2,
      "y": 13,
      "z": 0,
      "name": "Wood_Birch_Trunk_Full",
      "support": 15,
      "rotation": 5
    },
    {
      "x": -2,
      "y": 14,
      "z": 0,
      "name": "Wood_Birch_Trunk_Full",
      "support": 15,
      "rotation": 5
    },
    {
      "x": -2,
      "y": 16,
      "z": 0,
      "name": "Plant_Leaves_Aspen",
      "support": 15,
      "rotation": 1
    },
    {
      "x": -2,
      "y": 0,
      "z": 1,
      "name": "Rock_Marble_Brick"
    },
    {
      "x": -2,
      "y": 1,
      "z": 1,
      "name": "Rock_Marble_Brick"
    },
    {
      "x": -2,
      "y": 5,
      "z": 1,
      "name": "Rock_Marble_Brick_Smooth_Half"
    },
    {
      "x": -2,
      "y": 13,
      "z": 1,
      "name": "Wood_Birch_Trunk_Full",
      "support": 15,
      "rotation": 5
    },
    {
      "x": -2,
      "y": 16,
      "z": 1,
      "name": "Plant_Leaves_Aspen",
      "support": 15,
      "rotation": 1
    },
    {
      "x": -2,
      "y": 0,
      "z": 2,
      "name": "Rock_Marble_Brick"
    },
    {
      "x": -2,
      "y": 1,
      "z": 2,
      "name": "Rock_Marble_Brick_Smooth_Half"
    },
    {
      "x": -2,
      "y": 16,
      "z": 2,
      "name": "Plant_Leaves_Aspen",
      "support": 15,
      "rotation": 1
    },
    {
      "x": -2,
      "y": 17,
      "z": 2,
      "name": "Plant_Leaves_Aspen",
      "support": 15,
      "rotation": 1
    },
    {
      "x": -2,
      "y": 0,
      "z": 3,
      "name": "Rock_Marble_Brick"
    },
    {
      "x": -2,
      "y": 1,
      "z": 3,
      "name": "Rock_Marble_Brick"
    },
    {
      "x": -2,
      "y": 16,
      "z": 3,
      "name": "Plant_Leaves_Aspen",
      "support": 15,
      "rotation": 1
    },
    {
      "x": -2,
      "y": 0,
      "z": 4,
      "name": "Rock_Marble_Brick"
    },
    {
      "x": -2,
      "y": 1,
      "z": 4,
      "name": "Rock_Marble_Brick",
      "rotation": 1
    },
    {
      "x": -2,
      "y": 0,
      "z": 5,
      "name": "Rock_Marble_Brick"
    },
    {
      "x": -2,
      "y": 1,
      "z": 5,
      "name": "Rock_Marble_Brick",
      "rotation": 1
    },
    {
      "x": -1,
      "y": 0,
      "z": -5,
      "name": "Rock_Marble_Brick"
    },
    {
      "x": -1,
      "y": 1,
      "z": -5,
      "name": "Rock_Marble_Brick"
    },
    {
      "x": -1,
      "y": 2,
      "z": -5,
      "name": "Rock_Marble_Brick"
    },
    {
      "x": -1,
      "y": 3,
      "z": -5,
      "name": "Rock_Marble_Brick"
    },
    {
      "x": -1,
      "y": 4,
      "z": -5,
      "name": "Rock_Marble_Brick"
    },
    {
      "x": -1,
      "y": 5,
      "z": -5,
      "name": "Rock_Marble_Brick_Decorative"
    },
    {
      "x": -1,
      "y": 7,
      "z": -5,
      "name": "Rock_Marble_Brick_Smooth_Half",
      "rotation": 7
    },
    {
      "x": -1,
      "y": 8,
      "z": -5,
      "name": "Rock_Marble_Brick_Stairs",
      "rotation": 9
    },
    {
      "x": -1,
      "y": 9,
      "z": -5,
      "name": "Rock_Marble_Brick_Decorative"
    },
    {
      "x": -1,
      "y": 10,
      "z": -5,
      "name": "Rock_Marble_Brick_Smooth_Half"
    },
    {
      "x": -1,
      "y": 0,
      "z": -4,
      "name": "Wood_Birch_Trunk",
      "support": 15,
      "rotation": 1
    },
    {
      "x": -1,
      "y": 1,
      "z": -4,
      "name": "Wood_Birch_Trunk_Full",
      "support": 15,
      "rotation": 1
    },
    {
      "x": -1,
      "y": 2,
      "z": -4,
      "name": "Rock_Marble_SkyGrass"
    },
    {
      "x": -1,
      "y": 3,
      "z": -4,
      "name": "Plant_Bush_Sky",
      "support": 15
    },
    {
      "x": -1,
      "y": 9,
      "z": -4,
      "name": "Rock_Marble_Brick"
    },
    {
      "x": -1,
      "y": 0,
      "z": -3,
      "name": "Rock_Marble_Brick"
    },
    {
      "x": -1,
      "y": 1,
      "z": -3,
      "name": "Wood_Birch_Trunk",
      "support": 15,
      "rotation": 6
    },
    {
      "x": -1,
      "y": 9,
      "z": -3,
      "name": "Rock_Marble_Brick"
    },
    {
      "x": -1,
      "y": 16,
      "z": -3,
      "name": "Plant_Leaves_Aspen",
      "support": 15,
      "rotation": 1
    },
    {
      "x": -1,
      "y": 0,
      "z": -2,
      "name": "Rock_Marble_Brick"
    },
    {
      "x": -1,
      "y": 1,
      "z": -2,
      "name": "Wood_Birch_Trunk_Full",
      "support": 15,
      "rotation": 6
    },
    {
      "x": -1,
      "y": 9,
      "z": -2,
      "name": "Rock_Marble_Brick"
    },
    {
      "x": -1,
      "y": 10,
      "z": -2,
      "name": "Rock_Marble_SkyGrass"
    },
    {
      "x": -1,
      "y": 16,
      "z": -2,
      "name": "Plant_Leaves_Aspen",
      "support": 15,
      "rotation": 1
    },
    {
      "x": -1,
      "y": 0,
      "z": -1,
      "name": "Rock_Marble_Brick"
    },
    {
      "x": -1,
      "y": 1,
      "z": -1,
      "name": "Rock_Marble_Brick"
    },
    {
      "x": -1,
      "y": 2,
      "z": -1,
      "name": "Furniture_Temple_Light_Pot"
    },
    {
      "x": -1,
      "y": 4,
      "z": -1,
      "name": "Furniture_Ancient_Bookshelf",
      "rotation": 2
    },
    {
      "x": -1,
      "y": 5,
      "z": -1,
      "name": "Rock_Marble_Brick"
    },
    {
      "x": -1,
      "y": 9,
      "z": -1,
      "name": "Rock_Marble_Brick"
    },
    {
      "x": -1,
      "y": 10,
      "z": -1,
      "name": "Rock_Marble_SkyGrass"
    },
    {
      "x": -1,
      "y": 11,
      "z": -1,
      "name": "Plant_Grass_Sky_Long",
      "support": 15
    },
    {
      "x": -1,
      "y": 12,
      "z": -1,
      "name": "Plant_Grass_Sky_Long",
      "filler": 1024
    },
    {
      "x": -1,
      "y": 16,
      "z": -1,
      "name": "Plant_Leaves_Aspen",
      "support": 15,
      "rotation": 1
    },
    {
      "x": -1,
      "y": 0,
      "z": 0,
      "name": "Rock_Marble_Brick"
    },
    {
      "x": -1,
      "y": 1,
      "z": 0,
      "name": "Rock_Marble_Brick"
    },
    {
      "x": -1,
      "y": 2,
      "z": 0,
      "name": "Rock_Marble_Brick"
    },
    {
      "x": -1,
      "y": 3,
      "z": 0,
      "name": "Rock_Marble_Brick"
    },
    {
      "x": -1,
      "y": 4,
      "z": 0,
      "name": "Rock_Marble_Brick"
    },
    {
      "x": -1,
      "y": 5,
      "z": 0,
      "name": "Rock_Marble_Brick"
    },
    {
      "x": -1,
      "y": 8,
      "z": 0,
      "name": "Rock_Marble_Brick_Stairs",
      "rotation": 9
    },
    {
      "x": -1,
      "y": 9,
      "z": 0,
      "name": "Rock_Marble_Brick_Decorative"
    },
    {
      "x": -1,
      "y": 10,
      "z": 0,
      "name": "Rock_Marble_Brick_Smooth_Half"
    },
    {
      "x": -1,
      "y": 13,
      "z": 0,
      "name": "Wood_Birch_Trunk_Full",
      "support": 15,
      "rotation": 5
    },
    {
      "x": -1,
      "y": 14,
      "z": 0,
      "name": "Wood_Birch_Branch_Corner",
      "support": 15,
      "rotation": 1
    },
    {
      "x": -1,
      "y": 15,
      "z": 0,
      "name": "Wood_Birch_Branch_Corner",
      "support": 15,
      "rotation": 34
    },
    {
      "x": -1,
      "y": 16,
      "z": 0,
      "name": "Plant_Leaves_Aspen",
      "support": 15,
      "rotation": 1
    },
    {
      "x": -1,
      "y": 0,
      "z": 1,
      "name": "Rock_Marble_Brick"
    },
    {
      "x": -1,
      "y": 1,
      "z": 1,
      "name": "Rock_Marble_Brick"
    },
    {
      "x": -1,
      "y": 5,
      "z": 1,
      "name": "Rock_Marble_Brick_Smooth_Half"
    },
    {
      "x": -1,
      "y": 11,
      "z": 1,
      "name": "Wood_Birch_Trunk",
      "support": 15,
      "rotation": 1
    },
    {
      "x": -1,
      "y": 12,
      "z": 1,
      "name": "Wood_Birch_Trunk",
      "support": 15,
      "rotation": 1
    },
    {
      "x": -1,
      "y": 13,
      "z": 1,
      "name": "Wood_Birch_Trunk_Full",
      "support": 15,
      "rotation": 5
    },
    {
      "x": -1,
      "y": 15,
      "z": 1,
      "name": "Wood_Birch_Branch_Long",
      "support": 15,
      "rotation": 6
    },
    {
      "x": -1,
      "y": 16,
      "z": 1,
      "name": "Plant_Leaves_Aspen",
      "support": 15,
      "rotation": 1
    },
    {
      "x": -1,
      "y": 17,
      "z": 1,
      "name": "Plant_Leaves_Aspen",
      "support": 15,
      "rotation": 1
    },
    {
      "x": -1,
      "y": 0,
      "z": 2,
      "name": "Rock_Marble_Brick"
    },
    {
      "x": -1,
      "y": 1,
      "z": 2,
      "name": "Rock_Marble_Brick"
    },
    {
      "x": -1,
      "y": 5,
      "z": 2,
      "name": "Rock_Marble_Brick_Smooth_Half"
    },
    {
      "x": -1,
      "y": 15,
      "z": 2,
      "name": "Wood_Birch_Branch_Corner",
      "support": 15
    },
    {
      "x": -1,
      "y": 16,
      "z": 2,
      "name": "Wood_Birch_Branch_Corner",
      "support": 15,
      "rotation": 35
    },
    {
      "x": -1,
      "y": 17,
      "z": 2,
      "name": "Plant_Leaves_Aspen",
      "support": 15,
      "rotation": 1
    },
    {
      "x": -1,
      "y": 0,
      "z": 3,
      "name": "Rock_Marble_Brick"
    },
    {
      "x": -1,
      "y": 1,
      "z": 3,
      "name": "Rock_Marble_Brick"
    },
    {
      "x": -1,
      "y": 14,
      "z": 3,
      "name": "Plant_Leaves_Aspen",
      "support": 15,
      "rotation": 1
    },
    {
      "x": -1,
      "y": 15,
      "z": 3,
      "name": "Plant_Leaves_Aspen",
      "support": 15,
      "rotation": 1
    },
    {
      "x": -1,
      "y": 16,
      "z": 3,
      "name": "Plant_Leaves_Aspen",
      "support": 15,
      "rotation": 1
    },
    {
      "x": -1,
      "y": 17,
      "z": 3,
      "name": "Plant_Leaves_Aspen",
      "support": 15,
      "rotation": 1
    },
    {
      "x": -1,
      "y": 0,
      "z": 4,
      "name": "Rock_Marble_Brick"
    },
    {
      "x": -1,
      "y": 1,
      "z": 4,
      "name": "Rock_Marble_Brick_Smooth_Half"
    },
    {
      "x": -1,
      "y": 0,
      "z": 5,
      "name": "Rock_Marble_Brick"
    },
    {
      "x": -1,
      "y": 1,
      "z": 5,
      "name": "Rock_Marble_Brick",
      "rotation": 1
    },
    {
      "x": 0,
      "y": 0,
      "z": -5,
      "name": "Rock_Marble_Brick"
    },
    {
      "x": 0,
      "y": 1,
      "z": -5,
      "name": "Rock_Marble_Brick"
    },
    {
      "x": 0,
      "y": 2,
      "z": -5,
      "name": "Rock_Marble_Brick"
    },
    {
      "x": 0,
      "y": 3,
      "z": -5,
      "name": "Rock_Marble_Brick"
    },
    {
      "x": 0,
      "y": 5,
      "z": -5,
      "name": "Rock_Marble_Brick"
    },
    {
      "x": 0,
      "y": 6,
      "z": -5,
      "name": "Rock_Marble_Brick"
    },
    {
      "x": 0,
      "y": 7,
      "z": -5,
      "name": "Rock_Marble_Brick_Smooth_Half",
      "rotation": 8
    },
    {
      "x": 0,
      "y": 8,
      "z": -5,
      "name": "Rock_Marble_Brick"
    },
    {
      "x": 0,
      "y": 9,
      "z": -5,
      "name": "Rock_Marble_Brick_Decorative"
    },
    {
      "x": 0,
      "y": 10,
      "z": -5,
      "name": "Rock_Marble_Brick_Smooth_Half"
    },
    {
      "x": 0,
      "y": 0,
      "z": -4,
      "name": "Rock_Marble_Brick"
    },
    {
      "x": 0,
      "y": 1,
      "z": -4,
      "name": "Rock_Marble_Brick"
    },
    {
      "x": 0,
      "y": 2,
      "z": -4,
      "name": "Rock_Marble_SkyGrass"
    },
    {
      "x": 0,
      "y": 3,
      "z": -4,
      "name": "Plant_Grass_Sky",
      "support": 15
    },
    {
      "x": 0,
      "y": 9,
      "z": -4,
      "name": "Rock_Marble_Brick"
    },
    {
      "x": 0,
      "y": 0,
      "z": -3,
      "name": "Rock_Marble_Brick"
    },
    {
      "x": 0,
      "y": 1,
      "z": -3,
      "name": "Rock_Marble_SkyGrass"
    },
    {
      "x": 0,
      "y": 2,
      "z": -3,
      "name": "Plant_Grass_Sky",
      "support": 15
    },
    {
      "x": 0,
      "y": 5,
      "z": -3,
      "name": "Rock_Marble_Brick_Stairs",
      "rotation": 3
    },
    {
      "x": 0,
      "y": 9,
      "z": -3,
      "name": "Rock_Marble_Brick"
    },
    {
      "x": 0,
      "y": 10,
      "z": -3,
      "name": "Rock_Marble_SkyGrass"
    },
    {
      "x": 0,
      "y": 11,
      "z": -3,
      "name": "Plant_Grass_Sky_Long",
      "support": 15
    },
    {
      "x": 0,
      "y": 12,
      "z": -3,
      "name": "Plant_Grass_Sky_Long",
      "filler": 1024
    },
    {
      "x": 0,
      "y": 0,
      "z": -2,
      "name": "Rock_Marble_Brick"
    },
    {
      "x": 0,
      "y": 1,
      "z": -2,
      "name": "Rock_Marble_SkyGrass"
    },
    {
      "x": 0,
      "y": 2,
      "z": -2,
      "name": "Plant_Grass_Sky",
      "support": 15
    },
    {
      "x": 0,
      "y": 5,
      "z": -2,
      "name": "Rock_Marble_Brick"
    },
    {
      "x": 0,
      "y": 9,
      "z": -2,
      "name": "Rock_Marble_Brick"
    },
    {
      "x": 0,
      "y": 10,
      "z": -2,
      "name": "Rock_Marble_SkyGrass"
    },
    {
      "x": 0,
      "y": 11,
      "z": -2,
      "name": "Plant_Bush_Sky",
      "support": 15
    },
    {
      "x": 0,
      "y": 0,
      "z": -1,
      "name": "Rock_Marble_Brick"
    },
    {
      "x": 0,
      "y": 1,
      "z": -1,
      "name": "Rock_Marble_Brick"
    },
    {
      "x": 0,
      "y": 5,
      "z": -1,
      "name": "Rock_Marble_Brick"
    },
    {
      "x": 0,
      "y": 6,
      "z": -1,
      "name": "Furniture_Temple_Light_Chest_Small",
      "components": {
        "Components": {
          "PlacedByInteraction": {
            "WhoPlacedUuid": {
              "$binary": "rmwkrpH8RVykTc7XnK4YBA==",
              "$type": "04"
            }
          },
          "ItemContainerBlock": {
            "ItemContainer": {
              "Capacity": 18,
              "Items": {}
            },
            "Capacity": 18
          }
        }
      },
      "rotation": 3
    },
    {
      "x": 0,
      "y": 9,
      "z": -1,
      "name": "Rock_Marble_Brick"
    },
    {
      "x": 0,
      "y": 10,
      "z": -1,
      "name": "Rock_Marble_SkyGrass"
    },
    {
      "x": 0,
      "y": 16,
      "z": -1,
      "name": "Plant_Leaves_Aspen",
      "support": 15,
      "rotation": 1
    },
    {
      "x": 0,
      "y": 0,
      "z": 0,
      "name": "Rock_Marble_Brick"
    },
    {
      "x": 0,
      "y": 1,
      "z": 0,
      "name": "Rock_Marble_Brick"
    },
    {
      "x": 0,
      "y": 2,
      "z": 0,
      "name": "Rock_Marble_Brick"
    },
    {
      "x": 0,
      "y": 4,
      "z": 0,
      "name": "Rock_Marble_Brick_Ornate"
    },
    {
      "x": 0,
      "y": 5,
      "z": 0,
      "name": "Rock_Marble_Brick"
    },
    {
      "x": 0,
      "y": 6,
      "z": 0,
      "name": "Rock_Marble_Brick"
    },
    {
      "x": 0,
      "y": 7,
      "z": 0,
      "name": "Rock_Marble_Brick"
    },
    {
      "x": 0,
      "y": 8,
      "z": 0,
      "name": "Rock_Marble_Brick_Ornate"
    },
    {
      "x": 0,
      "y": 9,
      "z": 0,
      "name": "Rock_Marble_Brick_Decorative"
    },
    {
      "x": 0,
      "y": 10,
      "z": 0,
      "name": "Rock_Marble_Brick_Smooth_Half"
    },
    {
      "x": 0,
      "y": 12,
      "z": 0,
      "name": "Plant_Leaves_Aspen",
      "support": 15,
      "rotation": 1
    },
    {
      "x": 0,
      "y": 16,
      "z": 0,
      "name": "Plant_Leaves_Aspen",
      "support": 15,
      "rotation": 1
    },
    {
      "x": 0,
      "y": 0,
      "z": 1,
      "name": "Rock_Marble_Brick"
    },
    {
      "x": 0,
      "y": 1,
      "z": 1,
      "name": "Rock_Marble_Brick_Smooth_Half"
    },
    {
      "x": 0,
      "y": 5,
      "z": 1,
      "name": "Rock_Marble_Brick_Smooth_Half"
    },
    {
      "x": 0,
      "y": 11,
      "z": 1,
      "name": "Wood_Birch_Branch_Long",
      "support": 15,
      "rotation": 5
    },
    {
      "x": 0,
      "y": 12,
      "z": 1,
      "name": "Plant_Leaves_Aspen",
      "support": 15,
      "rotation": 1
    },
    {
      "x": 0,
      "y": 13,
      "z": 1,
      "name": "Plant_Leaves_Aspen",
      "support": 15,
      "rotation": 1
    },
    {
      "x": 0,
      "y": 16,
      "z": 1,
      "name": "Plant_Leaves_Aspen",
      "support": 15,
      "rotation": 1
    },
    {
      "x": 0,
      "y": 17,
      "z": 1,
      "name": "Plant_Leaves_Aspen",
      "support": 15,
      "rotation": 1
    },
    {
      "x": 0,
      "y": 0,
      "z": 2,
      "name": "Rock_Marble_Brick"
    },
    {
      "x": 0,
      "y": 1,
      "z": 2,
      "name": "Rock_Marble_Brick_Smooth_Half"
    },
    {
      "x": 0,
      "y": 5,
      "z": 2,
      "name": "Rock_Marble_Brick_Smooth_Half"
    },
    {
      "x": 0,
      "y": 12,
      "z": 2,
      "name": "Plant_Leaves_Aspen",
      "support": 15,
      "rotation": 1
    },
    {
      "x": 0,
      "y": 15,
      "z": 2,
      "name": "Plant_Leaves_Aspen",
      "support": 15,
      "rotation": 1
    },
    {
      "x": 0,
      "y": 16,
      "z": 2,
      "name": "Wood_Birch_Branch_Corner",
      "support": 15,
      "rotation": 1
    },
    {
      "x": 0,
      "y": 17,
      "z": 2,
      "name": "Plant_Leaves_Aspen",
      "support": 15,
      "rotation": 1
    },
    {
      "x": 0,
      "y": 0,
      "z": 3,
      "name": "Rock_Marble_Brick"
    },
    {
      "x": 0,
      "y": 1,
      "z": 3,
      "name": "Rock_Marble_Brick"
    },
    {
      "x": 0,
      "y": 5,
      "z": 3,
      "name": "Rock_Marble_Brick_Smooth_Half"
    },
    {
      "x": 0,
      "y": 16,
      "z": 3,
      "name": "Plant_Leaves_Aspen",
      "support": 15,
      "rotation": 1
    },
    {
      "x": 0,
      "y": 17,
      "z": 3,
      "name": "Plant_Leaves_Aspen",
      "support": 15,
      "rotation": 1
    },
    {
      "x": 0,
      "y": 0,
      "z": 4,
      "name": "Rock_Marble_Brick"
    },
    {
      "x": 0,
      "y": 1,
      "z": 4,
      "name": "Rock_Marble_Brick",
      "rotation": 1
    },
    {
      "x": 0,
      "y": 16,
      "z": 4,
      "name": "Plant_Leaves_Aspen",
      "support": 15,
      "rotation": 1
    },
    {
      "x": 0,
      "y": 0,
      "z": 5,
      "name": "Rock_Marble_Brick"
    },
    {
      "x": 0,
      "y": 1,
      "z": 5,
      "name": "Rock_Marble_Brick",
      "rotation": 1
    },
    {
      "x": 1,
      "y": 0,
      "z": -5,
      "name": "Rock_Marble_Brick"
    },
    {
      "x": 1,
      "y": 1,
      "z": -5,
      "name": "Rock_Marble_Brick"
    },
    {
      "x": 1,
      "y": 2,
      "z": -5,
      "name": "Rock_Marble_Brick"
    },
    {
      "x": 1,
      "y": 3,
      "z": -5,
      "name": "Rock_Marble_Brick"
    },
    {
      "x": 1,
      "y": 5,
      "z": -5,
      "name": "Rock_Marble_Brick"
    },
    {
      "x": 1,
      "y": 6,
      "z": -5,
      "name": "Rock_Marble_Brick"
    },
    {
      "x": 1,
      "y": 7,
      "z": -5,
      "name": "Rock_Marble_Brick"
    },
    {
      "x": 1,
      "y": 8,
      "z": -5,
      "name": "Rock_Marble_Brick"
    },
    {
      "x": 1,
      "y": 9,
      "z": -5,
      "name": "Rock_Marble_Brick_Decorative"
    },
    {
      "x": 1,
      "y": 10,
      "z": -5,
      "name": "Rock_Marble_Brick_Smooth_Half"
    },
    {
      "x": 1,
      "y": 0,
      "z": -4,
      "name": "Rock_Marble_Brick"
    },
    {
      "x": 1,
      "y": 1,
      "z": -4,
      "name": "Rock_Marble_Brick"
    },
    {
      "x": 1,
      "y": 2,
      "z": -4,
      "name": "Rock_Marble_Brick"
    },
    {
      "x": 1,
      "y": 3,
      "z": -4,
      "name": "Rock_Marble_Brick"
    },
    {
      "x": 1,
      "y": 4,
      "z": -4,
      "name": "Rock_Marble_Brick"
    },
    {
      "x": 1,
      "y": 5,
      "z": -4,
      "name": "Rock_Marble_Brick"
    },
    {
      "x": 1,
      "y": 6,
      "z": -4,
      "name": "Rock_Marble_Brick_Stairs",
      "rotation": 3
    },
    {
      "x": 1,
      "y": 9,
      "z": -4,
      "name": "Rock_Marble_Brick_Decorative"
    },
    {
      "x": 1,
      "y": 10,
      "z": -4,
      "name": "Rock_Marble_Brick_Smooth_Half"
    },
    {
      "x": 1,
      "y": 0,
      "z": -3,
      "name": "Rock_Marble_Brick"
    },
    {
      "x": 1,
      "y": 1,
      "z": -3,
      "name": "Rock_Marble_Brick"
    },
    {
      "x": 1,
      "y": 2,
      "z": -3,
      "name": "Rock_Marble_Brick"
    },
    {
      "x": 1,
      "y": 5,
      "z": -3,
      "name": "Rock_Marble_Brick"
    },
    {
      "x": 1,
      "y": 6,
      "z": -3,
      "name": "Rock_Marble_Brick_Stairs",
      "rotation": 3
    },
    {
      "x": 1,
      "y": 9,
      "z": -3,
      "name": "Rock_Marble_Brick_Decorative"
    },
    {
      "x": 1,
      "y": 10,
      "z": -3,
      "name": "Rock_Marble_Brick_Smooth_Half"
    },
    {
      "x": 1,
      "y": 0,
      "z": -2,
      "name": "Rock_Marble_Brick"
    },
    {
      "x": 1,
      "y": 1,
      "z": -2,
      "name": "Rock_Marble_SkyGrass"
    },
    {
      "x": 1,
      "y": 2,
      "z": -2,
      "name": "Plant_Bush_Sky",
      "support": 15
    },
    {
      "x": 1,
      "y": 5,
      "z": -2,
      "name": "Rock_Marble_Brick"
    },
    {
      "x": 1,
      "y": 6,
      "z": -2,
      "name": "Rock_Marble_Brick"
    },
    {
      "x": 1,
      "y": 7,
      "z": -2,
      "name": "Rock_Marble_Brick"
    },
    {
      "x": 1,
      "y": 8,
      "z": -2,
      "name": "Rock_Marble_Brick"
    },
    {
      "x": 1,
      "y": 9,
      "z": -2,
      "name": "Rock_Marble_Brick_Decorative"
    },
    {
      "x": 1,
      "y": 10,
      "z": -2,
      "name": "Rock_Marble_Brick_Smooth_Half"
    },
    {
      "x": 1,
      "y": 0,
      "z": -1,
      "name": "Rock_Marble_Brick"
    },
    {
      "x": 1,
      "y": 1,
      "z": -1,
      "name": "Rock_Marble_Brick"
    },
    {
      "x": 1,
      "y": 5,
      "z": -1,
      "name": "Rock_Marble_Brick"
    },
    {
      "x": 1,
      "y": 6,
      "z": -1,
      "name": "Rock_Marble_Brick"
    },
    {
      "x": 1,
      "y": 7,
      "z": -1,
      "name": "Rock_Marble_Brick"
    },
    {
      "x": 1,
      "y": 8,
      "z": -1,
      "name": "Rock_Marble_Brick_Smooth_Half",
      "rotation": 8
    },
    {
      "x": 1,
      "y": 9,
      "z": -1,
      "name": "Rock_Marble_Brick_Decorative"
    },
    {
      "x": 1,
      "y": 10,
      "z": -1,
      "name": "Rock_Marble_Brick_Smooth_Half"
    },
    {
      "x": 1,
      "y": 0,
      "z": 0,
      "name": "Rock_Marble_Brick"
    },
    {
      "x": 1,
      "y": 1,
      "z": 0,
      "name": "Rock_Marble_Brick"
    },
    {
      "x": 1,
      "y": 2,
      "z": 0,
      "name": "Furniture_Temple_Light_Door"
    },
    {
      "x": 1,
      "y": 3,
      "z": 0,
      "name": "Furniture_Temple_Light_Door",
      "filler": 1024
    },
    {
      "x": 1,
      "y": 5,
      "z": 0,
      "name": "Rock_Marble_Brick"
    },
    {
      "x": 1,
      "y": 6,
      "z": 0,
      "name": "Rock_Marble_Brick"
    },
    {
      "x": 1,
      "y": 7,
      "z": 0,
      "name": "Rock_Marble_Brick"
    },
    {
      "x": 1,
      "y": 8,
      "z": 0,
      "name": "Rock_Marble_Brick"
    },
    {
      "x": 1,
      "y": 9,
      "z": 0,
      "name": "Rock_Marble_Brick_Decorative"
    },
    {
      "x": 1,
      "y": 10,
      "z": 0,
      "name": "Rock_Marble_Brick_Smooth_Half"
    },
    {
      "x": 1,
      "y": 12,
      "z": 0,
      "name": "Plant_Leaves_Aspen",
      "support": 15,
      "rotation": 1
    },
    {
      "x": 1,
      "y": 0,
      "z": 1,
      "name": "Rock_Marble_Brick"
    },
    {
      "x": 1,
      "y": 1,
      "z": 1,
      "name": "Rock_Marble_Brick_Smooth_Half"
    },
    {
      "x": 1,
      "y": 5,
      "z": 1,
      "name": "Rock_Marble_Brick_Smooth_Half"
    },
    {
      "x": 1,
      "y": 11,
      "z": 1,
      "name": "Wood_Birch_Branch_Corner",
      "support": 15,
      "rotation": 1
    },
    {
      "x": 1,
      "y": 12,
      "z": 1,
      "name": "Wood_Birch_Branch_Long",
      "support": 15,
      "rotation": 1
    },
    {
      "x": 1,
      "y": 13,
      "z": 1,
      "name": "Plant_Leaves_Aspen",
      "support": 15,
      "rotation": 1
    },
    {
      "x": 1,
      "y": 16,
      "z": 1,
      "name": "Plant_Leaves_Aspen",
      "support": 15,
      "rotation": 1
    },
    {
      "x": 1,
      "y": 0,
      "z": 2,
      "name": "Rock_Marble_Brick"
    },
    {
      "x": 1,
      "y": 5,
      "z": 2,
      "name": "Rock_Marble_Brick_Smooth_Half"
    },
    {
      "x": 1,
      "y": 12,
      "z": 2,
      "name": "Plant_Leaves_Aspen",
      "support": 15,
      "rotation": 1
    },
    {
      "x": 1,
      "y": 16,
      "z": 2,
      "name": "Plant_Leaves_Aspen",
      "support": 15,
      "rotation": 1
    },
    {
      "x": 1,
      "y": 17,
      "z": 2,
      "name": "Plant_Leaves_Aspen",
      "support": 15,
      "rotation": 1
    },
    {
      "x": 1,
      "y": 0,
      "z": 3,
      "name": "Rock_Marble_Brick"
    },
    {
      "x": 1,
      "y": 1,
      "z": 3,
      "name": "Rock_Marble_Brick"
    },
    {
      "x": 1,
      "y": 5,
      "z": 3,
      "name": "Rock_Marble_Brick_Smooth_Half"
    },
    {
      "x": 1,
      "y": 16,
      "z": 3,
      "name": "Plant_Leaves_Aspen",
      "support": 15,
      "rotation": 1
    },
    {
      "x": 1,
      "y": 17,
      "z": 3,
      "name": "Plant_Leaves_Aspen",
      "support": 15,
      "rotation": 1
    },
    {
      "x": 1,
      "y": 0,
      "z": 4,
      "name": "Rock_Marble_Brick"
    },
    {
      "x": 1,
      "y": 1,
      "z": 4,
      "name": "Rock_Marble_Brick",
      "rotation": 1
    },
    {
      "x": 1,
      "y": 5,
      "z": 4,
      "name": "Rock_Marble_Brick_Smooth_Half"
    },
    {
      "x": 1,
      "y": 16,
      "z": 4,
      "name": "Plant_Leaves_Aspen",
      "support": 15,
      "rotation": 1
    },
    {
      "x": 1,
      "y": 0,
      "z": 5,
      "name": "Rock_Marble_Brick"
    },
    {
      "x": 1,
      "y": 1,
      "z": 5,
      "name": "Rock_Marble_Brick",
      "rotation": 1
    },
    {
      "x": 1,
      "y": 5,
      "z": 5,
      "name": "Rock_Marble_Brick_Decorative"
    },
    {
      "x": 2,
      "y": 0,
      "z": -5,
      "name": "Rock_Marble_Brick"
    },
    {
      "x": 2,
      "y": 1,
      "z": -5,
      "name": "Rock_Marble_Brick"
    },
    {
      "x": 2,
      "y": 2,
      "z": -5,
      "name": "Rock_Marble_Brick_Decorative"
    },
    {
      "x": 2,
      "y": 3,
      "z": -5,
      "name": "Rock_Marble_Brick_Smooth_Half"
    },
    {
      "x": 2,
      "y": 5,
      "z": -5,
      "name": "Rock_Marble_Brick"
    },
    {
      "x": 2,
      "y": 6,
      "z": -5,
      "name": "Rock_Marble_Brick"
    },
    {
      "x": 2,
      "y": 7,
      "z": -5,
      "name": "Rock_Marble_Brick_Smooth_Half"
    },
    {
      "x": 2,
      "y": 0,
      "z": -4,
      "name": "Rock_Marble_Brick"
    },
    {
      "x": 2,
      "y": 1,
      "z": -4,
      "name": "Rock_Marble_Brick"
    },
    {
      "x": 2,
      "y": 5,
      "z": -4,
      "name": "Rock_Marble_Brick"
    },
    {
      "x": 2,
      "y": 6,
      "z": -4,
      "name": "Rock_Marble_Brick"
    },
    {
      "x": 2,
      "y": 0,
      "z": -3,
      "name": "Rock_Marble_Brick"
    },
    {
      "x": 2,
      "y": 1,
      "z": -3,
      "name": "Rock_Marble_Brick"
    },
    {
      "x": 2,
      "y": 2,
      "z": -3,
      "name": "Furniture_Ancient_Chair",
      "rotation": 1
    },
    {
      "x": 2,
      "y": 5,
      "z": -3,
      "name": "Rock_Marble_Brick"
    },
    {
      "x": 2,
      "y": 6,
      "z": -3,
      "name": "Rock_Marble_Brick"
    },
    {
      "x": 2,
      "y": 0,
      "z": -2,
      "name": "Rock_Marble_Brick"
    },
    {
      "x": 2,
      "y": 1,
      "z": -2,
      "name": "Rock_Marble_Brick"
    },
    {
      "x": 2,
      "y": 5,
      "z": -2,
      "name": "Rock_Marble_Brick"
    },
    {
      "x": 2,
      "y": 6,
      "z": -2,
      "name": "Rock_Marble_Brick"
    },
    {
      "x": 2,
      "y": 7,
      "z": -2,
      "name": "Furniture_Ancient_Chair",
      "rotation": 1
    },
    {
      "x": 2,
      "y": 0,
      "z": -1,
      "name": "Rock_Marble_Brick"
    },
    {
      "x": 2,
      "y": 1,
      "z": -1,
      "name": "Rock_Marble_Brick"
    },
    {
      "x": 2,
      "y": 5,
      "z": -1,
      "name": "Rock_Marble_Brick"
    },
    {
      "x": 2,
      "y": 6,
      "z": -1,
      "name": "Rock_Marble_Brick"
    },
    {
      "x": 2,
      "y": 0,
      "z": 0,
      "name": "Rock_Marble_Brick"
    },
    {
      "x": 2,
      "y": 1,
      "z": 0,
      "name": "Rock_Marble_Brick"
    },
    {
      "x": 2,
      "y": 4,
      "z": 0,
      "name": "Rock_Marble_Brick_Ornate"
    },
    {
      "x": 2,
      "y": 5,
      "z": 0,
      "name": "Rock_Marble_Brick"
    },
    {
      "x": 2,
      "y": 6,
      "z": 0,
      "name": "Rock_Marble_Brick_Stairs"
    },
    {
      "x": 2,
      "y": 12,
      "z": 0,
      "name": "Plant_Leaves_Aspen",
      "support": 15,
      "rotation": 1
    },
    {
      "x": 2,
      "y": 0,
      "z": 1,
      "name": "Rock_Marble_Brick"
    },
    {
      "x": 2,
      "y": 1,
      "z": 1,
      "name": "Rock_Marble_Brick"
    },
    {
      "x": 2,
      "y": 5,
      "z": 1,
      "name": "Rock_Marble_Brick_Stairs"
    },
    {
      "x": 2,
      "y": 12,
      "z": 1,
      "name": "Plant_Leaves_Aspen",
      "support": 15,
      "rotation": 1
    },
    {
      "x": 2,
      "y": 0,
      "z": 2,
      "name": "Rock_Marble_Brick"
    },
    {
      "x": 2,
      "y": 5,
      "z": 2,
      "name": "Rock_Marble_Brick_Smooth_Half"
    },
    {
      "x": 2,
      "y": 12,
      "z": 2,
      "name": "Plant_Leaves_Aspen",
      "support": 15,
      "rotation": 1
    },
    {
      "x": 2,
      "y": 0,
      "z": 3,
      "name": "Rock_Marble_Brick"
    },
    {
      "x": 2,
      "y": 1,
      "z": 3,
      "name": "Rock_Marble_Brick_Smooth_Half"
    },
    {
      "x": 2,
      "y": 16,
      "z": 3,
      "name": "Plant_Leaves_Aspen",
      "support": 15,
      "rotation": 1
    },
    {
      "x": 2,
      "y": 0,
      "z": 4,
      "name": "Rock_Marble_Brick"
    },
    {
      "x": 2,
      "y": 1,
      "z": 4,
      "name": "Rock_Marble_Brick",
      "rotation": 1
    },
    {
      "x": 2,
      "y": 5,
      "z": 4,
      "name": "Rock_Marble_Brick_Smooth_Half"
    },
    {
      "x": 2,
      "y": 16,
      "z": 4,
      "name": "Plant_Leaves_Aspen",
      "support": 15,
      "rotation": 1
    },
    {
      "x": 2,
      "y": 0,
      "z": 5,
      "name": "Rock_Marble_Brick"
    },
    {
      "x": 2,
      "y": 1,
      "z": 5,
      "name": "Rock_Marble_Brick",
      "rotation": 1
    },
    {
      "x": 2,
      "y": 5,
      "z": 5,
      "name": "Rock_Marble_Brick_Decorative"
    },
    {
      "x": 3,
      "y": 0,
      "z": -5,
      "name": "Rock_Marble_Brick"
    },
    {
      "x": 3,
      "y": 1,
      "z": -5,
      "name": "Rock_Marble_Brick"
    },
    {
      "x": 3,
      "y": 2,
      "z": -5,
      "name": "Rock_Marble_Brick"
    },
    {
      "x": 3,
      "y": 3,
      "z": -5,
      "name": "Rock_Marble_Brick_Decorative"
    },
    {
      "x": 3,
      "y": 5,
      "z": -5,
      "name": "Rock_Marble_Brick"
    },
    {
      "x": 3,
      "y": 6,
      "z": -5,
      "name": "Rock_Marble_Brick"
    },
    {
      "x": 3,
      "y": 7,
      "z": -5,
      "name": "Rock_Marble_Brick_Smooth_Half"
    },
    {
      "x": 3,
      "y": 0,
      "z": -4,
      "name": "Rock_Marble_Brick"
    },
    {
      "x": 3,
      "y": 1,
      "z": -4,
      "name": "Rock_Marble_Brick"
    },
    {
      "x": 3,
      "y": 2,
      "z": -4,
      "name": "Furniture_Ancient_Table"
    },
    {
      "x": 3,
      "y": 3,
      "z": -4,
      "name": "Furniture_Temple_Light_Pot"
    },
    {
      "x": 3,
      "y": 5,
      "z": -4,
      "name": "Rock_Marble_Brick"
    },
    {
      "x": 3,
      "y": 6,
      "z": -4,
      "name": "Rock_Marble_Brick"
    },
    {
      "x": 3,
      "y": 0,
      "z": -3,
      "name": "Rock_Marble_Brick"
    },
    {
      "x": 3,
      "y": 1,
      "z": -3,
      "name": "Rock_Marble_Brick"
    },
    {
      "x": 3,
      "y": 2,
      "z": -3,
      "name": "Furniture_Ancient_Table",
      "filler": 32
    },
    {
      "x": 3,
      "y": 5,
      "z": -3,
      "name": "Rock_Marble_Brick"
    },
    {
      "x": 3,
      "y": 6,
      "z": -3,
      "name": "Rock_Marble_Brick"
    },
    {
      "x": 3,
      "y": 0,
      "z": -2,
      "name": "Rock_Marble_Brick"
    },
    {
      "x": 3,
      "y": 1,
      "z": -2,
      "name": "Rock_Marble_Brick"
    },
    {
      "x": 3,
      "y": 5,
      "z": -2,
      "name": "Rock_Marble_Brick"
    },
    {
      "x": 3,
      "y": 6,
      "z": -2,
      "name": "Rock_Marble_SkyGrass"
    },
    {
      "x": 3,
      "y": 7,
      "z": -2,
      "name": "Plant_Grass_Sky_Long",
      "support": 15
    },
    {
      "x": 3,
      "y": 8,
      "z": -2,
      "name": "Plant_Grass_Sky_Long",
      "filler": 1024
    },
    {
      "x": 3,
      "y": 0,
      "z": -1,
      "name": "Rock_Marble_Brick"
    },
    {
      "x": 3,
      "y": 1,
      "z": -1,
      "name": "Rock_Marble_Brick"
    },
    {
      "x": 3,
      "y": 3,
      "z": -1,
      "name": "Furniture_Temple_Light_Shelf",
      "rotation": 2
    },
    {
      "x": 3,
      "y": 5,
      "z": -1,
      "name": "Rock_Marble_Brick"
    },
    {
      "x": 3,
      "y": 6,
      "z": -1,
      "name": "Rock_Marble_SkyGrass"
    },
    {
      "x": 3,
      "y": 7,
      "z": -1,
      "name": "Plant_Bush_Sky",
      "support": 15
    },
    {
      "x": 3,
      "y": 0,
      "z": 0,
      "name": "Rock_Marble_Brick"
    },
    {
      "x": 3,
      "y": 1,
      "z": 0,
      "name": "Rock_Marble_Brick"
    },
    {
      "x": 3,
      "y": 2,
      "z": 0,
      "name": "Rock_Marble_Brick_Pillar_Middle"
    },
    {
      "x": 3,
      "y": 3,
      "z": 0,
      "name": "Rock_Marble_Brick"
    },
    {
      "x": 3,
      "y": 4,
      "z": 0,
      "name": "Rock_Marble_Brick"
    },
    {
      "x": 3,
      "y": 5,
      "z": 0,
      "name": "Rock_Marble_Brick"
    },
    {
      "x": 3,
      "y": 6,
      "z": 0,
      "name": "Rock_Marble_Brick_Stairs"
    },
    {
      "x": 3,
      "y": 0,
      "z": 1,
      "name": "Rock_Marble_Brick"
    },
    {
      "x": 3,
      "y": 1,
      "z": 1,
      "name": "Rock_Marble_Brick"
    },
    {
      "x": 3,
      "y": 5,
      "z": 1,
      "name": "Rock_Marble_Brick_Stairs"
    },
    {
      "x": 3,
      "y": 0,
      "z": 2,
      "name": "Rock_Marble_Brick"
    },
    {
      "x": 3,
      "y": 1,
      "z": 2,
      "name": "Rock_Marble_Brick_Smooth_Half"
    },
    {
      "x": 3,
      "y": 5,
      "z": 2,
      "name": "Rock_Marble_Brick_Smooth_Half"
    },
    {
      "x": 3,
      "y": 0,
      "z": 3,
      "name": "Rock_Marble_Brick"
    },
    {
      "x": 3,
      "y": 0,
      "z": 4,
      "name": "Rock_Marble_Brick"
    },
    {
      "x": 3,
      "y": 1,
      "z": 4,
      "name": "Rock_Marble_Brick",
      "rotation": 1
    },
    {
      "x": 3,
      "y": 5,
      "z": 4,
      "name": "Rock_Marble_Brick_Smooth_Half"
    },
    {
      "x": 3,
      "y": 0,
      "z": 5,
      "name": "Rock_Marble_Brick"
    },
    {
      "x": 3,
      "y": 1,
      "z": 5,
      "name": "Rock_Marble_Brick",
      "rotation": 1
    },
    {
      "x": 3,
      "y": 2,
      "z": 5,
      "name": "Rock_Marble_Brick_Pillar_Base"
    },
    {
      "x": 3,
      "y": 3,
      "z": 5,
      "name": "Rock_Marble_Brick_Pillar_Middle"
    },
    {
      "x": 3,
      "y": 4,
      "z": 5,
      "name": "Rock_Marble_Brick_Pillar_Base",
      "rotation": 8
    },
    {
      "x": 3,
      "y": 5,
      "z": 5,
      "name": "Rock_Marble_Brick_Decorative"
    },
    {
      "x": 4,
      "y": 0,
      "z": -5,
      "name": "Rock_Marble_Brick"
    },
    {
      "x": 4,
      "y": 1,
      "z": -5,
      "name": "Rock_Marble_Brick"
    },
    {
      "x": 4,
      "y": 2,
      "z": -5,
      "name": "Rock_Marble_Brick"
    },
    {
      "x": 4,
      "y": 3,
      "z": -5,
      "name": "Rock_Marble_Brick"
    },
    {
      "x": 4,
      "y": 4,
      "z": -5,
      "name": "Rock_Marble_Brick"
    },
    {
      "x": 4,
      "y": 5,
      "z": -5,
      "name": "Rock_Marble_Brick"
    },
    {
      "x": 4,
      "y": 0,
      "z": -4,
      "name": "Rock_Marble_Brick"
    },
    {
      "x": 4,
      "y": 1,
      "z": -4,
      "name": "Rock_Marble_Brick"
    },
    {
      "x": 4,
      "y": 2,
      "z": -4,
      "name": "Furniture_Ancient_Table",
      "filler": 1
    },
    {
      "x": 4,
      "y": 0,
      "z": -3,
      "name": "Rock_Marble_Brick"
    },
    {
      "x": 4,
      "y": 1,
      "z": -3,
      "name": "Rock_Marble_Brick"
    },
    {
      "x": 4,
      "y": 2,
      "z": -3,
      "name": "Furniture_Ancient_Table",
      "filler": 33
    },
    {
      "x": 4,
      "y": 5,
      "z": -3,
      "name": "Rock_Marble_Brick"
    },
    {
      "x": 4,
      "y": 6,
      "z": -3,
      "name": "Rock_Marble_SkyGrass"
    },
    {
      "x": 4,
      "y": 7,
      "z": -3,
      "name": "Plant_Bush_Sky",
      "support": 15
    },
    {
      "x": 4,
      "y": 0,
      "z": -2,
      "name": "Rock_Marble_Brick"
    },
    {
      "x": 4,
      "y": 1,
      "z": -2,
      "name": "Rock_Marble_Brick"
    },
    {
      "x": 4,
      "y": 2,
      "z": -2,
      "name": "Furniture_Temple_Light_Pot"
    },
    {
      "x": 4,
      "y": 5,
      "z": -2,
      "name": "Rock_Marble_Brick"
    },
    {
      "x": 4,
      "y": 6,
      "z": -2,
      "name": "Rock_Marble_SkyGrass"
    },
    {
      "x": 4,
      "y": 7,
      "z": -2,
      "name": "Plant_Grass_Sky_Wild",
      "support": 15
    },
    {
      "x": 4,
      "y": 8,
      "z": -2,
      "name": "Plant_Grass_Sky_Wild",
      "filler": 1024
    },
    {
      "x": 4,
      "y": 0,
      "z": -1,
      "name": "Rock_Marble_Brick"
    },
    {
      "x": 4,
      "y": 1,
      "z": -1,
      "name": "Rock_Marble_SkyGrass"
    },
    {
      "x": 4,
      "y": 2,
      "z": -1,
      "name": "Plant_Bush_Sky",
      "support": 15
    },
    {
      "x": 4,
      "y": 3,
      "z": -1,
      "name": "Furniture_Temple_Light_Shelf",
      "rotation": 2
    },
    {
      "x": 4,
      "y": 5,
      "z": -1,
      "name": "Rock_Marble_Brick"
    },
    {
      "x": 4,
      "y": 6,
      "z": -1,
      "name": "Rock_Marble_SkyGrass"
    },
    {
      "x": 4,
      "y": 7,
      "z": -1,
      "name": "Plant_Grass_Sky",
      "support": 15
    },
    {
      "x": 4,
      "y": 0,
      "z": 0,
      "name": "Rock_Marble_Brick"
    },
    {
      "x": 4,
      "y": 1,
      "z": 0,
      "name": "Rock_Marble_Brick"
    },
    {
      "x": 4,
      "y": 2,
      "z": 0,
      "name": "Rock_Marble_Brick"
    },
    {
      "x": 4,
      "y": 3,
      "z": 0,
      "name": "Rock_Marble_Brick"
    },
    {
      "x": 4,
      "y": 4,
      "z": 0,
      "name": "Rock_Marble_Brick"
    },
    {
      "x": 4,
      "y": 5,
      "z": 0,
      "name": "Rock_Marble_Brick"
    },
    {
      "x": 4,
      "y": 6,
      "z": 0,
      "name": "Rock_Marble_Brick"
    },
    {
      "x": 4,
      "y": 7,
      "z": 0,
      "name": "Rock_Marble_Brick_Smooth_Half"
    },
    {
      "x": 4,
      "y": 0,
      "z": 1,
      "name": "Rock_Marble_Brick"
    },
    {
      "x": 4,
      "y": 1,
      "z": 1,
      "name": "Rock_Marble_Brick"
    },
    {
      "x": 4,
      "y": 2,
      "z": 1,
      "name": "Furniture_Temple_Light_Pot"
    },
    {
      "x": 4,
      "y": 5,
      "z": 1,
      "name": "Rock_Marble_Brick_Smooth_Half"
    },
    {
      "x": 4,
      "y": 0,
      "z": 2,
      "name": "Rock_Marble_Brick"
    },
    {
      "x": 4,
      "y": 1,
      "z": 2,
      "name": "Rock_Marble_Brick"
    },
    {
      "x": 4,
      "y": 5,
      "z": 2,
      "name": "Rock_Marble_Brick_Smooth_Half"
    },
    {
      "x": 4,
      "y": 0,
      "z": 3,
      "name": "Rock_Marble_Brick"
    },
    {
      "x": 4,
      "y": 1,
      "z": 3,
      "name": "Rock_Marble_Brick"
    },
    {
      "x": 4,
      "y": 5,
      "z": 3,
      "name": "Rock_Marble_Brick_Smooth_Half"
    },
    {
      "x": 4,
      "y": 0,
      "z": 4,
      "name": "Rock_Marble_Brick"
    },
    {
      "x": 4,
      "y": 1,
      "z": 4,
      "name": "Rock_Marble_Brick",
      "rotation": 1
    },
    {
      "x": 4,
      "y": 5,
      "z": 4,
      "name": "Rock_Marble_Brick_Smooth_Half"
    },
    {
      "x": 4,
      "y": 0,
      "z": 5,
      "name": "Rock_Marble_Brick"
    },
    {
      "x": 4,
      "y": 1,
      "z": 5,
      "name": "Rock_Marble_Brick",
      "rotation": 1
    },
    {
      "x": 4,
      "y": 5,
      "z": 5,
      "name": "Rock_Marble_Brick_Decorative"
    },
    {
      "x": 5,
      "y": 0,
      "z": -5,
      "name": "Rock_Marble_Brick"
    },
    {
      "x": 5,
      "y": 1,
      "z": -5,
      "name": "Rock_Marble_Brick"
    },
    {
      "x": 5,
      "y": 0,
      "z": -4,
      "name": "Rock_Marble_Brick"
    },
    {
      "x": 5,
      "y": 1,
      "z": -4,
      "name": "Rock_Marble_Brick"
    },
    {
      "x": 5,
      "y": 2,
      "z": -4,
      "name": "Rock_Marble_Brick"
    },
    {
      "x": 5,
      "y": 3,
      "z": -4,
      "name": "Rock_Marble_Brick"
    },
    {
      "x": 5,
      "y": 0,
      "z": -3,
      "name": "Rock_Marble_Brick"
    },
    {
      "x": 5,
      "y": 1,
      "z": -3,
      "name": "Rock_Marble_Brick"
    },
    {
      "x": 5,
      "y": 2,
      "z": -3,
      "name": "Rock_Marble_Brick_Smooth_Half"
    },
    {
      "x": 5,
      "y": 6,
      "z": -3,
      "name": "Rock_Marble_Brick"
    },
    {
      "x": 5,
      "y": 7,
      "z": -3,
      "name": "Rock_Marble_Brick_Smooth_Half"
    },
    {
      "x": 5,
      "y": 0,
      "z": -2,
      "name": "Rock_Marble_Brick"
    },
    {
      "x": 5,
      "y": 1,
      "z": -2,
      "name": "Rock_Marble_Brick"
    },
    {
      "x": 5,
      "y": 2,
      "z": -2,
      "name": "Rock_Marble_Brick_Smooth_Half"
    },
    {
      "x": 5,
      "y": 4,
      "z": -2,
      "name": "Rock_Marble_Brick_Smooth_Half",
      "rotation": 6
    },
    {
      "x": 5,
      "y": 5,
      "z": -2,
      "name": "Rock_Marble_Brick"
    },
    {
      "x": 5,
      "y": 6,
      "z": -2,
      "name": "Rock_Marble_Brick"
    },
    {
      "x": 5,
      "y": 7,
      "z": -2,
      "name": "Rock_Marble_Brick_Smooth_Half"
    },
    {
      "x": 5,
      "y": 0,
      "z": -1,
      "name": "Rock_Marble_Brick"
    },
    {
      "x": 5,
      "y": 1,
      "z": -1,
      "name": "Rock_Marble_Brick"
    },
    {
      "x": 5,
      "y": 2,
      "z": -1,
      "name": "Rock_Marble_Brick"
    },
    {
      "x": 5,
      "y": 3,
      "z": -1,
      "name": "Rock_Marble_Brick"
    },
    {
      "x": 5,
      "y": 4,
      "z": -1,
      "name": "Rock_Marble_Brick"
    },
    {
      "x": 5,
      "y": 5,
      "z": -1,
      "name": "Rock_Marble_Brick"
    },
    {
      "x": 5,
      "y": 6,
      "z": -1,
      "name": "Rock_Marble_Brick"
    },
    {
      "x": 5,
      "y": 7,
      "z": -1,
      "name": "Rock_Marble_Brick_Smooth_Half"
    },
    {
      "x": 5,
      "y": 0,
      "z": 0,
      "name": "Rock_Marble_Brick"
    },
    {
      "x": 5,
      "y": 1,
      "z": 0,
      "name": "Rock_Marble_Brick"
    },
    {
      "x": 5,
      "y": 2,
      "z": 0,
      "name": "Rock_Marble_Brick"
    },
    {
      "x": 5,
      "y": 3,
      "z": 0,
      "name": "Rock_Marble_Brick"
    },
    {
      "x": 5,
      "y": 4,
      "z": 0,
      "name": "Rock_Marble_Brick"
    },
    {
      "x": 5,
      "y": 5,
      "z": 0,
      "name": "Rock_Marble_Brick"
    },
    {
      "x": 5,
      "y": 6,
      "z": 0,
      "name": "Rock_Marble_Brick"
    },
    {
      "x": 5,
      "y": 7,
      "z": 0,
      "name": "Rock_Marble_Brick_Smooth_Half"
    },
    {
      "x": 5,
      "y": 0,
      "z": 1,
      "name": "Rock_Marble_Brick"
    },
    {
      "x": 5,
      "y": 1,
      "z": 1,
      "name": "Rock_Marble_Brick"
    },
    {
      "x": 5,
      "y": 2,
      "z": 1,
      "name": "Rock_Marble_Brick_Pillar_Base"
    },
    {
      "x": 5,
      "y": 3,
      "z": 1,
      "name": "Rock_Marble_Brick_Pillar_Middle"
    },
    {
      "x": 5,
      "y": 4,
      "z": 1,
      "name": "Rock_Marble_Brick_Pillar_Base",
      "rotation": 8
    },
    {
      "x": 5,
      "y": 5,
      "z": 1,
      "name": "Rock_Marble_Brick_Decorative"
    },
    {
      "x": 5,
      "y": 0,
      "z": 2,
      "name": "Rock_Marble_Brick"
    },
    {
      "x": 5,
      "y": 1,
      "z": 2,
      "name": "Rock_Marble_Brick"
    },
    {
      "x": 5,
      "y": 5,
      "z": 2,
      "name": "Rock_Marble_Brick_Decorative"
    },
    {
      "x": 5,
      "y": 0,
      "z": 3,
      "name": "Rock_Marble_Brick"
    },
    {
      "x": 5,
      "y": 1,
      "z": 3,
      "name": "Rock_Marble_Brick"
    },
    {
      "x": 5,
      "y": 2,
      "z": 3,
      "name": "Rock_Marble_Brick_Pillar_Base"
    },
    {
      "x": 5,
      "y": 3,
      "z": 3,
      "name": "Rock_Marble_Brick_Pillar_Middle"
    },
    {
      "x": 5,
      "y": 4,
      "z": 3,
      "name": "Rock_Marble_Brick_Pillar_Base",
      "rotation": 8
    },
    {
      "x": 5,
      "y": 5,
      "z": 3,
      "name": "Rock_Marble_Brick_Decorative"
    },
    {
      "x": 5,
      "y": 0,
      "z": 4,
      "name": "Rock_Marble_Brick"
    },
    {
      "x": 5,
      "y": 1,
      "z": 4,
      "name": "Rock_Marble_Brick"
    },
    {
      "x": 5,
      "y": 5,
      "z": 4,
      "name": "Rock_Marble_Brick_Decorative"
    },
    {
      "x": 5,
      "y": 0,
      "z": 5,
      "name": "Rock_Marble_Brick"
    },
    {
      "x": 5,
      "y": 1,
      "z": 5,
      "name": "Rock_Marble_Brick"
    },
    {
      "x": 5,
      "y": 2,
      "z": 5,
      "name": "Rock_Marble_Brick_Pillar_Base"
    },
    {
      "x": 5,
      "y": 3,
      "z": 5,
      "name": "Rock_Marble_Brick_Pillar_Middle"
    },
    {
      "x": 5,
      "y": 4,
      "z": 5,
      "name": "Rock_Marble_Brick_Pillar_Base",
      "rotation": 8
    },
    {
      "x": 5,
      "y": 5,
      "z": 5,
      "name": "Rock_Marble_Brick_Decorative"
    }
  ]
}