{
  "version": 8,
  "blockIdVersion": 11,
  "anchorX": 0,
  "anchorY": 1,
  "anchorZ": 0,
  "blocks": [
    {
      "x": -5,
      "y": 8,
      "z": -2,
      "name": "Plant_Leaves_Aspen",
      "support": 15
    },
    {
      "x": -5,
      "y": 9,
      "z": -2,
      "name": "Plant_Leaves_Aspen",
      "support": 15
    },
    {
      "x": -5,
      "y": 9,
      "z": -1,
      "name": "Plant_Leaves_Aspen",
      "support": 15
    },
    {
      "x": -5,
      "y": 9,
      "z": 0,
      "name": "Plant_Leaves_Aspen",
      "support": 15
    },
    {
      "x": -5,
      "y": 6,
      "z": 1,
      "name": "Plant_Leaves_Aspen",
      "support": 15
    },
    {
      "x": -5,
      "y": 6,
      "z": 2,
      "name": "Plant_Leaves_Aspen",
      "support": 15
    },
    {
      "x": -5,
      "y": 6,
      "z": 3,
      "name": "Plant_Leaves_Aspen",
      "support": 15
    },
    {
      "x": -4,
      "y": 0,
      "z": -4,
      "name": "Rock_Marble_Brick"
    },
    {
      "x": -4,
      "y": 1,
      "z": -4,
      "name": "Rock_Marble_Brick"
    },
    {
      "x": -4,
      "y": 2,
      "z": -4,
      "name": "Rock_Marble_Brick"
    },
    {
      "x": -4,
      "y": 3,
      "z": -4,
      "name": "Rock_Marble_Brick"
    },
    {
      "x": -4,
      "y": 4,
      "z": -4,
      "name": "Rock_Marble_Brick"
    },
    {
      "x": -4,
      "y": 5,
      "z": -4,
      "name": "Rock_Marble_Brick"
    },
    {
      "x": -4,
      "y": 6,
      "z": -4,
      "name": "Rock_Marble_Brick"
    },
    {
      "x": -4,
      "y": 7,
      "z": -4,
      "name": "Rock_Marble_Brick"
    },
    {
      "x": -4,
      "y": 8,
      "z": -4,
      "name": "Rock_Marble_Brick"
    },
    {
      "x": -4,
      "y": 9,
      "z": -4,
      "name": "Plant_Leaves_Aspen",
      "support": 15
    },
    {
      "x": -4,
      "y": 0,
      "z": -3,
      "name": "Rock_Marble_Brick"
    },
    {
      "x": -4,
      "y": 1,
      "z": -3,
      "name": "Rock_Marble_Brick"
    },
    {
      "x": -4,
      "y": 2,
      "z": -3,
      "name": "Rock_Marble_Brick"
    },
    {
      "x": -4,
      "y": 3,
      "z": -3,
      "name": "Rock_Marble_Brick_Smooth_Half",
      "rotation": 8
    },
    {
      "x": -4,
      "y": 4,
      "z": -3,
      "name": "Rock_Marble_Brick"
    },
    {
      "x": -4,
      "y": 5,
      "z": -3,
      "name": "Rock_Marble_Brick"
    },
    {
      "x": -4,
      "y": 6,
      "z": -3,
      "name": "Rock_Marble_Brick"
    },
    {
      "x": -4,
      "y": 7,
      "z": -3,
      "name": "Rock_Marble_Brick_Smooth_Half"
    },
    {
      "x": -4,
      "y": 8,
      "z": -3,
      "name": "Rock_Marble_Brick"
    },
    {
      "x": -4,
      "y": 9,
      "z": -3,
      "name": "Plant_Leaves_Aspen",
      "support": 15
    },
    {
      "x": -4,
      "y": 0,
      "z": -2,
      "name": "Rock_Marble_Brick"
    },
    {
      "x": -4,
      "y": 1,
      "z": -2,
      "name": "Rock_Marble_Brick"
    },
    {
      "x": -4,
      "y": 2,
      "z": -2,
      "name": "Rock_Marble_Brick"
    },
    {
      "x": -4,
      "y": 3,
      "z": -2,
      "name": "Rock_Marble_Brick"
    },
    {
      "x": -4,
      "y": 4,
      "z": -2,
      "name": "Rock_Marble_Brick"
    },
    {
      "x": -4,
      "y": 5,
      "z": -2,
      "name": "Rock_Marble_Brick"
    },
    {
      "x": -4,
      "y": 6,
      "z": -2,
      "name": "Rock_Marble_Brick"
    },
    {
      "x": -4,
      "y": 7,
      "z": -2,
      "name": "Rock_Marble_Brick_Smooth_Half"
    },
    {
      "x": -4,
      "y": 8,
      "z": -2,
      "name": "Rock_Marble_Brick"
    },
    {
      "x": -4,
      "y": 9,
      "z": -2,
      "name": "Plant_Leaves_Aspen",
      "support": 15
    },
    {
      "x": -4,
      "y": 10,
      "z": -2,
      "name": "Plant_Leaves_Aspen",
      "support": 15
    },
    {
      "x": -4,
      "y": 0,
      "z": -1,
      "name": "Rock_Marble_Brick"
    },
    {
      "x": -4,
      "y": 1,
      "z": -1,
      "name": "Rock_Marble_Brick"
    },
    {
      "x": -4,
      "y": 2,
      "z": -1,
      "name": "Rock_Marble_Brick"
    },
    {
      "x": -4,
      "y": 3,
      "z": -1,
      "name": "Rock_Marble_Brick"
    },
    {
      "x": -4,
      "y": 4,
      "z": -1,
      "name": "Rock_Marble_Brick"
    },
    {
      "x": -4,
      "y": 6,
      "z": -1,
      "name": "Wood_Birch_Trunk_Full",
      "support": 15
    },
    {
      "x": -4,
      "y": 7,
      "z": -1,
      "name": "Rock_Marble_Brick"
    },
    {
      "x": -4,
      "y": 8,
      "z": -1,
      "name": "Rock_Marble_Brick"
    },
    {
      "x": -4,
      "y": 9,
      "z": -1,
      "name": "Plant_Leaves_Aspen",
      "support": 15
    },
    {
      "x": -4,
      "y": 10,
      "z": -1,
      "name": "Plant_Leaves_Aspen",
      "support": 15
    },
    {
      "x": -4,
      "y": 0,
      "z": 0,
      "name": "Rock_Marble_Brick"
    },
    {
      "x": -4,
      "y": 1,
      "z": 0,
      "name": "Rock_Marble_Brick"
    },
    {
      "x": -4,
      "y": 2,
      "z": 0,
      "name": "Rock_Marble_Brick"
    },
    {
      "x": -4,
      "y": 3,
      "z": 0,
      "name": "Wood_Birch_Trunk",
      "support": 15
    },
    {
      "x": -4,
      "y": 4,
      "z": 0,
      "name": "Wood_Birch_Trunk_Full",
      "support": 15
    },
    {
      "x": -4,
      "y": 5,
      "z": 0,
      "name": "Wood_Birch_Trunk_Full",
      "support": 15
    },
    {
      "x": -4,
      "y": 6,
      "z": 0,
      "name": "Plant_Leaves_Aspen",
      "support": 15
    },
    {
      "x": -4,
      "y": 9,
      "z": 0,
      "name": "Plant_Leaves_Aspen",
      "support": 15
    },
    {
      "x": -4,
      "y": 0,
      "z": 1,
      "name": "Rock_Marble_Brick"
    },
    {
      "x": -4,
      "y": 1,
      "z": 1,
      "name": "Rock_Marble_Brick"
    },
    {
      "x": -4,
      "y": 2,
      "z": 1,
      "name": "Rock_Marble_Brick"
    },
    {
      "x": -4,
      "y": 6,
      "z": 1,
      "name": "Plant_Leaves_Aspen",
      "support": 15
    },
    {
      "x": -4,
      "y": 7,
      "z": 1,
      "name": "Plant_Leaves_Aspen",
      "support": 15
    },
    {
      "x": -4,
      "y": 9,
      "z": 1,
      "name": "Plant_Leaves_Aspen",
      "support": 15
    },
    {
      "x": -4,
      "y": 0,
      "z": 2,
      "name": "Rock_Marble_Brick"
    },
    {
      "x": -4,
      "y": 1,
      "z": 2,
      "name": "Rock_Marble_Brick"
    },
    {
      "x": -4,
      "y": 2,
      "z": 2,
      "name": "Rock_Marble_Brick"
    },
    {
      "x": -4,
      "y": 3,
      "z": 2,
      "name": "Rock_Marble_Brick"
    },
    {
      "x": -4,
      "y": 5,
      "z": 2,
      "name": "Rock_Marble_Brick"
    },
    {
      "x": -4,
      "y": 6,
      "z": 2,
      "name": "Plant_Leaves_Aspen",
      "support": 15
    },
    {
      "x": -4,
      "y": 7,
      "z": 2,
      "name": "Plant_Leaves_Aspen",
      "support": 15
    },
    {
      "x": -4,
      "y": 0,
      "z": 3,
      "name": "Rock_Marble_Brick"
    },
    {
      "x": -4,
      "y": 1,
      "z": 3,
      "name": "Rock_Marble_Brick"
    },
    {
      "x": -4,
      "y": 2,
      "z": 3,
      "name": "Rock_Marble_Brick"
    },
    {
      "x": -4,
      "y": 3,
      "z": 3,
      "name": "Rock_Marble_Brick"
    },
    {
      "x": -4,
      "y": 4,
      "z": 3,
      "name": "Rock_Marble_Brick"
    },
    {
      "x": -4,
      "y": 5,
      "z": 3,
      "name": "Rock_Marble_Brick"
    },
    {
      "x": -4,
      "y": 6,
      "z": 3,
      "name": "Plant_Leaves_Aspen",
      "support": 15
    },
    {
      "x": -3,
      "y": 0,
      "z": -4,
      "name": "Rock_Marble_Brick"
    },
    {
      "x": -3,
      "y": 1,
      "z": -4,
      "name": "Rock_Marble_Brick"
    },
    {
      "x": -3,
      "y": 2,
      "z": -4,
      "name": "Rock_Marble_Brick"
    },
    {
      "x": -3,
      "y": 3,
      "z": -4,
      "name": "Rock_Marble_Brick"
    },
    {
      "x": -3,
      "y": 4,
      "z": -4,
      "name": "Rock_Marble_Brick"
    },
    {
      "x": -3,
      "y": 5,
      "z": -4,
      "name": "Rock_Marble_Brick"
    },
    {
      "x": -3,
      "y": 6,
      "z": -4,
      "name": "Wood_Birch_Branch_Corner",
      "support": 15,
      "rotation": 2
    },
    {
      "x": -3,
      "y": 7,
      "z": -4,
      "name": "Wood_Birch_Branch_Corner",
      "support": 15,
      "rotation": 8
    },
    {
      "x": -3,
      "y": 8,
      "z": -4,
      "name": "Rock_Marble_Brick"
    },
    {
      "x": -3,
      "y": 9,
      "z": -4,
      "name": "Plant_Leaves_Aspen",
      "support": 15
    },
    {
      "x": -3,
      "y": 0,
      "z": -3,
      "name": "Rock_Marble_SkyGrass"
    },
    {
      "x": -3,
      "y": 1,
      "z": -3,
      "name": "Plant_Bush_Sky",
      "support": 15
    },
    {
      "x": -3,
      "y": 2,
      "z": -3,
      "name": "Plant_Bush_Sky",
      "support": 15
    },
    {
      "x": -3,
      "y": 3,
      "z": -3,
      "name": "Plant_Bush_Sky",
      "support": 15
    },
    {
      "x": -3,
      "y": 7,
      "z": -3,
      "name": "Wood_Birch_Branch_Long",
      "support": 15,
      "rotation": 4
    },
    {
      "x": -3,
      "y": 9,
      "z": -3,
      "name": "Plant_Leaves_Aspen",
      "support": 15
    },
    {
      "x": -3,
      "y": 10,
      "z": -3,
      "name": "Plant_Leaves_Aspen",
      "support": 15
    },
    {
      "x": -3,
      "y": 13,
      "z": -3,
      "name": "Plant_Leaves_Aspen",
      "support": 15
    },
    {
      "x": -3,
      "y": 0,
      "z": -2,
      "name": "Rock_Marble_SkyGrass"
    },
    {
      "x": -3,
      "y": 6,
      "z": -2,
      "name": "Wood_Birch_Trunk_Full",
      "support": 15
    },
    {
      "x": -3,
      "y": 7,
      "z": -2,
      "name": "Wood_Birch_Trunk",
      "support": 15
    },
    {
      "x": -3,
      "y": 8,
      "z": -2,
      "name": "Wood_Birch_Trunk_Full",
      "support": 15
    },
    {
      "x": -3,
      "y": 9,
      "z": -2,
      "name": "Plant_Leaves_Aspen",
      "support": 15
    },
    {
      "x": -3,
      "y": 10,
      "z": -2,
      "name": "Plant_Leaves_Aspen",
      "support": 15
    },
    {
      "x": -3,
      "y": 13,
      "z": -2,
      "name": "Plant_Leaves_Aspen",
      "support": 15
    },
    {
      "x": -3,
      "y": 14,
      "z": -2,
      "name": "Plant_Leaves_Aspen",
      "support": 15
    },
    {
      "x": -3,
      "y": 0,
      "z": -1,
      "name": "Wood_Birch_Trunk_Full",
      "support": 15
    },
    {
      "x": -3,
      "y": 1,
      "z": -1,
      "name": "Wood_Birch_Trunk",
      "support": 15
    },
    {
      "x": -3,
      "y": 2,
      "z": -1,
      "name": "Wood_Birch_Trunk_Full",
      "support": 15
    },
    {
      "x": -3,
      "y": 4,
      "z": -1,
      "name": "Rock_Marble_Brick_Smooth_Half",
      "rotation": 5
    },
    {
      "x": -3,
      "y": 5,
      "z": -1,
      "name": "Wood_Birch_Trunk_Full",
      "support": 15
    },
    {
      "x": -3,
      "y": 6,
      "z": -1,
      "name": "Wood_Birch_Trunk_Full",
      "support": 15
    },
    {
      "x": -3,
      "y": 7,
      "z": -1,
      "name": "Rock_Marble_Brick_Smooth_Half"
    },
    {
      "x": -3,
      "y": 8,
      "z": -1,
      "name": "Wood_Birch_Branch_Long",
      "support": 15,
      "rotation": 4
    },
    {
      "x": -3,
      "y": 9,
      "z": -1,
      "name": "Plant_Leaves_Aspen",
      "support": 15
    },
    {
      "x": -3,
      "y": 10,
      "z": -1,
      "name": "Plant_Leaves_Aspen",
      "support": 15
    },
    {
      "x": -3,
      "y": 12,
      "z": -1,
      "name": "Plant_Leaves_Aspen",
      "support": 15
    },
    {
      "x": -3,
      "y": 13,
      "z": -1,
      "name": "Plant_Leaves_Aspen",
      "support": 15
    },
    {
      "x": -3,
      "y": 0,
      "z": 0,
      "name": "Wood_Birch_Trunk",
      "support": 15
    },
    {
      "x": -3,
      "y": 1,
      "z": 0,
      "name": "Wood_Birch_Trunk",
      "support": 15
    },
    {
      "x": -3,
      "y": 2,
      "z": 0,
      "name": "Wood_Birch_Trunk",
      "support": 15
    },
    {
      "x": -3,
      "y": 3,
      "z": 0,
      "name": "Wood_Birch_Trunk",
      "support": 15
    },
    {
      "x": -3,
      "y": 4,
      "z": 0,
      "name": "Wood_Birch_Trunk",
      "support": 15
    },
    {
      "x": -3,
      "y": 5,
      "z": 0,
      "name": "Wood_Birch_Trunk_Full",
      "support": 15
    },
    {
      "x": -3,
      "y": 6,
      "z": 0,
      "name": "Plant_Leaves_Aspen",
      "support": 15
    },
    {
      "x": -3,
      "y": 8,
      "z": 0,
      "name": "Wood_Birch_Branch_Long",
      "support": 15,
      "rotation": 4
    },
    {
      "x": -3,
      "y": 9,
      "z": 0,
      "name": "Plant_Leaves_Aspen",
      "support": 15
    },
    {
      "x": -3,
      "y": 10,
      "z": 0,
      "name": "Plant_Leaves_Aspen",
      "support": 15
    },
    {
      "x": -3,
      "y": 13,
      "z": 0,
      "name": "Plant_Leaves_Aspen",
      "support": 15
    },
    {
      "x": -3,
      "y": 0,
      "z": 1,
      "name": "Wood_Birch_Trunk_Full",
      "support": 15
    },
    {
      "x": -3,
      "y": 1,
      "z": 1,
      "name": "Wood_Birch_Trunk",
      "support": 15
    },
    {
      "x": -3,
      "y": 2,
      "z": 1,
      "name": "Wood_Birch_Trunk",
      "support": 15
    },
    {
      "x": -3,
      "y": 3,
      "z": 1,
      "name": "Wood_Birch_Trunk_Full",
      "support": 15
    },
    {
      "x": -3,
      "y": 5,
      "z": 1,
      "name": "Wood_Birch_Branch_Long",
      "support": 15,
      "rotation": 4
    },
    {
      "x": -3,
      "y": 6,
      "z": 1,
      "name": "Plant_Leaves_Aspen",
      "support": 15
    },
    {
      "x": -3,
      "y": 7,
      "z": 1,
      "name": "Plant_Leaves_Aspen",
      "support": 15
    },
    {
      "x": -3,
      "y": 8,
      "z": 1,
      "name": "Wood_Birch_Branch_Corner",
      "support": 15
    },
    {
      "x": -3,
      "y": 9,
      "z": 1,
      "name": "Wood_Birch_Branch_Long",
      "support": 15
    },
    {
      "x": -3,
      "y": 10,
      "z": 1,
      "name": "Plant_Leaves_Aspen",
      "support": 15
    },
    {
      "x": -3,
      "y": 0,
      "z": 2,
      "name": "Wood_Birch_Trunk_Full",
      "support": 15
    },
    {
      "x": -3,
      "y": 1,
      "z": 2,
      "name": "Rock_Marble_Brick"
    },
    {
      "x": -3,
      "y": 2,
      "z": 2,
      "name": "Furniture_Temple_Light_Pot"
    },
    {
      "x": -3,
      "y": 5,
      "z": 2,
      "name": "Wood_Birch_Branch_Corner",
      "support": 15
    },
    {
      "x": -3,
      "y": 6,
      "z": 2,
      "name": "Wood_Birch_Branch_Corner",
      "support": 15,
      "rotation": 8
    },
    {
      "x": -3,
      "y": 7,
      "z": 2,
      "name": "Plant_Leaves_Aspen",
      "support": 15
    },
    {
      "x": -3,
      "y": 9,
      "z": 2,
      "name": "Plant_Leaves_Aspen",
      "support": 15
    },
    {
      "x": -3,
      "y": 0,
      "z": 3,
      "name": "Rock_Marble_Brick"
    },
    {
      "x": -3,
      "y": 1,
      "z": 3,
      "name": "Rock_Marble_Brick"
    },
    {
      "x": -3,
      "y": 2,
      "z": 3,
      "name": "Rock_Marble_Brick_Decorative"
    },
    {
      "x": -3,
      "y": 4,
      "z": 3,
      "name": "Rock_Marble_Brick_Smooth_Half",
      "rotation": 5
    },
    {
      "x": -3,
      "y": 5,
      "z": 3,
      "name": "Rock_Marble_Brick"
    },
    {
      "x": -3,
      "y": 6,
      "z": 3,
      "name": "Plant_Leaves_Aspen",
      "support": 15
    },
    {
      "x": -3,
      "y": 7,
      "z": 3,
      "name": "Plant_Leaves_Aspen",
      "support": 15
    },
    {
      "x": -2,
      "y": 9,
      "z": -5,
      "name": "Plant_Leaves_Aspen",
      "support": 15
    },
    {
      "x": -2,
      "y": 0,
      "z": -4,
      "name": "Rock_Marble_Brick"
    },
    {
      "x": -2,
      "y": 1,
      "z": -4,
      "name": "Rock_Marble_Brick"
    },
    {
      "x": -2,
      "y": 2,
      "z": -4,
      "name": "Rock_Marble_Brick"
    },
    {
      "x": -2,
      "y": 3,
      "z": -4,
      "name": "Rock_Marble_Brick"
    },
    {
      "x": -2,
      "y": 4,
      "z": -4,
      "name": "Rock_Marble_Brick"
    },
    {
      "x": -2,
      "y": 9,
      "z": -4,
      "name": "Plant_Leaves_Aspen",
      "support": 15
    },
    {
      "x": -2,
      "y": 10,
      "z": -4,
      "name": "Plant_Leaves_Aspen",
      "support": 15
    },
    {
      "x": -2,
      "y": 11,
      "z": -4,
      "name": "Plant_Leaves_Aspen",
      "support": 15
    },
    {
      "x": -2,
      "y": 13,
      "z": -4,
      "name": "Plant_Leaves_Aspen",
      "support": 15
    },
    {
      "x": -2,
      "y": 0,
      "z": -3,
      "name": "Rock_Marble_SkyGrass"
    },
    {
      "x": -2,
      "y": 1,
      "z": -3,
      "name": "Plant_Grass_Sky_Wild",
      "support": 15
    },
    {
      "x": -2,
      "y": 2,
      "z": -3,
      "name": "Plant_Grass_Sky_Wild",
      "filler": 1024
    },
    {
      "x": -2,
      "y": 9,
      "z": -3,
      "name": "Wood_Birch_Branch_Corner",
      "support": 15,
      "rotation": 2
    },
    {
      "x": -2,
      "y": 10,
      "z": -3,
      "name": "Wood_Birch_Branch_Long",
      "support": 15
    },
    {
      "x": -2,
      "y": 11,
      "z": -3,
      "name": "Plant_Leaves_Aspen",
      "support": 15
    },
    {
      "x": -2,
      "y": 13,
      "z": -3,
      "name": "Plant_Leaves_Aspen",
      "support": 15
    },
    {
      "x": -2,
      "y": 14,
      "z": -3,
      "name": "Plant_Leaves_Aspen",
      "support": 15
    },
    {
      "x": -2,
      "y": 0,
      "z": -2,
      "name": "Rock_Marble_SkyGrass"
    },
    {
      "x": -2,
      "y": 1,
      "z": -2,
      "name": "Plant_Bush_Sky",
      "support": 15
    },
    {
      "x": -2,
      "y": 2,
      "z": -2,
      "name": "Plant_Bush_Sky",
      "support": 15
    },
    {
      "x": -2,
      "y": 8,
      "z": -2,
      "name": "Wood_Birch_Trunk_Full",
      "support": 15
    },
    {
      "x": -2,
      "y": 9,
      "z": -2,
      "name": "Wood_Birch_Trunk",
      "support": 15
    },
    {
      "x": -2,
      "y": 10,
      "z": -2,
      "name": "Wood_Birch_Trunk_Full",
      "support": 15
    },
    {
      "x": -2,
      "y": 11,
      "z": -2,
      "name": "Wood_Birch_Branch_Long",
      "support": 15
    },
    {
      "x": -2,
      "y": 12,
      "z": -2,
      "name": "Wood_Birch_Branch_Long",
      "support": 15
    },
    {
      "x": -2,
      "y": 13,
      "z": -2,
      "name": "Wood_Birch_Branch_Corner",
      "support": 15,
      "rotation": 8
    },
    {
      "x": -2,
      "y": 14,
      "z": -2,
      "name": "Plant_Leaves_Aspen",
      "support": 15
    },
    {
      "x": -2,
      "y": 0,
      "z": -1,
      "name": "Rock_Marble_Brick"
    },
    {
      "x": -2,
      "y": 1,
      "z": -1,
      "name": "Rock_Marble_SkyGrass"
    },
    {
      "x": -2,
      "y": 2,
      "z": -1,
      "name": "Plant_Bush_Sky",
      "support": 15
    },
    {
      "x": -2,
      "y": 5,
      "z": -1,
      "name": "Wood_Birch_Branch_Short",
      "support": 15,
      "rotation": 1
    },
    {
      "x": -2,
      "y": 6,
      "z": -1,
      "name": "Rock_Marble_Brick"
    },
    {
      "x": -2,
      "y": 8,
      "z": -1,
      "name": "Rock_Marble_Brick"
    },
    {
      "x": -2,
      "y": 9,
      "z": -1,
      "name": "Plant_Leaves_Aspen",
      "support": 15
    },
    {
      "x": -2,
      "y": 10,
      "z": -1,
      "name": "Plant_Leaves_Aspen",
      "support": 15
    },
    {
      "x": -2,
      "y": 13,
      "z": -1,
      "name": "Plant_Leaves_Aspen",
      "support": 15
    },
    {
      "x": -2,
      "y": 14,
      "z": -1,
      "name": "Plant_Leaves_Aspen",
      "support": 15
    },
    {
      "x": -2,
      "y": 0,
      "z": 0,
      "name": "Wood_Birch_Trunk_Full",
      "support": 15
    },
    {
      "x": -2,
      "y": 1,
      "z": 0,
      "name": "Wood_Birch_Trunk_Full",
      "support": 15
    },
    {
      "x": -2,
      "y": 2,
      "z": 0,
      "name": "Plant_Grass_Sky_Long",
      "support": 15
    },
    {
      "x": -2,
      "y": 3,
      "z": 0,
      "name": "Plant_Grass_Sky_Long",
      "filler": 1024
    },
    {
      "x": -2,
      "y": 6,
      "z": 0,
      "name": "Rock_Marble_Brick_Smooth_Half"
    },
    {
      "x": -2,
      "y": 9,
      "z": 0,
      "name": "Plant_Leaves_Aspen",
      "support": 15
    },
    {
      "x": -2,
      "y": 10,
      "z": 0,
      "name": "Plant_Leaves_Aspen",
      "support": 15
    },
    {
      "x": -2,
      "y": 13,
      "z": 0,
      "name": "Plant_Leaves_Aspen",
      "support": 15
    },
    {
      "x": -2,
      "y": 0,
      "z": 1,
      "name": "Rock_Marble_Brick"
    },
    {
      "x": -2,
      "y": 1,
      "z": 1,
      "name": "Rock_Marble_Brick_Smooth_Half"
    },
    {
      "x": -2,
      "y": 6,
      "z": 1,
      "name": "Plant_Leaves_Aspen",
      "support": 15
    },
    {
      "x": -2,
      "y": 7,
      "z": 1,
      "name": "Plant_Grass_Sky_Long",
      "support": 15
    },
    {
      "x": -2,
      "y": 8,
      "z": 1,
      "name": "Plant_Grass_Sky_Long",
      "filler": 1024
    },
    {
      "x": -2,
      "y": 9,
      "z": 1,
      "name": "Plant_Leaves_Aspen",
      "support": 15
    },
    {
      "x": -2,
      "y": 10,
      "z": 1,
      "name": "Plant_Leaves_Aspen",
      "support": 15
    },
    {
      "x": -2,
      "y": 0,
      "z": 2,
      "name": "Rock_Marble_Brick"
    },
    {
      "x": -2,
      "y": 6,
      "z": 2,
      "name": "Plant_Leaves_Aspen",
      "support": 15
    },
    {
      "x": -2,
      "y": 9,
      "z": 2,
      "name": "Plant_Leaves_Aspen",
      "support": 15
    },
    {
      "x": -2,
      "y": 0,
      "z": 3,
      "name": "Rock_Marble_Brick"
    },
    {
      "x": -2,
      "y": 1,
      "z": 3,
      "name": "Rock_Marble_Brick"
    },
    {
      "x": -2,
      "y": 5,
      "z": 3,
      "name": "Rock_Marble_Brick"
    },
    {
      "x": -2,
      "y": 6,
      "z": 3,
      "name": "Plant_Leaves_Aspen",
      "support": 15
    },
    {
      "x": -2,
      "y": 7,
      "z": 3,
      "name": "Plant_Leaves_Aspen",
      "support": 15
    },
    {
      "x": -1,
      "y": 0,
      "z": -4,
      "name": "Rock_Marble_Brick"
    },
    {
      "x": -1,
      "y": 1,
      "z": -4,
      "name": "Rock_Marble_Brick"
    },
    {
      "x": -1,
      "y": 2,
      "z": -4,
      "name": "Rock_Marble_Brick"
    },
    {
      "x": -1,
      "y": 3,
      "z": -4,
      "name": "Rock_Marble_Brick"
    },
    {
      "x": -1,
      "y": 4,
      "z": -4,
      "name": "Rock_Marble_Brick"
    },
    {
      "x": -1,
      "y": 9,
      "z": -4,
      "name": "Plant_Leaves_Aspen",
      "support": 15
    },
    {
      "x": -1,
      "y": 10,
      "z": -4,
      "name": "Plant_Leaves_Aspen",
      "support": 15
    },
    {
      "x": -1,
      "y": 13,
      "z": -4,
      "name": "Plant_Leaves_Aspen",
      "support": 15
    },
    {
      "x": -1,
      "y": 0,
      "z": -3,
      "name": "Rock_Marble_Brick"
    },
    {
      "x": -1,
      "y": 1,
      "z": -3,
      "name": "Rock_Marble_Brick"
    },
    {
      "x": -1,
      "y": 2,
      "z": -3,
      "name": "Rock_Marble_Brick_Smooth_Half",
      "rotation": 4
    },
    {
      "x": -1,
      "y": 3,
      "z": -3,
      "name": "Rock_Marble_Brick_Smooth_Half",
      "rotation": 4
    },
    {
      "x": -1,
      "y": 4,
      "z": -3,
      "name": "Rock_Marble_Brick_Smooth_Half",
      "rotation": 4
    },
    {
      "x": -1,
      "y": 5,
      "z": -3,
      "name": "Rock_Marble_Brick"
    },
    {
      "x": -1,
      "y": 7,
      "z": -3,
      "name": "Plant_Leaves_Aspen",
      "support": 15
    },
    {
      "x": -1,
      "y": 8,
      "z": -3,
      "name": "Plant_Leaves_Aspen",
      "support": 15
    },
    {
      "x": -1,
      "y": 9,
      "z": -3,
      "name": "Plant_Leaves_Aspen",
      "support": 15
    },
    {
      "x": -1,
      "y": 10,
      "z": -3,
      "name": "Plant_Leaves_Aspen",
      "support": 15
    },
    {
      "x": -1,
      "y": 11,
      "z": -3,
      "name": "Plant_Leaves_Aspen",
      "support": 15
    },
    {
      "x": -1,
      "y": 13,
      "z": -3,
      "name": "Plant_Leaves_Aspen",
      "support": 15
    },
    {
      "x": -1,
      "y": 0,
      "z": -2,
      "name": "Rock_Marble_Brick"
    },
    {
      "x": -1,
      "y": 1,
      "z": -2,
      "name": "Rock_Marble_Brick"
    },
    {
      "x": -1,
      "y": 5,
      "z": -2,
      "name": "Rock_Marble_Brick_Smooth_Half",
      "rotation": 8
    },
    {
      "x": -1,
      "y": 6,
      "z": -2,
      "name": "Rock_Marble_Brick"
    },
    {
      "x": -1,
      "y": 7,
      "z": -2,
      "name": "Rock_Marble_Brick_Smooth_Half"
    },
    {
      "x": -1,
      "y": 8,
      "z": -2,
      "name": "Rock_Marble_Brick"
    },
    {
      "x": -1,
      "y": 9,
      "z": -2,
      "name": "Plant_Leaves_Aspen",
      "support": 15
    },
    {
      "x": -1,
      "y": 10,
      "z": -2,
      "name": "Plant_Leaves_Aspen",
      "support": 15
    },
    {
      "x": -1,
      "y": 13,
      "z": -2,
      "name": "Plant_Leaves_Aspen",
      "support": 15
    },
    {
      "x": -1,
      "y": 14,
      "z": -2,
      "name": "Plant_Leaves_Aspen",
      "support": 15
    },
    {
      "x": -1,
      "y": 0,
      "z": -1,
      "name": "Rock_Marble_Brick"
    },
    {
      "x": -1,
      "y": 1,
      "z": -1,
      "name": "Rock_Marble_SkyGrass"
    },
    {
      "x": -1,
      "y": 5,
      "z": -1,
      "name": "Rock_Marble_Brick"
    },
    {
      "x": -1,
      "y": 6,
      "z": -1,
      "name": "Rock_Marble_Brick"
    },
    {
      "x": -1,
      "y": 7,
      "z": -1,
      "name": "Rock_Marble_Brick"
    },
    {
      "x": -1,
      "y": 8,
      "z": -1,
      "name": "Rock_Marble_Brick"
    },
    {
      "x": -1,
      "y": 9,
      "z": -1,
      "name": "Plant_Leaves_Aspen",
      "support": 15
    },
    {
      "x": -1,
      "y": 10,
      "z": -1,
      "name": "Plant_Leaves_Aspen",
      "support": 15
    },
    {
      "x": -1,
      "y": 13,
      "z": -1,
      "name": "Plant_Leaves_Aspen",
      "support": 15
    },
    {
      "x": -1,
      "y": 0,
      "z": 0,
      "name": "Rock_Marble_Brick"
    },
    {
      "x": -1,
      "y": 1,
      "z": 0,
      "name": "Rock_Marble_SkyGrass"
    },
    {
      "x": -1,
      "y": 4,
      "z": 0,
      "name": "Furniture_Ancient_Shelf",
      "rotation": 3
    },
    {
      "x": -1,
      "y": 6,
      "z": 0,
      "name": "Rock_Marble_SkyGrass"
    },
    {
      "x": -1,
      "y": 7,
      "z": 0,
      "name": "Plant_Bush_Sky",
      "support": 15
    },
    {
      "x": -1,
      "y": 9,
      "z": 0,
      "name": "Plant_Leaves_Aspen",
      "support": 15
    },
    {
      "x": -1,
      "y": 10,
      "z": 0,
      "name": "Plant_Leaves_Aspen",
      "support": 15
    },
    {
      "x": -1,
      "y": 0,
      "z": 1,
      "name": "Rock_Marble_Brick"
    },
    {
      "x": -1,
      "y": 1,
      "z": 1,
      "name": "Rock_Marble_SkyGrass"
    },
    {
      "x": -1,
      "y": 6,
      "z": 1,
      "name": "Rock_Marble_SkyGrass"
    },
    {
      "x": -1,
      "y": 9,
      "z": 1,
      "name": "Plant_Leaves_Aspen",
      "support": 15
    },
    {
      "x": -1,
      "y": 10,
      "z": 1,
      "name": "Plant_Leaves_Aspen",
      "support": 15
    },
    {
      "x": -1,
      "y": 0,
      "z": 2,
      "name": "Rock_Marble_Brick"
    },
    {
      "x": -1,
      "y": 1,
      "z": 2,
      "name": "Rock_Marble_Brick"
    },
    {
      "x": -1,
      "y": 6,
      "z": 2,
      "name": "Plant_Leaves_Aspen",
      "support": 15
    },
    {
      "x": -1,
      "y": 7,
      "z": 2,
      "name": "Plant_Bush_Sky",
      "support": 15
    },
    {
      "x": -1,
      "y": 0,
      "z": 3,
      "name": "Rock_Marble_Brick"
    },
    {
      "x": -1,
      "y": 1,
      "z": 3,
      "name": "Rock_Marble_Brick"
    },
    {
      "x": -1,
      "y": 2,
      "z": 3,
      "name": "Rock_Marble_Brick_Decorative"
    },
    {
      "x": -1,
      "y": 4,
      "z": 3,
      "name": "Rock_Marble_Brick_Smooth_Half",
      "rotation": 7
    },
    {
      "x": -1,
      "y": 5,
      "z": 3,
      "name": "Rock_Marble_Brick"
    },
    {
      "x": -1,
      "y": 6,
      "z": 3,
      "name": "Plant_Leaves_Aspen",
      "support": 15
    },
    {
      "x": -1,
      "y": 7,
      "z": 3,
      "name": "Plant_Grass_Sky_Long",
      "support": 15
    },
    {
      "x": -1,
      "y": 8,
      "z": 3,
      "name": "Plant_Grass_Sky_Long",
      "filler": 1024
    },
    {
      "x": 0,
      "y": 0,
      "z": -4,
      "name": "Rock_Marble_Brick"
    },
    {
      "x": 0,
      "y": 1,
      "z": -4,
      "name": "Rock_Marble_Brick"
    },
    {
      "x": 0,
      "y": 2,
      "z": -4,
      "name": "Rock_Marble_Brick"
    },
    {
      "x": 0,
      "y": 3,
      "z": -4,
      "name": "Rock_Marble_Brick"
    },
    {
      "x": 0,
      "y": 4,
      "z": -4,
      "name": "Rock_Marble_Brick_Smooth_Half",
      "rotation": 8
    },
    {
      "x": 0,
      "y": 0,
      "z": -3,
      "name": "Rock_Marble_Brick"
    },
    {
      "x": 0,
      "y": 1,
      "z": -3,
      "name": "Rock_Marble_Brick"
    },
    {
      "x": 0,
      "y": 2,
      "z": -3,
      "name": "Furniture_Crude_Chest_Small",
      "components": {
        "Components": {
          "PlacedByInteraction": {
            "WhoPlacedUuid": {
              "$binary": "rmwkrpH8RVykTc7XnK4YBA==",
              "$type": "04"
            }
          },
          "ItemContainerBlock": {
            "ItemContainer": {
              "Capacity": 18,
              "Items": {}
            },
            "Capacity": 18
          }
        }
      },
      "rotation": 1
    },
    {
      "x": 0,
      "y": 0,
      "z": -2,
      "name": "Rock_Marble_Brick"
    },
    {
      "x": 0,
      "y": 1,
      "z": -2,
      "name": "Rock_Marble_SkyGrass"
    },
    {
      "x": 0,
      "y": 2,
      "z": -2,
      "name": "Plant_Bush_Sky",
      "support": 15
    },
    {
      "x": 0,
      "y": 6,
      "z": -2,
      "name": "Rock_Marble_Brick_Smooth_Half"
    },
    {
      "x": 0,
      "y": 9,
      "z": -2,
      "name": "Plant_Leaves_Aspen",
      "support": 15
    },
    {
      "x": 0,
      "y": 0,
      "z": -1,
      "name": "Rock_Marble_Brick"
    },
    {
      "x": 0,
      "y": 1,
      "z": -1,
      "name": "Rock_Marble_SkyGrass"
    },
    {
      "x": 0,
      "y": 2,
      "z": -1,
      "name": "Plant_Grass_Sky_Long",
      "support": 15
    },
    {
      "x": 0,
      "y": 3,
      "z": -1,
      "name": "Plant_Grass_Sky_Long",
      "filler": 1024
    },
    {
      "x": 0,
      "y": 6,
      "z": -1,
      "name": "Rock_Marble_Brick_Smooth_Half"
    },
    {
      "x": 0,
      "y": 9,
      "z": -1,
      "name": "Plant_Leaves_Aspen",
      "support": 15
    },
    {
      "x": 0,
      "y": 0,
      "z": 0,
      "name": "Rock_Marble_Brick"
    },
    {
      "x": 0,
      "y": 1,
      "z": 0,
      "name": "Rock_Marble_Brick"
    },
    {
      "x": 0,
      "y": 4,
      "z": 0,
      "name": "Rock_Marble_Brick"
    },
    {
      "x": 0,
      "y": 5,
      "z": 0,
      "name": "Rock_Marble_Brick"
    },
    {
      "x": 0,
      "y": 6,
      "z": 0,
      "name": "Rock_Marble_Brick"
    },
    {
      "x": 0,
      "y": 0,
      "z": 1,
      "name": "Rock_Marble_Brick"
    },
    {
      "x": 0,
      "y": 1,
      "z": 1,
      "name": "Rock_Marble_Brick"
    },
    {
      "x": 0,
      "y": 5,
      "z": 1,
      "name": "Rock_Marble_Brick"
    },
    {
      "x": 0,
      "y": 6,
      "z": 1,
      "name": "Rock_Marble_SkyGrass"
    },
    {
      "x": 0,
      "y": 0,
      "z": 2,
      "name": "Rock_Marble_Brick"
    },
    {
      "x": 0,
      "y": 1,
      "z": 2,
      "name": "Rock_Marble_Brick"
    },
    {
      "x": 0,
      "y": 5,
      "z": 2,
      "name": "Rock_Marble_Brick"
    },
    {
      "x": 0,
      "y": 6,
      "z": 2,
      "name": "Rock_Marble_SkyGrass"
    },
    {
      "x": 0,
      "y": 7,
      "z": 2,
      "name": "Plant_Grass_Sky_Long",
      "support": 15
    },
    {
      "x": 0,
      "y": 8,
      "z": 2,
      "name": "Plant_Grass_Sky_Long",
      "filler": 1024
    },
    {
      "x": 0,
      "y": 0,
      "z": 3,
      "name": "Rock_Marble_Brick"
    },
    {
      "x": 0,
      "y": 1,
      "z": 3,
      "name": "Rock_Marble_Brick"
    },
    {
      "x": 0,
      "y": 2,
      "z": 3,
      "name": "Rock_Marble_Brick"
    },
    {
      "x": 0,
      "y": 3,
      "z": 3,
      "name": "Rock_Marble_Brick"
    },
    {
      "x": 0,
      "y": 4,
      "z": 3,
      "name": "Rock_Marble_Brick"
    },
    {
      "x": 0,
      "y": 5,
      "z": 3,
      "name": "Rock_Marble_SkyGrass"
    },
    {
      "x": 0,
      "y": 6,
      "z": 3,
      "name": "Plant_Grass_Sky_Long",
      "support": 15
    },
    {
      "x": 0,
      "y": 7,
      "z": 3,
      "name": "Plant_Grass_Sky_Long",
      "filler": 1024
    },
    {
      "x": 1,
      "y": 0,
      "z": -4,
      "name": "Rock_Marble_Brick"
    },
    {
      "x": 1,
      "y": 1,
      "z": -4,
      "name": "Rock_Marble_Brick"
    },
    {
      "x": 1,
      "y": 2,
      "z": -4,
      "name": "Rock_Marble_Brick"
    },
    {
      "x": 1,
      "y": 3,
      "z": -4,
      "name": "Rock_Marble_Brick_Decorative"
    },
    {
      "x": 1,
      "y": 0,
      "z": -3,
      "name": "Rock_Marble_Brick"
    },
    {
      "x": 1,
      "y": 1,
      "z": -3,
      "name": "Rock_Marble_Brick"
    },
    {
      "x": 1,
      "y": 0,
      "z": -2,
      "name": "Rock_Marble_Brick"
    },
    {
      "x": 1,
      "y": 1,
      "z": -2,
      "name": "Rock_Marble_Brick_Smooth_Half"
    },
    {
      "x": 1,
      "y": 0,
      "z": -1,
      "name": "Rock_Marble_Brick"
    },
    {
      "x": 1,
      "y": 1,
      "z": -1,
      "name": "Rock_Marble_Brick"
    },
    {
      "x": 1,
      "y": 6,
      "z": -1,
      "name": "Rock_Marble_Brick_Smooth_Half"
    },
    {
      "x": 1,
      "y": 0,
      "z": 0,
      "name": "Rock_Marble_Brick"
    },
    {
      "x": 1,
      "y": 1,
      "z": 0,
      "name": "Rock_Marble_Brick"
    },
    {
      "x": 1,
      "y": 2,
      "z": 0,
      "name": "Rock_Marble_Brick"
    },
    {
      "x": 1,
      "y": 3,
      "z": 0,
      "name": "Rock_Marble_Brick"
    },
    {
      "x": 1,
      "y": 4,
      "z": 0,
      "name": "Rock_Marble_Brick_Smooth_Half",
      "rotation": 8
    },
    {
      "x": 1,
      "y": 5,
      "z": 0,
      "name": "Rock_Marble_Brick"
    },
    {
      "x": 1,
      "y": 6,
      "z": 0,
      "name": "Rock_Marble_Brick"
    },
    {
      "x": 1,
      "y": 0,
      "z": 1,
      "name": "Rock_Marble_Brick"
    },
    {
      "x": 1,
      "y": 1,
      "z": 1,
      "name": "Rock_Marble_Brick"
    },
    {
      "x": 1,
      "y": 0,
      "z": 2,
      "name": "Rock_Marble_Brick"
    },
    {
      "x": 2,
      "y": 0,
      "z": -4,
      "name": "Rock_Marble_Brick"
    },
    {
      "x": 2,
      "y": 1,
      "z": -4,
      "name": "Rock_Marble_Brick"
    },
    {
      "x": 2,
      "y": 2,
      "z": -4,
      "name": "Rock_Marble_Brick"
    },
    {
      "x": 2,
      "y": 3,
      "z": -4,
      "name": "Rock_Marble_Brick"
    },
    {
      "x": 2,
      "y": 4,
      "z": -4,
      "name": "Rock_Marble_Brick_Smooth_Half"
    },
    {
      "x": 2,
      "y": 0,
      "z": -3,
      "name": "Rock_Marble_Brick"
    },
    {
      "x": 2,
      "y": 1,
      "z": -3,
      "name": "Furniture_Temple_Light_Pot"
    },
    {
      "x": 2,
      "y": 0,
      "z": -2,
      "name": "Rock_Marble_Brick"
    },
    {
      "x": 2,
      "y": 1,
      "z": -2,
      "name": "Rock_Marble_Brick_Smooth_Half"
    },
    {
      "x": 2,
      "y": 0,
      "z": -1,
      "name": "Rock_Marble_Brick"
    },
    {
      "x": 2,
      "y": 0,
      "z": 0,
      "name": "Rock_Marble_Brick"
    },
    {
      "x": 2,
      "y": 1,
      "z": 0,
      "name": "Rock_Marble_Brick"
    },
    {
      "x": 2,
      "y": 2,
      "z": 0,
      "name": "Furniture_Temple_Light_Door"
    },
    {
      "x": 2,
      "y": 3,
      "z": 0,
      "name": "Furniture_Temple_Light_Door",
      "filler": 1024
    },
    {
      "x": 2,
      "y": 4,
      "z": 0,
      "name": "Rock_Marble_Brick"
    },
    {
      "x": 2,
      "y": 5,
      "z": 0,
      "name": "Rock_Marble_Brick"
    },
    {
      "x": 2,
      "y": 0,
      "z": 1,
      "name": "Rock_Marble_Brick"
    },
    {
      "x": 2,
      "y": 1,
      "z": 1,
      "name": "Rock_Marble_Brick"
    },
    {
      "x": 2,
      "y": 0,
      "z": 2,
      "name": "Rock_Marble_Brick"
    },
    {
      "x": 2,
      "y": 1,
      "z": 2,
      "name": "Rock_Marble_Brick"
    },
    {
      "x": 3,
      "y": 0,
      "z": -4,
      "name": "Rock_Marble_Brick"
    },
    {
      "x": 3,
      "y": 1,
      "z": -4,
      "name": "Rock_Marble_Brick"
    },
    {
      "x": 3,
      "y": 2,
      "z": -4,
      "name": "Rock_Marble_Brick"
    },
    {
      "x": 3,
      "y": 3,
      "z": -4,
      "name": "Rock_Marble_Brick"
    },
    {
      "x": 3,
      "y": 4,
      "z": -4,
      "name": "Rock_Marble_Brick"
    },
    {
      "x": 3,
      "y": 5,
      "z": -4,
      "name": "Rock_Marble_Brick"
    },
    {
      "x": 3,
      "y": 6,
      "z": -4,
      "name": "Rock_Marble_Brick"
    },
    {
      "x": 3,
      "y": 0,
      "z": -3,
      "name": "Rock_Marble_Brick"
    },
    {
      "x": 3,
      "y": 1,
      "z": -3,
      "name": "Rock_Marble_Brick_Smooth_Half"
    },
    {
      "x": 3,
      "y": 3,
      "z": -3,
      "name": "Furniture_Ancient_Shelf"
    },
    {
      "x": 3,
      "y": 4,
      "z": -3,
      "name": "Furniture_Ancient_Shelf"
    },
    {
      "x": 3,
      "y": 6,
      "z": -3,
      "name": "Rock_Marble_Brick_Smooth_Half"
    },
    {
      "x": 3,
      "y": 0,
      "z": -2,
      "name": "Rock_Marble_Brick"
    },
    {
      "x": 3,
      "y": 1,
      "z": -2,
      "name": "Furniture_Temple_Light_Pot"
    },
    {
      "x": 3,
      "y": 6,
      "z": -2,
      "name": "Rock_Marble_Brick_Smooth_Half"
    },
    {
      "x": 3,
      "y": 0,
      "z": -1,
      "name": "Rock_Marble_Brick"
    },
    {
      "x": 3,
      "y": 1,
      "z": -1,
      "name": "Rock_Marble_Brick"
    },
    {
      "x": 3,
      "y": 2,
      "z": -1,
      "name": "Furniture_Temple_Light_Pot"
    },
    {
      "x": 3,
      "y": 0,
      "z": 0,
      "name": "Rock_Marble_Brick"
    },
    {
      "x": 3,
      "y": 1,
      "z": 0,
      "name": "Rock_Marble_Brick"
    },
    {
      "x": 3,
      "y": 2,
      "z": 0,
      "name": "Rock_Marble_Brick"
    },
    {
      "x": 3,
      "y": 4,
      "z": 0,
      "name": "Rock_Marble_Brick"
    },
    {
      "x": 3,
      "y": 0,
      "z": 1,
      "name": "Rock_Marble_Brick"
    },
    {
      "x": 3,
      "y": 1,
      "z": 1,
      "name": "Rock_Marble_Brick"
    },
    {
      "x": 3,
      "y": 0,
      "z": 2,
      "name": "Rock_Marble_Brick"
    },
    {
      "x": 3,
      "y": 1,
      "z": 2,
      "name": "Rock_Marble_Brick"
    },
    {
      "x": 4,
      "y": 0,
      "z": -4,
      "name": "Rock_Marble_Brick"
    },
    {
      "x": 4,
      "y": 1,
      "z": -4,
      "name": "Rock_Marble_Brick"
    },
    {
      "x": 4,
      "y": 2,
      "z": -4,
      "name": "Rock_Marble_Brick"
    },
    {
      "x": 4,
      "y": 3,
      "z": -4,
      "name": "Rock_Marble_Brick"
    },
    {
      "x": 4,
      "y": 4,
      "z": -4,
      "name": "Rock_Marble_Brick"
    },
    {
      "x": 4,
      "y": 5,
      "z": -4,
      "name": "Rock_Marble_Brick"
    },
    {
      "x": 4,
      "y": 6,
      "z": -4,
      "name": "Rock_Marble_Brick"
    },
    {
      "x": 4,
      "y": 0,
      "z": -3,
      "name": "Rock_Marble_Brick"
    },
    {
      "x": 4,
      "y": 1,
      "z": -3,
      "name": "Rock_Marble_Brick"
    },
    {
      "x": 4,
      "y": 2,
      "z": -3,
      "name": "Rock_Marble_Brick_Decorative"
    },
    {
      "x": 4,
      "y": 3,
      "z": -3,
      "name": "Rock_Marble_Brick"
    },
    {
      "x": 4,
      "y": 4,
      "z": -3,
      "name": "Rock_Marble_Brick_Smooth_Half"
    },
    {
      "x": 4,
      "y": 5,
      "z": -3,
      "name": "Rock_Marble_Brick"
    },
    {
      "x": 4,
      "y": 6,
      "z": -3,
      "name": "Rock_Marble_Brick"
    },
    {
      "x": 4,
      "y": 0,
      "z": -2,
      "name": "Rock_Marble_Brick"
    },
    {
      "x": 4,
      "y": 1,
      "z": -2,
      "name": "Rock_Marble_Brick"
    },
    {
      "x": 4,
      "y": 2,
      "z": -2,
      "name": "Rock_Marble_Brick"
    },
    {
      "x": 4,
      "y": 3,
      "z": -2,
      "name": "Rock_Marble_Brick"
    },
    {
      "x": 4,
      "y": 4,
      "z": -2,
      "name": "Rock_Marble_Brick_Decorative"
    },
    {
      "x": 4,
      "y": 5,
      "z": -2,
      "name": "Rock_Marble_Brick_Smooth_Half",
      "rotation": 8
    },
    {
      "x": 4,
      "y": 6,
      "z": -2,
      "name": "Rock_Marble_Brick"
    },
    {
      "x": 4,
      "y": 0,
      "z": -1,
      "name": "Rock_Marble_Brick"
    },
    {
      "x": 4,
      "y": 1,
      "z": -1,
      "name": "Rock_Marble_Brick"
    },
    {
      "x": 4,
      "y": 2,
      "z": -1,
      "name": "Rock_Marble_Brick"
    },
    {
      "x": 4,
      "y": 3,
      "z": -1,
      "name": "Rock_Marble_Brick_Smooth_Half"
    },
    {
      "x": 4,
      "y": 4,
      "z": -1,
      "name": "Rock_Marble_Brick"
    },
    {
      "x": 4,
      "y": 5,
      "z": -1,
      "name": "Rock_Marble_Brick"
    },
    {
      "x": 4,
      "y": 6,
      "z": -1,
      "name": "Rock_Marble_Brick"
    },
    {
      "x": 4,
      "y": 0,
      "z": 0,
      "name": "Rock_Marble_Brick"
    },
    {
      "x": 4,
      "y": 1,
      "z": 0,
      "name": "Rock_Marble_Brick"
    },
    {
      "x": 4,
      "y": 2,
      "z": 0,
      "name": "Rock_Marble_Brick"
    },
    {
      "x": 4,
      "y": 3,
      "z": 0,
      "name": "Rock_Marble_Brick"
    },
    {
      "x": 4,
      "y": 4,
      "z": 0,
      "name": "Rock_Marble_Brick"
    },
    {
      "x": 4,
      "y": 0,
      "z": 1,
      "name": "Rock_Marble_Brick"
    },
    {
      "x": 4,
      "y": 1,
      "z": 1,
      "name": "Rock_Marble_Brick"
    }
  ]
}