{
  "version": 8,
  "blockIdVersion": 11,
  "anchorX": 0,
  "anchorY": 1,
  "anchorZ": 0,
  "blocks": [
    {
      "x": -5,
      "y": 6,
      "z": -2,
      "name": "Plant_Crop_Mushroom_Block_Blue"
    },
    {
      "x": -5,
      "y": 7,
      "z": -2,
      "name": "Plant_Crop_Mushroom_Block_Blue"
    },
    {
      "x": -5,
      "y": 5,
      "z": -1,
      "name": "Plant_Crop_Mushroom_Block_Blue_Mycelium"
    },
    {
      "x": -5,
      "y": 6,
      "z": -1,
      "name": "Plant_Crop_Mushroom_Block_Blue"
    },
    {
      "x": -5,
      "y": 7,
      "z": -1,
      "name": "Plant_Crop_Mushroom_Block_Blue"
    },
    {
      "x": -5,
      "y": 8,
      "z": -1,
      "name": "Plant_Crop_Mushroom_Block_Blue"
    },
    {
      "x": -5,
      "y": 5,
      "z": 0,
      "name": "Plant_Crop_Mushroom_Block_Blue_Mycelium"
    },
    {
      "x": -5,
      "y": 6,
      "z": 0,
      "name": "Plant_Crop_Mushroom_Block_Blue"
    },
    {
      "x": -5,
      "y": 7,
      "z": 0,
      "name": "Plant_Crop_Mushroom_Block_Blue"
    },
    {
      "x": -5,
      "y": 8,
      "z": 0,
      "name": "Plant_Crop_Mushroom_Block_Blue"
    },
    {
      "x": -5,
      "y": 5,
      "z": 1,
      "name": "Plant_Crop_Mushroom_Block_Blue_Mycelium"
    },
    {
      "x": -5,
      "y": 6,
      "z": 1,
      "name": "Plant_Crop_Mushroom_Block_Blue"
    },
    {
      "x": -5,
      "y": 7,
      "z": 1,
      "name": "Plant_Crop_Mushroom_Block_Blue"
    },
    {
      "x": -5,
      "y": 8,
      "z": 1,
      "name": "Plant_Crop_Mushroom_Block_Blue"
    },
    {
      "x": -5,
      "y": 6,
      "z": 2,
      "name": "Plant_Crop_Mushroom_Block_Blue"
    },
    {
      "x": -5,
      "y": 7,
      "z": 2,
      "name": "Plant_Crop_Mushroom_Block_Blue"
    },
    {
      "x": -4,
      "y": 5,
      "z": -3,
      "name": "Plant_Crop_Mushroom_Block_Blue_Mycelium"
    },
    {
      "x": -4,
      "y": 6,
      "z": -3,
      "name": "Plant_Crop_Mushroom_Block_Blue"
    },
    {
      "x": -4,
      "y": 7,
      "z": -3,
      "name": "Plant_Crop_Mushroom_Block_Blue"
    },
    {
      "x": -4,
      "y": 8,
      "z": -3,
      "name": "Plant_Crop_Mushroom_Block_Blue"
    },
    {
      "x": -4,
      "y": 6,
      "z": -2,
      "name": "Empty"
    },
    {
      "x": -4,
      "y": 7,
      "z": -2,
      "name": "Rock_Crystal_Cyan_Large",
      "rotation": 8
    },
    {
      "x": -4,
      "y": 8,
      "z": -2,
      "name": "Plant_Crop_Mushroom_Block_Blue"
    },
    {
      "x": -4,
      "y": 6,
      "z": -1,
      "name": "Empty"
    },
    {
      "x": -4,
      "y": 7,
      "z": -1,
      "name": "Empty"
    },
    {
      "x": -4,
      "y": 8,
      "z": -1,
      "name": "Rock_Crystal_Cyan_Medium",
      "rotation": 8
    },
    {
      "x": -4,
      "y": 9,
      "z": -1,
      "name": "Plant_Crop_Mushroom_Block_Blue"
    },
    {
      "x": -4,
      "y": 6,
      "z": 0,
      "name": "Empty"
    },
    {
      "x": -4,
      "y": 7,
      "z": 0,
      "name": "Empty"
    },
    {
      "x": -4,
      "y": 8,
      "z": 0,
      "name": "Plant_Crop_Mushroom_Block_Blue_Trunk"
    },
    {
      "x": -4,
      "y": 9,
      "z": 0,
      "name": "Plant_Crop_Mushroom_Block_Blue"
    },
    {
      "x": -4,
      "y": 6,
      "z": 1,
      "name": "Empty"
    },
    {
      "x": -4,
      "y": 7,
      "z": 1,
      "name": "Empty"
    },
    {
      "x": -4,
      "y": 8,
      "z": 1,
      "name": "Empty"
    },
    {
      "x": -4,
      "y": 9,
      "z": 1,
      "name": "Plant_Crop_Mushroom_Block_Blue"
    },
    {
      "x": -4,
      "y": 6,
      "z": 2,
      "name": "Empty"
    },
    {
      "x": -4,
      "y": 7,
      "z": 2,
      "name": "Empty"
    },
    {
      "x": -4,
      "y": 8,
      "z": 2,
      "name": "Plant_Crop_Mushroom_Block_Blue"
    },
    {
      "x": -4,
      "y": 6,
      "z": 3,
      "name": "Plant_Crop_Mushroom_Block_Blue"
    },
    {
      "x": -4,
      "y": 7,
      "z": 3,
      "name": "Plant_Crop_Mushroom_Block_Blue"
    },
    {
      "x": -4,
      "y": 8,
      "z": 3,
      "name": "Plant_Crop_Mushroom_Block_Blue"
    },
    {
      "x": -3,
      "y": 5,
      "z": -4,
      "name": "Plant_Crop_Mushroom_Block_Blue_Mycelium"
    },
    {
      "x": -3,
      "y": 6,
      "z": -4,
      "name": "Plant_Crop_Mushroom_Block_Blue"
    },
    {
      "x": -3,
      "y": 7,
      "z": -4,
      "name": "Plant_Crop_Mushroom_Block_Blue"
    },
    {
      "x": -3,
      "y": 8,
      "z": -4,
      "name": "Plant_Crop_Mushroom_Block_Blue"
    },
    {
      "x": -3,
      "y": 6,
      "z": -3,
      "name": "Empty"
    },
    {
      "x": -3,
      "y": 7,
      "z": -3,
      "name": "Empty"
    },
    {
      "x": -3,
      "y": 8,
      "z": -3,
      "name": "Plant_Crop_Mushroom_Block_Blue_Trunk"
    },
    {
      "x": -3,
      "y": 9,
      "z": -3,
      "name": "Plant_Crop_Mushroom_Block_Blue"
    },
    {
      "x": -3,
      "y": 6,
      "z": -2,
      "name": "Empty"
    },
    {
      "x": -3,
      "y": 7,
      "z": -2,
      "name": "Empty"
    },
    {
      "x": -3,
      "y": 8,
      "z": -2,
      "name": "Empty"
    },
    {
      "x": -3,
      "y": 9,
      "z": -2,
      "name": "Plant_Crop_Mushroom_Block_Blue"
    },
    {
      "x": -3,
      "y": 6,
      "z": -1,
      "name": "Empty"
    },
    {
      "x": -3,
      "y": 7,
      "z": -1,
      "name": "Empty"
    },
    {
      "x": -3,
      "y": 8,
      "z": -1,
      "name": "Empty"
    },
    {
      "x": -3,
      "y": 9,
      "z": -1,
      "name": "Plant_Crop_Mushroom_Block_Blue"
    },
    {
      "x": -3,
      "y": 6,
      "z": 0,
      "name": "Empty"
    },
    {
      "x": -3,
      "y": 7,
      "z": 0,
      "name": "Empty"
    },
    {
      "x": -3,
      "y": 8,
      "z": 0,
      "name": "Plant_Crop_Mushroom_Block_Blue_Trunk"
    },
    {
      "x": -3,
      "y": 9,
      "z": 0,
      "name": "Plant_Crop_Mushroom_Block_Blue"
    },
    {
      "x": -3,
      "y": 6,
      "z": 1,
      "name": "Empty"
    },
    {
      "x": -3,
      "y": 7,
      "z": 1,
      "name": "Empty"
    },
    {
      "x": -3,
      "y": 8,
      "z": 1,
      "name": "Rock_Crystal_Cyan_Large",
      "rotation": 8
    },
    {
      "x": -3,
      "y": 9,
      "z": 1,
      "name": "Plant_Crop_Mushroom_Block_Blue"
    },
    {
      "x": -3,
      "y": 6,
      "z": 2,
      "name": "Empty"
    },
    {
      "x": -3,
      "y": 7,
      "z": 2,
      "name": "Empty"
    },
    {
      "x": -3,
      "y": 8,
      "z": 2,
      "name": "Rock_Crystal_Cyan_Medium",
      "rotation": 8
    },
    {
      "x": -3,
      "y": 9,
      "z": 2,
      "name": "Plant_Crop_Mushroom_Block_Blue"
    },
    {
      "x": -3,
      "y": 6,
      "z": 3,
      "name": "Empty"
    },
    {
      "x": -3,
      "y": 7,
      "z": 3,
      "name": "Empty"
    },
    {
      "x": -3,
      "y": 8,
      "z": 3,
      "name": "Plant_Crop_Mushroom_Block_Blue_Trunk"
    },
    {
      "x": -3,
      "y": 9,
      "z": 3,
      "name": "Plant_Crop_Mushroom_Block_Blue"
    },
    {
      "x": -3,
      "y": 5,
      "z": 4,
      "name": "Plant_Crop_Mushroom_Block_Blue_Mycelium"
    },
    {
      "x": -3,
      "y": 6,
      "z": 4,
      "name": "Plant_Crop_Mushroom_Block_Blue"
    },
    {
      "x": -3,
      "y": 7,
      "z": 4,
      "name": "Plant_Crop_Mushroom_Block_Blue"
    },
    {
      "x": -3,
      "y": 8,
      "z": 4,
      "name": "Plant_Crop_Mushroom_Block_Blue"
    },
    {
      "x": -2,
      "y": 6,
      "z": -5,
      "name": "Plant_Crop_Mushroom_Block_Blue"
    },
    {
      "x": -2,
      "y": 7,
      "z": -5,
      "name": "Plant_Crop_Mushroom_Block_Blue"
    },
    {
      "x": -2,
      "y": 6,
      "z": -4,
      "name": "Empty"
    },
    {
      "x": -2,
      "y": 7,
      "z": -4,
      "name": "Empty"
    },
    {
      "x": -2,
      "y": 8,
      "z": -4,
      "name": "Plant_Crop_Mushroom_Block_Blue"
    },
    {
      "x": -2,
      "y": 6,
      "z": -3,
      "name": "Empty"
    },
    {
      "x": -2,
      "y": 7,
      "z": -3,
      "name": "Empty"
    },
    {
      "x": -2,
      "y": 8,
      "z": -3,
      "name": "Rock_Crystal_Cyan_Medium",
      "rotation": 8
    },
    {
      "x": -2,
      "y": 9,
      "z": -3,
      "name": "Plant_Crop_Mushroom_Block_Blue"
    },
    {
      "x": -2,
      "y": 6,
      "z": -2,
      "name": "Empty"
    },
    {
      "x": -2,
      "y": 7,
      "z": -2,
      "name": "Empty"
    },
    {
      "x": -2,
      "y": 8,
      "z": -2,
      "name": "Plant_Crop_Mushroom_Block_Blue_Trunk"
    },
    {
      "x": -2,
      "y": 9,
      "z": -2,
      "name": "Plant_Crop_Mushroom_Block_Blue"
    },
    {
      "x": -2,
      "y": 6,
      "z": -1,
      "name": "Empty"
    },
    {
      "x": -2,
      "y": 7,
      "z": -1,
      "name": "Empty"
    },
    {
      "x": -2,
      "y": 8,
      "z": -1,
      "name": "Empty"
    },
    {
      "x": -2,
      "y": 9,
      "z": -1,
      "name": "Rock_Crystal_Cyan_Large",
      "rotation": 8
    },
    {
      "x": -2,
      "y": 10,
      "z": -1,
      "name": "Plant_Crop_Mushroom_Block_Blue"
    },
    {
      "x": -2,
      "y": 2,
      "z": 0,
      "name": "Plant_Crop_Mushroom_Block_Blue_Mycelium"
    },
    {
      "x": -2,
      "y": 3,
      "z": 0,
      "name": "Plant_Crop_Mushroom_Block_Blue"
    },
    {
      "x": -2,
      "y": 6,
      "z": 0,
      "name": "Empty"
    },
    {
      "x": -2,
      "y": 7,
      "z": 0,
      "name": "Empty"
    },
    {
      "x": -2,
      "y": 8,
      "z": 0,
      "name": "Empty"
    },
    {
      "x": -2,
      "y": 9,
      "z": 0,
      "name": "Plant_Crop_Mushroom_Block_Blue_Trunk"
    },
    {
      "x": -2,
      "y": 10,
      "z": 0,
      "name": "Plant_Crop_Mushroom_Block_Blue"
    },
    {
      "x": -2,
      "y": 2,
      "z": 1,
      "name": "Plant_Crop_Mushroom_Block_Blue_Mycelium"
    },
    {
      "x": -2,
      "y": 3,
      "z": 1,
      "name": "Plant_Crop_Mushroom_Block_Blue"
    },
    {
      "x": -2,
      "y": 6,
      "z": 1,
      "name": "Empty"
    },
    {
      "x": -2,
      "y": 7,
      "z": 1,
      "name": "Empty"
    },
    {
      "x": -2,
      "y": 8,
      "z": 1,
      "name": "Empty"
    },
    {
      "x": -2,
      "y": 9,
      "z": 1,
      "name": "Empty"
    },
    {
      "x": -2,
      "y": 10,
      "z": 1,
      "name": "Plant_Crop_Mushroom_Block_Blue"
    },
    {
      "x": -2,
      "y": 3,
      "z": 2,
      "name": "Plant_Crop_Mushroom_Block_Blue"
    },
    {
      "x": -2,
      "y": 6,
      "z": 2,
      "name": "Empty"
    },
    {
      "x": -2,
      "y": 7,
      "z": 2,
      "name": "Empty"
    },
    {
      "x": -2,
      "y": 8,
      "z": 2,
      "name": "Plant_Crop_Mushroom_Block_Blue_Trunk"
    },
    {
      "x": -2,
      "y": 9,
      "z": 2,
      "name": "Plant_Crop_Mushroom_Block_Blue"
    },
    {
      "x": -2,
      "y": 6,
      "z": 3,
      "name": "Empty"
    },
    {
      "x": -2,
      "y": 7,
      "z": 3,
      "name": "Empty"
    },
    {
      "x": -2,
      "y": 8,
      "z": 3,
      "name": "Empty"
    },
    {
      "x": -2,
      "y": 9,
      "z": 3,
      "name": "Plant_Crop_Mushroom_Block_Blue"
    },
    {
      "x": -2,
      "y": 6,
      "z": 4,
      "name": "Empty"
    },
    {
      "x": -2,
      "y": 7,
      "z": 4,
      "name": "Empty"
    },
    {
      "x": -2,
      "y": 8,
      "z": 4,
      "name": "Plant_Crop_Mushroom_Block_Blue"
    },
    {
      "x": -2,
      "y": 6,
      "z": 5,
      "name": "Plant_Crop_Mushroom_Block_Blue"
    },
    {
      "x": -2,
      "y": 7,
      "z": 5,
      "name": "Plant_Crop_Mushroom_Block_Blue"
    },
    {
      "x": -1,
      "y": 6,
      "z": -5,
      "name": "Plant_Crop_Mushroom_Block_Blue"
    },
    {
      "x": -1,
      "y": 7,
      "z": -5,
      "name": "Plant_Crop_Mushroom_Block_Blue"
    },
    {
      "x": -1,
      "y": 8,
      "z": -5,
      "name": "Plant_Crop_Mushroom_Block_Blue"
    },
    {
      "x": -1,
      "y": 6,
      "z": -4,
      "name": "Empty"
    },
    {
      "x": -1,
      "y": 7,
      "z": -4,
      "name": "Empty"
    },
    {
      "x": -1,
      "y": 8,
      "z": -4,
      "name": "Rock_Crystal_Cyan_Large",
      "rotation": 8
    },
    {
      "x": -1,
      "y": 9,
      "z": -4,
      "name": "Plant_Crop_Mushroom_Block_Blue"
    },
    {
      "x": -1,
      "y": 6,
      "z": -3,
      "name": "Empty"
    },
    {
      "x": -1,
      "y": 7,
      "z": -3,
      "name": "Empty"
    },
    {
      "x": -1,
      "y": 8,
      "z": -3,
      "name": "Empty"
    },
    {
      "x": -1,
      "y": 9,
      "z": -3,
      "name": "Plant_Crop_Mushroom_Block_Blue"
    },
    {
      "x": -1,
      "y": 6,
      "z": -2,
      "name": "Empty"
    },
    {
      "x": -1,
      "y": 7,
      "z": -2,
      "name": "Empty"
    },
    {
      "x": -1,
      "y": 8,
      "z": -2,
      "name": "Empty"
    },
    {
      "x": -1,
      "y": 9,
      "z": -2,
      "name": "Empty"
    },
    {
      "x": -1,
      "y": 10,
      "z": -2,
      "name": "Plant_Crop_Mushroom_Block_Blue"
    },
    {
      "x": -1,
      "y": 5,
      "z": -1,
      "name": "Plant_Crop_Mushroom_Block_Blue_Mycelium"
    },
    {
      "x": -1,
      "y": 6,
      "z": -1,
      "name": "Plant_Crop_Mushroom_Block_Blue_Trunk"
    },
    {
      "x": -1,
      "y": 7,
      "z": -1,
      "name": "Plant_Crop_Mushroom_Block_Blue_Trunk"
    },
    {
      "x": -1,
      "y": 8,
      "z": -1,
      "name": "Plant_Crop_Mushroom_Block_Blue_Trunk"
    },
    {
      "x": -1,
      "y": 9,
      "z": -1,
      "name": "Plant_Crop_Mushroom_Block_Blue_Trunk"
    },
    {
      "x": -1,
      "y": 10,
      "z": -1,
      "name": "Plant_Crop_Mushroom_Block_Blue"
    },
    {
      "x": -1,
      "y": 1,
      "z": 0,
      "name": "Plant_Crop_Mushroom_Block_Blue_Trunk"
    },
    {
      "x": -1,
      "y": 3,
      "z": 0,
      "name": "Plant_Crop_Mushroom_Block_Blue"
    },
    {
      "x": -1,
      "y": 4,
      "z": 0,
      "name": "Plant_Crop_Mushroom_Block_Blue_Trunk"
    },
    {
      "x": -1,
      "y": 5,
      "z": 0,
      "name": "Plant_Crop_Mushroom_Block_Blue_Trunk"
    },
    {
      "x": -1,
      "y": 6,
      "z": 0,
      "name": "Plant_Crop_Mushroom_Block_Blue_Trunk"
    },
    {
      "x": -1,
      "y": 7,
      "z": 0,
      "name": "Plant_Crop_Mushroom_Block_Blue_Trunk"
    },
    {
      "x": -1,
      "y": 8,
      "z": 0,
      "name": "Plant_Crop_Mushroom_Block_Blue_Trunk"
    },
    {
      "x": -1,
      "y": 9,
      "z": 0,
      "name": "Plant_Crop_Mushroom_Block_Blue_Trunk"
    },
    {
      "x": -1,
      "y": 10,
      "z": 0,
      "name": "Plant_Crop_Mushroom_Block_Blue"
    },
    {
      "x": -1,
      "y": 1,
      "z": 1,
      "name": "Plant_Crop_Mushroom_Block_Blue_Trunk"
    },
    {
      "x": -1,
      "y": 2,
      "z": 1,
      "name": "Plant_Crop_Mushroom_Block_Blue_Trunk"
    },
    {
      "x": -1,
      "y": 3,
      "z": 1,
      "name": "Plant_Crop_Mushroom_Block_Blue_Trunk"
    },
    {
      "x": -1,
      "y": 4,
      "z": 1,
      "name": "Plant_Crop_Mushroom_Block_Blue_Trunk"
    },
    {
      "x": -1,
      "y": 6,
      "z": 1,
      "name": "Empty"
    },
    {
      "x": -1,
      "y": 7,
      "z": 1,
      "name": "Plant_Crop_Mushroom_Block_Blue_Trunk"
    },
    {
      "x": -1,
      "y": 8,
      "z": 1,
      "name": "Plant_Crop_Mushroom_Block_Blue_Trunk"
    },
    {
      "x": -1,
      "y": 9,
      "z": 1,
      "name": "Plant_Crop_Mushroom_Block_Blue_Trunk"
    },
    {
      "x": -1,
      "y": 10,
      "z": 1,
      "name": "Plant_Crop_Mushroom_Block_Blue"
    },
    {
      "x": -1,
      "y": 1,
      "z": 2,
      "name": "Plant_Crop_Mushroom_Block_Blue_Trunk"
    },
    {
      "x": -1,
      "y": 3,
      "z": 2,
      "name": "Plant_Crop_Mushroom_Block_Blue"
    },
    {
      "x": -1,
      "y": 6,
      "z": 2,
      "name": "Empty"
    },
    {
      "x": -1,
      "y": 7,
      "z": 2,
      "name": "Empty"
    },
    {
      "x": -1,
      "y": 8,
      "z": 2,
      "name": "Empty"
    },
    {
      "x": -1,
      "y": 9,
      "z": 2,
      "name": "Rock_Crystal_Cyan_Large",
      "rotation": 8
    },
    {
      "x": -1,
      "y": 10,
      "z": 2,
      "name": "Plant_Crop_Mushroom_Block_Blue"
    },
    {
      "x": -1,
      "y": 6,
      "z": 3,
      "name": "Empty"
    },
    {
      "x": -1,
      "y": 7,
      "z": 3,
      "name": "Empty"
    },
    {
      "x": -1,
      "y": 8,
      "z": 3,
      "name": "Rock_Crystal_Cyan_Medium",
      "rotation": 8
    },
    {
      "x": -1,
      "y": 9,
      "z": 3,
      "name": "Plant_Crop_Mushroom_Block_Blue"
    },
    {
      "x": -1,
      "y": 6,
      "z": 4,
      "name": "Empty"
    },
    {
      "x": -1,
      "y": 7,
      "z": 4,
      "name": "Empty"
    },
    {
      "x": -1,
      "y": 8,
      "z": 4,
      "name": "Rock_Crystal_Cyan_Large",
      "rotation": 8
    },
    {
      "x": -1,
      "y": 9,
      "z": 4,
      "name": "Plant_Crop_Mushroom_Block_Blue"
    },
    {
      "x": -1,
      "y": 6,
      "z": 5,
      "name": "Plant_Crop_Mushroom_Block_Blue"
    },
    {
      "x": -1,
      "y": 7,
      "z": 5,
      "name": "Plant_Crop_Mushroom_Block_Blue"
    },
    {
      "x": -1,
      "y": 8,
      "z": 5,
      "name": "Plant_Crop_Mushroom_Block_Blue"
    },
    {
      "x": 0,
      "y": 6,
      "z": -5,
      "name": "Plant_Crop_Mushroom_Block_Blue"
    },
    {
      "x": 0,
      "y": 7,
      "z": -5,
      "name": "Plant_Crop_Mushroom_Block_Blue"
    },
    {
      "x": 0,
      "y": 8,
      "z": -5,
      "name": "Plant_Crop_Mushroom_Block_Blue"
    },
    {
      "x": 0,
      "y": 6,
      "z": -4,
      "name": "Empty"
    },
    {
      "x": 0,
      "y": 7,
      "z": -4,
      "name": "Empty"
    },
    {
      "x": 0,
      "y": 8,
      "z": -4,
      "name": "Plant_Crop_Mushroom_Block_Blue_Trunk"
    },
    {
      "x": 0,
      "y": 9,
      "z": -4,
      "name": "Plant_Crop_Mushroom_Block_Blue"
    },
    {
      "x": 0,
      "y": 6,
      "z": -3,
      "name": "Empty"
    },
    {
      "x": 0,
      "y": 7,
      "z": -3,
      "name": "Empty"
    },
    {
      "x": 0,
      "y": 8,
      "z": -3,
      "name": "Plant_Crop_Mushroom_Block_Blue_Trunk"
    },
    {
      "x": 0,
      "y": 9,
      "z": -3,
      "name": "Plant_Crop_Mushroom_Block_Blue"
    },
    {
      "x": 0,
      "y": 6,
      "z": -2,
      "name": "Empty"
    },
    {
      "x": 0,
      "y": 7,
      "z": -2,
      "name": "Empty"
    },
    {
      "x": 0,
      "y": 8,
      "z": -2,
      "name": "Empty"
    },
    {
      "x": 0,
      "y": 9,
      "z": -2,
      "name": "Plant_Crop_Mushroom_Block_Blue_Trunk"
    },
    {
      "x": 0,
      "y": 10,
      "z": -2,
      "name": "Plant_Crop_Mushroom_Block_Blue"
    },
    {
      "x": 0,
      "y": 1,
      "z": -1,
      "name": "Plant_Crop_Mushroom_Block_Blue_Trunk"
    },
    {
      "x": 0,
      "y": 3,
      "z": -1,
      "name": "Plant_Crop_Mushroom_Block_Blue_Mycelium"
    },
    {
      "x": 0,
      "y": 4,
      "z": -1,
      "name": "Plant_Crop_Mushroom_Block_Blue_Trunk"
    },
    {
      "x": 0,
      "y": 5,
      "z": -1,
      "name": "Plant_Crop_Mushroom_Block_Blue_Trunk"
    },
    {
      "x": 0,
      "y": 6,
      "z": -1,
      "name": "Plant_Crop_Mushroom_Block_Blue_Trunk"
    },
    {
      "x": 0,
      "y": 7,
      "z": -1,
      "name": "Plant_Crop_Mushroom_Block_Blue_Trunk"
    },
    {
      "x": 0,
      "y": 8,
      "z": -1,
      "name": "Plant_Crop_Mushroom_Block_Blue_Trunk"
    },
    {
      "x": 0,
      "y": 9,
      "z": -1,
      "name": "Plant_Crop_Mushroom_Block_Blue_Trunk"
    },
    {
      "x": 0,
      "y": 10,
      "z": -1,
      "name": "Plant_Crop_Mushroom_Block_Blue"
    },
    {
      "x": 0,
      "y": 1,
      "z": 0,
      "name": "Plant_Crop_Mushroom_Block_Blue_Trunk"
    },
    {
      "x": 0,
      "y": 2,
      "z": 0,
      "name": "Plant_Crop_Mushroom_Block_Blue_Trunk"
    },
    {
      "x": 0,
      "y": 3,
      "z": 0,
      "name": "Plant_Crop_Mushroom_Block_Blue_Trunk"
    },
    {
      "x": 0,
      "y": 4,
      "z": 0,
      "name": "Plant_Crop_Mushroom_Block_Blue_Trunk"
    },
    {
      "x": 0,
      "y": 5,
      "z": 0,
      "name": "Plant_Crop_Mushroom_Block_Blue_Trunk"
    },
    {
      "x": 0,
      "y": 6,
      "z": 0,
      "name": "Plant_Crop_Mushroom_Block_Blue_Trunk"
    },
    {
      "x": 0,
      "y": 7,
      "z": 0,
      "name": "Plant_Crop_Mushroom_Block_Blue_Trunk"
    },
    {
      "x": 0,
      "y": 8,
      "z": 0,
      "name": "Plant_Crop_Mushroom_Block_Blue_Trunk"
    },
    {
      "x": 0,
      "y": 9,
      "z": 0,
      "name": "Plant_Crop_Mushroom_Block_Blue_Trunk"
    },
    {
      "x": 0,
      "y": 10,
      "z": 0,
      "name": "Plant_Crop_Mushroom_Block_Blue"
    },
    {
      "x": 0,
      "y": 1,
      "z": 1,
      "name": "Plant_Crop_Mushroom_Block_Blue_Trunk"
    },
    {
      "x": 0,
      "y": 2,
      "z": 1,
      "name": "Plant_Crop_Mushroom_Block_Blue_Trunk"
    },
    {
      "x": 0,
      "y": 3,
      "z": 1,
      "name": "Plant_Crop_Mushroom_Block_Blue_Trunk"
    },
    {
      "x": 0,
      "y": 4,
      "z": 1,
      "name": "Plant_Crop_Mushroom_Block_Blue_Trunk"
    },
    {
      "x": 0,
      "y": 5,
      "z": 1,
      "name": "Plant_Crop_Mushroom_Block_Blue_Trunk"
    },
    {
      "x": 0,
      "y": 6,
      "z": 1,
      "name": "Plant_Crop_Mushroom_Block_Blue_Trunk"
    },
    {
      "x": 0,
      "y": 7,
      "z": 1,
      "name": "Plant_Crop_Mushroom_Block_Blue_Trunk"
    },
    {
      "x": 0,
      "y": 8,
      "z": 1,
      "name": "Plant_Crop_Mushroom_Block_Blue_Trunk"
    },
    {
      "x": 0,
      "y": 9,
      "z": 1,
      "name": "Plant_Crop_Mushroom_Block_Blue_Trunk"
    },
    {
      "x": 0,
      "y": 10,
      "z": 1,
      "name": "Plant_Crop_Mushroom_Block_Blue"
    },
    {
      "x": 0,
      "y": 1,
      "z": 2,
      "name": "Plant_Crop_Mushroom_Block_Blue_Trunk"
    },
    {
      "x": 0,
      "y": 2,
      "z": 2,
      "name": "Plant_Crop_Mushroom_Block_Blue_Trunk"
    },
    {
      "x": 0,
      "y": 6,
      "z": 2,
      "name": "Empty"
    },
    {
      "x": 0,
      "y": 7,
      "z": 2,
      "name": "Empty"
    },
    {
      "x": 0,
      "y": 8,
      "z": 2,
      "name": "Empty"
    },
    {
      "x": 0,
      "y": 9,
      "z": 2,
      "name": "Plant_Crop_Mushroom_Block_Blue_Trunk"
    },
    {
      "x": 0,
      "y": 10,
      "z": 2,
      "name": "Plant_Crop_Mushroom_Block_Blue"
    },
    {
      "x": 0,
      "y": 6,
      "z": 3,
      "name": "Empty"
    },
    {
      "x": 0,
      "y": 7,
      "z": 3,
      "name": "Empty"
    },
    {
      "x": 0,
      "y": 8,
      "z": 3,
      "name": "Plant_Crop_Mushroom_Block_Blue_Trunk"
    },
    {
      "x": 0,
      "y": 9,
      "z": 3,
      "name": "Plant_Crop_Mushroom_Block_Blue"
    },
    {
      "x": 0,
      "y": 6,
      "z": 4,
      "name": "Empty"
    },
    {
      "x": 0,
      "y": 7,
      "z": 4,
      "name": "Empty"
    },
    {
      "x": 0,
      "y": 8,
      "z": 4,
      "name": "Plant_Crop_Mushroom_Block_Blue_Trunk"
    },
    {
      "x": 0,
      "y": 9,
      "z": 4,
      "name": "Plant_Crop_Mushroom_Block_Blue"
    },
    {
      "x": 0,
      "y": 5,
      "z": 5,
      "name": "Plant_Crop_Mushroom_Block_Blue_Mycelium"
    },
    {
      "x": 0,
      "y": 6,
      "z": 5,
      "name": "Plant_Crop_Mushroom_Block_Blue"
    },
    {
      "x": 0,
      "y": 7,
      "z": 5,
      "name": "Plant_Crop_Mushroom_Block_Blue"
    },
    {
      "x": 0,
      "y": 8,
      "z": 5,
      "name": "Plant_Crop_Mushroom_Block_Blue"
    },
    {
      "x": 1,
      "y": 5,
      "z": -5,
      "name": "Plant_Crop_Mushroom_Block_Blue_Mycelium"
    },
    {
      "x": 1,
      "y": 6,
      "z": -5,
      "name": "Plant_Crop_Mushroom_Block_Blue"
    },
    {
      "x": 1,
      "y": 7,
      "z": -5,
      "name": "Plant_Crop_Mushroom_Block_Blue"
    },
    {
      "x": 1,
      "y": 8,
      "z": -5,
      "name": "Plant_Crop_Mushroom_Block_Blue"
    },
    {
      "x": 1,
      "y": 6,
      "z": -4,
      "name": "Empty"
    },
    {
      "x": 1,
      "y": 7,
      "z": -4,
      "name": "Empty"
    },
    {
      "x": 1,
      "y": 8,
      "z": -4,
      "name": "Rock_Crystal_Cyan_Medium",
      "rotation": 8
    },
    {
      "x": 1,
      "y": 9,
      "z": -4,
      "name": "Plant_Crop_Mushroom_Block_Blue"
    },
    {
      "x": 1,
      "y": 6,
      "z": -3,
      "name": "Empty"
    },
    {
      "x": 1,
      "y": 7,
      "z": -3,
      "name": "Empty"
    },
    {
      "x": 1,
      "y": 8,
      "z": -3,
      "name": "Empty"
    },
    {
      "x": 1,
      "y": 9,
      "z": -3,
      "name": "Plant_Crop_Mushroom_Block_Blue"
    },
    {
      "x": 1,
      "y": 6,
      "z": -2,
      "name": "Empty"
    },
    {
      "x": 1,
      "y": 7,
      "z": -2,
      "name": "Empty"
    },
    {
      "x": 1,
      "y": 8,
      "z": -2,
      "name": "Empty"
    },
    {
      "x": 1,
      "y": 9,
      "z": -2,
      "name": "Rock_Crystal_Cyan_Medium",
      "rotation": 8
    },
    {
      "x": 1,
      "y": 10,
      "z": -2,
      "name": "Plant_Crop_Mushroom_Block_Blue"
    },
    {
      "x": 1,
      "y": 1,
      "z": -1,
      "name": "Plant_Crop_Mushroom_Block_Blue_Trunk"
    },
    {
      "x": 1,
      "y": 4,
      "z": -1,
      "name": "Plant_Crop_Mushroom_Block_Blue_Trunk"
    },
    {
      "x": 1,
      "y": 5,
      "z": -1,
      "name": "Plant_Crop_Mushroom_Block_Blue_Trunk"
    },
    {
      "x": 1,
      "y": 6,
      "z": -1,
      "name": "Plant_Crop_Mushroom_Block_Blue_Trunk"
    },
    {
      "x": 1,
      "y": 7,
      "z": -1,
      "name": "Plant_Crop_Mushroom_Block_Blue_Trunk"
    },
    {
      "x": 1,
      "y": 8,
      "z": -1,
      "name": "Plant_Crop_Mushroom_Block_Blue_Trunk"
    },
    {
      "x": 1,
      "y": 9,
      "z": -1,
      "name": "Plant_Crop_Mushroom_Block_Blue_Trunk"
    },
    {
      "x": 1,
      "y": 10,
      "z": -1,
      "name": "Plant_Crop_Mushroom_Block_Blue"
    },
    {
      "x": 1,
      "y": 1,
      "z": 0,
      "name": "Plant_Crop_Mushroom_Block_Blue_Trunk"
    },
    {
      "x": 1,
      "y": 2,
      "z": 0,
      "name": "Plant_Crop_Mushroom_Block_Blue_Trunk"
    },
    {
      "x": 1,
      "y": 3,
      "z": 0,
      "name": "Plant_Crop_Mushroom_Block_Blue_Trunk"
    },
    {
      "x": 1,
      "y": 4,
      "z": 0,
      "name": "Plant_Crop_Mushroom_Block_Blue_Trunk"
    },
    {
      "x": 1,
      "y": 6,
      "z": 0,
      "name": "Empty"
    },
    {
      "x": 1,
      "y": 7,
      "z": 0,
      "name": "Plant_Crop_Mushroom_Block_Blue_Trunk"
    },
    {
      "x": 1,
      "y": 8,
      "z": 0,
      "name": "Plant_Crop_Mushroom_Block_Blue_Trunk"
    },
    {
      "x": 1,
      "y": 9,
      "z": 0,
      "name": "Plant_Crop_Mushroom_Block_Blue_Trunk"
    },
    {
      "x": 1,
      "y": 10,
      "z": 0,
      "name": "Plant_Crop_Mushroom_Block_Blue"
    },
    {
      "x": 1,
      "y": 1,
      "z": 1,
      "name": "Plant_Crop_Mushroom_Block_Blue_Trunk"
    },
    {
      "x": 1,
      "y": 2,
      "z": 1,
      "name": "Plant_Crop_Mushroom_Block_Blue_Trunk"
    },
    {
      "x": 1,
      "y": 3,
      "z": 1,
      "name": "Plant_Crop_Mushroom_Block_Blue_Trunk"
    },
    {
      "x": 1,
      "y": 6,
      "z": 1,
      "name": "Empty"
    },
    {
      "x": 1,
      "y": 7,
      "z": 1,
      "name": "Empty"
    },
    {
      "x": 1,
      "y": 8,
      "z": 1,
      "name": "Plant_Crop_Mushroom_Block_Blue_Trunk"
    },
    {
      "x": 1,
      "y": 9,
      "z": 1,
      "name": "Plant_Crop_Mushroom_Block_Blue_Trunk"
    },
    {
      "x": 1,
      "y": 10,
      "z": 1,
      "name": "Plant_Crop_Mushroom_Block_Blue"
    },
    {
      "x": 1,
      "y": 1,
      "z": 2,
      "name": "Plant_Crop_Mushroom_Block_Blue_Trunk"
    },
    {
      "x": 1,
      "y": 6,
      "z": 2,
      "name": "Empty"
    },
    {
      "x": 1,
      "y": 7,
      "z": 2,
      "name": "Empty"
    },
    {
      "x": 1,
      "y": 8,
      "z": 2,
      "name": "Empty"
    },
    {
      "x": 1,
      "y": 9,
      "z": 2,
      "name": "Rock_Crystal_Cyan_Medium",
      "rotation": 8
    },
    {
      "x": 1,
      "y": 10,
      "z": 2,
      "name": "Plant_Crop_Mushroom_Block_Blue"
    },
    {
      "x": 1,
      "y": 6,
      "z": 3,
      "name": "Empty"
    },
    {
      "x": 1,
      "y": 7,
      "z": 3,
      "name": "Empty"
    },
    {
      "x": 1,
      "y": 8,
      "z": 3,
      "name": "Empty"
    },
    {
      "x": 1,
      "y": 9,
      "z": 3,
      "name": "Plant_Crop_Mushroom_Block_Blue"
    },
    {
      "x": 1,
      "y": 6,
      "z": 4,
      "name": "Empty"
    },
    {
      "x": 1,
      "y": 7,
      "z": 4,
      "name": "Empty"
    },
    {
      "x": 1,
      "y": 8,
      "z": 4,
      "name": "Rock_Crystal_Cyan_Medium",
      "rotation": 8
    },
    {
      "x": 1,
      "y": 9,
      "z": 4,
      "name": "Plant_Crop_Mushroom_Block_Blue"
    },
    {
      "x": 1,
      "y": 5,
      "z": 5,
      "name": "Plant_Crop_Mushroom_Block_Blue_Mycelium"
    },
    {
      "x": 1,
      "y": 6,
      "z": 5,
      "name": "Plant_Crop_Mushroom_Block_Blue"
    },
    {
      "x": 1,
      "y": 7,
      "z": 5,
      "name": "Plant_Crop_Mushroom_Block_Blue"
    },
    {
      "x": 1,
      "y": 8,
      "z": 5,
      "name": "Plant_Crop_Mushroom_Block_Blue"
    },
    {
      "x": 2,
      "y": 6,
      "z": -5,
      "name": "Plant_Crop_Mushroom_Block_Blue"
    },
    {
      "x": 2,
      "y": 7,
      "z": -5,
      "name": "Plant_Crop_Mushroom_Block_Blue"
    },
    {
      "x": 2,
      "y": 6,
      "z": -4,
      "name": "Empty"
    },
    {
      "x": 2,
      "y": 7,
      "z": -4,
      "name": "Empty"
    },
    {
      "x": 2,
      "y": 8,
      "z": -4,
      "name": "Plant_Crop_Mushroom_Block_Blue"
    },
    {
      "x": 2,
      "y": 6,
      "z": -3,
      "name": "Empty"
    },
    {
      "x": 2,
      "y": 7,
      "z": -3,
      "name": "Empty"
    },
    {
      "x": 2,
      "y": 8,
      "z": -3,
      "name": "Rock_Crystal_Cyan_Large",
      "rotation": 8
    },
    {
      "x": 2,
      "y": 9,
      "z": -3,
      "name": "Plant_Crop_Mushroom_Block_Blue"
    },
    {
      "x": 2,
      "y": 6,
      "z": -2,
      "name": "Empty"
    },
    {
      "x": 2,
      "y": 7,
      "z": -2,
      "name": "Empty"
    },
    {
      "x": 2,
      "y": 8,
      "z": -2,
      "name": "Empty"
    },
    {
      "x": 2,
      "y": 9,
      "z": -2,
      "name": "Plant_Crop_Mushroom_Block_Blue"
    },
    {
      "x": 2,
      "y": 6,
      "z": -1,
      "name": "Empty"
    },
    {
      "x": 2,
      "y": 7,
      "z": -1,
      "name": "Empty"
    },
    {
      "x": 2,
      "y": 8,
      "z": -1,
      "name": "Empty"
    },
    {
      "x": 2,
      "y": 9,
      "z": -1,
      "name": "Rock_Crystal_Cyan_Large",
      "rotation": 8
    },
    {
      "x": 2,
      "y": 10,
      "z": -1,
      "name": "Plant_Crop_Mushroom_Block_Blue"
    },
    {
      "x": 2,
      "y": 1,
      "z": 0,
      "name": "Plant_Crop_Mushroom_Block_Blue_Trunk"
    },
    {
      "x": 2,
      "y": 2,
      "z": 0,
      "name": "Plant_Crop_Mushroom_Block_Blue_Trunk"
    },
    {
      "x": 2,
      "y": 6,
      "z": 0,
      "name": "Empty"
    },
    {
      "x": 2,
      "y": 7,
      "z": 0,
      "name": "Empty"
    },
    {
      "x": 2,
      "y": 8,
      "z": 0,
      "name": "Empty"
    },
    {
      "x": 2,
      "y": 9,
      "z": 0,
      "name": "Plant_Crop_Mushroom_Block_Blue_Trunk"
    },
    {
      "x": 2,
      "y": 10,
      "z": 0,
      "name": "Plant_Crop_Mushroom_Block_Blue"
    },
    {
      "x": 2,
      "y": 6,
      "z": 1,
      "name": "Empty"
    },
    {
      "x": 2,
      "y": 7,
      "z": 1,
      "name": "Empty"
    },
    {
      "x": 2,
      "y": 8,
      "z": 1,
      "name": "Empty"
    },
    {
      "x": 2,
      "y": 9,
      "z": 1,
      "name": "Empty"
    },
    {
      "x": 2,
      "y": 10,
      "z": 1,
      "name": "Plant_Crop_Mushroom_Block_Blue"
    },
    {
      "x": 2,
      "y": 6,
      "z": 2,
      "name": "Empty"
    },
    {
      "x": 2,
      "y": 7,
      "z": 2,
      "name": "Empty"
    },
    {
      "x": 2,
      "y": 8,
      "z": 2,
      "name": "Plant_Crop_Mushroom_Block_Blue_Trunk"
    },
    {
      "x": 2,
      "y": 9,
      "z": 2,
      "name": "Plant_Crop_Mushroom_Block_Blue"
    },
    {
      "x": 2,
      "y": 6,
      "z": 3,
      "name": "Empty"
    },
    {
      "x": 2,
      "y": 7,
      "z": 3,
      "name": "Empty"
    },
    {
      "x": 2,
      "y": 8,
      "z": 3,
      "name": "Rock_Crystal_Cyan_Large",
      "rotation": 8
    },
    {
      "x": 2,
      "y": 9,
      "z": 3,
      "name": "Plant_Crop_Mushroom_Block_Blue"
    },
    {
      "x": 2,
      "y": 6,
      "z": 4,
      "name": "Empty"
    },
    {
      "x": 2,
      "y": 7,
      "z": 4,
      "name": "Empty"
    },
    {
      "x": 2,
      "y": 8,
      "z": 4,
      "name": "Plant_Crop_Mushroom_Block_Blue"
    },
    {
      "x": 2,
      "y": 5,
      "z": 5,
      "name": "Plant_Crop_Mushroom_Block_Blue_Mycelium"
    },
    {
      "x": 2,
      "y": 6,
      "z": 5,
      "name": "Plant_Crop_Mushroom_Block_Blue"
    },
    {
      "x": 2,
      "y": 7,
      "z": 5,
      "name": "Plant_Crop_Mushroom_Block_Blue"
    },
    {
      "x": 3,
      "y": 6,
      "z": -4,
      "name": "Plant_Crop_Mushroom_Block_Blue"
    },
    {
      "x": 3,
      "y": 7,
      "z": -4,
      "name": "Plant_Crop_Mushroom_Block_Blue"
    },
    {
      "x": 3,
      "y": 8,
      "z": -4,
      "name": "Plant_Crop_Mushroom_Block_Blue"
    },
    {
      "x": 3,
      "y": 6,
      "z": -3,
      "name": "Empty"
    },
    {
      "x": 3,
      "y": 7,
      "z": -3,
      "name": "Empty"
    },
    {
      "x": 3,
      "y": 8,
      "z": -3,
      "name": "Empty"
    },
    {
      "x": 3,
      "y": 9,
      "z": -3,
      "name": "Plant_Crop_Mushroom_Block_Blue"
    },
    {
      "x": 3,
      "y": 6,
      "z": -2,
      "name": "Empty"
    },
    {
      "x": 3,
      "y": 7,
      "z": -2,
      "name": "Empty"
    },
    {
      "x": 3,
      "y": 8,
      "z": -2,
      "name": "Empty"
    },
    {
      "x": 3,
      "y": 9,
      "z": -2,
      "name": "Plant_Crop_Mushroom_Block_Blue"
    },
    {
      "x": 3,
      "y": 6,
      "z": -1,
      "name": "Empty"
    },
    {
      "x": 3,
      "y": 7,
      "z": -1,
      "name": "Empty"
    },
    {
      "x": 3,
      "y": 8,
      "z": -1,
      "name": "Rock_Crystal_Cyan_Medium",
      "rotation": 8
    },
    {
      "x": 3,
      "y": 9,
      "z": -1,
      "name": "Plant_Crop_Mushroom_Block_Blue"
    },
    {
      "x": 3,
      "y": 6,
      "z": 0,
      "name": "Empty"
    },
    {
      "x": 3,
      "y": 7,
      "z": 0,
      "name": "Empty"
    },
    {
      "x": 3,
      "y": 8,
      "z": 0,
      "name": "Plant_Crop_Mushroom_Block_Blue_Trunk"
    },
    {
      "x": 3,
      "y": 9,
      "z": 0,
      "name": "Plant_Crop_Mushroom_Block_Blue"
    },
    {
      "x": 3,
      "y": 6,
      "z": 1,
      "name": "Empty"
    },
    {
      "x": 3,
      "y": 7,
      "z": 1,
      "name": "Empty"
    },
    {
      "x": 3,
      "y": 8,
      "z": 1,
      "name": "Rock_Crystal_Cyan_Large",
      "rotation": 8
    },
    {
      "x": 3,
      "y": 9,
      "z": 1,
      "name": "Plant_Crop_Mushroom_Block_Blue"
    },
    {
      "x": 3,
      "y": 6,
      "z": 2,
      "name": "Empty"
    },
    {
      "x": 3,
      "y": 7,
      "z": 2,
      "name": "Empty"
    },
    {
      "x": 3,
      "y": 8,
      "z": 2,
      "name": "Empty"
    },
    {
      "x": 3,
      "y": 9,
      "z": 2,
      "name": "Plant_Crop_Mushroom_Block_Blue"
    },
    {
      "x": 3,
      "y": 6,
      "z": 3,
      "name": "Empty"
    },
    {
      "x": 3,
      "y": 7,
      "z": 3,
      "name": "Empty"
    },
    {
      "x": 3,
      "y": 8,
      "z": 3,
      "name": "Plant_Crop_Mushroom_Block_Blue_Trunk"
    },
    {
      "x": 3,
      "y": 9,
      "z": 3,
      "name": "Plant_Crop_Mushroom_Block_Blue"
    },
    {
      "x": 3,
      "y": 5,
      "z": 4,
      "name": "Plant_Crop_Mushroom_Block_Blue_Mycelium"
    },
    {
      "x": 3,
      "y": 6,
      "z": 4,
      "name": "Plant_Crop_Mushroom_Block_Blue"
    },
    {
      "x": 3,
      "y": 7,
      "z": 4,
      "name": "Plant_Crop_Mushroom_Block_Blue"
    },
    {
      "x": 3,
      "y": 8,
      "z": 4,
      "name": "Plant_Crop_Mushroom_Block_Blue"
    },
    {
      "x": 4,
      "y": 5,
      "z": -3,
      "name": "Plant_Crop_Mushroom_Block_Blue_Mycelium"
    },
    {
      "x": 4,
      "y": 6,
      "z": -3,
      "name": "Plant_Crop_Mushroom_Block_Blue"
    },
    {
      "x": 4,
      "y": 7,
      "z": -3,
      "name": "Plant_Crop_Mushroom_Block_Blue"
    },
    {
      "x": 4,
      "y": 8,
      "z": -3,
      "name": "Plant_Crop_Mushroom_Block_Blue"
    },
    {
      "x": 4,
      "y": 6,
      "z": -2,
      "name": "Empty"
    },
    {
      "x": 4,
      "y": 7,
      "z": -2,
      "name": "Rock_Crystal_Cyan_Medium",
      "rotation": 8
    },
    {
      "x": 4,
      "y": 8,
      "z": -2,
      "name": "Plant_Crop_Mushroom_Block_Blue"
    },
    {
      "x": 4,
      "y": 6,
      "z": -1,
      "name": "Empty"
    },
    {
      "x": 4,
      "y": 7,
      "z": -1,
      "name": "Empty"
    },
    {
      "x": 4,
      "y": 8,
      "z": -1,
      "name": "Empty"
    },
    {
      "x": 4,
      "y": 9,
      "z": -1,
      "name": "Plant_Crop_Mushroom_Block_Blue"
    },
    {
      "x": 4,
      "y": 6,
      "z": 0,
      "name": "Empty"
    },
    {
      "x": 4,
      "y": 7,
      "z": 0,
      "name": "Empty"
    },
    {
      "x": 4,
      "y": 8,
      "z": 0,
      "name": "Plant_Crop_Mushroom_Block_Blue_Trunk"
    },
    {
      "x": 4,
      "y": 9,
      "z": 0,
      "name": "Plant_Crop_Mushroom_Block_Blue"
    },
    {
      "x": 4,
      "y": 6,
      "z": 1,
      "name": "Empty"
    },
    {
      "x": 4,
      "y": 7,
      "z": 1,
      "name": "Empty"
    },
    {
      "x": 4,
      "y": 8,
      "z": 1,
      "name": "Empty"
    },
    {
      "x": 4,
      "y": 9,
      "z": 1,
      "name": "Plant_Crop_Mushroom_Block_Blue"
    },
    {
      "x": 4,
      "y": 6,
      "z": 2,
      "name": "Empty"
    },
    {
      "x": 4,
      "y": 7,
      "z": 2,
      "name": "Rock_Crystal_Cyan_Medium",
      "rotation": 8
    },
    {
      "x": 4,
      "y": 8,
      "z": 2,
      "name": "Plant_Crop_Mushroom_Block_Blue"
    },
    {
      "x": 4,
      "y": 6,
      "z": 3,
      "name": "Plant_Crop_Mushroom_Block_Blue"
    },
    {
      "x": 4,
      "y": 7,
      "z": 3,
      "name": "Plant_Crop_Mushroom_Block_Blue"
    },
    {
      "x": 4,
      "y": 8,
      "z": 3,
      "name": "Plant_Crop_Mushroom_Block_Blue"
    },
    {
      "x": 5,
      "y": 5,
      "z": -2,
      "name": "Plant_Crop_Mushroom_Block_Blue_Mycelium"
    },
    {
      "x": 5,
      "y": 6,
      "z": -2,
      "name": "Plant_Crop_Mushroom_Block_Blue"
    },
    {
      "x": 5,
      "y": 7,
      "z": -2,
      "name": "Plant_Crop_Mushroom_Block_Blue"
    },
    {
      "x": 5,
      "y": 5,
      "z": -1,
      "name": "Plant_Crop_Mushroom_Block_Blue_Mycelium"
    },
    {
      "x": 5,
      "y": 6,
      "z": -1,
      "name": "Plant_Crop_Mushroom_Block_Blue"
    },
    {
      "x": 5,
      "y": 7,
      "z": -1,
      "name": "Plant_Crop_Mushroom_Block_Blue"
    },
    {
      "x": 5,
      "y": 8,
      "z": -1,
      "name": "Plant_Crop_Mushroom_Block_Blue"
    },
    {
      "x": 5,
      "y": 6,
      "z": 0,
      "name": "Plant_Crop_Mushroom_Block_Blue"
    },
    {
      "x": 5,
      "y": 7,
      "z": 0,
      "name": "Plant_Crop_Mushroom_Block_Blue"
    },
    {
      "x": 5,
      "y": 8,
      "z": 0,
      "name": "Plant_Crop_Mushroom_Block_Blue"
    },
    {
      "x": 5,
      "y": 6,
      "z": 1,
      "name": "Plant_Crop_Mushroom_Block_Blue"
    },
    {
      "x": 5,
      "y": 7,
      "z": 1,
      "name": "Plant_Crop_Mushroom_Block_Blue"
    },
    {
      "x": 5,
      "y": 8,
      "z": 1,
      "name": "Plant_Crop_Mushroom_Block_Blue"
    },
    {
      "x": 5,
      "y": 5,
      "z": 2,
      "name": "Plant_Crop_Mushroom_Block_Blue_Mycelium"
    },
    {
      "x": 5,
      "y": 6,
      "z": 2,
      "name": "Plant_Crop_Mushroom_Block_Blue"
    },
    {
      "x": 5,
      "y": 7,
      "z": 2,
      "name": "Plant_Crop_Mushroom_Block_Blue"
    }
  ],
  "fluids": [
    {
      "x": -5,
      "y": 5,
      "z": -1,
      "name": "Glow_Water_Source",
      "level": 1
    },
    {
      "x": -5,
      "y": 5,
      "z": 0,
      "name": "Glow_Water_Source",
      "level": 1
    },
    {
      "x": -5,
      "y": 5,
      "z": 1,
      "name": "Glow_Water_Source",
      "level": 1
    },
    {
      "x": -4,
      "y": 5,
      "z": -3,
      "name": "Glow_Water_Source",
      "level": 1
    },
    {
      "x": -3,
      "y": 5,
      "z": -4,
      "name": "Glow_Water_Source",
      "level": 1
    },
    {
      "x": -3,
      "y": 5,
      "z": 4,
      "name": "Glow_Water_Source",
      "level": 1
    },
    {
      "x": -2,
      "y": 2,
      "z": 0,
      "name": "Glow_Water_Source",
      "level": 1
    },
    {
      "x": -2,
      "y": 2,
      "z": 1,
      "name": "Glow_Water_Source",
      "level": 1
    },
    {
      "x": -1,
      "y": 5,
      "z": -1,
      "name": "Glow_Water_Source",
      "level": 1
    },
    {
      "x": 0,
      "y": 3,
      "z": -1,
      "name": "Glow_Water_Source",
      "level": 1
    },
    {
      "x": 0,
      "y": 5,
      "z": 5,
      "name": "Glow_Water_Source",
      "level": 1
    },
    {
      "x": 1,
      "y": 5,
      "z": -5,
      "name": "Glow_Water_Source",
      "level": 1
    },
    {
      "x": 1,
      "y": 5,
      "z": 5,
      "name": "Glow_Water_Source",
      "level": 1
    },
    {
      "x": 2,
      "y": 5,
      "z": 5,
      "name": "Glow_Water_Source",
      "level": 1
    },
    {
      "x": 3,
      "y": 5,
      "z": 4,
      "name": "Glow_Water_Source",
      "level": 1
    },
    {
      "x": 4,
      "y": 5,
      "z": -3,
      "name": "Glow_Water_Source",
      "level": 1
    },
    {
      "x": 5,
      "y": 5,
      "z": -2,
      "name": "Glow_Water_Source",
      "level": 1
    },
    {
      "x": 5,
      "y": 5,
      "z": -1,
      "name": "Glow_Water_Source",
      "level": 1
    },
    {
      "x": 5,
      "y": 5,
      "z": 2,
      "name": "Glow_Water_Source",
      "level": 1
    }
  ]
}