{
  "version": 8,
  "blockIdVersion": 11,
  "anchorX": 0,
  "anchorY": 0,
  "anchorZ": 3,
  "blocks": [
    {
      "x": -10,
      "y": 9,
      "z": -5,
      "name": "Plant_Leaves_Aspen"
    },
    {
      "x": -10,
      "y": 10,
      "z": -5,
      "name": "Plant_Leaves_Aspen"
    },
    {
      "x": -10,
      "y": 11,
      "z": -5,
      "name": "Plant_Leaves_Aspen"
    },
    {
      "x": -10,
      "y": 9,
      "z": -4,
      "name": "Plant_Leaves_Aspen"
    },
    {
      "x": -10,
      "y": 10,
      "z": -4,
      "name": "Plant_Leaves_Aspen"
    },
    {
      "x": -10,
      "y": 11,
      "z": -4,
      "name": "Plant_Leaves_Aspen"
    },
    {
      "x": -10,
      "y": 9,
      "z": -3,
      "name": "Plant_Leaves_Aspen"
    },
    {
      "x": -10,
      "y": 10,
      "z": -3,
      "name": "Plant_Leaves_Aspen"
    },
    {
      "x": -9,
      "y": 9,
      "z": -6,
      "name": "Plant_Leaves_Aspen"
    },
    {
      "x": -9,
      "y": 10,
      "z": -6,
      "name": "Plant_Leaves_Aspen"
    },
    {
      "x": -9,
      "y": 11,
      "z": -6,
      "name": "Plant_Leaves_Aspen"
    },
    {
      "x": -9,
      "y": 9,
      "z": -5,
      "name": "Plant_Leaves_Aspen"
    },
    {
      "x": -9,
      "y": 10,
      "z": -5,
      "name": "Wood_Birch_Branch_Long",
      "rotation": 4
    },
    {
      "x": -9,
      "y": 11,
      "z": -5,
      "name": "Plant_Leaves_Aspen"
    },
    {
      "x": -9,
      "y": 7,
      "z": -4,
      "name": "Wood_Birch_Branch_Corner",
      "rotation": 3
    },
    {
      "x": -9,
      "y": 8,
      "z": -4,
      "name": "Wood_Birch_Branch_Long"
    },
    {
      "x": -9,
      "y": 9,
      "z": -4,
      "name": "Wood_Birch_Branch_Long"
    },
    {
      "x": -9,
      "y": 10,
      "z": -4,
      "name": "Wood_Birch_Branch_Corner",
      "rotation": 10
    },
    {
      "x": -9,
      "y": 11,
      "z": -4,
      "name": "Plant_Leaves_Aspen"
    },
    {
      "x": -9,
      "y": 7,
      "z": -3,
      "name": "Plant_Leaves_Aspen"
    },
    {
      "x": -9,
      "y": 8,
      "z": -3,
      "name": "Plant_Leaves_Aspen"
    },
    {
      "x": -9,
      "y": 9,
      "z": -3,
      "name": "Plant_Leaves_Aspen"
    },
    {
      "x": -9,
      "y": 10,
      "z": -3,
      "name": "Plant_Leaves_Aspen"
    },
    {
      "x": -9,
      "y": 11,
      "z": -3,
      "name": "Plant_Leaves_Aspen"
    },
    {
      "x": -9,
      "y": 10,
      "z": -2,
      "name": "Plant_Leaves_Aspen"
    },
    {
      "x": -8,
      "y": 10,
      "z": -6,
      "name": "Plant_Leaves_Aspen"
    },
    {
      "x": -8,
      "y": 10,
      "z": -5,
      "name": "Plant_Leaves_Aspen"
    },
    {
      "x": -8,
      "y": 11,
      "z": -5,
      "name": "Plant_Leaves_Aspen"
    },
    {
      "x": -8,
      "y": 7,
      "z": -4,
      "name": "Wood_Birch_Branch_Long",
      "rotation": 5
    },
    {
      "x": -8,
      "y": 10,
      "z": -4,
      "name": "Plant_Leaves_Aspen"
    },
    {
      "x": -8,
      "y": 11,
      "z": -4,
      "name": "Plant_Leaves_Aspen"
    },
    {
      "x": -8,
      "y": 11,
      "z": -3,
      "name": "Plant_Leaves_Aspen"
    },
    {
      "x": -8,
      "y": 12,
      "z": -3,
      "name": "Plant_Leaves_Aspen"
    },
    {
      "x": -8,
      "y": 11,
      "z": -2,
      "name": "Plant_Leaves_Aspen"
    },
    {
      "x": -7,
      "y": 10,
      "z": -6,
      "name": "Plant_Leaves_Aspen"
    },
    {
      "x": -7,
      "y": 12,
      "z": -6,
      "name": "Plant_Leaves_Aspen"
    },
    {
      "x": -7,
      "y": 13,
      "z": -6,
      "name": "Plant_Leaves_Aspen"
    },
    {
      "x": -7,
      "y": 9,
      "z": -5,
      "name": "Plant_Leaves_Aspen"
    },
    {
      "x": -7,
      "y": 10,
      "z": -5,
      "name": "Plant_Leaves_Aspen"
    },
    {
      "x": -7,
      "y": 11,
      "z": -5,
      "name": "Plant_Leaves_Aspen"
    },
    {
      "x": -7,
      "y": 12,
      "z": -5,
      "name": "Plant_Leaves_Aspen"
    },
    {
      "x": -7,
      "y": 13,
      "z": -5,
      "name": "Plant_Leaves_Aspen"
    },
    {
      "x": -7,
      "y": 7,
      "z": -4,
      "name": "Wood_Birch_Trunk_Full",
      "rotation": 5
    },
    {
      "x": -7,
      "y": 9,
      "z": -4,
      "name": "Plant_Leaves_Aspen"
    },
    {
      "x": -7,
      "y": 10,
      "z": -4,
      "name": "Wood_Birch_Branch_Corner",
      "rotation": 3
    },
    {
      "x": -7,
      "y": 11,
      "z": -4,
      "name": "Wood_Birch_Branch_Corner",
      "rotation": 8
    },
    {
      "x": -7,
      "y": 12,
      "z": -4,
      "name": "Plant_Leaves_Aspen"
    },
    {
      "x": -7,
      "y": 7,
      "z": -3,
      "name": "Wood_Birch_Branch_Short"
    },
    {
      "x": -7,
      "y": 9,
      "z": -3,
      "name": "Plant_Leaves_Aspen"
    },
    {
      "x": -7,
      "y": 10,
      "z": -3,
      "name": "Plant_Leaves_Aspen"
    },
    {
      "x": -7,
      "y": 11,
      "z": -3,
      "name": "Wood_Birch_Branch_Long",
      "rotation": 4
    },
    {
      "x": -7,
      "y": 12,
      "z": -3,
      "name": "Plant_Leaves_Aspen"
    },
    {
      "x": -7,
      "y": 13,
      "z": -3,
      "name": "Plant_Leaves_Aspen"
    },
    {
      "x": -7,
      "y": 1,
      "z": -2,
      "name": "Wood_Birch_Branch_Corner",
      "rotation": 3
    },
    {
      "x": -7,
      "y": 2,
      "z": -2,
      "name": "Wood_Birch_Branch_Corner",
      "rotation": 9
    },
    {
      "x": -7,
      "y": 11,
      "z": -2,
      "name": "Plant_Leaves_Aspen"
    },
    {
      "x": -6,
      "y": 11,
      "z": -9,
      "name": "Plant_Leaves_Aspen"
    },
    {
      "x": -6,
      "y": 10,
      "z": -8,
      "name": "Plant_Leaves_Aspen"
    },
    {
      "x": -6,
      "y": 11,
      "z": -8,
      "name": "Plant_Leaves_Aspen"
    },
    {
      "x": -6,
      "y": 8,
      "z": -7,
      "name": "Plant_Leaves_Aspen"
    },
    {
      "x": -6,
      "y": 9,
      "z": -7,
      "name": "Plant_Leaves_Aspen"
    },
    {
      "x": -6,
      "y": 10,
      "z": -7,
      "name": "Plant_Leaves_Aspen"
    },
    {
      "x": -6,
      "y": 11,
      "z": -7,
      "name": "Plant_Leaves_Aspen"
    },
    {
      "x": -6,
      "y": 12,
      "z": -6,
      "name": "Plant_Leaves_Aspen"
    },
    {
      "x": -6,
      "y": 13,
      "z": -6,
      "name": "Plant_Leaves_Aspen"
    },
    {
      "x": -6,
      "y": 10,
      "z": -5,
      "name": "Plant_Leaves_Aspen"
    },
    {
      "x": -6,
      "y": 11,
      "z": -5,
      "name": "Plant_Leaves_Aspen"
    },
    {
      "x": -6,
      "y": 12,
      "z": -5,
      "name": "Plant_Leaves_Aspen"
    },
    {
      "x": -6,
      "y": 13,
      "z": -5,
      "name": "Plant_Leaves_Aspen"
    },
    {
      "x": -6,
      "y": 14,
      "z": -5,
      "name": "Plant_Leaves_Aspen"
    },
    {
      "x": -6,
      "y": 7,
      "z": -4,
      "name": "Wood_Birch_Trunk",
      "rotation": 5
    },
    {
      "x": -6,
      "y": 8,
      "z": -4,
      "name": "Wood_Birch_Branch_Long"
    },
    {
      "x": -6,
      "y": 9,
      "z": -4,
      "name": "Wood_Birch_Branch_Long"
    },
    {
      "x": -6,
      "y": 10,
      "z": -4,
      "name": "Wood_Birch_Branch_Corner",
      "rotation": 11
    },
    {
      "x": -6,
      "y": 11,
      "z": -4,
      "name": "Plant_Leaves_Aspen"
    },
    {
      "x": -6,
      "y": 12,
      "z": -4,
      "name": "Plant_Leaves_Aspen"
    },
    {
      "x": -6,
      "y": 13,
      "z": -4,
      "name": "Plant_Leaves_Aspen"
    },
    {
      "x": -6,
      "y": 14,
      "z": -4,
      "name": "Plant_Leaves_Aspen"
    },
    {
      "x": -6,
      "y": 9,
      "z": -3,
      "name": "Plant_Leaves_Aspen"
    },
    {
      "x": -6,
      "y": 10,
      "z": -3,
      "name": "Plant_Leaves_Aspen"
    },
    {
      "x": -6,
      "y": 11,
      "z": -3,
      "name": "Plant_Leaves_Aspen"
    },
    {
      "x": -6,
      "y": 13,
      "z": -3,
      "name": "Plant_Leaves_Aspen"
    },
    {
      "x": -6,
      "y": 1,
      "z": -2,
      "name": "Wood_Birch_Branch_Long",
      "rotation": 5
    },
    {
      "x": -6,
      "y": 2,
      "z": -2,
      "name": "Wood_Birch_Branch_Corner",
      "rotation": 11
    },
    {
      "x": -6,
      "y": 10,
      "z": -2,
      "name": "Plant_Leaves_Aspen"
    },
    {
      "x": -6,
      "y": 11,
      "z": -2,
      "name": "Plant_Leaves_Aspen"
    },
    {
      "x": -6,
      "y": 3,
      "z": -1,
      "name": "Rock_Chalk"
    },
    {
      "x": -6,
      "y": 4,
      "z": -1,
      "name": "Rock_Marble_SkyGrass"
    },
    {
      "x": -6,
      "y": 5,
      "z": -1,
      "name": "Plant_Grass_Sky_Short"
    },
    {
      "x": -6,
      "y": 11,
      "z": -1,
      "name": "Plant_Leaves_Aspen"
    },
    {
      "x": -6,
      "y": 3,
      "z": 0,
      "name": "Rock_Chalk"
    },
    {
      "x": -6,
      "y": 4,
      "z": 0,
      "name": "Soil_Pebbles"
    },
    {
      "x": -6,
      "y": 10,
      "z": 0,
      "name": "Plant_Leaves_Aspen"
    },
    {
      "x": -6,
      "y": 11,
      "z": 0,
      "name": "Plant_Leaves_Aspen"
    },
    {
      "x": -6,
      "y": 3,
      "z": 1,
      "name": "Rock_Marble"
    },
    {
      "x": -6,
      "y": 4,
      "z": 1,
      "name": "Soil_Pebbles"
    },
    {
      "x": -6,
      "y": 10,
      "z": 1,
      "name": "Plant_Leaves_Aspen"
    },
    {
      "x": -5,
      "y": 9,
      "z": -9,
      "name": "Plant_Leaves_Aspen"
    },
    {
      "x": -5,
      "y": 10,
      "z": -9,
      "name": "Plant_Leaves_Aspen"
    },
    {
      "x": -5,
      "y": 10,
      "z": -8,
      "name": "Plant_Leaves_Aspen"
    },
    {
      "x": -5,
      "y": 11,
      "z": -8,
      "name": "Plant_Leaves_Aspen"
    },
    {
      "x": -5,
      "y": 8,
      "z": -7,
      "name": "Wood_Birch_Branch_Corner",
      "rotation": 2
    },
    {
      "x": -5,
      "y": 9,
      "z": -7,
      "name": "Wood_Birch_Branch_Long"
    },
    {
      "x": -5,
      "y": 10,
      "z": -7,
      "name": "Wood_Birch_Branch_Corner",
      "rotation": 9
    },
    {
      "x": -5,
      "y": 11,
      "z": -7,
      "name": "Plant_Leaves_Aspen"
    },
    {
      "x": -5,
      "y": 8,
      "z": -6,
      "name": "Wood_Birch_Branch_Long",
      "rotation": 4
    },
    {
      "x": -5,
      "y": 10,
      "z": -6,
      "name": "Plant_Leaves_Aspen"
    },
    {
      "x": -5,
      "y": 8,
      "z": -5,
      "name": "Wood_Birch_Trunk_Full",
      "rotation": 4
    },
    {
      "x": -5,
      "y": 9,
      "z": -5,
      "name": "Plant_Leaves_Aspen"
    },
    {
      "x": -5,
      "y": 10,
      "z": -5,
      "name": "Plant_Leaves_Aspen"
    },
    {
      "x": -5,
      "y": 12,
      "z": -5,
      "name": "Plant_Leaves_Aspen"
    },
    {
      "x": -5,
      "y": 13,
      "z": -5,
      "name": "Plant_Leaves_Aspen"
    },
    {
      "x": -5,
      "y": 14,
      "z": -5,
      "name": "Plant_Leaves_Aspen"
    },
    {
      "x": -5,
      "y": 6,
      "z": -4,
      "name": "Wood_Birch_Trunk_Full"
    },
    {
      "x": -5,
      "y": 7,
      "z": -4,
      "name": "Wood_Birch_Trunk"
    },
    {
      "x": -5,
      "y": 8,
      "z": -4,
      "name": "Wood_Birch_Trunk_Full",
      "rotation": 4
    },
    {
      "x": -5,
      "y": 9,
      "z": -4,
      "name": "Plant_Leaves_Aspen"
    },
    {
      "x": -5,
      "y": 10,
      "z": -4,
      "name": "Plant_Leaves_Aspen"
    },
    {
      "x": -5,
      "y": 11,
      "z": -4,
      "name": "Wood_Birch_Branch_Corner",
      "rotation": 3
    },
    {
      "x": -5,
      "y": 12,
      "z": -4,
      "name": "Wood_Birch_Branch_Long"
    },
    {
      "x": -5,
      "y": 13,
      "z": -4,
      "name": "Plant_Leaves_Aspen"
    },
    {
      "x": -5,
      "y": 14,
      "z": -4,
      "name": "Plant_Leaves_Aspen"
    },
    {
      "x": -5,
      "y": 3,
      "z": -3,
      "name": "Wood_Birch_Roots"
    },
    {
      "x": -5,
      "y": 4,
      "z": -3,
      "name": "Wood_Birch_Trunk_Full"
    },
    {
      "x": -5,
      "y": 5,
      "z": -3,
      "name": "Wood_Birch_Trunk"
    },
    {
      "x": -5,
      "y": 6,
      "z": -3,
      "name": "Wood_Birch_Trunk_Full"
    },
    {
      "x": -5,
      "y": 8,
      "z": -3,
      "name": "Wood_Birch_Branch_Long",
      "rotation": 4
    },
    {
      "x": -5,
      "y": 11,
      "z": -3,
      "name": "Plant_Leaves_Aspen"
    },
    {
      "x": -5,
      "y": 12,
      "z": -3,
      "name": "Plant_Leaves_Aspen"
    },
    {
      "x": -5,
      "y": 13,
      "z": -3,
      "name": "Plant_Leaves_Aspen"
    },
    {
      "x": -5,
      "y": 1,
      "z": -2,
      "name": "Wood_Birch_Branch_Long",
      "rotation": 5
    },
    {
      "x": -5,
      "y": 3,
      "z": -2,
      "name": "Rock_Chalk"
    },
    {
      "x": -5,
      "y": 4,
      "z": -2,
      "name": "Rock_Marble_SkyGrass"
    },
    {
      "x": -5,
      "y": 8,
      "z": -2,
      "name": "Wood_Birch_Branch_Corner"
    },
    {
      "x": -5,
      "y": 9,
      "z": -2,
      "name": "Wood_Birch_Branch_Long"
    },
    {
      "x": -5,
      "y": 10,
      "z": -2,
      "name": "Wood_Birch_Branch_Corner",
      "rotation": 8
    },
    {
      "x": -5,
      "y": 11,
      "z": -2,
      "name": "Plant_Leaves_Aspen"
    },
    {
      "x": -5,
      "y": 3,
      "z": -1,
      "name": "Rock_Chalk"
    },
    {
      "x": -5,
      "y": 4,
      "z": -1,
      "name": "Soil_Pebbles"
    },
    {
      "x": -5,
      "y": 8,
      "z": -1,
      "name": "Wood_Birch_Branch_Corner",
      "rotation": 2
    },
    {
      "x": -5,
      "y": 9,
      "z": -1,
      "name": "Wood_Birch_Branch_Corner",
      "rotation": 8
    },
    {
      "x": -5,
      "y": 10,
      "z": -1,
      "name": "Wood_Birch_Branch_Long",
      "rotation": 4
    },
    {
      "x": -5,
      "y": 11,
      "z": -1,
      "name": "Plant_Leaves_Aspen"
    },
    {
      "x": -5,
      "y": 3,
      "z": 0,
      "name": "Rock_Marble"
    },
    {
      "x": -5,
      "y": 4,
      "z": 0,
      "name": "Soil_Pebbles"
    },
    {
      "x": -5,
      "y": 8,
      "z": 0,
      "name": "Wood_Birch_Branch_Corner"
    },
    {
      "x": -5,
      "y": 9,
      "z": 0,
      "name": "Wood_Birch_Branch_Long"
    },
    {
      "x": -5,
      "y": 10,
      "z": 0,
      "name": "Wood_Birch_Branch_Corner",
      "rotation": 10
    },
    {
      "x": -5,
      "y": 11,
      "z": 0,
      "name": "Plant_Leaves_Aspen"
    },
    {
      "x": -5,
      "y": 3,
      "z": 1,
      "name": "Rock_Marble"
    },
    {
      "x": -5,
      "y": 4,
      "z": 1,
      "name": "Soil_Pebbles"
    },
    {
      "x": -5,
      "y": 5,
      "z": 1,
      "name": "Rubble_Marble_Medium"
    },
    {
      "x": -5,
      "y": 10,
      "z": 1,
      "name": "Plant_Leaves_Aspen"
    },
    {
      "x": -5,
      "y": 3,
      "z": 2,
      "name": "Rock_Marble"
    },
    {
      "x": -5,
      "y": 4,
      "z": 2,
      "name": "Soil_Pebbles"
    },
    {
      "x": -4,
      "y": 9,
      "z": -8,
      "name": "Plant_Leaves_Aspen"
    },
    {
      "x": -4,
      "y": 10,
      "z": -8,
      "name": "Plant_Leaves_Aspen"
    },
    {
      "x": -4,
      "y": 11,
      "z": -8,
      "name": "Plant_Leaves_Aspen"
    },
    {
      "x": -4,
      "y": 12,
      "z": -8,
      "name": "Plant_Leaves_Aspen"
    },
    {
      "x": -4,
      "y": 0,
      "z": -7,
      "name": "Wood_Birch_Branch_Corner",
      "rotation": 2
    },
    {
      "x": -4,
      "y": 1,
      "z": -7,
      "name": "Wood_Birch_Branch_Long"
    },
    {
      "x": -4,
      "y": 2,
      "z": -7,
      "name": "Wood_Birch_Branch_Corner",
      "rotation": 8
    },
    {
      "x": -4,
      "y": 9,
      "z": -7,
      "name": "Plant_Leaves_Aspen"
    },
    {
      "x": -4,
      "y": 10,
      "z": -7,
      "name": "Wood_Birch_Branch_Corner",
      "rotation": 1
    },
    {
      "x": -4,
      "y": 11,
      "z": -7,
      "name": "Wood_Birch_Branch_Long"
    },
    {
      "x": -4,
      "y": 12,
      "z": -7,
      "name": "Plant_Leaves_Aspen"
    },
    {
      "x": -4,
      "y": 0,
      "z": -6,
      "name": "Wood_Birch_Branch_Long",
      "rotation": 4
    },
    {
      "x": -4,
      "y": 1,
      "z": -6,
      "name": "Wood_Birch_Branch_Corner"
    },
    {
      "x": -4,
      "y": 2,
      "z": -6,
      "name": "Wood_Birch_Branch_Corner",
      "rotation": 10
    },
    {
      "x": -4,
      "y": 10,
      "z": -6,
      "name": "Plant_Leaves_Aspen"
    },
    {
      "x": -4,
      "y": 11,
      "z": -6,
      "name": "Plant_Leaves_Aspen"
    },
    {
      "x": -4,
      "y": 12,
      "z": -6,
      "name": "Plant_Leaves_Aspen"
    },
    {
      "x": -4,
      "y": 0,
      "z": -5,
      "name": "Wood_Birch_Branch_Corner"
    },
    {
      "x": -4,
      "y": 1,
      "z": -5,
      "name": "Wood_Birch_Branch_Long"
    },
    {
      "x": -4,
      "y": 2,
      "z": -5,
      "name": "Wood_Birch_Branch_Long"
    },
    {
      "x": -4,
      "y": 3,
      "z": -5,
      "name": "Wood_Birch_Branch_Corner",
      "rotation": 8
    },
    {
      "x": -4,
      "y": 8,
      "z": -5,
      "name": "Wood_Birch_Branch_Corner",
      "rotation": 1
    },
    {
      "x": -4,
      "y": 9,
      "z": -5,
      "name": "Wood_Birch_Branch_Long"
    },
    {
      "x": -4,
      "y": 10,
      "z": -5,
      "name": "Wood_Birch_Branch_Corner",
      "rotation": 8
    },
    {
      "x": -4,
      "y": 11,
      "z": -5,
      "name": "Plant_Leaves_Aspen"
    },
    {
      "x": -4,
      "y": 12,
      "z": -5,
      "name": "Plant_Leaves_Aspen"
    },
    {
      "x": -4,
      "y": 3,
      "z": -4,
      "name": "Wood_Birch_Branch_Long",
      "rotation": 4
    },
    {
      "x": -4,
      "y": 6,
      "z": -4,
      "name": "Wood_Birch_Branch_Short",
      "rotation": 1
    },
    {
      "x": -4,
      "y": 8,
      "z": -4,
      "name": "Wood_Birch_Branch_Long",
      "rotation": 5
    },
    {
      "x": -4,
      "y": 10,
      "z": -4,
      "name": "Wood_Birch_Branch_Corner"
    },
    {
      "x": -4,
      "y": 11,
      "z": -4,
      "name": "Wood_Birch_Branch_Corner",
      "rotation": 11
    },
    {
      "x": -4,
      "y": 12,
      "z": -4,
      "name": "Plant_Leaves_Aspen"
    },
    {
      "x": -4,
      "y": 13,
      "z": -4,
      "name": "Plant_Leaves_Aspen"
    },
    {
      "x": -4,
      "y": 2,
      "z": -3,
      "name": "Wood_Birch_Roots"
    },
    {
      "x": -4,
      "y": 3,
      "z": -3,
      "name": "Wood_Birch_Trunk_Full"
    },
    {
      "x": -4,
      "y": 4,
      "z": -3,
      "name": "Wood_Birch_Trunk"
    },
    {
      "x": -4,
      "y": 5,
      "z": -3,
      "name": "Wood_Birch_Trunk_Full"
    },
    {
      "x": -4,
      "y": 11,
      "z": -3,
      "name": "Plant_Leaves_Aspen"
    },
    {
      "x": -4,
      "y": 12,
      "z": -3,
      "name": "Plant_Leaves_Aspen"
    },
    {
      "x": -4,
      "y": 0,
      "z": -2,
      "name": "Wood_Birch_Roots"
    },
    {
      "x": -4,
      "y": 1,
      "z": -2,
      "name": "Wood_Birch_Trunk_Full"
    },
    {
      "x": -4,
      "y": 2,
      "z": -2,
      "name": "Wood_Birch_Trunk"
    },
    {
      "x": -4,
      "y": 3,
      "z": -2,
      "name": "Rock_Chalk"
    },
    {
      "x": -4,
      "y": 4,
      "z": -2,
      "name": "Soil_Pebbles"
    },
    {
      "x": -4,
      "y": 9,
      "z": -2,
      "name": "Plant_Leaves_Aspen"
    },
    {
      "x": -4,
      "y": 10,
      "z": -2,
      "name": "Plant_Leaves_Aspen"
    },
    {
      "x": -4,
      "y": 3,
      "z": -1,
      "name": "Rock_Marble"
    },
    {
      "x": -4,
      "y": 4,
      "z": -1,
      "name": "Soil_Pebbles"
    },
    {
      "x": -4,
      "y": 10,
      "z": -1,
      "name": "Plant_Leaves_Aspen"
    },
    {
      "x": -4,
      "y": 11,
      "z": -1,
      "name": "Plant_Leaves_Aspen"
    },
    {
      "x": -4,
      "y": 3,
      "z": 0,
      "name": "Rock_Marble"
    },
    {
      "x": -4,
      "y": 4,
      "z": 0,
      "name": "Soil_Pebbles"
    },
    {
      "x": -4,
      "y": 5,
      "z": 0,
      "name": "Rubble_Marble"
    },
    {
      "x": -4,
      "y": 10,
      "z": 0,
      "name": "Plant_Leaves_Aspen"
    },
    {
      "x": -4,
      "y": 11,
      "z": 0,
      "name": "Plant_Leaves_Aspen"
    },
    {
      "x": -4,
      "y": -1,
      "z": 1,
      "name": "Rock_Marble"
    },
    {
      "x": -4,
      "y": 0,
      "z": 1,
      "name": "Rock_Marble"
    },
    {
      "x": -4,
      "y": 1,
      "z": 1,
      "name": "Rock_Marble"
    },
    {
      "x": -4,
      "y": 2,
      "z": 1,
      "name": "Rock_Marble"
    },
    {
      "x": -4,
      "y": 3,
      "z": 1,
      "name": "Soil_Pebbles"
    },
    {
      "x": -4,
      "y": -1,
      "z": 2,
      "name": "Rock_Marble"
    },
    {
      "x": -4,
      "y": 0,
      "z": 2,
      "name": "Rock_Marble"
    },
    {
      "x": -4,
      "y": 1,
      "z": 2,
      "name": "Rock_Marble"
    },
    {
      "x": -4,
      "y": 2,
      "z": 2,
      "name": "Rock_Marble"
    },
    {
      "x": -4,
      "y": 3,
      "z": 2,
      "name": "Rock_Marble"
    },
    {
      "x": -4,
      "y": 4,
      "z": 2,
      "name": "Soil_Pebbles"
    },
    {
      "x": -4,
      "y": -1,
      "z": 3,
      "name": "Rock_Marble"
    },
    {
      "x": -4,
      "y": 0,
      "z": 3,
      "name": "Rock_Marble"
    },
    {
      "x": -4,
      "y": 1,
      "z": 3,
      "name": "Rock_Marble"
    },
    {
      "x": -4,
      "y": 2,
      "z": 3,
      "name": "Rock_Marble"
    },
    {
      "x": -4,
      "y": 3,
      "z": 3,
      "name": "Rock_Marble"
    },
    {
      "x": -4,
      "y": 4,
      "z": 3,
      "name": "Rock_Marble_SkyGrass"
    },
    {
      "x": -3,
      "y": 11,
      "z": -8,
      "name": "Plant_Leaves_Aspen"
    },
    {
      "x": -3,
      "y": 10,
      "z": -7,
      "name": "Plant_Leaves_Aspen"
    },
    {
      "x": -3,
      "y": 11,
      "z": -7,
      "name": "Plant_Leaves_Aspen"
    },
    {
      "x": -3,
      "y": 12,
      "z": -7,
      "name": "Plant_Leaves_Aspen"
    },
    {
      "x": -3,
      "y": 11,
      "z": -6,
      "name": "Plant_Leaves_Aspen"
    },
    {
      "x": -3,
      "y": 11,
      "z": -5,
      "name": "Plant_Leaves_Aspen"
    },
    {
      "x": -3,
      "y": 3,
      "z": -4,
      "name": "Rock_Chalk"
    },
    {
      "x": -3,
      "y": 4,
      "z": -4,
      "name": "Soil_Pebbles"
    },
    {
      "x": -3,
      "y": 8,
      "z": -4,
      "name": "Wood_Birch_Branch_Corner",
      "rotation": 1
    },
    {
      "x": -3,
      "y": 9,
      "z": -4,
      "name": "Wood_Birch_Branch_Corner",
      "rotation": 9
    },
    {
      "x": -3,
      "y": 11,
      "z": -4,
      "name": "Plant_Leaves_Aspen"
    },
    {
      "x": -3,
      "y": 2,
      "z": -3,
      "name": "Rock_Marble"
    },
    {
      "x": -3,
      "y": 3,
      "z": -3,
      "name": "Soil_Pebbles"
    },
    {
      "x": -3,
      "y": 4,
      "z": -3,
      "name": "Soil_Pebbles"
    },
    {
      "x": -3,
      "y": 10,
      "z": -3,
      "name": "Plant_Leaves_Aspen"
    },
    {
      "x": -3,
      "y": 2,
      "z": -2,
      "name": "Rock_Marble"
    },
    {
      "x": -3,
      "y": 3,
      "z": -2,
      "name": "Soil_Pebbles"
    },
    {
      "x": -3,
      "y": 4,
      "z": -2,
      "name": "Soil_Pebbles"
    },
    {
      "x": -3,
      "y": 2,
      "z": -1,
      "name": "Rock_Marble"
    },
    {
      "x": -3,
      "y": 3,
      "z": -1,
      "name": "Soil_Pebbles"
    },
    {
      "x": -3,
      "y": -1,
      "z": 0,
      "name": "Rock_Marble"
    },
    {
      "x": -3,
      "y": 0,
      "z": 0,
      "name": "Rock_Marble"
    },
    {
      "x": -3,
      "y": 1,
      "z": 0,
      "name": "Rock_Marble"
    },
    {
      "x": -3,
      "y": 2,
      "z": 0,
      "name": "Rock_Marble"
    },
    {
      "x": -3,
      "y": 3,
      "z": 0,
      "name": "Soil_Pebbles"
    },
    {
      "x": -3,
      "y": 4,
      "z": 0,
      "name": "Rubble_Marble_Medium"
    },
    {
      "x": -3,
      "y": -1,
      "z": 1,
      "name": "Rock_Marble"
    },
    {
      "x": -3,
      "y": 0,
      "z": 1,
      "name": "Rock_Marble"
    },
    {
      "x": -3,
      "y": 1,
      "z": 1,
      "name": "Rock_Marble"
    },
    {
      "x": -3,
      "y": 2,
      "z": 1,
      "name": "Rock_Marble"
    },
    {
      "x": -3,
      "y": 3,
      "z": 1,
      "name": "Soil_Pebbles"
    },
    {
      "x": -3,
      "y": -1,
      "z": 2,
      "name": "Rock_Marble"
    },
    {
      "x": -3,
      "y": 0,
      "z": 2,
      "name": "Rock_Marble"
    },
    {
      "x": -3,
      "y": 1,
      "z": 2,
      "name": "Rock_Marble"
    },
    {
      "x": -3,
      "y": 2,
      "z": 2,
      "name": "Rock_Marble"
    },
    {
      "x": -3,
      "y": 3,
      "z": 2,
      "name": "Soil_Pebbles"
    },
    {
      "x": -3,
      "y": -1,
      "z": 3,
      "name": "Rock_Marble"
    },
    {
      "x": -3,
      "y": 0,
      "z": 3,
      "name": "Rock_Marble"
    },
    {
      "x": -3,
      "y": 1,
      "z": 3,
      "name": "Rock_Marble"
    },
    {
      "x": -3,
      "y": 2,
      "z": 3,
      "name": "Rock_Marble"
    },
    {
      "x": -3,
      "y": 3,
      "z": 3,
      "name": "Rock_Marble"
    },
    {
      "x": -3,
      "y": 4,
      "z": 3,
      "name": "Rock_Marble_SkyGrass"
    },
    {
      "x": -3,
      "y": 5,
      "z": 3,
      "name": "Plant_Grass_Sky"
    },
    {
      "x": -3,
      "y": -1,
      "z": 4,
      "name": "Rock_Marble"
    },
    {
      "x": -3,
      "y": 0,
      "z": 4,
      "name": "Rock_Marble"
    },
    {
      "x": -3,
      "y": 1,
      "z": 4,
      "name": "Rock_Marble"
    },
    {
      "x": -3,
      "y": 2,
      "z": 4,
      "name": "Rock_Marble"
    },
    {
      "x": -3,
      "y": 3,
      "z": 4,
      "name": "Rock_Marble"
    },
    {
      "x": -3,
      "y": 4,
      "z": 4,
      "name": "Rock_Marble_SkyGrass"
    },
    {
      "x": -2,
      "y": 9,
      "z": -6,
      "name": "Plant_Leaves_Aspen"
    },
    {
      "x": -2,
      "y": 10,
      "z": -6,
      "name": "Plant_Leaves_Aspen"
    },
    {
      "x": -2,
      "y": 11,
      "z": -6,
      "name": "Plant_Leaves_Aspen"
    },
    {
      "x": -2,
      "y": 9,
      "z": -5,
      "name": "Plant_Leaves_Aspen"
    },
    {
      "x": -2,
      "y": 10,
      "z": -5,
      "name": "Plant_Leaves_Aspen"
    },
    {
      "x": -2,
      "y": 11,
      "z": -5,
      "name": "Plant_Leaves_Aspen"
    },
    {
      "x": -2,
      "y": 2,
      "z": -4,
      "name": "Rock_Marble"
    },
    {
      "x": -2,
      "y": 3,
      "z": -4,
      "name": "Rock_Chalk"
    },
    {
      "x": -2,
      "y": 4,
      "z": -4,
      "name": "Soil_Pebbles"
    },
    {
      "x": -2,
      "y": 8,
      "z": -4,
      "name": "Plant_Leaves_Aspen"
    },
    {
      "x": -2,
      "y": 9,
      "z": -4,
      "name": "Wood_Birch_Branch_Long",
      "rotation": 5
    },
    {
      "x": -2,
      "y": 10,
      "z": -4,
      "name": "Plant_Leaves_Aspen"
    },
    {
      "x": -2,
      "y": 11,
      "z": -4,
      "name": "Plant_Leaves_Aspen"
    },
    {
      "x": -2,
      "y": 2,
      "z": -3,
      "name": "Rock_Marble"
    },
    {
      "x": -2,
      "y": 3,
      "z": -3,
      "name": "Soil_Pebbles"
    },
    {
      "x": -2,
      "y": 4,
      "z": -3,
      "name": "Soil_Pebbles"
    },
    {
      "x": -2,
      "y": 9,
      "z": -3,
      "name": "Plant_Leaves_Aspen"
    },
    {
      "x": -2,
      "y": 2,
      "z": -2,
      "name": "Rock_Marble"
    },
    {
      "x": -2,
      "y": 3,
      "z": -2,
      "name": "Soil_Pebbles"
    },
    {
      "x": -2,
      "y": 2,
      "z": -1,
      "name": "Rock_Marble"
    },
    {
      "x": -2,
      "y": 3,
      "z": -1,
      "name": "Soil_Pebbles"
    },
    {
      "x": -2,
      "y": -1,
      "z": 0,
      "name": "Rock_Marble"
    },
    {
      "x": -2,
      "y": 0,
      "z": 0,
      "name": "Rock_Marble"
    },
    {
      "x": -2,
      "y": 1,
      "z": 0,
      "name": "Rock_Marble"
    },
    {
      "x": -2,
      "y": 2,
      "z": 0,
      "name": "Soil_Pebbles"
    },
    {
      "x": -2,
      "y": 3,
      "z": 0,
      "name": "Soil_Pebbles"
    },
    {
      "x": -2,
      "y": -1,
      "z": 1,
      "name": "Rock_Marble"
    },
    {
      "x": -2,
      "y": 0,
      "z": 1,
      "name": "Rock_Marble"
    },
    {
      "x": -2,
      "y": 1,
      "z": 1,
      "name": "Rock_Marble"
    },
    {
      "x": -2,
      "y": 2,
      "z": 1,
      "name": "Soil_Pebbles"
    },
    {
      "x": -2,
      "y": 3,
      "z": 1,
      "name": "Soil_Pebbles"
    },
    {
      "x": -2,
      "y": -1,
      "z": 2,
      "name": "Rock_Marble"
    },
    {
      "x": -2,
      "y": 0,
      "z": 2,
      "name": "Rock_Marble"
    },
    {
      "x": -2,
      "y": 1,
      "z": 2,
      "name": "Rock_Marble"
    },
    {
      "x": -2,
      "y": 2,
      "z": 2,
      "name": "Rock_Marble"
    },
    {
      "x": -2,
      "y": 3,
      "z": 2,
      "name": "Soil_Pebbles"
    },
    {
      "x": -2,
      "y": -1,
      "z": 3,
      "name": "Rock_Marble"
    },
    {
      "x": -2,
      "y": 0,
      "z": 3,
      "name": "Rock_Marble"
    },
    {
      "x": -2,
      "y": 1,
      "z": 3,
      "name": "Rock_Marble"
    },
    {
      "x": -2,
      "y": 2,
      "z": 3,
      "name": "Rock_Marble"
    },
    {
      "x": -2,
      "y": 3,
      "z": 3,
      "name": "Rock_Marble"
    },
    {
      "x": -2,
      "y": 4,
      "z": 3,
      "name": "Rock_Marble_SkyGrass"
    },
    {
      "x": -2,
      "y": 5,
      "z": 3,
      "name": "Plant_Grass_Sky_Long"
    },
    {
      "x": -2,
      "y": 6,
      "z": 3,
      "name": "Plant_Grass_Sky_Long",
      "filler": 1024
    },
    {
      "x": -2,
      "y": -1,
      "z": 4,
      "name": "Rock_Marble"
    },
    {
      "x": -2,
      "y": 0,
      "z": 4,
      "name": "Rock_Marble"
    },
    {
      "x": -2,
      "y": 1,
      "z": 4,
      "name": "Rock_Marble"
    },
    {
      "x": -2,
      "y": 2,
      "z": 4,
      "name": "Rock_Lime"
    },
    {
      "x": -2,
      "y": 3,
      "z": 4,
      "name": "Rock_Marble"
    },
    {
      "x": -2,
      "y": 4,
      "z": 4,
      "name": "Rock_Marble_SkyGrass"
    },
    {
      "x": -1,
      "y": 6,
      "z": -5,
      "name": "Plant_Leaves_Aspen"
    },
    {
      "x": -1,
      "y": 7,
      "z": -5,
      "name": "Plant_Leaves_Aspen"
    },
    {
      "x": -1,
      "y": 8,
      "z": -5,
      "name": "Plant_Leaves_Aspen"
    },
    {
      "x": -1,
      "y": 9,
      "z": -5,
      "name": "Plant_Leaves_Aspen"
    },
    {
      "x": -1,
      "y": 10,
      "z": -5,
      "name": "Plant_Leaves_Aspen"
    },
    {
      "x": -1,
      "y": 2,
      "z": -4,
      "name": "Rock_Marble"
    },
    {
      "x": -1,
      "y": 3,
      "z": -4,
      "name": "Rock_Marble"
    },
    {
      "x": -1,
      "y": 4,
      "z": -4,
      "name": "Soil_Pebbles"
    },
    {
      "x": -1,
      "y": 8,
      "z": -4,
      "name": "Plant_Leaves_Aspen"
    },
    {
      "x": -1,
      "y": 9,
      "z": -4,
      "name": "Wood_Birch_Branch_Long",
      "rotation": 5
    },
    {
      "x": -1,
      "y": 10,
      "z": -4,
      "name": "Plant_Leaves_Aspen"
    },
    {
      "x": -1,
      "y": 2,
      "z": -3,
      "name": "Rock_Marble"
    },
    {
      "x": -1,
      "y": 3,
      "z": -3,
      "name": "Soil_Pebbles"
    },
    {
      "x": -1,
      "y": 8,
      "z": -3,
      "name": "Plant_Leaves_Aspen"
    },
    {
      "x": -1,
      "y": 9,
      "z": -3,
      "name": "Plant_Leaves_Aspen"
    },
    {
      "x": -1,
      "y": 1,
      "z": -2,
      "name": "Rock_Chalk"
    },
    {
      "x": -1,
      "y": 2,
      "z": -2,
      "name": "Rock_Marble"
    },
    {
      "x": -1,
      "y": 3,
      "z": -2,
      "name": "Soil_Pebbles"
    },
    {
      "x": -1,
      "y": 1,
      "z": -1,
      "name": "Rock_Marble"
    },
    {
      "x": -1,
      "y": 2,
      "z": -1,
      "name": "Soil_Pebbles"
    },
    {
      "x": -1,
      "y": 5,
      "z": -1,
      "name": "Plant_Flower_Water_Green"
    },
    {
      "x": -1,
      "y": -1,
      "z": 0,
      "name": "Rock_Marble"
    },
    {
      "x": -1,
      "y": 0,
      "z": 0,
      "name": "Rock_Marble"
    },
    {
      "x": -1,
      "y": 1,
      "z": 0,
      "name": "Rock_Marble"
    },
    {
      "x": -1,
      "y": 2,
      "z": 0,
      "name": "Soil_Pebbles"
    },
    {
      "x": -1,
      "y": 3,
      "z": 0,
      "name": "Rubble_Marble"
    },
    {
      "x": -1,
      "y": -1,
      "z": 1,
      "name": "Rock_Marble"
    },
    {
      "x": -1,
      "y": 0,
      "z": 1,
      "name": "Rock_Marble"
    },
    {
      "x": -1,
      "y": 1,
      "z": 1,
      "name": "Rock_Marble"
    },
    {
      "x": -1,
      "y": 2,
      "z": 1,
      "name": "Soil_Pebbles"
    },
    {
      "x": -1,
      "y": 3,
      "z": 1,
      "name": "Soil_Pebbles"
    },
    {
      "x": -1,
      "y": 5,
      "z": 1,
      "name": "Plant_Flower_Water_White"
    },
    {
      "x": -1,
      "y": -1,
      "z": 2,
      "name": "Rock_Marble"
    },
    {
      "x": -1,
      "y": 0,
      "z": 2,
      "name": "Rock_Marble"
    },
    {
      "x": -1,
      "y": 1,
      "z": 2,
      "name": "Rock_Marble"
    },
    {
      "x": -1,
      "y": 2,
      "z": 2,
      "name": "Rock_Marble"
    },
    {
      "x": -1,
      "y": 3,
      "z": 2,
      "name": "Soil_Pebbles"
    },
    {
      "x": -1,
      "y": -1,
      "z": 3,
      "name": "Rock_Marble"
    },
    {
      "x": -1,
      "y": 0,
      "z": 3,
      "name": "Rock_Marble"
    },
    {
      "x": -1,
      "y": 1,
      "z": 3,
      "name": "Rock_Marble"
    },
    {
      "x": -1,
      "y": 2,
      "z": 3,
      "name": "Rock_Marble"
    },
    {
      "x": -1,
      "y": 3,
      "z": 3,
      "name": "Rock_Marble"
    },
    {
      "x": -1,
      "y": 4,
      "z": 3,
      "name": "Soil_Pebbles"
    },
    {
      "x": -1,
      "y": -1,
      "z": 4,
      "name": "Rock_Marble"
    },
    {
      "x": -1,
      "y": 0,
      "z": 4,
      "name": "Rock_Marble"
    },
    {
      "x": -1,
      "y": 1,
      "z": 4,
      "name": "Rock_Marble"
    },
    {
      "x": -1,
      "y": 2,
      "z": 4,
      "name": "Rock_Lime"
    },
    {
      "x": -1,
      "y": 3,
      "z": 4,
      "name": "Rock_Marble"
    },
    {
      "x": -1,
      "y": 4,
      "z": 4,
      "name": "Soil_Pebbles"
    },
    {
      "x": 0,
      "y": 2,
      "z": -5,
      "name": "Rock_Marble"
    },
    {
      "x": 0,
      "y": 3,
      "z": -5,
      "name": "Rock_Marble"
    },
    {
      "x": 0,
      "y": 9,
      "z": -5,
      "name": "Plant_Leaves_Aspen"
    },
    {
      "x": 0,
      "y": 2,
      "z": -4,
      "name": "Rock_Marble"
    },
    {
      "x": 0,
      "y": 3,
      "z": -4,
      "name": "Rock_Marble"
    },
    {
      "x": 0,
      "y": 4,
      "z": -4,
      "name": "Soil_Pebbles"
    },
    {
      "x": 0,
      "y": 8,
      "z": -4,
      "name": "Plant_Leaves_Aspen"
    },
    {
      "x": 0,
      "y": 9,
      "z": -4,
      "name": "Plant_Leaves_Aspen"
    },
    {
      "x": 0,
      "y": 1,
      "z": -3,
      "name": "Rock_Chalk"
    },
    {
      "x": 0,
      "y": 2,
      "z": -3,
      "name": "Rock_Marble"
    },
    {
      "x": 0,
      "y": 3,
      "z": -3,
      "name": "Soil_Pebbles"
    },
    {
      "x": 0,
      "y": 9,
      "z": -3,
      "name": "Plant_Leaves_Aspen"
    },
    {
      "x": 0,
      "y": 1,
      "z": -2,
      "name": "Rock_Chalk"
    },
    {
      "x": 0,
      "y": 2,
      "z": -2,
      "name": "Soil_Pebbles"
    },
    {
      "x": 0,
      "y": 3,
      "z": -2,
      "name": "Rubble_Marble_Medium"
    },
    {
      "x": 0,
      "y": 1,
      "z": -1,
      "name": "Rock_Marble"
    },
    {
      "x": 0,
      "y": 2,
      "z": -1,
      "name": "Soil_Pebbles"
    },
    {
      "x": 0,
      "y": 1,
      "z": 0,
      "name": "Rock_Marble"
    },
    {
      "x": 0,
      "y": 2,
      "z": 0,
      "name": "Soil_Pebbles"
    },
    {
      "x": 0,
      "y": -1,
      "z": 1,
      "name": "Rock_Marble"
    },
    {
      "x": 0,
      "y": 0,
      "z": 1,
      "name": "Rock_Marble"
    },
    {
      "x": 0,
      "y": 1,
      "z": 1,
      "name": "Rock_Marble"
    },
    {
      "x": 0,
      "y": 2,
      "z": 1,
      "name": "Rock_Marble"
    },
    {
      "x": 0,
      "y": 3,
      "z": 1,
      "name": "Soil_Pebbles"
    },
    {
      "x": 0,
      "y": -1,
      "z": 2,
      "name": "Rock_Marble"
    },
    {
      "x": 0,
      "y": 0,
      "z": 2,
      "name": "Rock_Marble"
    },
    {
      "x": 0,
      "y": 1,
      "z": 2,
      "name": "Rock_Marble"
    },
    {
      "x": 0,
      "y": 2,
      "z": 2,
      "name": "Rock_Marble"
    },
    {
      "x": 0,
      "y": 3,
      "z": 2,
      "name": "Soil_Pebbles"
    },
    {
      "x": 0,
      "y": -1,
      "z": 3,
      "name": "Rock_Marble"
    },
    {
      "x": 0,
      "y": 0,
      "z": 3,
      "name": "Rock_Marble"
    },
    {
      "x": 0,
      "y": 1,
      "z": 3,
      "name": "Rock_Marble"
    },
    {
      "x": 0,
      "y": 2,
      "z": 3,
      "name": "Rock_Lime"
    },
    {
      "x": 0,
      "y": 3,
      "z": 3,
      "name": "Soil_Pebbles"
    },
    {
      "x": 1,
      "y": 2,
      "z": -5,
      "name": "Rock_Marble"
    },
    {
      "x": 1,
      "y": 3,
      "z": -5,
      "name": "Rock_Marble"
    },
    {
      "x": 1,
      "y": 4,
      "z": -5,
      "name": "Rock_Marble_SkyGrass"
    },
    {
      "x": 1,
      "y": 2,
      "z": -4,
      "name": "Rock_Marble"
    },
    {
      "x": 1,
      "y": 3,
      "z": -4,
      "name": "Rock_Marble"
    },
    {
      "x": 1,
      "y": 4,
      "z": -4,
      "name": "Rock_Marble_SkyGrass"
    },
    {
      "x": 1,
      "y": 5,
      "z": -4,
      "name": "Plant_Grass_Sky"
    },
    {
      "x": 1,
      "y": 1,
      "z": -3,
      "name": "Rock_Chalk"
    },
    {
      "x": 1,
      "y": 2,
      "z": -3,
      "name": "Rock_Marble"
    },
    {
      "x": 1,
      "y": 3,
      "z": -3,
      "name": "Soil_Pebbles"
    },
    {
      "x": 1,
      "y": 0,
      "z": -2,
      "name": "Rock_Marble"
    },
    {
      "x": 1,
      "y": 1,
      "z": -2,
      "name": "Rock_Marble"
    },
    {
      "x": 1,
      "y": 2,
      "z": -2,
      "name": "Soil_Pebbles"
    },
    {
      "x": 1,
      "y": 5,
      "z": -2,
      "name": "Plant_Flower_Water_White"
    },
    {
      "x": 1,
      "y": 0,
      "z": -1,
      "name": "Rock_Marble"
    },
    {
      "x": 1,
      "y": 1,
      "z": -1,
      "name": "Rock_Marble"
    },
    {
      "x": 1,
      "y": 2,
      "z": -1,
      "name": "Soil_Pebbles"
    },
    {
      "x": 1,
      "y": 0,
      "z": 0,
      "name": "Rock_Marble"
    },
    {
      "x": 1,
      "y": 1,
      "z": 0,
      "name": "Rock_Marble"
    },
    {
      "x": 1,
      "y": 2,
      "z": 0,
      "name": "Soil_Pebbles"
    },
    {
      "x": 1,
      "y": 2,
      "z": 1,
      "name": "Rock_Lime"
    },
    {
      "x": 1,
      "y": 3,
      "z": 1,
      "name": "Soil_Pebbles"
    },
    {
      "x": 1,
      "y": 2,
      "z": 2,
      "name": "Rock_Lime"
    },
    {
      "x": 1,
      "y": 3,
      "z": 2,
      "name": "Soil_Pebbles"
    },
    {
      "x": 1,
      "y": 2,
      "z": 3,
      "name": "Rock_Lime"
    },
    {
      "x": 1,
      "y": 3,
      "z": 3,
      "name": "Soil_Pebbles"
    },
    {
      "x": 2,
      "y": 2,
      "z": -5,
      "name": "Rock_Marble"
    },
    {
      "x": 2,
      "y": 3,
      "z": -5,
      "name": "Rock_Marble"
    },
    {
      "x": 2,
      "y": 4,
      "z": -5,
      "name": "Rock_Marble_SkyGrass"
    },
    {
      "x": 2,
      "y": 2,
      "z": -4,
      "name": "Rock_Marble"
    },
    {
      "x": 2,
      "y": 3,
      "z": -4,
      "name": "Rock_Marble"
    },
    {
      "x": 2,
      "y": 4,
      "z": -4,
      "name": "Rock_Marble_SkyGrass"
    },
    {
      "x": 2,
      "y": 5,
      "z": -4,
      "name": "Plant_Grass_Sky_Short"
    },
    {
      "x": 2,
      "y": 0,
      "z": -3,
      "name": "Rock_Marble"
    },
    {
      "x": 2,
      "y": 1,
      "z": -3,
      "name": "Rock_Chalk"
    },
    {
      "x": 2,
      "y": 2,
      "z": -3,
      "name": "Rock_Marble"
    },
    {
      "x": 2,
      "y": 3,
      "z": -3,
      "name": "Soil_Pebbles"
    },
    {
      "x": 2,
      "y": 0,
      "z": -2,
      "name": "Rock_Marble"
    },
    {
      "x": 2,
      "y": 1,
      "z": -2,
      "name": "Rock_Marble"
    },
    {
      "x": 2,
      "y": 2,
      "z": -2,
      "name": "Rock_Marble"
    },
    {
      "x": 2,
      "y": 3,
      "z": -2,
      "name": "Soil_Pebbles"
    },
    {
      "x": 2,
      "y": 0,
      "z": -1,
      "name": "Rock_Marble"
    },
    {
      "x": 2,
      "y": 1,
      "z": -1,
      "name": "Rock_Marble"
    },
    {
      "x": 2,
      "y": 2,
      "z": -1,
      "name": "Soil_Pebbles"
    },
    {
      "x": 2,
      "y": 0,
      "z": 0,
      "name": "Rock_Marble"
    },
    {
      "x": 2,
      "y": 1,
      "z": 0,
      "name": "Rock_Marble"
    },
    {
      "x": 2,
      "y": 2,
      "z": 0,
      "name": "Soil_Pebbles"
    },
    {
      "x": 2,
      "y": 5,
      "z": 0,
      "name": "Plant_Flower_Water_Green"
    },
    {
      "x": 2,
      "y": 0,
      "z": 1,
      "name": "Rock_Marble"
    },
    {
      "x": 2,
      "y": 1,
      "z": 1,
      "name": "Rock_Marble"
    },
    {
      "x": 2,
      "y": 2,
      "z": 1,
      "name": "Rock_Marble"
    },
    {
      "x": 2,
      "y": 3,
      "z": 1,
      "name": "Soil_Pebbles"
    },
    {
      "x": 2,
      "y": 4,
      "z": 1,
      "name": "Rubble_Marble"
    },
    {
      "x": 2,
      "y": 2,
      "z": 2,
      "name": "Rock_Lime"
    },
    {
      "x": 2,
      "y": 3,
      "z": 2,
      "name": "Rock_Marble"
    },
    {
      "x": 2,
      "y": 4,
      "z": 2,
      "name": "Soil_Pebbles"
    },
    {
      "x": 2,
      "y": 5,
      "z": 2,
      "name": "Rubble_Marble_Medium"
    },
    {
      "x": 2,
      "y": 2,
      "z": 3,
      "name": "Rock_Lime"
    },
    {
      "x": 2,
      "y": 3,
      "z": 3,
      "name": "Rock_Marble"
    },
    {
      "x": 2,
      "y": 4,
      "z": 3,
      "name": "Soil_Pebbles"
    },
    {
      "x": 3,
      "y": 2,
      "z": -4,
      "name": "Rock_Lime"
    },
    {
      "x": 3,
      "y": 3,
      "z": -4,
      "name": "Rock_Marble"
    },
    {
      "x": 3,
      "y": 4,
      "z": -4,
      "name": "Rock_Marble_SkyGrass"
    },
    {
      "x": 3,
      "y": 0,
      "z": -3,
      "name": "Rock_Marble"
    },
    {
      "x": 3,
      "y": 1,
      "z": -3,
      "name": "Rock_Chalk"
    },
    {
      "x": 3,
      "y": 2,
      "z": -3,
      "name": "Rock_Marble"
    },
    {
      "x": 3,
      "y": 3,
      "z": -3,
      "name": "Rock_Marble"
    },
    {
      "x": 3,
      "y": 4,
      "z": -3,
      "name": "Rock_Marble_SkyGrass"
    },
    {
      "x": 3,
      "y": 5,
      "z": -3,
      "name": "Plant_Grass_Sky"
    },
    {
      "x": 3,
      "y": 0,
      "z": -2,
      "name": "Rock_Marble"
    },
    {
      "x": 3,
      "y": 1,
      "z": -2,
      "name": "Rock_Marble"
    },
    {
      "x": 3,
      "y": 2,
      "z": -2,
      "name": "Rock_Marble"
    },
    {
      "x": 3,
      "y": 3,
      "z": -2,
      "name": "Soil_Pebbles"
    },
    {
      "x": 3,
      "y": 0,
      "z": -1,
      "name": "Rock_Marble"
    },
    {
      "x": 3,
      "y": 1,
      "z": -1,
      "name": "Rock_Marble"
    },
    {
      "x": 3,
      "y": 2,
      "z": -1,
      "name": "Rock_Marble"
    },
    {
      "x": 3,
      "y": 3,
      "z": -1,
      "name": "Soil_Pebbles"
    },
    {
      "x": 3,
      "y": 0,
      "z": 0,
      "name": "Rock_Marble"
    },
    {
      "x": 3,
      "y": 1,
      "z": 0,
      "name": "Rock_Marble"
    },
    {
      "x": 3,
      "y": 2,
      "z": 0,
      "name": "Rock_Marble"
    },
    {
      "x": 3,
      "y": 3,
      "z": 0,
      "name": "Soil_Pebbles"
    },
    {
      "x": 3,
      "y": 0,
      "z": 1,
      "name": "Rock_Marble"
    },
    {
      "x": 3,
      "y": 1,
      "z": 1,
      "name": "Rock_Marble"
    },
    {
      "x": 3,
      "y": 2,
      "z": 1,
      "name": "Rock_Marble"
    },
    {
      "x": 3,
      "y": 3,
      "z": 1,
      "name": "Soil_Pebbles"
    },
    {
      "x": 3,
      "y": 2,
      "z": 2,
      "name": "Rock_Lime"
    },
    {
      "x": 3,
      "y": 3,
      "z": 2,
      "name": "Rock_Lime"
    },
    {
      "x": 3,
      "y": 4,
      "z": 2,
      "name": "Soil_Pebbles"
    },
    {
      "x": 4,
      "y": 2,
      "z": -4,
      "name": "Rock_Lime"
    },
    {
      "x": 4,
      "y": 3,
      "z": -4,
      "name": "Rock_Marble"
    },
    {
      "x": 4,
      "y": 4,
      "z": -4,
      "name": "Rock_Marble_SkyGrass"
    },
    {
      "x": 4,
      "y": 0,
      "z": -3,
      "name": "Rock_Marble"
    },
    {
      "x": 4,
      "y": 1,
      "z": -3,
      "name": "Rock_Chalk"
    },
    {
      "x": 4,
      "y": 2,
      "z": -3,
      "name": "Rock_Lime"
    },
    {
      "x": 4,
      "y": 3,
      "z": -3,
      "name": "Rock_Marble"
    },
    {
      "x": 4,
      "y": 4,
      "z": -3,
      "name": "Soil_Pebbles"
    },
    {
      "x": 4,
      "y": 0,
      "z": -2,
      "name": "Rock_Marble"
    },
    {
      "x": 4,
      "y": 1,
      "z": -2,
      "name": "Rock_Marble"
    },
    {
      "x": 4,
      "y": 2,
      "z": -2,
      "name": "Rock_Marble"
    },
    {
      "x": 4,
      "y": 3,
      "z": -2,
      "name": "Rock_Marble"
    },
    {
      "x": 4,
      "y": 4,
      "z": -2,
      "name": "Soil_Pebbles"
    },
    {
      "x": 4,
      "y": 0,
      "z": -1,
      "name": "Rock_Marble"
    },
    {
      "x": 4,
      "y": 1,
      "z": -1,
      "name": "Rock_Marble"
    },
    {
      "x": 4,
      "y": 2,
      "z": -1,
      "name": "Rock_Marble"
    },
    {
      "x": 4,
      "y": 3,
      "z": -1,
      "name": "Rock_Marble"
    },
    {
      "x": 4,
      "y": 4,
      "z": -1,
      "name": "Soil_Pebbles"
    },
    {
      "x": 4,
      "y": 5,
      "z": -1,
      "name": "Rubble_Marble"
    },
    {
      "x": 4,
      "y": 0,
      "z": 0,
      "name": "Rock_Marble"
    },
    {
      "x": 4,
      "y": 1,
      "z": 0,
      "name": "Rock_Marble"
    },
    {
      "x": 4,
      "y": 2,
      "z": 0,
      "name": "Rock_Marble"
    },
    {
      "x": 4,
      "y": 3,
      "z": 0,
      "name": "Rock_Marble"
    },
    {
      "x": 4,
      "y": 4,
      "z": 0,
      "name": "Soil_Pebbles"
    },
    {
      "x": 4,
      "y": 0,
      "z": 1,
      "name": "Rock_Marble"
    },
    {
      "x": 4,
      "y": 1,
      "z": 1,
      "name": "Rock_Marble"
    },
    {
      "x": 4,
      "y": 2,
      "z": 1,
      "name": "Rock_Lime"
    },
    {
      "x": 4,
      "y": 3,
      "z": 1,
      "name": "Rock_Lime"
    },
    {
      "x": 4,
      "y": 4,
      "z": 1,
      "name": "Soil_Pebbles"
    },
    {
      "x": 4,
      "y": 2,
      "z": 2,
      "name": "Rock_Lime"
    },
    {
      "x": 4,
      "y": 3,
      "z": 2,
      "name": "Rock_Lime"
    },
    {
      "x": 4,
      "y": 4,
      "z": 2,
      "name": "Soil_Pebbles"
    },
    {
      "x": 5,
      "y": 0,
      "z": -2,
      "name": "Rock_Marble"
    },
    {
      "x": 5,
      "y": 1,
      "z": -2,
      "name": "Rock_Chalk"
    },
    {
      "x": 5,
      "y": 2,
      "z": -2,
      "name": "Rock_Lime"
    },
    {
      "x": 5,
      "y": 3,
      "z": -2,
      "name": "Rock_Marble"
    },
    {
      "x": 5,
      "y": 4,
      "z": -2,
      "name": "Soil_Pebbles"
    },
    {
      "x": 5,
      "y": 0,
      "z": -1,
      "name": "Rock_Marble"
    },
    {
      "x": 5,
      "y": 1,
      "z": -1,
      "name": "Rock_Marble"
    },
    {
      "x": 5,
      "y": 2,
      "z": -1,
      "name": "Rock_Lime"
    },
    {
      "x": 5,
      "y": 3,
      "z": -1,
      "name": "Rock_Lime"
    },
    {
      "x": 5,
      "y": 4,
      "z": -1,
      "name": "Soil_Pebbles"
    },
    {
      "x": 5,
      "y": 0,
      "z": 0,
      "name": "Rock_Marble"
    },
    {
      "x": 5,
      "y": 1,
      "z": 0,
      "name": "Rock_Marble"
    },
    {
      "x": 5,
      "y": 2,
      "z": 0,
      "name": "Rock_Lime"
    },
    {
      "x": 5,
      "y": 3,
      "z": 0,
      "name": "Rock_Lime"
    },
    {
      "x": 5,
      "y": 4,
      "z": 0,
      "name": "Soil_Pebbles"
    }
  ],
  "fluids": [
    {
      "x": -4,
      "y": 4,
      "z": 1,
      "name": "Water_Source",
      "level": 1
    },
    {
      "x": -3,
      "y": 4,
      "z": -1,
      "name": "Water_Source",
      "level": 1
    },
    {
      "x": -3,
      "y": 4,
      "z": 0,
      "name": "Water_Source",
      "level": 1
    },
    {
      "x": -3,
      "y": 4,
      "z": 1,
      "name": "Water_Source",
      "level": 1
    },
    {
      "x": -3,
      "y": 4,
      "z": 2,
      "name": "Water_Source",
      "level": 1
    },
    {
      "x": -2,
      "y": 4,
      "z": -2,
      "name": "Water_Source",
      "level": 1
    },
    {
      "x": -2,
      "y": 4,
      "z": -1,
      "name": "Water_Source",
      "level": 1
    },
    {
      "x": -2,
      "y": 4,
      "z": 0,
      "name": "Water_Source",
      "level": 1
    },
    {
      "x": -2,
      "y": 4,
      "z": 1,
      "name": "Water_Source",
      "level": 1
    },
    {
      "x": -2,
      "y": 4,
      "z": 2,
      "name": "Water_Source",
      "level": 1
    },
    {
      "x": -1,
      "y": 4,
      "z": -3,
      "name": "Water_Source",
      "level": 1
    },
    {
      "x": -1,
      "y": 4,
      "z": -2,
      "name": "Water_Source",
      "level": 1
    },
    {
      "x": -1,
      "y": 3,
      "z": -1,
      "name": "Water_Source",
      "level": 1
    },
    {
      "x": -1,
      "y": 4,
      "z": -1,
      "name": "Water_Source",
      "level": 1
    },
    {
      "x": -1,
      "y": 3,
      "z": 0,
      "name": "Water_Source",
      "level": 1
    },
    {
      "x": -1,
      "y": 4,
      "z": 0,
      "name": "Water_Source",
      "level": 1
    },
    {
      "x": -1,
      "y": 4,
      "z": 1,
      "name": "Water_Source",
      "level": 1
    },
    {
      "x": -1,
      "y": 4,
      "z": 2,
      "name": "Water_Source",
      "level": 1
    },
    {
      "x": 0,
      "y": 4,
      "z": -3,
      "name": "Water_Source",
      "level": 1
    },
    {
      "x": 0,
      "y": 3,
      "z": -2,
      "name": "Water_Source",
      "level": 1
    },
    {
      "x": 0,
      "y": 4,
      "z": -2,
      "name": "Water_Source",
      "level": 1
    },
    {
      "x": 0,
      "y": 3,
      "z": -1,
      "name": "Water_Source",
      "level": 1
    },
    {
      "x": 0,
      "y": 4,
      "z": -1,
      "name": "Water_Source",
      "level": 1
    },
    {
      "x": 0,
      "y": 3,
      "z": 0,
      "name": "Water_Source",
      "level": 1
    },
    {
      "x": 0,
      "y": 4,
      "z": 0,
      "name": "Water_Source",
      "level": 1
    },
    {
      "x": 0,
      "y": 4,
      "z": 1,
      "name": "Water_Source",
      "level": 1
    },
    {
      "x": 0,
      "y": 4,
      "z": 2,
      "name": "Water",
      "level": 8
    },
    {
      "x": 0,
      "y": 4,
      "z": 3,
      "name": "Water_Source",
      "level": 1
    },
    {
      "x": 0,
      "y": -1,
      "z": 4,
      "name": "Water",
      "level": 8
    },
    {
      "x": 0,
      "y": 0,
      "z": 4,
      "name": "Water",
      "level": 8
    },
    {
      "x": 0,
      "y": 1,
      "z": 4,
      "name": "Water",
      "level": 8
    },
    {
      "x": 0,
      "y": 2,
      "z": 4,
      "name": "Water",
      "level": 8
    },
    {
      "x": 0,
      "y": 3,
      "z": 4,
      "name": "Water",
      "level": 8
    },
    {
      "x": 0,
      "y": 4,
      "z": 4,
      "name": "Water",
      "level": 7
    },
    {
      "x": 1,
      "y": 4,
      "z": -3,
      "name": "Water_Source",
      "level": 1
    },
    {
      "x": 1,
      "y": 3,
      "z": -2,
      "name": "Water_Source",
      "level": 1
    },
    {
      "x": 1,
      "y": 4,
      "z": -2,
      "name": "Water_Source",
      "level": 1
    },
    {
      "x": 1,
      "y": 3,
      "z": -1,
      "name": "Water_Source",
      "level": 1
    },
    {
      "x": 1,
      "y": 4,
      "z": -1,
      "name": "Water_Source",
      "level": 1
    },
    {
      "x": 1,
      "y": 3,
      "z": 0,
      "name": "Water_Source",
      "level": 1
    },
    {
      "x": 1,
      "y": 4,
      "z": 0,
      "name": "Water_Source",
      "level": 1
    },
    {
      "x": 1,
      "y": 4,
      "z": 1,
      "name": "Water_Source",
      "level": 1
    },
    {
      "x": 1,
      "y": 4,
      "z": 2,
      "name": "Water_Source",
      "level": 1
    },
    {
      "x": 1,
      "y": 4,
      "z": 3,
      "name": "Water_Source",
      "level": 1
    },
    {
      "x": 1,
      "y": -1,
      "z": 4,
      "name": "Water",
      "level": 8
    },
    {
      "x": 1,
      "y": 0,
      "z": 4,
      "name": "Water",
      "level": 8
    },
    {
      "x": 1,
      "y": 1,
      "z": 4,
      "name": "Water",
      "level": 8
    },
    {
      "x": 1,
      "y": 2,
      "z": 4,
      "name": "Water",
      "level": 8
    },
    {
      "x": 1,
      "y": 3,
      "z": 4,
      "name": "Water",
      "level": 8
    },
    {
      "x": 1,
      "y": 4,
      "z": 4,
      "name": "Water",
      "level": 7
    },
    {
      "x": 2,
      "y": 4,
      "z": -3,
      "name": "Water_Source",
      "level": 1
    },
    {
      "x": 2,
      "y": 4,
      "z": -2,
      "name": "Water_Source",
      "level": 1
    },
    {
      "x": 2,
      "y": 3,
      "z": -1,
      "name": "Water_Source",
      "level": 1
    },
    {
      "x": 2,
      "y": 4,
      "z": -1,
      "name": "Water_Source",
      "level": 1
    },
    {
      "x": 2,
      "y": 3,
      "z": 0,
      "name": "Water_Source",
      "level": 1
    },
    {
      "x": 2,
      "y": 4,
      "z": 0,
      "name": "Water_Source",
      "level": 1
    },
    {
      "x": 2,
      "y": 4,
      "z": 1,
      "name": "Water_Source",
      "level": 1
    },
    {
      "x": 3,
      "y": 4,
      "z": -2,
      "name": "Water_Source",
      "level": 1
    },
    {
      "x": 3,
      "y": 4,
      "z": -1,
      "name": "Water_Source",
      "level": 1
    },
    {
      "x": 3,
      "y": 4,
      "z": 0,
      "name": "Water_Source",
      "level": 1
    },
    {
      "x": 3,
      "y": 4,
      "z": 1,
      "name": "Water_Source",
      "level": 1
    }
  ]
}