{
  "version": 8,
  "blockIdVersion": 11,
  "anchorX": 5,
  "anchorY": 10,
  "anchorZ": 0,
  "blocks": [
    {
      "x": -16,
      "y": 2,
      "z": 18,
      "name": "Wood_Birch_Branch_Corner",
      "rotation": 3
    },
    {
      "x": -15,
      "y": 3,
      "z": 17,
      "name": "Wood_Birch_Branch_Corner",
      "rotation": 3
    },
    {
      "x": -15,
      "y": 4,
      "z": 17,
      "name": "Wood_Birch_Branch_Corner",
      "rotation": 8
    },
    {
      "x": -15,
      "y": 2,
      "z": 18,
      "name": "Wood_Birch_Branch_Corner",
      "rotation": 1
    },
    {
      "x": -15,
      "y": 3,
      "z": 18,
      "name": "Wood_Birch_Branch_Long"
    },
    {
      "x": -15,
      "y": 4,
      "z": 18,
      "name": "Wood_Birch_Branch_Corner",
      "rotation": 10
    },
    {
      "x": -14,
      "y": 3,
      "z": 17,
      "name": "Wood_Birch_Branch_Corner",
      "rotation": 1
    },
    {
      "x": -14,
      "y": 4,
      "z": 17,
      "name": "Wood_Birch_Branch_Corner",
      "rotation": 34
    },
    {
      "x": -14,
      "y": 7,
      "z": 17,
      "name": "Wood_Birch_Trunk_Full",
      "rotation": 6
    },
    {
      "x": -14,
      "y": 4,
      "z": 18,
      "name": "Wood_Birch_Branch_Corner"
    },
    {
      "x": -14,
      "y": 5,
      "z": 18,
      "name": "Wood_Birch_Branch_Long",
      "rotation": 1
    },
    {
      "x": -14,
      "y": 6,
      "z": 18,
      "name": "Wood_Birch_Branch_Long",
      "rotation": 1
    },
    {
      "x": -14,
      "y": 7,
      "z": 18,
      "name": "Wood_Birch_Branch_Corner",
      "rotation": 32
    },
    {
      "x": -13,
      "y": 10,
      "z": 13,
      "name": "Wood_Birch_Trunk_Full",
      "rotation": 5
    },
    {
      "x": -13,
      "y": 10,
      "z": 14,
      "name": "Wood_Birch_Trunk_Full",
      "rotation": 4
    },
    {
      "x": -13,
      "y": 5,
      "z": 15,
      "name": "Wood_Birch_Branch_Corner",
      "rotation": 3
    },
    {
      "x": -13,
      "y": 6,
      "z": 15,
      "name": "Wood_Birch_Branch_Long",
      "rotation": 1
    },
    {
      "x": -13,
      "y": 7,
      "z": 15,
      "name": "Wood_Birch_Trunk_Full",
      "rotation": 4
    },
    {
      "x": -13,
      "y": 8,
      "z": 15,
      "name": "Wood_Birch_Trunk_Full",
      "rotation": 1
    },
    {
      "x": -13,
      "y": 9,
      "z": 15,
      "name": "Wood_Birch_Trunk",
      "rotation": 1
    },
    {
      "x": -13,
      "y": 10,
      "z": 15,
      "name": "Wood_Birch_Trunk_Full",
      "rotation": 1
    },
    {
      "x": -13,
      "y": 7,
      "z": 16,
      "name": "Wood_Birch_Trunk_Full",
      "rotation": 4
    },
    {
      "x": -13,
      "y": 7,
      "z": 17,
      "name": "Wood_Birch_Trunk_Full",
      "rotation": 6
    },
    {
      "x": -12,
      "y": 10,
      "z": 13,
      "name": "Wood_Birch_Trunk_Full",
      "rotation": 5
    },
    {
      "x": -12,
      "y": 4,
      "z": 14,
      "name": "Wood_Birch_Branch_Corner",
      "rotation": 2
    },
    {
      "x": -12,
      "y": 4,
      "z": 15,
      "name": "Wood_Birch_Branch_Corner"
    },
    {
      "x": -12,
      "y": 5,
      "z": 15,
      "name": "Wood_Birch_Branch_Corner",
      "rotation": 33
    },
    {
      "x": -11,
      "y": 10,
      "z": 13,
      "name": "Wood_Birch_Trunk_Full",
      "rotation": 6
    },
    {
      "x": -11,
      "y": 11,
      "z": 13,
      "name": "Wood_Birch_Trunk_Full",
      "rotation": 6
    },
    {
      "x": -11,
      "y": 7,
      "z": 15,
      "name": "Wood_Birch_Branch_Corner",
      "rotation": 3
    },
    {
      "x": -11,
      "y": 8,
      "z": 15,
      "name": "Wood_Birch_Branch_Corner",
      "rotation": 8
    },
    {
      "x": -11,
      "y": 8,
      "z": 16,
      "name": "Wood_Birch_Branch_Corner",
      "rotation": 10
    },
    {
      "x": -10,
      "y": 11,
      "z": 12,
      "name": "Wood_Birch_Trunk_Full",
      "rotation": 4
    },
    {
      "x": -10,
      "y": 11,
      "z": 13,
      "name": "Wood_Birch_Trunk_Full",
      "rotation": 4
    },
    {
      "x": -10,
      "y": 11,
      "z": 14,
      "name": "Wood_Birch_Trunk_Full",
      "rotation": 4
    },
    {
      "x": -10,
      "y": 7,
      "z": 15,
      "name": "Wood_Birch_Branch_Corner",
      "rotation": 1
    },
    {
      "x": -10,
      "y": 8,
      "z": 15,
      "name": "Wood_Birch_Branch_Long"
    },
    {
      "x": -10,
      "y": 9,
      "z": 15,
      "name": "Wood_Birch_Branch_Long"
    },
    {
      "x": -10,
      "y": 10,
      "z": 15,
      "name": "Wood_Birch_Trunk_Full",
      "rotation": 6
    },
    {
      "x": -10,
      "y": 5,
      "z": 18,
      "name": "Wood_Birch_Branch_Corner",
      "rotation": 3
    },
    {
      "x": -10,
      "y": 6,
      "z": 18,
      "name": "Wood_Birch_Branch_Long",
      "rotation": 1
    },
    {
      "x": -10,
      "y": 7,
      "z": 18,
      "name": "Wood_Birch_Branch_Long",
      "rotation": 1
    },
    {
      "x": -10,
      "y": 8,
      "z": 18,
      "name": "Wood_Birch_Trunk_Full",
      "rotation": 1
    },
    {
      "x": -10,
      "y": 9,
      "z": 18,
      "name": "Wood_Birch_Trunk_Full"
    },
    {
      "x": -9,
      "y": 10,
      "z": 12,
      "name": "Wood_Birch_Trunk_Full",
      "rotation": 4
    },
    {
      "x": -9,
      "y": 11,
      "z": 12,
      "name": "Wood_Birch_Trunk_Full",
      "rotation": 4
    },
    {
      "x": -9,
      "y": 1,
      "z": 13,
      "name": "Wood_Birch_Branch_Corner",
      "rotation": 2
    },
    {
      "x": -9,
      "y": 2,
      "z": 13,
      "name": "Wood_Birch_Branch_Corner",
      "rotation": 11
    },
    {
      "x": -9,
      "y": 10,
      "z": 13,
      "name": "Wood_Birch_Trunk_Full",
      "rotation": 4
    },
    {
      "x": -9,
      "y": 11,
      "z": 13,
      "name": "Wood_Birch_Trunk_Full",
      "rotation": 6
    },
    {
      "x": -9,
      "y": 1,
      "z": 14,
      "name": "Wood_Birch_Branch_Corner"
    },
    {
      "x": -9,
      "y": 2,
      "z": 14,
      "name": "Wood_Birch_Branch_Long",
      "rotation": 1
    },
    {
      "x": -9,
      "y": 3,
      "z": 14,
      "name": "Wood_Birch_Trunk",
      "rotation": 1
    },
    {
      "x": -9,
      "y": 4,
      "z": 14,
      "name": "Wood_Birch_Trunk_Full",
      "rotation": 6
    },
    {
      "x": -9,
      "y": 10,
      "z": 14,
      "name": "Wood_Birch_Trunk",
      "rotation": 6
    },
    {
      "x": -9,
      "y": 11,
      "z": 14,
      "name": "Wood_Birch_Trunk_Full",
      "rotation": 4
    },
    {
      "x": -9,
      "y": 10,
      "z": 15,
      "name": "Wood_Birch_Trunk",
      "rotation": 5
    },
    {
      "x": -9,
      "y": 10,
      "z": 16,
      "name": "Wood_Birch_Trunk_Full",
      "rotation": 5
    },
    {
      "x": -9,
      "y": 10,
      "z": 17,
      "name": "Wood_Birch_Trunk_Full",
      "rotation": 4
    },
    {
      "x": -9,
      "y": 5,
      "z": 18,
      "name": "Wood_Birch_Branch_Corner",
      "rotation": 1
    },
    {
      "x": -9,
      "y": 6,
      "z": 18,
      "name": "Wood_Birch_Branch_Corner",
      "rotation": 32
    },
    {
      "x": -9,
      "y": 9,
      "z": 18,
      "name": "Wood_Birch_Trunk_Full"
    },
    {
      "x": -9,
      "y": 10,
      "z": 18,
      "name": "Wood_Birch_Trunk_Full"
    },
    {
      "x": -8,
      "y": 10,
      "z": 11,
      "name": "Wood_Birch_Trunk_Full",
      "rotation": 4
    },
    {
      "x": -8,
      "y": 11,
      "z": 11,
      "name": "Wood_Birch_Trunk_Full",
      "rotation": 6
    },
    {
      "x": -8,
      "y": 10,
      "z": 12,
      "name": "Wood_Birch_Trunk",
      "rotation": 6
    },
    {
      "x": -8,
      "y": 11,
      "z": 12,
      "name": "Wood_Birch_Trunk_Full",
      "rotation": 4
    },
    {
      "x": -8,
      "y": 12,
      "z": 12,
      "name": "Wood_Birch_Trunk_Half"
    },
    {
      "x": -8,
      "y": 4,
      "z": 13,
      "name": "Wood_Birch_Trunk_Full",
      "rotation": 4
    },
    {
      "x": -8,
      "y": 7,
      "z": 13,
      "name": "Wood_Birch_Trunk_Full"
    },
    {
      "x": -8,
      "y": 8,
      "z": 13,
      "name": "Wood_Birch_Trunk_Full"
    },
    {
      "x": -8,
      "y": 9,
      "z": 13,
      "name": "Wood_Birch_Trunk_Full"
    },
    {
      "x": -8,
      "y": 10,
      "z": 13,
      "name": "Wood_Birch_Trunk",
      "rotation": 6
    },
    {
      "x": -8,
      "y": 11,
      "z": 13,
      "name": "Wood_Birch_Trunk_Full",
      "rotation": 4
    },
    {
      "x": -8,
      "y": 12,
      "z": 13,
      "name": "Wood_Birch_Trunk_Half"
    },
    {
      "x": -8,
      "y": 4,
      "z": 14,
      "name": "Wood_Birch_Trunk_Full",
      "rotation": 4
    },
    {
      "x": -8,
      "y": 10,
      "z": 14,
      "name": "Wood_Birch_Trunk_Full",
      "rotation": 4
    },
    {
      "x": -8,
      "y": 9,
      "z": 16,
      "name": "Wood_Birch_Trunk_Full",
      "rotation": 6
    },
    {
      "x": -8,
      "y": 10,
      "z": 16,
      "name": "Wood_Birch_Trunk_Full",
      "rotation": 5
    },
    {
      "x": -7,
      "y": 10,
      "z": 10,
      "name": "Wood_Birch_Trunk_Full",
      "rotation": 4
    },
    {
      "x": -7,
      "y": 10,
      "z": 11,
      "name": "Wood_Birch_Trunk",
      "rotation": 6
    },
    {
      "x": -7,
      "y": 11,
      "z": 11,
      "name": "Wood_Birch_Trunk_Full",
      "rotation": 4
    },
    {
      "x": -7,
      "y": 4,
      "z": 12,
      "name": "Wood_Birch_Trunk_Full",
      "rotation": 4
    },
    {
      "x": -7,
      "y": 5,
      "z": 12,
      "name": "Wood_Birch_Trunk",
      "rotation": 1
    },
    {
      "x": -7,
      "y": 6,
      "z": 12,
      "name": "Wood_Birch_Trunk",
      "rotation": 1
    },
    {
      "x": -7,
      "y": 7,
      "z": 12,
      "name": "Wood_Birch_Trunk_Full",
      "rotation": 6
    },
    {
      "x": -7,
      "y": 9,
      "z": 12,
      "name": "Wood_Birch_Trunk_Full",
      "rotation": 6
    },
    {
      "x": -7,
      "y": 10,
      "z": 12,
      "name": "Wood_Birch_Trunk",
      "rotation": 6
    },
    {
      "x": -7,
      "y": 11,
      "z": 12,
      "name": "Wood_Birch_Trunk_Full",
      "rotation": 4
    },
    {
      "x": -7,
      "y": 4,
      "z": 13,
      "name": "Wood_Birch_Trunk_Full",
      "rotation": 4
    },
    {
      "x": -7,
      "y": 10,
      "z": 13,
      "name": "Wood_Birch_Trunk_Full",
      "rotation": 4
    },
    {
      "x": -6,
      "y": 9,
      "z": 9,
      "name": "Wood_Birch_Trunk_Full",
      "rotation": 6
    },
    {
      "x": -6,
      "y": 10,
      "z": 9,
      "name": "Wood_Birch_Trunk_Half",
      "rotation": 1
    },
    {
      "x": -6,
      "y": 5,
      "z": 10,
      "name": "Wood_Birch_Branch_Corner",
      "rotation": 2
    },
    {
      "x": -6,
      "y": 6,
      "z": 10,
      "name": "Wood_Birch_Branch_Corner",
      "rotation": 8
    },
    {
      "x": -6,
      "y": 9,
      "z": 10,
      "name": "Wood_Birch_Trunk_Full",
      "rotation": 4
    },
    {
      "x": -6,
      "y": 10,
      "z": 10,
      "name": "Wood_Birch_Trunk_Full",
      "rotation": 4
    },
    {
      "x": -6,
      "y": 11,
      "z": 10,
      "name": "Wood_Birch_Trunk_Half"
    },
    {
      "x": -6,
      "y": 5,
      "z": 11,
      "name": "Wood_Birch_Branch_Corner"
    },
    {
      "x": -6,
      "y": 6,
      "z": 11,
      "name": "Wood_Birch_Branch_Long",
      "rotation": 6
    },
    {
      "x": -6,
      "y": 9,
      "z": 11,
      "name": "Wood_Birch_Trunk",
      "rotation": 6
    },
    {
      "x": -6,
      "y": 10,
      "z": 11,
      "name": "Wood_Birch_Trunk",
      "rotation": 6
    },
    {
      "x": -6,
      "y": 11,
      "z": 11,
      "name": "Wood_Birch_Trunk_Full",
      "rotation": 4
    },
    {
      "x": -6,
      "y": 14,
      "z": 11,
      "name": "Plant_Leaves_Aspen"
    },
    {
      "x": -6,
      "y": 6,
      "z": 12,
      "name": "Wood_Birch_Branch_Corner"
    },
    {
      "x": -6,
      "y": 7,
      "z": 12,
      "name": "Wood_Birch_Branch_Corner",
      "rotation": 11
    },
    {
      "x": -6,
      "y": 9,
      "z": 12,
      "name": "Wood_Birch_Trunk_Full",
      "rotation": 4
    },
    {
      "x": -6,
      "y": 10,
      "z": 12,
      "name": "Wood_Birch_Trunk",
      "rotation": 6
    },
    {
      "x": -6,
      "y": 11,
      "z": 12,
      "name": "Wood_Birch_Trunk_Full",
      "rotation": 4
    },
    {
      "x": -6,
      "y": 14,
      "z": 12,
      "name": "Plant_Leaves_Aspen"
    },
    {
      "x": -6,
      "y": 10,
      "z": 13,
      "name": "Wood_Birch_Trunk_Full",
      "rotation": 6
    },
    {
      "x": -6,
      "y": 14,
      "z": 13,
      "name": "Plant_Leaves_Aspen"
    },
    {
      "x": -5,
      "y": 9,
      "z": 8,
      "name": "Wood_Birch_Trunk_Full",
      "rotation": 4
    },
    {
      "x": -5,
      "y": 10,
      "z": 8,
      "name": "Wood_Birch_Trunk_Half",
      "rotation": 1
    },
    {
      "x": -5,
      "y": 8,
      "z": 9,
      "name": "Wood_Birch_Trunk_Full",
      "rotation": 4
    },
    {
      "x": -5,
      "y": 9,
      "z": 9,
      "name": "Wood_Birch_Trunk",
      "rotation": 6
    },
    {
      "x": -5,
      "y": 10,
      "z": 9,
      "name": "Wood_Birch_Trunk_Half",
      "rotation": 1
    },
    {
      "x": -5,
      "y": 8,
      "z": 10,
      "name": "Wood_Birch_Trunk_Full",
      "rotation": 4
    },
    {
      "x": -5,
      "y": 9,
      "z": 10,
      "name": "Wood_Birch_Trunk",
      "rotation": 6
    },
    {
      "x": -5,
      "y": 10,
      "z": 10,
      "name": "Wood_Birch_Trunk_Full",
      "rotation": 4
    },
    {
      "x": -5,
      "y": 14,
      "z": 10,
      "name": "Plant_Leaves_Aspen"
    },
    {
      "x": -5,
      "y": 9,
      "z": 11,
      "name": "Wood_Birch_Trunk_Full",
      "rotation": 4
    },
    {
      "x": -5,
      "y": 10,
      "z": 11,
      "name": "Wood_Birch_Trunk_Full",
      "rotation": 4
    },
    {
      "x": -5,
      "y": 14,
      "z": 11,
      "name": "Plant_Leaves_Aspen"
    },
    {
      "x": -5,
      "y": 10,
      "z": 12,
      "name": "Wood_Birch_Trunk_Full",
      "rotation": 4
    },
    {
      "x": -5,
      "y": 14,
      "z": 12,
      "name": "Plant_Leaves_Aspen"
    },
    {
      "x": -5,
      "y": 14,
      "z": 13,
      "name": "Plant_Leaves_Aspen"
    },
    {
      "x": -5,
      "y": 14,
      "z": 14,
      "name": "Plant_Leaves_Aspen"
    },
    {
      "x": -4,
      "y": 15,
      "z": -2,
      "name": "Plant_Leaves_Aspen"
    },
    {
      "x": -4,
      "y": 15,
      "z": -1,
      "name": "Plant_Leaves_Aspen"
    },
    {
      "x": -4,
      "y": 15,
      "z": 0,
      "name": "Plant_Leaves_Aspen"
    },
    {
      "x": -4,
      "y": 9,
      "z": 6,
      "name": "Wood_Birch_Branch_Short",
      "rotation": 3
    },
    {
      "x": -4,
      "y": 8,
      "z": 7,
      "name": "Wood_Birch_Trunk_Full",
      "rotation": 4
    },
    {
      "x": -4,
      "y": 9,
      "z": 7,
      "name": "Wood_Birch_Trunk_Full",
      "rotation": 4
    },
    {
      "x": -4,
      "y": 8,
      "z": 8,
      "name": "Wood_Birch_Trunk_Full",
      "rotation": 6
    },
    {
      "x": -4,
      "y": 9,
      "z": 8,
      "name": "Wood_Birch_Trunk",
      "rotation": 6
    },
    {
      "x": -4,
      "y": 7,
      "z": 9,
      "name": "Wood_Birch_Trunk_Half",
      "rotation": 35
    },
    {
      "x": -4,
      "y": 8,
      "z": 9,
      "name": "Wood_Birch_Trunk",
      "rotation": 6
    },
    {
      "x": -4,
      "y": 9,
      "z": 9,
      "name": "Wood_Birch_Trunk",
      "rotation": 6
    },
    {
      "x": -4,
      "y": 10,
      "z": 9,
      "name": "Wood_Birch_Trunk_Full",
      "rotation": 4
    },
    {
      "x": -4,
      "y": 8,
      "z": 10,
      "name": "Wood_Birch_Trunk_Full",
      "rotation": 6
    },
    {
      "x": -4,
      "y": 9,
      "z": 10,
      "name": "Wood_Birch_Trunk",
      "rotation": 6
    },
    {
      "x": -4,
      "y": 10,
      "z": 10,
      "name": "Wood_Birch_Trunk_Full",
      "rotation": 6
    },
    {
      "x": -4,
      "y": 14,
      "z": 10,
      "name": "Plant_Leaves_Aspen"
    },
    {
      "x": -4,
      "y": 9,
      "z": 11,
      "name": "Wood_Birch_Trunk_Full",
      "rotation": 6
    },
    {
      "x": -4,
      "y": 10,
      "z": 11,
      "name": "Wood_Birch_Trunk_Full",
      "rotation": 4
    },
    {
      "x": -4,
      "y": 14,
      "z": 11,
      "name": "Plant_Leaves_Aspen"
    },
    {
      "x": -4,
      "y": 10,
      "z": 12,
      "name": "Wood_Birch_Branch_Corner",
      "rotation": 1
    },
    {
      "x": -4,
      "y": 11,
      "z": 12,
      "name": "Wood_Birch_Branch_Long"
    },
    {
      "x": -4,
      "y": 12,
      "z": 12,
      "name": "Wood_Birch_Branch_Long"
    },
    {
      "x": -4,
      "y": 13,
      "z": 12,
      "name": "Wood_Birch_Branch_Long"
    },
    {
      "x": -4,
      "y": 14,
      "z": 12,
      "name": "Wood_Birch_Branch_Long"
    },
    {
      "x": -4,
      "y": 15,
      "z": 12,
      "name": "Plant_Leaves_Aspen"
    },
    {
      "x": -4,
      "y": 14,
      "z": 13,
      "name": "Plant_Leaves_Aspen"
    },
    {
      "x": -4,
      "y": 14,
      "z": 14,
      "name": "Plant_Leaves_Aspen"
    },
    {
      "x": -3,
      "y": 15,
      "z": -3,
      "name": "Plant_Leaves_Aspen"
    },
    {
      "x": -3,
      "y": 15,
      "z": -2,
      "name": "Plant_Leaves_Aspen"
    },
    {
      "x": -3,
      "y": 15,
      "z": -1,
      "name": "Plant_Leaves_Aspen"
    },
    {
      "x": -3,
      "y": 15,
      "z": 0,
      "name": "Plant_Leaves_Aspen"
    },
    {
      "x": -3,
      "y": 15,
      "z": 1,
      "name": "Plant_Leaves_Aspen"
    },
    {
      "x": -3,
      "y": 8,
      "z": 6,
      "name": "Wood_Birch_Trunk_Full",
      "rotation": 4
    },
    {
      "x": -3,
      "y": 9,
      "z": 6,
      "name": "Wood_Birch_Trunk_Full",
      "rotation": 6
    },
    {
      "x": -3,
      "y": 7,
      "z": 7,
      "name": "Wood_Birch_Trunk_Full",
      "rotation": 4
    },
    {
      "x": -3,
      "y": 8,
      "z": 7,
      "name": "Wood_Birch_Trunk",
      "rotation": 6
    },
    {
      "x": -3,
      "y": 9,
      "z": 7,
      "name": "Wood_Birch_Trunk",
      "rotation": 6
    },
    {
      "x": -3,
      "y": 6,
      "z": 8,
      "name": "Wood_Birch_Trunk_Half",
      "rotation": 35
    },
    {
      "x": -3,
      "y": 7,
      "z": 8,
      "name": "Wood_Birch_Trunk",
      "rotation": 6
    },
    {
      "x": -3,
      "y": 8,
      "z": 8,
      "name": "Wood_Birch_Trunk",
      "rotation": 6
    },
    {
      "x": -3,
      "y": 9,
      "z": 8,
      "name": "Wood_Birch_Trunk",
      "rotation": 6
    },
    {
      "x": -3,
      "y": 10,
      "z": 8,
      "name": "Wood_Birch_Trunk_Half",
      "rotation": 1
    },
    {
      "x": -3,
      "y": 8,
      "z": 9,
      "name": "Wood_Birch_Trunk",
      "rotation": 6
    },
    {
      "x": -3,
      "y": 9,
      "z": 9,
      "name": "Wood_Birch_Trunk_Full",
      "rotation": 6
    },
    {
      "x": -3,
      "y": 10,
      "z": 9,
      "name": "Wood_Birch_Trunk_Half"
    },
    {
      "x": -3,
      "y": 8,
      "z": 10,
      "name": "Wood_Birch_Trunk_Full",
      "rotation": 6
    },
    {
      "x": -3,
      "y": 9,
      "z": 10,
      "name": "Wood_Birch_Trunk_Full",
      "rotation": 4
    },
    {
      "x": -3,
      "y": 10,
      "z": 10,
      "name": "Wood_Birch_Trunk_Full",
      "rotation": 6
    },
    {
      "x": -3,
      "y": 14,
      "z": 10,
      "name": "Plant_Leaves_Aspen"
    },
    {
      "x": -3,
      "y": 14,
      "z": 11,
      "name": "Plant_Leaves_Aspen"
    },
    {
      "x": -3,
      "y": 14,
      "z": 12,
      "name": "Plant_Leaves_Aspen"
    },
    {
      "x": -3,
      "y": 14,
      "z": 13,
      "name": "Plant_Leaves_Aspen"
    },
    {
      "x": -3,
      "y": 14,
      "z": 14,
      "name": "Plant_Leaves_Aspen"
    },
    {
      "x": -2,
      "y": 15,
      "z": -4,
      "name": "Plant_Leaves_Aspen"
    },
    {
      "x": -2,
      "y": 15,
      "z": -3,
      "name": "Plant_Leaves_Aspen"
    },
    {
      "x": -2,
      "y": 15,
      "z": -2,
      "name": "Plant_Leaves_Aspen"
    },
    {
      "x": -2,
      "y": 15,
      "z": -1,
      "name": "Plant_Leaves_Aspen"
    },
    {
      "x": -2,
      "y": 16,
      "z": -1,
      "name": "Plant_Leaves_Aspen"
    },
    {
      "x": -2,
      "y": 17,
      "z": -1,
      "name": "Plant_Leaves_Aspen"
    },
    {
      "x": -2,
      "y": 12,
      "z": 0,
      "name": "Plant_Leaves_Aspen"
    },
    {
      "x": -2,
      "y": 15,
      "z": 0,
      "name": "Plant_Leaves_Aspen"
    },
    {
      "x": -2,
      "y": 17,
      "z": 0,
      "name": "Plant_Leaves_Aspen"
    },
    {
      "x": -2,
      "y": 12,
      "z": 1,
      "name": "Plant_Leaves_Aspen"
    },
    {
      "x": -2,
      "y": 15,
      "z": 1,
      "name": "Plant_Leaves_Aspen"
    },
    {
      "x": -2,
      "y": 17,
      "z": 1,
      "name": "Plant_Leaves_Aspen"
    },
    {
      "x": -2,
      "y": 12,
      "z": 2,
      "name": "Plant_Leaves_Aspen"
    },
    {
      "x": -2,
      "y": 15,
      "z": 2,
      "name": "Plant_Leaves_Aspen"
    },
    {
      "x": -2,
      "y": 17,
      "z": 2,
      "name": "Plant_Leaves_Aspen"
    },
    {
      "x": -2,
      "y": 17,
      "z": 3,
      "name": "Plant_Leaves_Aspen"
    },
    {
      "x": -2,
      "y": 7,
      "z": 4,
      "name": "Wood_Birch_Trunk_Full",
      "rotation": 4
    },
    {
      "x": -2,
      "y": 7,
      "z": 5,
      "name": "Wood_Birch_Trunk",
      "rotation": 6
    },
    {
      "x": -2,
      "y": 8,
      "z": 5,
      "name": "Wood_Birch_Trunk_Full",
      "rotation": 6
    },
    {
      "x": -2,
      "y": 7,
      "z": 6,
      "name": "Wood_Birch_Trunk_Full",
      "rotation": 6
    },
    {
      "x": -2,
      "y": 8,
      "z": 6,
      "name": "Wood_Birch_Trunk",
      "rotation": 6
    },
    {
      "x": -2,
      "y": 6,
      "z": 7,
      "name": "Wood_Birch_Trunk_Full",
      "rotation": 6
    },
    {
      "x": -2,
      "y": 7,
      "z": 7,
      "name": "Wood_Birch_Trunk",
      "rotation": 6
    },
    {
      "x": -2,
      "y": 8,
      "z": 7,
      "name": "Wood_Birch_Trunk",
      "rotation": 6
    },
    {
      "x": -2,
      "y": 9,
      "z": 7,
      "name": "Wood_Birch_Trunk_Half"
    },
    {
      "x": -2,
      "y": 7,
      "z": 8,
      "name": "Wood_Birch_Trunk_Full",
      "rotation": 6
    },
    {
      "x": -2,
      "y": 8,
      "z": 8,
      "name": "Wood_Birch_Trunk",
      "rotation": 6
    },
    {
      "x": -2,
      "y": 9,
      "z": 8,
      "name": "Wood_Birch_Trunk_Half"
    },
    {
      "x": -2,
      "y": 7,
      "z": 9,
      "name": "Wood_Birch_Trunk_Full",
      "rotation": 6
    },
    {
      "x": -2,
      "y": 8,
      "z": 9,
      "name": "Wood_Birch_Trunk_Full",
      "rotation": 4
    },
    {
      "x": -2,
      "y": 9,
      "z": 9,
      "name": "Wood_Birch_Trunk_Half",
      "rotation": 1
    },
    {
      "x": -2,
      "y": 14,
      "z": 11,
      "name": "Plant_Leaves_Aspen"
    },
    {
      "x": -2,
      "y": 14,
      "z": 12,
      "name": "Plant_Leaves_Aspen"
    },
    {
      "x": -2,
      "y": 14,
      "z": 13,
      "name": "Plant_Leaves_Aspen"
    },
    {
      "x": -1,
      "y": 15,
      "z": -4,
      "name": "Plant_Leaves_Aspen"
    },
    {
      "x": -1,
      "y": 15,
      "z": -3,
      "name": "Plant_Leaves_Aspen"
    },
    {
      "x": -1,
      "y": 15,
      "z": -2,
      "name": "Plant_Leaves_Aspen"
    },
    {
      "x": -1,
      "y": 16,
      "z": -2,
      "name": "Plant_Leaves_Aspen"
    },
    {
      "x": -1,
      "y": 17,
      "z": -2,
      "name": "Plant_Leaves_Aspen"
    },
    {
      "x": -1,
      "y": 13,
      "z": -1,
      "name": "Wood_Birch_Branch_Corner",
      "rotation": 2
    },
    {
      "x": -1,
      "y": 14,
      "z": -1,
      "name": "Wood_Birch_Branch_Long"
    },
    {
      "x": -1,
      "y": 15,
      "z": -1,
      "name": "Wood_Birch_Branch_Long"
    },
    {
      "x": -1,
      "y": 16,
      "z": -1,
      "name": "Wood_Birch_Branch_Long"
    },
    {
      "x": -1,
      "y": 17,
      "z": -1,
      "name": "Plant_Leaves_Aspen"
    },
    {
      "x": -1,
      "y": 12,
      "z": 0,
      "name": "Plant_Leaves_Aspen"
    },
    {
      "x": -1,
      "y": 13,
      "z": 0,
      "name": "Wood_Birch_Branch_Long",
      "rotation": 4
    },
    {
      "x": -1,
      "y": 15,
      "z": 0,
      "name": "Plant_Leaves_Aspen"
    },
    {
      "x": -1,
      "y": 16,
      "z": 0,
      "name": "Plant_Leaves_Aspen"
    },
    {
      "x": -1,
      "y": 17,
      "z": 0,
      "name": "Plant_Leaves_Aspen"
    },
    {
      "x": -1,
      "y": 10,
      "z": 1,
      "name": "Wood_Birch_Trunk_Full"
    },
    {
      "x": -1,
      "y": 11,
      "z": 1,
      "name": "Wood_Birch_Trunk_Full"
    },
    {
      "x": -1,
      "y": 12,
      "z": 1,
      "name": "Wood_Birch_Trunk_Full"
    },
    {
      "x": -1,
      "y": 13,
      "z": 1,
      "name": "Wood_Birch_Trunk_Full"
    },
    {
      "x": -1,
      "y": 14,
      "z": 1,
      "name": "Wood_Birch_Trunk_Full"
    },
    {
      "x": -1,
      "y": 15,
      "z": 1,
      "name": "Plant_Leaves_Aspen"
    },
    {
      "x": -1,
      "y": 17,
      "z": 1,
      "name": "Plant_Leaves_Aspen"
    },
    {
      "x": -1,
      "y": 9,
      "z": 2,
      "name": "Wood_Birch_Trunk_Half",
      "rotation": 7
    },
    {
      "x": -1,
      "y": 10,
      "z": 2,
      "name": "Wood_Birch_Trunk_Half",
      "rotation": 4
    },
    {
      "x": -1,
      "y": 11,
      "z": 2,
      "name": "Wood_Birch_Trunk_Half",
      "rotation": 4
    },
    {
      "x": -1,
      "y": 12,
      "z": 2,
      "name": "Plant_Leaves_Aspen"
    },
    {
      "x": -1,
      "y": 15,
      "z": 2,
      "name": "Plant_Leaves_Aspen"
    },
    {
      "x": -1,
      "y": 17,
      "z": 2,
      "name": "Plant_Leaves_Aspen"
    },
    {
      "x": -1,
      "y": 7,
      "z": 3,
      "name": "Wood_Birch_Trunk_Full",
      "rotation": 4
    },
    {
      "x": -1,
      "y": 17,
      "z": 3,
      "name": "Plant_Leaves_Aspen"
    },
    {
      "x": -1,
      "y": 7,
      "z": 4,
      "name": "Wood_Birch_Trunk",
      "rotation": 6
    },
    {
      "x": -1,
      "y": 17,
      "z": 4,
      "name": "Plant_Leaves_Aspen"
    },
    {
      "x": -1,
      "y": 7,
      "z": 5,
      "name": "Wood_Birch_Trunk",
      "rotation": 6
    },
    {
      "x": -1,
      "y": 8,
      "z": 5,
      "name": "Wood_Birch_Trunk_Full",
      "rotation": 6
    },
    {
      "x": -1,
      "y": 6,
      "z": 6,
      "name": "Wood_Birch_Trunk_Full"
    },
    {
      "x": -1,
      "y": 7,
      "z": 6,
      "name": "Wood_Birch_Trunk",
      "rotation": 6
    },
    {
      "x": -1,
      "y": 8,
      "z": 6,
      "name": "Wood_Birch_Trunk",
      "rotation": 4
    },
    {
      "x": -1,
      "y": 6,
      "z": 7,
      "name": "Wood_Birch_Trunk_Half",
      "rotation": 5
    },
    {
      "x": -1,
      "y": 7,
      "z": 7,
      "name": "Wood_Birch_Trunk",
      "rotation": 6
    },
    {
      "x": -1,
      "y": 8,
      "z": 7,
      "name": "Wood_Birch_Trunk",
      "rotation": 4
    },
    {
      "x": -1,
      "y": 7,
      "z": 8,
      "name": "Wood_Birch_Trunk",
      "rotation": 6
    },
    {
      "x": -1,
      "y": 8,
      "z": 8,
      "name": "Wood_Birch_Trunk_Full",
      "rotation": 6
    },
    {
      "x": -1,
      "y": 7,
      "z": 9,
      "name": "Wood_Birch_Trunk_Full",
      "rotation": 4
    },
    {
      "x": 0,
      "y": 15,
      "z": -4,
      "name": "Plant_Leaves_Aspen"
    },
    {
      "x": 0,
      "y": 15,
      "z": -3,
      "name": "Plant_Leaves_Aspen"
    },
    {
      "x": 0,
      "y": 17,
      "z": -3,
      "name": "Plant_Leaves_Aspen"
    },
    {
      "x": 0,
      "y": 15,
      "z": -2,
      "name": "Plant_Leaves_Aspen"
    },
    {
      "x": 0,
      "y": 17,
      "z": -2,
      "name": "Plant_Leaves_Aspen"
    },
    {
      "x": 0,
      "y": 15,
      "z": -1,
      "name": "Plant_Leaves_Aspen"
    },
    {
      "x": 0,
      "y": 16,
      "z": -1,
      "name": "Plant_Leaves_Aspen"
    },
    {
      "x": 0,
      "y": 17,
      "z": -1,
      "name": "Plant_Leaves_Aspen"
    },
    {
      "x": 0,
      "y": 12,
      "z": 0,
      "name": "Plant_Leaves_Aspen"
    },
    {
      "x": 0,
      "y": 15,
      "z": 0,
      "name": "Plant_Leaves_Aspen"
    },
    {
      "x": 0,
      "y": 17,
      "z": 0,
      "name": "Plant_Leaves_Aspen"
    },
    {
      "x": 0,
      "y": 9,
      "z": 1,
      "name": "Wood_Birch_Trunk_Half",
      "rotation": 6
    },
    {
      "x": 0,
      "y": 10,
      "z": 1,
      "name": "Wood_Birch_Trunk_Half",
      "rotation": 5
    },
    {
      "x": 0,
      "y": 11,
      "z": 1,
      "name": "Wood_Birch_Trunk_Half",
      "rotation": 5
    },
    {
      "x": 0,
      "y": 12,
      "z": 1,
      "name": "Plant_Leaves_Aspen"
    },
    {
      "x": 0,
      "y": 14,
      "z": 1,
      "name": "Wood_Birch_Trunk_Full",
      "rotation": 5
    },
    {
      "x": 0,
      "y": 15,
      "z": 1,
      "name": "Wood_Birch_Trunk_Full"
    },
    {
      "x": 0,
      "y": 17,
      "z": 1,
      "name": "Plant_Leaves_Aspen"
    },
    {
      "x": 0,
      "y": 7,
      "z": 2,
      "name": "Wood_Birch_Trunk_Full"
    },
    {
      "x": 0,
      "y": 8,
      "z": 2,
      "name": "Wood_Birch_Trunk_Full"
    },
    {
      "x": 0,
      "y": 9,
      "z": 2,
      "name": "Wood_Birch_Trunk_Full"
    },
    {
      "x": 0,
      "y": 10,
      "z": 2,
      "name": "Wood_Birch_Trunk_Full"
    },
    {
      "x": 0,
      "y": 12,
      "z": 2,
      "name": "Plant_Leaves_Aspen"
    },
    {
      "x": 0,
      "y": 15,
      "z": 2,
      "name": "Plant_Leaves_Aspen"
    },
    {
      "x": 0,
      "y": 17,
      "z": 2,
      "name": "Plant_Leaves_Aspen"
    },
    {
      "x": 0,
      "y": 7,
      "z": 3,
      "name": "Wood_Birch_Trunk_Full",
      "rotation": 4
    },
    {
      "x": 0,
      "y": 17,
      "z": 3,
      "name": "Plant_Leaves_Aspen"
    },
    {
      "x": 0,
      "y": 6,
      "z": 4,
      "name": "Wood_Birch_Trunk_Full",
      "rotation": 4
    },
    {
      "x": 0,
      "y": 7,
      "z": 4,
      "name": "Wood_Birch_Trunk_Full",
      "rotation": 4
    },
    {
      "x": 0,
      "y": 8,
      "z": 4,
      "name": "Wood_Birch_Trunk_Half"
    },
    {
      "x": 0,
      "y": 17,
      "z": 4,
      "name": "Plant_Leaves_Aspen"
    },
    {
      "x": 0,
      "y": 5,
      "z": 5,
      "name": "Wood_Birch_Trunk_Half",
      "rotation": 35
    },
    {
      "x": 0,
      "y": 6,
      "z": 5,
      "name": "Wood_Birch_Trunk",
      "rotation": 6
    },
    {
      "x": 0,
      "y": 7,
      "z": 5,
      "name": "Wood_Birch_Trunk",
      "rotation": 6
    },
    {
      "x": 0,
      "y": 8,
      "z": 5,
      "name": "Wood_Birch_Trunk_Half"
    },
    {
      "x": 0,
      "y": 17,
      "z": 5,
      "name": "Plant_Leaves_Aspen"
    },
    {
      "x": 0,
      "y": 6,
      "z": 6,
      "name": "Wood_Birch_Trunk_Full",
      "rotation": 4
    },
    {
      "x": 0,
      "y": 7,
      "z": 6,
      "name": "Wood_Birch_Trunk",
      "rotation": 6
    },
    {
      "x": 0,
      "y": 8,
      "z": 6,
      "name": "Wood_Birch_Trunk_Half"
    },
    {
      "x": 0,
      "y": 7,
      "z": 7,
      "name": "Wood_Birch_Trunk",
      "rotation": 6
    },
    {
      "x": 0,
      "y": 8,
      "z": 7,
      "name": "Wood_Birch_Trunk_Half"
    },
    {
      "x": 0,
      "y": 7,
      "z": 8,
      "name": "Wood_Birch_Trunk_Full",
      "rotation": 4
    },
    {
      "x": 1,
      "y": 15,
      "z": -3,
      "name": "Plant_Leaves_Aspen"
    },
    {
      "x": 1,
      "y": 17,
      "z": -3,
      "name": "Plant_Leaves_Aspen"
    },
    {
      "x": 1,
      "y": 15,
      "z": -2,
      "name": "Plant_Leaves_Aspen"
    },
    {
      "x": 1,
      "y": 17,
      "z": -2,
      "name": "Plant_Leaves_Aspen"
    },
    {
      "x": 1,
      "y": 15,
      "z": -1,
      "name": "Plant_Leaves_Aspen"
    },
    {
      "x": 1,
      "y": 17,
      "z": -1,
      "name": "Plant_Leaves_Aspen"
    },
    {
      "x": 1,
      "y": 15,
      "z": 0,
      "name": "Plant_Leaves_Aspen"
    },
    {
      "x": 1,
      "y": 17,
      "z": 0,
      "name": "Plant_Leaves_Aspen"
    },
    {
      "x": 1,
      "y": 18,
      "z": 0,
      "name": "Plant_Leaves_Aspen"
    },
    {
      "x": 1,
      "y": 15,
      "z": 1,
      "name": "Wood_Birch_Trunk_Full",
      "rotation": 5
    },
    {
      "x": 1,
      "y": 17,
      "z": 1,
      "name": "Plant_Leaves_Aspen"
    },
    {
      "x": 1,
      "y": 18,
      "z": 1,
      "name": "Plant_Leaves_Aspen"
    },
    {
      "x": 1,
      "y": 6,
      "z": 2,
      "name": "Wood_Birch_Trunk_Full",
      "rotation": 4
    },
    {
      "x": 1,
      "y": 7,
      "z": 2,
      "name": "Wood_Birch_Trunk_Full",
      "rotation": 6
    },
    {
      "x": 1,
      "y": 17,
      "z": 2,
      "name": "Plant_Leaves_Aspen"
    },
    {
      "x": 1,
      "y": 18,
      "z": 2,
      "name": "Plant_Leaves_Aspen"
    },
    {
      "x": 1,
      "y": 6,
      "z": 3,
      "name": "Wood_Birch_Trunk_Full",
      "rotation": 6
    },
    {
      "x": 1,
      "y": 7,
      "z": 3,
      "name": "Wood_Birch_Trunk",
      "rotation": 6
    },
    {
      "x": 1,
      "y": 17,
      "z": 3,
      "name": "Plant_Leaves_Aspen"
    },
    {
      "x": 1,
      "y": 5,
      "z": 4,
      "name": "Wood_Birch_Trunk_Half",
      "rotation": 35
    },
    {
      "x": 1,
      "y": 6,
      "z": 4,
      "name": "Wood_Birch_Trunk",
      "rotation": 6
    },
    {
      "x": 1,
      "y": 7,
      "z": 4,
      "name": "Wood_Birch_Trunk",
      "rotation": 6
    },
    {
      "x": 1,
      "y": 17,
      "z": 4,
      "name": "Plant_Leaves_Aspen"
    },
    {
      "x": 1,
      "y": 6,
      "z": 5,
      "name": "Wood_Birch_Trunk_Full",
      "rotation": 6
    },
    {
      "x": 1,
      "y": 7,
      "z": 5,
      "name": "Wood_Birch_Trunk",
      "rotation": 6
    },
    {
      "x": 1,
      "y": 17,
      "z": 5,
      "name": "Plant_Leaves_Aspen"
    },
    {
      "x": 1,
      "y": 7,
      "z": 6,
      "name": "Wood_Birch_Trunk",
      "rotation": 6
    },
    {
      "x": 1,
      "y": 7,
      "z": 7,
      "name": "Wood_Birch_Trunk_Full",
      "rotation": 4
    },
    {
      "x": 2,
      "y": 17,
      "z": -3,
      "name": "Plant_Leaves_Aspen"
    },
    {
      "x": 2,
      "y": 15,
      "z": -2,
      "name": "Plant_Leaves_Aspen"
    },
    {
      "x": 2,
      "y": 17,
      "z": -2,
      "name": "Plant_Leaves_Aspen"
    },
    {
      "x": 2,
      "y": 15,
      "z": -1,
      "name": "Plant_Leaves_Aspen"
    },
    {
      "x": 2,
      "y": 17,
      "z": -1,
      "name": "Plant_Leaves_Aspen"
    },
    {
      "x": 2,
      "y": 15,
      "z": 0,
      "name": "Plant_Leaves_Aspen"
    },
    {
      "x": 2,
      "y": 17,
      "z": 0,
      "name": "Plant_Leaves_Aspen"
    },
    {
      "x": 2,
      "y": 18,
      "z": 0,
      "name": "Plant_Leaves_Aspen"
    },
    {
      "x": 2,
      "y": 6,
      "z": 1,
      "name": "Wood_Birch_Trunk_Full",
      "rotation": 4
    },
    {
      "x": 2,
      "y": 7,
      "z": 1,
      "name": "Wood_Birch_Trunk_Half",
      "rotation": 1
    },
    {
      "x": 2,
      "y": 10,
      "z": 1,
      "name": "Wood_Birch_Branch_Corner",
      "rotation": 3
    },
    {
      "x": 2,
      "y": 11,
      "z": 1,
      "name": "Wood_Birch_Branch_Corner",
      "rotation": 9
    },
    {
      "x": 2,
      "y": 15,
      "z": 1,
      "name": "Wood_Birch_Trunk_Full",
      "rotation": 5
    },
    {
      "x": 2,
      "y": 16,
      "z": 1,
      "name": "Wood_Birch_Branch_Long"
    },
    {
      "x": 2,
      "y": 17,
      "z": 1,
      "name": "Wood_Birch_Branch_Long"
    },
    {
      "x": 2,
      "y": 18,
      "z": 1,
      "name": "Plant_Leaves_Aspen"
    },
    {
      "x": 2,
      "y": 6,
      "z": 2,
      "name": "Wood_Birch_Trunk",
      "rotation": 6
    },
    {
      "x": 2,
      "y": 7,
      "z": 2,
      "name": "Wood_Birch_Trunk_Full",
      "rotation": 6
    },
    {
      "x": 2,
      "y": 17,
      "z": 2,
      "name": "Plant_Leaves_Aspen"
    },
    {
      "x": 2,
      "y": 18,
      "z": 2,
      "name": "Plant_Leaves_Aspen"
    },
    {
      "x": 2,
      "y": 5,
      "z": 3,
      "name": "Wood_Birch_Trunk_Full",
      "rotation": 4
    },
    {
      "x": 2,
      "y": 6,
      "z": 3,
      "name": "Wood_Birch_Trunk",
      "rotation": 6
    },
    {
      "x": 2,
      "y": 7,
      "z": 3,
      "name": "Wood_Birch_Trunk",
      "rotation": 6
    },
    {
      "x": 2,
      "y": 8,
      "z": 3,
      "name": "Wood_Birch_Trunk_Half",
      "rotation": 1
    },
    {
      "x": 2,
      "y": 17,
      "z": 3,
      "name": "Plant_Leaves_Aspen"
    },
    {
      "x": 2,
      "y": 5,
      "z": 4,
      "name": "Wood_Birch_Trunk_Full",
      "rotation": 4
    },
    {
      "x": 2,
      "y": 6,
      "z": 4,
      "name": "Wood_Birch_Trunk",
      "rotation": 6
    },
    {
      "x": 2,
      "y": 7,
      "z": 4,
      "name": "Wood_Birch_Trunk",
      "rotation": 6
    },
    {
      "x": 2,
      "y": 8,
      "z": 4,
      "name": "Wood_Birch_Trunk_Half"
    },
    {
      "x": 2,
      "y": 17,
      "z": 4,
      "name": "Plant_Leaves_Aspen"
    },
    {
      "x": 2,
      "y": 6,
      "z": 5,
      "name": "Wood_Birch_Trunk_Full",
      "rotation": 6
    },
    {
      "x": 2,
      "y": 7,
      "z": 5,
      "name": "Wood_Birch_Trunk",
      "rotation": 6
    },
    {
      "x": 2,
      "y": 17,
      "z": 5,
      "name": "Plant_Leaves_Aspen"
    },
    {
      "x": 2,
      "y": 7,
      "z": 6,
      "name": "Wood_Birch_Trunk_Full",
      "rotation": 4
    },
    {
      "x": 3,
      "y": 17,
      "z": -3,
      "name": "Plant_Leaves_Aspen"
    },
    {
      "x": 3,
      "y": 17,
      "z": -2,
      "name": "Plant_Leaves_Aspen"
    },
    {
      "x": 3,
      "y": 17,
      "z": -1,
      "name": "Plant_Leaves_Aspen"
    },
    {
      "x": 3,
      "y": 5,
      "z": 0,
      "name": "Wood_Birch_Trunk_Full",
      "rotation": 4
    },
    {
      "x": 3,
      "y": 6,
      "z": 0,
      "name": "Wood_Birch_Trunk_Full",
      "rotation": 4
    },
    {
      "x": 3,
      "y": 17,
      "z": 0,
      "name": "Plant_Leaves_Aspen"
    },
    {
      "x": 3,
      "y": 18,
      "z": 0,
      "name": "Plant_Leaves_Aspen"
    },
    {
      "x": 3,
      "y": 5,
      "z": 1,
      "name": "Wood_Birch_Trunk_Full",
      "rotation": 6
    },
    {
      "x": 3,
      "y": 6,
      "z": 1,
      "name": "Wood_Birch_Trunk",
      "rotation": 6
    },
    {
      "x": 3,
      "y": 7,
      "z": 1,
      "name": "Wood_Birch_Trunk_Half",
      "rotation": 1
    },
    {
      "x": 3,
      "y": 10,
      "z": 1,
      "name": "Wood_Birch_Branch_Corner",
      "rotation": 1
    },
    {
      "x": 3,
      "y": 11,
      "z": 1,
      "name": "Wood_Birch_Branch_Corner",
      "rotation": 9
    },
    {
      "x": 3,
      "y": 14,
      "z": 1,
      "name": "Wood_Birch_Trunk_Full"
    },
    {
      "x": 3,
      "y": 15,
      "z": 1,
      "name": "Wood_Birch_Trunk_Full"
    },
    {
      "x": 3,
      "y": 17,
      "z": 1,
      "name": "Plant_Leaves_Aspen"
    },
    {
      "x": 3,
      "y": 18,
      "z": 1,
      "name": "Plant_Leaves_Aspen"
    },
    {
      "x": 3,
      "y": 4,
      "z": 2,
      "name": "Wood_Birch_Trunk_Half",
      "rotation": 35
    },
    {
      "x": 3,
      "y": 5,
      "z": 2,
      "name": "Wood_Birch_Trunk",
      "rotation": 6
    },
    {
      "x": 3,
      "y": 6,
      "z": 2,
      "name": "Wood_Birch_Trunk",
      "rotation": 6
    },
    {
      "x": 3,
      "y": 7,
      "z": 2,
      "name": "Wood_Birch_Trunk_Full",
      "rotation": 4
    },
    {
      "x": 3,
      "y": 8,
      "z": 2,
      "name": "Wood_Birch_Trunk_Half",
      "rotation": 1
    },
    {
      "x": 3,
      "y": 17,
      "z": 2,
      "name": "Plant_Leaves_Aspen"
    },
    {
      "x": 3,
      "y": 18,
      "z": 2,
      "name": "Plant_Leaves_Aspen"
    },
    {
      "x": 3,
      "y": 5,
      "z": 3,
      "name": "Wood_Birch_Trunk_Full",
      "rotation": 4
    },
    {
      "x": 3,
      "y": 6,
      "z": 3,
      "name": "Wood_Birch_Trunk",
      "rotation": 6
    },
    {
      "x": 3,
      "y": 7,
      "z": 3,
      "name": "Wood_Birch_Trunk",
      "rotation": 6
    },
    {
      "x": 3,
      "y": 8,
      "z": 3,
      "name": "Wood_Birch_Trunk_Half"
    },
    {
      "x": 3,
      "y": 17,
      "z": 3,
      "name": "Plant_Leaves_Aspen"
    },
    {
      "x": 3,
      "y": 6,
      "z": 4,
      "name": "Wood_Birch_Trunk",
      "rotation": 6
    },
    {
      "x": 3,
      "y": 7,
      "z": 4,
      "name": "Wood_Birch_Trunk_Full",
      "rotation": 4
    },
    {
      "x": 3,
      "y": 17,
      "z": 4,
      "name": "Plant_Leaves_Aspen"
    },
    {
      "x": 3,
      "y": 6,
      "z": 5,
      "name": "Wood_Birch_Trunk_Full",
      "rotation": 4
    },
    {
      "x": 3,
      "y": 17,
      "z": 5,
      "name": "Plant_Leaves_Aspen"
    },
    {
      "x": 4,
      "y": 17,
      "z": -3,
      "name": "Plant_Leaves_Aspen"
    },
    {
      "x": 4,
      "y": 17,
      "z": -2,
      "name": "Plant_Leaves_Aspen"
    },
    {
      "x": 4,
      "y": 5,
      "z": -1,
      "name": "Wood_Birch_Trunk_Full",
      "rotation": 4
    },
    {
      "x": 4,
      "y": 6,
      "z": -1,
      "name": "Wood_Birch_Trunk_Full",
      "rotation": 4
    },
    {
      "x": 4,
      "y": 7,
      "z": -1,
      "name": "Wood_Birch_Trunk_Half",
      "rotation": 1
    },
    {
      "x": 4,
      "y": 17,
      "z": -1,
      "name": "Plant_Leaves_Aspen"
    },
    {
      "x": 4,
      "y": 5,
      "z": 0,
      "name": "Wood_Birch_Trunk",
      "rotation": 6
    },
    {
      "x": 4,
      "y": 6,
      "z": 0,
      "name": "Wood_Birch_Trunk",
      "rotation": 6
    },
    {
      "x": 4,
      "y": 7,
      "z": 0,
      "name": "Wood_Birch_Trunk_Full",
      "rotation": 4
    },
    {
      "x": 4,
      "y": 17,
      "z": 0,
      "name": "Plant_Leaves_Aspen"
    },
    {
      "x": 4,
      "y": 5,
      "z": 1,
      "name": "Wood_Birch_Trunk",
      "rotation": 6
    },
    {
      "x": 4,
      "y": 6,
      "z": 1,
      "name": "Wood_Birch_Trunk",
      "rotation": 6
    },
    {
      "x": 4,
      "y": 7,
      "z": 1,
      "name": "Wood_Birch_Trunk_Full",
      "rotation": 4
    },
    {
      "x": 4,
      "y": 11,
      "z": 1,
      "name": "Wood_Birch_Branch_Corner",
      "rotation": 1
    },
    {
      "x": 4,
      "y": 12,
      "z": 1,
      "name": "Wood_Birch_Branch_Long"
    },
    {
      "x": 4,
      "y": 13,
      "z": 1,
      "name": "Wood_Birch_Trunk_Full"
    },
    {
      "x": 4,
      "y": 14,
      "z": 1,
      "name": "Wood_Birch_Trunk_Full"
    },
    {
      "x": 4,
      "y": 17,
      "z": 1,
      "name": "Plant_Leaves_Aspen"
    },
    {
      "x": 4,
      "y": 5,
      "z": 2,
      "name": "Wood_Birch_Trunk",
      "rotation": 6
    },
    {
      "x": 4,
      "y": 6,
      "z": 2,
      "name": "Wood_Birch_Trunk",
      "rotation": 6
    },
    {
      "x": 4,
      "y": 7,
      "z": 2,
      "name": "Wood_Birch_Trunk_Full",
      "rotation": 6
    },
    {
      "x": 4,
      "y": 17,
      "z": 2,
      "name": "Plant_Leaves_Aspen"
    },
    {
      "x": 4,
      "y": 5,
      "z": 3,
      "name": "Wood_Birch_Trunk_Full",
      "rotation": 6
    },
    {
      "x": 4,
      "y": 6,
      "z": 3,
      "name": "Wood_Birch_Trunk",
      "rotation": 6
    },
    {
      "x": 4,
      "y": 7,
      "z": 3,
      "name": "Wood_Birch_Trunk_Full",
      "rotation": 4
    },
    {
      "x": 4,
      "y": 17,
      "z": 3,
      "name": "Plant_Leaves_Aspen"
    },
    {
      "x": 4,
      "y": 6,
      "z": 4,
      "name": "Wood_Birch_Trunk_Full",
      "rotation": 4
    },
    {
      "x": 4,
      "y": 17,
      "z": 4,
      "name": "Plant_Leaves_Aspen"
    },
    {
      "x": 4,
      "y": 17,
      "z": 5,
      "name": "Plant_Leaves_Aspen"
    },
    {
      "x": 5,
      "y": 5,
      "z": -2,
      "name": "Wood_Birch_Trunk_Full",
      "rotation": 4
    },
    {
      "x": 5,
      "y": 6,
      "z": -2,
      "name": "Wood_Birch_Trunk_Full",
      "rotation": 4
    },
    {
      "x": 5,
      "y": 7,
      "z": -2,
      "name": "Wood_Birch_Trunk_Full",
      "rotation": 6
    },
    {
      "x": 5,
      "y": 17,
      "z": -2,
      "name": "Plant_Leaves_Aspen"
    },
    {
      "x": 5,
      "y": 5,
      "z": -1,
      "name": "Wood_Birch_Trunk",
      "rotation": 6
    },
    {
      "x": 5,
      "y": 6,
      "z": -1,
      "name": "Wood_Birch_Trunk",
      "rotation": 6
    },
    {
      "x": 5,
      "y": 7,
      "z": -1,
      "name": "Wood_Birch_Trunk_Full",
      "rotation": 6
    },
    {
      "x": 5,
      "y": 17,
      "z": -1,
      "name": "Plant_Leaves_Aspen"
    },
    {
      "x": 5,
      "y": 5,
      "z": 0,
      "name": "Wood_Birch_Trunk",
      "rotation": 6
    },
    {
      "x": 5,
      "y": 6,
      "z": 0,
      "name": "Wood_Birch_Trunk",
      "rotation": 6
    },
    {
      "x": 5,
      "y": 7,
      "z": 0,
      "name": "Wood_Birch_Trunk_Full",
      "rotation": 6
    },
    {
      "x": 5,
      "y": 17,
      "z": 0,
      "name": "Plant_Leaves_Aspen"
    },
    {
      "x": 5,
      "y": 5,
      "z": 1,
      "name": "Wood_Birch_Trunk",
      "rotation": 6
    },
    {
      "x": 5,
      "y": 6,
      "z": 1,
      "name": "Wood_Birch_Trunk",
      "rotation": 6
    },
    {
      "x": 5,
      "y": 7,
      "z": 1,
      "name": "Wood_Birch_Trunk_Full",
      "rotation": 6
    },
    {
      "x": 5,
      "y": 17,
      "z": 1,
      "name": "Plant_Leaves_Aspen"
    },
    {
      "x": 5,
      "y": 5,
      "z": 2,
      "name": "Wood_Birch_Trunk_Full",
      "rotation": 4
    },
    {
      "x": 5,
      "y": 6,
      "z": 2,
      "name": "Wood_Birch_Trunk_Full",
      "rotation": 4
    },
    {
      "x": 5,
      "y": 17,
      "z": 2,
      "name": "Plant_Leaves_Aspen"
    },
    {
      "x": 5,
      "y": 6,
      "z": 3,
      "name": "Wood_Birch_Branch_Long",
      "rotation": 4
    },
    {
      "x": 5,
      "y": 17,
      "z": 3,
      "name": "Plant_Leaves_Aspen"
    },
    {
      "x": 5,
      "y": 6,
      "z": 4,
      "name": "Wood_Birch_Branch_Long",
      "rotation": 4
    },
    {
      "x": 5,
      "y": 17,
      "z": 4,
      "name": "Plant_Leaves_Aspen"
    },
    {
      "x": 5,
      "y": 6,
      "z": 5,
      "name": "Wood_Birch_Branch_Corner"
    },
    {
      "x": 5,
      "y": 7,
      "z": 5,
      "name": "Wood_Birch_Branch_Corner",
      "rotation": 9
    },
    {
      "x": 5,
      "y": 12,
      "z": 5,
      "name": "Plant_Leaves_Aspen"
    },
    {
      "x": 5,
      "y": 12,
      "z": 6,
      "name": "Plant_Leaves_Aspen"
    },
    {
      "x": 5,
      "y": 12,
      "z": 7,
      "name": "Plant_Leaves_Aspen"
    },
    {
      "x": 6,
      "y": 6,
      "z": -3,
      "name": "Wood_Birch_Trunk_Full",
      "rotation": 4
    },
    {
      "x": 6,
      "y": 7,
      "z": -3,
      "name": "Wood_Birch_Trunk_Full",
      "rotation": 4
    },
    {
      "x": 6,
      "y": 5,
      "z": -2,
      "name": "Wood_Birch_Trunk_Full",
      "rotation": 4
    },
    {
      "x": 6,
      "y": 6,
      "z": -2,
      "name": "Wood_Birch_Trunk",
      "rotation": 6
    },
    {
      "x": 6,
      "y": 7,
      "z": -2,
      "name": "Wood_Birch_Trunk",
      "rotation": 6
    },
    {
      "x": 6,
      "y": 5,
      "z": -1,
      "name": "Wood_Birch_Trunk",
      "rotation": 6
    },
    {
      "x": 6,
      "y": 6,
      "z": -1,
      "name": "Wood_Birch_Trunk",
      "rotation": 6
    },
    {
      "x": 6,
      "y": 7,
      "z": -1,
      "name": "Wood_Birch_Trunk",
      "rotation": 6
    },
    {
      "x": 6,
      "y": 17,
      "z": -1,
      "name": "Plant_Leaves_Aspen"
    },
    {
      "x": 6,
      "y": 5,
      "z": 0,
      "name": "Wood_Birch_Trunk",
      "rotation": 6
    },
    {
      "x": 6,
      "y": 6,
      "z": 0,
      "name": "Wood_Birch_Trunk",
      "rotation": 6
    },
    {
      "x": 6,
      "y": 7,
      "z": 0,
      "name": "Wood_Birch_Trunk_Full",
      "rotation": 4
    },
    {
      "x": 6,
      "y": 17,
      "z": 0,
      "name": "Plant_Leaves_Aspen"
    },
    {
      "x": 6,
      "y": 5,
      "z": 1,
      "name": "Wood_Birch_Trunk_Full",
      "rotation": 4
    },
    {
      "x": 6,
      "y": 6,
      "z": 1,
      "name": "Wood_Birch_Trunk_Full",
      "rotation": 4
    },
    {
      "x": 6,
      "y": 7,
      "z": 1,
      "name": "Wood_Birch_Trunk_Half",
      "rotation": 1
    },
    {
      "x": 6,
      "y": 17,
      "z": 1,
      "name": "Plant_Leaves_Aspen"
    },
    {
      "x": 6,
      "y": 17,
      "z": 2,
      "name": "Plant_Leaves_Aspen"
    },
    {
      "x": 6,
      "y": 12,
      "z": 3,
      "name": "Plant_Leaves_Aspen"
    },
    {
      "x": 6,
      "y": 17,
      "z": 3,
      "name": "Plant_Leaves_Aspen"
    },
    {
      "x": 6,
      "y": 12,
      "z": 4,
      "name": "Plant_Leaves_Aspen"
    },
    {
      "x": 6,
      "y": 7,
      "z": 5,
      "name": "Wood_Birch_Branch_Long",
      "rotation": 5
    },
    {
      "x": 6,
      "y": 12,
      "z": 5,
      "name": "Plant_Leaves_Aspen"
    },
    {
      "x": 6,
      "y": 12,
      "z": 6,
      "name": "Plant_Leaves_Aspen"
    },
    {
      "x": 6,
      "y": 12,
      "z": 7,
      "name": "Plant_Leaves_Aspen"
    },
    {
      "x": 6,
      "y": 12,
      "z": 8,
      "name": "Plant_Leaves_Aspen"
    },
    {
      "x": 7,
      "y": 6,
      "z": -4,
      "name": "Wood_Birch_Trunk_Full",
      "rotation": 4
    },
    {
      "x": 7,
      "y": 6,
      "z": -3,
      "name": "Wood_Birch_Trunk",
      "rotation": 6
    },
    {
      "x": 7,
      "y": 7,
      "z": -3,
      "name": "Wood_Birch_Trunk_Full",
      "rotation": 6
    },
    {
      "x": 7,
      "y": 5,
      "z": -2,
      "name": "Wood_Birch_Trunk_Full",
      "rotation": 4
    },
    {
      "x": 7,
      "y": 6,
      "z": -2,
      "name": "Wood_Birch_Trunk",
      "rotation": 6
    },
    {
      "x": 7,
      "y": 7,
      "z": -2,
      "name": "Wood_Birch_Trunk_Full",
      "rotation": 4
    },
    {
      "x": 7,
      "y": 5,
      "z": -1,
      "name": "Wood_Birch_Trunk",
      "rotation": 6
    },
    {
      "x": 7,
      "y": 6,
      "z": -1,
      "name": "Wood_Birch_Trunk_Full",
      "rotation": 4
    },
    {
      "x": 7,
      "y": 7,
      "z": -1,
      "name": "Wood_Birch_Trunk_Half"
    },
    {
      "x": 7,
      "y": 5,
      "z": 0,
      "name": "Wood_Birch_Trunk_Full",
      "rotation": 4
    },
    {
      "x": 7,
      "y": 6,
      "z": 0,
      "name": "Wood_Birch_Trunk_Full",
      "rotation": 4
    },
    {
      "x": 7,
      "y": 5,
      "z": 1,
      "name": "Wood_Birch_Trunk_Half",
      "rotation": 5
    },
    {
      "x": 7,
      "y": 12,
      "z": 3,
      "name": "Plant_Leaves_Aspen"
    },
    {
      "x": 7,
      "y": 12,
      "z": 4,
      "name": "Plant_Leaves_Aspen"
    },
    {
      "x": 7,
      "y": 7,
      "z": 5,
      "name": "Wood_Birch_Branch_Corner",
      "rotation": 1
    },
    {
      "x": 7,
      "y": 8,
      "z": 5,
      "name": "Wood_Birch_Branch_Corner",
      "rotation": 8
    },
    {
      "x": 7,
      "y": 12,
      "z": 5,
      "name": "Plant_Leaves_Aspen"
    },
    {
      "x": 7,
      "y": 13,
      "z": 5,
      "name": "Plant_Leaves_Aspen"
    },
    {
      "x": 7,
      "y": 8,
      "z": 6,
      "name": "Wood_Birch_Branch_Corner"
    },
    {
      "x": 7,
      "y": 9,
      "z": 6,
      "name": "Wood_Birch_Branch_Corner",
      "rotation": 9
    },
    {
      "x": 7,
      "y": 10,
      "z": 6,
      "name": "Plant_Leaves_Aspen"
    },
    {
      "x": 7,
      "y": 12,
      "z": 6,
      "name": "Plant_Leaves_Aspen"
    },
    {
      "x": 7,
      "y": 13,
      "z": 6,
      "name": "Plant_Leaves_Aspen"
    },
    {
      "x": 7,
      "y": 10,
      "z": 7,
      "name": "Plant_Leaves_Aspen"
    },
    {
      "x": 7,
      "y": 12,
      "z": 7,
      "name": "Plant_Leaves_Aspen"
    },
    {
      "x": 7,
      "y": 13,
      "z": 7,
      "name": "Plant_Leaves_Aspen"
    },
    {
      "x": 7,
      "y": 12,
      "z": 8,
      "name": "Plant_Leaves_Aspen"
    },
    {
      "x": 7,
      "y": 12,
      "z": 9,
      "name": "Plant_Leaves_Aspen"
    },
    {
      "x": 8,
      "y": 6,
      "z": -5,
      "name": "Wood_Birch_Trunk_Full",
      "rotation": 6
    },
    {
      "x": 8,
      "y": 6,
      "z": -4,
      "name": "Wood_Birch_Trunk",
      "rotation": 6
    },
    {
      "x": 8,
      "y": 7,
      "z": -4,
      "name": "Wood_Birch_Trunk_Full",
      "rotation": 4
    },
    {
      "x": 8,
      "y": 5,
      "z": -3,
      "name": "Wood_Birch_Trunk_Full",
      "rotation": 4
    },
    {
      "x": 8,
      "y": 6,
      "z": -3,
      "name": "Wood_Birch_Trunk",
      "rotation": 6
    },
    {
      "x": 8,
      "y": 7,
      "z": -3,
      "name": "Wood_Birch_Trunk_Full",
      "rotation": 4
    },
    {
      "x": 8,
      "y": 8,
      "z": -3,
      "name": "Wood_Birch_Trunk_Half",
      "rotation": 1
    },
    {
      "x": 8,
      "y": 5,
      "z": -2,
      "name": "Wood_Birch_Trunk_Full",
      "rotation": 6
    },
    {
      "x": 8,
      "y": 6,
      "z": -2,
      "name": "Wood_Birch_Trunk",
      "rotation": 6
    },
    {
      "x": 8,
      "y": 7,
      "z": -2,
      "name": "Wood_Birch_Trunk_Full",
      "rotation": 6
    },
    {
      "x": 8,
      "y": 8,
      "z": -2,
      "name": "Wood_Birch_Trunk_Half"
    },
    {
      "x": 8,
      "y": 5,
      "z": -1,
      "name": "Wood_Birch_Trunk_Full",
      "rotation": 6
    },
    {
      "x": 8,
      "y": 6,
      "z": -1,
      "name": "Wood_Birch_Trunk_Full",
      "rotation": 4
    },
    {
      "x": 8,
      "y": 7,
      "z": -1,
      "name": "Wood_Birch_Trunk_Half",
      "rotation": 1
    },
    {
      "x": 8,
      "y": 5,
      "z": 0,
      "name": "Wood_Birch_Trunk_Half",
      "rotation": 5
    },
    {
      "x": 8,
      "y": 12,
      "z": 2,
      "name": "Plant_Leaves_Aspen"
    },
    {
      "x": 8,
      "y": 12,
      "z": 3,
      "name": "Plant_Leaves_Aspen"
    },
    {
      "x": 8,
      "y": 12,
      "z": 4,
      "name": "Plant_Leaves_Aspen"
    },
    {
      "x": 8,
      "y": 11,
      "z": 5,
      "name": "Plant_Leaves_Aspen"
    },
    {
      "x": 8,
      "y": 12,
      "z": 5,
      "name": "Plant_Leaves_Aspen"
    },
    {
      "x": 8,
      "y": 13,
      "z": 5,
      "name": "Plant_Leaves_Aspen"
    },
    {
      "x": 8,
      "y": 9,
      "z": 6,
      "name": "Wood_Birch_Branch_Corner",
      "rotation": 1
    },
    {
      "x": 8,
      "y": 10,
      "z": 6,
      "name": "Wood_Birch_Branch_Long"
    },
    {
      "x": 8,
      "y": 11,
      "z": 6,
      "name": "Wood_Birch_Branch_Long"
    },
    {
      "x": 8,
      "y": 12,
      "z": 6,
      "name": "Wood_Birch_Branch_Long"
    },
    {
      "x": 8,
      "y": 13,
      "z": 6,
      "name": "Plant_Leaves_Aspen"
    },
    {
      "x": 8,
      "y": 10,
      "z": 7,
      "name": "Plant_Leaves_Aspen"
    },
    {
      "x": 8,
      "y": 12,
      "z": 7,
      "name": "Plant_Leaves_Aspen"
    },
    {
      "x": 8,
      "y": 13,
      "z": 7,
      "name": "Plant_Leaves_Aspen"
    },
    {
      "x": 8,
      "y": 12,
      "z": 8,
      "name": "Plant_Leaves_Aspen"
    },
    {
      "x": 8,
      "y": 12,
      "z": 9,
      "name": "Plant_Leaves_Aspen"
    },
    {
      "x": 9,
      "y": 12,
      "z": -12,
      "name": "Plant_Leaves_Aspen"
    },
    {
      "x": 9,
      "y": 12,
      "z": -11,
      "name": "Plant_Leaves_Aspen"
    },
    {
      "x": 9,
      "y": 12,
      "z": -10,
      "name": "Plant_Leaves_Aspen"
    },
    {
      "x": 9,
      "y": 6,
      "z": -5,
      "name": "Wood_Birch_Trunk_Full",
      "rotation": 6
    },
    {
      "x": 9,
      "y": 7,
      "z": -5,
      "name": "Wood_Birch_Trunk_Full",
      "rotation": 4
    },
    {
      "x": 9,
      "y": 5,
      "z": -4,
      "name": "Wood_Birch_Trunk_Full",
      "rotation": 4
    },
    {
      "x": 9,
      "y": 6,
      "z": -4,
      "name": "Wood_Birch_Trunk",
      "rotation": 6
    },
    {
      "x": 9,
      "y": 7,
      "z": -4,
      "name": "Wood_Birch_Trunk_Full",
      "rotation": 4
    },
    {
      "x": 9,
      "y": 8,
      "z": -4,
      "name": "Wood_Birch_Trunk_Half",
      "rotation": 1
    },
    {
      "x": 9,
      "y": 6,
      "z": -3,
      "name": "Wood_Birch_Trunk",
      "rotation": 6
    },
    {
      "x": 9,
      "y": 7,
      "z": -3,
      "name": "Wood_Birch_Trunk",
      "rotation": 6
    },
    {
      "x": 9,
      "y": 8,
      "z": -3,
      "name": "Wood_Birch_Trunk_Half"
    },
    {
      "x": 9,
      "y": 5,
      "z": -2,
      "name": "Wood_Birch_Branch_Long",
      "rotation": 5
    },
    {
      "x": 9,
      "y": 6,
      "z": -2,
      "name": "Wood_Birch_Trunk_Full",
      "rotation": 4
    },
    {
      "x": 9,
      "y": 7,
      "z": -2,
      "name": "Wood_Birch_Trunk_Full",
      "rotation": 4
    },
    {
      "x": 9,
      "y": 12,
      "z": 2,
      "name": "Plant_Leaves_Aspen"
    },
    {
      "x": 9,
      "y": 12,
      "z": 3,
      "name": "Plant_Leaves_Aspen"
    },
    {
      "x": 9,
      "y": 12,
      "z": 4,
      "name": "Plant_Leaves_Aspen"
    },
    {
      "x": 9,
      "y": 11,
      "z": 5,
      "name": "Plant_Leaves_Aspen"
    },
    {
      "x": 9,
      "y": 12,
      "z": 5,
      "name": "Plant_Leaves_Aspen"
    },
    {
      "x": 9,
      "y": 13,
      "z": 5,
      "name": "Plant_Leaves_Aspen"
    },
    {
      "x": 9,
      "y": 11,
      "z": 6,
      "name": "Plant_Leaves_Aspen"
    },
    {
      "x": 9,
      "y": 12,
      "z": 6,
      "name": "Plant_Leaves_Aspen"
    },
    {
      "x": 9,
      "y": 13,
      "z": 6,
      "name": "Plant_Leaves_Aspen"
    },
    {
      "x": 9,
      "y": 12,
      "z": 7,
      "name": "Plant_Leaves_Aspen"
    },
    {
      "x": 9,
      "y": 13,
      "z": 7,
      "name": "Plant_Leaves_Aspen"
    },
    {
      "x": 9,
      "y": 12,
      "z": 8,
      "name": "Plant_Leaves_Aspen"
    },
    {
      "x": 9,
      "y": 12,
      "z": 9,
      "name": "Plant_Leaves_Aspen"
    },
    {
      "x": 10,
      "y": 12,
      "z": -13,
      "name": "Plant_Leaves_Aspen"
    },
    {
      "x": 10,
      "y": 12,
      "z": -12,
      "name": "Plant_Leaves_Aspen"
    },
    {
      "x": 10,
      "y": 12,
      "z": -11,
      "name": "Plant_Leaves_Aspen"
    },
    {
      "x": 10,
      "y": 12,
      "z": -10,
      "name": "Plant_Leaves_Aspen"
    },
    {
      "x": 10,
      "y": 12,
      "z": -9,
      "name": "Plant_Leaves_Aspen"
    },
    {
      "x": 10,
      "y": 7,
      "z": -7,
      "name": "Wood_Birch_Trunk_Full",
      "rotation": 6
    },
    {
      "x": 10,
      "y": 6,
      "z": -6,
      "name": "Wood_Birch_Trunk_Full",
      "rotation": 4
    },
    {
      "x": 10,
      "y": 7,
      "z": -6,
      "name": "Wood_Birch_Trunk_Full",
      "rotation": 6
    },
    {
      "x": 10,
      "y": 5,
      "z": -5,
      "name": "Wood_Birch_Trunk_Full",
      "rotation": 6
    },
    {
      "x": 10,
      "y": 6,
      "z": -5,
      "name": "Wood_Birch_Trunk_Full"
    },
    {
      "x": 10,
      "y": 7,
      "z": -5,
      "name": "Wood_Birch_Trunk",
      "rotation": 6
    },
    {
      "x": 10,
      "y": 8,
      "z": -5,
      "name": "Wood_Birch_Trunk_Full",
      "rotation": 6
    },
    {
      "x": 10,
      "y": 6,
      "z": -4,
      "name": "Wood_Birch_Trunk",
      "rotation": 6
    },
    {
      "x": 10,
      "y": 7,
      "z": -4,
      "name": "Wood_Birch_Trunk",
      "rotation": 1
    },
    {
      "x": 10,
      "y": 8,
      "z": -4,
      "name": "Wood_Birch_Trunk_Full",
      "rotation": 4
    },
    {
      "x": 10,
      "y": 6,
      "z": -3,
      "name": "Wood_Birch_Trunk_Full",
      "rotation": 4
    },
    {
      "x": 10,
      "y": 7,
      "z": -3,
      "name": "Wood_Birch_Trunk_Full",
      "rotation": 4
    },
    {
      "x": 10,
      "y": 5,
      "z": -2,
      "name": "Wood_Birch_Branch_Long",
      "rotation": 5
    },
    {
      "x": 10,
      "y": 6,
      "z": -2,
      "name": "Wood_Birch_Trunk_Half",
      "rotation": 5
    },
    {
      "x": 10,
      "y": 12,
      "z": 2,
      "name": "Plant_Leaves_Aspen"
    },
    {
      "x": 10,
      "y": 12,
      "z": 3,
      "name": "Plant_Leaves_Aspen"
    },
    {
      "x": 10,
      "y": 12,
      "z": 4,
      "name": "Plant_Leaves_Aspen"
    },
    {
      "x": 10,
      "y": 12,
      "z": 5,
      "name": "Plant_Leaves_Aspen"
    },
    {
      "x": 10,
      "y": 12,
      "z": 6,
      "name": "Plant_Leaves_Aspen"
    },
    {
      "x": 10,
      "y": 12,
      "z": 7,
      "name": "Plant_Leaves_Aspen"
    },
    {
      "x": 10,
      "y": 12,
      "z": 8,
      "name": "Plant_Leaves_Aspen"
    },
    {
      "x": 11,
      "y": 12,
      "z": -14,
      "name": "Plant_Leaves_Aspen"
    },
    {
      "x": 11,
      "y": 12,
      "z": -13,
      "name": "Plant_Leaves_Aspen"
    },
    {
      "x": 11,
      "y": 12,
      "z": -12,
      "name": "Plant_Leaves_Aspen"
    },
    {
      "x": 11,
      "y": 12,
      "z": -11,
      "name": "Plant_Leaves_Aspen"
    },
    {
      "x": 11,
      "y": 13,
      "z": -11,
      "name": "Plant_Leaves_Aspen"
    },
    {
      "x": 11,
      "y": 12,
      "z": -10,
      "name": "Plant_Leaves_Aspen"
    },
    {
      "x": 11,
      "y": 12,
      "z": -9,
      "name": "Plant_Leaves_Aspen"
    },
    {
      "x": 11,
      "y": 7,
      "z": -8,
      "name": "Wood_Birch_Trunk_Full",
      "rotation": 4
    },
    {
      "x": 11,
      "y": 12,
      "z": -8,
      "name": "Plant_Leaves_Aspen"
    },
    {
      "x": 11,
      "y": 6,
      "z": -7,
      "name": "Wood_Birch_Trunk_Full",
      "rotation": 4
    },
    {
      "x": 11,
      "y": 7,
      "z": -7,
      "name": "Wood_Birch_Trunk",
      "rotation": 6
    },
    {
      "x": 11,
      "y": 8,
      "z": -7,
      "name": "Wood_Birch_Trunk_Half",
      "rotation": 1
    },
    {
      "x": 11,
      "y": 5,
      "z": -6,
      "name": "Wood_Birch_Trunk_Half",
      "rotation": 35
    },
    {
      "x": 11,
      "y": 6,
      "z": -6,
      "name": "Wood_Birch_Trunk",
      "rotation": 6
    },
    {
      "x": 11,
      "y": 7,
      "z": -6,
      "name": "Wood_Birch_Trunk",
      "rotation": 6
    },
    {
      "x": 11,
      "y": 8,
      "z": -6,
      "name": "Wood_Birch_Trunk_Full",
      "rotation": 4
    },
    {
      "x": 11,
      "y": 6,
      "z": -5,
      "name": "Wood_Birch_Trunk_Full",
      "rotation": 6
    },
    {
      "x": 11,
      "y": 7,
      "z": -5,
      "name": "Wood_Birch_Trunk",
      "rotation": 6
    },
    {
      "x": 11,
      "y": 8,
      "z": -5,
      "name": "Wood_Birch_Trunk_Full",
      "rotation": 4
    },
    {
      "x": 11,
      "y": 6,
      "z": -4,
      "name": "Wood_Birch_Trunk_Full",
      "rotation": 4
    },
    {
      "x": 11,
      "y": 7,
      "z": -4,
      "name": "Wood_Birch_Trunk_Full",
      "rotation": 4
    },
    {
      "x": 11,
      "y": 6,
      "z": -3,
      "name": "Wood_Birch_Trunk_Half",
      "rotation": 5
    },
    {
      "x": 11,
      "y": 10,
      "z": -3,
      "name": "Plant_Leaves_Aspen"
    },
    {
      "x": 11,
      "y": 5,
      "z": -2,
      "name": "Wood_Birch_Branch_Long",
      "rotation": 5
    },
    {
      "x": 11,
      "y": 10,
      "z": -2,
      "name": "Plant_Leaves_Aspen"
    },
    {
      "x": 11,
      "y": 9,
      "z": -1,
      "name": "Plant_Leaves_Aspen"
    },
    {
      "x": 11,
      "y": 10,
      "z": -1,
      "name": "Plant_Leaves_Aspen"
    },
    {
      "x": 11,
      "y": 9,
      "z": 0,
      "name": "Plant_Leaves_Aspen"
    },
    {
      "x": 11,
      "y": 9,
      "z": 1,
      "name": "Plant_Leaves_Aspen"
    },
    {
      "x": 11,
      "y": 12,
      "z": 3,
      "name": "Plant_Leaves_Aspen"
    },
    {
      "x": 11,
      "y": 12,
      "z": 4,
      "name": "Plant_Leaves_Aspen"
    },
    {
      "x": 11,
      "y": 12,
      "z": 5,
      "name": "Plant_Leaves_Aspen"
    },
    {
      "x": 11,
      "y": 12,
      "z": 6,
      "name": "Plant_Leaves_Aspen"
    },
    {
      "x": 11,
      "y": 12,
      "z": 7,
      "name": "Plant_Leaves_Aspen"
    },
    {
      "x": 12,
      "y": 12,
      "z": -14,
      "name": "Plant_Leaves_Aspen"
    },
    {
      "x": 12,
      "y": 12,
      "z": -13,
      "name": "Plant_Leaves_Aspen"
    },
    {
      "x": 12,
      "y": 12,
      "z": -12,
      "name": "Plant_Leaves_Aspen"
    },
    {
      "x": 12,
      "y": 13,
      "z": -12,
      "name": "Plant_Leaves_Aspen"
    },
    {
      "x": 12,
      "y": 8,
      "z": -11,
      "name": "Wood_Birch_Branch_Corner",
      "rotation": 2
    },
    {
      "x": 12,
      "y": 9,
      "z": -11,
      "name": "Wood_Birch_Branch_Long"
    },
    {
      "x": 12,
      "y": 10,
      "z": -11,
      "name": "Wood_Birch_Branch_Long"
    },
    {
      "x": 12,
      "y": 11,
      "z": -11,
      "name": "Wood_Birch_Branch_Long"
    },
    {
      "x": 12,
      "y": 12,
      "z": -11,
      "name": "Wood_Birch_Branch_Long"
    },
    {
      "x": 12,
      "y": 13,
      "z": -11,
      "name": "Plant_Leaves_Aspen"
    },
    {
      "x": 12,
      "y": 8,
      "z": -10,
      "name": "Wood_Birch_Branch_Long",
      "rotation": 4
    },
    {
      "x": 12,
      "y": 12,
      "z": -10,
      "name": "Plant_Leaves_Aspen"
    },
    {
      "x": 12,
      "y": 13,
      "z": -10,
      "name": "Plant_Leaves_Aspen"
    },
    {
      "x": 12,
      "y": 7,
      "z": -9,
      "name": "Wood_Birch_Trunk_Full",
      "rotation": 4
    },
    {
      "x": 12,
      "y": 8,
      "z": -9,
      "name": "Wood_Birch_Trunk_Full",
      "rotation": 4
    },
    {
      "x": 12,
      "y": 12,
      "z": -9,
      "name": "Plant_Leaves_Aspen"
    },
    {
      "x": 12,
      "y": 6,
      "z": -8,
      "name": "Wood_Birch_Trunk_Full",
      "rotation": 4
    },
    {
      "x": 12,
      "y": 7,
      "z": -8,
      "name": "Wood_Birch_Trunk",
      "rotation": 6
    },
    {
      "x": 12,
      "y": 8,
      "z": -8,
      "name": "Wood_Birch_Trunk",
      "rotation": 6
    },
    {
      "x": 12,
      "y": 12,
      "z": -8,
      "name": "Plant_Leaves_Aspen"
    },
    {
      "x": 12,
      "y": 6,
      "z": -7,
      "name": "Wood_Birch_Trunk_Full",
      "rotation": 4
    },
    {
      "x": 12,
      "y": 7,
      "z": -7,
      "name": "Wood_Birch_Trunk",
      "rotation": 6
    },
    {
      "x": 12,
      "y": 8,
      "z": -7,
      "name": "Wood_Birch_Trunk",
      "rotation": 6
    },
    {
      "x": 12,
      "y": 6,
      "z": -6,
      "name": "Wood_Birch_Trunk_Full",
      "rotation": 4
    },
    {
      "x": 12,
      "y": 7,
      "z": -6,
      "name": "Wood_Birch_Trunk",
      "rotation": 6
    },
    {
      "x": 12,
      "y": 8,
      "z": -6,
      "name": "Wood_Birch_Trunk_Full",
      "rotation": 4
    },
    {
      "x": 12,
      "y": 6,
      "z": -5,
      "name": "Wood_Birch_Trunk_Full",
      "rotation": 6
    },
    {
      "x": 12,
      "y": 7,
      "z": -5,
      "name": "Wood_Birch_Trunk_Full",
      "rotation": 4
    },
    {
      "x": 12,
      "y": 10,
      "z": -4,
      "name": "Plant_Leaves_Aspen"
    },
    {
      "x": 12,
      "y": 10,
      "z": -3,
      "name": "Plant_Leaves_Aspen"
    },
    {
      "x": 12,
      "y": 5,
      "z": -2,
      "name": "Wood_Birch_Branch_Long",
      "rotation": 5
    },
    {
      "x": 12,
      "y": 9,
      "z": -2,
      "name": "Plant_Leaves_Aspen"
    },
    {
      "x": 12,
      "y": 10,
      "z": -2,
      "name": "Plant_Leaves_Aspen"
    },
    {
      "x": 12,
      "y": 9,
      "z": -1,
      "name": "Plant_Leaves_Aspen"
    },
    {
      "x": 12,
      "y": 10,
      "z": -1,
      "name": "Plant_Leaves_Aspen"
    },
    {
      "x": 12,
      "y": 9,
      "z": 0,
      "name": "Plant_Leaves_Aspen"
    },
    {
      "x": 12,
      "y": 10,
      "z": 0,
      "name": "Plant_Leaves_Aspen"
    },
    {
      "x": 12,
      "y": 9,
      "z": 1,
      "name": "Plant_Leaves_Aspen"
    },
    {
      "x": 12,
      "y": 9,
      "z": 2,
      "name": "Plant_Leaves_Aspen"
    },
    {
      "x": 13,
      "y": 12,
      "z": -14,
      "name": "Plant_Leaves_Aspen"
    },
    {
      "x": 13,
      "y": 12,
      "z": -13,
      "name": "Plant_Leaves_Aspen"
    },
    {
      "x": 13,
      "y": 12,
      "z": -12,
      "name": "Plant_Leaves_Aspen"
    },
    {
      "x": 13,
      "y": 8,
      "z": -11,
      "name": "Wood_Birch_Trunk_Half",
      "rotation": 7
    },
    {
      "x": 13,
      "y": 12,
      "z": -11,
      "name": "Plant_Leaves_Aspen"
    },
    {
      "x": 13,
      "y": 13,
      "z": -11,
      "name": "Plant_Leaves_Aspen"
    },
    {
      "x": 13,
      "y": 7,
      "z": -10,
      "name": "Wood_Birch_Trunk_Full",
      "rotation": 6
    },
    {
      "x": 13,
      "y": 8,
      "z": -10,
      "name": "Wood_Birch_Trunk_Full",
      "rotation": 4
    },
    {
      "x": 13,
      "y": 12,
      "z": -10,
      "name": "Plant_Leaves_Aspen"
    },
    {
      "x": 13,
      "y": 7,
      "z": -9,
      "name": "Wood_Birch_Trunk",
      "rotation": 6
    },
    {
      "x": 13,
      "y": 8,
      "z": -9,
      "name": "Wood_Birch_Trunk",
      "rotation": 6
    },
    {
      "x": 13,
      "y": 9,
      "z": -9,
      "name": "Wood_Birch_Trunk_Half"
    },
    {
      "x": 13,
      "y": 12,
      "z": -9,
      "name": "Plant_Leaves_Aspen"
    },
    {
      "x": 13,
      "y": 6,
      "z": -8,
      "name": "Wood_Birch_Trunk_Full",
      "rotation": 6
    },
    {
      "x": 13,
      "y": 7,
      "z": -8,
      "name": "Wood_Birch_Trunk",
      "rotation": 6
    },
    {
      "x": 13,
      "y": 8,
      "z": -8,
      "name": "Wood_Birch_Trunk",
      "rotation": 6
    },
    {
      "x": 13,
      "y": 9,
      "z": -8,
      "name": "Wood_Birch_Trunk_Half",
      "rotation": 1
    },
    {
      "x": 13,
      "y": 12,
      "z": -8,
      "name": "Plant_Leaves_Aspen"
    },
    {
      "x": 13,
      "y": 7,
      "z": -7,
      "name": "Wood_Birch_Trunk_Full",
      "rotation": 6
    },
    {
      "x": 13,
      "y": 8,
      "z": -7,
      "name": "Wood_Birch_Trunk_Full",
      "rotation": 4
    },
    {
      "x": 13,
      "y": 7,
      "z": -6,
      "name": "Wood_Birch_Trunk_Full",
      "rotation": 4
    },
    {
      "x": 13,
      "y": 10,
      "z": -5,
      "name": "Plant_Leaves_Aspen"
    },
    {
      "x": 13,
      "y": 10,
      "z": -4,
      "name": "Plant_Leaves_Aspen"
    },
    {
      "x": 13,
      "y": 7,
      "z": -3,
      "name": "Plant_Leaves_Aspen"
    },
    {
      "x": 13,
      "y": 9,
      "z": -3,
      "name": "Plant_Leaves_Aspen"
    },
    {
      "x": 13,
      "y": 10,
      "z": -3,
      "name": "Plant_Leaves_Aspen"
    },
    {
      "x": 13,
      "y": 5,
      "z": -2,
      "name": "Wood_Birch_Branch_Corner",
      "rotation": 1
    },
    {
      "x": 13,
      "y": 6,
      "z": -2,
      "name": "Wood_Birch_Branch_Corner",
      "rotation": 35
    },
    {
      "x": 13,
      "y": 7,
      "z": -2,
      "name": "Plant_Leaves_Aspen"
    },
    {
      "x": 13,
      "y": 9,
      "z": -2,
      "name": "Plant_Leaves_Aspen"
    },
    {
      "x": 13,
      "y": 10,
      "z": -2,
      "name": "Plant_Leaves_Aspen"
    },
    {
      "x": 13,
      "y": 11,
      "z": -2,
      "name": "Plant_Leaves_Aspen"
    },
    {
      "x": 13,
      "y": 7,
      "z": -1,
      "name": "Plant_Leaves_Aspen"
    },
    {
      "x": 13,
      "y": 9,
      "z": -1,
      "name": "Plant_Leaves_Aspen"
    },
    {
      "x": 13,
      "y": 10,
      "z": -1,
      "name": "Plant_Leaves_Aspen"
    },
    {
      "x": 13,
      "y": 9,
      "z": 0,
      "name": "Plant_Leaves_Aspen"
    },
    {
      "x": 13,
      "y": 10,
      "z": 0,
      "name": "Plant_Leaves_Aspen"
    },
    {
      "x": 13,
      "y": 9,
      "z": 1,
      "name": "Plant_Leaves_Aspen"
    },
    {
      "x": 13,
      "y": 10,
      "z": 1,
      "name": "Plant_Leaves_Aspen"
    },
    {
      "x": 13,
      "y": 9,
      "z": 2,
      "name": "Plant_Leaves_Aspen"
    },
    {
      "x": 13,
      "y": 9,
      "z": 3,
      "name": "Plant_Leaves_Aspen"
    },
    {
      "x": 14,
      "y": 12,
      "z": -13,
      "name": "Plant_Leaves_Aspen"
    },
    {
      "x": 14,
      "y": 12,
      "z": -12,
      "name": "Plant_Leaves_Aspen"
    },
    {
      "x": 14,
      "y": 8,
      "z": -11,
      "name": "Wood_Birch_Trunk_Full",
      "rotation": 6
    },
    {
      "x": 14,
      "y": 9,
      "z": -11,
      "name": "Wood_Birch_Trunk_Full",
      "rotation": 4
    },
    {
      "x": 14,
      "y": 12,
      "z": -11,
      "name": "Plant_Leaves_Aspen"
    },
    {
      "x": 14,
      "y": 8,
      "z": -10,
      "name": "Wood_Birch_Trunk",
      "rotation": 6
    },
    {
      "x": 14,
      "y": 9,
      "z": -10,
      "name": "Wood_Birch_Trunk_Full",
      "rotation": 6
    },
    {
      "x": 14,
      "y": 12,
      "z": -10,
      "name": "Plant_Leaves_Aspen"
    },
    {
      "x": 14,
      "y": 7,
      "z": -9,
      "name": "Wood_Birch_Trunk_Full",
      "rotation": 4
    },
    {
      "x": 14,
      "y": 8,
      "z": -9,
      "name": "Wood_Birch_Trunk",
      "rotation": 6
    },
    {
      "x": 14,
      "y": 9,
      "z": -9,
      "name": "Wood_Birch_Trunk",
      "rotation": 6
    },
    {
      "x": 14,
      "y": 12,
      "z": -9,
      "name": "Plant_Leaves_Aspen"
    },
    {
      "x": 14,
      "y": 7,
      "z": -8,
      "name": "Wood_Birch_Trunk_Full",
      "rotation": 4
    },
    {
      "x": 14,
      "y": 8,
      "z": -8,
      "name": "Wood_Birch_Trunk",
      "rotation": 6
    },
    {
      "x": 14,
      "y": 9,
      "z": -8,
      "name": "Wood_Birch_Trunk_Full",
      "rotation": 4
    },
    {
      "x": 14,
      "y": 7,
      "z": -7,
      "name": "Wood_Birch_Trunk_Full",
      "rotation": 6
    },
    {
      "x": 14,
      "y": 8,
      "z": -7,
      "name": "Wood_Birch_Trunk_Full",
      "rotation": 4
    },
    {
      "x": 14,
      "y": 10,
      "z": -5,
      "name": "Plant_Leaves_Aspen"
    },
    {
      "x": 14,
      "y": 10,
      "z": -4,
      "name": "Plant_Leaves_Aspen"
    },
    {
      "x": 14,
      "y": 7,
      "z": -3,
      "name": "Plant_Leaves_Aspen"
    },
    {
      "x": 14,
      "y": 9,
      "z": -3,
      "name": "Plant_Leaves_Aspen"
    },
    {
      "x": 14,
      "y": 10,
      "z": -3,
      "name": "Plant_Leaves_Aspen"
    },
    {
      "x": 14,
      "y": 11,
      "z": -3,
      "name": "Plant_Leaves_Aspen"
    },
    {
      "x": 14,
      "y": 6,
      "z": -2,
      "name": "Wood_Birch_Branch_Corner",
      "rotation": 1
    },
    {
      "x": 14,
      "y": 7,
      "z": -2,
      "name": "Wood_Birch_Branch_Long",
      "rotation": 1
    },
    {
      "x": 14,
      "y": 8,
      "z": -2,
      "name": "Wood_Birch_Branch_Long"
    },
    {
      "x": 14,
      "y": 9,
      "z": -2,
      "name": "Wood_Birch_Branch_Long"
    },
    {
      "x": 14,
      "y": 10,
      "z": -2,
      "name": "Wood_Birch_Branch_Long"
    },
    {
      "x": 14,
      "y": 11,
      "z": -2,
      "name": "Plant_Leaves_Aspen"
    },
    {
      "x": 14,
      "y": 7,
      "z": -1,
      "name": "Wood_Birch_Branch_Long",
      "rotation": 4
    },
    {
      "x": 14,
      "y": 8,
      "z": -1,
      "name": "Plant_Leaves_Aspen"
    },
    {
      "x": 14,
      "y": 9,
      "z": -1,
      "name": "Plant_Leaves_Aspen"
    },
    {
      "x": 14,
      "y": 10,
      "z": -1,
      "name": "Plant_Leaves_Aspen"
    },
    {
      "x": 14,
      "y": 11,
      "z": -1,
      "name": "Plant_Leaves_Aspen"
    },
    {
      "x": 14,
      "y": 7,
      "z": 0,
      "name": "Wood_Birch_Branch_Corner"
    },
    {
      "x": 14,
      "y": 8,
      "z": 0,
      "name": "Wood_Birch_Branch_Long"
    },
    {
      "x": 14,
      "y": 9,
      "z": 0,
      "name": "Wood_Birch_Branch_Long"
    },
    {
      "x": 14,
      "y": 10,
      "z": 0,
      "name": "Plant_Leaves_Aspen"
    },
    {
      "x": 14,
      "y": 9,
      "z": 1,
      "name": "Plant_Leaves_Aspen"
    },
    {
      "x": 14,
      "y": 10,
      "z": 1,
      "name": "Plant_Leaves_Aspen"
    },
    {
      "x": 14,
      "y": 9,
      "z": 2,
      "name": "Plant_Leaves_Aspen"
    },
    {
      "x": 14,
      "y": 9,
      "z": 3,
      "name": "Plant_Leaves_Aspen"
    },
    {
      "x": 15,
      "y": 9,
      "z": -12,
      "name": "Wood_Birch_Trunk_Full",
      "rotation": 6
    },
    {
      "x": 15,
      "y": 12,
      "z": -12,
      "name": "Plant_Leaves_Aspen"
    },
    {
      "x": 15,
      "y": 9,
      "z": -11,
      "name": "Wood_Birch_Trunk",
      "rotation": 6
    },
    {
      "x": 15,
      "y": 12,
      "z": -11,
      "name": "Plant_Leaves_Aspen"
    },
    {
      "x": 15,
      "y": 8,
      "z": -10,
      "name": "Wood_Birch_Trunk_Full",
      "rotation": 4
    },
    {
      "x": 15,
      "y": 9,
      "z": -10,
      "name": "Wood_Birch_Trunk_Full",
      "rotation": 4
    },
    {
      "x": 15,
      "y": 10,
      "z": -10,
      "name": "Wood_Birch_Trunk_Half"
    },
    {
      "x": 15,
      "y": 12,
      "z": -10,
      "name": "Plant_Leaves_Aspen"
    },
    {
      "x": 15,
      "y": 8,
      "z": -9,
      "name": "Wood_Birch_Trunk",
      "rotation": 6
    },
    {
      "x": 15,
      "y": 9,
      "z": -9,
      "name": "Wood_Birch_Trunk_Full",
      "rotation": 4
    },
    {
      "x": 15,
      "y": 10,
      "z": -9,
      "name": "Wood_Birch_Trunk_Half"
    },
    {
      "x": 15,
      "y": 8,
      "z": -8,
      "name": "Wood_Birch_Trunk_Full",
      "rotation": 4
    },
    {
      "x": 15,
      "y": 9,
      "z": -8,
      "name": "Wood_Birch_Trunk_Full",
      "rotation": 4
    },
    {
      "x": 15,
      "y": 10,
      "z": -5,
      "name": "Plant_Leaves_Aspen"
    },
    {
      "x": 15,
      "y": 10,
      "z": -4,
      "name": "Plant_Leaves_Aspen"
    },
    {
      "x": 15,
      "y": 9,
      "z": -3,
      "name": "Plant_Leaves_Aspen"
    },
    {
      "x": 15,
      "y": 10,
      "z": -3,
      "name": "Plant_Leaves_Aspen"
    },
    {
      "x": 15,
      "y": 7,
      "z": -2,
      "name": "Plant_Leaves_Aspen"
    },
    {
      "x": 15,
      "y": 9,
      "z": -2,
      "name": "Plant_Leaves_Aspen"
    },
    {
      "x": 15,
      "y": 10,
      "z": -2,
      "name": "Plant_Leaves_Aspen"
    },
    {
      "x": 15,
      "y": 11,
      "z": -2,
      "name": "Plant_Leaves_Aspen"
    },
    {
      "x": 15,
      "y": 7,
      "z": -1,
      "name": "Plant_Leaves_Aspen"
    },
    {
      "x": 15,
      "y": 9,
      "z": -1,
      "name": "Plant_Leaves_Aspen"
    },
    {
      "x": 15,
      "y": 10,
      "z": -1,
      "name": "Plant_Leaves_Aspen"
    },
    {
      "x": 15,
      "y": 9,
      "z": 0,
      "name": "Plant_Leaves_Aspen"
    },
    {
      "x": 15,
      "y": 10,
      "z": 0,
      "name": "Plant_Leaves_Aspen"
    },
    {
      "x": 15,
      "y": 9,
      "z": 1,
      "name": "Plant_Leaves_Aspen"
    },
    {
      "x": 15,
      "y": 10,
      "z": 1,
      "name": "Plant_Leaves_Aspen"
    },
    {
      "x": 15,
      "y": 9,
      "z": 2,
      "name": "Plant_Leaves_Aspen"
    },
    {
      "x": 15,
      "y": 9,
      "z": 3,
      "name": "Plant_Leaves_Aspen"
    },
    {
      "x": 16,
      "y": 10,
      "z": -13,
      "name": "Wood_Birch_Trunk_Full",
      "rotation": 6
    },
    {
      "x": 16,
      "y": 9,
      "z": -12,
      "name": "Wood_Birch_Trunk_Full",
      "rotation": 6
    },
    {
      "x": 16,
      "y": 10,
      "z": -12,
      "name": "Wood_Birch_Trunk_Full",
      "rotation": 4
    },
    {
      "x": 16,
      "y": 9,
      "z": -11,
      "name": "Wood_Birch_Trunk",
      "rotation": 6
    },
    {
      "x": 16,
      "y": 10,
      "z": -11,
      "name": "Wood_Birch_Trunk",
      "rotation": 6
    },
    {
      "x": 16,
      "y": 9,
      "z": -10,
      "name": "Wood_Birch_Trunk",
      "rotation": 6
    },
    {
      "x": 16,
      "y": 10,
      "z": -10,
      "name": "Wood_Birch_Trunk_Full",
      "rotation": 6
    },
    {
      "x": 16,
      "y": 8,
      "z": -9,
      "name": "Wood_Birch_Trunk_Full",
      "rotation": 6
    },
    {
      "x": 16,
      "y": 9,
      "z": -9,
      "name": "Wood_Birch_Trunk_Full",
      "rotation": 6
    },
    {
      "x": 16,
      "y": 10,
      "z": -9,
      "name": "Wood_Birch_Branch_Short"
    },
    {
      "x": 16,
      "y": 10,
      "z": -4,
      "name": "Plant_Leaves_Aspen"
    },
    {
      "x": 16,
      "y": 10,
      "z": -3,
      "name": "Plant_Leaves_Aspen"
    },
    {
      "x": 16,
      "y": 9,
      "z": -2,
      "name": "Plant_Leaves_Aspen"
    },
    {
      "x": 16,
      "y": 10,
      "z": -2,
      "name": "Plant_Leaves_Aspen"
    },
    {
      "x": 16,
      "y": 9,
      "z": -1,
      "name": "Plant_Leaves_Aspen"
    },
    {
      "x": 16,
      "y": 10,
      "z": -1,
      "name": "Plant_Leaves_Aspen"
    },
    {
      "x": 16,
      "y": 9,
      "z": 0,
      "name": "Plant_Leaves_Aspen"
    },
    {
      "x": 16,
      "y": 10,
      "z": 0,
      "name": "Plant_Leaves_Aspen"
    },
    {
      "x": 16,
      "y": 9,
      "z": 1,
      "name": "Plant_Leaves_Aspen"
    },
    {
      "x": 16,
      "y": 9,
      "z": 2,
      "name": "Plant_Leaves_Aspen"
    },
    {
      "x": 17,
      "y": 10,
      "z": -14,
      "name": "Wood_Birch_Trunk_Full",
      "rotation": 4
    },
    {
      "x": 17,
      "y": 10,
      "z": -13,
      "name": "Wood_Birch_Trunk",
      "rotation": 6
    },
    {
      "x": 17,
      "y": 11,
      "z": -13,
      "name": "Wood_Birch_Trunk_Half"
    },
    {
      "x": 17,
      "y": 9,
      "z": -12,
      "name": "Wood_Birch_Trunk_Full",
      "rotation": 4
    },
    {
      "x": 17,
      "y": 10,
      "z": -12,
      "name": "Wood_Birch_Trunk",
      "rotation": 6
    },
    {
      "x": 17,
      "y": 11,
      "z": -12,
      "name": "Wood_Birch_Trunk_Half"
    },
    {
      "x": 17,
      "y": 9,
      "z": -11,
      "name": "Wood_Birch_Trunk",
      "rotation": 6
    },
    {
      "x": 17,
      "y": 10,
      "z": -11,
      "name": "Wood_Birch_Trunk",
      "rotation": 6
    },
    {
      "x": 17,
      "y": 11,
      "z": -11,
      "name": "Wood_Birch_Trunk_Half"
    },
    {
      "x": 17,
      "y": 9,
      "z": -10,
      "name": "Wood_Birch_Trunk_Full",
      "rotation": 4
    },
    {
      "x": 17,
      "y": 10,
      "z": -10,
      "name": "Wood_Birch_Trunk_Full",
      "rotation": 4
    },
    {
      "x": 17,
      "y": 10,
      "z": -3,
      "name": "Plant_Leaves_Aspen"
    },
    {
      "x": 17,
      "y": 10,
      "z": -2,
      "name": "Plant_Leaves_Aspen"
    },
    {
      "x": 17,
      "y": 9,
      "z": -1,
      "name": "Plant_Leaves_Aspen"
    },
    {
      "x": 17,
      "y": 10,
      "z": -1,
      "name": "Plant_Leaves_Aspen"
    },
    {
      "x": 17,
      "y": 9,
      "z": 0,
      "name": "Plant_Leaves_Aspen"
    },
    {
      "x": 17,
      "y": 9,
      "z": 1,
      "name": "Plant_Leaves_Aspen"
    },
    {
      "x": 18,
      "y": 4,
      "z": -15,
      "name": "Wood_Birch_Branch_Corner",
      "rotation": 3
    },
    {
      "x": 18,
      "y": 10,
      "z": -15,
      "name": "Wood_Birch_Trunk_Full",
      "rotation": 6
    },
    {
      "x": 18,
      "y": 10,
      "z": -14,
      "name": "Wood_Birch_Trunk",
      "rotation": 6
    },
    {
      "x": 18,
      "y": 11,
      "z": -14,
      "name": "Wood_Birch_Trunk_Full",
      "rotation": 4
    },
    {
      "x": 18,
      "y": 9,
      "z": -13,
      "name": "Wood_Birch_Trunk_Full",
      "rotation": 4
    },
    {
      "x": 18,
      "y": 10,
      "z": -13,
      "name": "Wood_Birch_Trunk",
      "rotation": 6
    },
    {
      "x": 18,
      "y": 11,
      "z": -13,
      "name": "Wood_Birch_Trunk_Full",
      "rotation": 4
    },
    {
      "x": 18,
      "y": 9,
      "z": -12,
      "name": "Wood_Birch_Trunk",
      "rotation": 6
    },
    {
      "x": 18,
      "y": 10,
      "z": -12,
      "name": "Wood_Birch_Trunk",
      "rotation": 6
    },
    {
      "x": 18,
      "y": 9,
      "z": -11,
      "name": "Wood_Birch_Trunk_Full",
      "rotation": 4
    },
    {
      "x": 18,
      "y": 10,
      "z": -11,
      "name": "Wood_Birch_Trunk_Full",
      "rotation": 4
    },
    {
      "x": 19,
      "y": 7,
      "z": -18,
      "name": "Wood_Birch_Branch_Corner",
      "rotation": 3
    },
    {
      "x": 19,
      "y": 1,
      "z": -17,
      "name": "Wood_Birch_Branch_Corner",
      "rotation": 2
    },
    {
      "x": 19,
      "y": 2,
      "z": -17,
      "name": "Wood_Birch_Branch_Corner",
      "rotation": 35
    },
    {
      "x": 19,
      "y": 6,
      "z": -17,
      "name": "Wood_Birch_Branch_Corner",
      "rotation": 2
    },
    {
      "x": 19,
      "y": 7,
      "z": -17,
      "name": "Wood_Birch_Branch_Corner",
      "rotation": 9
    },
    {
      "x": 19,
      "y": 1,
      "z": -16,
      "name": "Wood_Birch_Branch_Corner"
    },
    {
      "x": 19,
      "y": 2,
      "z": -16,
      "name": "Wood_Birch_Branch_Corner",
      "rotation": 9
    },
    {
      "x": 19,
      "y": 6,
      "z": -16,
      "name": "Wood_Birch_Branch_Long",
      "rotation": 6
    },
    {
      "x": 19,
      "y": 4,
      "z": -15,
      "name": "Wood_Birch_Branch_Corner",
      "rotation": 1
    },
    {
      "x": 19,
      "y": 5,
      "z": -15,
      "name": "Wood_Birch_Branch_Corner",
      "rotation": 34
    },
    {
      "x": 19,
      "y": 6,
      "z": -15,
      "name": "Wood_Birch_Branch_Long",
      "rotation": 6
    },
    {
      "x": 19,
      "y": 10,
      "z": -15,
      "name": "Wood_Birch_Trunk_Full",
      "rotation": 5
    },
    {
      "x": 19,
      "y": 5,
      "z": -14,
      "name": "Wood_Birch_Branch_Corner"
    },
    {
      "x": 19,
      "y": 6,
      "z": -14,
      "name": "Wood_Birch_Branch_Corner",
      "rotation": 10
    },
    {
      "x": 19,
      "y": 10,
      "z": -14,
      "name": "Wood_Birch_Trunk",
      "rotation": 6
    },
    {
      "x": 19,
      "y": 9,
      "z": -13,
      "name": "Wood_Birch_Trunk_Full"
    },
    {
      "x": 19,
      "y": 10,
      "z": -13,
      "name": "Wood_Birch_Trunk",
      "rotation": 6
    },
    {
      "x": 19,
      "y": 9,
      "z": -12,
      "name": "Wood_Birch_Trunk_Full",
      "rotation": 4
    },
    {
      "x": 19,
      "y": 10,
      "z": -12,
      "name": "Wood_Birch_Trunk_Full",
      "rotation": 4
    },
    {
      "x": 20,
      "y": 7,
      "z": -18,
      "name": "Wood_Birch_Branch_Corner",
      "rotation": 1
    },
    {
      "x": 20,
      "y": 8,
      "z": -18,
      "name": "Wood_Birch_Branch_Corner",
      "rotation": 8
    },
    {
      "x": 20,
      "y": 3,
      "z": -17,
      "name": "Wood_Birch_Branch_Corner",
      "rotation": 2
    },
    {
      "x": 20,
      "y": 4,
      "z": -17,
      "name": "Wood_Birch_Branch_Long",
      "rotation": 1
    },
    {
      "x": 20,
      "y": 5,
      "z": -17,
      "name": "Wood_Birch_Branch_Long",
      "rotation": 1
    },
    {
      "x": 20,
      "y": 6,
      "z": -17,
      "name": "Wood_Birch_Trunk_Full",
      "rotation": 1
    },
    {
      "x": 20,
      "y": 7,
      "z": -17,
      "name": "Wood_Birch_Trunk",
      "rotation": 1
    },
    {
      "x": 20,
      "y": 8,
      "z": -17,
      "name": "Wood_Birch_Trunk_Full",
      "rotation": 1
    },
    {
      "x": 20,
      "y": 9,
      "z": -17,
      "name": "Wood_Birch_Trunk_Full",
      "rotation": 1
    },
    {
      "x": 20,
      "y": 10,
      "z": -17,
      "name": "Wood_Birch_Trunk_Full",
      "rotation": 4
    },
    {
      "x": 20,
      "y": 2,
      "z": -16,
      "name": "Wood_Birch_Branch_Corner",
      "rotation": 1
    },
    {
      "x": 20,
      "y": 3,
      "z": -16,
      "name": "Wood_Birch_Branch_Corner",
      "rotation": 10
    },
    {
      "x": 20,
      "y": 10,
      "z": -16,
      "name": "Wood_Birch_Trunk_Full",
      "rotation": 4
    },
    {
      "x": 20,
      "y": 10,
      "z": -15,
      "name": "Wood_Birch_Trunk_Full",
      "rotation": 5
    },
    {
      "x": 20,
      "y": 9,
      "z": -13,
      "name": "Wood_Birch_Trunk_Full",
      "rotation": 6
    },
    {
      "x": 20,
      "y": 10,
      "z": -13,
      "name": "Wood_Birch_Trunk_Full",
      "rotation": 6
    },
    {
      "x": 21,
      "y": 10,
      "z": -15,
      "name": "Wood_Birch_Trunk_Full",
      "rotation": 5
    },
    {
      "x": 21,
      "y": 7,
      "z": -13,
      "name": "Wood_Birch_Trunk_Full"
    },
    {
      "x": 21,
      "y": 8,
      "z": -13,
      "name": "Wood_Birch_Trunk_Full"
    },
    {
      "x": 21,
      "y": 9,
      "z": -13,
      "name": "Wood_Birch_Trunk_Full"
    },
    {
      "x": 21,
      "y": 3,
      "z": -12,
      "name": "Wood_Birch_Trunk_Full",
      "rotation": 1
    },
    {
      "x": 21,
      "y": 4,
      "z": -12,
      "name": "Wood_Birch_Trunk",
      "rotation": 1
    },
    {
      "x": 21,
      "y": 5,
      "z": -12,
      "name": "Wood_Birch_Trunk_Full"
    },
    {
      "x": 22,
      "y": 2,
      "z": -17,
      "name": "Wood_Birch_Branch_Corner",
      "rotation": 3
    },
    {
      "x": 22,
      "y": 3,
      "z": -17,
      "name": "Wood_Birch_Branch_Long"
    },
    {
      "x": 22,
      "y": 4,
      "z": -17,
      "name": "Wood_Birch_Branch_Long"
    },
    {
      "x": 22,
      "y": 5,
      "z": -17,
      "name": "Wood_Birch_Branch_Corner",
      "rotation": 9
    },
    {
      "x": 22,
      "y": 9,
      "z": -16,
      "name": "Wood_Birch_Trunk_Full",
      "rotation": 4
    },
    {
      "x": 22,
      "y": 9,
      "z": -15,
      "name": "Wood_Birch_Trunk_Full",
      "rotation": 4
    },
    {
      "x": 22,
      "y": 10,
      "z": -15,
      "name": "Wood_Birch_Trunk_Full",
      "rotation": 5
    },
    {
      "x": 22,
      "y": 0,
      "z": -13,
      "name": "Wood_Birch_Branch_Corner",
      "rotation": 2
    },
    {
      "x": 22,
      "y": 1,
      "z": -13,
      "name": "Wood_Birch_Branch_Long",
      "rotation": 1
    },
    {
      "x": 22,
      "y": 2,
      "z": -13,
      "name": "Wood_Birch_Trunk_Full",
      "rotation": 1
    },
    {
      "x": 22,
      "y": 3,
      "z": -13,
      "name": "Wood_Birch_Trunk_Full",
      "rotation": 1
    },
    {
      "x": 22,
      "y": 5,
      "z": -13,
      "name": "Wood_Birch_Trunk_Full"
    },
    {
      "x": 22,
      "y": 6,
      "z": -13,
      "name": "Wood_Birch_Trunk_Full"
    },
    {
      "x": 22,
      "y": 7,
      "z": -13,
      "name": "Wood_Birch_Trunk_Full",
      "rotation": 5
    },
    {
      "x": 22,
      "y": 0,
      "z": -12,
      "name": "Wood_Birch_Branch_Corner"
    },
    {
      "x": 23,
      "y": 4,
      "z": -19,
      "name": "Wood_Birch_Trunk_Full"
    },
    {
      "x": 23,
      "y": 5,
      "z": -19,
      "name": "Wood_Birch_Trunk_Full"
    },
    {
      "x": 23,
      "y": 6,
      "z": -19,
      "name": "Wood_Birch_Trunk_Full",
      "rotation": 5
    },
    {
      "x": 23,
      "y": 2,
      "z": -18,
      "name": "Wood_Birch_Branch_Corner",
      "rotation": 3
    },
    {
      "x": 23,
      "y": 3,
      "z": -18,
      "name": "Wood_Birch_Branch_Long",
      "rotation": 1
    },
    {
      "x": 23,
      "y": 4,
      "z": -18,
      "name": "Wood_Birch_Trunk_Full",
      "rotation": 1
    },
    {
      "x": 23,
      "y": 2,
      "z": -17,
      "name": "Wood_Birch_Branch_Corner",
      "rotation": 1
    },
    {
      "x": 23,
      "y": 3,
      "z": -17,
      "name": "Wood_Birch_Branch_Corner",
      "rotation": 34
    },
    {
      "x": 23,
      "y": 5,
      "z": -17,
      "name": "Wood_Birch_Branch_Long",
      "rotation": 5
    },
    {
      "x": 23,
      "y": 9,
      "z": -17,
      "name": "Wood_Birch_Trunk_Full",
      "rotation": 4
    },
    {
      "x": 23,
      "y": 0,
      "z": -16,
      "name": "Wood_Birch_Branch_Corner",
      "rotation": 2
    },
    {
      "x": 23,
      "y": 1,
      "z": -16,
      "name": "Wood_Birch_Branch_Long",
      "rotation": 1
    },
    {
      "x": 23,
      "y": 2,
      "z": -16,
      "name": "Wood_Birch_Branch_Long",
      "rotation": 1
    },
    {
      "x": 23,
      "y": 3,
      "z": -16,
      "name": "Wood_Birch_Branch_Corner",
      "rotation": 32
    },
    {
      "x": 23,
      "y": 9,
      "z": -16,
      "name": "Wood_Birch_Trunk_Full",
      "rotation": 4
    },
    {
      "x": 23,
      "y": 0,
      "z": -15,
      "name": "Wood_Birch_Branch_Corner"
    },
    {
      "x": 23,
      "y": 1,
      "z": -15,
      "name": "Wood_Birch_Branch_Corner",
      "rotation": 11
    },
    {
      "x": 23,
      "y": 7,
      "z": -13,
      "name": "Wood_Birch_Branch_Long",
      "rotation": 5
    },
    {
      "x": 24,
      "y": 6,
      "z": -19,
      "name": "Wood_Birch_Trunk_Full",
      "rotation": 5
    },
    {
      "x": 24,
      "y": 6,
      "z": -18,
      "name": "Wood_Birch_Trunk_Full",
      "rotation": 4
    },
    {
      "x": 24,
      "y": 7,
      "z": -18,
      "name": "Wood_Birch_Trunk_Full",
      "rotation": 1
    },
    {
      "x": 24,
      "y": 8,
      "z": -18,
      "name": "Wood_Birch_Trunk_Full",
      "rotation": 1
    },
    {
      "x": 24,
      "y": 5,
      "z": -17,
      "name": "Wood_Birch_Trunk_Full",
      "rotation": 1
    },
    {
      "x": 24,
      "y": 6,
      "z": -17,
      "name": "Wood_Birch_Trunk_Full"
    },
    {
      "x": 24,
      "y": 8,
      "z": -17,
      "name": "Wood_Birch_Trunk_Full"
    },
    {
      "x": 24,
      "y": 9,
      "z": -17,
      "name": "Wood_Birch_Trunk_Full"
    },
    {
      "x": 24,
      "y": 6,
      "z": -16,
      "name": "Wood_Birch_Branch_Long",
      "rotation": 4
    },
    {
      "x": 24,
      "y": 4,
      "z": -15,
      "name": "Wood_Birch_Branch_Long",
      "rotation": 1
    },
    {
      "x": 24,
      "y": 5,
      "z": -15,
      "name": "Wood_Birch_Branch_Long",
      "rotation": 1
    },
    {
      "x": 24,
      "y": 6,
      "z": -15,
      "name": "Wood_Birch_Branch_Corner",
      "rotation": 10
    },
    {
      "x": 24,
      "y": 6,
      "z": -13,
      "name": "Wood_Birch_Branch_Corner",
      "rotation": 2
    },
    {
      "x": 24,
      "y": 7,
      "z": -13,
      "name": "Wood_Birch_Branch_Corner",
      "rotation": 11
    },
    {
      "x": 24,
      "y": 4,
      "z": -12,
      "name": "Wood_Birch_Branch_Long"
    },
    {
      "x": 24,
      "y": 5,
      "z": -12,
      "name": "Wood_Birch_Branch_Long"
    },
    {
      "x": 24,
      "y": 6,
      "z": -12,
      "name": "Wood_Birch_Branch_Corner",
      "rotation": 10
    }
  ]
}