{
  "version": 8,
  "blockIdVersion": 11,
  "anchorX": 0,
  "anchorY": 0,
  "anchorZ": 0,
  "blocks": [
    {
      "x": -4,
      "y": -1,
      "z": 6,
      "name": "Wood_Birch_Trunk_Full",
      "support": 15,
      "rotation": 4
    },
    {
      "x": -4,
      "y": -3,
      "z": 7,
      "name": "Wood_Birch_Trunk_Full",
      "support": 15,
      "rotation": 4
    },
    {
      "x": -4,
      "y": -2,
      "z": 7,
      "name": "Wood_Birch_Trunk",
      "support": 15
    },
    {
      "x": -4,
      "y": -1,
      "z": 7,
      "name": "Wood_Birch_Trunk_Full",
      "support": 15,
      "rotation": 4
    },
    {
      "x": -4,
      "y": -3,
      "z": 8,
      "name": "Wood_Birch_Trunk",
      "support": 15,
      "rotation": 4
    },
    {
      "x": -4,
      "y": -3,
      "z": 9,
      "name": "Wood_Birch_Trunk_Full",
      "support": 15,
      "rotation": 4
    },
    {
      "x": -3,
      "y": 3,
      "z": -5,
      "name": "Wood_Birch_Branch_Corner",
      "support": 15,
      "rotation": 3
    },
    {
      "x": -3,
      "y": 4,
      "z": -5,
      "name": "Wood_Birch_Branch_Long",
      "support": 15
    },
    {
      "x": -3,
      "y": -1,
      "z": 6,
      "name": "Wood_Birch_Trunk",
      "support": 15,
      "rotation": 5
    },
    {
      "x": -2,
      "y": 3,
      "z": -5,
      "name": "Wood_Birch_Branch_Long",
      "support": 15,
      "rotation": 5
    },
    {
      "x": -2,
      "y": 1,
      "z": 3,
      "name": "Wood_Birch_Trunk_Full",
      "support": 15,
      "rotation": 5
    },
    {
      "x": -2,
      "y": 1,
      "z": 4,
      "name": "Wood_Birch_Trunk",
      "support": 15,
      "rotation": 4
    },
    {
      "x": -2,
      "y": 1,
      "z": 5,
      "name": "Wood_Birch_Trunk",
      "support": 15,
      "rotation": 4
    },
    {
      "x": -2,
      "y": -1,
      "z": 6,
      "name": "Wood_Birch_Trunk_Full",
      "support": 15
    },
    {
      "x": -2,
      "y": 0,
      "z": 6,
      "name": "Wood_Birch_Trunk",
      "support": 15
    },
    {
      "x": -2,
      "y": 1,
      "z": 6,
      "name": "Wood_Birch_Trunk_Full",
      "support": 15,
      "rotation": 4
    },
    {
      "x": -2,
      "y": 1,
      "z": 7,
      "name": "Wood_Birch_Trunk_Full",
      "support": 15
    },
    {
      "x": -2,
      "y": 2,
      "z": 7,
      "name": "Wood_Birch_Branch_Long",
      "support": 15
    },
    {
      "x": -2,
      "y": 3,
      "z": 7,
      "name": "Wood_Birch_Branch_Corner",
      "support": 15,
      "rotation": 8
    },
    {
      "x": -2,
      "y": 3,
      "z": 8,
      "name": "Wood_Birch_Branch_Long",
      "support": 15,
      "rotation": 4
    },
    {
      "x": -2,
      "y": -1,
      "z": 9,
      "name": "Wood_Birch_Branch_Corner",
      "support": 15,
      "rotation": 2
    },
    {
      "x": -2,
      "y": 0,
      "z": 9,
      "name": "Wood_Birch_Branch_Long",
      "support": 15
    },
    {
      "x": -2,
      "y": 1,
      "z": 9,
      "name": "Wood_Birch_Branch_Long",
      "support": 15
    },
    {
      "x": -2,
      "y": 2,
      "z": 9,
      "name": "Wood_Birch_Branch_Long",
      "support": 15
    },
    {
      "x": -2,
      "y": 3,
      "z": 9,
      "name": "Wood_Birch_Branch_Corner",
      "support": 15,
      "rotation": 10
    },
    {
      "x": -1,
      "y": 3,
      "z": -5,
      "name": "Wood_Birch_Branch_Long",
      "support": 15,
      "rotation": 5
    },
    {
      "x": -1,
      "y": -5,
      "z": -2,
      "name": "Wood_Birch_Branch_Corner",
      "support": 15,
      "rotation": 2
    },
    {
      "x": -1,
      "y": -4,
      "z": -2,
      "name": "Wood_Birch_Branch_Long",
      "support": 15
    },
    {
      "x": -1,
      "y": -3,
      "z": -2,
      "name": "Wood_Birch_Branch_Corner",
      "support": 15,
      "rotation": 8
    },
    {
      "x": -1,
      "y": -5,
      "z": -1,
      "name": "Wood_Birch_Branch_Corner",
      "support": 15
    },
    {
      "x": -1,
      "y": -3,
      "z": -1,
      "name": "Wood_Birch_Branch_Long",
      "support": 15,
      "rotation": 4
    },
    {
      "x": -1,
      "y": -3,
      "z": 0,
      "name": "Wood_Birch_Branch_Long",
      "support": 15,
      "rotation": 4
    },
    {
      "x": -1,
      "y": -3,
      "z": 1,
      "name": "Wood_Birch_Trunk_Full",
      "support": 15,
      "rotation": 4
    },
    {
      "x": -1,
      "y": -3,
      "z": 2,
      "name": "Wood_Birch_Trunk_Full",
      "support": 15,
      "rotation": 4
    },
    {
      "x": -1,
      "y": 1,
      "z": 3,
      "name": "Wood_Birch_Trunk",
      "support": 15,
      "rotation": 5
    },
    {
      "x": 0,
      "y": 0,
      "z": -6,
      "name": "Wood_Birch_Branch_Corner",
      "support": 15,
      "rotation": 2
    },
    {
      "x": 0,
      "y": 1,
      "z": -6,
      "name": "Wood_Birch_Branch_Corner",
      "support": 15,
      "rotation": 8
    },
    {
      "x": 0,
      "y": 7,
      "z": -6,
      "name": "Wood_Birch_Branch_Corner",
      "support": 15,
      "rotation": 2
    },
    {
      "x": 0,
      "y": 8,
      "z": -6,
      "name": "Wood_Birch_Branch_Long",
      "support": 15
    },
    {
      "x": 0,
      "y": 9,
      "z": -6,
      "name": "Wood_Birch_Branch_Long",
      "support": 15
    },
    {
      "x": 0,
      "y": 1,
      "z": -5,
      "name": "Wood_Birch_Trunk_Full",
      "support": 15,
      "rotation": 4
    },
    {
      "x": 0,
      "y": 2,
      "z": -5,
      "name": "Wood_Birch_Trunk",
      "support": 15
    },
    {
      "x": 0,
      "y": 3,
      "z": -5,
      "name": "Wood_Birch_Trunk",
      "support": 15
    },
    {
      "x": 0,
      "y": 4,
      "z": -5,
      "name": "Wood_Birch_Trunk",
      "support": 15
    },
    {
      "x": 0,
      "y": 5,
      "z": -5,
      "name": "Wood_Birch_Branch_Long",
      "support": 15
    },
    {
      "x": 0,
      "y": 6,
      "z": -5,
      "name": "Wood_Birch_Branch_Long",
      "support": 15
    },
    {
      "x": 0,
      "y": 7,
      "z": -5,
      "name": "Wood_Birch_Branch_Corner",
      "support": 15,
      "rotation": 10
    },
    {
      "x": 0,
      "y": 1,
      "z": -4,
      "name": "Wood_Birch_Trunk",
      "support": 15,
      "rotation": 4
    },
    {
      "x": 0,
      "y": 3,
      "z": -4,
      "name": "Wood_Birch_Branch_Long",
      "support": 15,
      "rotation": 4
    },
    {
      "x": 0,
      "y": 0,
      "z": -3,
      "name": "Wood_Birch_Trunk_Full",
      "support": 15,
      "rotation": 4
    },
    {
      "x": 0,
      "y": 1,
      "z": -3,
      "name": "Wood_Birch_Trunk_Full",
      "support": 15,
      "rotation": 4
    },
    {
      "x": 0,
      "y": 3,
      "z": -3,
      "name": "Wood_Birch_Branch_Long",
      "support": 15,
      "rotation": 4
    },
    {
      "x": 0,
      "y": 0,
      "z": -2,
      "name": "Wood_Birch_Trunk",
      "support": 15,
      "rotation": 4
    },
    {
      "x": 0,
      "y": 3,
      "z": -2,
      "name": "Wood_Birch_Branch_Corner",
      "support": 15
    },
    {
      "x": 0,
      "y": 4,
      "z": -2,
      "name": "Wood_Birch_Branch_Long",
      "support": 15
    },
    {
      "x": 0,
      "y": -1,
      "z": -1,
      "name": "Wood_Birch_Trunk_Full",
      "support": 15,
      "rotation": 4
    },
    {
      "x": 0,
      "y": 0,
      "z": -1,
      "name": "Wood_Birch_Trunk",
      "support": 15,
      "rotation": 4
    },
    {
      "x": 0,
      "y": -1,
      "z": 0,
      "name": "Wood_Birch_Trunk",
      "support": 15,
      "rotation": 4
    },
    {
      "x": 0,
      "y": 0,
      "z": 0,
      "name": "Wood_Birch_Trunk",
      "support": 15,
      "rotation": 4
    },
    {
      "x": 0,
      "y": -1,
      "z": 1,
      "name": "Wood_Birch_Trunk",
      "support": 15,
      "rotation": 4
    },
    {
      "x": 0,
      "y": 0,
      "z": 1,
      "name": "Wood_Birch_Trunk_Full",
      "support": 15,
      "rotation": 4
    },
    {
      "x": 0,
      "y": 1,
      "z": 1,
      "name": "Wood_Birch_Trunk_Full",
      "support": 15,
      "rotation": 4
    },
    {
      "x": 0,
      "y": -3,
      "z": 2,
      "name": "Wood_Birch_Trunk_Full",
      "support": 15,
      "rotation": 4
    },
    {
      "x": 0,
      "y": -1,
      "z": 2,
      "name": "Wood_Birch_Trunk_Full",
      "support": 15,
      "rotation": 4
    },
    {
      "x": 0,
      "y": 0,
      "z": 2,
      "name": "Wood_Birch_Trunk_Full",
      "support": 15,
      "rotation": 4
    },
    {
      "x": 0,
      "y": 1,
      "z": 2,
      "name": "Wood_Birch_Trunk_Full",
      "support": 15,
      "rotation": 4
    },
    {
      "x": 0,
      "y": -3,
      "z": 3,
      "name": "Wood_Birch_Trunk_Full",
      "support": 15,
      "rotation": 4
    },
    {
      "x": 0,
      "y": -2,
      "z": 3,
      "name": "Wood_Birch_Trunk",
      "support": 15
    },
    {
      "x": 0,
      "y": -1,
      "z": 3,
      "name": "Wood_Birch_Trunk_Full",
      "support": 15,
      "rotation": 4
    },
    {
      "x": 0,
      "y": 0,
      "z": 3,
      "name": "Wood_Birch_Trunk_Full",
      "support": 15,
      "rotation": 4
    },
    {
      "x": 0,
      "y": 1,
      "z": 3,
      "name": "Wood_Birch_Trunk_Full",
      "support": 15,
      "rotation": 4
    },
    {
      "x": 0,
      "y": 0,
      "z": 4,
      "name": "Wood_Birch_Trunk_Full",
      "support": 15,
      "rotation": 4
    },
    {
      "x": 0,
      "y": 1,
      "z": 4,
      "name": "Wood_Birch_Trunk",
      "support": 15,
      "rotation": 4
    },
    {
      "x": 0,
      "y": 3,
      "z": 4,
      "name": "Wood_Birch_Branch_Long",
      "support": 15
    },
    {
      "x": 0,
      "y": 4,
      "z": 4,
      "name": "Wood_Birch_Branch_Corner",
      "support": 15,
      "rotation": 8
    },
    {
      "x": 0,
      "y": -1,
      "z": 5,
      "name": "Wood_Birch_Trunk_Full",
      "support": 15
    },
    {
      "x": 0,
      "y": 0,
      "z": 5,
      "name": "Wood_Birch_Trunk_Full",
      "support": 15,
      "rotation": 4
    },
    {
      "x": 0,
      "y": 1,
      "z": 5,
      "name": "Wood_Birch_Trunk",
      "support": 15,
      "rotation": 4
    },
    {
      "x": 0,
      "y": 4,
      "z": 5,
      "name": "Wood_Birch_Branch_Long",
      "support": 15,
      "rotation": 4
    },
    {
      "x": 0,
      "y": 1,
      "z": 6,
      "name": "Wood_Birch_Trunk_Full",
      "support": 15,
      "rotation": 4
    },
    {
      "x": 0,
      "y": 2,
      "z": 6,
      "name": "Wood_Birch_Branch_Long",
      "support": 15
    },
    {
      "x": 0,
      "y": 3,
      "z": 6,
      "name": "Wood_Birch_Branch_Long",
      "support": 15
    },
    {
      "x": 0,
      "y": 4,
      "z": 6,
      "name": "Wood_Birch_Branch_Corner",
      "support": 15,
      "rotation": 10
    },
    {
      "x": 0,
      "y": 1,
      "z": 7,
      "name": "Wood_Birch_Trunk_Full",
      "support": 15,
      "rotation": 4
    },
    {
      "x": 1,
      "y": 0,
      "z": 0,
      "name": "Wood_Birch_Trunk_Full",
      "support": 15,
      "rotation": 4
    },
    {
      "x": 1,
      "y": 0,
      "z": 1,
      "name": "Wood_Birch_Trunk_Full",
      "support": 15,
      "rotation": 4
    },
    {
      "x": 1,
      "y": 0,
      "z": 2,
      "name": "Wood_Birch_Trunk_Full",
      "support": 15,
      "rotation": 4
    },
    {
      "x": 1,
      "y": -8,
      "z": 5,
      "name": "Wood_Birch_Branch_Corner",
      "support": 15,
      "rotation": 3
    },
    {
      "x": 1,
      "y": -7,
      "z": 5,
      "name": "Wood_Birch_Branch_Long",
      "support": 15
    },
    {
      "x": 1,
      "y": -6,
      "z": 5,
      "name": "Wood_Birch_Branch_Long",
      "support": 15
    },
    {
      "x": 1,
      "y": -5,
      "z": 5,
      "name": "Wood_Birch_Trunk_Full",
      "support": 15
    },
    {
      "x": 1,
      "y": -4,
      "z": 5,
      "name": "Wood_Birch_Trunk_Full",
      "support": 15
    },
    {
      "x": 1,
      "y": -3,
      "z": 5,
      "name": "Wood_Birch_Trunk_Full",
      "support": 15
    },
    {
      "x": 1,
      "y": -2,
      "z": 5,
      "name": "Wood_Birch_Trunk_Full",
      "support": 15
    },
    {
      "x": 1,
      "y": -1,
      "z": 5,
      "name": "Wood_Birch_Trunk_Full",
      "support": 15,
      "rotation": 5
    },
    {
      "x": 2,
      "y": -11,
      "z": 4,
      "name": "Wood_Birch_Branch_Corner",
      "support": 15,
      "rotation": 2
    },
    {
      "x": 2,
      "y": -10,
      "z": 4,
      "name": "Wood_Birch_Branch_Corner",
      "support": 15,
      "rotation": 8
    },
    {
      "x": 2,
      "y": -10,
      "z": 5,
      "name": "Wood_Birch_Branch_Corner",
      "support": 15
    },
    {
      "x": 2,
      "y": -9,
      "z": 5,
      "name": "Wood_Birch_Branch_Long",
      "support": 15
    },
    {
      "x": 2,
      "y": -8,
      "z": 5,
      "name": "Wood_Birch_Branch_Corner",
      "support": 15,
      "rotation": 11
    }
  ]
}