{
  "version": 8,
  "blockIdVersion": 11,
  "anchorX": -2,
  "anchorY": 4,
  "anchorZ": 2,
  "blocks": [
    {
      "x": -5,
      "y": 8,
      "z": -3,
      "name": "Wood_Birch_Branch_Corner",
      "rotation": 3
    },
    {
      "x": -5,
      "y": 9,
      "z": -3,
      "name": "Wood_Birch_Branch_Long",
      "rotation": 1
    },
    {
      "x": -5,
      "y": 10,
      "z": -3,
      "name": "Wood_Birch_Branch_Long",
      "rotation": 1
    },
    {
      "x": -4,
      "y": 8,
      "z": -3,
      "name": "Wood_Birch_Branch_Long",
      "rotation": 5
    },
    {
      "x": -3,
      "y": 8,
      "z": -3,
      "name": "Wood_Birch_Branch_Long",
      "rotation": 5
    },
    {
      "x": -3,
      "y": 4,
      "z": 3,
      "name": "Wood_Birch_Trunk_Full",
      "rotation": 6
    },
    {
      "x": -3,
      "y": 0,
      "z": 4,
      "name": "Wood_Birch_Branch_Corner",
      "rotation": 2
    },
    {
      "x": -3,
      "y": 1,
      "z": 4,
      "name": "Wood_Birch_Branch_Long",
      "rotation": 1
    },
    {
      "x": -3,
      "y": 2,
      "z": 4,
      "name": "Wood_Birch_Branch_Corner",
      "rotation": 8
    },
    {
      "x": -3,
      "y": 4,
      "z": 4,
      "name": "Wood_Birch_Trunk",
      "rotation": 6
    },
    {
      "x": -3,
      "y": 0,
      "z": 5,
      "name": "Wood_Birch_Branch_Long",
      "rotation": 6
    },
    {
      "x": -3,
      "y": 2,
      "z": 5,
      "name": "Wood_Birch_Branch_Corner",
      "rotation": 10
    },
    {
      "x": -3,
      "y": 4,
      "z": 5,
      "name": "Wood_Birch_Trunk",
      "rotation": 6
    },
    {
      "x": -3,
      "y": 0,
      "z": 6,
      "name": "Wood_Birch_Trunk",
      "rotation": 6
    },
    {
      "x": -3,
      "y": 4,
      "z": 6,
      "name": "Wood_Birch_Trunk_Full",
      "rotation": 6
    },
    {
      "x": -3,
      "y": 0,
      "z": 7,
      "name": "Wood_Birch_Trunk_Full",
      "rotation": 6
    },
    {
      "x": -3,
      "y": 1,
      "z": 7,
      "name": "Wood_Birch_Trunk",
      "rotation": 1
    },
    {
      "x": -3,
      "y": 2,
      "z": 7,
      "name": "Wood_Birch_Trunk",
      "rotation": 1
    },
    {
      "x": -3,
      "y": 3,
      "z": 7,
      "name": "Wood_Birch_Trunk",
      "rotation": 1
    },
    {
      "x": -3,
      "y": 4,
      "z": 7,
      "name": "Wood_Birch_Trunk_Full",
      "rotation": 6
    },
    {
      "x": -3,
      "y": 4,
      "z": 8,
      "name": "Wood_Birch_Branch_Long",
      "rotation": 6
    },
    {
      "x": -3,
      "y": 4,
      "z": 9,
      "name": "Wood_Birch_Branch_Long",
      "rotation": 6
    },
    {
      "x": -2,
      "y": 5,
      "z": -9,
      "name": "Wood_Birch_Trunk_Full",
      "rotation": 6
    },
    {
      "x": -2,
      "y": 6,
      "z": -9,
      "name": "Wood_Birch_Trunk",
      "rotation": 1
    },
    {
      "x": -2,
      "y": 7,
      "z": -9,
      "name": "Wood_Birch_Trunk",
      "rotation": 1
    },
    {
      "x": -2,
      "y": 8,
      "z": -9,
      "name": "Wood_Birch_Trunk_Full",
      "rotation": 6
    },
    {
      "x": -2,
      "y": 4,
      "z": -8,
      "name": "Wood_Birch_Trunk_Full",
      "rotation": 6
    },
    {
      "x": -2,
      "y": 5,
      "z": -8,
      "name": "Wood_Birch_Trunk_Full",
      "rotation": 6
    },
    {
      "x": -2,
      "y": 8,
      "z": -8,
      "name": "Wood_Birch_Trunk_Full",
      "rotation": 6
    },
    {
      "x": -2,
      "y": 9,
      "z": -8,
      "name": "Wood_Birch_Trunk_Full",
      "rotation": 6
    },
    {
      "x": -2,
      "y": 10,
      "z": -8,
      "name": "Wood_Birch_Branch_Long",
      "rotation": 1
    },
    {
      "x": -2,
      "y": 4,
      "z": -7,
      "name": "Wood_Birch_Trunk_Full",
      "rotation": 6
    },
    {
      "x": -2,
      "y": 9,
      "z": -7,
      "name": "Wood_Birch_Trunk",
      "rotation": 6
    },
    {
      "x": -2,
      "y": 4,
      "z": -6,
      "name": "Wood_Birch_Branch_Long",
      "rotation": 6
    },
    {
      "x": -2,
      "y": 6,
      "z": -6,
      "name": "Wood_Birch_Branch_Corner",
      "rotation": 8
    },
    {
      "x": -2,
      "y": 9,
      "z": -6,
      "name": "Wood_Birch_Trunk",
      "rotation": 6
    },
    {
      "x": -2,
      "y": 4,
      "z": -5,
      "name": "Wood_Birch_Branch_Corner"
    },
    {
      "x": -2,
      "y": 5,
      "z": -5,
      "name": "Wood_Birch_Branch_Long",
      "rotation": 1
    },
    {
      "x": -2,
      "y": 6,
      "z": -5,
      "name": "Wood_Birch_Branch_Corner",
      "rotation": 10
    },
    {
      "x": -2,
      "y": 9,
      "z": -5,
      "name": "Wood_Birch_Trunk",
      "rotation": 6
    },
    {
      "x": -2,
      "y": 8,
      "z": -4,
      "name": "Wood_Birch_Trunk_Full",
      "rotation": 6
    },
    {
      "x": -2,
      "y": 9,
      "z": -4,
      "name": "Wood_Birch_Trunk_Full",
      "rotation": 6
    },
    {
      "x": -2,
      "y": 10,
      "z": -4,
      "name": "Wood_Birch_Branch_Long",
      "rotation": 1
    },
    {
      "x": -2,
      "y": 5,
      "z": -3,
      "name": "Wood_Birch_Trunk_Full",
      "rotation": 6
    },
    {
      "x": -2,
      "y": 6,
      "z": -3,
      "name": "Wood_Birch_Trunk",
      "rotation": 1
    },
    {
      "x": -2,
      "y": 7,
      "z": -3,
      "name": "Wood_Birch_Trunk",
      "rotation": 1
    },
    {
      "x": -2,
      "y": 8,
      "z": -3,
      "name": "Wood_Birch_Trunk_Full",
      "rotation": 6
    },
    {
      "x": -2,
      "y": 4,
      "z": -2,
      "name": "Wood_Birch_Trunk_Full",
      "rotation": 6
    },
    {
      "x": -2,
      "y": 5,
      "z": -2,
      "name": "Wood_Birch_Trunk_Full",
      "rotation": 6
    },
    {
      "x": -2,
      "y": 6,
      "z": -2,
      "name": "Wood_Birch_Branch_Corner",
      "rotation": 10
    },
    {
      "x": -2,
      "y": 4,
      "z": -1,
      "name": "Wood_Birch_Trunk",
      "rotation": 6
    },
    {
      "x": -2,
      "y": 5,
      "z": -1,
      "name": "Wood_Birch_Trunk_Full",
      "rotation": 6
    },
    {
      "x": -2,
      "y": 4,
      "z": 0,
      "name": "Wood_Birch_Trunk",
      "support": 15,
      "rotation": 6
    },
    {
      "x": -2,
      "y": 3,
      "z": 1,
      "name": "Wood_Birch_Trunk_Full",
      "rotation": 6
    },
    {
      "x": -2,
      "y": 4,
      "z": 1,
      "name": "Wood_Birch_Trunk",
      "support": 15,
      "rotation": 6
    },
    {
      "x": -2,
      "y": 3,
      "z": 2,
      "name": "Wood_Birch_Trunk_Full",
      "rotation": 6
    },
    {
      "x": -2,
      "y": 4,
      "z": 2,
      "name": "Wood_Birch_Trunk",
      "rotation": 6
    },
    {
      "x": -2,
      "y": 3,
      "z": 3,
      "name": "Wood_Birch_Trunk_Full",
      "rotation": 6
    },
    {
      "x": -2,
      "y": 4,
      "z": 3,
      "name": "Wood_Birch_Trunk",
      "rotation": 6
    },
    {
      "x": -2,
      "y": 4,
      "z": 4,
      "name": "Wood_Birch_Trunk",
      "rotation": 6
    },
    {
      "x": -2,
      "y": 4,
      "z": 5,
      "name": "Wood_Birch_Trunk",
      "rotation": 6
    },
    {
      "x": -2,
      "y": 4,
      "z": 6,
      "name": "Wood_Birch_Trunk",
      "rotation": 6
    },
    {
      "x": -2,
      "y": 4,
      "z": 7,
      "name": "Wood_Birch_Trunk",
      "rotation": 6
    },
    {
      "x": -2,
      "y": 4,
      "z": 8,
      "name": "Wood_Birch_Trunk",
      "rotation": 6
    },
    {
      "x": -2,
      "y": 4,
      "z": 9,
      "name": "Wood_Birch_Trunk_Full",
      "rotation": 6
    },
    {
      "x": -2,
      "y": 5,
      "z": 9,
      "name": "Wood_Birch_Trunk",
      "rotation": 1
    },
    {
      "x": -2,
      "y": 6,
      "z": 9,
      "name": "Wood_Birch_Trunk",
      "rotation": 1
    },
    {
      "x": -2,
      "y": 7,
      "z": 9,
      "name": "Wood_Birch_Trunk_Full",
      "rotation": 1
    },
    {
      "x": -1,
      "y": 9,
      "z": -6,
      "name": "Wood_Birch_Branch_Long",
      "rotation": 5
    },
    {
      "x": -1,
      "y": 4,
      "z": 2,
      "name": "Wood_Birch_Trunk_Full",
      "rotation": 6
    },
    {
      "x": -1,
      "y": 4,
      "z": 3,
      "name": "Wood_Birch_Trunk",
      "rotation": 6
    },
    {
      "x": -1,
      "y": 4,
      "z": 4,
      "name": "Wood_Birch_Trunk",
      "rotation": 6
    },
    {
      "x": -1,
      "y": 4,
      "z": 5,
      "name": "Wood_Birch_Trunk_Full",
      "rotation": 6
    },
    {
      "x": 0,
      "y": 9,
      "z": -6,
      "name": "Wood_Birch_Branch_Long",
      "rotation": 5
    },
    {
      "x": 0,
      "y": 4,
      "z": 5,
      "name": "Wood_Birch_Trunk",
      "rotation": 5
    },
    {
      "x": 1,
      "y": 9,
      "z": -6,
      "name": "Wood_Birch_Branch_Corner",
      "rotation": 1
    },
    {
      "x": 1,
      "y": 10,
      "z": -6,
      "name": "Wood_Birch_Branch_Long",
      "rotation": 1
    },
    {
      "x": 1,
      "y": 4,
      "z": 5,
      "name": "Wood_Birch_Trunk",
      "rotation": 5
    },
    {
      "x": 2,
      "y": 4,
      "z": 5,
      "name": "Wood_Birch_Trunk_Full",
      "rotation": 5
    },
    {
      "x": 2,
      "y": 4,
      "z": 6,
      "name": "Wood_Birch_Trunk",
      "rotation": 6
    },
    {
      "x": 2,
      "y": 4,
      "z": 7,
      "name": "Wood_Birch_Trunk",
      "rotation": 6
    },
    {
      "x": 2,
      "y": 4,
      "z": 8,
      "name": "Wood_Birch_Trunk",
      "rotation": 6
    },
    {
      "x": 2,
      "y": 4,
      "z": 9,
      "name": "Wood_Birch_Trunk_Full",
      "rotation": 6
    }
  ]
}