{
  "version": 8,
  "blockIdVersion": 11,
  "anchorX": 5,
  "anchorY": 5,
  "anchorZ": 8,
  "blocks": [
    {
      "x": -20,
      "y": 15,
      "z": 3,
      "name": "Wood_Darkwood_Planks"
    },
    {
      "x": -20,
      "y": 14,
      "z": 4,
      "name": "Wood_Darkwood_Planks"
    },
    {
      "x": -19,
      "y": 15,
      "z": 3,
      "name": "Deco_Rope",
      "rotation": 5
    },
    {
      "x": -19,
      "y": 14,
      "z": 4,
      "name": "Wood_Darkwood_Planks",
      "rotation": 4
    },
    {
      "x": -19,
      "y": 13,
      "z": 5,
      "name": "Wood_Darkwood_Planks"
    },
    {
      "x": -18,
      "y": 11,
      "z": 3,
      "name": "Wood_Darkwood_Stairs",
      "rotation": 2
    },
    {
      "x": -18,
      "y": 15,
      "z": 3,
      "name": "Deco_Rope",
      "rotation": 15
    },
    {
      "x": -18,
      "y": 11,
      "z": 4,
      "name": "Wood_Darkwood_Stairs",
      "rotation": 10
    },
    {
      "x": -18,
      "y": 12,
      "z": 4,
      "name": "Wood_Darkwood_Stairs",
      "rotation": 2
    },
    {
      "x": -18,
      "y": 14,
      "z": 4,
      "name": "Wood_Darkwood_Planks",
      "rotation": 4
    },
    {
      "x": -18,
      "y": 12,
      "z": 5,
      "name": "Wood_Darkwood_Planks"
    },
    {
      "x": -18,
      "y": 13,
      "z": 5,
      "name": "Wood_Darkwood_Planks"
    },
    {
      "x": -18,
      "y": 12,
      "z": 6,
      "name": "Wood_Darkwood_Planks"
    },
    {
      "x": -18,
      "y": 13,
      "z": 6,
      "name": "Wood_Darkwood_Planks"
    },
    {
      "x": -18,
      "y": 14,
      "z": 6,
      "name": "Wood_Darkwood_Stairs",
      "rotation": 2
    },
    {
      "x": -18,
      "y": 14,
      "z": 7,
      "name": "Wood_Darkwood_Stairs",
      "rotation": 10
    },
    {
      "x": -18,
      "y": 15,
      "z": 7,
      "name": "Wood_Darkwood_Stairs",
      "rotation": 2
    },
    {
      "x": -17,
      "y": 15,
      "z": 3,
      "name": "Deco_Rope",
      "rotation": 15
    },
    {
      "x": -17,
      "y": 12,
      "z": 5,
      "name": "Wood_Darkwood_Planks"
    },
    {
      "x": -17,
      "y": 13,
      "z": 5,
      "name": "Wood_Darkwood_Planks"
    },
    {
      "x": -17,
      "y": 14,
      "z": 5,
      "name": "Plant_Seaweed_Winter_Short",
      "support": 15
    },
    {
      "x": -17,
      "y": 12,
      "z": 6,
      "name": "Wood_Darkwood_Planks"
    },
    {
      "x": -16,
      "y": 15,
      "z": 3,
      "name": "Deco_Rope",
      "rotation": 5
    },
    {
      "x": -16,
      "y": 12,
      "z": 6,
      "name": "Wood_Darkwood_Planks",
      "rotation": 4
    },
    {
      "x": -16,
      "y": 11,
      "z": 7,
      "name": "Wood_Darkwood_Planks"
    },
    {
      "x": -15,
      "y": 15,
      "z": 3,
      "name": "Wood_Darkwood_Planks",
      "rotation": 4
    },
    {
      "x": -15,
      "y": 14,
      "z": 4,
      "name": "Wood_Darkwood_Planks_Half",
      "rotation": 11
    },
    {
      "x": -15,
      "y": 11,
      "z": 5,
      "name": "Wood_Deadwood_Planks",
      "rotation": 4
    },
    {
      "x": -15,
      "y": 11,
      "z": 6,
      "name": "Wood_Deadwood_Planks",
      "rotation": 4
    },
    {
      "x": -15,
      "y": 12,
      "z": 6,
      "name": "Wood_Deadwood_Planks",
      "rotation": 4
    },
    {
      "x": -15,
      "y": 11,
      "z": 7,
      "name": "Wood_Darkwood_Planks",
      "rotation": 4
    },
    {
      "x": -15,
      "y": 12,
      "z": 7,
      "name": "Wood_Deadwood_Planks",
      "rotation": 4
    },
    {
      "x": -15,
      "y": 13,
      "z": 7,
      "name": "Wood_Deadwood_Planks",
      "rotation": 4
    },
    {
      "x": -15,
      "y": 10,
      "z": 8,
      "name": "Wood_Darkwood_Planks"
    },
    {
      "x": -14,
      "y": 14,
      "z": 4,
      "name": "Wood_Darkwood_Planks",
      "rotation": 4
    },
    {
      "x": -14,
      "y": 11,
      "z": 5,
      "name": "Wood_Deadwood_Planks",
      "rotation": 4
    },
    {
      "x": -14,
      "y": 12,
      "z": 5,
      "name": "Wood_Deadwood_Planks",
      "rotation": 4
    },
    {
      "x": -14,
      "y": 13,
      "z": 5,
      "name": "Wood_Darkwood_Planks",
      "rotation": 4
    },
    {
      "x": -14,
      "y": 10,
      "z": 6,
      "name": "Wood_Deadwood_Planks",
      "rotation": 4
    },
    {
      "x": -14,
      "y": 11,
      "z": 6,
      "name": "Wood_Deadwood_Planks",
      "rotation": 4
    },
    {
      "x": -14,
      "y": 12,
      "z": 6,
      "name": "Wood_Deadwood_Planks",
      "rotation": 4
    },
    {
      "x": -14,
      "y": 13,
      "z": 6,
      "name": "Wood_Deadwood_Planks",
      "rotation": 4
    },
    {
      "x": -14,
      "y": 11,
      "z": 7,
      "name": "Wood_Deadwood_Planks",
      "rotation": 4
    },
    {
      "x": -14,
      "y": 12,
      "z": 7,
      "name": "Wood_Deadwood_Planks",
      "rotation": 4
    },
    {
      "x": -14,
      "y": 13,
      "z": 7,
      "name": "Wood_Deadwood_Planks",
      "rotation": 4
    },
    {
      "x": -14,
      "y": 10,
      "z": 8,
      "name": "Wood_Darkwood_Planks",
      "rotation": 4
    },
    {
      "x": -14,
      "y": 12,
      "z": 8,
      "name": "Wood_Deadwood_Planks",
      "rotation": 4
    },
    {
      "x": -13,
      "y": 11,
      "z": 4,
      "name": "Wood_Deadwood_Planks",
      "rotation": 4
    },
    {
      "x": -13,
      "y": 12,
      "z": 4,
      "name": "Plant_Seaweed_Winter_Short",
      "support": 15
    },
    {
      "x": -13,
      "y": 10,
      "z": 5,
      "name": "Wood_Deadwood_Planks",
      "rotation": 4
    },
    {
      "x": -13,
      "y": 11,
      "z": 5,
      "name": "Wood_Deadwood_Planks",
      "rotation": 4
    },
    {
      "x": -13,
      "y": 12,
      "z": 5,
      "name": "Wood_Deadwood_Planks",
      "rotation": 4
    },
    {
      "x": -13,
      "y": 13,
      "z": 5,
      "name": "Wood_Darkwood_Stairs",
      "rotation": 5
    },
    {
      "x": -13,
      "y": 10,
      "z": 6,
      "name": "Wood_Deadwood_Planks",
      "rotation": 4
    },
    {
      "x": -13,
      "y": 11,
      "z": 6,
      "name": "Wood_Deadwood_Planks",
      "rotation": 4
    },
    {
      "x": -13,
      "y": 12,
      "z": 6,
      "name": "Wood_Darkwood_Planks",
      "rotation": 4
    },
    {
      "x": -13,
      "y": 13,
      "z": 6,
      "name": "Wood_Deadwood_Planks",
      "rotation": 4
    },
    {
      "x": -13,
      "y": 9,
      "z": 7,
      "name": "Wood_Deadwood_Planks",
      "rotation": 4
    },
    {
      "x": -13,
      "y": 10,
      "z": 7,
      "name": "Wood_Deadwood_Planks",
      "rotation": 4
    },
    {
      "x": -13,
      "y": 11,
      "z": 7,
      "name": "Wood_Darkwood_Planks",
      "rotation": 4
    },
    {
      "x": -13,
      "y": 12,
      "z": 7,
      "name": "Wood_Deadwood_Planks",
      "rotation": 4
    },
    {
      "x": -13,
      "y": 13,
      "z": 7,
      "name": "Wood_Deadwood_Planks",
      "rotation": 4
    },
    {
      "x": -13,
      "y": 14,
      "z": 7,
      "name": "Wood_Deadwood_Planks",
      "rotation": 4
    },
    {
      "x": -13,
      "y": 9,
      "z": 8,
      "name": "Wood_Deadwood_Planks",
      "rotation": 4
    },
    {
      "x": -13,
      "y": 10,
      "z": 8,
      "name": "Wood_Darkwood_Planks",
      "rotation": 4
    },
    {
      "x": -13,
      "y": 11,
      "z": 8,
      "name": "Wood_Deadwood_Planks",
      "rotation": 4
    },
    {
      "x": -13,
      "y": 12,
      "z": 8,
      "name": "Wood_Deadwood_Planks",
      "rotation": 4
    },
    {
      "x": -13,
      "y": 13,
      "z": 8,
      "name": "Wood_Deadwood_Planks",
      "rotation": 4
    },
    {
      "x": -13,
      "y": 9,
      "z": 9,
      "name": "Wood_Darkwood_Planks"
    },
    {
      "x": -13,
      "y": 10,
      "z": 9,
      "name": "Wood_Deadwood_Planks",
      "rotation": 4
    },
    {
      "x": -13,
      "y": 11,
      "z": 9,
      "name": "Wood_Deadwood_Planks",
      "rotation": 4
    },
    {
      "x": -12,
      "y": 10,
      "z": 4,
      "name": "Wood_Deadwood_Planks",
      "rotation": 4
    },
    {
      "x": -12,
      "y": 11,
      "z": 4,
      "name": "Wood_Deadwood_Planks",
      "rotation": 4
    },
    {
      "x": -12,
      "y": 9,
      "z": 5,
      "name": "Plant_Barnacles",
      "rotation": 6
    },
    {
      "x": -12,
      "y": 10,
      "z": 5,
      "name": "Wood_Deadwood_Planks",
      "rotation": 4
    },
    {
      "x": -12,
      "y": 11,
      "z": 5,
      "name": "Wood_Darkwood_Planks",
      "rotation": 4
    },
    {
      "x": -12,
      "y": 8,
      "z": 6,
      "name": "Plant_Barnacles",
      "rotation": 6
    },
    {
      "x": -12,
      "y": 9,
      "z": 6,
      "name": "Wood_Deadwood_Planks",
      "rotation": 4
    },
    {
      "x": -12,
      "y": 10,
      "z": 6,
      "name": "Wood_Darkwood_Planks",
      "rotation": 4
    },
    {
      "x": -12,
      "y": 11,
      "z": 6,
      "name": "Wood_Darkwood_Planks",
      "rotation": 4
    },
    {
      "x": -12,
      "y": 12,
      "z": 6,
      "name": "Wood_Darkwood_Planks",
      "rotation": 4
    },
    {
      "x": -12,
      "y": 13,
      "z": 6,
      "name": "Plant_Barnacles",
      "rotation": 6
    },
    {
      "x": -12,
      "y": 14,
      "z": 6,
      "name": "Plant_Barnacles",
      "rotation": 6
    },
    {
      "x": -12,
      "y": 8,
      "z": 7,
      "name": "Wood_Deadwood_Planks",
      "rotation": 4
    },
    {
      "x": -12,
      "y": 11,
      "z": 7,
      "name": "Wood_Darkwood_Planks",
      "rotation": 4
    },
    {
      "x": -12,
      "y": 12,
      "z": 7,
      "name": "Wood_Darkwood_Planks",
      "rotation": 4
    },
    {
      "x": -12,
      "y": 13,
      "z": 7,
      "name": "Wood_Darkwood_Planks",
      "rotation": 4
    },
    {
      "x": -12,
      "y": 14,
      "z": 7,
      "name": "Wood_Deadwood_Planks",
      "rotation": 4
    },
    {
      "x": -12,
      "y": 8,
      "z": 8,
      "name": "Wood_Deadwood_Planks",
      "rotation": 4
    },
    {
      "x": -12,
      "y": 10,
      "z": 8,
      "name": "Wood_Darkwood_Planks",
      "rotation": 4
    },
    {
      "x": -12,
      "y": 11,
      "z": 8,
      "name": "Furniture_Ancient_Barrel"
    },
    {
      "x": -12,
      "y": 12,
      "z": 8,
      "name": "Wood_Darkwood_Planks",
      "rotation": 4
    },
    {
      "x": -12,
      "y": 13,
      "z": 8,
      "name": "Wood_Deadwood_Planks",
      "rotation": 4
    },
    {
      "x": -12,
      "y": 14,
      "z": 8,
      "name": "Wood_Deadwood_Planks",
      "rotation": 4
    },
    {
      "x": -12,
      "y": 8,
      "z": 9,
      "name": "Wood_Deadwood_Planks",
      "rotation": 4
    },
    {
      "x": -12,
      "y": 9,
      "z": 9,
      "name": "Wood_Darkwood_Planks",
      "rotation": 4
    },
    {
      "x": -12,
      "y": 10,
      "z": 9,
      "name": "Furniture_Ancient_Barrel"
    },
    {
      "x": -12,
      "y": 12,
      "z": 9,
      "name": "Wood_Deadwood_Planks",
      "rotation": 4
    },
    {
      "x": -12,
      "y": 8,
      "z": 10,
      "name": "Wood_Darkwood_Planks"
    },
    {
      "x": -12,
      "y": 9,
      "z": 10,
      "name": "Wood_Deadwood_Planks",
      "rotation": 4
    },
    {
      "x": -12,
      "y": 10,
      "z": 10,
      "name": "Wood_Deadwood_Planks",
      "rotation": 4
    },
    {
      "x": -12,
      "y": 11,
      "z": 10,
      "name": "Wood_Deadwood_Planks",
      "rotation": 4
    },
    {
      "x": -11,
      "y": 10,
      "z": 3,
      "name": "Wood_Deadwood_Planks",
      "rotation": 4
    },
    {
      "x": -11,
      "y": 9,
      "z": 4,
      "name": "Plant_Barnacles",
      "rotation": 6
    },
    {
      "x": -11,
      "y": 10,
      "z": 4,
      "name": "Wood_Deadwood_Planks",
      "rotation": 4
    },
    {
      "x": -11,
      "y": 8,
      "z": 5,
      "name": "Plant_Barnacles",
      "rotation": 6
    },
    {
      "x": -11,
      "y": 9,
      "z": 5,
      "name": "Wood_Deadwood_Planks",
      "rotation": 4
    },
    {
      "x": -11,
      "y": 10,
      "z": 5,
      "name": "Wood_Darkwood_Planks",
      "rotation": 4
    },
    {
      "x": -11,
      "y": 11,
      "z": 5,
      "name": "Wood_Darkwood_Planks",
      "rotation": 4
    },
    {
      "x": -11,
      "y": 12,
      "z": 5,
      "name": "Plant_Coral_Model_Cyan"
    },
    {
      "x": -11,
      "y": 8,
      "z": 6,
      "name": "Wood_Deadwood_Planks",
      "rotation": 4
    },
    {
      "x": -11,
      "y": 9,
      "z": 6,
      "name": "Wood_Deadwood_Planks",
      "rotation": 4
    },
    {
      "x": -11,
      "y": 10,
      "z": 6,
      "name": "Wood_Darkwood_Planks",
      "rotation": 4
    },
    {
      "x": -11,
      "y": 11,
      "z": 6,
      "name": "Wood_Darkwood_Planks",
      "rotation": 4
    },
    {
      "x": -11,
      "y": 12,
      "z": 6,
      "name": "Wood_Darkwood_Planks",
      "rotation": 4
    },
    {
      "x": -11,
      "y": 13,
      "z": 6,
      "name": "Plant_Barnacles",
      "rotation": 6
    },
    {
      "x": -11,
      "y": 8,
      "z": 7,
      "name": "Wood_Deadwood_Planks",
      "rotation": 4
    },
    {
      "x": -11,
      "y": 11,
      "z": 7,
      "name": "Wood_Oak_Trunk",
      "support": 15,
      "rotation": 9
    },
    {
      "x": -11,
      "y": 12,
      "z": 7,
      "name": "Wood_Darkwood_Planks",
      "rotation": 4
    },
    {
      "x": -11,
      "y": 13,
      "z": 7,
      "name": "Wood_Darkwood_Planks",
      "rotation": 4
    },
    {
      "x": -11,
      "y": 7,
      "z": 8,
      "name": "Wood_Deadwood_Planks",
      "rotation": 4
    },
    {
      "x": -11,
      "y": 8,
      "z": 8,
      "name": "Wood_Darkwood_Planks",
      "rotation": 4
    },
    {
      "x": -11,
      "y": 12,
      "z": 8,
      "name": "Wood_Darkwood_Planks",
      "rotation": 4
    },
    {
      "x": -11,
      "y": 13,
      "z": 8,
      "name": "Wood_Darkwood_Planks",
      "rotation": 4
    },
    {
      "x": -11,
      "y": 14,
      "z": 8,
      "name": "Wood_Deadwood_Planks",
      "rotation": 4
    },
    {
      "x": -11,
      "y": 15,
      "z": 8,
      "name": "Wood_Deadwood_Planks",
      "rotation": 4
    },
    {
      "x": -11,
      "y": 7,
      "z": 9,
      "name": "Wood_Deadwood_Planks",
      "rotation": 4
    },
    {
      "x": -11,
      "y": 8,
      "z": 9,
      "name": "Wood_Darkwood_Planks",
      "rotation": 4
    },
    {
      "x": -11,
      "y": 9,
      "z": 9,
      "name": "Wood_Oak_Trunk",
      "support": 15,
      "rotation": 9
    },
    {
      "x": -11,
      "y": 10,
      "z": 9,
      "name": "Furniture_Ancient_Barrel"
    },
    {
      "x": -11,
      "y": 12,
      "z": 9,
      "name": "Wood_Deadwood_Planks",
      "rotation": 4
    },
    {
      "x": -11,
      "y": 13,
      "z": 9,
      "name": "Wood_Deadwood_Planks",
      "rotation": 4
    },
    {
      "x": -11,
      "y": 8,
      "z": 10,
      "name": "Wood_Darkwood_Planks",
      "rotation": 4
    },
    {
      "x": -11,
      "y": 9,
      "z": 10,
      "name": "Wood_Darkwood_Planks",
      "rotation": 4
    },
    {
      "x": -11,
      "y": 10,
      "z": 10,
      "name": "Wood_Darkwood_Planks",
      "rotation": 4
    },
    {
      "x": -11,
      "y": 11,
      "z": 10,
      "name": "Wood_Deadwood_Planks",
      "rotation": 4
    },
    {
      "x": -11,
      "y": 12,
      "z": 10,
      "name": "Wood_Deadwood_Planks",
      "rotation": 4
    },
    {
      "x": -11,
      "y": 9,
      "z": 11,
      "name": "Wood_Deadwood_Planks",
      "rotation": 4
    },
    {
      "x": -11,
      "y": 10,
      "z": 11,
      "name": "Wood_Deadwood_Planks",
      "rotation": 4
    },
    {
      "x": -10,
      "y": 14,
      "z": -3,
      "name": "Cloth_Roof_Hide_Vertical",
      "rotation": 3
    },
    {
      "x": -10,
      "y": 15,
      "z": -3,
      "name": "Cloth_Roof_Hide_Vertical",
      "rotation": 3
    },
    {
      "x": -10,
      "y": 13,
      "z": -2,
      "name": "Cloth_Roof_Hide_Flap",
      "rotation": 3
    },
    {
      "x": -10,
      "y": 14,
      "z": -2,
      "name": "Cloth_Roof_Hide_Vertical",
      "rotation": 3
    },
    {
      "x": -10,
      "y": 15,
      "z": -2,
      "name": "Cloth_Roof_Hide_Vertical",
      "rotation": 3
    },
    {
      "x": -10,
      "y": 12,
      "z": -1,
      "name": "Cloth_Roof_Hide_Vertical",
      "rotation": 3
    },
    {
      "x": -10,
      "y": 13,
      "z": -1,
      "name": "Cloth_Roof_Hide_Vertical",
      "rotation": 3
    },
    {
      "x": -10,
      "y": 14,
      "z": -1,
      "name": "Cloth_Roof_Hide_Flap",
      "rotation": 3
    },
    {
      "x": -10,
      "y": 15,
      "z": -1,
      "name": "Cloth_Roof_Hide_Vertical",
      "rotation": 3
    },
    {
      "x": -10,
      "y": 16,
      "z": -1,
      "name": "Cloth_Roof_Hide_Vertical",
      "rotation": 3
    },
    {
      "x": -10,
      "y": 17,
      "z": -1,
      "name": "Cloth_Roof_Hide_Vertical",
      "rotation": 3
    },
    {
      "x": -10,
      "y": 13,
      "z": 0,
      "name": "Cloth_Roof_Hide_Flap",
      "rotation": 3
    },
    {
      "x": -10,
      "y": 14,
      "z": 0,
      "name": "Cloth_Roof_Hide_Vertical",
      "rotation": 3
    },
    {
      "x": -10,
      "y": 15,
      "z": 0,
      "name": "Cloth_Roof_Leather_Vertical",
      "rotation": 3
    },
    {
      "x": -10,
      "y": 16,
      "z": 0,
      "name": "Cloth_Roof_Leather_Vertical",
      "rotation": 3
    },
    {
      "x": -10,
      "y": 17,
      "z": 0,
      "name": "Cloth_Roof_Hide_Vertical",
      "rotation": 3
    },
    {
      "x": -10,
      "y": 15,
      "z": 1,
      "name": "Cloth_Roof_Leather_Vertical",
      "rotation": 3
    },
    {
      "x": -10,
      "y": 16,
      "z": 1,
      "name": "Cloth_Roof_Leather_Vertical",
      "rotation": 3
    },
    {
      "x": -10,
      "y": 17,
      "z": 1,
      "name": "Cloth_Roof_Hide_Vertical",
      "rotation": 3
    },
    {
      "x": -10,
      "y": 18,
      "z": 1,
      "name": "Cloth_Roof_Hide_Vertical",
      "rotation": 3
    },
    {
      "x": -10,
      "y": 16,
      "z": 2,
      "name": "Cloth_Roof_Hide_Flap",
      "rotation": 3
    },
    {
      "x": -10,
      "y": 17,
      "z": 2,
      "name": "Cloth_Roof_Hide_Vertical",
      "rotation": 3
    },
    {
      "x": -10,
      "y": 18,
      "z": 2,
      "name": "Cloth_Roof_Hide_Vertical",
      "rotation": 3
    },
    {
      "x": -10,
      "y": 19,
      "z": 2,
      "name": "Cloth_Roof_Hide_Vertical",
      "rotation": 3
    },
    {
      "x": -10,
      "y": 9,
      "z": 3,
      "name": "Wood_Deadwood_Planks",
      "rotation": 4
    },
    {
      "x": -10,
      "y": 10,
      "z": 3,
      "name": "Wood_Deadwood_Planks",
      "rotation": 4
    },
    {
      "x": -10,
      "y": 18,
      "z": 3,
      "name": "Cloth_Roof_Hide_Flap",
      "rotation": 3
    },
    {
      "x": -10,
      "y": 19,
      "z": 3,
      "name": "Cloth_Roof_Hide_Vertical",
      "rotation": 3
    },
    {
      "x": -10,
      "y": 20,
      "z": 3,
      "name": "Cloth_Roof_Hide_Vertical",
      "rotation": 3
    },
    {
      "x": -10,
      "y": 21,
      "z": 3,
      "name": "Cloth_Roof_Hide_Vertical",
      "rotation": 3
    },
    {
      "x": -10,
      "y": 9,
      "z": 4,
      "name": "Wood_Deadwood_Planks",
      "rotation": 4
    },
    {
      "x": -10,
      "y": 10,
      "z": 4,
      "name": "Wood_Darkwood_Planks",
      "rotation": 4
    },
    {
      "x": -10,
      "y": 11,
      "z": 4,
      "name": "Plant_Seaweed_Winter_Short",
      "support": 15
    },
    {
      "x": -10,
      "y": 10,
      "z": 5,
      "name": "Wood_Darkwood_Planks",
      "rotation": 4
    },
    {
      "x": -10,
      "y": 11,
      "z": 5,
      "name": "Wood_Darkwood_Planks",
      "rotation": 4
    },
    {
      "x": -10,
      "y": 10,
      "z": 6,
      "name": "Wood_Darkwood_Planks",
      "rotation": 4
    },
    {
      "x": -10,
      "y": 11,
      "z": 6,
      "name": "Wood_Darkwood_Planks",
      "rotation": 4
    },
    {
      "x": -10,
      "y": 12,
      "z": 6,
      "name": "Wood_Darkwood_Planks",
      "rotation": 4
    },
    {
      "x": -10,
      "y": 13,
      "z": 6,
      "name": "Plant_Seaweed_Winter_Blue",
      "support": 15
    },
    {
      "x": -10,
      "y": 14,
      "z": 6,
      "name": "Plant_Seaweed_Winter_Blue",
      "filler": 1024
    },
    {
      "x": -10,
      "y": 11,
      "z": 7,
      "name": "Wood_Oak_Trunk",
      "support": 15,
      "rotation": 9
    },
    {
      "x": -10,
      "y": 12,
      "z": 7,
      "name": "Wood_Darkwood_Planks",
      "rotation": 4
    },
    {
      "x": -10,
      "y": 13,
      "z": 7,
      "name": "Wood_Darkwood_Planks",
      "rotation": 4
    },
    {
      "x": -10,
      "y": 7,
      "z": 8,
      "name": "Wood_Deadwood_Planks",
      "rotation": 4
    },
    {
      "x": -10,
      "y": 8,
      "z": 8,
      "name": "Wood_Darkwood_Planks",
      "rotation": 4
    },
    {
      "x": -10,
      "y": 12,
      "z": 8,
      "name": "Wood_Darkwood_Planks",
      "rotation": 4
    },
    {
      "x": -10,
      "y": 13,
      "z": 8,
      "name": "Wood_Darkwood_Planks",
      "rotation": 4
    },
    {
      "x": -10,
      "y": 14,
      "z": 8,
      "name": "Wood_Darkwood_Planks",
      "rotation": 4
    },
    {
      "x": -10,
      "y": 15,
      "z": 8,
      "name": "Wood_Deadwood_Planks",
      "rotation": 4
    },
    {
      "x": -10,
      "y": 7,
      "z": 9,
      "name": "Wood_Deadwood_Planks",
      "rotation": 4
    },
    {
      "x": -10,
      "y": 8,
      "z": 9,
      "name": "Wood_Darkwood_Planks",
      "rotation": 4
    },
    {
      "x": -10,
      "y": 9,
      "z": 9,
      "name": "Wood_Oak_Trunk",
      "support": 15,
      "rotation": 9
    },
    {
      "x": -10,
      "y": 13,
      "z": 9,
      "name": "Wood_Redwood_Planks",
      "rotation": 4
    },
    {
      "x": -10,
      "y": 14,
      "z": 9,
      "name": "Wood_Deadwood_Planks",
      "rotation": 4
    },
    {
      "x": -10,
      "y": 15,
      "z": 9,
      "name": "Wood_Deadwood_Planks",
      "rotation": 4
    },
    {
      "x": -10,
      "y": 8,
      "z": 10,
      "name": "Wood_Darkwood_Planks",
      "rotation": 4
    },
    {
      "x": -10,
      "y": 9,
      "z": 10,
      "name": "Wood_Darkwood_Planks",
      "rotation": 4
    },
    {
      "x": -10,
      "y": 10,
      "z": 10,
      "name": "Wood_Darkwood_Planks",
      "rotation": 4
    },
    {
      "x": -10,
      "y": 11,
      "z": 10,
      "name": "Furniture_Ancient_Barrel"
    },
    {
      "x": -10,
      "y": 12,
      "z": 10,
      "name": "Wood_Redwood_Planks",
      "rotation": 4
    },
    {
      "x": -10,
      "y": 14,
      "z": 10,
      "name": "Wood_Redwood_Planks",
      "rotation": 4
    },
    {
      "x": -10,
      "y": 9,
      "z": 11,
      "name": "Wood_Deadwood_Planks",
      "rotation": 4
    },
    {
      "x": -10,
      "y": 10,
      "z": 11,
      "name": "Wood_Deadwood_Planks",
      "rotation": 4
    },
    {
      "x": -10,
      "y": 11,
      "z": 11,
      "name": "Wood_Deadwood_Planks"
    },
    {
      "x": -9,
      "y": 15,
      "z": -4,
      "name": "Wood_Darkwood_Stairs",
      "rotation": 2
    },
    {
      "x": -9,
      "y": 15,
      "z": -3,
      "name": "Wood_Darkwood_Stairs",
      "rotation": 10
    },
    {
      "x": -9,
      "y": 16,
      "z": -3,
      "name": "Wood_Darkwood_Stairs",
      "rotation": 2
    },
    {
      "x": -9,
      "y": 16,
      "z": -2,
      "name": "Wood_Darkwood_Stairs",
      "rotation": 10
    },
    {
      "x": -9,
      "y": 17,
      "z": -2,
      "name": "Wood_Darkwood_Stairs",
      "rotation": 2
    },
    {
      "x": -9,
      "y": 19,
      "z": -2,
      "name": "Wood_Darkwood_Stairs",
      "rotation": 8
    },
    {
      "x": -9,
      "y": 20,
      "z": -2,
      "name": "Wood_Oak_Trunk",
      "support": 15
    },
    {
      "x": -9,
      "y": 21,
      "z": -2,
      "name": "Plant_Coral_Bush_Blue"
    },
    {
      "x": -9,
      "y": 17,
      "z": -1,
      "name": "Wood_Darkwood_Stairs",
      "rotation": 10
    },
    {
      "x": -9,
      "y": 18,
      "z": -1,
      "name": "Wood_Darkwood_Stairs",
      "rotation": 2
    },
    {
      "x": -9,
      "y": 19,
      "z": -1,
      "name": "Wood_Oak_Trunk",
      "support": 15,
      "rotation": 4
    },
    {
      "x": -9,
      "y": 20,
      "z": -1,
      "name": "Wood_Darkwood_Stairs"
    },
    {
      "x": -9,
      "y": 15,
      "z": 0,
      "name": "Deco_Lantern_Ceiling"
    },
    {
      "x": -9,
      "y": 16,
      "z": 0,
      "name": "Deco_Iron_Chain_Small"
    },
    {
      "x": -9,
      "y": 17,
      "z": 0,
      "name": "Wood_Darkwood_Stairs",
      "rotation": 8
    },
    {
      "x": -9,
      "y": 18,
      "z": 0,
      "name": "Wood_Oak_Trunk",
      "support": 15,
      "rotation": 4
    },
    {
      "x": -9,
      "y": 19,
      "z": 0,
      "name": "Wood_Darkwood_Stairs"
    },
    {
      "x": -9,
      "y": 16,
      "z": 1,
      "name": "Wood_Darkwood_Stairs",
      "rotation": 8
    },
    {
      "x": -9,
      "y": 17,
      "z": 1,
      "name": "Wood_Oak_Trunk",
      "support": 15,
      "rotation": 4
    },
    {
      "x": -9,
      "y": 18,
      "z": 1,
      "name": "Wood_Darkwood_Stairs"
    },
    {
      "x": -9,
      "y": 19,
      "z": 1,
      "name": "Wood_Darkwood_Stairs",
      "rotation": 10
    },
    {
      "x": -9,
      "y": 20,
      "z": 1,
      "name": "Wood_Darkwood_Stairs",
      "rotation": 2
    },
    {
      "x": -9,
      "y": 9,
      "z": 2,
      "name": "Wood_Deadwood_Planks",
      "rotation": 4
    },
    {
      "x": -9,
      "y": 10,
      "z": 2,
      "name": "Deco_Rope"
    },
    {
      "x": -9,
      "y": 11,
      "z": 2,
      "name": "Deco_Rope"
    },
    {
      "x": -9,
      "y": 12,
      "z": 2,
      "name": "Deco_Rope"
    },
    {
      "x": -9,
      "y": 13,
      "z": 2,
      "name": "Deco_Rope"
    },
    {
      "x": -9,
      "y": 14,
      "z": 2,
      "name": "Deco_Rope"
    },
    {
      "x": -9,
      "y": 15,
      "z": 2,
      "name": "Wood_Oak_Trunk",
      "support": 15
    },
    {
      "x": -9,
      "y": 16,
      "z": 2,
      "name": "Wood_Oak_Trunk",
      "support": 15,
      "rotation": 4
    },
    {
      "x": -9,
      "y": 17,
      "z": 2,
      "name": "Wood_Darkwood_Stairs"
    },
    {
      "x": -9,
      "y": 20,
      "z": 2,
      "name": "Wood_Darkwood_Stairs",
      "rotation": 10
    },
    {
      "x": -9,
      "y": 21,
      "z": 2,
      "name": "Wood_Darkwood_Stairs",
      "rotation": 2
    },
    {
      "x": -9,
      "y": 9,
      "z": 3,
      "name": "Wood_Deadwood_Planks",
      "rotation": 4
    },
    {
      "x": -9,
      "y": 10,
      "z": 3,
      "name": "Wood_Deadwood_Planks",
      "rotation": 4
    },
    {
      "x": -9,
      "y": 14,
      "z": 3,
      "name": "Wood_Darkwood_Stairs",
      "rotation": 8
    },
    {
      "x": -9,
      "y": 15,
      "z": 3,
      "name": "Wood_Oak_Trunk",
      "support": 15,
      "rotation": 4
    },
    {
      "x": -9,
      "y": 16,
      "z": 3,
      "name": "Wood_Oak_Trunk",
      "support": 15,
      "rotation": 4
    },
    {
      "x": -9,
      "y": 21,
      "z": 3,
      "name": "Wood_Darkwood_Stairs",
      "rotation": 10
    },
    {
      "x": -9,
      "y": 22,
      "z": 3,
      "name": "Wood_Darkwood_Stairs",
      "rotation": 2
    },
    {
      "x": -9,
      "y": 8,
      "z": 4,
      "name": "Wood_Redwood_Planks",
      "rotation": 4
    },
    {
      "x": -9,
      "y": 9,
      "z": 4,
      "name": "Wood_Deadwood_Planks",
      "rotation": 4
    },
    {
      "x": -9,
      "y": 13,
      "z": 4,
      "name": "Wood_Darkwood_Stairs",
      "rotation": 8
    },
    {
      "x": -9,
      "y": 14,
      "z": 4,
      "name": "Wood_Oak_Trunk",
      "support": 15,
      "rotation": 4
    },
    {
      "x": -9,
      "y": 15,
      "z": 4,
      "name": "Wood_Darkwood_Stairs"
    },
    {
      "x": -9,
      "y": 16,
      "z": 4,
      "name": "Deco_Rope",
      "rotation": 14
    },
    {
      "x": -9,
      "y": 10,
      "z": 5,
      "name": "Wood_Darkwood_Planks"
    },
    {
      "x": -9,
      "y": 12,
      "z": 5,
      "name": "Wood_Darkwood_Stairs",
      "rotation": 8
    },
    {
      "x": -9,
      "y": 13,
      "z": 5,
      "name": "Wood_Oak_Trunk",
      "support": 15,
      "rotation": 4
    },
    {
      "x": -9,
      "y": 14,
      "z": 5,
      "name": "Wood_Darkwood_Stairs"
    },
    {
      "x": -9,
      "y": 16,
      "z": 5,
      "name": "Deco_Rope",
      "support": 3,
      "rotation": 12
    },
    {
      "x": -9,
      "y": 10,
      "z": 6,
      "name": "Wood_Oak_Trunk",
      "support": 15,
      "rotation": 8
    },
    {
      "x": -9,
      "y": 11,
      "z": 6,
      "name": "Wood_Darkwood_Planks"
    },
    {
      "x": -9,
      "y": 12,
      "z": 6,
      "name": "Wood_Oak_Trunk",
      "support": 15,
      "rotation": 4
    },
    {
      "x": -9,
      "y": 13,
      "z": 6,
      "name": "Wood_Darkwood_Stairs"
    },
    {
      "x": -9,
      "y": 16,
      "z": 6,
      "name": "Deco_Rope",
      "support": 2,
      "rotation": 12
    },
    {
      "x": -9,
      "y": 7,
      "z": 7,
      "name": "Wood_Deadwood_Planks",
      "rotation": 4
    },
    {
      "x": -9,
      "y": 11,
      "z": 7,
      "name": "Wood_Oak_Trunk",
      "support": 15,
      "rotation": 4
    },
    {
      "x": -9,
      "y": 12,
      "z": 7,
      "name": "Wood_Darkwood_Planks"
    },
    {
      "x": -9,
      "y": 16,
      "z": 7,
      "name": "Deco_Rope",
      "support": 1,
      "rotation": 12
    },
    {
      "x": -9,
      "y": 7,
      "z": 8,
      "name": "Wood_Darkwood_Planks",
      "rotation": 4
    },
    {
      "x": -9,
      "y": 8,
      "z": 8,
      "name": "Wood_Darkwood_Planks",
      "rotation": 4
    },
    {
      "x": -9,
      "y": 9,
      "z": 8,
      "name": "Soil_Pebbles_Frozen",
      "support": 15
    },
    {
      "x": -9,
      "y": 10,
      "z": 8,
      "name": "Wood_Oak_Trunk",
      "support": 15,
      "rotation": 4
    },
    {
      "x": -9,
      "y": 11,
      "z": 8,
      "name": "Furniture_Ancient_Barrel"
    },
    {
      "x": -9,
      "y": 12,
      "z": 8,
      "name": "Wood_Oak_Trunk",
      "support": 15,
      "rotation": 8
    },
    {
      "x": -9,
      "y": 13,
      "z": 8,
      "name": "Wood_Darkwood_Planks"
    },
    {
      "x": -9,
      "y": 15,
      "z": 8,
      "name": "Wood_Deadwood_Planks",
      "rotation": 4
    },
    {
      "x": -9,
      "y": 16,
      "z": 8,
      "name": "Deco_Rope",
      "rotation": 12
    },
    {
      "x": -9,
      "y": 8,
      "z": 9,
      "name": "Wood_Darkwood_Planks",
      "rotation": 4
    },
    {
      "x": -9,
      "y": 9,
      "z": 9,
      "name": "Wood_Oak_Trunk",
      "support": 15,
      "rotation": 9
    },
    {
      "x": -9,
      "y": 13,
      "z": 9,
      "name": "Wood_Oak_Trunk",
      "support": 15,
      "rotation": 8
    },
    {
      "x": -9,
      "y": 14,
      "z": 9,
      "name": "Wood_Deadwood_Planks",
      "rotation": 4
    },
    {
      "x": -9,
      "y": 15,
      "z": 9,
      "name": "Wood_Deadwood_Planks",
      "rotation": 4
    },
    {
      "x": -9,
      "y": 16,
      "z": 9,
      "name": "Wood_Deadwood_Planks",
      "rotation": 4
    },
    {
      "x": -9,
      "y": 7,
      "z": 10,
      "name": "Wood_Deadwood_Planks",
      "rotation": 4
    },
    {
      "x": -9,
      "y": 8,
      "z": 10,
      "name": "Wood_Darkwood_Planks",
      "rotation": 4
    },
    {
      "x": -9,
      "y": 9,
      "z": 10,
      "name": "Wood_Oak_Trunk",
      "support": 15,
      "rotation": 8
    },
    {
      "x": -9,
      "y": 10,
      "z": 10,
      "name": "Wood_Oak_Trunk",
      "support": 15,
      "rotation": 8
    },
    {
      "x": -9,
      "y": 12,
      "z": 10,
      "name": "Wood_Redwood_Planks",
      "rotation": 4
    },
    {
      "x": -9,
      "y": 13,
      "z": 10,
      "name": "Wood_Redwood_Planks",
      "rotation": 4
    },
    {
      "x": -9,
      "y": 14,
      "z": 10,
      "name": "Wood_Redwood_Planks",
      "rotation": 4
    },
    {
      "x": -9,
      "y": 8,
      "z": 11,
      "name": "Wood_Deadwood_Planks",
      "rotation": 4
    },
    {
      "x": -9,
      "y": 9,
      "z": 11,
      "name": "Wood_Deadwood_Planks",
      "rotation": 4
    },
    {
      "x": -9,
      "y": 10,
      "z": 11,
      "name": "Wood_Deadwood_Planks"
    },
    {
      "x": -9,
      "y": 11,
      "z": 11,
      "name": "Wood_Deadwood_Planks",
      "rotation": 4
    },
    {
      "x": -9,
      "y": 12,
      "z": 11,
      "name": "Wood_Deadwood_Planks"
    },
    {
      "x": -9,
      "y": 13,
      "z": 11,
      "name": "Wood_Redwood_Planks",
      "rotation": 4
    },
    {
      "x": -8,
      "y": 19,
      "z": -1,
      "name": "Deco_Rope",
      "rotation": 15
    },
    {
      "x": -8,
      "y": 8,
      "z": 2,
      "name": "Deco_Rope"
    },
    {
      "x": -8,
      "y": 9,
      "z": 2,
      "name": "Wood_Deadwood_Planks",
      "rotation": 4
    },
    {
      "x": -8,
      "y": 8,
      "z": 3,
      "name": "Wood_Deadwood_Planks",
      "rotation": 4
    },
    {
      "x": -8,
      "y": 9,
      "z": 3,
      "name": "Wood_Deadwood_Planks",
      "rotation": 4
    },
    {
      "x": -8,
      "y": 8,
      "z": 4,
      "name": "Wood_Oak_Trunk",
      "support": 15,
      "rotation": 9
    },
    {
      "x": -8,
      "y": 9,
      "z": 4,
      "name": "Wood_Deadwood_Planks",
      "rotation": 4
    },
    {
      "x": -8,
      "y": 7,
      "z": 5,
      "name": "Wood_Redwood_Planks",
      "rotation": 4
    },
    {
      "x": -8,
      "y": 8,
      "z": 5,
      "name": "Wood_Redwood_Planks",
      "rotation": 4
    },
    {
      "x": -8,
      "y": 9,
      "z": 5,
      "name": "Wood_Darkwood_Planks",
      "rotation": 4
    },
    {
      "x": -8,
      "y": 7,
      "z": 6,
      "name": "Wood_Deadwood_Planks",
      "rotation": 4
    },
    {
      "x": -8,
      "y": 10,
      "z": 6,
      "name": "Wood_Darkwood_Planks",
      "rotation": 4
    },
    {
      "x": -8,
      "y": 7,
      "z": 7,
      "name": "Wood_Deadwood_Planks",
      "rotation": 4
    },
    {
      "x": -8,
      "y": 11,
      "z": 7,
      "name": "Wood_Oak_Trunk",
      "support": 15,
      "rotation": 5
    },
    {
      "x": -8,
      "y": 12,
      "z": 7,
      "name": "Plant_Seaweed_Winter_Short",
      "support": 15
    },
    {
      "x": -8,
      "y": 7,
      "z": 8,
      "name": "Wood_Darkwood_Planks",
      "rotation": 4
    },
    {
      "x": -8,
      "y": 8,
      "z": 8,
      "name": "Wood_Darkwood_Planks",
      "rotation": 4
    },
    {
      "x": -8,
      "y": 9,
      "z": 8,
      "name": "Soil_Pebbles_Frozen",
      "support": 15
    },
    {
      "x": -8,
      "y": 10,
      "z": 8,
      "name": "Plant_Seaweed_Winter_Blue",
      "support": 15
    },
    {
      "x": -8,
      "y": 11,
      "z": 8,
      "name": "Plant_Seaweed_Winter_Blue",
      "filler": 1024
    },
    {
      "x": -8,
      "y": 12,
      "z": 8,
      "name": "Wood_Darkwood_Planks",
      "rotation": 4
    },
    {
      "x": -8,
      "y": 8,
      "z": 9,
      "name": "Wood_Darkwood_Planks",
      "rotation": 4
    },
    {
      "x": -8,
      "y": 9,
      "z": 9,
      "name": "Wood_Oak_Trunk",
      "support": 15,
      "rotation": 9
    },
    {
      "x": -8,
      "y": 10,
      "z": 9,
      "name": "Soil_Pebbles_Frozen",
      "support": 15
    },
    {
      "x": -8,
      "y": 13,
      "z": 9,
      "name": "Wood_Darkwood_Planks",
      "rotation": 4
    },
    {
      "x": -8,
      "y": 14,
      "z": 9,
      "name": "Wood_Deadwood_Planks",
      "rotation": 4
    },
    {
      "x": -8,
      "y": 15,
      "z": 9,
      "name": "Wood_Deadwood_Planks",
      "rotation": 4
    },
    {
      "x": -8,
      "y": 16,
      "z": 9,
      "name": "Wood_Deadwood_Planks",
      "rotation": 4
    },
    {
      "x": -8,
      "y": 7,
      "z": 10,
      "name": "Wood_Deadwood_Planks",
      "rotation": 4
    },
    {
      "x": -8,
      "y": 9,
      "z": 10,
      "name": "Wood_Darkwood_Planks",
      "rotation": 4
    },
    {
      "x": -8,
      "y": 10,
      "z": 10,
      "name": "Wood_Darkwood_Planks",
      "rotation": 4
    },
    {
      "x": -8,
      "y": 13,
      "z": 10,
      "name": "Wood_Redwood_Planks",
      "rotation": 4
    },
    {
      "x": -8,
      "y": 14,
      "z": 10,
      "name": "Wood_Oak_Trunk",
      "support": 15,
      "rotation": 9
    },
    {
      "x": -8,
      "y": 15,
      "z": 10,
      "name": "Wood_Deadwood_Planks",
      "rotation": 4
    },
    {
      "x": -8,
      "y": 7,
      "z": 11,
      "name": "Wood_Darkwood_Planks"
    },
    {
      "x": -8,
      "y": 8,
      "z": 11,
      "name": "Wood_Deadwood_Planks",
      "rotation": 4
    },
    {
      "x": -8,
      "y": 9,
      "z": 11,
      "name": "Wood_Deadwood_Planks"
    },
    {
      "x": -8,
      "y": 10,
      "z": 11,
      "name": "Wood_Deadwood_Planks"
    },
    {
      "x": -8,
      "y": 11,
      "z": 11,
      "name": "Wood_Deadwood_Planks",
      "rotation": 4
    },
    {
      "x": -8,
      "y": 12,
      "z": 11,
      "name": "Wood_Deadwood_Planks",
      "rotation": 4
    },
    {
      "x": -8,
      "y": 13,
      "z": 11,
      "name": "Wood_Redwood_Planks",
      "rotation": 4
    },
    {
      "x": -7,
      "y": 19,
      "z": -1,
      "name": "Deco_Rope",
      "support": 1,
      "rotation": 15
    },
    {
      "x": -7,
      "y": 8,
      "z": 3,
      "name": "Wood_Deadwood_Planks",
      "rotation": 4
    },
    {
      "x": -7,
      "y": 9,
      "z": 3,
      "name": "Plant_Seaweed_Winter_Blue",
      "support": 15
    },
    {
      "x": -7,
      "y": 10,
      "z": 3,
      "name": "Plant_Seaweed_Winter_Blue",
      "filler": 1024
    },
    {
      "x": -7,
      "y": 7,
      "z": 4,
      "name": "Wood_Redwood_Planks",
      "rotation": 4
    },
    {
      "x": -7,
      "y": 8,
      "z": 4,
      "name": "Wood_Oak_Trunk",
      "support": 15,
      "rotation": 5
    },
    {
      "x": -7,
      "y": 6,
      "z": 5,
      "name": "Wood_Deadwood_Planks",
      "rotation": 4
    },
    {
      "x": -7,
      "y": 9,
      "z": 5,
      "name": "Wood_Darkwood_Planks",
      "rotation": 4
    },
    {
      "x": -7,
      "y": 10,
      "z": 5,
      "name": "Plant_Seaweed_Winter_Short",
      "support": 15
    },
    {
      "x": -7,
      "y": 6,
      "z": 6,
      "name": "Wood_Redwood_Planks",
      "rotation": 4
    },
    {
      "x": -7,
      "y": 9,
      "z": 6,
      "name": "Wood_Darkwood_Planks"
    },
    {
      "x": -7,
      "y": 10,
      "z": 6,
      "name": "Wood_Darkwood_Planks",
      "rotation": 4
    },
    {
      "x": -7,
      "y": 6,
      "z": 7,
      "name": "Wood_Redwood_Planks",
      "rotation": 4
    },
    {
      "x": -7,
      "y": 7,
      "z": 7,
      "name": "Wood_Darkwood_Planks",
      "rotation": 4
    },
    {
      "x": -7,
      "y": 5,
      "z": 8,
      "name": "Plant_Barnacles",
      "rotation": 8
    },
    {
      "x": -7,
      "y": 6,
      "z": 8,
      "name": "Wood_Redwood_Planks",
      "rotation": 4
    },
    {
      "x": -7,
      "y": 7,
      "z": 8,
      "name": "Wood_Darkwood_Planks",
      "rotation": 4
    },
    {
      "x": -7,
      "y": 8,
      "z": 8,
      "name": "Wood_Darkwood_Planks",
      "rotation": 4
    },
    {
      "x": -7,
      "y": 9,
      "z": 8,
      "name": "Soil_Pebbles_Frozen",
      "support": 15
    },
    {
      "x": -7,
      "y": 10,
      "z": 8,
      "name": "Plant_Crop_Mana3"
    },
    {
      "x": -7,
      "y": 11,
      "z": 8,
      "name": "Plant_Crop_Mana3",
      "filler": 1024
    },
    {
      "x": -7,
      "y": 12,
      "z": 8,
      "name": "Wood_Deadwood_Planks"
    },
    {
      "x": -7,
      "y": 5,
      "z": 9,
      "name": "Plant_Barnacles",
      "rotation": 8
    },
    {
      "x": -7,
      "y": 6,
      "z": 9,
      "name": "Wood_Deadwood_Planks",
      "rotation": 4
    },
    {
      "x": -7,
      "y": 7,
      "z": 9,
      "name": "Wood_Darkwood_Planks"
    },
    {
      "x": -7,
      "y": 8,
      "z": 9,
      "name": "Wood_Darkwood_Planks",
      "rotation": 4
    },
    {
      "x": -7,
      "y": 9,
      "z": 9,
      "name": "Wood_Oak_Trunk",
      "support": 15,
      "rotation": 9
    },
    {
      "x": -7,
      "y": 10,
      "z": 9,
      "name": "Soil_Pebbles_Frozen",
      "support": 15
    },
    {
      "x": -7,
      "y": 13,
      "z": 9,
      "name": "Wood_Darkwood_Planks",
      "rotation": 4
    },
    {
      "x": -7,
      "y": 6,
      "z": 10,
      "name": "Wood_Deadwood_Planks",
      "rotation": 4
    },
    {
      "x": -7,
      "y": 7,
      "z": 10,
      "name": "Wood_Deadwood_Planks",
      "rotation": 4
    },
    {
      "x": -7,
      "y": 8,
      "z": 10,
      "name": "Wood_Darkwood_Planks"
    },
    {
      "x": -7,
      "y": 9,
      "z": 10,
      "name": "Wood_Darkwood_Planks",
      "rotation": 4
    },
    {
      "x": -7,
      "y": 10,
      "z": 10,
      "name": "Wood_Darkwood_Planks",
      "rotation": 4
    },
    {
      "x": -7,
      "y": 14,
      "z": 10,
      "name": "Wood_Oak_Trunk",
      "support": 15,
      "rotation": 5
    },
    {
      "x": -7,
      "y": 15,
      "z": 10,
      "name": "Wood_Deadwood_Planks",
      "rotation": 4
    },
    {
      "x": -7,
      "y": 6,
      "z": 11,
      "name": "Wood_Deadwood_Planks",
      "rotation": 4
    },
    {
      "x": -7,
      "y": 7,
      "z": 11,
      "name": "Wood_Darkwood_Planks",
      "rotation": 4
    },
    {
      "x": -7,
      "y": 8,
      "z": 11,
      "name": "Wood_Deadwood_Planks",
      "rotation": 4
    },
    {
      "x": -7,
      "y": 9,
      "z": 11,
      "name": "Wood_Darkwood_Planks"
    },
    {
      "x": -7,
      "y": 10,
      "z": 11,
      "name": "Wood_Darkwood_Planks",
      "rotation": 4
    },
    {
      "x": -7,
      "y": 11,
      "z": 11,
      "name": "Wood_Darkwood_Planks",
      "rotation": 4
    },
    {
      "x": -7,
      "y": 12,
      "z": 11,
      "name": "Wood_Deadwood_Planks",
      "rotation": 4
    },
    {
      "x": -7,
      "y": 14,
      "z": 11,
      "name": "Wood_Redwood_Planks",
      "rotation": 4
    },
    {
      "x": -7,
      "y": 7,
      "z": 12,
      "name": "Wood_Deadwood_Planks",
      "rotation": 4
    },
    {
      "x": -7,
      "y": 8,
      "z": 12,
      "name": "Wood_Deadwood_Planks",
      "rotation": 4
    },
    {
      "x": -7,
      "y": 9,
      "z": 12,
      "name": "Wood_Deadwood_Planks",
      "rotation": 4
    },
    {
      "x": -7,
      "y": 10,
      "z": 12,
      "name": "Wood_Deadwood_Planks"
    },
    {
      "x": -7,
      "y": 11,
      "z": 12,
      "name": "Wood_Redwood_Planks",
      "rotation": 4
    },
    {
      "x": -7,
      "y": 12,
      "z": 12,
      "name": "Wood_Redwood_Planks",
      "rotation": 4
    },
    {
      "x": -7,
      "y": 13,
      "z": 12,
      "name": "Wood_Deadwood_Planks",
      "rotation": 4
    },
    {
      "x": -6,
      "y": 19,
      "z": -1,
      "name": "Deco_Rope",
      "support": 2,
      "rotation": 15
    },
    {
      "x": -6,
      "y": 8,
      "z": 3,
      "name": "Wood_Deadwood_Planks",
      "rotation": 4
    },
    {
      "x": -6,
      "y": 7,
      "z": 4,
      "name": "Wood_Redwood_Planks",
      "rotation": 4
    },
    {
      "x": -6,
      "y": 8,
      "z": 4,
      "name": "Wood_Oak_Trunk",
      "support": 15,
      "rotation": 5
    },
    {
      "x": -6,
      "y": 6,
      "z": 5,
      "name": "Wood_Deadwood_Planks",
      "rotation": 4
    },
    {
      "x": -6,
      "y": 9,
      "z": 5,
      "name": "Wood_Darkwood_Planks",
      "rotation": 4
    },
    {
      "x": -6,
      "y": 5,
      "z": 6,
      "name": "Wood_Redwood_Planks",
      "rotation": 4
    },
    {
      "x": -6,
      "y": 6,
      "z": 6,
      "name": "Wood_Oak_Trunk",
      "support": 15,
      "rotation": 5
    },
    {
      "x": -6,
      "y": 9,
      "z": 6,
      "name": "Wood_Darkwood_Planks"
    },
    {
      "x": -6,
      "y": 5,
      "z": 7,
      "name": "Wood_Redwood_Planks",
      "rotation": 4
    },
    {
      "x": -6,
      "y": 6,
      "z": 7,
      "name": "Wood_Oak_Trunk",
      "support": 15,
      "rotation": 9
    },
    {
      "x": -6,
      "y": 7,
      "z": 7,
      "name": "Wood_Darkwood_Planks",
      "rotation": 4
    },
    {
      "x": -6,
      "y": 9,
      "z": 7,
      "name": "Wood_Darkwood_Stairs",
      "rotation": 2
    },
    {
      "x": -6,
      "y": 6,
      "z": 8,
      "name": "Wood_Redwood_Planks",
      "rotation": 4
    },
    {
      "x": -6,
      "y": 7,
      "z": 8,
      "name": "Wood_Darkwood_Planks",
      "rotation": 4
    },
    {
      "x": -6,
      "y": 8,
      "z": 8,
      "name": "Wood_Darkwood_Planks",
      "rotation": 4
    },
    {
      "x": -6,
      "y": 9,
      "z": 8,
      "name": "Wood_Darkwood_Stairs",
      "rotation": 2
    },
    {
      "x": -6,
      "y": 5,
      "z": 9,
      "name": "Plant_Barnacles",
      "rotation": 8
    },
    {
      "x": -6,
      "y": 6,
      "z": 9,
      "name": "Wood_Deadwood_Planks",
      "rotation": 4
    },
    {
      "x": -6,
      "y": 7,
      "z": 9,
      "name": "Soil_Pebbles_Frozen",
      "support": 15
    },
    {
      "x": -6,
      "y": 9,
      "z": 9,
      "name": "Wood_Oak_Trunk",
      "support": 15,
      "rotation": 5
    },
    {
      "x": -6,
      "y": 13,
      "z": 9,
      "name": "Wood_Deadwood_Planks"
    },
    {
      "x": -6,
      "y": 6,
      "z": 10,
      "name": "Wood_Deadwood_Planks",
      "rotation": 4
    },
    {
      "x": -6,
      "y": 7,
      "z": 10,
      "name": "Wood_Deadwood_Planks",
      "rotation": 4
    },
    {
      "x": -6,
      "y": 8,
      "z": 10,
      "name": "Plant_Seaweed_Winter_Short",
      "support": 15
    },
    {
      "x": -6,
      "y": 10,
      "z": 10,
      "name": "Wood_Darkwood_Planks",
      "rotation": 4
    },
    {
      "x": -6,
      "y": 14,
      "z": 10,
      "name": "Wood_Oak_Trunk",
      "support": 15,
      "rotation": 5
    },
    {
      "x": -6,
      "y": 15,
      "z": 10,
      "name": "Wood_Deadwood_Planks",
      "rotation": 4
    },
    {
      "x": -6,
      "y": 6,
      "z": 11,
      "name": "Wood_Deadwood_Planks",
      "rotation": 4
    },
    {
      "x": -6,
      "y": 7,
      "z": 11,
      "name": "Wood_Darkwood_Planks",
      "rotation": 4
    },
    {
      "x": -6,
      "y": 8,
      "z": 11,
      "name": "Wood_Deadwood_Planks",
      "rotation": 4
    },
    {
      "x": -6,
      "y": 10,
      "z": 11,
      "name": "Wood_Darkwood_Planks",
      "rotation": 4
    },
    {
      "x": -6,
      "y": 11,
      "z": 11,
      "name": "Wood_Darkwood_Planks",
      "rotation": 4
    },
    {
      "x": -6,
      "y": 14,
      "z": 11,
      "name": "Wood_Redwood_Planks",
      "rotation": 4
    },
    {
      "x": -6,
      "y": 7,
      "z": 12,
      "name": "Wood_Deadwood_Planks",
      "rotation": 4
    },
    {
      "x": -6,
      "y": 8,
      "z": 12,
      "name": "Wood_Deadwood_Planks",
      "rotation": 4
    },
    {
      "x": -6,
      "y": 9,
      "z": 12,
      "name": "Wood_Deadwood_Planks",
      "rotation": 4
    },
    {
      "x": -6,
      "y": 10,
      "z": 12,
      "name": "Wood_Redwood_Planks",
      "rotation": 4
    },
    {
      "x": -6,
      "y": 11,
      "z": 12,
      "name": "Wood_Oak_Trunk",
      "support": 15,
      "rotation": 9
    },
    {
      "x": -6,
      "y": 12,
      "z": 12,
      "name": "Wood_Oak_Trunk",
      "support": 15,
      "rotation": 5
    },
    {
      "x": -6,
      "y": 11,
      "z": 13,
      "name": "Wood_Redwood_Planks",
      "rotation": 4
    },
    {
      "x": -6,
      "y": 12,
      "z": 13,
      "name": "Wood_Redwood_Planks",
      "rotation": 4
    },
    {
      "x": -5,
      "y": 19,
      "z": -1,
      "name": "Deco_Rope",
      "support": 3,
      "rotation": 15
    },
    {
      "x": -5,
      "y": 6,
      "z": 2,
      "name": "Vehicle_Wood_Boat",
      "filler": 1023,
      "rotation": 1
    },
    {
      "x": -5,
      "y": 6,
      "z": 3,
      "name": "Vehicle_Wood_Boat",
      "filler": 31,
      "rotation": 1
    },
    {
      "x": -5,
      "y": 7,
      "z": 3,
      "name": "Deco_Rope"
    },
    {
      "x": -5,
      "y": 8,
      "z": 3,
      "name": "Wood_Deadwood_Planks",
      "rotation": 4
    },
    {
      "x": -5,
      "y": 6,
      "z": 4,
      "name": "Vehicle_Wood_Boat",
      "filler": 63,
      "rotation": 1
    },
    {
      "x": -5,
      "y": 7,
      "z": 4,
      "name": "Wood_Redwood_Planks",
      "rotation": 4
    },
    {
      "x": -5,
      "y": 8,
      "z": 4,
      "name": "Wood_Oak_Trunk",
      "support": 15,
      "rotation": 5
    },
    {
      "x": -5,
      "y": 9,
      "z": 4,
      "name": "Plant_Coral_Model_Cyan"
    },
    {
      "x": -5,
      "y": 6,
      "z": 5,
      "name": "Wood_Deadwood_Planks",
      "rotation": 4
    },
    {
      "x": -5,
      "y": 9,
      "z": 5,
      "name": "Wood_Darkwood_Planks",
      "rotation": 4
    },
    {
      "x": -5,
      "y": 5,
      "z": 6,
      "name": "Wood_Redwood_Planks",
      "rotation": 4
    },
    {
      "x": -5,
      "y": 6,
      "z": 6,
      "name": "Wood_Oak_Trunk",
      "support": 15,
      "rotation": 5
    },
    {
      "x": -5,
      "y": 9,
      "z": 6,
      "name": "Wood_Darkwood_Planks"
    },
    {
      "x": -5,
      "y": 5,
      "z": 7,
      "name": "Wood_Redwood_Planks",
      "rotation": 4
    },
    {
      "x": -5,
      "y": 6,
      "z": 7,
      "name": "Wood_Oak_Trunk",
      "support": 15,
      "rotation": 9
    },
    {
      "x": -5,
      "y": 7,
      "z": 7,
      "name": "Wood_Darkwood_Planks",
      "rotation": 4
    },
    {
      "x": -5,
      "y": 9,
      "z": 7,
      "name": "Wood_Darkwood_Stairs",
      "rotation": 2
    },
    {
      "x": -5,
      "y": 5,
      "z": 8,
      "name": "Plant_Barnacles",
      "rotation": 8
    },
    {
      "x": -5,
      "y": 6,
      "z": 8,
      "name": "Wood_Redwood_Planks",
      "rotation": 4
    },
    {
      "x": -5,
      "y": 7,
      "z": 8,
      "name": "Wood_Darkwood_Planks",
      "rotation": 4
    },
    {
      "x": -5,
      "y": 8,
      "z": 8,
      "name": "Wood_Darkwood_Planks",
      "rotation": 4
    },
    {
      "x": -5,
      "y": 9,
      "z": 8,
      "name": "Wood_Darkwood_Stairs",
      "rotation": 2
    },
    {
      "x": -5,
      "y": 6,
      "z": 9,
      "name": "Wood_Deadwood_Planks",
      "rotation": 4
    },
    {
      "x": -5,
      "y": 7,
      "z": 9,
      "name": "Soil_Pebbles_Frozen",
      "support": 15
    },
    {
      "x": -5,
      "y": 8,
      "z": 9,
      "name": "Plant_Seaweed_Winter_Short",
      "support": 15
    },
    {
      "x": -5,
      "y": 9,
      "z": 9,
      "name": "Wood_Oak_Trunk",
      "support": 15,
      "rotation": 5
    },
    {
      "x": -5,
      "y": 10,
      "z": 9,
      "name": "Plant_Seaweed_Winter_Blue",
      "support": 15
    },
    {
      "x": -5,
      "y": 11,
      "z": 9,
      "name": "Plant_Seaweed_Winter_Blue",
      "filler": 1024
    },
    {
      "x": -5,
      "y": 6,
      "z": 10,
      "name": "Wood_Deadwood_Planks",
      "rotation": 4
    },
    {
      "x": -5,
      "y": 7,
      "z": 10,
      "name": "Wood_Deadwood_Planks",
      "rotation": 4
    },
    {
      "x": -5,
      "y": 10,
      "z": 10,
      "name": "Wood_Darkwood_Planks",
      "rotation": 4
    },
    {
      "x": -5,
      "y": 14,
      "z": 10,
      "name": "Wood_Oak_Trunk",
      "support": 15,
      "rotation": 5
    },
    {
      "x": -5,
      "y": 15,
      "z": 10,
      "name": "Wood_Deadwood_Planks",
      "rotation": 4
    },
    {
      "x": -5,
      "y": 6,
      "z": 11,
      "name": "Wood_Deadwood_Planks",
      "rotation": 4
    },
    {
      "x": -5,
      "y": 7,
      "z": 11,
      "name": "Wood_Darkwood_Planks",
      "rotation": 4
    },
    {
      "x": -5,
      "y": 8,
      "z": 11,
      "name": "Wood_Deadwood_Planks",
      "rotation": 4
    },
    {
      "x": -5,
      "y": 9,
      "z": 11,
      "name": "Furniture_Dungeon_Chest_Epic",
      "components": {
        "Components": {
          "PlacedByInteraction": {
            "WhoPlacedUuid": {
              "$binary": "rmwkrpH8RVykTc7XnK4YBA==",
              "$type": "04"
            }
          },
          "ItemContainerBlock": {
            "ItemContainer": {
              "Capacity": 18,
              "Items": {}
            },
            "Capacity": 18
          }
        }
      },
      "rotation": 1
    },
    {
      "x": -5,
      "y": 10,
      "z": 11,
      "name": "Wood_Darkwood_Planks",
      "rotation": 4
    },
    {
      "x": -5,
      "y": 11,
      "z": 11,
      "name": "Wood_Darkwood_Planks",
      "rotation": 4
    },
    {
      "x": -5,
      "y": 7,
      "z": 12,
      "name": "Wood_Deadwood_Planks",
      "rotation": 4
    },
    {
      "x": -5,
      "y": 8,
      "z": 12,
      "name": "Wood_Deadwood_Planks",
      "rotation": 4
    },
    {
      "x": -5,
      "y": 9,
      "z": 12,
      "name": "Wood_Deadwood_Planks",
      "rotation": 4
    },
    {
      "x": -5,
      "y": 10,
      "z": 12,
      "name": "Wood_Redwood_Planks",
      "rotation": 4
    },
    {
      "x": -5,
      "y": 11,
      "z": 12,
      "name": "Wood_Oak_Trunk",
      "support": 15,
      "rotation": 9
    },
    {
      "x": -5,
      "y": 11,
      "z": 13,
      "name": "Wood_Redwood_Planks",
      "rotation": 4
    },
    {
      "x": -5,
      "y": 12,
      "z": 13,
      "name": "Wood_Redwood_Planks",
      "rotation": 4
    },
    {
      "x": -4,
      "y": 19,
      "z": -1,
      "name": "Deco_Rope",
      "support": 4,
      "rotation": 15
    },
    {
      "x": -4,
      "y": 6,
      "z": 2,
      "name": "Vehicle_Wood_Boat",
      "filler": 992,
      "rotation": 1
    },
    {
      "x": -4,
      "y": 8,
      "z": 2,
      "name": "Plant_Barnacles",
      "rotation": 6
    },
    {
      "x": -4,
      "y": 6,
      "z": 3,
      "name": "Vehicle_Wood_Boat",
      "rotation": 1
    },
    {
      "x": -4,
      "y": 8,
      "z": 3,
      "name": "Wood_Deadwood_Planks",
      "rotation": 4
    },
    {
      "x": -4,
      "y": 6,
      "z": 4,
      "name": "Vehicle_Wood_Boat",
      "filler": 32,
      "rotation": 1
    },
    {
      "x": -4,
      "y": 8,
      "z": 4,
      "name": "Wood_Oak_Trunk",
      "support": 15,
      "rotation": 5
    },
    {
      "x": -4,
      "y": 9,
      "z": 4,
      "name": "Plant_Coral_Bush_Blue"
    },
    {
      "x": -4,
      "y": 6,
      "z": 5,
      "name": "Wood_Deadwood_Planks",
      "rotation": 4
    },
    {
      "x": -4,
      "y": 9,
      "z": 5,
      "name": "Wood_Darkwood_Planks",
      "rotation": 4
    },
    {
      "x": -4,
      "y": 5,
      "z": 6,
      "name": "Wood_Redwood_Planks",
      "rotation": 4
    },
    {
      "x": -4,
      "y": 6,
      "z": 6,
      "name": "Wood_Oak_Trunk",
      "support": 15,
      "rotation": 5
    },
    {
      "x": -4,
      "y": 9,
      "z": 6,
      "name": "Wood_Darkwood_Planks"
    },
    {
      "x": -4,
      "y": 5,
      "z": 7,
      "name": "Wood_Redwood_Planks",
      "rotation": 4
    },
    {
      "x": -4,
      "y": 6,
      "z": 7,
      "name": "Wood_Oak_Trunk",
      "support": 15,
      "rotation": 9
    },
    {
      "x": -4,
      "y": 7,
      "z": 7,
      "name": "Wood_Darkwood_Planks",
      "rotation": 4
    },
    {
      "x": -4,
      "y": 9,
      "z": 7,
      "name": "Wood_Darkwood_Stairs",
      "rotation": 2
    },
    {
      "x": -4,
      "y": 6,
      "z": 8,
      "name": "Wood_Redwood_Planks"
    },
    {
      "x": -4,
      "y": 7,
      "z": 8,
      "name": "Wood_Darkwood_Planks"
    },
    {
      "x": -4,
      "y": 8,
      "z": 8,
      "name": "Wood_Darkwood_Planks",
      "rotation": 4
    },
    {
      "x": -4,
      "y": 9,
      "z": 8,
      "name": "Wood_Darkwood_Stairs",
      "rotation": 2
    },
    {
      "x": -4,
      "y": 6,
      "z": 9,
      "name": "Wood_Deadwood_Planks",
      "rotation": 4
    },
    {
      "x": -4,
      "y": 7,
      "z": 9,
      "name": "Soil_Pebbles_Frozen",
      "support": 15
    },
    {
      "x": -4,
      "y": 9,
      "z": 9,
      "name": "Wood_Oak_Trunk",
      "support": 15,
      "rotation": 5
    },
    {
      "x": -4,
      "y": 5,
      "z": 10,
      "name": "Wood_Deadwood_Planks",
      "rotation": 4
    },
    {
      "x": -4,
      "y": 6,
      "z": 10,
      "name": "Wood_Deadwood_Planks",
      "rotation": 4
    },
    {
      "x": -4,
      "y": 7,
      "z": 10,
      "name": "Soil_Pebbles_Frozen",
      "support": 15
    },
    {
      "x": -4,
      "y": 8,
      "z": 10,
      "name": "Plant_Crop_Mana3"
    },
    {
      "x": -4,
      "y": 9,
      "z": 10,
      "name": "Plant_Crop_Mana3",
      "filler": 1024
    },
    {
      "x": -4,
      "y": 10,
      "z": 10,
      "name": "Wood_Darkwood_Planks",
      "rotation": 4
    },
    {
      "x": -4,
      "y": 14,
      "z": 10,
      "name": "Wood_Oak_Trunk",
      "support": 15,
      "rotation": 5
    },
    {
      "x": -4,
      "y": 15,
      "z": 10,
      "name": "Wood_Deadwood_Planks",
      "rotation": 4
    },
    {
      "x": -4,
      "y": 6,
      "z": 11,
      "name": "Wood_Deadwood_Planks",
      "rotation": 4
    },
    {
      "x": -4,
      "y": 7,
      "z": 11,
      "name": "Soil_Pebbles_Frozen",
      "support": 15
    },
    {
      "x": -4,
      "y": 10,
      "z": 11,
      "name": "Wood_Darkwood_Planks",
      "rotation": 4
    },
    {
      "x": -4,
      "y": 11,
      "z": 11,
      "name": "Wood_Darkwood_Planks",
      "rotation": 4
    },
    {
      "x": -4,
      "y": 7,
      "z": 12,
      "name": "Wood_Deadwood_Planks",
      "rotation": 4
    },
    {
      "x": -4,
      "y": 8,
      "z": 12,
      "name": "Wood_Deadwood_Planks",
      "rotation": 4
    },
    {
      "x": -4,
      "y": 9,
      "z": 12,
      "name": "Wood_Deadwood_Planks",
      "rotation": 4
    },
    {
      "x": -4,
      "y": 10,
      "z": 12,
      "name": "Wood_Redwood_Planks",
      "rotation": 4
    },
    {
      "x": -4,
      "y": 11,
      "z": 12,
      "name": "Wood_Oak_Trunk",
      "support": 15,
      "rotation": 9
    },
    {
      "x": -4,
      "y": 8,
      "z": 13,
      "name": "Wood_Deadwood_Planks",
      "rotation": 4
    },
    {
      "x": -4,
      "y": 11,
      "z": 13,
      "name": "Wood_Redwood_Planks",
      "rotation": 4
    },
    {
      "x": -4,
      "y": 12,
      "z": 13,
      "name": "Wood_Redwood_Planks",
      "rotation": 4
    },
    {
      "x": -3,
      "y": 19,
      "z": -1,
      "name": "Deco_Rope",
      "rotation": 15
    },
    {
      "x": -3,
      "y": 6,
      "z": 2,
      "name": "Vehicle_Wood_Boat",
      "filler": 993,
      "rotation": 1
    },
    {
      "x": -3,
      "y": 8,
      "z": 2,
      "name": "Plant_Barnacles",
      "rotation": 6
    },
    {
      "x": -3,
      "y": 6,
      "z": 3,
      "name": "Vehicle_Wood_Boat",
      "filler": 1,
      "rotation": 1
    },
    {
      "x": -3,
      "y": 8,
      "z": 3,
      "name": "Wood_Deadwood_Planks",
      "rotation": 4
    },
    {
      "x": -3,
      "y": 6,
      "z": 4,
      "name": "Vehicle_Wood_Boat",
      "filler": 33,
      "rotation": 1
    },
    {
      "x": -3,
      "y": 7,
      "z": 4,
      "name": "Wood_Redwood_Planks",
      "rotation": 4
    },
    {
      "x": -3,
      "y": 8,
      "z": 4,
      "name": "Wood_Oak_Trunk",
      "support": 15,
      "rotation": 5
    },
    {
      "x": -3,
      "y": 6,
      "z": 5,
      "name": "Wood_Deadwood_Planks",
      "rotation": 4
    },
    {
      "x": -3,
      "y": 9,
      "z": 5,
      "name": "Wood_Darkwood_Planks",
      "rotation": 4
    },
    {
      "x": -3,
      "y": 5,
      "z": 6,
      "name": "Wood_Redwood_Planks",
      "rotation": 4
    },
    {
      "x": -3,
      "y": 6,
      "z": 6,
      "name": "Wood_Oak_Trunk",
      "support": 15,
      "rotation": 5
    },
    {
      "x": -3,
      "y": 10,
      "z": 6,
      "name": "Wood_Darkwood_Planks",
      "rotation": 4
    },
    {
      "x": -3,
      "y": 11,
      "z": 6,
      "name": "Plant_Seaweed_Winter_Short",
      "support": 15
    },
    {
      "x": -3,
      "y": 5,
      "z": 7,
      "name": "Wood_Redwood_Planks",
      "rotation": 4
    },
    {
      "x": -3,
      "y": 6,
      "z": 7,
      "name": "Wood_Oak_Trunk",
      "support": 15,
      "rotation": 9
    },
    {
      "x": -3,
      "y": 7,
      "z": 7,
      "name": "Wood_Darkwood_Planks",
      "rotation": 4
    },
    {
      "x": -3,
      "y": 6,
      "z": 8,
      "name": "Wood_Redwood_Planks"
    },
    {
      "x": -3,
      "y": 7,
      "z": 8,
      "name": "Wood_Darkwood_Planks"
    },
    {
      "x": -3,
      "y": 8,
      "z": 8,
      "name": "Wood_Darkwood_Planks",
      "rotation": 4
    },
    {
      "x": -3,
      "y": 11,
      "z": 8,
      "name": "Wood_Deadwood_Planks"
    },
    {
      "x": -3,
      "y": 12,
      "z": 8,
      "name": "Wood_Darkwood_Planks",
      "rotation": 4
    },
    {
      "x": -3,
      "y": 6,
      "z": 9,
      "name": "Wood_Deadwood_Planks",
      "rotation": 4
    },
    {
      "x": -3,
      "y": 7,
      "z": 9,
      "name": "Soil_Pebbles_Frozen",
      "support": 15
    },
    {
      "x": -3,
      "y": 9,
      "z": 9,
      "name": "Wood_Oak_Trunk",
      "support": 15,
      "rotation": 5
    },
    {
      "x": -3,
      "y": 13,
      "z": 9,
      "name": "Wood_Darkwood_Planks",
      "rotation": 4
    },
    {
      "x": -3,
      "y": 14,
      "z": 9,
      "name": "Plant_Barnacles"
    },
    {
      "x": -3,
      "y": 5,
      "z": 10,
      "name": "Wood_Deadwood_Planks",
      "rotation": 4
    },
    {
      "x": -3,
      "y": 6,
      "z": 10,
      "name": "Wood_Deadwood_Planks",
      "rotation": 4
    },
    {
      "x": -3,
      "y": 7,
      "z": 10,
      "name": "Soil_Pebbles_Frozen",
      "support": 15
    },
    {
      "x": -3,
      "y": 8,
      "z": 10,
      "name": "Plant_Seaweed_Winter_Blue",
      "support": 15
    },
    {
      "x": -3,
      "y": 9,
      "z": 10,
      "name": "Plant_Seaweed_Winter_Blue",
      "filler": 1024
    },
    {
      "x": -3,
      "y": 10,
      "z": 10,
      "name": "Wood_Darkwood_Planks",
      "rotation": 4
    },
    {
      "x": -3,
      "y": 14,
      "z": 10,
      "name": "Wood_Oak_Trunk",
      "support": 15,
      "rotation": 5
    },
    {
      "x": -3,
      "y": 15,
      "z": 10,
      "name": "Wood_Deadwood_Planks",
      "rotation": 4
    },
    {
      "x": -3,
      "y": 6,
      "z": 11,
      "name": "Wood_Deadwood_Planks",
      "rotation": 4
    },
    {
      "x": -3,
      "y": 7,
      "z": 11,
      "name": "Soil_Pebbles_Frozen",
      "support": 15
    },
    {
      "x": -3,
      "y": 8,
      "z": 11,
      "name": "Plant_Crop_Mana3"
    },
    {
      "x": -3,
      "y": 9,
      "z": 11,
      "name": "Plant_Crop_Mana3",
      "filler": 1024
    },
    {
      "x": -3,
      "y": 10,
      "z": 11,
      "name": "Wood_Darkwood_Planks",
      "rotation": 4
    },
    {
      "x": -3,
      "y": 11,
      "z": 11,
      "name": "Wood_Darkwood_Planks",
      "rotation": 4
    },
    {
      "x": -3,
      "y": 12,
      "z": 11,
      "name": "Furniture_Ancient_Barrel"
    },
    {
      "x": -3,
      "y": 14,
      "z": 11,
      "name": "Wood_Redwood_Planks",
      "rotation": 4
    },
    {
      "x": -3,
      "y": 7,
      "z": 12,
      "name": "Wood_Deadwood_Planks",
      "rotation": 4
    },
    {
      "x": -3,
      "y": 8,
      "z": 12,
      "name": "Wood_Deadwood_Planks",
      "rotation": 4
    },
    {
      "x": -3,
      "y": 9,
      "z": 12,
      "name": "Wood_Deadwood_Planks",
      "rotation": 4
    },
    {
      "x": -3,
      "y": 10,
      "z": 12,
      "name": "Wood_Redwood_Planks",
      "rotation": 4
    },
    {
      "x": -3,
      "y": 11,
      "z": 12,
      "name": "Wood_Oak_Trunk",
      "support": 15,
      "rotation": 9
    },
    {
      "x": -3,
      "y": 12,
      "z": 12,
      "name": "Wood_Oak_Trunk",
      "support": 15,
      "rotation": 5
    },
    {
      "x": -3,
      "y": 13,
      "z": 12,
      "name": "Wood_Deadwood_Planks",
      "rotation": 4
    },
    {
      "x": -3,
      "y": 8,
      "z": 13,
      "name": "Wood_Deadwood_Planks",
      "rotation": 4
    },
    {
      "x": -3,
      "y": 11,
      "z": 13,
      "name": "Wood_Redwood_Planks",
      "rotation": 4
    },
    {
      "x": -3,
      "y": 12,
      "z": 13,
      "name": "Wood_Redwood_Planks",
      "rotation": 4
    },
    {
      "x": -2,
      "y": 19,
      "z": -1,
      "name": "Deco_Rope",
      "support": 4,
      "rotation": 15
    },
    {
      "x": -2,
      "y": 6,
      "z": 2,
      "name": "Vehicle_Wood_Boat",
      "filler": 994,
      "rotation": 1
    },
    {
      "x": -2,
      "y": 8,
      "z": 2,
      "name": "Plant_Barnacles",
      "rotation": 6
    },
    {
      "x": -2,
      "y": 6,
      "z": 3,
      "name": "Vehicle_Wood_Boat",
      "filler": 2,
      "rotation": 1
    },
    {
      "x": -2,
      "y": 7,
      "z": 3,
      "name": "Deco_Rope"
    },
    {
      "x": -2,
      "y": 8,
      "z": 3,
      "name": "Wood_Deadwood_Planks",
      "rotation": 4
    },
    {
      "x": -2,
      "y": 6,
      "z": 4,
      "name": "Vehicle_Wood_Boat",
      "filler": 34,
      "rotation": 1
    },
    {
      "x": -2,
      "y": 8,
      "z": 4,
      "name": "Wood_Oak_Trunk",
      "support": 15,
      "rotation": 5
    },
    {
      "x": -2,
      "y": 6,
      "z": 5,
      "name": "Wood_Deadwood_Planks",
      "rotation": 4
    },
    {
      "x": -2,
      "y": 9,
      "z": 5,
      "name": "Wood_Darkwood_Planks",
      "rotation": 4
    },
    {
      "x": -2,
      "y": 5,
      "z": 6,
      "name": "Wood_Redwood_Planks",
      "rotation": 4
    },
    {
      "x": -2,
      "y": 6,
      "z": 6,
      "name": "Wood_Oak_Trunk",
      "support": 15,
      "rotation": 5
    },
    {
      "x": -2,
      "y": 10,
      "z": 6,
      "name": "Wood_Darkwood_Planks",
      "rotation": 4
    },
    {
      "x": -2,
      "y": 5,
      "z": 7,
      "name": "Wood_Redwood_Planks",
      "rotation": 4
    },
    {
      "x": -2,
      "y": 6,
      "z": 7,
      "name": "Wood_Oak_Trunk",
      "support": 15,
      "rotation": 9
    },
    {
      "x": -2,
      "y": 7,
      "z": 7,
      "name": "Wood_Darkwood_Planks",
      "rotation": 4
    },
    {
      "x": -2,
      "y": 10,
      "z": 7,
      "name": "Wood_Darkwood_Stairs",
      "rotation": 8
    },
    {
      "x": -2,
      "y": 11,
      "z": 7,
      "name": "Wood_Oak_Trunk",
      "support": 15,
      "rotation": 5
    },
    {
      "x": -2,
      "y": 5,
      "z": 8,
      "name": "Wood_Deadwood_Planks",
      "rotation": 4
    },
    {
      "x": -2,
      "y": 7,
      "z": 8,
      "name": "Wood_Darkwood_Planks"
    },
    {
      "x": -2,
      "y": 8,
      "z": 8,
      "name": "Wood_Darkwood_Planks",
      "rotation": 4
    },
    {
      "x": -2,
      "y": 9,
      "z": 8,
      "name": "Wood_Darkwood_Stairs",
      "rotation": 8
    },
    {
      "x": -2,
      "y": 10,
      "z": 8,
      "name": "Wood_Oak_Trunk",
      "support": 15,
      "rotation": 4
    },
    {
      "x": -2,
      "y": 11,
      "z": 8,
      "name": "Wood_Darkwood_Stairs"
    },
    {
      "x": -2,
      "y": 12,
      "z": 8,
      "name": "Wood_Darkwood_Planks",
      "rotation": 4
    },
    {
      "x": -2,
      "y": 13,
      "z": 8,
      "name": "Plant_Barnacles"
    },
    {
      "x": -2,
      "y": 6,
      "z": 9,
      "name": "Wood_Deadwood_Planks",
      "rotation": 4
    },
    {
      "x": -2,
      "y": 7,
      "z": 9,
      "name": "Soil_Pebbles_Frozen",
      "support": 15
    },
    {
      "x": -2,
      "y": 9,
      "z": 9,
      "name": "Wood_Oak_Trunk",
      "support": 15,
      "rotation": 5
    },
    {
      "x": -2,
      "y": 10,
      "z": 9,
      "name": "Wood_Darkwood_Stairs"
    },
    {
      "x": -2,
      "y": 12,
      "z": 9,
      "name": "Deco_Lantern_Ceiling"
    },
    {
      "x": -2,
      "y": 13,
      "z": 9,
      "name": "Wood_Darkwood_Planks",
      "rotation": 4
    },
    {
      "x": -2,
      "y": 14,
      "z": 9,
      "name": "Plant_Barnacles"
    },
    {
      "x": -2,
      "y": 5,
      "z": 10,
      "name": "Wood_Deadwood_Planks",
      "rotation": 4
    },
    {
      "x": -2,
      "y": 6,
      "z": 10,
      "name": "Wood_Deadwood_Planks",
      "rotation": 4
    },
    {
      "x": -2,
      "y": 7,
      "z": 10,
      "name": "Soil_Pebbles_Frozen",
      "support": 15
    },
    {
      "x": -2,
      "y": 8,
      "z": 10,
      "name": "Plant_Crop_Mana3"
    },
    {
      "x": -2,
      "y": 9,
      "z": 10,
      "name": "Plant_Crop_Mana3",
      "filler": 1024
    },
    {
      "x": -2,
      "y": 10,
      "z": 10,
      "name": "Wood_Darkwood_Planks",
      "rotation": 4
    },
    {
      "x": -2,
      "y": 14,
      "z": 10,
      "name": "Wood_Oak_Trunk",
      "support": 15,
      "rotation": 5
    },
    {
      "x": -2,
      "y": 15,
      "z": 10,
      "name": "Wood_Deadwood_Planks",
      "rotation": 4
    },
    {
      "x": -2,
      "y": 6,
      "z": 11,
      "name": "Wood_Deadwood_Planks",
      "rotation": 4
    },
    {
      "x": -2,
      "y": 7,
      "z": 11,
      "name": "Soil_Pebbles_Frozen",
      "support": 15
    },
    {
      "x": -2,
      "y": 8,
      "z": 11,
      "name": "Plant_Seaweed_Winter_Blue",
      "support": 15
    },
    {
      "x": -2,
      "y": 9,
      "z": 11,
      "name": "Plant_Seaweed_Winter_Blue",
      "filler": 1024
    },
    {
      "x": -2,
      "y": 10,
      "z": 11,
      "name": "Wood_Darkwood_Planks",
      "rotation": 4
    },
    {
      "x": -2,
      "y": 11,
      "z": 11,
      "name": "Wood_Darkwood_Planks",
      "rotation": 4
    },
    {
      "x": -2,
      "y": 12,
      "z": 11,
      "name": "Furniture_Village_Chest_Small",
      "components": {
        "Components": {
          "PlacedByInteraction": {
            "WhoPlacedUuid": {
              "$binary": "rmwkrpH8RVykTc7XnK4YBA==",
              "$type": "04"
            }
          },
          "ItemContainerBlock": {
            "ItemContainer": {
              "Capacity": 18,
              "Items": {}
            },
            "Capacity": 18
          }
        }
      },
      "rotation": 2
    },
    {
      "x": -2,
      "y": 7,
      "z": 12,
      "name": "Wood_Deadwood_Planks",
      "rotation": 4
    },
    {
      "x": -2,
      "y": 8,
      "z": 12,
      "name": "Wood_Deadwood_Planks",
      "rotation": 4
    },
    {
      "x": -2,
      "y": 9,
      "z": 12,
      "name": "Wood_Deadwood_Planks",
      "rotation": 4
    },
    {
      "x": -2,
      "y": 11,
      "z": 12,
      "name": "Wood_Oak_Trunk",
      "support": 15,
      "rotation": 9
    },
    {
      "x": -2,
      "y": 12,
      "z": 12,
      "name": "Wood_Oak_Trunk",
      "support": 15,
      "rotation": 5
    },
    {
      "x": -2,
      "y": 13,
      "z": 12,
      "name": "Wood_Deadwood_Planks",
      "rotation": 4
    },
    {
      "x": -2,
      "y": 8,
      "z": 13,
      "name": "Wood_Deadwood_Planks",
      "rotation": 4
    },
    {
      "x": -2,
      "y": 10,
      "z": 13,
      "name": "Wood_Deadwood_Planks",
      "rotation": 4
    },
    {
      "x": -2,
      "y": 11,
      "z": 13,
      "name": "Wood_Redwood_Planks",
      "rotation": 4
    },
    {
      "x": -2,
      "y": 12,
      "z": 13,
      "name": "Wood_Redwood_Planks",
      "rotation": 4
    },
    {
      "x": -1,
      "y": 19,
      "z": -1,
      "name": "Deco_Rope",
      "support": 3,
      "rotation": 15
    },
    {
      "x": -1,
      "y": 8,
      "z": 3,
      "name": "Wood_Deadwood_Planks",
      "rotation": 4
    },
    {
      "x": -1,
      "y": 7,
      "z": 4,
      "name": "Wood_Redwood_Planks",
      "rotation": 4
    },
    {
      "x": -1,
      "y": 8,
      "z": 4,
      "name": "Wood_Oak_Trunk",
      "support": 15,
      "rotation": 5
    },
    {
      "x": -1,
      "y": 6,
      "z": 5,
      "name": "Wood_Deadwood_Planks",
      "rotation": 4
    },
    {
      "x": -1,
      "y": 9,
      "z": 5,
      "name": "Wood_Darkwood_Planks",
      "rotation": 4
    },
    {
      "x": -1,
      "y": 5,
      "z": 6,
      "name": "Wood_Redwood_Planks",
      "rotation": 4
    },
    {
      "x": -1,
      "y": 6,
      "z": 6,
      "name": "Wood_Oak_Trunk",
      "support": 15,
      "rotation": 5
    },
    {
      "x": -1,
      "y": 10,
      "z": 6,
      "name": "Wood_Darkwood_Planks"
    },
    {
      "x": -1,
      "y": 11,
      "z": 6,
      "name": "Plant_Seaweed_Winter_Blue",
      "support": 15
    },
    {
      "x": -1,
      "y": 12,
      "z": 6,
      "name": "Plant_Seaweed_Winter_Blue",
      "filler": 1024
    },
    {
      "x": -1,
      "y": 5,
      "z": 7,
      "name": "Wood_Redwood_Planks",
      "rotation": 4
    },
    {
      "x": -1,
      "y": 6,
      "z": 7,
      "name": "Wood_Oak_Trunk",
      "support": 15,
      "rotation": 9
    },
    {
      "x": -1,
      "y": 7,
      "z": 7,
      "name": "Wood_Darkwood_Planks",
      "rotation": 4
    },
    {
      "x": -1,
      "y": 11,
      "z": 7,
      "name": "Wood_Oak_Trunk",
      "support": 15,
      "rotation": 5
    },
    {
      "x": -1,
      "y": 5,
      "z": 8,
      "name": "Wood_Deadwood_Planks",
      "rotation": 4
    },
    {
      "x": -1,
      "y": 7,
      "z": 8,
      "name": "Wood_Darkwood_Planks"
    },
    {
      "x": -1,
      "y": 8,
      "z": 8,
      "name": "Wood_Darkwood_Planks",
      "rotation": 4
    },
    {
      "x": -1,
      "y": 9,
      "z": 8,
      "name": "Furniture_Village_Chest_Small",
      "components": {
        "Components": {
          "PlacedByInteraction": {
            "WhoPlacedUuid": {
              "$binary": "rmwkrpH8RVykTc7XnK4YBA==",
              "$type": "04"
            }
          },
          "ItemContainerBlock": {
            "ItemContainer": {
              "Capacity": 18,
              "Items": {}
            },
            "Capacity": 18
          }
        }
      },
      "rotation": 1
    },
    {
      "x": -1,
      "y": 12,
      "z": 8,
      "name": "Wood_Darkwood_Planks"
    },
    {
      "x": -1,
      "y": 13,
      "z": 8,
      "name": "Plant_Barnacles"
    },
    {
      "x": -1,
      "y": 6,
      "z": 9,
      "name": "Wood_Deadwood_Planks",
      "rotation": 4
    },
    {
      "x": -1,
      "y": 7,
      "z": 9,
      "name": "Soil_Pebbles_Frozen",
      "support": 15
    },
    {
      "x": -1,
      "y": 9,
      "z": 9,
      "name": "Wood_Oak_Trunk",
      "support": 15,
      "rotation": 5
    },
    {
      "x": -1,
      "y": 13,
      "z": 9,
      "name": "Wood_Darkwood_Planks",
      "rotation": 4
    },
    {
      "x": -1,
      "y": 14,
      "z": 9,
      "name": "Furniture_Ancient_Barrel"
    },
    {
      "x": -1,
      "y": 5,
      "z": 10,
      "name": "Wood_Deadwood_Planks",
      "rotation": 4
    },
    {
      "x": -1,
      "y": 6,
      "z": 10,
      "name": "Wood_Deadwood_Planks",
      "rotation": 4
    },
    {
      "x": -1,
      "y": 7,
      "z": 10,
      "name": "Soil_Pebbles_Frozen",
      "support": 15
    },
    {
      "x": -1,
      "y": 8,
      "z": 10,
      "name": "Plant_Seaweed_Winter_Blue",
      "support": 15
    },
    {
      "x": -1,
      "y": 9,
      "z": 10,
      "name": "Plant_Seaweed_Winter_Blue",
      "filler": 1024
    },
    {
      "x": -1,
      "y": 10,
      "z": 10,
      "name": "Wood_Darkwood_Planks",
      "rotation": 4
    },
    {
      "x": -1,
      "y": 11,
      "z": 10,
      "name": "Furniture_Ancient_Barrel"
    },
    {
      "x": -1,
      "y": 14,
      "z": 10,
      "name": "Wood_Oak_Trunk",
      "support": 15,
      "rotation": 5
    },
    {
      "x": -1,
      "y": 15,
      "z": 10,
      "name": "Wood_Deadwood_Planks",
      "rotation": 4
    },
    {
      "x": -1,
      "y": 6,
      "z": 11,
      "name": "Wood_Deadwood_Planks",
      "rotation": 4
    },
    {
      "x": -1,
      "y": 7,
      "z": 11,
      "name": "Wood_Darkwood_Planks",
      "rotation": 4
    },
    {
      "x": -1,
      "y": 8,
      "z": 11,
      "name": "Plant_Seaweed_Winter_Short",
      "support": 15
    },
    {
      "x": -1,
      "y": 10,
      "z": 11,
      "name": "Wood_Darkwood_Planks",
      "rotation": 4
    },
    {
      "x": -1,
      "y": 11,
      "z": 11,
      "name": "Wood_Darkwood_Planks",
      "rotation": 4
    },
    {
      "x": -1,
      "y": 14,
      "z": 11,
      "name": "Wood_Redwood_Planks",
      "rotation": 4
    },
    {
      "x": -1,
      "y": 7,
      "z": 12,
      "name": "Wood_Deadwood_Planks",
      "rotation": 4
    },
    {
      "x": -1,
      "y": 8,
      "z": 12,
      "name": "Wood_Deadwood_Planks",
      "rotation": 4
    },
    {
      "x": -1,
      "y": 9,
      "z": 12,
      "name": "Wood_Deadwood_Planks",
      "rotation": 4
    },
    {
      "x": -1,
      "y": 11,
      "z": 12,
      "name": "Wood_Oak_Trunk",
      "support": 15,
      "rotation": 9
    },
    {
      "x": -1,
      "y": 12,
      "z": 12,
      "name": "Wood_Oak_Trunk",
      "support": 15,
      "rotation": 5
    },
    {
      "x": -1,
      "y": 13,
      "z": 12,
      "name": "Wood_Deadwood_Planks",
      "rotation": 4
    },
    {
      "x": -1,
      "y": 8,
      "z": 13,
      "name": "Wood_Deadwood_Planks",
      "rotation": 4
    },
    {
      "x": -1,
      "y": 10,
      "z": 13,
      "name": "Wood_Deadwood_Planks",
      "rotation": 4
    },
    {
      "x": -1,
      "y": 11,
      "z": 13,
      "name": "Wood_Redwood_Planks",
      "rotation": 4
    },
    {
      "x": -1,
      "y": 12,
      "z": 13,
      "name": "Wood_Redwood_Planks",
      "rotation": 4
    },
    {
      "x": 0,
      "y": 19,
      "z": -1,
      "name": "Deco_Rope",
      "support": 2,
      "rotation": 15
    },
    {
      "x": 0,
      "y": 8,
      "z": 3,
      "name": "Wood_Deadwood_Planks",
      "rotation": 4
    },
    {
      "x": 0,
      "y": 8,
      "z": 4,
      "name": "Wood_Oak_Trunk",
      "support": 15,
      "rotation": 5
    },
    {
      "x": 0,
      "y": 9,
      "z": 4,
      "name": "Furniture_Ancient_Barrel"
    },
    {
      "x": 0,
      "y": 6,
      "z": 5,
      "name": "Wood_Deadwood_Planks",
      "rotation": 4
    },
    {
      "x": 0,
      "y": 9,
      "z": 5,
      "name": "Wood_Darkwood_Planks",
      "rotation": 4
    },
    {
      "x": 0,
      "y": 5,
      "z": 6,
      "name": "Wood_Redwood_Planks",
      "rotation": 4
    },
    {
      "x": 0,
      "y": 6,
      "z": 6,
      "name": "Wood_Oak_Trunk",
      "support": 15,
      "rotation": 5
    },
    {
      "x": 0,
      "y": 10,
      "z": 6,
      "name": "Wood_Darkwood_Planks"
    },
    {
      "x": 0,
      "y": 11,
      "z": 6,
      "name": "Plant_Coral_Bush_Blue"
    },
    {
      "x": 0,
      "y": 5,
      "z": 7,
      "name": "Wood_Redwood_Planks",
      "rotation": 4
    },
    {
      "x": 0,
      "y": 6,
      "z": 7,
      "name": "Wood_Oak_Trunk",
      "support": 15,
      "rotation": 9
    },
    {
      "x": 0,
      "y": 7,
      "z": 7,
      "name": "Wood_Darkwood_Planks",
      "rotation": 4
    },
    {
      "x": 0,
      "y": 11,
      "z": 7,
      "name": "Wood_Oak_Trunk",
      "support": 15,
      "rotation": 5
    },
    {
      "x": 0,
      "y": 12,
      "z": 7,
      "name": "Plant_Seaweed_Winter_Blue",
      "support": 15
    },
    {
      "x": 0,
      "y": 13,
      "z": 7,
      "name": "Plant_Seaweed_Winter_Blue",
      "filler": 1024
    },
    {
      "x": 0,
      "y": 5,
      "z": 8,
      "name": "Wood_Deadwood_Planks",
      "rotation": 4
    },
    {
      "x": 0,
      "y": 7,
      "z": 8,
      "name": "Wood_Darkwood_Planks",
      "rotation": 4
    },
    {
      "x": 0,
      "y": 8,
      "z": 8,
      "name": "Wood_Darkwood_Planks",
      "rotation": 4
    },
    {
      "x": 0,
      "y": 9,
      "z": 8,
      "name": "Furniture_Ancient_Barrel"
    },
    {
      "x": 0,
      "y": 12,
      "z": 8,
      "name": "Wood_Darkwood_Planks"
    },
    {
      "x": 0,
      "y": 6,
      "z": 9,
      "name": "Wood_Deadwood_Planks",
      "rotation": 4
    },
    {
      "x": 0,
      "y": 8,
      "z": 9,
      "name": "Wood_Darkwood_Planks",
      "rotation": 4
    },
    {
      "x": 0,
      "y": 9,
      "z": 9,
      "name": "Wood_Oak_Trunk",
      "support": 15,
      "rotation": 5
    },
    {
      "x": 0,
      "y": 13,
      "z": 9,
      "name": "Wood_Darkwood_Planks",
      "rotation": 4
    },
    {
      "x": 0,
      "y": 14,
      "z": 9,
      "name": "Furniture_Ancient_Barrel"
    },
    {
      "x": 0,
      "y": 5,
      "z": 10,
      "name": "Wood_Deadwood_Planks",
      "rotation": 4
    },
    {
      "x": 0,
      "y": 6,
      "z": 10,
      "name": "Wood_Deadwood_Planks",
      "rotation": 4
    },
    {
      "x": 0,
      "y": 7,
      "z": 10,
      "name": "Plant_Seaweed_Winter_Short",
      "support": 15
    },
    {
      "x": 0,
      "y": 9,
      "z": 10,
      "name": "Wood_Darkwood_Planks"
    },
    {
      "x": 0,
      "y": 10,
      "z": 10,
      "name": "Wood_Darkwood_Planks",
      "rotation": 4
    },
    {
      "x": 0,
      "y": 11,
      "z": 10,
      "name": "Plant_Seaweed_Winter_Blue",
      "support": 15
    },
    {
      "x": 0,
      "y": 12,
      "z": 10,
      "name": "Plant_Seaweed_Winter_Blue",
      "filler": 1024
    },
    {
      "x": 0,
      "y": 14,
      "z": 10,
      "name": "Wood_Oak_Trunk",
      "support": 15,
      "rotation": 5
    },
    {
      "x": 0,
      "y": 15,
      "z": 10,
      "name": "Wood_Deadwood_Planks",
      "rotation": 4
    },
    {
      "x": 0,
      "y": 6,
      "z": 11,
      "name": "Wood_Deadwood_Planks",
      "rotation": 4
    },
    {
      "x": 0,
      "y": 7,
      "z": 11,
      "name": "Wood_Darkwood_Planks",
      "rotation": 4
    },
    {
      "x": 0,
      "y": 10,
      "z": 11,
      "name": "Wood_Darkwood_Planks",
      "rotation": 4
    },
    {
      "x": 0,
      "y": 11,
      "z": 11,
      "name": "Wood_Darkwood_Planks",
      "rotation": 4
    },
    {
      "x": 0,
      "y": 7,
      "z": 12,
      "name": "Wood_Deadwood_Planks",
      "rotation": 4
    },
    {
      "x": 0,
      "y": 8,
      "z": 12,
      "name": "Wood_Deadwood_Planks",
      "rotation": 4
    },
    {
      "x": 0,
      "y": 9,
      "z": 12,
      "name": "Wood_Deadwood_Planks",
      "rotation": 4
    },
    {
      "x": 0,
      "y": 11,
      "z": 12,
      "name": "Wood_Oak_Trunk",
      "support": 15,
      "rotation": 9
    },
    {
      "x": 0,
      "y": 12,
      "z": 12,
      "name": "Wood_Oak_Trunk",
      "support": 15,
      "rotation": 5
    },
    {
      "x": 0,
      "y": 13,
      "z": 12,
      "name": "Wood_Deadwood_Planks",
      "rotation": 4
    },
    {
      "x": 0,
      "y": 8,
      "z": 13,
      "name": "Wood_Deadwood_Planks",
      "rotation": 4
    },
    {
      "x": 0,
      "y": 10,
      "z": 13,
      "name": "Wood_Deadwood_Planks",
      "rotation": 4
    },
    {
      "x": 0,
      "y": 11,
      "z": 13,
      "name": "Wood_Redwood_Planks",
      "rotation": 4
    },
    {
      "x": 0,
      "y": 12,
      "z": 13,
      "name": "Wood_Redwood_Planks",
      "rotation": 4
    },
    {
      "x": 1,
      "y": 16,
      "z": -11,
      "name": "Cloth_Roof_Hide_Flap",
      "rotation": 3
    },
    {
      "x": 1,
      "y": 17,
      "z": -11,
      "name": "Cloth_Roof_Hide_Vertical",
      "rotation": 3
    },
    {
      "x": 1,
      "y": 18,
      "z": -11,
      "name": "Cloth_Roof_Hide_Vertical",
      "rotation": 3
    },
    {
      "x": 1,
      "y": 12,
      "z": -10,
      "name": "Cloth_Roof_Hide_Flap",
      "rotation": 3
    },
    {
      "x": 1,
      "y": 13,
      "z": -10,
      "name": "Cloth_Roof_Hide_Vertical",
      "rotation": 3
    },
    {
      "x": 1,
      "y": 14,
      "z": -10,
      "name": "Cloth_Roof_Hide_Vertical",
      "rotation": 3
    },
    {
      "x": 1,
      "y": 15,
      "z": -10,
      "name": "Cloth_Roof_Hide_Vertical",
      "rotation": 3
    },
    {
      "x": 1,
      "y": 16,
      "z": -10,
      "name": "Cloth_Roof_Leather_Vertical",
      "rotation": 3
    },
    {
      "x": 1,
      "y": 17,
      "z": -10,
      "name": "Cloth_Roof_Hide_Vertical",
      "rotation": 3
    },
    {
      "x": 1,
      "y": 18,
      "z": -10,
      "name": "Cloth_Roof_Hide_Vertical",
      "rotation": 3
    },
    {
      "x": 1,
      "y": 13,
      "z": -9,
      "name": "Cloth_Roof_Hide_Flap",
      "rotation": 3
    },
    {
      "x": 1,
      "y": 14,
      "z": -9,
      "name": "Cloth_Roof_Hide_Vertical",
      "rotation": 3
    },
    {
      "x": 1,
      "y": 15,
      "z": -9,
      "name": "Cloth_Roof_Hide_Vertical",
      "rotation": 3
    },
    {
      "x": 1,
      "y": 16,
      "z": -9,
      "name": "Cloth_Roof_Hide_Vertical",
      "rotation": 3
    },
    {
      "x": 1,
      "y": 17,
      "z": -9,
      "name": "Cloth_Roof_Leather_Vertical",
      "rotation": 3
    },
    {
      "x": 1,
      "y": 18,
      "z": -9,
      "name": "Cloth_Roof_Hide_Vertical",
      "rotation": 3
    },
    {
      "x": 1,
      "y": 19,
      "z": -9,
      "name": "Cloth_Roof_Hide_Vertical",
      "rotation": 3
    },
    {
      "x": 1,
      "y": 12,
      "z": -8,
      "name": "Cloth_Roof_Hide_Flap",
      "rotation": 3
    },
    {
      "x": 1,
      "y": 13,
      "z": -8,
      "name": "Cloth_Roof_Hide_Vertical",
      "rotation": 3
    },
    {
      "x": 1,
      "y": 15,
      "z": -8,
      "name": "Cloth_Roof_Hide_Flap",
      "rotation": 3
    },
    {
      "x": 1,
      "y": 16,
      "z": -8,
      "name": "Cloth_Roof_Hide_Vertical",
      "rotation": 3
    },
    {
      "x": 1,
      "y": 17,
      "z": -8,
      "name": "Cloth_Roof_Hide_Vertical",
      "rotation": 3
    },
    {
      "x": 1,
      "y": 18,
      "z": -8,
      "name": "Cloth_Roof_Hide_Vertical",
      "rotation": 3
    },
    {
      "x": 1,
      "y": 19,
      "z": -8,
      "name": "Cloth_Roof_Hide_Vertical",
      "rotation": 3
    },
    {
      "x": 1,
      "y": 20,
      "z": -8,
      "name": "Cloth_Roof_Hide_Vertical",
      "rotation": 3
    },
    {
      "x": 1,
      "y": 11,
      "z": -7,
      "name": "Cloth_Roof_Hide_Flap",
      "rotation": 3
    },
    {
      "x": 1,
      "y": 12,
      "z": -7,
      "name": "Cloth_Roof_Hide_Vertical",
      "rotation": 3
    },
    {
      "x": 1,
      "y": 13,
      "z": -7,
      "name": "Cloth_Roof_Hide_Vertical",
      "rotation": 3
    },
    {
      "x": 1,
      "y": 14,
      "z": -7,
      "name": "Cloth_Roof_Hide_Vertical",
      "rotation": 3
    },
    {
      "x": 1,
      "y": 15,
      "z": -7,
      "name": "Cloth_Roof_Hide_Vertical",
      "rotation": 3
    },
    {
      "x": 1,
      "y": 16,
      "z": -7,
      "name": "Cloth_Roof_Hide_Vertical",
      "rotation": 3
    },
    {
      "x": 1,
      "y": 17,
      "z": -7,
      "name": "Cloth_Roof_Leather_Vertical",
      "rotation": 3
    },
    {
      "x": 1,
      "y": 18,
      "z": -7,
      "name": "Cloth_Roof_Hide_Vertical",
      "rotation": 3
    },
    {
      "x": 1,
      "y": 19,
      "z": -7,
      "name": "Cloth_Roof_Leather_Vertical",
      "rotation": 3
    },
    {
      "x": 1,
      "y": 20,
      "z": -7,
      "name": "Cloth_Roof_Leather_Vertical",
      "rotation": 3
    },
    {
      "x": 1,
      "y": 21,
      "z": -7,
      "name": "Cloth_Roof_Hide_Vertical",
      "rotation": 3
    },
    {
      "x": 1,
      "y": 22,
      "z": -7,
      "name": "Cloth_Roof_Hide_Vertical",
      "rotation": 3
    },
    {
      "x": 1,
      "y": 15,
      "z": -6,
      "name": "Cloth_Roof_Leather_Flap",
      "rotation": 3
    },
    {
      "x": 1,
      "y": 16,
      "z": -6,
      "name": "Cloth_Roof_Leather_Vertical",
      "rotation": 3
    },
    {
      "x": 1,
      "y": 17,
      "z": -6,
      "name": "Cloth_Roof_Leather_Vertical",
      "rotation": 3
    },
    {
      "x": 1,
      "y": 18,
      "z": -6,
      "name": "Cloth_Roof_Leather_Vertical",
      "rotation": 3
    },
    {
      "x": 1,
      "y": 19,
      "z": -6,
      "name": "Cloth_Roof_Leather_Vertical",
      "rotation": 3
    },
    {
      "x": 1,
      "y": 20,
      "z": -6,
      "name": "Cloth_Roof_Hide_Vertical",
      "rotation": 3
    },
    {
      "x": 1,
      "y": 21,
      "z": -6,
      "name": "Cloth_Roof_Hide_Vertical",
      "rotation": 3
    },
    {
      "x": 1,
      "y": 22,
      "z": -6,
      "name": "Cloth_Roof_Hide_Vertical",
      "rotation": 3
    },
    {
      "x": 1,
      "y": 16,
      "z": -5,
      "name": "Cloth_Roof_Leather_Flap",
      "rotation": 3
    },
    {
      "x": 1,
      "y": 17,
      "z": -5,
      "name": "Cloth_Roof_Leather_Vertical",
      "rotation": 3
    },
    {
      "x": 1,
      "y": 18,
      "z": -5,
      "name": "Cloth_Roof_Hide_Vertical",
      "rotation": 3
    },
    {
      "x": 1,
      "y": 19,
      "z": -5,
      "name": "Cloth_Roof_Leather_Vertical",
      "rotation": 3
    },
    {
      "x": 1,
      "y": 20,
      "z": -5,
      "name": "Cloth_Roof_Hide_Vertical",
      "rotation": 3
    },
    {
      "x": 1,
      "y": 21,
      "z": -5,
      "name": "Cloth_Roof_Hide_Vertical",
      "rotation": 3
    },
    {
      "x": 1,
      "y": 22,
      "z": -5,
      "name": "Cloth_Roof_Hide_Vertical",
      "rotation": 3
    },
    {
      "x": 1,
      "y": 20,
      "z": -4,
      "name": "Cloth_Roof_Hide_Flap",
      "rotation": 3
    },
    {
      "x": 1,
      "y": 21,
      "z": -4,
      "name": "Cloth_Roof_Hide_Vertical",
      "rotation": 3
    },
    {
      "x": 1,
      "y": 22,
      "z": -4,
      "name": "Cloth_Roof_Hide_Vertical",
      "rotation": 3
    },
    {
      "x": 1,
      "y": 23,
      "z": -4,
      "name": "Cloth_Roof_Hide_Vertical",
      "rotation": 3
    },
    {
      "x": 1,
      "y": 18,
      "z": -3,
      "name": "Cloth_Roof_Hide_Flap",
      "rotation": 3
    },
    {
      "x": 1,
      "y": 19,
      "z": -3,
      "name": "Cloth_Roof_Hide_Vertical",
      "rotation": 3
    },
    {
      "x": 1,
      "y": 20,
      "z": -3,
      "name": "Cloth_Roof_Leather_Vertical",
      "rotation": 3
    },
    {
      "x": 1,
      "y": 21,
      "z": -3,
      "name": "Cloth_Roof_Leather_Vertical",
      "rotation": 3
    },
    {
      "x": 1,
      "y": 22,
      "z": -3,
      "name": "Cloth_Roof_Hide_Vertical",
      "rotation": 3
    },
    {
      "x": 1,
      "y": 23,
      "z": -3,
      "name": "Cloth_Roof_Hide_Vertical",
      "rotation": 3
    },
    {
      "x": 1,
      "y": 24,
      "z": -3,
      "name": "Cloth_Roof_Hide_Vertical",
      "rotation": 3
    },
    {
      "x": 1,
      "y": 25,
      "z": -3,
      "name": "Cloth_Roof_Hide_Vertical",
      "rotation": 3
    },
    {
      "x": 1,
      "y": 26,
      "z": -3,
      "name": "Cloth_Roof_Hide_Vertical",
      "rotation": 3
    },
    {
      "x": 1,
      "y": 22,
      "z": -2,
      "name": "Cloth_Roof_Hide_Vertical",
      "rotation": 3
    },
    {
      "x": 1,
      "y": 23,
      "z": -2,
      "name": "Cloth_Roof_Hide_Flap",
      "rotation": 3
    },
    {
      "x": 1,
      "y": 24,
      "z": -2,
      "name": "Cloth_Roof_Hide_Vertical",
      "rotation": 3
    },
    {
      "x": 1,
      "y": 25,
      "z": -2,
      "name": "Cloth_Roof_Hide_Vertical",
      "rotation": 3
    },
    {
      "x": 1,
      "y": 26,
      "z": -2,
      "name": "Cloth_Roof_Hide_Vertical",
      "rotation": 3
    },
    {
      "x": 1,
      "y": 19,
      "z": -1,
      "name": "Deco_Rope",
      "support": 1,
      "rotation": 15
    },
    {
      "x": 1,
      "y": 20,
      "z": -1,
      "name": "Cloth_Roof_Hide_Flap",
      "rotation": 3
    },
    {
      "x": 1,
      "y": 21,
      "z": -1,
      "name": "Cloth_Roof_Hide_Vertical",
      "rotation": 3
    },
    {
      "x": 1,
      "y": 22,
      "z": -1,
      "name": "Cloth_Roof_Hide_Vertical",
      "rotation": 3
    },
    {
      "x": 1,
      "y": 23,
      "z": -1,
      "name": "Cloth_Roof_Hide_Vertical",
      "rotation": 3
    },
    {
      "x": 1,
      "y": 24,
      "z": -1,
      "name": "Cloth_Roof_Hide_Vertical",
      "rotation": 3
    },
    {
      "x": 1,
      "y": 25,
      "z": -1,
      "name": "Cloth_Roof_Hide_Vertical",
      "rotation": 3
    },
    {
      "x": 1,
      "y": 26,
      "z": -1,
      "name": "Cloth_Roof_Hide_Vertical",
      "rotation": 3
    },
    {
      "x": 1,
      "y": 27,
      "z": -1,
      "name": "Cloth_Roof_Hide_Vertical",
      "rotation": 3
    },
    {
      "x": 1,
      "y": 28,
      "z": -1,
      "name": "Cloth_Roof_Hide_Vertical",
      "rotation": 3
    },
    {
      "x": 1,
      "y": 8,
      "z": 3,
      "name": "Wood_Deadwood_Planks",
      "rotation": 4
    },
    {
      "x": 1,
      "y": 7,
      "z": 4,
      "name": "Wood_Redwood_Planks",
      "rotation": 4
    },
    {
      "x": 1,
      "y": 8,
      "z": 4,
      "name": "Wood_Oak_Trunk",
      "support": 15,
      "rotation": 5
    },
    {
      "x": 1,
      "y": 6,
      "z": 5,
      "name": "Wood_Deadwood_Planks",
      "rotation": 4
    },
    {
      "x": 1,
      "y": 9,
      "z": 5,
      "name": "Wood_Darkwood_Planks",
      "rotation": 4
    },
    {
      "x": 1,
      "y": 5,
      "z": 6,
      "name": "Wood_Redwood_Planks",
      "rotation": 4
    },
    {
      "x": 1,
      "y": 6,
      "z": 6,
      "name": "Wood_Oak_Trunk",
      "support": 15,
      "rotation": 5
    },
    {
      "x": 1,
      "y": 10,
      "z": 6,
      "name": "Wood_Darkwood_Planks"
    },
    {
      "x": 1,
      "y": 5,
      "z": 7,
      "name": "Wood_Redwood_Planks",
      "rotation": 4
    },
    {
      "x": 1,
      "y": 6,
      "z": 7,
      "name": "Wood_Oak_Trunk",
      "support": 15,
      "rotation": 9
    },
    {
      "x": 1,
      "y": 7,
      "z": 7,
      "name": "Wood_Darkwood_Planks",
      "rotation": 4
    },
    {
      "x": 1,
      "y": 11,
      "z": 7,
      "name": "Wood_Oak_Trunk",
      "support": 15,
      "rotation": 5
    },
    {
      "x": 1,
      "y": 5,
      "z": 8,
      "name": "Wood_Deadwood_Planks",
      "rotation": 4
    },
    {
      "x": 1,
      "y": 7,
      "z": 8,
      "name": "Wood_Darkwood_Planks",
      "rotation": 4
    },
    {
      "x": 1,
      "y": 8,
      "z": 8,
      "name": "Wood_Darkwood_Planks",
      "rotation": 4
    },
    {
      "x": 1,
      "y": 9,
      "z": 8,
      "name": "Furniture_Ancient_Barrel"
    },
    {
      "x": 1,
      "y": 12,
      "z": 8,
      "name": "Wood_Darkwood_Planks"
    },
    {
      "x": 1,
      "y": 6,
      "z": 9,
      "name": "Wood_Deadwood_Planks",
      "rotation": 4
    },
    {
      "x": 1,
      "y": 8,
      "z": 9,
      "name": "Wood_Darkwood_Planks",
      "rotation": 4
    },
    {
      "x": 1,
      "y": 9,
      "z": 9,
      "name": "Wood_Oak_Trunk",
      "support": 15,
      "rotation": 5
    },
    {
      "x": 1,
      "y": 13,
      "z": 9,
      "name": "Wood_Darkwood_Planks",
      "rotation": 4
    },
    {
      "x": 1,
      "y": 14,
      "z": 9,
      "name": "Furniture_Ancient_Barrel"
    },
    {
      "x": 1,
      "y": 5,
      "z": 10,
      "name": "Wood_Deadwood_Planks",
      "rotation": 4
    },
    {
      "x": 1,
      "y": 6,
      "z": 10,
      "name": "Wood_Deadwood_Planks",
      "rotation": 4
    },
    {
      "x": 1,
      "y": 9,
      "z": 10,
      "name": "Wood_Darkwood_Planks"
    },
    {
      "x": 1,
      "y": 10,
      "z": 10,
      "name": "Wood_Darkwood_Planks",
      "rotation": 4
    },
    {
      "x": 1,
      "y": 14,
      "z": 10,
      "name": "Wood_Oak_Trunk",
      "support": 15,
      "rotation": 5
    },
    {
      "x": 1,
      "y": 15,
      "z": 10,
      "name": "Wood_Deadwood_Planks",
      "rotation": 4
    },
    {
      "x": 1,
      "y": 16,
      "z": 10,
      "name": "Plant_Seaweed_Winter_Short",
      "support": 15
    },
    {
      "x": 1,
      "y": 6,
      "z": 11,
      "name": "Wood_Deadwood_Planks",
      "rotation": 4
    },
    {
      "x": 1,
      "y": 7,
      "z": 11,
      "name": "Wood_Darkwood_Planks",
      "rotation": 4
    },
    {
      "x": 1,
      "y": 8,
      "z": 11,
      "name": "Plant_Seaweed_Winter_Blue",
      "support": 15
    },
    {
      "x": 1,
      "y": 9,
      "z": 11,
      "name": "Plant_Seaweed_Winter_Blue",
      "filler": 1024
    },
    {
      "x": 1,
      "y": 10,
      "z": 11,
      "name": "Wood_Darkwood_Planks",
      "rotation": 4
    },
    {
      "x": 1,
      "y": 11,
      "z": 11,
      "name": "Wood_Darkwood_Planks",
      "rotation": 4
    },
    {
      "x": 1,
      "y": 12,
      "z": 11,
      "name": "Plant_Coral_Model_Cyan"
    },
    {
      "x": 1,
      "y": 14,
      "z": 11,
      "name": "Wood_Redwood_Planks",
      "rotation": 4
    },
    {
      "x": 1,
      "y": 15,
      "z": 11,
      "name": "Plant_Seaweed_Winter_Short",
      "support": 15
    },
    {
      "x": 1,
      "y": 7,
      "z": 12,
      "name": "Wood_Deadwood_Planks",
      "rotation": 4
    },
    {
      "x": 1,
      "y": 8,
      "z": 12,
      "name": "Wood_Deadwood_Planks",
      "rotation": 4
    },
    {
      "x": 1,
      "y": 9,
      "z": 12,
      "name": "Wood_Deadwood_Planks",
      "rotation": 4
    },
    {
      "x": 1,
      "y": 11,
      "z": 12,
      "name": "Wood_Oak_Trunk",
      "support": 15,
      "rotation": 9
    },
    {
      "x": 1,
      "y": 12,
      "z": 12,
      "name": "Wood_Oak_Trunk",
      "support": 15,
      "rotation": 5
    },
    {
      "x": 1,
      "y": 13,
      "z": 12,
      "name": "Wood_Deadwood_Planks",
      "rotation": 4
    },
    {
      "x": 1,
      "y": 8,
      "z": 13,
      "name": "Wood_Deadwood_Planks",
      "rotation": 4
    },
    {
      "x": 1,
      "y": 10,
      "z": 13,
      "name": "Wood_Deadwood_Planks",
      "rotation": 4
    },
    {
      "x": 1,
      "y": 11,
      "z": 13,
      "name": "Wood_Redwood_Planks",
      "rotation": 4
    },
    {
      "x": 1,
      "y": 12,
      "z": 13,
      "name": "Wood_Redwood_Planks",
      "rotation": 4
    },
    {
      "x": 2,
      "y": 11,
      "z": -12,
      "name": "Deco_Rope"
    },
    {
      "x": 2,
      "y": 12,
      "z": -12,
      "name": "Deco_Rope"
    },
    {
      "x": 2,
      "y": 13,
      "z": -12,
      "name": "Deco_Rope"
    },
    {
      "x": 2,
      "y": 14,
      "z": -12,
      "name": "Deco_Rope"
    },
    {
      "x": 2,
