{
  "version": 8,
  "blockIdVersion": 11,
  "anchorX": 0,
  "anchorY": 1,
  "anchorZ": 0,
  "blocks": [
    {
      "x": -1,
      "y": 1,
      "z": -1,
      "name": "Wood_Poisoned_Trunk_Full",
      "support": 15
    },
    {
      "x": -1,
      "y": 2,
      "z": -1,
      "name": "Wood_Poisoned_Trunk_Full",
      "support": 15
    },
    {
      "x": -1,
      "y": 0,
      "z": 0,
      "name": "Wood_Poisoned_Trunk_Full",
      "support": 15
    },
    {
      "x": -1,
      "y": 1,
      "z": 0,
      "name": "Wood_Poisoned_Trunk_Full",
      "support": 15
    },
    {
      "x": -1,
      "y": 2,
      "z": 0,
      "name": "Wood_Poisoned_Trunk_Full",
      "support": 15
    },
    {
      "x": -1,
      "y": 3,
      "z": 0,
      "name": "Wood_Poisoned_Trunk_Full",
      "support": 15
    },
    {
      "x": -1,
      "y": 4,
      "z": 0,
      "name": "Wood_Fire_Trunk_Stairs",
      "rotation": 3
    },
    {
      "x": -1,
      "y": 5,
      "z": 0,
      "name": "Wood_Fire_Trunk_Half",
      "rotation": 7
    },
    {
      "x": -1,
      "y": 1,
      "z": 1,
      "name": "Wood_Poisoned_Trunk_Full",
      "support": 15
    },
    {
      "x": 0,
      "y": 0,
      "z": -1,
      "name": "Wood_Poisoned_Trunk_Full",
      "support": 15
    },
    {
      "x": 0,
      "y": 1,
      "z": -1,
      "name": "Wood_Poisoned_Trunk_Full",
      "support": 15
    },
    {
      "x": 0,
      "y": 2,
      "z": -1,
      "name": "Wood_Poisoned_Trunk_Full",
      "support": 15
    },
    {
      "x": 0,
      "y": 3,
      "z": -1,
      "name": "Wood_Fire_Trunk_Full",
      "support": 15,
      "rotation": 4
    },
    {
      "x": 0,
      "y": 4,
      "z": -1,
      "name": "Wood_Fire_Trunk_Half",
      "rotation": 6
    },
    {
      "x": 0,
      "y": 0,
      "z": 0,
      "name": "Wood_Poisoned_Trunk_Full",
      "support": 15
    },
    {
      "x": 0,
      "y": 1,
      "z": 0,
      "name": "Wood_Poisoned_Trunk_Full",
      "support": 15
    },
    {
      "x": 0,
      "y": 2,
      "z": 0,
      "name": "Wood_Poisoned_Trunk_Full",
      "support": 15
    },
    {
      "x": 0,
      "y": 3,
      "z": 0,
      "name": "Wood_Poisoned_Trunk_Full",
      "support": 15
    },
    {
      "x": 0,
      "y": 4,
      "z": 0,
      "name": "Wood_Fire_Trunk_Full",
      "support": 15
    },
    {
      "x": 0,
      "y": 5,
      "z": 0,
      "name": "Wood_Fire_Trunk_Full",
      "support": 15
    },
    {
      "x": 0,
      "y": 6,
      "z": 0,
      "name": "Wood_Fire_Trunk_Full",
      "support": 15
    },
    {
      "x": 0,
      "y": 7,
      "z": 0,
      "name": "Wood_Fire_Branch_Long",
      "support": 15
    },
    {
      "x": 0,
      "y": 0,
      "z": 1,
      "name": "Wood_Poisoned_Trunk_Full",
      "support": 15
    },
    {
      "x": 0,
      "y": 1,
      "z": 1,
      "name": "Wood_Poisoned_Trunk_Full",
      "support": 15
    },
    {
      "x": 0,
      "y": 2,
      "z": 1,
      "name": "Wood_Poisoned_Trunk_Full",
      "support": 15
    },
    {
      "x": 0,
      "y": 3,
      "z": 1,
      "name": "Wood_Fire_Trunk_Full",
      "support": 15
    },
    {
      "x": 0,
      "y": 4,
      "z": 1,
      "name": "Wood_Fire_Trunk_Full",
      "support": 15
    },
    {
      "x": 1,
      "y": 1,
      "z": -1,
      "name": "Wood_Poisoned_Trunk_Full",
      "support": 15
    },
    {
      "x": 1,
      "y": 0,
      "z": 0,
      "name": "Wood_Poisoned_Trunk_Full",
      "support": 15
    },
    {
      "x": 1,
      "y": 1,
      "z": 0,
      "name": "Wood_Poisoned_Trunk_Full",
      "support": 15
    },
    {
      "x": 1,
      "y": 2,
      "z": 0,
      "name": "Wood_Poisoned_Trunk_Full",
      "support": 15
    },
    {
      "x": 1,
      "y": 3,
      "z": 0,
      "name": "Wood_Fire_Trunk_Full",
      "support": 15
    },
    {
      "x": 1,
      "y": 4,
      "z": 0,
      "name": "Wood_Fire_Trunk_Full",
      "support": 15,
      "rotation": 5
    },
    {
      "x": 1,
      "y": 5,
      "z": 0,
      "name": "Wood_Fire_Branch_Corner",
      "support": 15,
      "rotation": 1
    },
    {
      "x": 1,
      "y": 6,
      "z": 0,
      "name": "Wood_Fire_Branch_Long",
      "support": 15
    },
    {
      "x": 1,
      "y": 1,
      "z": 1,
      "name": "Wood_Poisoned_Trunk_Full",
      "support": 15
    },
    {
      "x": 1,
      "y": 2,
      "z": 1,
      "name": "Wood_Poisoned_Trunk_Full",
      "support": 15
    },
    {
      "x": 1,
      "y": 3,
      "z": 1,
      "name": "Wood_Fire_Trunk_Full",
      "support": 15
    }
  ]
}