{
  "version": 8,
  "blockIdVersion": 11,
  "anchorX": 0,
  "anchorY": -1,
  "anchorZ": 0,
  "blocks": [
    {
      "x": -3,
      "y": 1,
      "z": -1,
      "name": "Plant_Crop_Mushroom_Block_Boom_Low"
    },
    {
      "x": -3,
      "y": 2,
      "z": -1,
      "name": "Plant_Crop_Mushroom_Block_Boom"
    },
    {
      "x": -3,
      "y": 3,
      "z": -1,
      "name": "Plant_Crop_Mushroom_Block_Boom"
    },
    {
      "x": -3,
      "y": 1,
      "z": 0,
      "name": "Plant_Crop_Mushroom_Block_Boom_Low"
    },
    {
      "x": -3,
      "y": 2,
      "z": 0,
      "name": "Plant_Crop_Mushroom_Block_Boom"
    },
    {
      "x": -3,
      "y": 3,
      "z": 0,
      "name": "Plant_Crop_Mushroom_Block_Boom"
    },
    {
      "x": -3,
      "y": 1,
      "z": 1,
      "name": "Plant_Crop_Mushroom_Block_Boom_Low"
    },
    {
      "x": -3,
      "y": 2,
      "z": 1,
      "name": "Plant_Crop_Mushroom_Block_Boom"
    },
    {
      "x": -3,
      "y": 3,
      "z": 1,
      "name": "Plant_Crop_Mushroom_Block_Boom"
    },
    {
      "x": -3,
      "y": 1,
      "z": 2,
      "name": "Plant_Crop_Mushroom_Block_Boom_Low"
    },
    {
      "x": -3,
      "y": 2,
      "z": 2,
      "name": "Plant_Crop_Mushroom_Block_Boom"
    },
    {
      "x": -3,
      "y": 3,
      "z": 2,
      "name": "Plant_Crop_Mushroom_Block_Boom"
    },
    {
      "x": -2,
      "y": 1,
      "z": -2,
      "name": "Plant_Crop_Mushroom_Block_Boom_Low"
    },
    {
      "x": -2,
      "y": 2,
      "z": -2,
      "name": "Plant_Crop_Mushroom_Block_Boom"
    },
    {
      "x": -2,
      "y": 3,
      "z": -2,
      "name": "Plant_Crop_Mushroom_Block_Boom"
    },
    {
      "x": -2,
      "y": 1,
      "z": -1,
      "name": "Plant_Crop_Mushroom_Block_Boom_Low"
    },
    {
      "x": -2,
      "y": 2,
      "z": -1,
      "name": "Plant_Crop_Mushroom_Block_Boom"
    },
    {
      "x": -2,
      "y": 3,
      "z": -1,
      "name": "Plant_Crop_Mushroom_Block_Boom"
    },
    {
      "x": -2,
      "y": 3,
      "z": 0,
      "name": "Plant_Crop_Mushroom_Block_Boom"
    },
    {
      "x": -2,
      "y": 4,
      "z": 0,
      "name": "Plant_Crop_Mushroom_Block_Boom"
    },
    {
      "x": -2,
      "y": 3,
      "z": 1,
      "name": "Plant_Crop_Mushroom_Block_Boom"
    },
    {
      "x": -2,
      "y": 4,
      "z": 1,
      "name": "Plant_Crop_Mushroom_Block_Boom"
    },
    {
      "x": -2,
      "y": 1,
      "z": 2,
      "name": "Plant_Crop_Mushroom_Block_Boom_Low"
    },
    {
      "x": -2,
      "y": 2,
      "z": 2,
      "name": "Plant_Crop_Mushroom_Block_Boom"
    },
    {
      "x": -2,
      "y": 3,
      "z": 2,
      "name": "Plant_Crop_Mushroom_Block_Boom"
    },
    {
      "x": -2,
      "y": 1,
      "z": 3,
      "name": "Plant_Crop_Mushroom_Block_Boom_Low"
    },
    {
      "x": -2,
      "y": 2,
      "z": 3,
      "name": "Plant_Crop_Mushroom_Block_Boom"
    },
    {
      "x": -2,
      "y": 3,
      "z": 3,
      "name": "Plant_Crop_Mushroom_Block_Boom"
    },
    {
      "x": -1,
      "y": 1,
      "z": -2,
      "name": "Plant_Crop_Mushroom_Block_Boom_Low"
    },
    {
      "x": -1,
      "y": 2,
      "z": -2,
      "name": "Plant_Crop_Mushroom_Block_Boom"
    },
    {
      "x": -1,
      "y": 3,
      "z": -2,
      "name": "Plant_Crop_Mushroom_Block_Boom"
    },
    {
      "x": -1,
      "y": 3,
      "z": -1,
      "name": "Plant_Crop_Mushroom_Block_Boom"
    },
    {
      "x": -1,
      "y": 4,
      "z": -1,
      "name": "Plant_Crop_Mushroom_Block_Boom"
    },
    {
      "x": -1,
      "y": -1,
      "z": 0,
      "name": "Plant_Crop_Mushroom_Block_Purple_Trunk"
    },
    {
      "x": -1,
      "y": 0,
      "z": 0,
      "name": "Plant_Crop_Mushroom_Block_Purple_Trunk"
    },
    {
      "x": -1,
      "y": 1,
      "z": 0,
      "name": "Plant_Crop_Mushroom_Block_Purple_Trunk"
    },
    {
      "x": -1,
      "y": 2,
      "z": 0,
      "name": "Plant_Crop_Mushroom_Block_Purple_Trunk"
    },
    {
      "x": -1,
      "y": 3,
      "z": 0,
      "name": "Plant_Crop_Mushroom_Block_Purple_Trunk"
    },
    {
      "x": -1,
      "y": 4,
      "z": 0,
      "name": "Plant_Crop_Mushroom_Block_Boom"
    },
    {
      "x": -1,
      "y": -1,
      "z": 1,
      "name": "Plant_Crop_Mushroom_Block_Purple_Trunk"
    },
    {
      "x": -1,
      "y": 0,
      "z": 1,
      "name": "Plant_Crop_Mushroom_Block_Purple_Trunk"
    },
    {
      "x": -1,
      "y": 1,
      "z": 1,
      "name": "Plant_Crop_Mushroom_Block_Purple_Trunk"
    },
    {
      "x": -1,
      "y": 2,
      "z": 1,
      "name": "Plant_Crop_Mushroom_Block_Purple_Trunk"
    },
    {
      "x": -1,
      "y": 3,
      "z": 1,
      "name": "Plant_Crop_Mushroom_Block_Purple_Trunk"
    },
    {
      "x": -1,
      "y": 4,
      "z": 1,
      "name": "Plant_Crop_Mushroom_Block_Boom"
    },
    {
      "x": -1,
      "y": 3,
      "z": 2,
      "name": "Plant_Crop_Mushroom_Block_Boom"
    },
    {
      "x": -1,
      "y": 4,
      "z": 2,
      "name": "Plant_Crop_Mushroom_Block_Boom"
    },
    {
      "x": -1,
      "y": 1,
      "z": 3,
      "name": "Plant_Crop_Mushroom_Block_Boom_Low"
    },
    {
      "x": -1,
      "y": 2,
      "z": 3,
      "name": "Plant_Crop_Mushroom_Block_Boom"
    },
    {
      "x": -1,
      "y": 3,
      "z": 3,
      "name": "Plant_Crop_Mushroom_Block_Boom"
    },
    {
      "x": 0,
      "y": 1,
      "z": -2,
      "name": "Plant_Crop_Mushroom_Block_Boom_Low"
    },
    {
      "x": 0,
      "y": 2,
      "z": -2,
      "name": "Plant_Crop_Mushroom_Block_Boom"
    },
    {
      "x": 0,
      "y": 3,
      "z": -2,
      "name": "Plant_Crop_Mushroom_Block_Boom"
    },
    {
      "x": 0,
      "y": 3,
      "z": -1,
      "name": "Plant_Crop_Mushroom_Block_Boom"
    },
    {
      "x": 0,
      "y": 4,
      "z": -1,
      "name": "Plant_Crop_Mushroom_Block_Boom"
    },
    {
      "x": 0,
      "y": -1,
      "z": 0,
      "name": "Plant_Crop_Mushroom_Block_Purple_Trunk"
    },
    {
      "x": 0,
      "y": 0,
      "z": 0,
      "name": "Plant_Crop_Mushroom_Block_Purple_Trunk"
    },
    {
      "x": 0,
      "y": 1,
      "z": 0,
      "name": "Plant_Crop_Mushroom_Block_Purple_Trunk"
    },
    {
      "x": 0,
      "y": 2,
      "z": 0,
      "name": "Plant_Crop_Mushroom_Block_Purple_Trunk"
    },
    {
      "x": 0,
      "y": 3,
      "z": 0,
      "name": "Plant_Crop_Mushroom_Block_Purple_Trunk"
    },
    {
      "x": 0,
      "y": 4,
      "z": 0,
      "name": "Plant_Crop_Mushroom_Block_Boom"
    },
    {
      "x": 0,
      "y": -1,
      "z": 1,
      "name": "Plant_Crop_Mushroom_Block_Purple_Trunk"
    },
    {
      "x": 0,
      "y": 0,
      "z": 1,
      "name": "Plant_Crop_Mushroom_Block_Purple_Trunk"
    },
    {
      "x": 0,
      "y": 1,
      "z": 1,
      "name": "Plant_Crop_Mushroom_Block_Purple_Trunk"
    },
    {
      "x": 0,
      "y": 2,
      "z": 1,
      "name": "Plant_Crop_Mushroom_Block_Purple_Trunk"
    },
    {
      "x": 0,
      "y": 3,
      "z": 1,
      "name": "Plant_Crop_Mushroom_Block_Purple_Trunk"
    },
    {
      "x": 0,
      "y": 4,
      "z": 1,
      "name": "Plant_Crop_Mushroom_Block_Boom"
    },
    {
      "x": 0,
      "y": 3,
      "z": 2,
      "name": "Plant_Crop_Mushroom_Block_Boom"
    },
    {
      "x": 0,
      "y": 4,
      "z": 2,
      "name": "Plant_Crop_Mushroom_Block_Boom"
    },
    {
      "x": 0,
      "y": 1,
      "z": 3,
      "name": "Plant_Crop_Mushroom_Block_Boom_Low"
    },
    {
      "x": 0,
      "y": 2,
      "z": 3,
      "name": "Plant_Crop_Mushroom_Block_Boom"
    },
    {
      "x": 0,
      "y": 3,
      "z": 3,
      "name": "Plant_Crop_Mushroom_Block_Boom"
    },
    {
      "x": 1,
      "y": 1,
      "z": -2,
      "name": "Plant_Crop_Mushroom_Block_Boom_Low"
    },
    {
      "x": 1,
      "y": 2,
      "z": -2,
      "name": "Plant_Crop_Mushroom_Block_Boom"
    },
    {
      "x": 1,
      "y": 3,
      "z": -2,
      "name": "Plant_Crop_Mushroom_Block_Boom"
    },
    {
      "x": 1,
      "y": 1,
      "z": -1,
      "name": "Plant_Crop_Mushroom_Block_Boom_Low"
    },
    {
      "x": 1,
      "y": 2,
      "z": -1,
      "name": "Plant_Crop_Mushroom_Block_Boom"
    },
    {
      "x": 1,
      "y": 3,
      "z": -1,
      "name": "Plant_Crop_Mushroom_Block_Boom"
    },
    {
      "x": 1,
      "y": 3,
      "z": 0,
      "name": "Plant_Crop_Mushroom_Block_Boom"
    },
    {
      "x": 1,
      "y": 4,
      "z": 0,
      "name": "Plant_Crop_Mushroom_Block_Boom"
    },
    {
      "x": 1,
      "y": 3,
      "z": 1,
      "name": "Plant_Crop_Mushroom_Block_Boom"
    },
    {
      "x": 1,
      "y": 4,
      "z": 1,
      "name": "Plant_Crop_Mushroom_Block_Boom"
    },
    {
      "x": 1,
      "y": 1,
      "z": 2,
      "name": "Plant_Crop_Mushroom_Block_Boom_Low"
    },
    {
      "x": 1,
      "y": 2,
      "z": 2,
      "name": "Plant_Crop_Mushroom_Block_Boom"
    },
    {
      "x": 1,
      "y": 3,
      "z": 2,
      "name": "Plant_Crop_Mushroom_Block_Boom"
    },
    {
      "x": 1,
      "y": 1,
      "z": 3,
      "name": "Plant_Crop_Mushroom_Block_Boom_Low"
    },
    {
      "x": 1,
      "y": 2,
      "z": 3,
      "name": "Plant_Crop_Mushroom_Block_Boom"
    },
    {
      "x": 1,
      "y": 3,
      "z": 3,
      "name": "Plant_Crop_Mushroom_Block_Boom"
    },
    {
      "x": 2,
      "y": 1,
      "z": -1,
      "name": "Plant_Crop_Mushroom_Block_Boom_Low"
    },
    {
      "x": 2,
      "y": 2,
      "z": -1,
      "name": "Plant_Crop_Mushroom_Block_Boom"
    },
    {
      "x": 2,
      "y": 3,
      "z": -1,
      "name": "Plant_Crop_Mushroom_Block_Boom"
    },
    {
      "x": 2,
      "y": 1,
      "z": 0,
      "name": "Plant_Crop_Mushroom_Block_Boom_Low"
    },
    {
      "x": 2,
      "y": 2,
      "z": 0,
      "name": "Plant_Crop_Mushroom_Block_Boom"
    },
    {
      "x": 2,
      "y": 3,
      "z": 0,
      "name": "Plant_Crop_Mushroom_Block_Boom"
    },
    {
      "x": 2,
      "y": 1,
      "z": 1,
      "name": "Plant_Crop_Mushroom_Block_Boom_Low"
    },
    {
      "x": 2,
      "y": 2,
      "z": 1,
      "name": "Plant_Crop_Mushroom_Block_Boom"
    },
    {
      "x": 2,
      "y": 3,
      "z": 1,
      "name": "Plant_Crop_Mushroom_Block_Boom"
    },
    {
      "x": 2,
      "y": 1,
      "z": 2,
      "name": "Plant_Crop_Mushroom_Block_Boom_Low"
    },
    {
      "x": 2,
      "y": 2,
      "z": 2,
      "name": "Plant_Crop_Mushroom_Block_Boom"
    },
    {
      "x": 2,
      "y": 3,
      "z": 2,
      "name": "Plant_Crop_Mushroom_Block_Boom"
    }
  ]
}