{
  "version": 8,
  "blockIdVersion": 11,
  "anchorX": 0,
  "anchorY": 14,
  "anchorZ": 0,
  "blocks": [
    {
      "x": -7,
      "y": 0,
      "z": -7,
      "name": "Wood_Birch_Trunk_Full",
      "support": 15
    },
    {
      "x": -7,
      "y": 0,
      "z": -6,
      "name": "Wood_Birch_Trunk_Full",
      "support": 15
    },
    {
      "x": -6,
      "y": 0,
      "z": -6,
      "name": "Wood_Birch_Trunk_Full",
      "support": 15
    },
    {
      "x": -6,
      "y": 8,
      "z": -6,
      "name": "Wood_Birch_Trunk",
      "support": 15
    },
    {
      "x": -6,
      "y": 9,
      "z": -6,
      "name": "Wood_Birch_Trunk",
      "support": 15
    },
    {
      "x": -6,
      "y": 10,
      "z": -6,
      "name": "Wood_Birch_Trunk",
      "support": 15
    },
    {
      "x": -6,
      "y": 11,
      "z": -6,
      "name": "Wood_Birch_Trunk_Full",
      "support": 15
    },
    {
      "x": -6,
      "y": 0,
      "z": -5,
      "name": "Wood_Birch_Trunk_Full",
      "support": 15
    },
    {
      "x": -6,
      "y": 1,
      "z": -5,
      "name": "Wood_Birch_Trunk_Full",
      "support": 15
    },
    {
      "x": -6,
      "y": 4,
      "z": -5,
      "name": "Wood_Birch_Trunk",
      "support": 15
    },
    {
      "x": -6,
      "y": 5,
      "z": -5,
      "name": "Wood_Birch_Trunk",
      "support": 15
    },
    {
      "x": -6,
      "y": 6,
      "z": -5,
      "name": "Wood_Birch_Trunk",
      "support": 15
    },
    {
      "x": -6,
      "y": 7,
      "z": -5,
      "name": "Wood_Birch_Trunk",
      "support": 15
    },
    {
      "x": -6,
      "y": 8,
      "z": -5,
      "name": "Wood_Birch_Trunk",
      "support": 15
    },
    {
      "x": -6,
      "y": 9,
      "z": -5,
      "name": "Wood_Birch_Trunk",
      "support": 15
    },
    {
      "x": -6,
      "y": 10,
      "z": -5,
      "name": "Wood_Birch_Trunk",
      "support": 15
    },
    {
      "x": -6,
      "y": 11,
      "z": -5,
      "name": "Wood_Birch_Trunk",
      "support": 15
    },
    {
      "x": -6,
      "y": 12,
      "z": -5,
      "name": "Wood_Birch_Trunk_Full",
      "support": 15
    },
    {
      "x": -5,
      "y": 0,
      "z": -6,
      "name": "Wood_Birch_Trunk_Full",
      "support": 15
    },
    {
      "x": -5,
      "y": 1,
      "z": -6,
      "name": "Wood_Birch_Trunk_Full",
      "support": 15
    },
    {
      "x": -5,
      "y": 4,
      "z": -6,
      "name": "Wood_Birch_Trunk",
      "support": 15
    },
    {
      "x": -5,
      "y": 5,
      "z": -6,
      "name": "Wood_Birch_Trunk",
      "support": 15
    },
    {
      "x": -5,
      "y": 6,
      "z": -6,
      "name": "Wood_Birch_Trunk",
      "support": 15
    },
    {
      "x": -5,
      "y": 7,
      "z": -6,
      "name": "Wood_Birch_Trunk",
      "support": 15
    },
    {
      "x": -5,
      "y": 8,
      "z": -6,
      "name": "Wood_Birch_Trunk",
      "support": 15
    },
    {
      "x": -5,
      "y": 9,
      "z": -6,
      "name": "Wood_Birch_Trunk",
      "support": 15
    },
    {
      "x": -5,
      "y": 10,
      "z": -6,
      "name": "Wood_Birch_Trunk",
      "support": 15
    },
    {
      "x": -5,
      "y": 11,
      "z": -6,
      "name": "Wood_Birch_Trunk",
      "support": 15
    },
    {
      "x": -5,
      "y": 12,
      "z": -6,
      "name": "Wood_Birch_Trunk_Full",
      "support": 15
    },
    {
      "x": -5,
      "y": 0,
      "z": -5,
      "name": "Wood_Birch_Trunk_Full",
      "support": 15
    },
    {
      "x": -5,
      "y": 1,
      "z": -5,
      "name": "Wood_Birch_Trunk",
      "support": 15
    },
    {
      "x": -5,
      "y": 2,
      "z": -5,
      "name": "Wood_Birch_Trunk",
      "support": 15
    },
    {
      "x": -5,
      "y": 3,
      "z": -5,
      "name": "Wood_Birch_Trunk",
      "support": 15
    },
    {
      "x": -5,
      "y": 4,
      "z": -5,
      "name": "Wood_Birch_Trunk",
      "support": 15
    },
    {
      "x": -5,
      "y": 5,
      "z": -5,
      "name": "Wood_Birch_Trunk",
      "support": 15
    },
    {
      "x": -5,
      "y": 6,
      "z": -5,
      "name": "Wood_Birch_Trunk",
      "support": 15
    },
    {
      "x": -5,
      "y": 7,
      "z": -5,
      "name": "Wood_Birch_Trunk",
      "support": 15
    },
    {
      "x": -5,
      "y": 8,
      "z": -5,
      "name": "Wood_Birch_Trunk",
      "support": 15
    },
    {
      "x": -5,
      "y": 9,
      "z": -5,
      "name": "Wood_Birch_Trunk",
      "support": 15
    },
    {
      "x": -5,
      "y": 10,
      "z": -5,
      "name": "Wood_Birch_Trunk",
      "support": 15
    },
    {
      "x": -5,
      "y": 11,
      "z": -5,
      "name": "Wood_Birch_Trunk",
      "support": 15
    },
    {
      "x": -5,
      "y": 12,
      "z": -5,
      "name": "Wood_Birch_Trunk",
      "support": 15
    },
    {
      "x": -5,
      "y": 13,
      "z": -5,
      "name": "Wood_Birch_Trunk_Full",
      "support": 15
    },
    {
      "x": -5,
      "y": 1,
      "z": -4,
      "name": "Wood_Birch_Trunk_Full",
      "support": 15
    },
    {
      "x": -5,
      "y": 2,
      "z": -4,
      "name": "Wood_Birch_Trunk",
      "support": 15
    },
    {
      "x": -5,
      "y": 3,
      "z": -4,
      "name": "Wood_Birch_Trunk",
      "support": 15
    },
    {
      "x": -5,
      "y": 4,
      "z": -4,
      "name": "Wood_Birch_Trunk",
      "support": 15
    },
    {
      "x": -5,
      "y": 5,
      "z": -4,
      "name": "Wood_Birch_Trunk",
      "support": 15
    },
    {
      "x": -5,
      "y": 6,
      "z": -4,
      "name": "Wood_Birch_Trunk",
      "support": 15
    },
    {
      "x": -5,
      "y": 7,
      "z": -4,
      "name": "Wood_Birch_Trunk_Full",
      "support": 15
    },
    {
      "x": -5,
      "y": 10,
      "z": -4,
      "name": "Wood_Birch_Trunk_Full",
      "support": 15
    },
    {
      "x": -5,
      "y": 11,
      "z": -4,
      "name": "Wood_Birch_Trunk",
      "support": 15
    },
    {
      "x": -5,
      "y": 12,
      "z": -4,
      "name": "Wood_Birch_Trunk",
      "support": 15
    },
    {
      "x": -5,
      "y": 13,
      "z": -4,
      "name": "Wood_Birch_Trunk_Full",
      "support": 15
    },
    {
      "x": -4,
      "y": 1,
      "z": -5,
      "name": "Wood_Birch_Trunk_Full",
      "support": 15
    },
    {
      "x": -4,
      "y": 2,
      "z": -5,
      "name": "Wood_Birch_Trunk",
      "support": 15
    },
    {
      "x": -4,
      "y": 3,
      "z": -5,
      "name": "Wood_Birch_Trunk",
      "support": 15
    },
    {
      "x": -4,
      "y": 4,
      "z": -5,
      "name": "Wood_Birch_Trunk",
      "support": 15
    },
    {
      "x": -4,
      "y": 5,
      "z": -5,
      "name": "Wood_Birch_Trunk",
      "support": 15
    },
    {
      "x": -4,
      "y": 6,
      "z": -5,
      "name": "Wood_Birch_Trunk_Full",
      "support": 15
    },
    {
      "x": -4,
      "y": 10,
      "z": -5,
      "name": "Wood_Birch_Trunk_Full",
      "support": 15
    },
    {
      "x": -4,
      "y": 11,
      "z": -5,
      "name": "Wood_Birch_Trunk",
      "support": 15
    },
    {
      "x": -4,
      "y": 12,
      "z": -5,
      "name": "Wood_Birch_Trunk",
      "support": 15
    },
    {
      "x": -4,
      "y": 13,
      "z": -5,
      "name": "Wood_Birch_Trunk_Full",
      "support": 15
    },
    {
      "x": -4,
      "y": 3,
      "z": -4,
      "name": "Wood_Birch_Trunk_Full",
      "support": 15
    },
    {
      "x": -4,
      "y": 4,
      "z": -4,
      "name": "Wood_Birch_Trunk_Full",
      "support": 15
    },
    {
      "x": -4,
      "y": 11,
      "z": -4,
      "name": "Wood_Birch_Trunk_Full",
      "support": 15
    },
    {
      "x": -4,
      "y": 12,
      "z": -4,
      "name": "Wood_Birch_Trunk",
      "support": 15
    },
    {
      "x": -4,
      "y": 13,
      "z": -4,
      "name": "Wood_Birch_Trunk",
      "support": 15
    },
    {
      "x": -4,
      "y": 14,
      "z": -4,
      "name": "Wood_Birch_Trunk",
      "support": 15
    },
    {
      "x": -4,
      "y": 15,
      "z": -4,
      "name": "Wood_Birch_Trunk_Full",
      "support": 15
    },
    {
      "x": -4,
      "y": 12,
      "z": -3,
      "name": "Wood_Birch_Trunk_Full",
      "support": 15
    },
    {
      "x": -4,
      "y": 13,
      "z": -3,
      "name": "Wood_Birch_Trunk",
      "support": 15
    },
    {
      "x": -4,
      "y": 14,
      "z": -3,
      "name": "Wood_Birch_Trunk",
      "support": 15
    },
    {
      "x": -4,
      "y": 15,
      "z": -3,
      "name": "Wood_Birch_Trunk",
      "support": 15
    },
    {
      "x": -4,
      "y": 16,
      "z": -3,
      "name": "Wood_Birch_Trunk_Full",
      "support": 15
    },
    {
      "x": -4,
      "y": 14,
      "z": -1,
      "name": "Wood_Birch_Trunk_Full",
      "support": 15
    },
    {
      "x": -4,
      "y": 15,
      "z": -1,
      "name": "Wood_Birch_Trunk_Full",
      "support": 15
    },
    {
      "x": -4,
      "y": 2,
      "z": 0,
      "name": "Wood_Birch_Trunk_Full",
      "support": 15
    },
    {
      "x": -4,
      "y": 3,
      "z": 0,
      "name": "Wood_Birch_Trunk",
      "support": 15
    },
    {
      "x": -4,
      "y": 4,
      "z": 0,
      "name": "Wood_Birch_Trunk",
      "support": 15
    },
    {
      "x": -4,
      "y": 5,
      "z": 0,
      "name": "Wood_Birch_Trunk",
      "support": 15
    },
    {
      "x": -4,
      "y": 6,
      "z": 0,
      "name": "Wood_Birch_Trunk",
      "support": 15
    },
    {
      "x": -4,
      "y": 7,
      "z": 0,
      "name": "Wood_Birch_Trunk",
      "support": 15
    },
    {
      "x": -4,
      "y": 8,
      "z": 0,
      "name": "Wood_Birch_Trunk_Full",
      "support": 15
    },
    {
      "x": -4,
      "y": 10,
      "z": 0,
      "name": "Wood_Birch_Trunk_Full",
      "support": 15
    },
    {
      "x": -4,
      "y": 11,
      "z": 0,
      "name": "Wood_Birch_Trunk",
      "support": 15
    },
    {
      "x": -4,
      "y": 12,
      "z": 0,
      "name": "Wood_Birch_Trunk",
      "support": 15
    },
    {
      "x": -4,
      "y": 13,
      "z": 0,
      "name": "Wood_Birch_Trunk",
      "support": 15
    },
    {
      "x": -4,
      "y": 14,
      "z": 0,
      "name": "Wood_Birch_Trunk",
      "support": 15
    },
    {
      "x": -4,
      "y": 15,
      "z": 0,
      "name": "Wood_Birch_Trunk",
      "support": 15
    },
    {
      "x": -4,
      "y": 16,
      "z": 0,
      "name": "Wood_Birch_Trunk_Full",
      "support": 15
    },
    {
      "x": -4,
      "y": 2,
      "z": 1,
      "name": "Wood_Birch_Trunk_Full",
      "support": 15
    },
    {
      "x": -4,
      "y": 3,
      "z": 1,
      "name": "Wood_Birch_Trunk",
      "support": 15
    },
    {
      "x": -4,
      "y": 4,
      "z": 1,
      "name": "Wood_Birch_Trunk",
      "support": 15
    },
    {
      "x": -4,
      "y": 5,
      "z": 1,
      "name": "Wood_Birch_Trunk",
      "support": 15
    },
    {
      "x": -4,
      "y": 6,
      "z": 1,
      "name": "Wood_Birch_Trunk_Full",
      "support": 15
    },
    {
      "x": -4,
      "y": 12,
      "z": 1,
      "name": "Wood_Birch_Trunk_Full",
      "support": 15
    },
    {
      "x": -4,
      "y": 13,
      "z": 1,
      "name": "Wood_Birch_Trunk",
      "support": 15
    },
    {
      "x": -4,
      "y": 14,
      "z": 1,
      "name": "Wood_Birch_Trunk_Full",
      "support": 15
    },
    {
      "x": -3,
      "y": 12,
      "z": -4,
      "name": "Wood_Birch_Trunk_Full",
      "support": 15
    },
    {
      "x": -3,
      "y": 13,
      "z": -4,
      "name": "Wood_Birch_Trunk",
      "support": 15
    },
    {
      "x": -3,
      "y": 14,
      "z": -4,
      "name": "Wood_Birch_Trunk",
      "support": 15
    },
    {
      "x": -3,
      "y": 15,
      "z": -4,
      "name": "Wood_Birch_Trunk",
      "support": 15
    },
    {
      "x": -3,
      "y": 16,
      "z": -4,
      "name": "Wood_Birch_Trunk_Full",
      "support": 15
    },
    {
      "x": -3,
      "y": 12,
      "z": -3,
      "name": "Wood_Birch_Trunk_Full",
      "support": 15
    },
    {
      "x": -3,
      "y": 13,
      "z": -3,
      "name": "Wood_Birch_Trunk",
      "support": 15
    },
    {
      "x": -3,
      "y": 14,
      "z": -3,
      "name": "Wood_Birch_Trunk",
      "support": 15
    },
    {
      "x": -3,
      "y": 15,
      "z": -3,
      "name": "Wood_Birch_Trunk",
      "support": 15
    },
    {
      "x": -3,
      "y": 16,
      "z": -3,
      "name": "Wood_Birch_Trunk",
      "support": 15
    },
    {
      "x": -3,
      "y": 17,
      "z": -3,
      "name": "Wood_Birch_Trunk_Full",
      "support": 15
    },
    {
      "x": -3,
      "y": 14,
      "z": -2,
      "name": "Wood_Birch_Trunk_Full",
      "support": 15
    },
    {
      "x": -3,
      "y": 15,
      "z": -2,
      "name": "Wood_Birch_Trunk",
      "support": 15
    },
    {
      "x": -3,
      "y": 16,
      "z": -2,
      "name": "Wood_Birch_Trunk",
      "support": 15
    },
    {
      "x": -3,
      "y": 17,
      "z": -2,
      "name": "Wood_Birch_Trunk_Full",
      "support": 15
    },
    {
      "x": -3,
      "y": 8,
      "z": -1,
      "name": "Wood_Birch_Trunk_Full",
      "support": 15
    },
    {
      "x": -3,
      "y": 9,
      "z": -1,
      "name": "Wood_Birch_Trunk",
      "support": 15
    },
    {
      "x": -3,
      "y": 10,
      "z": -1,
      "name": "Wood_Birch_Trunk",
      "support": 15
    },
    {
      "x": -3,
      "y": 11,
      "z": -1,
      "name": "Wood_Birch_Trunk_Full",
      "support": 15,
      "rotation": 5
    },
    {
      "x": -3,
      "y": 14,
      "z": -1,
      "name": "Wood_Birch_Trunk_Full",
      "support": 15
    },
    {
      "x": -3,
      "y": 15,
      "z": -1,
      "name": "Wood_Birch_Trunk"
    },
    {
      "x": -3,
      "y": 16,
      "z": -1,
      "name": "Wood_Birch_Trunk"
    },
    {
      "x": -3,
      "y": 17,
      "z": -1,
      "name": "Wood_Birch_Trunk"
    },
    {
      "x": -3,
      "y": 18,
      "z": -1,
      "name": "Wood_Birch_Trunk"
    },
    {
      "x": -3,
      "y": 19,
      "z": -1,
      "name": "Wood_Birch_Trunk"
    },
    {
      "x": -3,
      "y": 20,
      "z": -1,
      "name": "Wood_Birch_Trunk"
    },
    {
      "x": -3,
      "y": 21,
      "z": -1,
      "name": "Wood_Birch_Trunk"
    },
    {
      "x": -3,
      "y": 22,
      "z": -1,
      "name": "Wood_Birch_Trunk",
      "support": 15
    },
    {
      "x": -3,
      "y": 23,
      "z": -1,
      "name": "Wood_Birch_Trunk_Full",
      "support": 15
    },
    {
      "x": -3,
      "y": 1,
      "z": 0,
      "name": "Wood_Birch_Trunk_Full",
      "support": 15
    },
    {
      "x": -3,
      "y": 2,
      "z": 0,
      "name": "Wood_Birch_Trunk_Full",
      "support": 15
    },
    {
      "x": -3,
      "y": 6,
      "z": 0,
      "name": "Wood_Birch_Trunk_Full",
      "support": 15
    },
    {
      "x": -3,
      "y": 7,
      "z": 0,
      "name": "Wood_Birch_Trunk",
      "support": 15
    },
    {
      "x": -3,
      "y": 8,
      "z": 0,
      "name": "Wood_Birch_Trunk",
      "support": 15
    },
    {
      "x": -3,
      "y": 9,
      "z": 0,
      "name": "Wood_Birch_Trunk",
      "support": 15
    },
    {
      "x": -3,
      "y": 10,
      "z": 0,
      "name": "Wood_Birch_Trunk",
      "support": 15
    },
    {
      "x": -3,
      "y": 11,
      "z": 0,
      "name": "Wood_Birch_Trunk",
      "support": 15
    },
    {
      "x": -3,
      "y": 12,
      "z": 0,
      "name": "Wood_Birch_Trunk",
      "support": 15
    },
    {
      "x": -3,
      "y": 13,
      "z": 0,
      "name": "Wood_Birch_Trunk",
      "support": 15
    },
    {
      "x": -3,
      "y": 14,
      "z": 0,
      "name": "Wood_Birch_Trunk"
    },
    {
      "x": -3,
      "y": 15,
      "z": 0,
      "name": "Wood_Birch_Trunk"
    },
    {
      "x": -3,
      "y": 16,
      "z": 0,
      "name": "Wood_Birch_Trunk"
    },
    {
      "x": -3,
      "y": 17,
      "z": 0,
      "name": "Wood_Birch_Trunk"
    },
    {
      "x": -3,
      "y": 18,
      "z": 0,
      "name": "Wood_Birch_Trunk"
    },
    {
      "x": -3,
      "y": 19,
      "z": 0,
      "name": "Wood_Birch_Trunk"
    },
    {
      "x": -3,
      "y": 20,
      "z": 0,
      "name": "Wood_Birch_Trunk"
    },
    {
      "x": -3,
      "y": 21,
      "z": 0,
      "name": "Wood_Birch_Trunk"
    },
    {
      "x": -3,
      "y": 22,
      "z": 0,
      "name": "Wood_Birch_Trunk_Full",
      "support": 15
    },
    {
      "x": -3,
      "y": 5,
      "z": 1,
      "name": "Wood_Birch_Trunk_Full",
      "support": 15
    },
    {
      "x": -3,
      "y": 6,
      "z": 1,
      "name": "Wood_Birch_Trunk",
      "support": 15
    },
    {
      "x": -3,
      "y": 7,
      "z": 1,
      "name": "Wood_Birch_Trunk_Full",
      "support": 15
    },
    {
      "x": -3,
      "y": 11,
      "z": 1,
      "name": "Wood_Birch_Trunk_Full",
      "support": 15
    },
    {
      "x": -3,
      "y": 12,
      "z": 1,
      "name": "Wood_Birch_Trunk",
      "support": 15
    },
    {
      "x": -3,
      "y": 13,
      "z": 1,
      "name": "Wood_Birch_Trunk",
      "support": 15
    },
    {
      "x": -3,
      "y": 14,
      "z": 1,
      "name": "Wood_Birch_Trunk"
    },
    {
      "x": -3,
      "y": 15,
      "z": 1,
      "name": "Wood_Birch_Trunk"
    },
    {
      "x": -3,
      "y": 16,
      "z": 1,
      "name": "Wood_Birch_Trunk"
    },
    {
      "x": -3,
      "y": 17,
      "z": 1,
      "name": "Wood_Birch_Trunk"
    },
    {
      "x": -3,
      "y": 18,
      "z": 1,
      "name": "Wood_Birch_Trunk"
    },
    {
      "x": -3,
      "y": 19,
      "z": 1,
      "name": "Wood_Birch_Trunk"
    },
    {
      "x": -3,
      "y": 20,
      "z": 1,
      "name": "Wood_Birch_Trunk"
    },
    {
      "x": -3,
      "y": 21,
      "z": 1,
      "name": "Wood_Birch_Trunk"
    },
    {
      "x": -3,
      "y": 22,
      "z": 1,
      "name": "Wood_Birch_Trunk_Full",
      "support": 15
    },
    {
      "x": -3,
      "y": 5,
      "z": 4,
      "name": "Wood_Birch_Trunk_Full",
      "support": 15
    },
    {
      "x": -3,
      "y": 6,
      "z": 4,
      "name": "Wood_Birch_Trunk",
      "support": 15
    },
    {
      "x": -3,
      "y": 7,
      "z": 4,
      "name": "Wood_Birch_Trunk_Full",
      "support": 15
    },
    {
      "x": -3,
      "y": 5,
      "z": 5,
      "name": "Wood_Birch_Trunk_Full",
      "support": 15
    },
    {
      "x": -3,
      "y": 6,
      "z": 5,
      "name": "Wood_Birch_Trunk",
      "support": 15
    },
    {
      "x": -3,
      "y": 7,
      "z": 5,
      "name": "Wood_Birch_Trunk",
      "support": 15
    },
    {
      "x": -3,
      "y": 8,
      "z": 5,
      "name": "Wood_Birch_Trunk",
      "support": 15
    },
    {
      "x": -3,
      "y": 9,
      "z": 5,
      "name": "Wood_Birch_Trunk_Full",
      "support": 15
    },
    {
      "x": -2,
      "y": 13,
      "z": -3,
      "name": "Wood_Birch_Trunk_Full",
      "support": 15
    },
    {
      "x": -2,
      "y": 14,
      "z": -3,
      "name": "Wood_Birch_Trunk",
      "support": 15
    },
    {
      "x": -2,
      "y": 15,
      "z": -3,
      "name": "Wood_Birch_Trunk",
      "support": 15
    },
    {
      "x": -2,
      "y": 16,
      "z": -3,
      "name": "Wood_Birch_Trunk",
      "support": 15
    },
    {
      "x": -2,
      "y": 17,
      "z": -3,
      "name": "Wood_Birch_Trunk_Full",
      "support": 15
    },
    {
      "x": -2,
      "y": 18,
      "z": -3,
      "name": "Wood_Birch_Trunk_Full",
      "support": 15
    },
    {
      "x": -2,
      "y": 14,
      "z": -2,
      "name": "Wood_Birch_Trunk_Full",
      "support": 15
    },
    {
      "x": -2,
      "y": 15,
      "z": -2,
      "name": "Wood_Birch_Trunk"
    },
    {
      "x": -2,
      "y": 16,
      "z": -2,
      "name": "Wood_Birch_Trunk"
    },
    {
      "x": -2,
      "y": 17,
      "z": -2,
      "name": "Wood_Birch_Trunk"
    },
    {
      "x": -2,
      "y": 18,
      "z": -2,
      "name": "Wood_Birch_Trunk"
    },
    {
      "x": -2,
      "y": 19,
      "z": -2,
      "name": "Wood_Birch_Trunk"
    },
    {
      "x": -2,
      "y": 20,
      "z": -2,
      "name": "Wood_Birch_Trunk"
    },
    {
      "x": -2,
      "y": 21,
      "z": -2,
      "name": "Wood_Birch_Trunk"
    },
    {
      "x": -2,
      "y": 22,
      "z": -2,
      "name": "Wood_Birch_Trunk",
      "support": 15
    },
    {
      "x": -2,
      "y": 23,
      "z": -2,
      "name": "Wood_Birch_Trunk_Full",
      "support": 15
    },
    {
      "x": -2,
      "y": 1,
      "z": -1,
      "name": "Wood_Birch_Trunk_Full",
      "support": 15
    },
    {
      "x": -2,
      "y": 9,
      "z": -1,
      "name": "Wood_Birch_Trunk_Full",
      "support": 15
    },
    {
      "x": -2,
      "y": 10,
      "z": -1,
      "name": "Wood_Birch_Trunk",
      "support": 15
    },
    {
      "x": -2,
      "y": 11,
      "z": -1,
      "name": "Wood_Birch_Trunk",
      "support": 15
    },
    {
      "x": -2,
      "y": 12,
      "z": -1,
      "name": "Wood_Birch_Trunk",
      "support": 15
    },
    {
      "x": -2,
      "y": 13,
      "z": -1,
      "name": "Wood_Birch_Trunk",
      "support": 15
    },
    {
      "x": -2,
      "y": 14,
      "z": -1,
      "name": "Wood_Birch_Trunk_Full",
      "support": 15
    },
    {
      "x": -2,
      "y": 15,
      "z": -1,
      "name": "Wood_Birch_Trunk_Full",
      "support": 15
    },
    {
      "x": -2,
      "y": 16,
      "z": -1,
      "name": "Empty"
    },
    {
      "x": -2,
      "y": 17,
      "z": -1,
      "name": "Empty"
    },
    {
      "x": -2,
      "y": 18,
      "z": -1,
      "name": "Wood_Birch_Trunk",
      "support": 1
    },
    {
      "x": -2,
      "y": 19,
      "z": -1,
      "name": "Wood_Birch_Trunk"
    },
    {
      "x": -2,
      "y": 20,
      "z": -1,
      "name": "Wood_Birch_Trunk"
    },
    {
      "x": -2,
      "y": 21,
      "z": -1,
      "name": "Wood_Birch_Trunk"
    },
    {
      "x": -2,
      "y": 22,
      "z": -1,
      "name": "Plant_Petals_Storm"
    },
    {
      "x": -2,
      "y": 1,
      "z": 0,
      "name": "Wood_Birch_Trunk_Full",
      "support": 15
    },
    {
      "x": -2,
      "y": 7,
      "z": 0,
      "name": "Wood_Birch_Trunk_Full",
      "support": 15
    },
    {
      "x": -2,
      "y": 8,
      "z": 0,
      "name": "Wood_Birch_Trunk",
      "support": 15
    },
    {
      "x": -2,
      "y": 9,
      "z": 0,
      "name": "Wood_Birch_Trunk",
      "support": 15
    },
    {
      "x": -2,
      "y": 10,
      "z": 0,
      "name": "Wood_Birch_Trunk",
      "support": 15
    },
    {
      "x": -2,
      "y": 11,
      "z": 0,
      "name": "Wood_Birch_Trunk",
      "support": 15
    },
    {
      "x": -2,
      "y": 12,
      "z": 0,
      "name": "Wood_Birch_Trunk",
      "support": 15
    },
    {
      "x": -2,
      "y": 13,
      "z": 0,
      "name": "Wood_Birch_Trunk_Full",
      "support": 15
    },
    {
      "x": -2,
      "y": 14,
      "z": 0,
      "name": "Wood_Birch_Trunk"
    },
    {
      "x": -2,
      "y": 15,
      "z": 0,
      "name": "Rock_Marble_SkyGrass"
    },
    {
      "x": -2,
      "y": 16,
      "z": 0,
      "name": "Plant_Crop_Stamina2"
    },
    {
      "x": -2,
      "y": 17,
      "z": 0,
      "name": "Empty"
    },
    {
      "x": -2,
      "y": 18,
      "z": 0,
      "name": "Wood_Birch_Trunk",
      "support": 1
    },
    {
      "x": -2,
      "y": 19,
      "z": 0,
      "name": "Wood_Birch_Trunk"
    },
    {
      "x": -2,
      "y": 20,
      "z": 0,
      "name": "Wood_Birch_Trunk"
    },
    {
      "x": -2,
      "y": 21,
      "z": 0,
      "name": "Wood_Birch_Trunk"
    },
    {
      "x": -2,
      "y": 22,
      "z": 0,
      "name": "Empty"
    },
    {
      "x": -2,
      "y": 14,
      "z": 1,
      "name": "Wood_Birch_Trunk_Full",
      "support": 15
    },
    {
      "x": -2,
      "y": 15,
      "z": 1,
      "name": "Wood_Birch_Trunk"
    },
    {
      "x": -2,
      "y": 16,
      "z": 1,
      "name": "Wood_Birch_Trunk"
    },
    {
      "x": -2,
      "y": 17,
      "z": 1,
      "name": "Wood_Birch_Trunk"
    },
    {
      "x": -2,
      "y": 18,
      "z": 1,
      "name": "Wood_Birch_Trunk"
    },
    {
      "x": -2,
      "y": 19,
      "z": 1,
      "name": "Wood_Birch_Trunk"
    },
    {
      "x": -2,
      "y": 20,
      "z": 1,
      "name": "Wood_Birch_Trunk"
    },
    {
      "x": -2,
      "y": 21,
      "z": 1,
      "name": "Wood_Birch_Trunk"
    },
    {
      "x": -2,
      "y": 22,
      "z": 1,
      "name": "Empty"
    },
    {
      "x": -2,
      "y": 14,
      "z": 2,
      "name": "Wood_Birch_Trunk_Full",
      "support": 15
    },
    {
      "x": -2,
      "y": 15,
      "z": 2,
      "name": "Wood_Birch_Trunk"
    },
    {
      "x": -2,
      "y": 16,
      "z": 2,
      "name": "Wood_Birch_Trunk"
    },
    {
      "x": -2,
      "y": 17,
      "z": 2,
      "name": "Wood_Birch_Trunk"
    },
    {
      "x": -2,
      "y": 18,
      "z": 2,
      "name": "Wood_Birch_Trunk"
    },
    {
      "x": -2,
      "y": 19,
      "z": 2,
      "name": "Wood_Birch_Trunk"
    },
    {
      "x": -2,
      "y": 20,
      "z": 2,
      "name": "Wood_Birch_Trunk_Full",
      "support": 15
    },
    {
      "x": -2,
      "y": 21,
      "z": 2,
      "name": "Wood_Birch_Trunk_Full",
      "support": 15
    },
    {
      "x": -2,
      "y": 22,
      "z": 2,
      "name": "Wood_Birch_Trunk_Full",
      "support": 15
    },
    {
      "x": -2,
      "y": 15,
      "z": 3,
      "name": "Wood_Birch_Trunk_Full",
      "support": 15
    },
    {
      "x": -2,
      "y": 16,
      "z": 3,
      "name": "Wood_Birch_Trunk",
      "support": 15
    },
    {
      "x": -2,
      "y": 17,
      "z": 3,
      "name": "Wood_Birch_Trunk_Full",
      "support": 15
    },
    {
      "x": -2,
      "y": 5,
      "z": 4,
      "name": "Wood_Birch_Trunk_Full",
      "support": 15
    },
    {
      "x": -2,
      "y": 6,
      "z": 4,
      "name": "Wood_Birch_Trunk",
      "support": 15
    },
    {
      "x": -2,
      "y": 7,
      "z": 4,
      "name": "Wood_Birch_Trunk",
      "support": 15
    },
    {
      "x": -2,
      "y": 8,
      "z": 4,
      "name": "Wood_Birch_Trunk_Full",
      "support": 15
    },
    {
      "x": -2,
      "y": 12,
      "z": 4,
      "name": "Wood_Birch_Trunk_Full",
      "support": 15
    },
    {
      "x": -2,
      "y": 13,
      "z": 4,
      "name": "Wood_Birch_Trunk",
      "support": 15
    },
    {
      "x": -2,
      "y": 14,
      "z": 4,
      "name": "Wood_Birch_Trunk",
      "support": 15
    },
    {
      "x": -2,
      "y": 15,
      "z": 4,
      "name": "Wood_Birch_Trunk",
      "support": 15
    },
    {
      "x": -2,
      "y": 16,
      "z": 4,
      "name": "Wood_Birch_Trunk",
      "support": 15
    },
    {
      "x": -2,
      "y": 17,
      "z": 4,
      "name": "Wood_Birch_Trunk_Full",
      "support": 15
    },
    {
      "x": -2,
      "y": 3,
      "z": 5,
      "name": "Wood_Birch_Trunk_Full",
      "support": 15
    },
    {
      "x": -2,
      "y": 4,
      "z": 5,
      "name": "Wood_Birch_Trunk",
      "support": 15
    },
    {
      "x": -2,
      "y": 5,
      "z": 5,
      "name": "Wood_Birch_Trunk",
      "support": 15
    },
    {
      "x": -2,
      "y": 6,
      "z": 5,
      "name": "Wood_Birch_Trunk",
      "support": 15
    },
    {
      "x": -2,
      "y": 7,
      "z": 5,
      "name": "Wood_Birch_Trunk",
      "support": 15
    },
    {
      "x": -2,
      "y": 8,
      "z": 5,
      "name": "Wood_Birch_Trunk",
      "support": 15
    },
    {
      "x": -2,
      "y": 9,
      "z": 5,
      "name": "Wood_Birch_Trunk",
      "support": 15
    },
    {
      "x": -2,
      "y": 10,
      "z": 5,
      "name": "Wood_Birch_Trunk",
      "support": 15
    },
    {
      "x": -2,
      "y": 11,
      "z": 5,
      "name": "Wood_Birch_Trunk",
      "support": 15
    },
    {
      "x": -2,
      "y": 12,
      "z": 5,
      "name": "Wood_Birch_Trunk",
      "support": 15
    },
    {
      "x": -2,
      "y": 13,
      "z": 5,
      "name": "Wood_Birch_Trunk",
      "support": 15
    },
    {
      "x": -2,
      "y": 14,
      "z": 5,
      "name": "Wood_Birch_Trunk",
      "support": 15
    },
    {
      "x": -2,
      "y": 15,
      "z": 5,
      "name": "Wood_Birch_Trunk",
      "support": 15
    },
    {
      "x": -2,
      "y": 16,
      "z": 5,
      "name": "Wood_Birch_Trunk_Full",
      "support": 15
    },
    {
      "x": -2,
      "y": 3,
      "z": 6,
      "name": "Wood_Birch_Trunk_Full",
      "support": 15
    },
    {
      "x": -2,
      "y": 4,
      "z": 6,
      "name": "Wood_Birch_Trunk_Full",
      "support": 15
    },
    {
      "x": -2,
      "y": 7,
      "z": 6,
      "name": "Wood_Birch_Trunk_Full",
      "support": 15
    },
    {
      "x": -2,
      "y": 8,
      "z": 6,
      "name": "Wood_Birch_Trunk",
      "support": 15
    },
    {
      "x": -2,
      "y": 9,
      "z": 6,
      "name": "Wood_Birch_Trunk",
      "support": 15
    },
    {
      "x": -2,
      "y": 10,
      "z": 6,
      "name": "Wood_Birch_Trunk",
      "support": 15
    },
    {
      "x": -2,
      "y": 11,
      "z": 6,
      "name": "Wood_Birch_Trunk",
      "support": 15
    },
    {
      "x": -2,
      "y": 12,
      "z": 6,
      "name": "Wood_Birch_Trunk_Full",
      "support": 15
    },
    {
      "x": -1,
      "y": 12,
      "z": -4,
      "name": "Wood_Birch_Trunk_Full",
      "support": 15
    },
    {
      "x": -1,
      "y": 13,
      "z": -4,
      "name": "Wood_Birch_Trunk",
      "support": 15
    },
    {
      "x": -1,
      "y": 14,
      "z": -4,
      "name": "Wood_Birch_Trunk_Full",
      "support": 15
    },
    {
      "x": -1,
      "y": 11,
      "z": -3,
      "name": "Wood_Birch_Trunk_Full",
      "support": 15
    },
    {
      "x": -1,
      "y": 12,
      "z": -3,
      "name": "Wood_Birch_Trunk",
      "support": 15
    },
    {
      "x": -1,
      "y": 13,
      "z": -3,
      "name": "Wood_Birch_Trunk",
      "support": 15
    },
    {
      "x": -1,
      "y": 14,
      "z": -3,
      "name": "Wood_Birch_Trunk"
    },
    {
      "x": -1,
      "y": 15,
      "z": -3,
      "name": "Wood_Birch_Trunk"
    },
    {
      "x": -1,
      "y": 16,
      "z": -3,
      "name": "Wood_Birch_Trunk"
    },
    {
      "x": -1,
      "y": 17,
      "z": -3,
      "name": "Wood_Birch_Trunk"
    },
    {
      "x": -1,
      "y": 18,
      "z": -3,
      "name": "Wood_Birch_Trunk"
    },
    {
      "x": -1,
      "y": 19,
      "z": -3,
      "name": "Wood_Birch_Trunk"
    },
    {
      "x": -1,
      "y": 20,
      "z": -3,
      "name": "Wood_Birch_Trunk"
    },
    {
      "x": -1,
      "y": 21,
      "z": -3,
      "name": "Wood_Birch_Trunk"
    },
    {
      "x": -1,
      "y": 22,
      "z": -3,
      "name": "Wood_Birch_Trunk_Full",
      "support": 15
    },
    {
      "x": -1,
      "y": 13,
      "z": -2,
      "name": "Wood_Birch_Trunk_Full",
      "support": 15
    },
    {
      "x": -1,
      "y": 14,
      "z": -2,
      "name": "Wood_Birch_Trunk"
    },
    {
      "x": -1,
      "y": 15,
      "z": -2,
      "name": "Wood_Birch_Trunk",
      "support": 15
    },
    {
      "x": -1,
      "y": 16,
      "z": -2,
      "name": "Plant_Grass_Cave_Short",
      "support": 15
    },
    {
      "x": -1,
      "y": 17,
      "z": -2,
      "name": "Empty"
    },
    {
      "x": -1,
      "y": 18,
      "z": -2,
      "name": "Wood_Birch_Trunk",
      "support": 1
    },
    {
      "x": -1,
      "y": 19,
      "z": -2,
      "name": "Wood_Birch_Trunk"
    },
    {
      "x": -1,
      "y": 20,
      "z": -2,
      "name": "Wood_Birch_Trunk"
    },
    {
      "x": -1,
      "y": 21,
      "z": -2,
      "name": "Rock_Marble_SkyGrass"
    },
    {
      "x": -1,
      "y": 22,
      "z": -2,
      "name": "Plant_Crop_Stamina2"
    },
    {
      "x": -1,
      "y": 13,
      "z": -1,
      "name": "Wood_Birch_Trunk_Full",
      "support": 15
    },
    {
      "x": -1,
      "y": 14,
      "z": -1,
      "name": "Wood_Birch_Trunk"
    },
    {
      "x": -1,
      "y": 15,
      "z": -1,
      "name": "Empty"
    },
    {
      "x": -1,
      "y": 16,
      "z": -1,
      "name": "Empty"
    },
    {
      "x": -1,
      "y": 17,
      "z": -1,
      "name": "Empty"
    },
    {
      "x": -1,
      "y": 18,
      "z": -1,
      "name": "Empty"
    },
    {
      "x": -1,
      "y": 19,
      "z": -1,
      "name": "Wood_Birch_Trunk",
      "support": 1
    },
    {
      "x": -1,
      "y": 20,
      "z": -1,
      "name": "Wood_Birch_Trunk"
    },
    {
      "x": -1,
      "y": 21,
      "z": -1,
      "name": "Wood_Birch_Trunk"
    },
    {
      "x": -1,
      "y": 22,
      "z": -1,
      "name": "Empty"
    },
    {
      "x": -1,
      "y": 12,
      "z": 0,
      "name": "Wood_Birch_Trunk_Full",
      "support": 15
    },
    {
      "x": -1,
      "y": 13,
      "z": 0,
      "name": "Wood_Birch_Trunk",
      "support": 15
    },
    {
      "x": -1,
      "y": 14,
      "z": 0,
      "name": "Wood_Birch_Trunk"
    },
    {
      "x": -1,
      "y": 15,
      "z": 0,
      "name": "Empty"
    },
    {
      "x": -1,
      "y": 16,
      "z": 0,
      "name": "Empty"
    },
    {
      "x": -1,
      "y": 17,
      "z": 0,
      "name": "Empty"
    },
    {
      "x": -1,
      "y": 18,
      "z": 0,
      "name": "Empty"
    },
    {
      "x": -1,
      "y": 19,
      "z": 0,
      "name": "Wood_Birch_Trunk",
      "support": 15
    },
    {
      "x": -1,
      "y": 20,
      "z": 0,
      "name": "Wood_Birch_Trunk"
    },
    {
      "x": -1,
      "y": 21,
      "z": 0,
      "name": "Wood_Birch_Trunk",
      "support": 15
    },
    {
      "x": -1,
      "y": 22,
      "z": 0,
      "name": "Empty"
    },
    {
      "x": -1,
      "y": 13,
      "z": 1,
      "name": "Wood_Birch_Trunk_Full",
      "support": 15
    },
    {
      "x": -1,
      "y": 14,
      "z": 1,
      "name": "Wood_Birch_Trunk"
    },
    {
      "x": -1,
      "y": 15,
      "z": 1,
      "name": "Plant_Grass_Cave_Short",
      "support": 15
    },
    {
      "x": -1,
      "y": 16,
      "z": 1,
      "name": "Plant_Crop_Mushroom_Shelve_Yellow"
    },
    {
      "x": -1,
      "y": 17,
      "z": 1,
      "name": "Empty"
    },
    {
      "x": -1,
      "y": 18,
      "z": 1,
      "name": "Wood_Birch_Trunk",
      "support": 15
    },
    {
      "x": -1,
      "y": 19,
      "z": 1,
      "name": "Wood_Birch_Trunk",
      "support": 15
    },
    {
      "x": -1,
      "y": 20,
      "z": 1,
      "name": "Wood_Birch_Trunk"
    },
    {
      "x": -1,
      "y": 21,
      "z": 1,
      "name": "Wood_Birch_Trunk"
    },
    {
      "x": -1,
      "y": 22,
      "z": 1,
      "name": "Empty"
    },
    {
      "x": -1,
      "y": 13,
      "z": 2,
      "name": "Wood_Birch_Trunk_Full",
      "support": 15
    },
    {
      "x": -1,
      "y": 14,
      "z": 2,
      "name": "Wood_Birch_Trunk"
    },
    {
      "x": -1,
      "y": 15,
      "z": 2,
      "name": "Wood_Birch_Trunk"
    },
    {
      "x": -1,
      "y": 16,
      "z": 2,
      "name": "Wood_Birch_Trunk"
    },
    {
      "x": -1,
      "y": 17,
      "z": 2,
      "name": "Wood_Birch_Trunk"
    },
    {
      "x": -1,
      "y": 18,
      "z": 2,
      "name": "Wood_Birch_Trunk"
    },
    {
      "x": -1,
      "y": 19,
      "z": 2,
      "name": "Wood_Birch_Trunk"
    },
    {
      "x": -1,
      "y": 20,
      "z": 2,
      "name": "Wood_Birch_Trunk"
    },
    {
      "x": -1,
      "y": 21,
      "z": 2,
      "name": "Wood_Birch_Trunk"
    },
    {
      "x": -1,
      "y": 22,
      "z": 2,
      "name": "Empty"
    },
    {
      "x": -1,
      "y": 14,
      "z": 3,
      "name": "Wood_Birch_Trunk_Full",
      "support": 15
    },
    {
      "x": -1,
      "y": 15,
      "z": 3,
      "name": "Wood_Birch_Trunk"
    },
    {
      "x": -1,
      "y": 16,
      "z": 3,
      "name": "Wood_Birch_Trunk"
    },
    {
      "x": -1,
      "y": 17,
      "z": 3,
      "name": "Wood_Birch_Trunk"
    },
    {
      "x": -1,
      "y": 18,
      "z": 3,
      "name": "Wood_Birch_Trunk"
    },
    {
      "x": -1,
      "y": 19,
      "z": 3,
      "name": "Wood_Birch_Trunk"
    },
    {
      "x": -1,
      "y": 20,
      "z": 3,
      "name": "Wood_Birch_Trunk"
    },
    {
      "x": -1,
      "y": 21,
      "z": 3,
      "name": "Wood_Birch_Trunk_Full",
      "support": 15
    },
    {
      "x": -1,
      "y": 12,
      "z": 4,
      "name": "Wood_Birch_Trunk_Full",
      "support": 15
    },
    {
      "x": -1,
      "y": 13,
      "z": 4,
      "name": "Wood_Birch_Trunk",
      "support": 15
    },
    {
      "x": -1,
      "y": 14,
      "z": 4,
      "name": "Wood_Birch_Trunk",
      "support": 15
    },
    {
      "x": -1,
      "y": 15,
      "z": 4,
      "name": "Wood_Birch_Trunk",
      "support": 15
    },
    {
      "x": -1,
      "y": 16,
      "z": 4,
      "name": "Wood_Birch_Trunk_Full",
      "support": 15
    },
    {
      "x": -1,
      "y": 3,
      "z": 5,
      "name": "Wood_Birch_Trunk_Full",
      "support": 15
    },
    {
      "x": -1,
      "y": 4,
      "z": 5,
      "name": "Wood_Birch_Trunk_Full",
      "support": 15
    },
    {
      "x": -1,
      "y": 7,
      "z": 5,
      "name": "Wood_Birch_Trunk_Full",
      "support": 15
    },
    {
      "x": -1,
      "y": 8,
      "z": 5,
      "name": "Wood_Birch_Trunk",
      "support": 15
    },
    {
      "x": -1,
      "y": 9,
      "z": 5,
      "name": "Wood_Birch_Trunk",
      "support": 15
    },
    {
      "x": -1,
      "y": 10,
      "z": 5,
      "name": "Wood_Birch_Trunk",
      "support": 15
    },
    {
      "x": -1,
      "y": 11,
      "z": 5,
      "name": "Wood_Birch_Trunk",
      "support": 15
    },
    {
      "x": -1,
      "y": 12,
      "z": 5,
      "name": "Wood_Birch_Trunk",
      "support": 15
    },
    {
      "x": -1,
      "y": 13,
      "z": 5,
      "name": "Wood_Birch_Trunk",
      "support": 15
    },
    {
      "x": -1,
      "y": 14,
      "z": 5,
      "name": "Wood_Birch_Trunk",
      "support": 15
    },
    {
      "x": -1,
      "y": 15,
      "z": 5,
      "name": "Wood_Birch_Trunk",
      "support": 15
    },
    {
      "x": -1,
      "y": 16,
      "z": 5,
      "name": "Wood_Birch_Trunk_Full",
      "support": 15
    },
    {
      "x": -1,
      "y": 2,
      "z": 6,
      "name": "Wood_Birch_Trunk_Full",
      "support": 15
    },
    {
      "x": -1,
      "y": 3,
      "z": 6,
      "name": "Wood_Birch_Trunk_Full",
      "support": 15
    },
    {
      "x": -1,
      "y": 9,
      "z": 6,
      "name": "Wood_Birch_Trunk_Full",
      "support": 15
    },
    {
      "x": -1,
      "y": 10,
      "z": 6,
      "name": "Wood_Birch_Trunk",
      "support": 15
    },
    {
      "x": -1,
      "y": 11,
      "z": 6,
      "name": "Wood_Birch_Trunk",
      "support": 15
    },
    {
      "x": -1,
      "y": 12,
      "z": 6,
      "name": "Wood_Birch_Trunk",
      "support": 15
    },
    {
      "x": -1,
      "y": 13,
      "z": 6,
      "name": "Wood_Birch_Trunk_Full",
      "support": 15
    },
    {
      "x": 0,
      "y": 11,
      "z": -4,
      "name": "Wood_Birch_Trunk_Full",
      "support": 15
    },
    {
      "x": 0,
      "y": 12,
      "z": -4,
      "name": "Wood_Birch_Trunk",
      "support": 15
    },
    {
      "x": 0,
      "y": 13,
      "z": -4,
      "name": "Wood_Birch_Trunk",
      "support": 15
    },
    {
      "x": 0,
      "y": 14,
      "z": -4,
      "name": "Wood_Birch_Trunk",
      "support": 15
    },
    {
      "x": 0,
      "y": 15,
      "z": -4,
      "name": "Wood_Birch_Trunk",
      "support": 15
    },
    {
      "x": 0,
      "y": 16,
      "z": -4,
      "name": "Wood_Birch_Trunk",
      "support": 15
    },
    {
      "x": 0,
      "y": 17,
      "z": -4,
      "name": "Wood_Birch_Trunk",
      "support": 15
    },
    {
      "x": 0,
      "y": 18,
      "z": -4,
      "name": "Wood_Birch_Trunk_Full",
      "support": 15
    },
    {
      "x": 0,
      "y": 10,
      "z": -3,
      "name": "Wood_Birch_Trunk_Full",
      "support": 15
    },
    {
      "x": 0,
      "y": 11,
      "z": -3,
      "name": "Wood_Birch_Trunk",
      "support": 15
    },
    {
      "x": 0,
      "y": 12,
      "z": -3,
      "name": "Wood_Birch_Trunk",
      "support": 15
    },
    {
      "x": 0,
      "y": 13,
      "z": -3,
      "name": "Wood_Birch_Trunk",
      "support": 15
    },
    {
      "x": 0,
      "y": 14,
      "z": -3,
      "name": "Wood_Birch_Trunk"
    },
    {
      "x": 0,
      "y": 15,
      "z": -3,
      "name": "Plant_Crop_Mushroom_Glowing_Violet"
    },
    {
      "x": 0,
      "y": 16,
      "z": -3,
      "name": "Empty"
    },
    {
      "x": 0,
      "y": 17,
      "z": -3,
      "name": "Wood_Birch_Trunk",
      "support": 2
    },
    {
      "x": 0,
      "y": 18,
      "z": -3,
      "name": "Wood_Birch_Trunk"
    },
    {
      "x": 0,
      "y": 19,
      "z": -3,
      "name": "Wood_Birch_Trunk"
    },
    {
      "x": 0,
      "y": 20,
      "z": -3,
      "name": "Wood_Birch_Trunk"
    },
    {
      "x": 0,
      "y": 21,
      "z": -3,
      "name": "Wood_Birch_Trunk_Full",
      "support": 15
    },
    {
      "x": 0,
      "y": 13,
      "z": -2,
      "name": "Wood_Birch_Trunk_Full",
      "support": 15
    },
    {
      "x": 0,
      "y": 14,
      "z": -2,
      "name": "Rock_Marble_SkyGrass"
    },
    {
      "x": 0,
      "y": 15,
      "z": -2,
      "name": "Plant_Crop_Stamina2"
    },
    {
      "x": 0,
      "y": 16,
      "z": -2,
      "name": "Empty"
    },
    {
      "x": 0,
      "y": 17,
      "z": -2,
      "name": "Empty"
    },
    {
      "x": 0,
      "y": 18,
      "z": -2,
      "name": "Wood_Birch_Trunk",
      "support": 15
    },
    {
      "x": 0,
      "y": 19,
      "z": -2,
      "name": "Wood_Birch_Trunk"
    },
    {
      "x": 0,
      "y": 20,
      "z": -2,
      "name": "Wood_Birch_Trunk"
    },
    {
      "x": 0,
      "y": 21,
      "z": -2,
      "name": "Wood_Birch_Trunk"
    },
    {
      "x": 0,
      "y": 22,
      "z": -2,
      "name": "Empty"
    },
    {
      "x": 0,
      "y": 11,
      "z": -1,
      "name": "Wood_Birch_Trunk_Full",
      "support": 15
    },
    {
      "x": 0,
      "y": 12,
      "z": -1,
      "name": "Wood_Birch_Trunk",
      "support": 15
    },
    {
      "x": 0,
      "y": 13,
      "z": -1,
      "name": "Wood_Birch_Trunk",
      "support": 15
    },
    {
      "x": 0,
      "y": 14,
      "z": -1,
      "name": "Wood_Birch_Trunk"
    },
    {
      "x": 0,
      "y": 15,
      "z": -1,
      "name": "Empty"
    },
    {
      "x": 0,
      "y": 16,
      "z": -1,
      "name": "Empty"
    },
    {
      "x": 0,
      "y": 17,
      "z": -1,
      "name": "Empty"
    },
    {
      "x": 0,
      "y": 18,
      "z": -1,
      "name": "Wood_Birch_Trunk",
      "support": 15
    },
    {
      "x": 0,
      "y": 19,
      "z": -1,
      "name": "Wood_Birch_Trunk"
    },
    {
      "x": 0,
      "y": 20,
      "z": -1,
      "name": "Wood_Birch_Trunk",
      "support": 15
    },
    {
      "x": 0,
      "y": 21,
      "z": -1,
      "name": "Empty"
    },
    {
      "x": 0,
      "y": 22,
      "z": -1,
      "name": "Empty"
    },
    {
      "x": 0,
      "y": 12,
      "z": 0,
      "name": "Wood_Birch_Trunk_Full",
      "support": 15
    },
    {
      "x": 0,
      "y": 13,
      "z": 0,
      "name": "Wood_Birch_Trunk",
      "support": 15
    },
    {
      "x": 0,
      "y": 14,
      "z": 0,
      "name": "Wood_Birch_Trunk",
      "support": 15
    },
    {
      "x": 0,
      "y": 15,
      "z": 0,
      "name": "Plant_Grass_Cave_Short",
      "support": 15
    },
    {
      "x": 0,
      "y": 16,
      "z": 0,
      "name": "Empty"
    },
    {
      "x": 0,
      "y": 17,
      "z": 0,
      "name": "Empty"
    },
    {
      "x": 0,
      "y": 18,
      "z": 0,
      "name": "Empty"
    },
    {
      "x": 0,
      "y": 19,
      "z": 0,
      "name": "Empty"
    },
    {
      "x": 0,
      "y": 20,
      "z": 0,
      "name": "Empty"
    },
    {
      "x": 0,
      "y": 21,
      "z": 0,
      "name": "Empty"
    },
    {
      "x": 0,
      "y": 22,
      "z": 0,
      "name": "Empty"
    },
    {
      "x": 0,
      "y": 12,
      "z": 1,
      "name": "Wood_Birch_Trunk_Full",
      "support": 15
    },
    {
      "x": 0,
      "y": 13,
      "z": 1,
      "name": "Wood_Birch_Trunk",
      "support": 15
    },
    {
      "x": 0,
      "y": 14,
      "z": 1,
      "name": "Wood_Birch_Trunk"
    },
    {
      "x": 0,
      "y": 15,
      "z": 1,
      "name": "Empty"
    },
    {
      "x": 0,
      "y": 16,
      "z": 1,
      "name": "Empty"
    },
    {
      "x": 0,
      "y": 17,
      "z": 1,
      "name": "Empty"
    },
    {
      "x": 0,
      "y": 18,
      "z": 1,
      "name": "Empty"
    },
    {
      "x": 0,
      "y": 19,
      "z": 1,
      "name": "Wood_Birch_Trunk",
      "support": 15
    },
    {
      "x": 0,
      "y": 20,
      "z": 1,
      "name": "Wood_Birch_Trunk"
    },
    {
      "x": 0,
      "y": 21,
      "z": 1,
      "name": "Wood_Birch_Trunk",
      "support": 15
    },
    {
      "x": 0,
      "y": 22,
      "z": 1,
      "name": "Empty"
    },
    {
      "x": 0,
      "y": 12,
      "z": 2,
      "name": "Wood_Birch_Trunk_Full",
      "support": 15
    },
    {
      "x": 0,
      "y": 13,
      "z": 2,
      "name": "Wood_Birch_Trunk",
      "support": 15
    },
    {
      "x": 0,
      "y": 14,
      "z": 2,
      "name": "Wood_Birch_Trunk"
    },
    {
      "x": 0,
      "y": 15,
      "z": 2,
      "name": "Wood_Birch_Trunk",
      "support": 15
    },
    {
      "x": 0,
      "y": 16,
      "z": 2,
      "name": "Plant_Crop_Mushroom_Shelve_Yellow"
    },
    {
      "x": 0,
      "y": 17,
      "z": 2,
      "name": "Empty"
    },
    {
      "x": 0,
      "y": 18,
      "z": 2,
      "name": "Wood_Birch_Trunk",
      "support": 1
    },
    {
      "x": 0,
      "y": 19,
      "z": 2,
      "name": "Wood_Birch_Trunk"
    },
    {
      "x": 0,
      "y": 20,
      "z": 2,
      "name": "Wood_Birch_Trunk"
    },
    {
      "x": 0,
      "y": 21,
      "z": 2,
      "name": "Wood_Birch_Trunk"
    },
    {
      "x": 0,
      "y": 22,
      "z": 2,
      "name": "Empty"
    },
    {
      "x": 0,
      "y": 14,
      "z": 3,
      "name": "Wood_Birch_Trunk_Full",
      "support": 15
    },
    {
      "x": 0,
      "y": 15,
      "z": 3,
      "name": "Wood_Birch_Trunk"
    },
    {
      "x": 0,
      "y": 16,
      "z": 3,
      "name": "Wood_Birch_Trunk"
    },
    {
      "x": 0,
      "y": 17,
      "z": 3,
      "name": "Wood_Birch_Trunk"
    },
    {
      "x": 0,
      "y": 18,
      "z": 3,
      "name": "Wood_Birch_Trunk"
    },
    {
      "x": 0,
      "y": 19,
      "z": 3,
      "name": "Wood_Birch_Trunk"
    },
    {
      "x": 0,
      "y": 20,
      "z": 3,
      "name": "Wood_Birch_Trunk"
    },
    {
      "x": 0,
      "y": 21,
      "z": 3,
      "name": "Wood_Birch_Trunk_Full",
      "support": 15
    },
    {
      "x": 0,
      "y": 2,
      "z": 6,
      "name": "Wood_Birch_Trunk_Full",
      "support": 15
    },
    {
      "x": 0,
      "y": 2,
      "z": 7,
      "name": "Wood_Birch_Trunk_Full",
      "support": 15
    },
    {
      "x": 1,
      "y": 12,
      "z": -4,
      "name": "Wood_Birch_Trunk_Full",
      "support": 15
    },
    {
      "x": 1,
      "y": 13,
      "z": -4,
      "name": "Wood_Birch_Trunk",
      "support": 15
    },
    {
      "x": 1,
      "y": 14,
      "z": -4,
      "name": "Wood_Birch_Trunk",
      "support": 15
    },
    {
      "x": 1,
      "y": 15,
      "z": -4,
      "name": "Wood_Birch_Trunk",
      "support": 15
    },
    {
      "x": 1,
      "y": 16,
      "z": -4,
      "name": "Wood_Birch_Trunk_Full",
      "support": 15
    },
    {
      "x": 1,
      "y": 2,
      "z": -3,
      "name": "Wood_Birch_Trunk_Full",
      "support": 15
    },
    {
      "x": 1,
      "y": 3,
      "z": -3,
      "name": "Wood_Birch_Trunk",
      "support": 15
    },
    {
      "x": 1,
      "y": 4,
      "z": -3,
      "name": "Wood_Birch_Trunk",
      "support": 15
    },
    {
      "x": 1,
      "y": 5,
      "z": -3,
      "name": "Wood_Birch_Trunk_Full",
      "support": 15
    },
    {
      "x": 1,
      "y": 8,
      "z": -3,
      "name": "Wood_Birch_Trunk_Full",
      "support": 15
    },
    {
      "x": 1,
      "y": 9,
      "z": -3,
      "name": "Wood_Birch_Trunk",
      "support": 15
    },
    {
      "x": 1,
      "y": 10,
      "z": -3,
      "name": "Wood_Birch_Trunk",
      "support": 15
    },
    {
      "x": 1,
      "y": 11,
      "z": -3,
      "name": "Wood_Birch_Trunk",
      "support": 15
    },
    {
      "x": 1,
      "y": 12,
      "z": -3,
      "name": "Wood_Birch_Trunk",
      "support": 15
    },
    {
      "x": 1,
      "y": 13,
      "z": -3,
      "name": "Wood_Birch_Trunk",
      "support": 15
    },
    {
      "x": 1,
      "y": 14,
      "z": -3,
      "name": "Wood_Birch_Trunk"
    },
    {
      "x": 1,
      "y": 15,
      "z": -3,
      "name": "Wood_Birch_Trunk",
      "support": 15
    },
    {
      "x": 1,
      "y": 16,
      "z": -3,
      "name": "Wood_Birch_Trunk",
      "support": 15
    },
    {
      "x": 1,
      "y": 17,
      "z": -3,
      "name": "Wood_Birch_Trunk"
    },
    {
      "x": 1,
      "y": 18,
      "z": -3,
      "name": "Wood_Birch_Trunk"
    },
    {
      "x": 1,
      "y": 19,
      "z": -3,
      "name": "Wood_Birch_Trunk"
    },
    {
      "x": 1,
      "y": 20,
      "z": -3,
      "name": "Wood_Birch_Trunk"
    },
    {
      "x": 1,
      "y": 21,
      "z": -3,
      "name": "Wood_Birch_Trunk_Full",
      "support": 15
    },
    {
      "x": 1,
      "y": 3,
      "z": -2,
      "name": "Wood_Birch_Trunk_Full",
      "support": 15
    },
    {
      "x": 1,
      "y": 4,
      "z": -2,
      "name": "Wood_Birch_Trunk_Full",
      "support": 15
    },
    {
      "x": 1,
      "y": 12,
      "z": -2,
      "name": "Wood_Birch_Trunk_Full",
      "support": 15
    },
    {
      "x": 1,
      "y": 13,
      "z": -2,
      "name": "Wood_Birch_Trunk",
      "support": 15
    },
    {
      "x": 1,
      "y": 14,
      "z": -2,
      "name": "Wood_Birch_Trunk"
    },
    {
      "x": 1,
      "y": 15,
      "z": -2,
      "name": "Plant_Grass_Cave_Short",
      "support": 15
    },
    {
      "x": 1,
      "y": 16,
      "z": -2,
      "name": "Empty"
    },
    {
      "x": 1,
      "y": 17,
      "z": -2,
      "name": "Wood_Birch_Trunk",
      "support": 15
    },
    {
      "x": 1,
      "y": 18,
      "z": -2,
      "name": "Wood_Birch_Trunk"
    },
    {
      "x": 1,
      "y": 19,
      "z": -2,
      "name": "Wood_Birch_Trunk"
    },
    {
      "x": 1,
      "y": 20,
      "z": -2,
      "name": "Wood_Birch_Trunk"
    },
    {
      "x": 1,
      "y": 21,
      "z": -2,
      "name": "Wood_Birch_Trunk"
    },
    {
      "x": 1,
      "y": 22,
      "z": -2,
      "name": "Empty"
    },
    {
      "x": 1,
      "y": 10,
      "z": -1,
      "name": "Wood_Birch_Trunk_Full",
      "support": 15
    },
    {
      "x": 1,
      "y": 11,
      "z": -1,
      "name": "Wood_Birch_Trunk",
      "support": 15
    },
    {
      "x": 1,
      "y": 12,
      "z": -1,
      "name": "Wood_Birch_Trunk",
      "support": 15
    },
    {
      "x": 1,
      "y": 13,
      "z": -1,
      "name": "Wood_Birch_Trunk",
      "support": 15
    },
    {
      "x": 1,
      "y": 14,
      "z": -1,
      "name": "Wood_Birch_Trunk"
    },
    {
      "x": 1,
      "y": 15,
      "z": -1,
      "name": "Plant_Petals_Storm"
    },
    {
      "x": 1,
      "y": 16,
      "z": -1,
      "name": "Empty"
    },
    {
      "x": 1,
      "y": 17,
      "z": -1,
      "name": "Empty"
    },
    {
      "x": 1,
      "y": 18,
      "z": -1,
      "name": "Wood_Birch_Trunk",
      "support": 15
    },
    {
      "x": 1,
      "y": 19,
      "z": -1,
      "name": "Wood_Birch_Trunk"
    },
    {
      "x": 1,
      "y": 20,
      "z": -1,
      "name": "Wood_Birch_Trunk"
    },
    {
      "x": 1,
      "y": 21,
      "z": -1,
      "name": "Wood_Birch_Trunk"
    },
    {
      "x": 1,
      "y": 22,
      "z": -1,
      "name": "Empty"
    },
    {
      "x": 1,
      "y": 11,
      "z": 0,
      "name": "Wood_Birch_Trunk_Full",
      "support": 15
    },
    {
      "x": 1,
      "y": 12,
      "z": 0,
      "name": "Wood_Birch_Trunk",
      "support": 15
    },
    {
      "x": 1,
      "y": 13,
      "z": 0,
      "name": "Wood_Birch_Trunk",
      "support": 15
    },
    {
      "x": 1,
      "y": 14,
      "z": 0,
      "name": "Wood_Birch_Trunk",
      "support": 15
    },
    {
      "x": 1,
      "y": 15,
      "z": 0,
      "name": "Furniture_Temple_Light_Chest_Small",
      "components": {
        "Components": {
          "PlacedByInteraction": {
            "WhoPlacedUuid": {
              "$binary": "rmwkrpH8RVykTc7XnK4YBA==",
              "$type": "04"
            }
          },
          "container": {
            "Custom": false,
            "AllowViewing": true,
            "ItemContainer": {
              "Capacity": 18,
              "Items": {}
            }
          }
        }
      },
      "rotation": 3
    },
    {
      "x": 1,
      "y": 16,
      "z": 0,
      "name": "Empty"
    },
    {
      "x": 1,
      "y": 17,
      "z": 0,
      "name": "Empty"
    },
    {
      "x": 1,
      "y": 18,
      "z": 0,
      "name": "Wood_Birch_Trunk",
      "support": 15
    },
    {
      "x": 1,
      "y": 19,
      "z": 0,
      "name": "Wood_Birch_Trunk"
    },
    {
      "x": 1,
      "y": 20,
      "z": 0,
      "name": "Wood_Birch_Trunk"
    },
    {
      "x": 1,
      "y": 21,
      "z": 0,
      "name": "Wood_Birch_Trunk",
      "support": 15
    },
    {
      "x": 1,
      "y": 22,
      "z": 0,
      "name": "Empty"
    },
    {
      "x": 1,
      "y": 13,
      "z": 1,
      "name": "Wood_Birch_Trunk_Full",
      "support": 15
    },
    {
      "x": 1,
      "y": 14,
      "z": 1,
      "name": "Rock_Marble_SkyGrass"
    },
    {
      "x": 1,
      "y": 15,
      "z": 1,
      "name": "Plant_Crop_Stamina2"
    },
    {
      "x": 1,
      "y": 16,
      "z": 1,
      "name": "Empty"
    },
    {
      "x": 1,
      "y": 17,
      "z": 1,
      "name": "Wood_Birch_Trunk",
      "support": 15
    },
    {
      "x": 1,
      "y": 18,
      "z": 1,
      "name": "Wood_Birch_Trunk",
      "support": 15
    },
    {
      "x": 1,
      "y": 19,
      "z": 1,
      "name": "Wood_Birch_Trunk"
    },
    {
      "x": 1,
      "y": 20,
      "z": 1,
      "name": "Wood_Birch_Trunk"
    },
    {
      "x": 1,
      "y": 21,
      "z": 1,
      "name": "Wood_Birch_Trunk"
    },
    {
      "x": 1,
      "y": 22,
      "z": 1,
      "name": "Plant_Petals_Storm"
    },
    {
      "x": 1,
      "y": 13,
      "z": 2,
      "name": "Wood_Birch_Trunk_Full",
      "support": 15
    },
    {
      "x": 1,
      "y": 14,
      "z": 2,
      "name": "Wood_Birch_Trunk"
    },
    {
      "x": 1,
      "y": 17,
      "z": 2,
      "name": "Wood_Birch_Trunk",
      "support": 15
    },
    {
      "x": 1,
      "y": 18,
      "z": 2,
      "name": "Wood_Birch_Trunk"
    },
    {
      "x": 1,
      "y": 19,
      "z": 2,
      "name": "Wood_Birch_Trunk"
    },
    {
      "x": 1,
      "y": 20,
      "z": 2,
      "name": "Wood_Birch_Trunk"
    },
    {
      "x": 1,
      "y": 21,
      "z": 2,
      "name": "Wood_Birch_Trunk"
    },
    {
      "x": 1,
      "y": 22,
      "z": 2,
      "name": "Empty"
    },
    {
      "x": 1,
      "y": 14,
      "z": 3,
      "name": "Wood_Birch_Trunk_Full",
      "support": 15
    },
    {
      "x": 1,
      "y": 15,
      "z": 3,
      "name": "Wood_Birch_Trunk"
    },
    {
      "x": 1,
      "y": 16,
      "z": 3,
      "name": "Wood_Birch_Trunk"
    },
    {
      "x": 1,
      "y": 17,
      "z": 3,
      "name": "Wood_Birch_Trunk"
    },
    {
      "x": 1,
      "y": 18,
      "z": 3,
      "name": "Wood_Birch_Trunk"
    },
    {
      "x": 1,
      "y": 19,
      "z": 3,
      "name": "Wood_Birch_Trunk"
    },
    {
      "x": 1,
      "y": 20,
      "z": 3,
      "name": "Wood_Birch_Trunk"
    },
    {
      "x": 1,
      "y": 21,
      "z": 3,
      "name": "Wood_Birch_Trunk_Full",
      "support": 15
    },
    {
      "x": 1,
      "y": 13,
      "z": 4,
      "name": "Wood_Birch_Trunk_Full",
      "support": 15
    },
    {
      "x": 1,
      "y": 14,
      "z": 4,
      "name": "Wood_Birch_Trunk_Full",
      "support": 15
    },
    {
      "x": 2,
      "y": 5,
      "z": -4,
      "name": "Wood_Birch_Trunk_Full",
      "support": 15
    },
    {
      "x": 2,
      "y": 6,
      "z": -4,
      "name": "Wood_Birch_Trunk",
      "support": 15
    },
    {
      "x": 2,
      "y": 7,
      "z": -4,
      "name": "Wood_Birch_Trunk",
      "support": 15
    },
    {
      "x": 2,
      "y": 8,
      "z": -4,
      "name": "Wood_Birch_Trunk",
      "support": 15
    },
    {
      "x": 2,
      "y": 9,
      "z": -4,
      "name": "Wood_Birch_Trunk",
      "support": 15
    },
    {
      "x": 2,
      "y": 10,
      "z": -4,
      "name": "Wood_Birch_Trunk",
      "support": 15
    },
    {
      "x": 2,
      "y": 11,
      "z": -4,
      "name": "Wood_Birch_Trunk",
      "support": 15
    },
    {
      "x": 2,
      "y": 12,
      "z": -4,
      "name": "Wood_Birch_Trunk",
      "support": 15
    },
    {
      "x": 2,
      "y": 13,
      "z": -4,
      "name": "Wood_Birch_Trunk",
      "support": 15
    },
    {
      "x": 2,
      "y": 14,
      "z": -4,
      "name": "Wood_Birch_Trunk_Full",
      "support": 15
    },
    {
      "x": 2,
      "y": 1,
      "z": -3,
      "name": "Wood_Birch_Trunk_Full",
      "support": 15
    },
    {
      "x": 2,
      "y": 2,
      "z": -3,
      "name": "Wood_Birch_Trunk",
      "support": 15
    },
    {
      "x": 2,
      "y": 3,
      "z": -3,
      "name": "Wood_Birch_Trunk",
      "support": 15
    },
    {
      "x": 2,
      "y": 4,
      "z": -3,
      "name": "Wood_Birch_Trunk",
      "support": 15
    },
    {
      "x": 2,
      "y": 5,
      "z": -3,
      "name": "Wood_Birch_Trunk",
      "support": 15
    },
    {
      "x": 2,
      "y": 6,
      "z": -3,
      "name": "Wood_Birch_Trunk",
      "support": 15
    },
    {
      "x": 2,
      "y": 7,
      "z": -3,
      "name": "Wood_Birch_Trunk",
      "support": 15
    },
    {
      "x": 2,
      "y": 8,
      "z": -3,
      "name": "Wood_Birch_Trunk",
      "support": 15
    },
    {
      "x": 2,
      "y": 9,
      "z": -3,
      "name": "Wood_Birch_Trunk",
      "support": 15
    },
    {
      "x": 2,
      "y": 10,
      "z": -3,
      "name": "Wood_Birch_Trunk",
      "support": 15
    },
    {
      "x": 2,
      "y": 11,
      "z": -3,
      "name": "Wood_Birch_Trunk",
      "support": 15
    },
    {
      "x": 2,
      "y": 12,
      "z": -3,
      "name": "Wood_Birch_Trunk",
      "support": 15
    },
    {
      "x": 2,
      "y": 13,
      "z": -3,
      "name": "Wood_Birch_Trunk",
      "support": 15
    },
    {
      "x": 2,
      "y": 14,
      "z": -3,
      "name": "Wood_Birch_Trunk",
      "support": 15
    },
    {
      "x": 2,
      "y": 15,
      "z": -3,
      "name": "Wood_Birch_Trunk_Full",
      "support": 15
    },
    {
      "x": 2,
      "y": 2,
      "z": -2,
      "name": "Wood_Birch_Trunk_Full",
      "support": 15
    },
    {
      "x": 2,
      "y": 3,
      "z": -2,
      "name": "Wood_Birch_Trunk",
      "support": 15
    },
    {
      "x": 2,
      "y": 4,
      "z": -2,
      "name": "Wood_Birch_Trunk",
      "support": 15
    },
    {
      "x": 2,
      "y": 5,
      "z": -2,
      "name": "Wood_Birch_Trunk_Full",
      "support": 15
    },
    {
      "x": 2,
      "y": 9,
      "z": -2,
      "name": "Wood_Birch_Trunk_Full",
      "support": 15
    },
    {
      "x": 2,
      "y": 10,
      "z": -2,
      "name": "Wood_Birch_Trunk",
      "support": 15
    },
    {
      "x": 2,
      "y": 11,
      "z": -2,
      "name": "Wood_Birch_Trunk",
      "support": 15
    },
    {
      "x": 2,
      "y": 12,
      "z": -2,
      "name": "Wood_Birch_Trunk",
      "support": 15
    },
    {
      "x": 2,
      "y": 13,
      "z": -2,
      "name": "Wood_Birch_Trunk",
      "support": 15
    },
    {
      "x": 2,
      "y": 14,
      "z": -2,
      "name": "Wood_Birch_Trunk"
    },
    {
      "x": 2,
      "y": 15,
      "z": -2,
      "name": "Wood_Birch_Trunk"
    },
    {
      "x": 2,
      "y": 16,
      "z": -2,
      "name": "Wood_Birch_Trunk"
    },
    {
      "x": 2,
      "y": 17,
      "z": -2,
      "name": "Wood_Birch_Trunk"
    },
    {
      "x": 2,
      "y": 18,
      "z": -2,
      "name": "Wood_Birch_Trunk"
    },
    {
      "x": 2,
      "y": 19,
      "z": -2,
      "name": "Wood_Birch_Trunk"
    },
    {
      "x": 2,
      "y": 20,
      "z": -2,
      "name": "Wood_Birch_Trunk"
    },
    {
      "x": 2,
      "y": 21,
      "z": -2,
      "name": "Wood_Birch_Trunk"
    },
    {
      "x": 2,
      "y": 22,
      "z": -2,
      "name": "Wood_Birch_Trunk_Full",
      "support": 15
    },
    {
      "x": 2,
      "y": 13,
      "z": -1,
      "name": "Wood_Birch_Trunk_Full",
      "support": 15
    },
    {
      "x": 2,
      "y": 14,
      "z": -1,
      "name": "Wood_Birch_Trunk"
    },
    {
      "x": 2,
      "y": 15,
      "z": -1,
      "name": "Empty"
    },
    {
      "x": 2,
      "y": 16,
      "z": -1,
      "name": "Wood_Birch_Trunk",
      "support": 15
    },
    {
      "x": 2,
      "y": 17,
      "z": -1,
      "name": "Wood_Birch_Trunk"
    },
    {
      "x": 2,
      "y": 18,
      "z": -1,
      "name": "Wood_Birch_Trunk"
    },
    {
      "x": 2,
      "y": 19,
      "z": -1,
      "name": "Wood_Birch_Trunk"
    },
    {
      "x": 2,
      "y": 20,
      "z": -1,
      "name": "Wood_Birch_Trunk"
    },
    {
      "x": 2,
      "y": 21,
      "z": -1,
      "name": "Wood_Birch_Trunk"
    },
    {
      "x": 2,
      "y": 22,
      "z": -1,
      "name": "Empty"
    },
    {
      "x": 2,
      "y": 13,
      "z": 0,
      "name": "Wood_Birch_Trunk_Full",
      "support": 15
    },
    {
      "x": 2,
      "y": 14,
      "z": 0,
      "name": "Wood_Birch_Trunk"
    },
    {
      "x": 2,
      "y": 15,
      "z": 0,
      "name": "Plant_Crop_Mushroom_Shelve_Yellow"
    },
    {
      "x": 2,
      "y": 16,
      "z": 0,
      "name": "Empty"
    },
    {
      "x": 2,
      "y": 17,
      "z": 0,
      "name": "Wood_Birch_Trunk",
      "support": 1
    },
    {
      "x": 2,
      "y": 18,
      "z": 0,
      "name": "Wood_Birch_Trunk"
    },
    {
      "x": 2,
      "y": 19,
      "z": 0,
      "name": "Wood_Birch_Trunk"
    },
    {
      "x": 2,
      "y": 20,
      "z": 0,
      "name": "Wood_Birch_Trunk"
    },
    {
      "x": 2,
      "y": 21,
      "z": 0,
      "name": "Wood_Birch_Trunk"
    },
    {
      "x": 2,
      "y": 22,
      "z": 0,
      "name": "Empty"
    },
    {
      "x": 2,
      "y": 13,
      "z": 1,
      "name": "Wood_Birch_Trunk_Full",
      "support": 15
    },
    {
      "x": 2,
      "y": 14,
      "z": 1,
      "name": "Wood_Birch_Trunk"
    },
    {
      "x": 2,
      "y": 15,
      "z": 1,
      "name": "Wood_Birch_Trunk"
    },
    {
      "x": 2,
      "y": 16,
      "z": 1,
      "name": "Wood_Birch_Trunk"
    },
    {
      "x": 2,
      "y": 17,
      "z": 1,
      "name": "Wood_Birch_Trunk"
    },
    {
      "x": 2,
      "y": 18,
      "z": 1,
      "name": "Wood_Birch_Trunk"
    },
    {
      "x": 2,
      "y": 19,
      "z": 1,
      "name": "Wood_Birch_Trunk"
    },
    {
      "x": 2,
      "y": 20,
      "z": 1,
      "name": "Wood_Birch_Trunk"
    },
    {
      "x": 2,
      "y": 21,
      "z": 1,
      "name": "Rock_Marble_SkyGrass"
    },
    {
      "x": 2,
      "y": 22,
      "z": 1,
      "name": "Plant_Crop_Stamina2"
    },
    {
      "x": 2,
      "y": 13,
      "z": 2,
      "name": "Wood_Birch_Trunk_Full",
      "support": 15
    },
    {
      "x": 2,
      "y": 14,
      "z": 2,
      "name": "Wood_Birch_Trunk"
    },
    {
      "x": 2,
      "y": 15,
      "z": 2,
      "name": "Wood_Birch_Trunk"
    },
    {
      "x": 2,
      "y": 16,
      "z": 2,
      "name": "Wood_Birch_Trunk"
    },
    {
      "x": 2,
      "y": 17,
      "z": 2,
      "name": "Wood_Birch_Trunk"
    },
    {
      "x": 2,
      "y": 18,
      "z": 2,
      "name": "Wood_Birch_Trunk"
    },
    {
      "x": 2,
      "y": 19,
      "z": 2,
      "name": "Wood_Birch_Trunk"
    },
    {
      "x": 2,
      "y": 20,
      "z": 2,
      "name": "Wood_Birch_Trunk"
    },
    {
      "x": 2,
      "y": 21,
      "z": 2,
      "name": "Wood_Birch_Trunk"
    },
    {
      "x": 2,
      "y": 22,
      "z": 2,
      "name": "Wood_Birch_Trunk_Full",
      "support": 15
    },
    {
      "x": 2,
      "y": 2,
      "z": 3,
      "name": "Wood_Birch_Trunk_Full",
      "support": 15
    },
    {
      "x": 2,
      "y": 12,
      "z": 3,
      "name": "Wood_Birch_Trunk_Full",
      "support": 15
    },
    {
      "x": 2,
      "y": 13,
      "z": 3,
      "name": "Wood_Birch_Trunk",
      "support": 15
    },
    {
      "x": 2,
      "y": 14,
      "z": 3,
      "name": "Wood_Birch_Trunk",
      "support": 15
    },
    {
      "x": 2,
      "y": 15,
      "z": 3,
      "name": "Wood_Birch_Trunk",
      "support": 15
    },
    {
      "x": 2,
      "y": 16,
      "z": 3,
      "name": "Wood_Birch_Trunk",
      "support": 15
    },
    {
      "x": 2,
      "y": 17,
      "z": 3,
      "name": "Wood_Birch_Trunk",
      "support": 15
    },
    {
      "x": 2,
      "y": 18,
      "z": 3,
      "name": "Wood_Birch_Trunk_Full",
      "support": 15
    },
    {
      "x": 2,
      "y": 2,
      "z": 4,
      "name": "Wood_Birch_Trunk_Full",
      "support": 15
    },
    {
      "x": 2,
      "y": 12,
      "z": 4,
      "name": "Wood_Birch_Trunk_Full",
      "support": 15
    },
    {
      "x": 2,
      "y": 13,
      "z": 4,
      "name": "Wood_Birch_Trunk",
      "support": 15
    },
    {
      "x": 2,
      "y": 14,
      "z": 4,
      "name": "Wood_Birch_Trunk",
      "support": 15
    },
    {
      "x": 2,
      "y": 15,
      "z": 4,
      "name": "Wood_Birch_Trunk",
      "support": 15
    },
    {
      "x": 2,
      "y": 16,
      "z": 4,
      "name": "Wood_Birch_Trunk_Full",
      "support": 15
    },
    {
      "x": 3,
      "y": 1,
      "z": -4,
      "name": "Wood_Birch_Trunk_Full",
      "support": 15
    },
    {
      "x": 3,
      "y": 7,
      "z": -4,
      "name": "Wood_Birch_Trunk_Full",
      "support": 15
    },
    {
      "x": 3,
      "y": 8,
      "z": -4,
      "name": "Wood_Birch_Trunk",
      "support": 15
    },
    {
      "x": 3,
      "y": 9,
      "z": -4,
      "name": "Wood_Birch_Trunk",
      "support": 15
    },
    {
      "x": 3,
      "y": 10,
      "z": -4,
      "name": "Wood_Birch_Trunk",
      "support": 15
    },
    {
      "x": 3,
      "y": 11,
      "z": -4,
      "name": "Wood_Birch_Trunk_Full",
      "support": 15
    },
    {
      "x": 3,
      "y": 1,
      "z": -3,
      "name": "Wood_Birch_Trunk_Full",
      "support": 15
    },
    {
      "x": 3,
      "y": 5,
      "z": -3,
      "name": "Wood_Birch_Trunk_Full",
      "support": 15
    },
    {
      "x": 3,
      "y": 6,
      "z": -3,
      "name": "Wood_Birch_Trunk",
      "support": 15
    },
    {
      "x": 3,
      "y": 7,
      "z": -3,
      "name": "Wood_Birch_Trunk",
      "support": 15
    },
    {
      "x": 3,
      "y": 8,
      "z": -3,
      "name": "Wood_Birch_Trunk",
      "support": 15
    },
    {
      "x": 3,
      "y": 9,
      "z": -3,
      "name": "Wood_Birch_Trunk",
      "support": 15
    },
    {
      "x": 3,
      "y": 10,
      "z": -3,
      "name": "Wood_Birch_Trunk",
      "support": 15
    },
    {
      "x": 3,
      "y": 11,
      "z": -3,
      "name": "Wood_Birch_Trunk",
      "support": 15
    },
    {
      "x": 3,
      "y": 12,
      "z": -3,
      "name": "Wood_Birch_Trunk",
      "support": 15
    },
    {
      "x": 3,
      "y": 13,
      "z": -3,
      "name": "Wood_Birch_Trunk",
      "support": 15
    },
    {
      "x": 3,
      "y": 14,
      "z": -3,
      "name": "Wood_Birch_Trunk_Full",
      "support": 15
    },
    {
      "x": 3,
      "y": 11,
      "z": -2,
      "name": "Wood_Birch_Trunk_Full",
      "support": 15
    },
    {
      "x": 3,
      "y": 12,
      "z": -2,
      "name": "Wood_Birch_Trunk_Full",
      "support": 15
    },
    {
      "x": 3,
      "y": 13,
      "z": -2,
      "name": "Wood_Birch_Trunk_Full",
      "support": 15
    },
    {
      "x": 3,
      "y": 14,
      "z": -2,
      "name": "Wood_Birch_Trunk",
      "support": 15
    },
    {
      "x": 3,
      "y": 15,
      "z": -2,
      "name": "Wood_Birch_Trunk",
      "support": 15
    },
    {
      "x": 3,
      "y": 16,
      "z": -2,
      "name": "Wood_Birch_Trunk_Full",
      "support": 15
    },
    {
      "x": 3,
      "y": 7,
      "z": -1,
      "name": "Wood_Birch_Trunk_Full",
      "support": 15
    },
    {
      "x": 3,
      "y": 8,
      "z": -1,
      "name": "Wood_Birch_Trunk",
      "support": 15
    },
    {
      "x": 3,
      "y": 9,
      "z": -1,
      "name": "Wood_Birch_Trunk_Full",
      "support": 15
    },
    {
      "x": 3,
      "y": 14,
      "z": -1,
      "name": "Wood_Birch_Trunk_Full",
      "support": 15
    },
    {
      "x": 3,
      "y": 15,
      "z": -1,
      "name": "Wood_Birch_Trunk"
    },
    {
      "x": 3,
      "y": 16,
      "z": -1,
      "name": "Wood_Birch_Trunk"
    },
    {
      "x": 3,
      "y": 17,
      "z": -1,
      "name": "Wood_Birch_Trunk"
    },
    {
      "x": 3,
      "y": 18,
      "z": -1,
      "name": "Wood_Birch_Trunk"
    },
    {
      "x": 3,
      "y": 19,
      "z": -1,
      "name": "Wood_Birch_Trunk"
    },
    {
      "x": 3,
      "y": 20,
      "z": -1,
      "name": "Wood_Birch_Trunk"
    },
    {
      "x": 3,
      "y": 21,
      "z": -1,
      "name": "Wood_Birch_Trunk"
    },
    {
      "x": 3,
      "y": 22,
      "z": -1,
      "name": "Wood_Birch_Trunk",
      "support": 15
    },
    {
      "x": 3,
      "y": 23,
      "z": -1,
      "name": "Wood_Birch_Trunk_Full",
      "support": 15
    },
    {
      "x": 3,
      "y": 8,
      "z": 0,
      "name": "Wood_Birch_Trunk_Full",
      "support": 15
    },
    {
      "x": 3,
      "y": 9,
      "z": 0,
      "name": "Wood_Birch_Trunk_Full",
      "support": 15
    },
    {
      "x": 3,
      "y": 13,
      "z": 0,
      "name": "Wood_Birch_Trunk_Full",
      "support": 15
    },
    {
      "x": 3,
      "y": 14,
      "z": 0,
      "name": "Wood_Birch_Trunk"
    },
    {
      "x": 3,
      "y": 15,
      "z": 0,
      "name": "Wood_Birch_Trunk"
    },
    {
      "x": 3,
      "y": 16,
      "z": 0,
      "name": "Wood_Birch_Trunk"
    },
    {
      "x": 3,
      "y": 17,
      "z": 0,
      "name": "Wood_Birch_Trunk"
    },
    {
      "x": 3,
      "y": 18,
      "z": 0,
      "name": "Wood_Birch_Trunk"
    },
    {
      "x": 3,
      "y": 19,
      "z": 0,
      "name": "Wood_Birch_Trunk"
    },
    {
      "x": 3,
      "y": 20,
      "z": 0,
      "name": "Wood_Birch_Trunk"
    },
    {
      "x": 3,
      "y": 21,
      "z": 0,
      "name": "Wood_Birch_Trunk"
    },
    {
      "x": 3,
      "y": 22,
      "z": 0,
      "name": "Wood_Birch_Trunk_Full",
      "support": 15
    },
    {
      "x": 3,
      "y": 13,
      "z": 1,
      "name": "Wood_Birch_Trunk_Full",
      "support": 15
    },
    {
      "x": 3,
      "y": 14,
      "z": 1,
      "name": "Wood_Birch_Trunk"
    },
    {
      "x": 3,
      "y": 15,
      "z": 1,
      "name": "Wood_Birch_Trunk"
    },
    {
      "x": 3,
      "y": 16,
      "z": 1,
      "name": "Wood_Birch_Trunk"
    },
    {
      "x": 3,
      "y": 17,
      "z": 1,
      "name": "Wood_Birch_Trunk"
    },
    {
      "x": 3,
      "y": 18,
      "z": 1,
      "name": "Wood_Birch_Trunk"
    },
    {
      "x": 3,
      "y": 19,
      "z": 1,
      "name": "Wood_Birch_Trunk"
    },
    {
      "x": 3,
      "y": 20,
      "z": 1,
      "name": "Wood_Birch_Trunk"
    },
    {
      "x": 3,
      "y": 21,
      "z": 1,
      "name": "Wood_Birch_Trunk"
    },
    {
      "x": 3,
      "y": 22,
      "z": 1,
      "name": "Wood_Birch_Trunk_Full",
      "support": 15
    },
    {
      "x": 3,
      "y": 13,
      "z": 2,
      "name": "Wood_Birch_Trunk_Full",
      "support": 15
    },
    {
      "x": 3,
      "y": 14,
      "z": 2,
      "name": "Wood_Birch_Trunk",
      "support": 15
    },
    {
      "x": 3,
      "y": 15,
      "z": 2,
      "name": "Wood_Birch_Trunk",
      "support": 15
    },
    {
      "x": 3,
      "y": 16,
      "z": 2,
      "name": "Wood_Birch_Trunk_Full",
      "support": 15
    },
    {
      "x": 3,
      "y": 17,
      "z": 2,
      "name": "Wood_Birch_Trunk_Full",
      "support": 15
    },
    {
      "x": 3,
      "y": 12,
      "z": 3,
      "name": "Wood_Birch_Trunk_Full",
      "support": 15
    },
    {
      "x": 3,
      "y": 13,
      "z": 3,
      "name": "Wood_Birch_Trunk",
      "support": 15
    },
    {
      "x": 3,
      "y": 14,
      "z": 3,
      "name": "Wood_Birch_Trunk",
      "support": 15
    },
    {
      "x": 3,
      "y": 15,
      "z": 3,
      "name": "Wood_Birch_Trunk",
      "support": 15
    },
    {
      "x": 3,
      "y": 16,
      "z": 3,
      "name": "Wood_Birch_Trunk_Full",
      "support": 15
    },
    {
      "x": 3,
      "y": 2,
      "z": 4,
      "name": "Wood_Birch_Trunk_Full",
      "support": 15
    },
    {
      "x": 3,
      "y": 3,
      "z": 4,
      "name": "Wood_Birch_Trunk_Full",
      "support": 15
    },
    {
      "x": 3,
      "y": 10,
      "z": 4,
      "name": "Wood_Birch_Trunk_Full",
      "support": 15
    },
    {
      "x": 3,
      "y": 11,
      "z": 4,
      "name": "Wood_Birch_Trunk",
      "support": 15
    },
    {
      "x": 3,
      "y": 12,
      "z": 4,
      "name": "Wood_Birch_Trunk",
      "support": 15
    },
    {
      "x": 3,
      "y": 13,
      "z": 4,
      "name": "Wood_Birch_Trunk",
      "support": 15
    },
    {
      "x": 3,
      "y": 14,
      "z": 4,
      "name": "Wood_Birch_Trunk",
      "support": 15
    },
    {
      "x": 3,
      "y": 15,
      "z": 4,
      "name": "Wood_Birch_Trunk",
      "support": 15
    },
    {
      "x": 3,
      "y": 16,
      "z": 4,
      "name": "Wood_Birch_Trunk_Full",
      "support": 15
    },
    {
      "x": 3,
      "y": 3,
      "z": 5,
      "name": "Wood_Birch_Trunk_Full",
      "support": 15
    },
    {
      "x": 3,
      "y": 4,
      "z": 5,
      "name": "Wood_Birch_Trunk",
      "support": 15
    },
    {
      "x": 3,
      "y": 5,
      "z": 5,
      "name": "Wood_Birch_Trunk_Full",
      "support": 15
    },
    {
      "x": 3,
      "y": 9,
      "z": 5,
      "name": "Wood_Birch_Trunk_Full",
      "support": 15
    },
    {
      "x": 3,
      "y": 10,
      "z": 5,
      "name": "Wood_Birch_Trunk",
      "support": 15
    },
    {
      "x": 3,
      "y": 11,
      "z": 5,
      "name": "Wood_Birch_Trunk",
      "support": 15
    },
    {
      "x": 3,
      "y": 12,
      "z": 5,
      "name": "Wood_Birch_Trunk",
      "support": 15
    },
    {
      "x": 3,
      "y": 13,
      "z": 5,
      "name": "Wood_Birch_Trunk_Full",
      "support": 15
    },
    {
      "x": 4,
      "y": 9,
      "z": -2,
      "name": "Wood_Birch_Trunk_Full",
      "support": 15
    },
    {
      "x": 4,
      "y": 10,
      "z": -2,
      "name": "Wood_Birch_Trunk",
      "support": 15
    },
    {
      "x": 4,
      "y": 11,
      "z": -2,
      "name": "Wood_Birch_Trunk_Full",
      "support": 15
    },
    {
      "x": 4,
      "y": 5,
      "z": -1,
      "name": "Wood_Birch_Trunk_Full",
      "support": 15
    },
    {
      "x": 4,
      "y": 6,
      "z": -1,
      "name": "Wood_Birch_Trunk",
      "support": 15
    },
    {
      "x": 4,
      "y": 7,
      "z": -1,
      "name": "Wood_Birch_Trunk",
      "support": 15
    },
    {
      "x": 4,
      "y": 8,
      "z": -1,
      "name": "Wood_Birch_Trunk",
      "support": 15
    },
    {
      "x": 4,
      "y": 9,
      "z": -1,
      "name": "Wood_Birch_Trunk",
      "support": 15
    },
    {
      "x": 4,
      "y": 10,
      "z": -1,
      "name": "Wood_Birch_Trunk",
      "support": 15
    },
    {
      "x": 4,
      "y": 11,
      "z": -1,
      "name": "Wood_Birch_Trunk",
      "support": 15
    },
    {
      "x": 4,
      "y": 12,
      "z": -1,
      "name": "Wood_Birch_Trunk",
      "support": 15
    },
    {
      "x": 4,
      "y": 13,
      "z": -1,
      "name": "Wood_Birch_Trunk",
      "support": 15
    },
    {
      "x": 4,
      "y": 14,
      "z": -1,
      "name": "Wood_Birch_Trunk",
      "support": 15
    },
    {
      "x": 4,
      "y": 15,
      "z": -1,
      "name": "Wood_Birch_Trunk",
      "support": 15
    },
    {
      "x": 4,
      "y": 16,
      "z": -1,
      "name": "Wood_Birch_Trunk",
      "support": 15
    },
    {
      "x": 4,
      "y": 17,
      "z": -1,
      "name": "Wood_Birch_Trunk_Full",
      "support": 15
    },
    {
      "x": 4,
      "y": 6,
      "z": 0,
      "name": "Wood_Birch_Trunk_Full",
      "support": 15
    },
    {
      "x": 4,
      "y": 7,
      "z": 0,
      "name": "Wood_Birch_Trunk",
      "support": 15
    },
    {
      "x": 4,
      "y": 8,
      "z": 0,
      "name": "Wood_Birch_Trunk",
      "support": 15
    },
    {
      "x": 4,
      "y": 9,
      "z": 0,
      "name": "Wood_Birch_Trunk",
      "support": 15
    },
    {
      "x": 4,
      "y": 10,
      "z": 0,
      "name": "Wood_Birch_Trunk",
      "support": 15
    },
    {
      "x": 4,
      "y": 11,
      "z": 0,
      "name": "Wood_Birch_Trunk",
      "support": 15
    },
    {
      "x": 4,
      "y": 12,
      "z": 0,
      "name": "Wood_Birch_Trunk",
      "support": 15
    },
    {
      "x": 4,
      "y": 13,
      "z": 0,
      "name": "Wood_Birch_Trunk",
      "support": 15
    },
    {
      "x": 4,
      "y": 14,
      "z": 0,
      "name": "Wood_Birch_Trunk",
      "support": 15
    },
    {
      "x": 4,
      "y": 15,
      "z": 0,
      "name": "Wood_Birch_Trunk",
      "support": 15
    },
    {
      "x": 4,
      "y": 16,
      "z": 0,
      "name": "Wood_Birch_Trunk",
      "support": 15
    },
    {
      "x": 4,
      "y": 17,
      "z": 0,
      "name": "Wood_Birch_Trunk_Full",
      "support": 15
    },
    {
      "x": 4,
      "y": 13,
      "z": 1,
      "name": "Wood_Birch_Trunk_Full",
      "support": 15
    },
    {
      "x": 4,
      "y": 14,
      "z": 1,
      "name": "Wood_Birch_Trunk",
      "support": 15
    },
    {
      "x": 4,
      "y": 15,
      "z": 1,
      "name": "Wood_Birch_Trunk_Full",
      "support": 15
    },
    {
      "x": 4,
      "y": 13,
      "z": 2,
      "name": "Wood_Birch_Trunk_Full",
      "support": 15
    },
    {
      "x": 4,
      "y": 14,
      "z": 2,
      "name": "Wood_Birch_Trunk_Full",
      "support": 15
    },
    {
      "x": 4,
      "y": 3,
      "z": 4,
      "name": "Wood_Birch_Trunk_Full",
      "support": 15
    },
    {
      "x": 4,
      "y": 4,
      "z": 4,
      "name": "Wood_Birch_Trunk",
      "support": 15
    },
    {
      "x": 4,
      "y": 5,
      "z": 4,
      "name": "Wood_Birch_Trunk_Full",
      "support": 15
    },
    {
      "x": 4,
      "y": 9,
      "z": 4,
      "name": "Wood_Birch_Trunk_Full",
      "support": 15
    },
    {
      "x": 4,
      "y": 10,
      "z": 4,
      "name": "Wood_Birch_Trunk",
      "support": 15
    },
    {
      "x": 4,
      "y": 11,
      "z": 4,
      "name": "Wood_Birch_Trunk",
      "support": 15
    },
    {
      "x": 4,
      "y": 12,
      "z": 4,
      "name": "Wood_Birch_Trunk",
      "support": 15
    },
    {
      "x": 4,
      "y": 13,
      "z": 4,
      "name": "Wood_Birch_Trunk_Full",
      "support": 15
    },
    {
      "x": 4,
      "y": 3,
      "z": 5,
      "name": "Wood_Birch_Trunk_Full",
      "support": 15
    },
    {
      "x": 4,
      "y": 4,
      "z": 5,
      "name": "Wood_Birch_Trunk",
      "support": 15
    },
    {
      "x": 4,
      "y": 5,
      "z": 5,
      "name": "Wood_Birch_Trunk",
      "support": 15
    },
    {
      "x": 4,
      "y": 6,
      "z": 5,
      "name": "Wood_Birch_Trunk",
      "support": 15
    },
    {
      "x": 4,
      "y": 7,
      "z": 5,
      "name": "Wood_Birch_Trunk",
      "support": 15
    },
    {
      "x": 4,
      "y": 8,
      "z": 5,
      "name": "Wood_Birch_Trunk",
      "support": 15
    },
    {
      "x": 4,
      "y": 9,
      "z": 5,
      "name": "Wood_Birch_Trunk",
      "support": 15
    },
    {
      "x": 4,
      "y": 10,
      "z": 5,
      "name": "Wood_Birch_Trunk",
      "support": 15
    },
    {
      "x": 4,
      "y": 11,
      "z": 5,
      "name": "Wood_Birch_Trunk_Full",
      "support": 15
    },
    {
      "x": 4,
      "y": 4,
      "z": 6,
      "name": "Wood_Birch_Trunk_Full",
      "support": 15
    },
    {
      "x": 4,
      "y": 5,
      "z": 6,
      "name": "Wood_Birch_Trunk",
      "support": 15
    },
    {
      "x": 4,
      "y": 6,
      "z": 6,
      "name": "Wood_Birch_Trunk",
      "support": 15
    },
    {
      "x": 4,
      "y": 7,
      "z": 6,
      "name": "Wood_Birch_Trunk",
      "support": 15
    },
    {
      "x": 4,
      "y": 8,
      "z": 6,
      "name": "Wood_Birch_Trunk",
      "support": 15
    },
    {
      "x": 4,
      "y": 9,
      "z": 6,
      "name": "Wood_Birch_Trunk_Full",
      "support": 15
    },
    {
      "x": 5,
      "y": 4,
      "z": -1,
      "name": "Wood_Birch_Trunk_Full",
      "support": 15
    },
    {
      "x": 5,
      "y": 5,
      "z": -1,
      "name": "Wood_Birch_Trunk_Full",
      "support": 15
    },
    {
      "x": 5,
      "y": 8,
      "z": -1,
      "name": "Wood_Birch_Trunk_Full",
      "support": 15
    },
    {
      "x": 5,
      "y": 9,
      "z": -1,
      "name": "Wood_Birch_Trunk",
      "support": 15
    },
    {
      "x": 5,
      "y": 10,
      "z": -1,
      "name": "Wood_Birch_Trunk",
      "support": 15
    },
    {
      "x": 5,
      "y": 11,
      "z": -1,
      "name": "Wood_Birch_Trunk",
      "support": 15
    },
    {
      "x": 5,
      "y": 12,
      "z": -1,
      "name": "Wood_Birch_Trunk",
      "support": 15
    },
    {
      "x": 5,
      "y": 13,
      "z": -1,
      "name": "Wood_Birch_Trunk",
      "support": 15
    },
    {
      "x": 5,
      "y": 14,
      "z": -1,
      "name": "Wood_Birch_Trunk",
      "support": 15
    },
    {
      "x": 5,
      "y": 15,
      "z": -1,
      "name": "Wood_Birch_Trunk",
      "support": 15
    },
    {
      "x": 5,
      "y": 16,
      "z": -1,
      "name": "Wood_Birch_Trunk_Full",
      "support": 15
    },
    {
      "x": 5,
      "y": 10,
      "z": 0,
      "name": "Wood_Birch_Trunk_Full",
      "support": 15
    },
    {
      "x": 5,
      "y": 11,
      "z": 0,
      "name": "Wood_Birch_Trunk",
      "support": 15
    },
    {
      "x": 5,
      "y": 12,
      "z": 0,
      "name": "Wood_Birch_Trunk",
      "support": 15
    },
    {
      "x": 5,
      "y": 13,
      "z": 0,
      "name": "Wood_Birch_Trunk",
      "support": 15
    },
    {
      "x": 5,
      "y": 14,
      "z": 0,
      "name": "Wood_Birch_Trunk",
      "support": 15
    },
    {
      "x": 5,
      "y": 15,
      "z": 0,
      "name": "Wood_Birch_Trunk",
      "support": 15
    },
    {
      "x": 5,
      "y": 16,
      "z": 0,
      "name": "Wood_Birch_Trunk_Full",
      "support": 15
    },
    {
      "x": 5,
      "y": 4,
      "z": 5,
      "name": "Wood_Birch_Trunk_Full",
      "support": 15
    },
    {
      "x": 5,
      "y": 5,
      "z": 5,
      "name": "Wood_Birch_Trunk",
      "support": 15
    },
    {
      "x": 5,
      "y": 6,
      "z": 5,
      "name": "Wood_Birch_Trunk",
      "support": 15
    },
    {
      "x": 5,
      "y": 7,
      "z": 5,
      "name": "Wood_Birch_Trunk",
      "support": 15
    },
    {
      "x": 5,
      "y": 8,
      "z": 5,
      "name": "Wood_Birch_Trunk",
      "support": 15
    },
    {
      "x": 5,
      "y": 9,
      "z": 5,
      "name": "Wood_Birch_Trunk_Full",
      "support": 15
    },
    {
      "x": 5,
      "y": 6,
      "z": 6,
      "name": "Wood_Birch_Trunk_Full",
      "support": 15
    },
    {
      "x": 5,
      "y": 7,
      "z": 6,
      "name": "Wood_Birch_Trunk_Full",
      "support": 15
    },
    {
      "x": 6,
      "y": 4,
      "z": -1,
      "name": "Wood_Birch_Trunk_Full",
      "support": 15
    }
  ]
}