{
  "version": 8,
  "blockIdVersion": 11,
  "anchorX": 0,
  "anchorY": 14,
  "anchorZ": 0,
  "blocks": [
    {
      "x": -20,
      "y": 25,
      "z": -5,
      "name": "Plant_Leaves_Aspen"
    },
    {
      "x": -20,
      "y": 25,
      "z": -4,
      "name": "Plant_Leaves_Aspen"
    },
    {
      "x": -20,
      "y": 25,
      "z": -3,
      "name": "Plant_Leaves_Aspen"
    },
    {
      "x": -19,
      "y": 25,
      "z": -8,
      "name": "Plant_Leaves_Aspen"
    },
    {
      "x": -19,
      "y": 25,
      "z": -7,
      "name": "Plant_Leaves_Aspen"
    },
    {
      "x": -19,
      "y": 25,
      "z": -6,
      "name": "Plant_Leaves_Aspen"
    },
    {
      "x": -19,
      "y": 25,
      "z": -5,
      "name": "Plant_Leaves_Aspen"
    },
    {
      "x": -19,
      "y": 25,
      "z": -4,
      "name": "Plant_Leaves_Aspen"
    },
    {
      "x": -19,
      "y": 25,
      "z": -3,
      "name": "Plant_Leaves_Aspen"
    },
    {
      "x": -19,
      "y": 25,
      "z": -2,
      "name": "Plant_Leaves_Aspen"
    },
    {
      "x": -18,
      "y": 25,
      "z": -9,
      "name": "Plant_Leaves_Aspen"
    },
    {
      "x": -18,
      "y": 25,
      "z": -8,
      "name": "Plant_Leaves_Aspen"
    },
    {
      "x": -18,
      "y": 25,
      "z": -7,
      "name": "Plant_Leaves_Aspen"
    },
    {
      "x": -18,
      "y": 25,
      "z": -6,
      "name": "Plant_Leaves_Aspen"
    },
    {
      "x": -18,
      "y": 25,
      "z": -5,
      "name": "Plant_Leaves_Aspen"
    },
    {
      "x": -18,
      "y": 25,
      "z": -4,
      "name": "Plant_Leaves_Aspen"
    },
    {
      "x": -18,
      "y": 25,
      "z": -3,
      "name": "Plant_Leaves_Aspen"
    },
    {
      "x": -18,
      "y": 25,
      "z": -2,
      "name": "Plant_Leaves_Aspen"
    },
    {
      "x": -18,
      "y": 25,
      "z": -1,
      "name": "Plant_Leaves_Aspen"
    },
    {
      "x": -17,
      "y": 25,
      "z": -10,
      "name": "Plant_Leaves_Aspen"
    },
    {
      "x": -17,
      "y": 25,
      "z": -9,
      "name": "Plant_Leaves_Aspen"
    },
    {
      "x": -17,
      "y": 25,
      "z": -8,
      "name": "Plant_Leaves_Aspen"
    },
    {
      "x": -17,
      "y": 25,
      "z": -7,
      "name": "Plant_Leaves_Aspen"
    },
    {
      "x": -17,
      "y": 24,
      "z": -6,
      "name": "Plant_Leaves_Aspen"
    },
    {
      "x": -17,
      "y": 25,
      "z": -6,
      "name": "Plant_Leaves_Aspen"
    },
    {
      "x": -17,
      "y": 26,
      "z": -6,
      "name": "Plant_Leaves_Aspen"
    },
    {
      "x": -17,
      "y": 24,
      "z": -5,
      "name": "Plant_Leaves_Aspen"
    },
    {
      "x": -17,
      "y": 25,
      "z": -5,
      "name": "Plant_Leaves_Aspen"
    },
    {
      "x": -17,
      "y": 26,
      "z": -5,
      "name": "Plant_Leaves_Aspen"
    },
    {
      "x": -17,
      "y": 24,
      "z": -4,
      "name": "Plant_Leaves_Aspen"
    },
    {
      "x": -17,
      "y": 25,
      "z": -4,
      "name": "Plant_Leaves_Aspen"
    },
    {
      "x": -17,
      "y": 26,
      "z": -4,
      "name": "Plant_Leaves_Aspen"
    },
    {
      "x": -17,
      "y": 25,
      "z": -3,
      "name": "Plant_Leaves_Aspen"
    },
    {
      "x": -17,
      "y": 25,
      "z": -2,
      "name": "Plant_Leaves_Aspen"
    },
    {
      "x": -17,
      "y": 25,
      "z": -1,
      "name": "Plant_Leaves_Aspen"
    },
    {
      "x": -17,
      "y": 27,
      "z": 4,
      "name": "Plant_Leaves_Aspen",
      "support": 4
    },
    {
      "x": -16,
      "y": 25,
      "z": -10,
      "name": "Plant_Leaves_Aspen"
    },
    {
      "x": -16,
      "y": 25,
      "z": -9,
      "name": "Plant_Leaves_Aspen"
    },
    {
      "x": -16,
      "y": 25,
      "z": -8,
      "name": "Plant_Leaves_Aspen"
    },
    {
      "x": -16,
      "y": 24,
      "z": -7,
      "name": "Plant_Leaves_Aspen"
    },
    {
      "x": -16,
      "y": 25,
      "z": -7,
      "name": "Plant_Leaves_Aspen"
    },
    {
      "x": -16,
      "y": 26,
      "z": -7,
      "name": "Plant_Leaves_Aspen"
    },
    {
      "x": -16,
      "y": 24,
      "z": -6,
      "name": "Plant_Leaves_Aspen"
    },
    {
      "x": -16,
      "y": 25,
      "z": -6,
      "name": "Plant_Leaves_Aspen"
    },
    {
      "x": -16,
      "y": 26,
      "z": -6,
      "name": "Plant_Leaves_Aspen"
    },
    {
      "x": -16,
      "y": 24,
      "z": -5,
      "name": "Plant_Leaves_Aspen"
    },
    {
      "x": -16,
      "y": 25,
      "z": -5,
      "name": "Plant_Leaves_Aspen"
    },
    {
      "x": -16,
      "y": 26,
      "z": -5,
      "name": "Plant_Leaves_Aspen"
    },
    {
      "x": -16,
      "y": 24,
      "z": -4,
      "name": "Plant_Leaves_Aspen"
    },
    {
      "x": -16,
      "y": 25,
      "z": -4,
      "name": "Plant_Leaves_Aspen"
    },
    {
      "x": -16,
      "y": 26,
      "z": -4,
      "name": "Plant_Leaves_Aspen"
    },
    {
      "x": -16,
      "y": 24,
      "z": -3,
      "name": "Plant_Leaves_Aspen"
    },
    {
      "x": -16,
      "y": 25,
      "z": -3,
      "name": "Plant_Leaves_Aspen"
    },
    {
      "x": -16,
      "y": 26,
      "z": -3,
      "name": "Plant_Leaves_Aspen"
    },
    {
      "x": -16,
      "y": 25,
      "z": -2,
      "name": "Plant_Leaves_Aspen"
    },
    {
      "x": -16,
      "y": 25,
      "z": -1,
      "name": "Plant_Leaves_Aspen"
    },
    {
      "x": -16,
      "y": 27,
      "z": 3,
      "name": "Plant_Leaves_Aspen",
      "support": 4
    },
    {
      "x": -16,
      "y": 27,
      "z": 4,
      "name": "Plant_Leaves_Aspen",
      "support": 3
    },
    {
      "x": -16,
      "y": 27,
      "z": 5,
      "name": "Plant_Leaves_Aspen",
      "support": 4
    },
    {
      "x": -16,
      "y": 27,
      "z": 8,
      "name": "Plant_Leaves_Aspen",
      "support": 4
    },
    {
      "x": -15,
      "y": 25,
      "z": -10,
      "name": "Plant_Leaves_Aspen"
    },
    {
      "x": -15,
      "y": 25,
      "z": -9,
      "name": "Plant_Leaves_Aspen"
    },
    {
      "x": -15,
      "y": 25,
      "z": -8,
      "name": "Plant_Leaves_Aspen"
    },
    {
      "x": -15,
      "y": 32,
      "z": -8,
      "name": "Plant_Leaves_Aspen",
      "support": 4
    },
    {
      "x": -15,
      "y": 24,
      "z": -7,
      "name": "Plant_Leaves_Aspen"
    },
    {
      "x": -15,
      "y": 25,
      "z": -7,
      "name": "Plant_Leaves_Aspen"
    },
    {
      "x": -15,
      "y": 26,
      "z": -7,
      "name": "Plant_Leaves_Aspen"
    },
    {
      "x": -15,
      "y": 24,
      "z": -6,
      "name": "Plant_Leaves_Aspen"
    },
    {
      "x": -15,
      "y": 25,
      "z": -6,
      "name": "Plant_Leaves_Aspen"
    },
    {
      "x": -15,
      "y": 26,
      "z": -6,
      "name": "Plant_Leaves_Aspen"
    },
    {
      "x": -15,
      "y": 24,
      "z": -5,
      "name": "Plant_Leaves_Aspen"
    },
    {
      "x": -15,
      "y": 25,
      "z": -5,
      "name": "Wood_Birch_Branch_Long",
      "support": 15,
      "rotation": 5
    },
    {
      "x": -15,
      "y": 26,
      "z": -5,
      "name": "Plant_Leaves_Aspen"
    },
    {
      "x": -15,
      "y": 24,
      "z": -4,
      "name": "Plant_Leaves_Aspen"
    },
    {
      "x": -15,
      "y": 25,
      "z": -4,
      "name": "Plant_Leaves_Aspen"
    },
    {
      "x": -15,
      "y": 26,
      "z": -4,
      "name": "Plant_Leaves_Aspen"
    },
    {
      "x": -15,
      "y": 24,
      "z": -3,
      "name": "Plant_Leaves_Aspen"
    },
    {
      "x": -15,
      "y": 25,
      "z": -3,
      "name": "Plant_Leaves_Aspen"
    },
    {
      "x": -15,
      "y": 26,
      "z": -3,
      "name": "Plant_Leaves_Aspen"
    },
    {
      "x": -15,
      "y": 25,
      "z": -2,
      "name": "Plant_Leaves_Aspen"
    },
    {
      "x": -15,
      "y": 27,
      "z": 2,
      "name": "Plant_Leaves_Aspen",
      "support": 4
    },
    {
      "x": -15,
      "y": 30,
      "z": 2,
      "name": "Plant_Leaves_Aspen",
      "support": 4
    },
    {
      "x": -15,
      "y": 27,
      "z": 3,
      "name": "Plant_Leaves_Aspen",
      "support": 3
    },
    {
      "x": -15,
      "y": 30,
      "z": 3,
      "name": "Plant_Leaves_Aspen",
      "support": 3
    },
    {
      "x": -15,
      "y": 27,
      "z": 4,
      "name": "Plant_Leaves_Aspen",
      "support": 2
    },
    {
      "x": -15,
      "y": 30,
      "z": 4,
      "name": "Plant_Leaves_Aspen",
      "support": 2
    },
    {
      "x": -15,
      "y": 27,
      "z": 5,
      "name": "Plant_Leaves_Aspen",
      "support": 3
    },
    {
      "x": -15,
      "y": 30,
      "z": 5,
      "name": "Plant_Leaves_Aspen",
      "support": 3
    },
    {
      "x": -15,
      "y": 27,
      "z": 6,
      "name": "Plant_Leaves_Aspen",
      "support": 4
    },
    {
      "x": -15,
      "y": 27,
      "z": 7,
      "name": "Plant_Leaves_Aspen",
      "support": 4
    },
    {
      "x": -15,
      "y": 27,
      "z": 8,
      "name": "Plant_Leaves_Aspen",
      "support": 3
    },
    {
      "x": -15,
      "y": 27,
      "z": 9,
      "name": "Plant_Leaves_Aspen",
      "support": 4
    },
    {
      "x": -14,
      "y": 32,
      "z": -10,
      "name": "Plant_Leaves_Aspen",
      "support": 3
    },
    {
      "x": -14,
      "y": 25,
      "z": -9,
      "name": "Plant_Leaves_Aspen"
    },
    {
      "x": -14,
      "y": 32,
      "z": -9,
      "name": "Plant_Leaves_Aspen",
      "support": 2
    },
    {
      "x": -14,
      "y": 25,
      "z": -8,
      "name": "Plant_Leaves_Aspen"
    },
    {
      "x": -14,
      "y": 31,
      "z": -8,
      "name": "Plant_Leaves_Aspen",
      "support": 4
    },
    {
      "x": -14,
      "y": 32,
      "z": -8,
      "name": "Plant_Leaves_Aspen",
      "support": 3
    },
    {
      "x": -14,
      "y": 24,
      "z": -7,
      "name": "Plant_Leaves_Aspen"
    },
    {
      "x": -14,
      "y": 25,
      "z": -7,
      "name": "Plant_Leaves_Aspen"
    },
    {
      "x": -14,
      "y": 26,
      "z": -7,
      "name": "Plant_Leaves_Aspen"
    },
    {
      "x": -14,
      "y": 32,
      "z": -7,
      "name": "Plant_Leaves_Aspen",
      "support": 4
    },
    {
      "x": -14,
      "y": 24,
      "z": -6,
      "name": "Plant_Leaves_Aspen"
    },
    {
      "x": -14,
      "y": 25,
      "z": -6,
      "name": "Plant_Leaves_Aspen"
    },
    {
      "x": -14,
      "y": 26,
      "z": -6,
      "name": "Plant_Leaves_Aspen"
    },
    {
      "x": -14,
      "y": 24,
      "z": -5,
      "name": "Plant_Leaves_Aspen"
    },
    {
      "x": -14,
      "y": 25,
      "z": -5,
      "name": "Wood_Birch_Branch_Long",
      "support": 15,
      "rotation": 5
    },
    {
      "x": -14,
      "y": 26,
      "z": -5,
      "name": "Plant_Leaves_Aspen"
    },
    {
      "x": -14,
      "y": 24,
      "z": -4,
      "name": "Plant_Leaves_Aspen"
    },
    {
      "x": -14,
      "y": 25,
      "z": -4,
      "name": "Plant_Leaves_Aspen"
    },
    {
      "x": -14,
      "y": 26,
      "z": -4,
      "name": "Plant_Leaves_Aspen"
    },
    {
      "x": -14,
      "y": 24,
      "z": -3,
      "name": "Plant_Leaves_Aspen"
    },
    {
      "x": -14,
      "y": 25,
      "z": -3,
      "name": "Plant_Leaves_Aspen"
    },
    {
      "x": -14,
      "y": 26,
      "z": -3,
      "name": "Plant_Leaves_Aspen"
    },
    {
      "x": -14,
      "y": 29,
      "z": -3,
      "name": "Wood_Birch_Branch_Corner",
      "support": 15,
      "rotation": 3
    },
    {
      "x": -14,
      "y": 30,
      "z": -3,
      "name": "Wood_Birch_Branch_Long",
      "support": 15
    },
    {
      "x": -14,
      "y": 31,
      "z": -3,
      "name": "Wood_Birch_Branch_Long",
      "support": 15
    },
    {
      "x": -14,
      "y": 32,
      "z": -3,
      "name": "Wood_Birch_Branch_Corner",
      "support": 15,
      "rotation": 9
    },
    {
      "x": -14,
      "y": 25,
      "z": -2,
      "name": "Plant_Leaves_Aspen"
    },
    {
      "x": -14,
      "y": 27,
      "z": 1,
      "name": "Plant_Leaves_Aspen",
      "support": 4
    },
    {
      "x": -14,
      "y": 30,
      "z": 1,
      "name": "Plant_Leaves_Aspen",
      "support": 4
    },
    {
      "x": -14,
      "y": 27,
      "z": 2,
      "name": "Plant_Leaves_Aspen",
      "support": 3
    },
    {
      "x": -14,
      "y": 30,
      "z": 2,
      "name": "Plant_Leaves_Aspen",
      "support": 3
    },
    {
      "x": -14,
      "y": 27,
      "z": 3,
      "name": "Plant_Leaves_Aspen",
      "support": 2
    },
    {
      "x": -14,
      "y": 29,
      "z": 3,
      "name": "Plant_Leaves_Aspen",
      "support": 2
    },
    {
      "x": -14,
      "y": 30,
      "z": 3,
      "name": "Plant_Leaves_Aspen",
      "support": 2
    },
    {
      "x": -14,
      "y": 31,
      "z": 3,
      "name": "Plant_Leaves_Aspen",
      "support": 3
    },
    {
      "x": -14,
      "y": 27,
      "z": 4,
      "name": "Plant_Leaves_Aspen",
      "support": 1
    },
    {
      "x": -14,
      "y": 29,
      "z": 4,
      "name": "Plant_Leaves_Aspen",
      "support": 1
    },
    {
      "x": -14,
      "y": 30,
      "z": 4,
      "name": "Plant_Leaves_Aspen",
      "support": 1
    },
    {
      "x": -14,
      "y": 31,
      "z": 4,
      "name": "Plant_Leaves_Aspen",
      "support": 2
    },
    {
      "x": -14,
      "y": 27,
      "z": 5,
      "name": "Plant_Leaves_Aspen",
      "support": 2
    },
    {
      "x": -14,
      "y": 29,
      "z": 5,
      "name": "Plant_Leaves_Aspen",
      "support": 2
    },
    {
      "x": -14,
      "y": 30,
      "z": 5,
      "name": "Plant_Leaves_Aspen",
      "support": 2
    },
    {
      "x": -14,
      "y": 31,
      "z": 5,
      "name": "Plant_Leaves_Aspen",
      "support": 3
    },
    {
      "x": -14,
      "y": 27,
      "z": 6,
      "name": "Plant_Leaves_Aspen",
      "support": 3
    },
    {
      "x": -14,
      "y": 30,
      "z": 6,
      "name": "Plant_Leaves_Aspen",
      "support": 3
    },
    {
      "x": -14,
      "y": 27,
      "z": 7,
      "name": "Plant_Leaves_Aspen",
      "support": 3
    },
    {
      "x": -14,
      "y": 27,
      "z": 8,
      "name": "Plant_Leaves_Aspen",
      "support": 2
    },
    {
      "x": -14,
      "y": 27,
      "z": 9,
      "name": "Plant_Leaves_Aspen",
      "support": 3
    },
    {
      "x": -14,
      "y": 27,
      "z": 10,
      "name": "Plant_Leaves_Aspen",
      "support": 4
    },
    {
      "x": -13,
      "y": 32,
      "z": -12,
      "name": "Plant_Leaves_Aspen",
      "support": 15
    },
    {
      "x": -13,
      "y": 32,
      "z": -11,
      "name": "Plant_Leaves_Aspen",
      "support": 2
    },
    {
      "x": -13,
      "y": 31,
      "z": -10,
      "name": "Plant_Leaves_Aspen",
      "support": 3
    },
    {
      "x": -13,
      "y": 32,
      "z": -10,
      "name": "Plant_Leaves_Aspen",
      "support": 2
    },
    {
      "x": -13,
      "y": 33,
      "z": -10,
      "name": "Plant_Leaves_Aspen",
      "support": 3
    },
    {
      "x": -13,
      "y": 31,
      "z": -9,
      "name": "Plant_Leaves_Aspen",
      "support": 2
    },
    {
      "x": -13,
      "y": 32,
      "z": -9,
      "name": "Plant_Leaves_Aspen",
      "support": 1
    },
    {
      "x": -13,
      "y": 33,
      "z": -9,
      "name": "Plant_Leaves_Aspen",
      "support": 2
    },
    {
      "x": -13,
      "y": 25,
      "z": -8,
      "name": "Plant_Leaves_Aspen"
    },
    {
      "x": -13,
      "y": 31,
      "z": -8,
      "name": "Plant_Leaves_Aspen",
      "support": 3
    },
    {
      "x": -13,
      "y": 32,
      "z": -8,
      "name": "Plant_Leaves_Aspen",
      "support": 2
    },
    {
      "x": -13,
      "y": 33,
      "z": -8,
      "name": "Plant_Leaves_Aspen",
      "support": 3
    },
    {
      "x": -13,
      "y": 25,
      "z": -7,
      "name": "Plant_Leaves_Aspen"
    },
    {
      "x": -13,
      "y": 31,
      "z": -7,
      "name": "Plant_Leaves_Aspen",
      "support": 4
    },
    {
      "x": -13,
      "y": 32,
      "z": -7,
      "name": "Plant_Leaves_Aspen",
      "support": 3
    },
    {
      "x": -13,
      "y": 24,
      "z": -6,
      "name": "Plant_Leaves_Aspen"
    },
    {
      "x": -13,
      "y": 25,
      "z": -6,
      "name": "Plant_Leaves_Aspen"
    },
    {
      "x": -13,
      "y": 26,
      "z": -6,
      "name": "Plant_Leaves_Aspen"
    },
    {
      "x": -13,
      "y": 32,
      "z": -6,
      "name": "Plant_Leaves_Aspen",
      "support": 4
    },
    {
      "x": -13,
      "y": 24,
      "z": -5,
      "name": "Plant_Leaves_Aspen"
    },
    {
      "x": -13,
      "y": 25,
      "z": -5,
      "name": "Wood_Birch_Branch_Long",
      "support": 15,
      "rotation": 5
    },
    {
      "x": -13,
      "y": 26,
      "z": -5,
      "name": "Plant_Leaves_Aspen"
    },
    {
      "x": -13,
      "y": 24,
      "z": -4,
      "name": "Plant_Leaves_Aspen"
    },
    {
      "x": -13,
      "y": 25,
      "z": -4,
      "name": "Plant_Leaves_Aspen"
    },
    {
      "x": -13,
      "y": 26,
      "z": -4,
      "name": "Plant_Leaves_Aspen"
    },
    {
      "x": -13,
      "y": 25,
      "z": -3,
      "name": "Plant_Leaves_Aspen"
    },
    {
      "x": -13,
      "y": 29,
      "z": -3,
      "name": "Wood_Birch_Branch_Long",
      "support": 15,
      "rotation": 5
    },
    {
      "x": -13,
      "y": 30,
      "z": -3,
      "name": "Wood_Birch_Branch_Corner",
      "support": 15,
      "rotation": 3
    },
    {
      "x": -13,
      "y": 32,
      "z": -3,
      "name": "Wood_Birch_Branch_Long",
      "support": 15,
      "rotation": 5
    },
    {
      "x": -13,
      "y": 27,
      "z": 0,
      "name": "Plant_Leaves_Aspen",
      "support": 4
    },
    {
      "x": -13,
      "y": 30,
      "z": 0,
      "name": "Plant_Leaves_Aspen",
      "support": 4
    },
    {
      "x": -13,
      "y": 27,
      "z": 1,
      "name": "Plant_Leaves_Aspen",
      "support": 3
    },
    {
      "x": -13,
      "y": 30,
      "z": 1,
      "name": "Plant_Leaves_Aspen",
      "support": 3
    },
    {
      "x": -13,
      "y": 27,
      "z": 2,
      "name": "Plant_Leaves_Aspen",
      "support": 2
    },
    {
      "x": -13,
      "y": 30,
      "z": 2,
      "name": "Plant_Leaves_Aspen",
      "support": 2
    },
    {
      "x": -13,
      "y": 31,
      "z": 2,
      "name": "Plant_Leaves_Aspen",
      "support": 3
    },
    {
      "x": -13,
      "y": 27,
      "z": 3,
      "name": "Plant_Leaves_Aspen",
      "support": 1
    },
    {
      "x": -13,
      "y": 30,
      "z": 3,
      "name": "Plant_Leaves_Aspen",
      "support": 1
    },
    {
      "x": -13,
      "y": 31,
      "z": 3,
      "name": "Plant_Leaves_Aspen",
      "support": 2
    },
    {
      "x": -13,
      "y": 27,
      "z": 4,
      "name": "Plant_Leaves_Aspen"
    },
    {
      "x": -13,
      "y": 29,
      "z": 4,
      "name": "Plant_Leaves_Aspen"
    },
    {
      "x": -13,
      "y": 30,
      "z": 4,
      "name": "Plant_Leaves_Aspen"
    },
    {
      "x": -13,
      "y": 31,
      "z": 4,
      "name": "Plant_Leaves_Aspen",
      "support": 1
    },
    {
      "x": -13,
      "y": 27,
      "z": 5,
      "name": "Plant_Leaves_Aspen",
      "support": 1
    },
    {
      "x": -13,
      "y": 29,
      "z": 5,
      "name": "Plant_Leaves_Aspen",
      "support": 1
    },
    {
      "x": -13,
      "y": 30,
      "z": 5,
      "name": "Plant_Leaves_Aspen",
      "support": 1
    },
    {
      "x": -13,
      "y": 31,
      "z": 5,
      "name": "Plant_Leaves_Aspen",
      "support": 2
    },
    {
      "x": -13,
      "y": 27,
      "z": 6,
      "name": "Plant_Leaves_Aspen",
      "support": 2
    },
    {
      "x": -13,
      "y": 29,
      "z": 6,
      "name": "Plant_Leaves_Aspen",
      "support": 2
    },
    {
      "x": -13,
      "y": 30,
      "z": 6,
      "name": "Plant_Leaves_Aspen",
      "support": 2
    },
    {
      "x": -13,
      "y": 31,
      "z": 6,
      "name": "Plant_Leaves_Aspen",
      "support": 3
    },
    {
      "x": -13,
      "y": 26,
      "z": 7,
      "name": "Plant_Leaves_Aspen",
      "support": 2
    },
    {
      "x": -13,
      "y": 27,
      "z": 7,
      "name": "Plant_Leaves_Aspen",
      "support": 2
    },
    {
      "x": -13,
      "y": 28,
      "z": 7,
      "name": "Plant_Leaves_Aspen",
      "support": 3
    },
    {
      "x": -13,
      "y": 30,
      "z": 7,
      "name": "Plant_Leaves_Aspen",
      "support": 3
    },
    {
      "x": -13,
      "y": 26,
      "z": 8,
      "name": "Plant_Leaves_Aspen",
      "support": 1
    },
    {
      "x": -13,
      "y": 27,
      "z": 8,
      "name": "Plant_Leaves_Aspen",
      "support": 1
    },
    {
      "x": -13,
      "y": 28,
      "z": 8,
      "name": "Plant_Leaves_Aspen",
      "support": 2
    },
    {
      "x": -13,
      "y": 26,
      "z": 9,
      "name": "Plant_Leaves_Aspen",
      "support": 2
    },
    {
      "x": -13,
      "y": 27,
      "z": 9,
      "name": "Plant_Leaves_Aspen",
      "support": 2
    },
    {
      "x": -13,
      "y": 28,
      "z": 9,
      "name": "Plant_Leaves_Aspen",
      "support": 3
    },
    {
      "x": -13,
      "y": 27,
      "z": 10,
      "name": "Plant_Leaves_Aspen",
      "support": 3
    },
    {
      "x": -13,
      "y": 27,
      "z": 11,
      "name": "Plant_Leaves_Aspen",
      "support": 4
    },
    {
      "x": -12,
      "y": 27,
      "z": -13,
      "name": "Plant_Leaves_Aspen",
      "support": 3
    },
    {
      "x": -12,
      "y": 27,
      "z": -12,
      "name": "Plant_Leaves_Aspen",
      "support": 2
    },
    {
      "x": -12,
      "y": 32,
      "z": -12,
      "name": "Plant_Leaves_Aspen",
      "support": 2
    },
    {
      "x": -12,
      "y": 27,
      "z": -11,
      "name": "Plant_Leaves_Aspen",
      "support": 3
    },
    {
      "x": -12,
      "y": 31,
      "z": -11,
      "name": "Plant_Leaves_Aspen",
      "support": 3
    },
    {
      "x": -12,
      "y": 32,
      "z": -11,
      "name": "Plant_Leaves_Aspen",
      "support": 2
    },
    {
      "x": -12,
      "y": 33,
      "z": -11,
      "name": "Plant_Leaves_Aspen",
      "support": 3
    },
    {
      "x": -12,
      "y": 31,
      "z": -10,
      "name": "Plant_Leaves_Aspen",
      "support": 2
    },
    {
      "x": -12,
      "y": 32,
      "z": -10,
      "name": "Plant_Leaves_Aspen",
      "support": 1
    },
    {
      "x": -12,
      "y": 33,
      "z": -10,
      "name": "Plant_Leaves_Aspen",
      "support": 2
    },
    {
      "x": -12,
      "y": 31,
      "z": -9,
      "name": "Plant_Leaves_Aspen",
      "support": 1
    },
    {
      "x": -12,
      "y": 32,
      "z": -9,
      "name": "Plant_Leaves_Aspen"
    },
    {
      "x": -12,
      "y": 33,
      "z": -9,
      "name": "Plant_Leaves_Aspen",
      "support": 1
    },
    {
      "x": -12,
      "y": 31,
      "z": -8,
      "name": "Plant_Leaves_Aspen",
      "support": 2
    },
    {
      "x": -12,
      "y": 32,
      "z": -8,
      "name": "Plant_Leaves_Aspen",
      "support": 1
    },
    {
      "x": -12,
      "y": 33,
      "z": -8,
      "name": "Plant_Leaves_Aspen",
      "support": 2
    },
    {
      "x": -12,
      "y": 31,
      "z": -7,
      "name": "Plant_Leaves_Aspen",
      "support": 3
    },
    {
      "x": -12,
      "y": 32,
      "z": -7,
      "name": "Plant_Leaves_Aspen",
      "support": 2
    },
    {
      "x": -12,
      "y": 33,
      "z": -7,
      "name": "Plant_Leaves_Aspen",
      "support": 3
    },
    {
      "x": -12,
      "y": 25,
      "z": -6,
      "name": "Plant_Leaves_Aspen"
    },
    {
      "x": -12,
      "y": 31,
      "z": -6,
      "name": "Plant_Leaves_Aspen",
      "support": 4
    },
    {
      "x": -12,
      "y": 32,
      "z": -6,
      "name": "Plant_Leaves_Aspen",
      "support": 3
    },
    {
      "x": -12,
      "y": 25,
      "z": -5,
      "name": "Wood_Birch_Trunk_Full",
      "support": 15,
      "rotation": 5
    },
    {
      "x": -12,
      "y": 32,
      "z": -5,
      "name": "Plant_Leaves_Aspen",
      "support": 4
    },
    {
      "x": -12,
      "y": 25,
      "z": -4,
      "name": "Plant_Leaves_Aspen"
    },
    {
      "x": -12,
      "y": 29,
      "z": -3,
      "name": "Wood_Birch_Branch_Long",
      "support": 15,
      "rotation": 5
    },
    {
      "x": -12,
      "y": 30,
      "z": -3,
      "name": "Wood_Birch_Branch_Corner",
      "support": 15,
      "rotation": 1
    },
    {
      "x": -12,
      "y": 31,
      "z": -3,
      "name": "Wood_Birch_Branch_Long",
      "support": 15
    },
    {
      "x": -12,
      "y": 32,
      "z": -3,
      "name": "Wood_Birch_Branch_Corner",
      "support": 15,
      "rotation": 11
    },
    {
      "x": -12,
      "y": 27,
      "z": -1,
      "name": "Plant_Leaves_Aspen",
      "support": 4
    },
    {
      "x": -12,
      "y": 30,
      "z": -1,
      "name": "Plant_Leaves_Aspen",
      "support": 4
    },
    {
      "x": -12,
      "y": 26,
      "z": 0,
      "name": "Plant_Leaves_Aspen",
      "support": 3
    },
    {
      "x": -12,
      "y": 27,
      "z": 0,
      "name": "Plant_Leaves_Aspen",
      "support": 3
    },
    {
      "x": -12,
      "y": 30,
      "z": 0,
      "name": "Plant_Leaves_Aspen",
      "support": 3
    },
    {
      "x": -12,
      "y": 26,
      "z": 1,
      "name": "Plant_Leaves_Aspen",
      "support": 2
    },
    {
      "x": -12,
      "y": 27,
      "z": 1,
      "name": "Plant_Leaves_Aspen",
      "support": 2
    },
    {
      "x": -12,
      "y": 30,
      "z": 1,
      "name": "Plant_Leaves_Aspen",
      "support": 2
    },
    {
      "x": -12,
      "y": 26,
      "z": 2,
      "name": "Plant_Leaves_Aspen",
      "support": 2
    },
    {
      "x": -12,
      "y": 27,
      "z": 2,
      "name": "Plant_Leaves_Aspen",
      "support": 1
    },
    {
      "x": -12,
      "y": 30,
      "z": 2,
      "name": "Plant_Leaves_Aspen",
      "support": 1
    },
    {
      "x": -12,
      "y": 31,
      "z": 2,
      "name": "Plant_Leaves_Aspen",
      "support": 2
    },
    {
      "x": -12,
      "y": 27,
      "z": 3,
      "name": "Plant_Leaves_Aspen"
    },
    {
      "x": -12,
      "y": 30,
      "z": 3,
      "name": "Plant_Leaves_Aspen"
    },
    {
      "x": -12,
      "y": 31,
      "z": 3,
      "name": "Plant_Leaves_Aspen",
      "support": 1
    },
    {
      "x": -12,
      "y": 26,
      "z": 4,
      "name": "Wood_Birch_Branch_Corner",
      "support": 15,
      "rotation": 3
    },
    {
      "x": -12,
      "y": 27,
      "z": 4,
      "name": "Wood_Birch_Branch_Long",
      "support": 15
    },
    {
      "x": -12,
      "y": 28,
      "z": 4,
      "name": "Wood_Birch_Branch_Long",
      "support": 15
    },
    {
      "x": -12,
      "y": 29,
      "z": 4,
      "name": "Wood_Birch_Branch_Long",
      "support": 15
    },
    {
      "x": -12,
      "y": 30,
      "z": 4,
      "name": "Wood_Birch_Branch_Long",
      "support": 15
    },
    {
      "x": -12,
      "y": 31,
      "z": 4,
      "name": "Plant_Leaves_Aspen"
    },
    {
      "x": -12,
      "y": 27,
      "z": 5,
      "name": "Plant_Leaves_Aspen"
    },
    {
      "x": -12,
      "y": 29,
      "z": 5,
      "name": "Plant_Leaves_Aspen"
    },
    {
      "x": -12,
      "y": 30,
      "z": 5,
      "name": "Plant_Leaves_Aspen"
    },
    {
      "x": -12,
      "y": 31,
      "z": 5,
      "name": "Plant_Leaves_Aspen",
      "support": 1
    },
    {
      "x": -12,
      "y": 26,
      "z": 6,
      "name": "Plant_Leaves_Aspen",
      "support": 2
    },
    {
      "x": -12,
      "y": 27,
      "z": 6,
      "name": "Plant_Leaves_Aspen",
      "support": 1
    },
    {
      "x": -12,
      "y": 28,
      "z": 6,
      "name": "Plant_Leaves_Aspen",
      "support": 2
    },
    {
      "x": -12,
      "y": 29,
      "z": 6,
      "name": "Plant_Leaves_Aspen",
      "support": 1
    },
    {
      "x": -12,
      "y": 30,
      "z": 6,
      "name": "Plant_Leaves_Aspen",
      "support": 1
    },
    {
      "x": -12,
      "y": 31,
      "z": 6,
      "name": "Plant_Leaves_Aspen",
      "support": 2
    },
    {
      "x": -12,
      "y": 26,
      "z": 7,
      "name": "Plant_Leaves_Aspen",
      "support": 1
    },
    {
      "x": -12,
      "y": 27,
      "z": 7,
      "name": "Plant_Leaves_Aspen",
      "support": 1
    },
    {
      "x": -12,
      "y": 28,
      "z": 7,
      "name": "Plant_Leaves_Aspen",
      "support": 2
    },
    {
      "x": -12,
      "y": 30,
      "z": 7,
      "name": "Plant_Leaves_Aspen",
      "support": 2
    },
    {
      "x": -12,
      "y": 26,
      "z": 8,
      "name": "Plant_Leaves_Aspen"
    },
    {
      "x": -12,
      "y": 27,
      "z": 8,
      "name": "Plant_Leaves_Aspen"
    },
    {
      "x": -12,
      "y": 28,
      "z": 8,
      "name": "Plant_Leaves_Aspen",
      "support": 1
    },
    {
      "x": -12,
      "y": 26,
      "z": 9,
      "name": "Plant_Leaves_Aspen",
      "support": 1
    },
    {
      "x": -12,
      "y": 27,
      "z": 9,
      "name": "Plant_Leaves_Aspen",
      "support": 1
    },
    {
      "x": -12,
      "y": 28,
      "z": 9,
      "name": "Plant_Leaves_Aspen",
      "support": 2
    },
    {
      "x": -12,
      "y": 23,
      "z": 10,
      "name": "Plant_Leaves_Aspen"
    },
    {
      "x": -12,
      "y": 26,
      "z": 10,
      "name": "Plant_Leaves_Aspen",
      "support": 2
    },
    {
      "x": -12,
      "y": 27,
      "z": 10,
      "name": "Plant_Leaves_Aspen",
      "support": 2
    },
    {
      "x": -12,
      "y": 28,
      "z": 10,
      "name": "Plant_Leaves_Aspen",
      "support": 3
    },
    {
      "x": -12,
      "y": 23,
      "z": 11,
      "name": "Plant_Leaves_Aspen"
    },
    {
      "x": -12,
      "y": 27,
      "z": 11,
      "name": "Plant_Leaves_Aspen",
      "support": 3
    },
    {
      "x": -12,
      "y": 23,
      "z": 12,
      "name": "Plant_Leaves_Aspen"
    },
    {
      "x": -11,
      "y": 27,
      "z": -14,
      "name": "Plant_Leaves_Aspen",
      "support": 3
    },
    {
      "x": -11,
      "y": 26,
      "z": -13,
      "name": "Plant_Leaves_Aspen",
      "support": 2
    },
    {
      "x": -11,
      "y": 27,
      "z": -13,
      "name": "Plant_Leaves_Aspen",
      "support": 2
    },
    {
      "x": -11,
      "y": 28,
      "z": -13,
      "name": "Plant_Leaves_Aspen",
      "support": 3
    },
    {
      "x": -11,
      "y": 32,
      "z": -13,
      "name": "Plant_Leaves_Aspen",
      "support": 15
    },
    {
      "x": -11,
      "y": 26,
      "z": -12,
      "name": "Plant_Leaves_Aspen",
      "support": 1
    },
    {
      "x": -11,
      "y": 27,
      "z": -12,
      "name": "Plant_Leaves_Aspen",
      "support": 1
    },
    {
      "x": -11,
      "y": 28,
      "z": -12,
      "name": "Plant_Leaves_Aspen",
      "support": 2
    },
    {
      "x": -11,
      "y": 32,
      "z": -12,
      "name": "Plant_Leaves_Aspen",
      "support": 2
    },
    {
      "x": -11,
      "y": 26,
      "z": -11,
      "name": "Plant_Leaves_Aspen",
      "support": 1
    },
    {
      "x": -11,
      "y": 27,
      "z": -11,
      "name": "Plant_Leaves_Aspen",
      "support": 2
    },
    {
      "x": -11,
      "y": 28,
      "z": -11,
      "name": "Plant_Leaves_Aspen",
      "support": 3
    },
    {
      "x": -11,
      "y": 31,
      "z": -11,
      "name": "Plant_Leaves_Aspen",
      "support": 2
    },
    {
      "x": -11,
      "y": 32,
      "z": -11,
      "name": "Plant_Leaves_Aspen",
      "support": 1
    },
    {
      "x": -11,
      "y": 33,
      "z": -11,
      "name": "Plant_Leaves_Aspen",
      "support": 2
    },
    {
      "x": -11,
      "y": 27,
      "z": -10,
      "name": "Plant_Leaves_Aspen",
      "support": 2
    },
    {
      "x": -11,
      "y": 31,
      "z": -10,
      "name": "Plant_Leaves_Aspen",
      "support": 1
    },
    {
      "x": -11,
      "y": 32,
      "z": -10,
      "name": "Plant_Leaves_Aspen"
    },
    {
      "x": -11,
      "y": 33,
      "z": -10,
      "name": "Plant_Leaves_Aspen",
      "support": 1
    },
    {
      "x": -11,
      "y": 31,
      "z": -9,
      "name": "Plant_Leaves_Aspen"
    },
    {
      "x": -11,
      "y": 32,
      "z": -9,
      "name": "Wood_Birch_Branch_Long",
      "support": 15,
      "rotation": 5
    },
    {
      "x": -11,
      "y": 33,
      "z": -9,
      "name": "Plant_Leaves_Aspen"
    },
    {
      "x": -11,
      "y": 31,
      "z": -8,
      "name": "Plant_Leaves_Aspen",
      "support": 1
    },
    {
      "x": -11,
      "y": 32,
      "z": -8,
      "name": "Plant_Leaves_Aspen"
    },
    {
      "x": -11,
      "y": 33,
      "z": -8,
      "name": "Plant_Leaves_Aspen",
      "support": 1
    },
    {
      "x": -11,
      "y": 31,
      "z": -7,
      "name": "Plant_Leaves_Aspen",
      "support": 2
    },
    {
      "x": -11,
      "y": 32,
      "z": -7,
      "name": "Plant_Leaves_Aspen",
      "support": 1
    },
    {
      "x": -11,
      "y": 33,
      "z": -7,
      "name": "Plant_Leaves_Aspen",
      "support": 2
    },
    {
      "x": -11,
      "y": 31,
      "z": -6,
      "name": "Plant_Leaves_Aspen",
      "support": 3
    },
    {
      "x": -11,
      "y": 32,
      "z": -6,
      "name": "Plant_Leaves_Aspen",
      "support": 2
    },
    {
      "x": -11,
      "y": 24,
      "z": -5,
      "name": "Wood_Birch_Trunk_Full",
      "support": 15,
      "rotation": 5
    },
    {
      "x": -11,
      "y": 25,
      "z": -5,
      "name": "Wood_Birch_Trunk_Full",
      "support": 15,
      "rotation": 5
    },
    {
      "x": -11,
      "y": 31,
      "z": -5,
      "name": "Plant_Leaves_Aspen",
      "support": 4
    },
    {
      "x": -11,
      "y": 32,
      "z": -5,
      "name": "Plant_Leaves_Aspen",
      "support": 3
    },
    {
      "x": -11,
      "y": 32,
      "z": -4,
      "name": "Plant_Leaves_Aspen",
      "support": 4
    },
    {
      "x": -11,
      "y": 29,
      "z": -3,
      "name": "Wood_Birch_Branch_Long",
      "support": 15,
      "rotation": 5
    },
    {
      "x": -11,
      "y": 27,
      "z": -2,
      "name": "Plant_Leaves_Aspen",
      "support": 4
    },
    {
      "x": -11,
      "y": 30,
      "z": -2,
      "name": "Plant_Leaves_Aspen",
      "support": 4
    },
    {
      "x": -11,
      "y": 26,
      "z": -1,
      "name": "Plant_Leaves_Aspen",
      "support": 2
    },
    {
      "x": -11,
      "y": 27,
      "z": -1,
      "name": "Plant_Leaves_Aspen",
      "support": 3
    },
    {
      "x": -11,
      "y": 30,
      "z": -1,
      "name": "Plant_Leaves_Aspen",
      "support": 3
    },
    {
      "x": -11,
      "y": 25,
      "z": 0,
      "name": "Plant_Leaves_Aspen",
      "support": 2
    },
    {
      "x": -11,
      "y": 26,
      "z": 0,
      "name": "Plant_Leaves_Aspen",
      "support": 2
    },
    {
      "x": -11,
      "y": 27,
      "z": 0,
      "name": "Plant_Leaves_Aspen",
      "support": 3
    },
    {
      "x": -11,
      "y": 30,
      "z": 0,
      "name": "Plant_Leaves_Aspen",
      "support": 2
    },
    {
      "x": -11,
      "y": 25,
      "z": 1,
      "name": "Plant_Leaves_Aspen",
      "support": 1
    },
    {
      "x": -11,
      "y": 26,
      "z": 1,
      "name": "Plant_Leaves_Aspen",
      "support": 1
    },
    {
      "x": -11,
      "y": 27,
      "z": 1,
      "name": "Plant_Leaves_Aspen",
      "support": 2
    },
    {
      "x": -11,
      "y": 30,
      "z": 1,
      "name": "Plant_Leaves_Aspen",
      "support": 3
    },
    {
      "x": -11,
      "y": 25,
      "z": 2,
      "name": "Plant_Leaves_Aspen",
      "support": 2
    },
    {
      "x": -11,
      "y": 26,
      "z": 2,
      "name": "Plant_Leaves_Aspen",
      "support": 1
    },
    {
      "x": -11,
      "y": 27,
      "z": 2,
      "name": "Plant_Leaves_Aspen",
      "support": 2
    },
    {
      "x": -11,
      "y": 30,
      "z": 2,
      "name": "Plant_Leaves_Aspen",
      "support": 2
    },
    {
      "x": -11,
      "y": 31,
      "z": 2,
      "name": "Plant_Leaves_Aspen",
      "support": 3
    },
    {
      "x": -11,
      "y": 26,
      "z": 3,
      "name": "Plant_Leaves_Aspen"
    },
    {
      "x": -11,
      "y": 27,
      "z": 3,
      "name": "Plant_Leaves_Aspen",
      "support": 1
    },
    {
      "x": -11,
      "y": 30,
      "z": 3,
      "name": "Plant_Leaves_Aspen",
      "support": 1
    },
    {
      "x": -11,
      "y": 31,
      "z": 3,
      "name": "Plant_Leaves_Aspen",
      "support": 2
    },
    {
      "x": -11,
      "y": 26,
      "z": 4,
      "name": "Wood_Birch_Trunk_Full",
      "support": 15,
      "rotation": 5
    },
    {
      "x": -11,
      "y": 27,
      "z": 4,
      "name": "Plant_Leaves_Aspen"
    },
    {
      "x": -11,
      "y": 30,
      "z": 4,
      "name": "Plant_Leaves_Aspen"
    },
    {
      "x": -11,
      "y": 31,
      "z": 4,
      "name": "Plant_Leaves_Aspen",
      "support": 1
    },
    {
      "x": -11,
      "y": 27,
      "z": 5,
      "name": "Plant_Leaves_Aspen",
      "support": 1
    },
    {
      "x": -11,
      "y": 29,
      "z": 5,
      "name": "Plant_Leaves_Aspen",
      "support": 1
    },
    {
      "x": -11,
      "y": 30,
      "z": 5,
      "name": "Plant_Leaves_Aspen",
      "support": 1
    },
    {
      "x": -11,
      "y": 31,
      "z": 5,
      "name": "Plant_Leaves_Aspen",
      "support": 2
    },
    {
      "x": -11,
      "y": 26,
      "z": 6,
      "name": "Plant_Leaves_Aspen",
      "support": 1
    },
    {
      "x": -11,
      "y": 27,
      "z": 6,
      "name": "Plant_Leaves_Aspen",
      "support": 1
    },
    {
      "x": -11,
      "y": 28,
      "z": 6,
      "name": "Plant_Leaves_Aspen",
      "support": 2
    },
    {
      "x": -11,
      "y": 29,
      "z": 6,
      "name": "Plant_Leaves_Aspen",
      "support": 2
    },
    {
      "x": -11,
      "y": 30,
      "z": 6,
      "name": "Plant_Leaves_Aspen",
      "support": 2
    },
    {
      "x": -11,
      "y": 31,
      "z": 6,
      "name": "Plant_Leaves_Aspen",
      "support": 3
    },
    {
      "x": -11,
      "y": 26,
      "z": 7,
      "name": "Plant_Leaves_Aspen"
    },
    {
      "x": -11,
      "y": 27,
      "z": 7,
      "name": "Plant_Leaves_Aspen"
    },
    {
      "x": -11,
      "y": 28,
      "z": 7,
      "name": "Plant_Leaves_Aspen",
      "support": 1
    },
    {
      "x": -11,
      "y": 30,
      "z": 7,
      "name": "Plant_Leaves_Aspen",
      "support": 3
    },
    {
      "x": -11,
      "y": 24,
      "z": 8,
      "name": "Wood_Birch_Branch_Corner",
      "support": 15,
      "rotation": 3
    },
    {
      "x": -11,
      "y": 25,
      "z": 8,
      "name": "Wood_Birch_Branch_Long",
      "support": 15
    },
    {
      "x": -11,
      "y": 26,
      "z": 8,
      "name": "Wood_Birch_Branch_Long",
      "support": 15
    },
    {
      "x": -11,
      "y": 27,
      "z": 8,
      "name": "Wood_Birch_Branch_Long",
      "support": 15
    },
    {
      "x": -11,
      "y": 28,
      "z": 8,
      "name": "Plant_Leaves_Aspen"
    },
    {
      "x": -11,
      "y": 23,
      "z": 9,
      "name": "Plant_Leaves_Aspen"
    },
    {
      "x": -11,
      "y": 26,
      "z": 9,
      "name": "Plant_Leaves_Aspen"
    },
    {
      "x": -11,
      "y": 27,
      "z": 9,
      "name": "Plant_Leaves_Aspen"
    },
    {
      "x": -11,
      "y": 28,
      "z": 9,
      "name": "Plant_Leaves_Aspen",
      "support": 1
    },
    {
      "x": -11,
      "y": 23,
      "z": 10,
      "name": "Plant_Leaves_Aspen"
    },
    {
      "x": -11,
      "y": 26,
      "z": 10,
      "name": "Plant_Leaves_Aspen",
      "support": 1
    },
    {
      "x": -11,
      "y": 27,
      "z": 10,
      "name": "Plant_Leaves_Aspen",
      "support": 1
    },
    {
      "x": -11,
      "y": 28,
      "z": 10,
      "name": "Plant_Leaves_Aspen",
      "support": 2
    },
    {
      "x": -11,
      "y": 23,
      "z": 11,
      "name": "Plant_Leaves_Aspen"
    },
    {
      "x": -11,
      "y": 27,
      "z": 11,
      "name": "Plant_Leaves_Aspen",
      "support": 2
    },
    {
      "x": -11,
      "y": 23,
      "z": 12,
      "name": "Plant_Leaves_Aspen"
    },
    {
      "x": -11,
      "y": 23,
      "z": 13,
      "name": "Plant_Leaves_Aspen"
    },
    {
      "x": -10,
      "y": 27,
      "z": -15,
      "name": "Plant_Leaves_Aspen",
      "support": 3
    },
    {
      "x": -10,
      "y": 26,
      "z": -14,
      "name": "Plant_Leaves_Aspen",
      "support": 2
    },
    {
      "x": -10,
      "y": 27,
      "z": -14,
      "name": "Plant_Leaves_Aspen",
      "support": 2
    },
    {
      "x": -10,
      "y": 28,
      "z": -14,
      "name": "Plant_Leaves_Aspen",
      "support": 3
    },
    {
      "x": -10,
      "y": 26,
      "z": -13,
      "name": "Plant_Leaves_Aspen",
      "support": 1
    },
    {
      "x": -10,
      "y": 27,
      "z": -13,
      "name": "Plant_Leaves_Aspen",
      "support": 1
    },
    {
      "x": -10,
      "y": 28,
      "z": -13,
      "name": "Plant_Leaves_Aspen",
      "support": 2
    },
    {
      "x": -10,
      "y": 32,
      "z": -13,
      "name": "Plant_Leaves_Aspen",
      "support": 15
    },
    {
      "x": -10,
      "y": 26,
      "z": -12,
      "name": "Plant_Leaves_Aspen"
    },
    {
      "x": -10,
      "y": 27,
      "z": -12,
      "name": "Plant_Leaves_Aspen"
    },
    {
      "x": -10,
      "y": 28,
      "z": -12,
      "name": "Plant_Leaves_Aspen",
      "support": 1
    },
    {
      "x": -10,
      "y": 32,
      "z": -12,
      "name": "Plant_Leaves_Aspen",
      "support": 2
    },
    {
      "x": -10,
      "y": 26,
      "z": -11,
      "name": "Plant_Leaves_Aspen"
    },
    {
      "x": -10,
      "y": 27,
      "z": -11,
      "name": "Plant_Leaves_Aspen",
      "support": 1
    },
    {
      "x": -10,
      "y": 28,
      "z": -11,
      "name": "Plant_Leaves_Aspen",
      "support": 2
    },
    {
      "x": -10,
      "y": 31,
      "z": -11,
      "name": "Plant_Leaves_Aspen",
      "support": 2
    },
    {
      "x": -10,
      "y": 32,
      "z": -11,
      "name": "Plant_Leaves_Aspen",
      "support": 1
    },
    {
      "x": -10,
      "y": 33,
      "z": -11,
      "name": "Plant_Leaves_Aspen",
      "support": 2
    },
    {
      "x": -10,
      "y": 26,
      "z": -10,
      "name": "Plant_Leaves_Aspen"
    },
    {
      "x": -10,
      "y": 27,
      "z": -10,
      "name": "Plant_Leaves_Aspen",
      "support": 1
    },
    {
      "x": -10,
      "y": 28,
      "z": -10,
      "name": "Plant_Leaves_Aspen",
      "support": 2
    },
    {
      "x": -10,
      "y": 31,
      "z": -10,
      "name": "Plant_Leaves_Aspen",
      "support": 1
    },
    {
      "x": -10,
      "y": 32,
      "z": -10,
      "name": "Plant_Leaves_Aspen"
    },
    {
      "x": -10,
      "y": 33,
      "z": -10,
      "name": "Plant_Leaves_Aspen",
      "support": 1
    },
    {
      "x": -10,
      "y": 27,
      "z": -9,
      "name": "Plant_Leaves_Aspen",
      "support": 1
    },
    {
      "x": -10,
      "y": 31,
      "z": -9,
      "name": "Plant_Leaves_Aspen"
    },
    {
      "x": -10,
      "y": 32,
      "z": -9,
      "name": "Wood_Birch_Branch_Long",
      "support": 15,
      "rotation": 5
    },
    {
      "x": -10,
      "y": 33,
      "z": -9,
      "name": "Plant_Leaves_Aspen"
    },
    {
      "x": -10,
      "y": 31,
      "z": -8,
      "name": "Plant_Leaves_Aspen",
      "support": 1
    },
    {
      "x": -10,
      "y": 32,
      "z": -8,
      "name": "Plant_Leaves_Aspen"
    },
    {
      "x": -10,
      "y": 33,
      "z": -8,
      "name": "Plant_Leaves_Aspen",
      "support": 1
    },
    {
      "x": -10,
      "y": 31,
      "z": -7,
      "name": "Plant_Leaves_Aspen",
      "support": 2
    },
    {
      "x": -10,
      "y": 32,
      "z": -7,
      "name": "Plant_Leaves_Aspen",
      "support": 1
    },
    {
      "x": -10,
      "y": 33,
      "z": -7,
      "name": "Plant_Leaves_Aspen",
      "support": 2
    },
    {
      "x": -10,
      "y": 31,
      "z": -6,
      "name": "Plant_Leaves_Aspen",
      "support": 3
    },
    {
      "x": -10,
      "y": 32,
      "z": -6,
      "name": "Plant_Leaves_Aspen",
      "support": 2
    },
    {
      "x": -10,
      "y": 24,
      "z": -5,
      "name": "Wood_Birch_Trunk",
      "support": 15,
      "rotation": 5
    },
    {
      "x": -10,
      "y": 31,
      "z": -5,
      "name": "Plant_Leaves_Aspen",
      "support": 4
    },
    {
      "x": -10,
      "y": 32,
      "z": -5,
      "name": "Plant_Leaves_Aspen",
      "support": 3
    },
    {
      "x": -10,
      "y": 29,
      "z": -3,
      "name": "Wood_Birch_Branch_Long",
      "support": 15,
      "rotation": 5
    },
    {
      "x": -10,
      "y": 24,
      "z": -2,
      "name": "Wood_Birch_Trunk_Full",
      "support": 15,
      "rotation": 5
    },
    {
      "x": -10,
      "y": 26,
      "z": -2,
      "name": "Plant_Leaves_Aspen",
      "support": 2
    },
    {
      "x": -10,
      "y": 27,
      "z": -2,
      "name": "Plant_Leaves_Aspen",
      "support": 3
    },
    {
      "x": -10,
      "y": 22,
      "z": -1,
      "name": "Wood_Birch_Trunk_Full",
      "support": 15
    },
    {
      "x": -10,
      "y": 23,
      "z": -1,
      "name": "Wood_Birch_Trunk",
      "support": 15
    },
    {
      "x": -10,
      "y": 24,
      "z": -1,
      "name": "Wood_Birch_Trunk_Full",
      "support": 15
    },
    {
      "x": -10,
      "y": 25,
      "z": -1,
      "name": "Plant_Leaves_Aspen"
    },
    {
      "x": -10,
      "y": 26,
      "z": -1,
      "name": "Plant_Leaves_Aspen",
      "support": 1
    },
    {
      "x": -10,
      "y": 27,
      "z": -1,
      "name": "Plant_Leaves_Aspen",
      "support": 2
    },
    {
      "x": -10,
      "y": 30,
      "z": -1,
      "name": "Plant_Leaves_Aspen",
      "support": 2
    },
    {
      "x": -10,
      "y": 25,
      "z": 0,
      "name": "Plant_Leaves_Aspen",
      "support": 1
    },
    {
      "x": -10,
      "y": 26,
      "z": 0,
      "name": "Plant_Leaves_Aspen",
      "support": 1
    },
    {
      "x": -10,
      "y": 27,
      "z": 0,
      "name": "Plant_Leaves_Aspen",
      "support": 2
    },
    {
      "x": -10,
      "y": 30,
      "z": 0,
      "name": "Plant_Leaves_Aspen",
      "support": 1
    },
    {
      "x": -10,
      "y": 33,
      "z": 0,
      "name": "Plant_Leaves_Aspen",
      "support": 15
    },
    {
      "x": -10,
      "y": 25,
      "z": 1,
      "name": "Plant_Leaves_Aspen"
    },
    {
      "x": -10,
      "y": 26,
      "z": 1,
      "name": "Plant_Leaves_Aspen"
    },
    {
      "x": -10,
      "y": 27,
      "z": 1,
      "name": "Plant_Leaves_Aspen",
      "support": 1
    },
    {
      "x": -10,
      "y": 30,
      "z": 1,
      "name": "Plant_Leaves_Aspen",
      "support": 2
    },
    {
      "x": -10,
      "y": 33,
      "z": 1,
      "name": "Plant_Leaves_Aspen",
      "support": 15
    },
    {
      "x": -10,
      "y": 25,
      "z": 2,
      "name": "Plant_Leaves_Aspen",
      "support": 1
    },
    {
      "x": -10,
      "y": 26,
      "z": 2,
      "name": "Plant_Leaves_Aspen",
      "support": 1
    },
    {
      "x": -10,
      "y": 27,
      "z": 2,
      "name": "Plant_Leaves_Aspen",
      "support": 2
    },
    {
      "x": -10,
      "y": 30,
      "z": 2,
      "name": "Plant_Leaves_Aspen",
      "support": 3
    },
    {
      "x": -10,
      "y": 25,
      "z": 3,
      "name": "Plant_Leaves_Aspen",
      "support": 1
    },
    {
      "x": -10,
      "y": 26,
      "z": 3,
      "name": "Plant_Leaves_Aspen"
    },
    {
      "x": -10,
      "y": 27,
      "z": 3,
      "name": "Plant_Leaves_Aspen",
      "support": 1
    },
    {
      "x": -10,
      "y": 30,
      "z": 3,
      "name": "Plant_Leaves_Aspen",
      "support": 2
    },
    {
      "x": -10,
      "y": 31,
      "z": 3,
      "name": "Plant_Leaves_Aspen",
      "support": 3
    },
    {
      "x": -10,
      "y": 26,
      "z": 4,
      "name": "Wood_Birch_Trunk",
      "support": 15,
      "rotation": 5
    },
    {
      "x": -10,
      "y": 27,
      "z": 4,
      "name": "Plant_Leaves_Aspen"
    },
    {
      "x": -10,
      "y": 30,
      "z": 4,
      "name": "Plant_Leaves_Aspen",
      "support": 1
    },
    {
      "x": -10,
      "y": 31,
      "z": 4,
      "name": "Plant_Leaves_Aspen",
      "support": 2
    },
    {
      "x": -10,
      "y": 27,
      "z": 5,
      "name": "Plant_Leaves_Aspen",
      "support": 1
    },
    {
      "x": -10,
      "y": 29,
      "z": 5,
      "name": "Plant_Leaves_Aspen",
      "support": 2
    },
    {
      "x": -10,
      "y": 30,
      "z": 5,
      "name": "Plant_Leaves_Aspen",
      "support": 2
    },
    {
      "x": -10,
      "y": 31,
      "z": 5,
      "name": "Plant_Leaves_Aspen",
      "support": 3
    },
    {
      "x": -10,
      "y": 26,
      "z": 6,
      "name": "Plant_Leaves_Aspen",
      "support": 2
    },
    {
      "x": -10,
      "y": 27,
      "z": 6,
      "name": "Plant_Leaves_Aspen",
      "support": 2
    },
    {
      "x": -10,
      "y": 28,
      "z": 6,
      "name": "Plant_Leaves_Aspen",
      "support": 3
    },
    {
      "x": -10,
      "y": 30,
      "z": 6,
      "name": "Plant_Leaves_Aspen",
      "support": 3
    },
    {
      "x": -10,
      "y": 26,
      "z": 7,
      "name": "Plant_Leaves_Aspen",
      "support": 1
    },
    {
      "x": -10,
      "y": 27,
      "z": 7,
      "name": "Plant_Leaves_Aspen",
      "support": 1
    },
    {
      "x": -10,
      "y": 28,
      "z": 7,
      "name": "Plant_Leaves_Aspen",
      "support": 2
    },
    {
      "x": -10,
      "y": 23,
      "z": 8,
      "name": "Plant_Leaves_Aspen"
    },
    {
      "x": -10,
      "y": 24,
      "z": 8,
      "name": "Wood_Birch_Branch_Long",
      "support": 15,
      "rotation": 5
    },
    {
      "x": -10,
      "y": 26,
      "z": 8,
      "name": "Plant_Leaves_Aspen"
    },
    {
      "x": -10,
      "y": 27,
      "z": 8,
      "name": "Plant_Leaves_Aspen"
    },
    {
      "x": -10,
      "y": 28,
      "z": 8,
      "name": "Plant_Leaves_Aspen",
      "support": 1
    },
    {
      "x": -10,
      "y": 23,
      "z": 9,
      "name": "Plant_Leaves_Aspen"
    },
    {
      "x": -10,
      "y": 26,
      "z": 9,
      "name": "Plant_Leaves_Aspen",
      "support": 1
    },
    {
      "x": -10,
      "y": 27,
      "z": 9,
      "name": "Plant_Leaves_Aspen",
      "support": 1
    },
    {
      "x": -10,
      "y": 28,
      "z": 9,
      "name": "Plant_Leaves_Aspen",
      "support": 2
    },
    {
      "x": -10,
      "y": 23,
      "z": 10,
      "name": "Plant_Leaves_Aspen"
    },
    {
      "x": -10,
      "y": 26,
      "z": 10,
      "name": "Plant_Leaves_Aspen",
      "support": 2
    },
    {
      "x": -10,
      "y": 27,
      "z": 10,
      "name": "Plant_Leaves_Aspen",
      "support": 2
    },
    {
      "x": -10,
      "y": 28,
      "z": 10,
      "name": "Plant_Leaves_Aspen",
      "support": 3
    },
    {
      "x": -10,
      "y": 23,
      "z": 11,
      "name": "Plant_Leaves_Aspen"
    },
    {
      "x": -10,
      "y": 27,
      "z": 11,
      "name": "Plant_Leaves_Aspen",
      "support": 3
    },
    {
      "x": -10,
      "y": 23,
      "z": 12,
      "name": "Plant_Leaves_Aspen"
    },
    {
      "x": -10,
      "y": 23,
      "z": 13,
      "name": "Plant_Leaves_Aspen"
    },
    {
      "x": -10,
      "y": 23,
      "z": 14,
      "name": "Plant_Leaves_Aspen"
    },
    {
      "x": -9,
      "y": 27,
      "z": -15,
      "name": "Plant_Leaves_Aspen",
      "support": 2
    },
    {
      "x": -9,
      "y": 26,
      "z": -14,
      "name": "Plant_Leaves_Aspen",
      "support": 1
    },
    {
      "x": -9,
      "y": 27,
      "z": -14,
      "name": "Plant_Leaves_Aspen",
      "support": 1
    },
    {
      "x": -9,
      "y": 28,
      "z": -14,
      "name": "Plant_Leaves_Aspen",
      "support": 2
    },
    {
      "x": -9,
      "y": 26,
      "z": -13,
      "name": "Plant_Leaves_Aspen"
    },
    {
      "x": -9,
      "y": 27,
      "z": -13,
      "name": "Plant_Leaves_Aspen"
    },
    {
      "x": -9,
      "y": 28,
      "z": -13,
      "name": "Plant_Leaves_Aspen",
      "support": 1
    },
    {
      "x": -9,
      "y": 32,
      "z": -13,
      "name": "Plant_Leaves_Aspen",
      "support": 15
    },
    {
      "x": -9,
      "y": 26,
      "z": -12,
      "name": "Wood_Birch_Branch_Corner",
      "support": 15,
      "rotation": 2
    },
    {
      "x": -9,
      "y": 27,
      "z": -12,
      "name": "Wood_Birch_Branch_Long",
      "support": 15
    },
    {
      "x": -9,
      "y": 28,
      "z": -12,
      "name": "Plant_Leaves_Aspen"
    },
    {
      "x": -9,
      "y": 32,
      "z": -12,
      "name": "Plant_Leaves_Aspen",
      "support": 15
    },
    {
      "x": -9,
      "y": 26,
      "z": -11,
      "name": "Wood_Birch_Branch_Long",
      "support": 15,
      "rotation": 4
    },
    {
      "x": -9,
      "y": 27,
      "z": -11,
      "name": "Plant_Leaves_Aspen"
    },
    {
      "x": -9,
      "y": 28,
      "z": -11,
      "name": "Plant_Leaves_Aspen",
      "support": 1
    },
    {
      "x": -9,
      "y": 32,
      "z": -11,
      "name": "Plant_Leaves_Aspen",
      "support": 1
    },
    {
      "x": -9,
      "y": 26,
      "z": -10,
      "name": "Wood_Birch_Branch_Long",
      "support": 15,
      "rotation": 4
    },
    {
      "x": -9,
      "y": 27,
      "z": -10,
      "name": "Plant_Leaves_Aspen"
    },
    {
      "x": -9,
      "y": 28,
      "z": -10,
      "name": "Plant_Leaves_Aspen",
      "support": 1
    },
    {
      "x": -9,
      "y": 31,
      "z": -10,
      "name": "Plant_Leaves_Aspen"
    },
    {
      "x": -9,
      "y": 32,
      "z": -10,
      "name": "Plant_Leaves_Aspen"
    },
    {
      "x": -9,
      "y": 33,
      "z": -10,
      "name": "Plant_Leaves_Aspen",
      "support": 1
    },
    {
      "x": -9,
      "y": 26,
      "z": -9,
      "name": "Wood_Birch_Trunk_Full",
      "support": 15,
      "rotation": 4
    },
    {
      "x": -9,
      "y": 27,
      "z": -9,
      "name": "Plant_Leaves_Aspen"
    },
    {
      "x": -9,
      "y": 30,
      "z": -9,
      "name": "Wood_Birch_Branch_Corner",
      "support": 15,
      "rotation": 2
    },
    {
      "x": -9,
      "y": 31,
      "z": -9,
      "name": "Wood_Birch_Branch_Long",
      "support": 15
    },
    {
      "x": -9,
      "y": 32,
      "z": -9,
      "name": "Wood_Birch_Branch_Corner",
      "support": 15,
      "rotation": 11
    },
    {
      "x": -9,
      "y": 33,
      "z": -9,
      "name": "Plant_Leaves_Aspen"
    },
    {
      "x": -9,
      "y": 26,
      "z": -8,
      "name": "Wood_Birch_Trunk",
      "support": 15,
      "rotation": 4
    },
    {
      "x": -9,
      "y": 29,
      "z": -8,
      "name": "Wood_Birch_Branch_Corner",
      "support": 15,
      "rotation": 2
    },
    {
      "x": -9,
      "y": 30,
      "z": -8,
      "name": "Wood_Birch_Branch_Corner",
      "support": 15,
      "rotation": 10
    },
    {
      "x": -9,
      "y": 31,
      "z": -8,
      "name": "Plant_Leaves_Aspen"
    },
    {
      "x": -9,
      "y": 32,
      "z": -8,
      "name": "Plant_Leaves_Aspen"
    },
    {
      "x": -9,
      "y": 33,
      "z": -8,
      "name": "Plant_Leaves_Aspen",
      "support": 1
    },
    {
      "x": -9,
      "y": 25,
      "z": -7,
      "name": "Wood_Birch_Trunk_Full",
      "support": 15,
      "rotation": 5
    },
    {
      "x": -9,
      "y": 26,
      "z": -7,
      "name": "Wood_Birch_Trunk_Full",
      "support": 15,
      "rotation": 4
    },
    {
      "x": -9,
      "y": 29,
      "z": -7,
      "name": "Wood_Birch_Branch_Long",
      "support": 15,
      "rotation": 4
    },
    {
      "x": -9,
      "y": 31,
      "z": -7,
      "name": "Plant_Leaves_Aspen",
      "support": 1
    },
    {
      "x": -9,
      "y": 32,
      "z": -7,
      "name": "Plant_Leaves_Aspen",
      "support": 1
    },
    {
      "x": -9,
      "y": 29,
      "z": -6,
      "name": "Wood_Birch_Branch_Long",
      "support": 15,
      "rotation": 4
    },
    {
      "x": -9,
      "y": 31,
      "z": -6,
      "name": "Plant_Leaves_Aspen",
      "support": 2
    },
    {
      "x": -9,
      "y": 32,
      "z": -6,
      "name": "Plant_Leaves_Aspen",
      "support": 2
    },
    {
      "x": -9,
      "y": 24,
      "z": -5,
      "name": "Wood_Birch_Trunk",
      "support": 15,
      "rotation": 5
    },
    {
      "x": -9,
      "y": 29,
      "z": -5,
      "name": "Wood_Birch_Trunk_Full",
      "support": 15,
      "rotation": 4
    },
    {
      "x": -9,
      "y": 31,
      "z": -5,
      "name": "Plant_Leaves_Aspen",
      "support": 3
    },
    {
      "x": -9,
      "y": 24,
      "z": -4,
      "name": "Wood_Birch_Trunk_Full",
      "support": 15,
      "rotation": 5
    },
    {
      "x": -9,
      "y": 28,
      "z": -4,
      "name": "Wood_Birch_Branch_Long",
      "support": 15,
      "rotation": 5
    },
    {
      "x": -9,
      "y": 29,
      "z": -4,
      "name": "Wood_Birch_Trunk",
      "support": 15,
      "rotation": 4
    },
    {
      "x": -9,
      "y": 31,
      "z": -4,
      "name": "Plant_Leaves_Aspen",
      "support": 4
    },
    {
      "x": -9,
      "y": 24,
      "z": -3,
      "name": "Wood_Birch_Trunk",
      "support": 15,
      "rotation": 4
    },
    {
      "x": -9,
      "y": 29,
      "z": -3,
      "name": "Wood_Birch_Trunk",
      "support": 15,
      "rotation": 4
    },
    {
      "x": -9,
      "y": 22,
      "z": -2,
      "name": "Wood_Birch_Trunk_Full",
      "support": 15,
      "rotation": 4
    },
    {
      "x": -9,
      "y": 24,
      "z": -2,
      "name": "Wood_Birch_Trunk_Full",
      "support": 15,
      "rotation": 5
    },
    {
      "x": -9,
      "y": 26,
      "z": -2,
      "name": "Plant_Leaves_Aspen",
      "support": 2
    },
    {
      "x": -9,
      "y": 29,
      "z": -2,
      "name": "Wood_Birch_Trunk",
      "support": 15,
      "rotation": 4
    },
    {
      "x": -9,
      "y": 22,
      "z": -1,
      "name": "Wood_Birch_Trunk_Full",
      "support": 15,
      "rotation": 4
    },
    {
      "x": -9,
      "y": 25,
      "z": -1,
      "name": "Plant_Leaves_Aspen",
      "support": 1
    },
    {
      "x": -9,
      "y": 26,
      "z": -1,
      "name": "Plant_Leaves_Aspen",
      "support": 1
    },
    {
      "x": -9,
      "y": 27,
      "z": -1,
      "name": "Plant_Leaves_Aspen",
      "support": 2
    },
    {
      "x": -9,
      "y": 29,
      "z": -1,
      "name": "Wood_Birch_Trunk",
      "support": 15,
      "rotation": 4
    },
    {
      "x": -9,
      "y": 25,
      "z": 0,
      "name": "Plant_Leaves_Aspen"
    },
    {
      "x": -9,
      "y": 26,
      "z": 0,
      "name": "Plant_Leaves_Aspen"
    },
    {
      "x": -9,
      "y": 27,
      "z": 0,
      "name": "Plant_Leaves_Aspen",
      "support": 1
    },
    {
      "x": -9,
      "y": 29,
      "z": 0,
      "name": "Wood_Birch_Trunk_Full",
      "support": 15,
      "rotation": 4
    },
    {
      "x": -9,
      "y": 30,
      "z": 0,
      "name": "Plant_Leaves_Aspen"
    },
    {
      "x": -9,
      "y": 33,
      "z": 0,
      "name": "Plant_Leaves_Aspen",
      "support": 2
    },
    {
      "x": -9,
      "y": 34,
      "z": 0,
      "name": "Plant_Leaves_Aspen",
      "support": 3
    },
    {
      "x": -9,
      "y": 24,
      "z": 1,
      "name": "Wood_Birch_Branch_Corner",
      "support": 15,
      "rotation": 3
    },
    {
      "x": -9,
      "y": 25,
      "z": 1,
      "name": "Wood_Birch_Branch_Long",
      "support": 15
    },
    {
      "x": -9,
      "y": 26,
      "z": 1,
      "name": "Wood_Birch_Branch_Long",
      "support": 15
    },
    {
      "x": -9,
      "y": 27,
      "z": 1,
      "name": "Plant_Leaves_Aspen"
    },
    {
      "x": -9,
      "y": 30,
      "z": 1,
      "name": "Plant_Leaves_Aspen",
      "support": 1
    },
    {
      "x": -9,
      "y": 33,
      "z": 1,
      "name": "Plant_Leaves_Aspen",
      "support": 2
    },
    {
      "x": -9,
      "y": 25,
      "z": 2,
      "name": "Plant_Leaves_Aspen"
    },
    {
      "x": -9,
      "y": 26,
      "z": 2,
      "name": "Plant_Leaves_Aspen"
    },
    {
      "x": -9,
      "y": 27,
      "z": 2,
      "name": "Plant_Leaves_Aspen",
      "support": 1
    },
    {
      "x": -9,
      "y": 30,
      "z": 2,
      "name": "Plant_Leaves_Aspen",
      "support": 2
    },
    {
      "x": -9,
      "y": 33,
      "z": 2,
      "name": "Plant_Leaves_Aspen",
      "support": 15
    },
    {
      "x": -9,
      "y": 25,
      "z": 3,
      "name": "Plant_Leaves_Aspen",
      "support": 1
    },
    {
      "x": -9,
      "y": 26,
      "z": 3,
      "name": "Plant_Leaves_Aspen"
    },
    {
      "x": -9,
      "y": 27,
      "z": 3,
      "name": "Plant_Leaves_Aspen",
      "support": 1
    },
    {
      "x": -9,
      "y": 30,
      "z": 3,
      "name": "Plant_Leaves_Aspen",
      "support": 3
    },
    {
      "x": -9,
      "y": 26,
      "z": 4,
      "name": "Wood_Birch_Trunk",
      "support": 15,
      "rotation": 5
    },
    {
      "x": -9,
      "y": 27,
      "z": 4,
      "name": "Plant_Leaves_Aspen"
    },
    {
      "x": -9,
      "y": 30,
      "z": 4,
      "name": "Plant_Leaves_Aspen",
      "support": 2
    },
    {
      "x": -9,
      "y": 27,
      "z": 5,
      "name": "Plant_Leaves_Aspen",
      "support": 1
    },
    {
      "x": -9,
      "y": 30,
      "z": 5,
      "name": "Plant_Leaves_Aspen",
      "support": 3
    },
    {
      "x": -9,
      "y": 27,
      "z": 6,
      "name": "Plant_Leaves_Aspen",
      "support": 2
    },
    {
      "x": -9,
      "y": 26,
      "z": 7,
      "name": "Plant_Leaves_Aspen",
      "support": 2
    },
    {
      "x": -9,
      "y": 27,
      "z": 7,
      "name": "Plant_Leaves_Aspen",
      "support": 2
    },
    {
      "x": -9,
      "y": 28,
      "z": 7,
      "name": "Plant_Leaves_Aspen",
      "support": 3
    },
    {
      "x": -9,
      "y": 23,
      "z": 8,
      "name": "Plant_Leaves_Aspen"
    },
    {
      "x": -9,
      "y": 24,
      "z": 8,
      "name": "Wood_Birch_Trunk_Full",
      "support": 15,
      "rotation": 5
    },
    {
      "x": -9,
      "y": 26,
      "z": 8,
      "name": "Plant_Leaves_Aspen",
      "support": 1
    },
    {
      "x": -9,
      "y": 27,
      "z": 8,
      "name": "Plant_Leaves_Aspen",
      "support": 1
    },
    {
      "x": -9,
      "y": 28,
      "z": 8,
      "name": "Plant_Leaves_Aspen",
      "support": 2
    },
    {
      "x": -9,
      "y": 23,
      "z": 9,
      "name": "Plant_Leaves_Aspen"
    },
    {
      "x": -9,
      "y": 26,
      "z": 9,
      "name": "Plant_Leaves_Aspen",
      "support": 2
    },
    {
      "x": -9,
      "y": 27,
      "z": 9,
      "name": "Plant_Leaves_Aspen",
      "support": 2
    },
    {
      "x": -9,
      "y": 28,
      "z": 9,
      "name": "Plant_Leaves_Aspen",
      "support": 3
    },
    {
      "x": -9,
      "y": 22,
      "z": 10,
      "name": "Plant_Leaves_Aspen"
    },
    {
      "x": -9,
      "y": 23,
      "z": 10,
      "name": "Plant_Leaves_Aspen"
    },
    {
      "x": -9,
      "y": 24,
      "z": 10,
      "name": "Plant_Leaves_Aspen"
    },
    {
      "x": -9,
      "y": 27,
      "z": 10,
      "name": "Plant_Leaves_Aspen",
      "support": 3
    },
    {
      "x": -9,
      "y": 22,
      "z": 11,
      "name": "Plant_Leaves_Aspen"
    },
    {
      "x": -9,
      "y": 23,
      "z": 11,
      "name": "Plant_Leaves_Aspen"
    },
    {
      "x": -9,
      "y": 24,
      "z": 11,
      "name": "Plant_Leaves_Aspen"
    },
    {
      "x": -9,
      "y": 22,
      "z": 12,
      "name": "Plant_Leaves_Aspen"
    },
    {
      "x": -9,
      "y": 23,
      "z": 12,
      "name": "Plant_Leaves_Aspen"
    },
    {
      "x": -9,
      "y": 24,
      "z": 12,
      "name": "Plant_Leaves_Aspen"
    },
    {
      "x": -9,
      "y": 23,
      "z": 13,
      "name": "Plant_Leaves_Aspen"
    },
    {
      "x": -9,
      "y": 23,
      "z": 14,
      "name": "Plant_Leaves_Aspen"
    },
    {
      "x": -8,
      "y": 27,
      "z": -15,
      "name": "Plant_Leaves_Aspen",
      "support": 3
    },
    {
      "x": -8,
      "y": 26,
      "z": -14,
      "name": "Plant_Leaves_Aspen",
      "support": 2
    },
    {
      "x": -8,
      "y": 27,
      "z": -14,
      "name": "Plant_Leaves_Aspen",
      "support": 2
    },
    {
      "x": -8,
      "y": 28,
      "z": -14,
      "name": "Plant_Leaves_Aspen",
      "support": 3
    },
    {
      "x": -8,
      "y": 26,
      "z": -13,
      "name": "Plant_Leaves_Aspen",
      "support": 1
    },
    {
      "x": -8,
      "y": 27,
      "z": -13,
      "name": "Plant_Leaves_Aspen",
      "support": 1
    },
    {
      "x": -8,
      "y": 28,
      "z": -13,
      "name": "Plant_Leaves_Aspen",
      "support": 2
    },
    {
      "x": -8,
      "y": 30,
      "z": -13,
      "name": "Plant_Leaves_Aspen",
      "support": 3
    },
    {
      "x": -8,
      "y": 26,
      "z": -12,
      "name": "Plant_Leaves_Aspen"
    },
    {
      "x": -8,
      "y": 27,
      "z": -12,
      "name": "Plant_Leaves_Aspen"
    },
    {
      "x": -8,
      "y": 28,
      "z": -12,
      "name": "Plant_Leaves_Aspen",
      "support": 1
    },
    {
      "x": -8,
      "y": 30,
      "z": -12,
      "name": "Plant_Leaves_Aspen",
      "support": 2
    },
    {
      "x": -8,
      "y": 26,
      "z": -11,
      "name": "Plant_Leaves_Aspen"
    },
    {
      "x": -8,
      "y": 27,
      "z": -11,
      "name": "Plant_Leaves_Aspen",
      "support": 1
    },
    {
      "x": -8,
      "y": 28,
      "z": -11,
      "name": "Plant_Leaves_Aspen",
      "support": 2
    },
    {
      "x": -8,
      "y": 30,
      "z": -11,
      "name": "Plant_Leaves_Aspen",
      "support": 3
    },
    {
      "x": -8,
      "y": 26,
      "z": -10,
      "name": "Plant_Leaves_Aspen"
    },
    {
      "x": -8,
      "y": 27,
      "z": -10,
      "name": "Plant_Leaves_Aspen",
      "support": 1
    },
    {
      "x": -8,
      "y": 28,
      "z": -10,
      "name": "Plant_Leaves_Aspen",
      "support": 2
    },
    {
      "x": -8,
      "y": 32,
      "z": -10,
      "name": "Plant_Leaves_Aspen",
      "support": 1
    },
    {
      "x": -8,
      "y": 27,
      "z": -9,
      "name": "Plant_Leaves_Aspen",
      "support": 1
    },
    {
      "x": -8,
      "y": 32,
      "z": -9,
      "name": "Plant_Leaves_Aspen"
    },
    {
      "x": -8,
      "y": 32,
      "z": -8,
      "name": "Plant_Leaves_Aspen",
      "support": 1
    },
    {
      "x": -8,
      "y": 25,
      "z": -7,
      "name": "Wood_Birch_Trunk_Full",
      "support": 15,
      "rotation": 4
    },
    {
      "x": -8,
      "y": 31,
      "z": -7,
      "name": "Plant_Leaves_Aspen",
      "support": 2
    },
    {
      "x": -8,
      "y": 24,
      "z": -6,
      "name": "Wood_Birch_Trunk_Full",
      "support": 15,
      "rotation": 5
    },
    {
      "x": -8,
      "y": 25,
      "z": -6,
      "name": "Wood_Birch_Trunk_Full",
      "support": 15,
      "rotation": 4
    },
    {
      "x": -8,
      "y": 31,
      "z": -6,
      "name": "Plant_Leaves_Aspen",
      "support": 3
    },
    {
      "x": -8,
      "y": 23,
      "z": -5,
      "name": "Wood_Birch_Trunk_Full",
      "support": 15,
      "rotation": 5
    },
    {
      "x": -8,
      "y": 24,
      "z": -5,
      "name": "Wood_Birch_Trunk",
      "support": 15,
      "rotation": 5
    },
    {
      "x": -8,
      "y": 31,
      "z": -5,
      "name": "Plant_Leaves_Aspen",
      "support": 4
    },
    {
      "x": -8,
      "y": 24,
      "z": -4,
      "name": "Wood_Birch_Trunk",
      "support": 15,
      "rotation": 5
    },
    {
      "x": -8,
      "y": 26,
      "z": -2,
      "name": "Plant_Leaves_Aspen",
      "support": 3
    },
    {
      "x": -8,
      "y": 25,
      "z": -1,
      "name": "Plant_Leaves_Aspen",
      "support": 2
    },
    {
      "x": -8,
      "y": 26,
      "z": -1,
      "name": "Plant_Leaves_Aspen",
      "support": 2
    },
    {
      "x": -8,
      "y": 27,
      "z": -1,
      "name": "Plant_Leaves_Aspen",
      "support": 1
    },
    {
      "x": -8,
      "y": 29,
      "z": -1,
      "name": "Wood_Birch_Trunk_Full",
      "support": 15,
      "rotation": 4
    },
    {
      "x": -8,
      "y": 33,
      "z": -1,
      "name": "Plant_Leaves_Aspen",
      "support": 4
    },
    {
      "x": -8,
      "y": 34,
      "z": -1,
      "name": "Plant_Leaves_Aspen",
      "support": 4
    },
    {
      "x": -8,
      "y": 25,
      "z": 0,
      "name": "Plant_Leaves_Aspen",
      "support": 1
    },
    {
      "x": -8,
      "y": 26,
      "z": 0,
      "name": "Plant_Leaves_Aspen",
      "support": 1
    },
    {
      "x": -8,
      "y": 27,
      "z": 0,
      "name": "Plant_Leaves_Aspen"
    },
    {
      "x": -8,
      "y": 28,
      "z": 0,
      "name": "Wood_Birch_Trunk_Full",
      "support": 15,
      "rotation": 4
    },
    {
      "x": -8,
      "y": 29,
      "z": 0,
      "name": "Wood_Birch_Trunk",
      "support": 15,
      "rotation": 4
    },
    {
      "x": -8,
      "y": 33,
      "z": 0,
      "name": "Plant_Leaves_Aspen",
      "support": 3
    },
    {
      "x": -8,
      "y": 34,
      "z": 0,
      "name": "Plant_Leaves_Aspen",
      "support": 3
    },
    {
      "x": -8,
      "y": 24,
      "z": 1,
      "name": "Wood_Birch_Branch_Long",
      "support": 15,
      "rotation": 5
    },
    {
      "x": -8,
      "y": 25,
      "z": 1,
      "name": "Plant_Leaves_Aspen"
    },
    {
      "x": -8,
      "y": 26,
      "z": 1,
      "name": "Plant_Leaves_Aspen"
    },
    {
      "x": -8,
      "y": 27,
      "z": 1,
      "name": "Plant_Leaves_Aspen"
    },
    {
      "x": -8,
      "y": 28,
      "z": 1,
      "name": "Wood_Birch_Trunk_Full",
      "support": 15,
      "rotation": 4
    },
    {
      "x": -8,
      "y": 29,
      "z": 1,
      "name": "Wood_Birch_Trunk_Full",
      "support": 15,
      "rotation": 4
    },
    {
      "x": -8,
      "y": 30,
      "z": 1,
      "name": "Plant_Leaves_Aspen"
    },
    {
      "x": -8,
      "y": 33,
      "z": 1,
      "name": "Plant_Leaves_Aspen",
      "support": 2
    },
    {
      "x": -8,
      "y": 34,
      "z": 1,
      "name": "Plant_Leaves_Aspen",
      "support": 2
    },
    {
      "x": -8,
      "y": 25,
      "z": 2,
      "name": "Plant_Leaves_Aspen",
      "support": 1
    },
    {
      "x": -8,
      "y": 26,
      "z": 2,
      "name": "Plant_Leaves_Aspen",
      "support": 1
    },
    {
      "x": -8,
      "y": 27,
      "z": 2,
      "name": "Plant_Leaves_Aspen",
      "support": 1
    },
    {
      "x": -8,
      "y": 30,
      "z": 2,
      "name": "Plant_Leaves_Aspen",
      "support": 1
    },
    {
      "x": -8,
      "y": 33,
      "z": 2,
      "name": "Plant_Leaves_Aspen",
      "support": 2
    },
    {
      "x": -8,
      "y": 25,
      "z": 3,
      "name": "Plant_Leaves_Aspen",
      "support": 1
    },
    {
      "x": -8,
      "y": 26,
      "z": 3,
      "name": "Plant_Leaves_Aspen"
    },
    {
      "x": -8,
      "y": 27,
      "z": 3,
      "name": "Plant_Leaves_Aspen",
      "support": 1
    },
    {
      "x": -8,
      "y": 30,
      "z": 3,
      "name": "Plant_Leaves_Aspen",
      "support": 2
    },
    {
      "x": -8,
      "y": 33,
      "z": 3,
      "name": "Plant_Leaves_Aspen",
      "support": 15
    },
    {
      "x": -8,
      "y": 26,
      "z": 4,
      "name": "Wood_Birch_Trunk",
      "support": 15,
      "rotation": 5
    },
    {
      "x": -8,
      "y": 27,
      "z": 4,
      "name": "Plant_Leaves_Aspen"
    },
    {
      "x": -8,
      "y": 27,
      "z": 5,
      "name": "Plant_Leaves_Aspen",
      "support": 1
    },
    {
      "x": -8,
      "y": 27,
      "z": 6,
      "name": "Plant_Leaves_Aspen",
      "support": 2
    },
    {
      "x": -8,
      "y": 27,
      "z": 7,
      "name": "Plant_Leaves_Aspen",
      "support": 3
    },
    {
      "x": -8,
      "y": 23,
      "z": 8,
      "name": "Plant_Leaves_Aspen"
    },
    {
      "x": -8,
      "y": 24,
      "z": 8,
      "name": "Wood_Birch_Trunk_Full",
      "support": 15,
      "rotation": 5
    },
    {
      "x": -8,
      "y": 27,
      "z": 8,
      "name": "Plant_Leaves_Aspen",
      "support": 2
    },
    {
      "x": -8,
      "y": 22,
      "z": 9,
      "name": "Plant_Leaves_Aspen"
    },
    {
      "x": -8,
      "y": 23,
      "z": 9,
      "name": "Plant_Leaves_Aspen"
    },
    {
      "x": -8,
      "y": 24,
      "z": 9,
      "name": "Plant_Leaves_Aspen"
    },
    {
      "x": -8,
      "y": 27,
      "z": 9,
      "name": "Plant_Leaves_Aspen",
      "support": 3
    },
    {
      "x": -8,
      "y": 22,
      "z": 10,
      "name": "Plant_Leaves_Aspen"
    },
    {
      "x": -8,
      "y": 23,
      "z": 10,
      "name": "Plant_Leaves_Aspen"
    },
    {
      "x": -8,
      "y": 24,
      "z": 10,
      "name": "Plant_Leaves_Aspen"
    },
    {
      "x": -8,
      "y": 22,
      "z": 11,
      "name": "Plant_Leaves_Aspen"
    },
    {
      "x": -8,
      "y": 23,
      "z": 11,
      "name": "Plant_Leaves_Aspen"
    },
    {
      "x": -8,
      "y": 24,
      "z": 11,
      "name": "Plant_Leaves_Aspen"
    },
    {
      "x": -8,
      "y": 22,
      "z": 12,
      "name": "Plant_Leaves_Aspen"
    },
    {
      "x": -8,
      "y": 23,
      "z": 12,
      "name": "Plant_Leaves_Aspen"
    },
    {
      "x": -8,
      "y": 24,
      "z": 12,
      "name": "Plant_Leaves_Aspen"
    },
    {
      "x": -8,
      "y": 22,
      "z": 13,
      "name": "Plant_Leaves_Aspen"
    },
    {
      "x": -8,
      "y": 23,
      "z": 13,
      "name": "Plant_Leaves_Aspen"
    },
    {
      "x": -8,
      "y": 24,
      "z": 13,
      "name": "Plant_Leaves_Aspen"
    },
    {
      "x": -8,
      "y": 23,
      "z": 14,
      "name": "Plant_Leaves_Aspen"
    },
    {
      "x": -7,
      "y": 27,
      "z": -14,
      "name": "Plant_Leaves_Aspen",
      "support": 3
    },
    {
      "x": -7,
      "y": 30,
      "z": -14,
      "name": "Plant_Leaves_Aspen",
      "support": 3
    },
    {
      "x": -7,
      "y": 26,
      "z": -13,
      "name": "Plant_Leaves_Aspen",
      "support": 2
    },
    {
      "x": -7,
      "y": 27,
      "z": -13,
      "name": "Plant_Leaves_Aspen",
      "support": 2
    },
    {
      "x": -7,
      "y": 28,
      "z": -13,
      "name": "Plant_Leaves_Aspen",
      "support": 3
    },
    {
      "x": -7,
      "y": 29,
      "z": -13,
      "name": "Plant_Leaves_Aspen",
      "support": 2
    },
    {
      "x": -7,
      "y": 30,
      "z": -13,
      "name": "Plant_Leaves_Aspen",
      "support": 2
    },
    {
      "x": -7,
      "y": 31,
      "z": -13,
      "name": "Plant_Leaves_Aspen",
      "support": 3
    },
    {
      "x": -7,
      "y": 26,
      "z": -12,
      "name": "Plant_Leaves_Aspen",
      "support": 1
    },
    {
      "x": -7,
      "y": 27,
      "z": -12,
      "name": "Plant_Leaves_Aspen",
      "support": 1
    },
    {
      "x": -7,
      "y": 28,
      "z": -12,
      "name": "Plant_Leaves_Aspen",
      "support": 2
    },
    {
      "x": -7,
      "y": 29,
      "z": -12,
      "name": "Plant_Leaves_Aspen",
      "support": 1
    },
    {
      "x": -7,
      "y": 30,
      "z": -12,
      "name": "Plant_Leaves_Aspen",
      "support": 1
    },
    {
      "x": -7,
      "y": 31,
      "z": -12,
      "name": "Plant_Leaves_Aspen",
      "support": 2
    },
    {
      "x": -7,
      "y": 26,
      "z": -11,
      "name": "Plant_Leaves_Aspen",
      "support": 1
    },
    {
      "x": -7,
      "y": 27,
      "z": -11,
      "name": "Plant_Leaves_Aspen",
      "support": 2
    },
    {
      "x": -7,
      "y": 28,
      "z": -11,
      "name": "Plant_Leaves_Aspen",
      "support": 3
    },
    {
      "x": -7,
      "y": 29,
      "z": -11,
      "name": "Plant_Leaves_Aspen",
      "support": 2
    },
    {
      "x": -7,
      "y": 30,
      "z": -11,
      "name": "Plant_Leaves_Aspen",
      "support": 2
    },
    {
      "x": -7,
      "y": 31,
      "z": -11,
      "name": "Plant_Leaves_Aspen",
      "support": 3
    },
    {
      "x": -7,
      "y": 27,
      "z": -10,
      "name": "Plant_Leaves_Aspen",
      "support": 2
    },
    {
      "x": -7,
      "y": 30,
      "z": -10,
      "name": "Plant_Leaves_Aspen",
      "support": 3
    },
    {
      "x": -7,
      "y": 24,
      "z": -6,
      "name": "Wood_Birch_Trunk_Full",
      "support": 15,
      "rotation": 5
    },
    {
      "x": -7,
      "y": 23,
      "z": -5,
      "name": "Wood_Birch_Trunk",
      "support": 15,
      "rotation": 5
    },
    {
      "x": -7,
      "y": 24,
      "z": -5,
      "name": "Wood_Birch_Trunk",
      "support": 15,
      "rotation": 5
    },
    {
      "x": -7,
      "y": 23,
      "z": -4,
      "name": "Wood_Birch_Trunk_Full",
      "support": 15,
      "rotation": 5
    },
    {
      "x": -7,
      "y": 24,
      "z": -4,
      "name": "Wood_Birch_Trunk_Full",
      "support": 15,
      "rotation": 5
    },
    {
      "x": -7,
      "y": 33,
      "z": -2,
      "name": "Plant_Leaves_Aspen",
      "support": 4
    },
    {
      "x": -7,
      "y": 34,
      "z": -2,
      "name": "Plant_Leaves_Aspen",
      "support": 4
    },
    {
      "x": -7,
      "y": 39,
      "z": -2,
      "name": "Plant_Leaves_Aspen",
      "support": 4
    },
    {
      "x": -7,
      "y": 26,
      "z": -1,
      "name": "Plant_Leaves_Aspen",
      "support": 2
    },
    {
      "x": -7,
      "y": 33,
      "z": -1,
      "name": "Plant_Leaves_Aspen",
      "support": 3
    },
    {
      "x": -7,
      "y": 34,
      "z": -1,
      "name": "Plant_Leaves_Aspen",
      "support": 3
    },
    {
      "x": -7,
      "y": 25,
      "z": 0,
      "name": "Plant_Leaves_Aspen",
      "support": 1
    },
    {
      "x": -7,
      "y": 26,
      "z": 0,
      "name": "Plant_Leaves_Aspen",
      "support": 1
    },
    {
      "x": -7,
      "y": 27,
      "z": 0,
      "name": "Plant_Leaves_Aspen"
    },
    {
      "x": -7,
      "y": 28,
      "z": 0,
      "name": "Wood_Birch_Trunk_Full",
      "support": 15,
      "rotation": 4
    },
    {
      "x": -7,
      "y": 33,
      "z": 0,
      "name": "Plant_Leaves_Aspen",
      "support": 2
    },
    {
      "x": -7,
      "y": 34,
      "z": 0,
      "name": "Plant_Leaves_Aspen",
      "support": 2
    },
    {
      "x": -7,
      "y": 24,
      "z": 1,
      "name": "Wood_Birch_Branch_Long",
      "support": 15,
      "rotation": 5
    },
    {
      "x": -7,
      "y": 25,
      "z": 1,
      "name": "Plant_Leaves_Aspen"
    },
    {
      "x": -7,
      "y": 26,
      "z": 1,
      "name": "Plant_Leaves_Aspen",
      "support": 1
    },
    {
      "x": -7,
      "y": 27,
      "z": 1,
      "name": "Plant_Leaves_Aspen"
    },
    {
      "x": -7,
      "y": 28,
      "z": 1,
      "name": "Wood_Birch_Trunk",
      "support": 15,
      "rotation": 4
    },
    {
      "x": -7,
      "y": 29,
      "z": 1,
      "name": "Wood_Birch_Trunk_Full",
      "support": 15,
      "rotation": 4
    },
    {
      "x": -7,
      "y": 33,
      "z": 1,
      "name": "Plant_Leaves_Aspen",
      "support": 1
    },
    {
      "x": -7,
      "y": 34,
      "z": 1,
      "name": "Plant_Leaves_Aspen",
      "support": 1
    },
    {
      "x": -7,
      "y": 25,
      "z": 2,
      "name": "Plant_Leaves_Aspen",
      "support": 1
    },
    {
      "x": -7,
      "y": 26,
      "z": 2,
      "name": "Plant_Leaves_Aspen",
      "support": 1
    },
    {
      "x": -7,
      "y": 27,
      "z": 2,
      "name": "Plant_Leaves_Aspen"
    },
    {
      "x": -7,
      "y": 28,
      "z": 2,
      "name": "Wood_Birch_Trunk_Full",
      "support": 15,
      "rotation": 4
    },
    {
      "x": -7,
      "y": 29,
      "z": 2,
      "name": "Wood_Birch_Trunk_Full",
      "support": 15,
      "rotation": 4
    },
    {
      "x": -7,
      "y": 33,
      "z": 2,
      "name": "Plant_Leaves_Aspen",
      "support": 2
    },
    {
      "x": -7,
      "y": 34,
      "z": 2,
      "name": "Plant_Leaves_Aspen",
      "support": 2
    },
    {
      "x": -7,
      "y": 26,
      "z": 3,
      "name": "Plant_Leaves_Aspen"
    },
    {
      "x": -7,
      "y": 33,
      "z": 3,
      "name": "Plant_Leaves_Aspen",
      "support": 2
    },
    {
      "x": -7,
      "y": 25,
      "z": 4,
      "name": "Wood_Birch_Trunk_Full",
      "support": 15,
      "rotation": 5
    },
    {
      "x": -7,
      "y": 26,
      "z": 4,
      "name": "Wood_Birch_Trunk",
      "support": 15,
      "rotation": 5
    },
    {
      "x": -7,
      "y": 24,
      "z": 6,
      "name": "Wood_Birch_Trunk_Full",
      "support": 15,
      "rotation": 4
    },
    {
      "x": -7,
      "y": 34,
      "z": 6,
      "name": "Plant_Leaves_Aspen",
      "support": 15
    },
    {
      "x": -7,
      "y": 24,
      "z": 7,
      "name": "Wood_Birch_Trunk_Full",
      "support": 15,
      "rotation": 4
    },
    {
      "x": -7,
      "y": 34,
      "z": 7,
      "name": "Plant_Leaves_Aspen",
      "support": 15
    },
    {
      "x": -7,
      "y": 23,
      "z": 8,
      "name": "Wood_Birch_Trunk_Full",
      "support": 15,
      "rotation": 5
    },
    {
      "x": -7,
      "y": 24,
      "z": 8,
      "name": "Wood_Birch_Trunk_Full",
      "support": 15,
      "rotation": 5
    },
    {
      "x": -7,
      "y": 22,
      "z": 9,
      "name": "Plant_Leaves_Aspen"
    },
    {
      "x": -7,
      "y": 23,
      "z": 9,
      "name": "Plant_Leaves_Aspen"
    },
    {
      "x": -7,
      "y": 24,
      "z": 9,
      "name": "Plant_Leaves_Aspen"
    },
    {
      "x": -7,
      "y": 22,
      "z": 10,
      "name": "Plant_Leaves_Aspen"
    },
    {
      "x": -7,
      "y": 23,
      "z": 10,
      "name": "Plant_Leaves_Aspen"
    },
    {
      "x": -7,
      "y": 24,
      "z": 10,
      "name": "Plant_Leaves_Aspen"
    },
    {
      "x": -7,
      "y": 22,
      "z": 11,
      "name": "Plant_Leaves_Aspen"
    },
    {
      "x": -7,
      "y": 23,
      "z": 11,
      "name": "Wood_Birch_Branch_Long",
      "support": 15,
      "rotation": 5
    },
    {
      "x": -7,
      "y": 24,
      "z": 11,
      "name": "Plant_Leaves_Aspen"
    },
    {
      "x": -7,
      "y": 22,
      "z": 12,
      "name": "Plant_Leaves_Aspen"
    },
    {
      "x": -7,
      "y": 23,
      "z": 12,
      "name": "Plant_Leaves_Aspen"
    },
    {
      "x": -7,
      "y": 24,
      "z": 12,
      "name": "Plant_Leaves_Aspen"
    },
    {
      "x": -7,
      "y": 22,
      "z": 13,
      "name": "Plant_Leaves_Aspen"
    },
    {
      "x": -7,
      "y": 23,
      "z": 13,
      "name": "Plant_Leaves_Aspen"
    },
    {
      "x": -7,
      "y": 24,
      "z": 13,
      "name": "Plant_Leaves_Aspen"
    },
    {
      "x": -7,
      "y": 23,
      "z": 14,
      "name": "Plant_Leaves_Aspen"
    },
    {
      "x": -6,
      "y": 30,
      "z": -15,
      "name": "Plant_Leaves_Aspen",
      "support": 3
    },
    {
      "x": -6,
      "y": 29,
      "z": -14,
      "name": "Plant_Leaves_Aspen",
      "support": 2
    },
    {
      "x": -6,
      "y": 30,
      "z": -14,
      "name": "Plant_Leaves_Aspen",
      "support": 2
    },
    {
      "x": -6,
      "y": 31,
      "z": -14,
      "name": "Plant_Leaves_Aspen",
      "support": 3
    },
    {
      "x": -6,
      "y": 27,
      "z": -13,
      "name": "Plant_Leaves_Aspen",
      "support": 3
    },
    {
      "x": -6,
      "y": 29,
      "z": -13,
      "name": "Plant_Leaves_Aspen",
      "support": 1
    },
    {
      "x": -6,
      "y": 30,
      "z": -13,
      "name": "Plant_Leaves_Aspen",
      "support": 1
    },
    {
      "x": -6,
      "y": 31,
      "z": -13,
      "name": "Plant_Leaves_Aspen",
      "support": 2
    },
    {
      "x": -6,
      "y": 27,
      "z": -12,
      "name": "Plant_Leaves_Aspen",
      "support": 2
    },
    {
      "x": -6,
      "y": 29,
      "z": -12,
      "name": "Plant_Leaves_Aspen"
    },
    {
      "x": -6,
      "y": 30,
      "z": -12,
      "name": "Plant_Leaves_Aspen"
    },
    {
      "x": -6,
      "y": 31,
      "z": -12,
      "name": "Plant_Leaves_Aspen",
      "support": 1
    },
    {
      "x": -6,
      "y": 27,
      "z": -11,
      "name": "Plant_Leaves_Aspen",
      "support": 3
    },
    {
      "x": -6,
      "y": 29,
      "z": -11,
      "name": "Plant_Leaves_Aspen",
      "support": 1
    },
    {
      "x": -6,
      "y": 30,
      "z": -11,
      "name": "Plant_Leaves_Aspen",
      "support": 1
    },
    {
      "x": -6,
      "y": 31,
      "z": -11,
      "name": "Plant_Leaves_Aspen",
      "support": 2
    },
    {
      "x": -6,
      "y": 29,
      "z": -10,
      "name": "Plant_Leaves_Aspen",
      "support": 2
    },
    {
      "x": -6,
      "y": 30,
      "z": -10,
      "name": "Plant_Leaves_Aspen",
      "support": 2
    },
    {
      "x": -6,
      "y": 31,
      "z": -10,
      "name": "Plant_Leaves_Aspen",
      "support": 3
    },
    {
      "x": -6,
      "y": 30,
      "z": -9,
      "name": "Plant_Leaves_Aspen",
      "support": 3
    },
    {
      "x": -6,
      "y": 2,
      "z": -8,
      "name": "Wood_Birch_Trunk_Full",
      "support": 15,
      "rotation": 4
    },
    {
      "x": -6,
      "y": 3,
      "z": -8,
      "name": "Wood_Birch_Trunk",
      "support": 15
    },
    {
      "x": -6,
      "y": 4,
      "z": -8,
      "name": "Wood_Birch_Trunk_Full",
      "support": 15
    },
    {
      "x": -6,
      "y": 1,
      "z": -7,
      "name": "Wood_Birch_Trunk_Full",
      "support": 15,
      "rotation": 4
    },
    {
      "x": -6,
      "y": 2,
      "z": -7,
      "name": "Wood_Birch_Trunk_Full",
      "support": 15,
      "rotation": 4
    },
    {
      "x": -6,
      "y": 4,
      "z": -7,
      "name": "Wood_Birch_Trunk_Full",
      "support": 15
    },
    {
      "x": -6,
      "y": 5,
      "z": -7,
      "name": "Wood_Birch_Trunk_Full",
      "support": 15
    },
    {
      "x": -6,
      "y": 1,
      "z": -6,
      "name": "Wood_Birch_Trunk_Full",
      "support": 15,
      "rotation": 4
    },
    {
      "x": -6,
      "y": 23,
      "z": -5,
      "name": "Wood_Birch_Trunk",
      "support": 15,
      "rotation": 5
    },
    {
      "x": -6,
      "y": 24,
      "z": -5,
      "name": "Wood_Birch_Trunk",
      "support": 15,
      "rotation": 5
    },
    {
      "x": -6,
      "y": 23,
      "z": -4,
      "name": "Wood_Birch_Trunk",
      "support": 15,
      "rotation": 5
    },
    {
      "x": -6,
      "y": 33,
      "z": -3,
      "name": "Plant_Leaves_Aspen",
      "support": 4
    },
    {
      "x": -6,
      "y": 34,
      "z": -3,
      "name": "Plant_Leaves_Aspen",
      "support": 4
    },
    {
      "x": -6,
      "y": 39,
      "z": -3,
      "name": "Plant_Leaves_Aspen",
      "support": 4
    },
    {
      "x": -6,
      "y": 33,
      "z": -2,
      "name": "Plant_Leaves_Aspen",
      "support": 3
    },
    {
      "x": -6,
      "y": 34,
      "z": -2,
      "name": "Plant_Leaves_Aspen",
      "support": 3
    },
    {
      "x": -6,
      "y": 39,
      "z": -2,
      "name": "Plant_Leaves_Aspen",
      "support": 3
    },
    {
      "x": -6,
      "y": 33,
      "z": -1,
      "name": "Plant_Leaves_Aspen",
      "support": 2
    },
    {
      "x": -6,
      "y": 34,
      "z": -1,
      "name": "Plant_Leaves_Aspen",
      "support": 2
    },
    {
      "x": -6,
      "y": 39,
      "z": -1,
      "name": "Plant_Leaves_Aspen",
      "support": 2
    },
    {
      "x": -6,
      "y": 26,
      "z": 0,
      "name": "Plant_Leaves_Aspen",
      "support": 2
    },
    {
      "x": -6,
      "y": 33,
      "z": 0,
      "name": "Plant_Leaves_Aspen",
      "support": 1
    },
    {
      "x": -6,
      "y": 34,
      "z": 0,
      "name": "Plant_Leaves_Aspen",
      "support": 1
    },
    {
      "x": -6,
      "y": 39,
      "z": 0,
      "name": "Plant_Leaves_Aspen",
      "support": 3
    },
    {
      "x": -6,
      "y": 43,
      "z": 0,
      "name": "Plant_Leaves_Aspen",
      "support": 4
    },
    {
      "x": -6,
      "y": 44,
      "z": 0,
      "name": "Plant_Leaves_Aspen",
      "support": 4
    },
    {
      "x": -6,
      "y": 47,
      "z": 0,
      "name": "Plant_Leaves_Aspen",
      "support": 4
    },
    {
      "x": -6,
      "y": 24,
      "z": 1,
      "name": "Wood_Birch_Trunk_Full",
      "support": 15,
      "rotation": 5
    },
    {
      "x": -6,
      "y": 26,
      "z": 1,
      "name": "Plant_Leaves_Aspen",
      "support": 1
    },
    {
      "x": -6,
      "y": 28,
      "z": 1,
      "name": "Wood_Birch_Trunk_Full",
      "support": 15,
      "rotation": 4
    },
    {
      "x": -6,
      "y": 33,
      "z": 1,
      "name": "Plant_Leaves_Aspen"
    },
    {
      "x": -6,
      "y": 34,
      "z": 1,
      "name": "Plant_Leaves_Aspen"
    },
    {
      "x": -6,
      "y": 44,
      "z": 1,
      "name": "Plant_Leaves_Aspen",
      "support": 3
    },
    {
      "x": -6,
      "y": 47,
      "z": 1,
      "name": "Plant_Leaves_Aspen",
      "support": 3
    },
    {
      "x": -6,
      "y": 26,
      "z": 2,
      "name": "Plant_Leaves_Aspen"
    },
    {
      "x": -6,
      "y": 27,
      "z": 2,
      "name": "Wood_Birch_Trunk_Full",
      "support": 15
    },
    {
      "x": -6,
      "y": 28,
      "z": 2,
      "name": "Wood_Birch_Trunk",
      "support": 15
    },
    {
      "x": -6,
      "y": 29,
      "z": 2,
      "name": "Wood_Birch_Trunk"
    },
    {
      "x": -6,
      "y": 30,
      "z": 2,
      "name": "Wood_Birch_Trunk"
    },
    {
      "x": -6,
      "y": 31,
      "z": 2,
      "name": "Wood_Birch_Trunk_Full",
      "support": 15
    },
    {
      "x": -6,
      "y": 33,
      "z": 2,
      "name": "Plant_Leaves_Aspen",
      "support": 1
    },
    {
      "x": -6,
      "y": 34,
      "z": 2,
      "name": "Plant_Leaves_Aspen",
      "support": 1
    },
    {
      "x": -6,
      "y": 44,
      "z": 2,
      "name": "Plant_Leaves_Aspen",
      "support": 4
    },
    {
      "x": -6,
      "y": 47,
      "z": 2,
      "name": "Plant_Leaves_Aspen",
      "support": 4
    },
    {
      "x": -6,
      "y": 2,
      "z": 3,
      "name": "Wood_Birch_Trunk_Full",
      "support": 15
    },
    {
      "x": -6,
      "y": 3,
      "z": 3,
      "name": "Wood_Birch_Trunk",
      "support": 15
    },
    {
      "x": -6,
      "y": 4,
      "z": 3,
      "name": "Wood_Birch_Trunk",
      "support": 15
    },
    {
      "x": -6,
      "y": 5,
      "z": 3,
      "name": "Wood_Birch_Trunk",
      "support": 15
    },
    {
      "x": -6,
      "y": 6,
      "z": 3,
      "name": "Wood_Birch_Trunk",
      "support": 15
    },
    {
      "x": -6,
      "y": 7,
      "z": 3,
      "name": "Wood_Birch_Trunk",
      "support": 15
    },
    {
      "x": -6,
      "y": 8,
      "z": 3,
      "name": "Wood_Birch_Trunk",
      "support": 15
    },
    {
      "x": -6,
      "y": 9,
      "z": 3,
      "name": "Wood_Birch_Trunk",
      "support": 15
    },
    {
      "x": -6,
      "y": 10,
      "z": 3,
      "name": "Wood_Birch_Trunk_Full",
      "support": 15
    },
    {
      "x": -6,
      "y": 27,
      "z": 3,
      "name": "Wood_Birch_Trunk_Full",
      "support": 15
    },
    {
      "x": -6,
      "y": 28,
      "z": 3,
      "name": "Wood_Birch_Trunk",
      "support": 15
    },
    {
      "x": -6,
      "y": 29,
      "z": 3,
      "name": "Wood_Birch_Trunk_Full",
      "support": 15
    },
    {
      "x": -6,
      "y": 33,
      "z": 3,
      "name": "Plant_Leaves_Aspen",
      "support": 1
    },
    {
      "x": -6,
      "y": 4,
      "z": 4,
      "name": "Wood_Birch_Trunk_Full",
      "support": 15
    },
    {
      "x": -6,
      "y": 5,
      "z": 4,
      "name": "Wood_Birch_Trunk",
      "support": 15
    },
    {
      "x": -6,
      "y": 6,
      "z": 4,
      "name": "Wood_Birch_Trunk",
      "support": 15
    },
    {
      "x": -6,
      "y": 7,
      "z": 4,
      "name": "Wood_Birch_Trunk",
      "support": 15
    },
    {
      "x": -6,
      "y": 8,
      "z": 4,
      "name": "Wood_Birch_Trunk_Full",
      "support": 15
    },
    {
      "x": -6,
      "y": 25,
      "z": 4,
      "name": "Wood_Birch_Trunk",
      "support": 15,
      "rotation": 5
    },
    {
      "x": -6,
      "y": 26,
      "z": 4,
      "name": "Wood_Birch_Trunk",
      "support": 15
    },
    {
      "x": -6,
      "y": 27,
      "z": 4,
      "name": "Wood_Birch_Trunk_Full",
      "support": 15
    },
    {
      "x": -6,
      "y": 34,
      "z": 4,
      "name": "Plant_Leaves_Aspen",
      "support": 2
    },
    {
      "x": -6,
      "y": 34,
      "z": 5,
      "name": "Plant_Leaves_Aspen",
      "support": 1
    },
    {
      "x": -6,
      "y": 34,
      "z": 6,
      "name": "Plant_Leaves_Aspen",
      "support": 2
    },
    {
      "x": -6,
      "y": 38,
      "z": 6,
      "name": "Plant_Leaves_Aspen",
      "support": 3
    },
    {
      "x": -6,
      "y": 34,
      "z": 7,
      "name": "Plant_Leaves_Aspen",
      "support": 15
    },
    {
      "x": -6,
      "y": 38,
      "z": 7,
      "name": "Plant_Leaves_Aspen",
      "support": 2
    },
    {
      "x": -6,
      "y": 23,
      "z": 8,
      "name": "Wood_Birch_Trunk",
      "support": 15,
      "rotation": 5
    },
    {
      "x": -6,
      "y": 34,
      "z": 8,
      "name": "Plant_Leaves_Aspen",
      "support": 15
    },
    {
      "x": -6,
      "y": 38,
      "z": 8,
      "name": "Plant_Leaves_Aspen",
      "support": 3
    },
    {
      "x": -6,
      "y": 22,
      "z": 9,
      "name": "Plant_Leaves_Aspen"
    },
    {
      "x": -6,
      "y": 23,
      "z": 9,
      "name": "Plant_Leaves_Aspen"
    },
    {
      "x": -6,
      "y": 24,
      "z": 9,
      "name": "Plant_Leaves_Aspen"
    },
    {
      "x": -6,
      "y": 22,
      "z": 10,
      "name": "Plant_Leaves_Aspen"
    },
    {
      "x": -6,
      "y": 23,
      "z": 10,
      "name": "Plant_Leaves_Aspen"
    },
    {
      "x": -6,
      "y": 24,
      "z": 10,
      "name": "Plant_Leaves_Aspen"
    },
    {
      "x": -6,
      "y": 22,
      "z": 11,
      "name": "Plant_Leaves_Aspen"
    },
    {
      "x": -6,
      "y": 23,
      "z": 11,
      "name": "Wood_Birch_Branch_Long",
      "support": 15,
      "rotation": 5
    },
    {
      "x": -6,
      "y": 24,
      "z": 11,
      "name": "Plant_Leaves_Aspen"
    },
    {
      "x": -6,
      "y": 22,
      "z": 12,
      "name": "Plant_Leaves_Aspen"
    },
    {
      "x": -6,
      "y": 23,
      "z": 12,
      "name": "Plant_Leaves_Aspen"
    },
    {
      "x": -6,
      "y": 24,
      "z": 12,
      "name": "Plant_Leaves_Aspen"
    },
    {
      "x": -6,
      "y": 22,
      "z": 13,
      "name": "Plant_Leaves_Aspen"
    },
    {
      "x": -6,
      "y": 23,
      "z": 13,
      "name": "Plant_Leaves_Aspen"
    },
    {
      "x": -6,
      "y": 24,
      "z": 13,
      "name": "Plant_Leaves_Aspen"
    },
    {
      "x": -6,
      "y": 23,
      "z": 14,
      "name": "Plant_Leaves_Aspen"
    },
    {
      "x": -6,
      "y": 23,
      "z": 15,
      "name": "Plant_Leaves_Aspen"
    },
    {
      "x": -5,
      "y": 30,
      "z": -15,
      "name": "Plant_Leaves_Aspen",
      "support": 2
    },
    {
      "x": -5,
      "y": 29,
      "z": -14,
      "name": "Plant_Leaves_Aspen",
      "support": 1
    },
    {
      "x": -5,
      "y": 30,
      "z": -14,
      "name": "Plant_Leaves_Aspen",
      "support": 1
    },
    {
      "x": -5,
      "y": 31,
      "z": -14,
      "name": "Plant_Leaves_Aspen",
      "support": 2
    },
    {
      "x": -5,
      "y": 29,
      "z": -13,
      "name": "Plant_Leaves_Aspen"
    },
    {
      "x": -5,
      "y": 30,
      "z": -13,
      "name": "Plant_Leaves_Aspen"
    },
    {
      "x": -5,
      "y": 31,
      "z": -13,
      "name": "Plant_Leaves_Aspen",
      "support": 1
    },
    {
      "x": -5,
      "y": 28,
      "z": -12,
      "name": "Wood_Birch_Branch_Corner",
      "support": 15,
      "rotation": 3
    },
    {
      "x": -5,
      "y": 29,
      "z": -12,
      "name": "Wood_Birch_Branch_Long",
      "support": 15
    },
    {
      "x": -5,
      "y": 30,
      "z": -12,
      "name": "Wood_Birch_Branch_Long",
      "support": 15
    },
    {
      "x": -5,
      "y": 31,
      "z": -12,
      "name": "Plant_Leaves_Aspen"
    },
    {
      "x": -5,
      "y": 29,
      "z": -11,
      "name": "Plant_Leaves_Aspen"
    },
    {
      "x": -5,
      "y": 30,
      "z": -11,
      "name": "Plant_Leaves_Aspen"
    },
    {
      "x": -5,
      "y": 31,
      "z": -11,
      "name": "Plant_Leaves_Aspen",
      "support": 1
    },
    {
      "x": -5,
      "y": 29,
      "z": -10,
      "name": "Plant_Leaves_Aspen",
      "support": 1
    },
    {
      "x": -5,
      "y": 30,
      "z": -10,
      "name": "Plant_Leaves_Aspen",
      "support": 1
    },
    {
      "x": -5,
      "y": 31,
      "z": -10,
      "name": "Plant_Leaves_Aspen",
      "support": 2
    },
    {
      "x": -5,
      "y": 30,
      "z": -9,
      "name": "Plant_Leaves_Aspen",
      "support": 2
    },
    {
      "x": -5,
      "y": 25,
      "z": -8,
      "name": "Wood_Birch_Trunk_Full",
      "support": 15,
      "rotation": 4
    },
    {
      "x": -5,
      "y": 5,
      "z": -7,
      "name": "Wood_Birch_Trunk_Full",
      "support": 15,
      "rotation": 4
    },
    {
      "x": -5,
      "y": 24,
      "z": -7,
      "name": "Wood_Birch_Trunk_Full",
      "support": 15,
      "rotation": 4
    },
    {
      "x": -5,
      "y": 25,
      "z": -7,
      "name": "Wood_Birch_Trunk",
      "support": 15,
      "rotation": 4
    },
    {
      "x": -5,
      "y": 1,
      "z": -6,
      "name": "Wood_Birch_Trunk_Full",
      "support": 15,
      "rotation": 4
    },
    {
      "x": -5,
      "y": 5,
      "z": -6,
      "name": "Wood_Birch_Trunk_Full",
      "support": 15,
      "rotation": 4
    },
    {
      "x": -5,
      "y": 24,
      "z": -6,
      "name": "Wood_Birch_Trunk",
      "support": 15,
      "rotation": 4
    },
    {
      "x": -5,
      "y": 25,
      "z": -6,
      "name": "Wood_Birch_Trunk_Full",
      "support": 15,
      "rotation": 4
    },
    {
      "x": -5,
      "y": 1,
      "z": -5,
      "name": "Wood_Birch_Trunk_Full",
      "support": 15,
      "rotation": 4
    },
    {
      "x": -5,
      "y": 23,
      "z": -5,
      "name": "Wood_Birch_Trunk",
      "support": 15,
      "rotation": 5
    },
    {
      "x": -5,
      "y": 24,
      "z": -5,
      "name": "Wood_Birch_Trunk_Full",
      "support": 15
    },
    {
      "x": -5,
      "y": 23,
      "z": -4,
      "name": "Wood_Birch_Trunk",
      "support": 15,
      "rotation": 5
    },
    {
      "x": -5,
      "y": 33,
      "z": -4,
      "name": "Plant_Leaves_Aspen",
      "support": 4
    },
    {
      "x": -5,
      "y": 34,
      "z": -4,
      "name": "Plant_Leaves_Aspen",
      "support": 4
    },
    {
      "x": -5,
      "y": 39,
      "z": -4,
      "name": "Plant_Leaves_Aspen",
      "support": 4
    },
    {
      "x": -5,
      "y": 22,
      "z": -3,
      "name": "Wood_Birch_Trunk_Full",
      "support": 15
    },
    {
      "x": -5,
      "y": 23,
      "z": -3,
      "name": "Wood_Birch_Trunk_Full",
      "support": 15
