{
  "version": 8,
  "blockIdVersion": 11,
  "anchorX": 0,
  "anchorY": 3,
  "anchorZ": 0,
  "blocks": [
    {
      "x": -3,
      "y": 12,
      "z": -4,
      "name": "Wood_Ash_Branch_Corner",
      "support": 15,
      "rotation": 3
    },
    {
      "x": -3,
      "y": 13,
      "z": -4,
      "name": "Wood_Ash_Branch_Long",
      "support": 15
    },
    {
      "x": -3,
      "y": 9,
      "z": 1,
      "name": "Wood_Ash_Branch_Corner",
      "support": 15,
      "rotation": 3
    },
    {
      "x": -3,
      "y": 10,
      "z": 1,
      "name": "Wood_Ash_Branch_Long",
      "support": 15
    },
    {
      "x": -3,
      "y": 11,
      "z": 1,
      "name": "Wood_Ash_Branch_Long",
      "support": 15
    },
    {
      "x": -3,
      "y": 12,
      "z": 1,
      "name": "Wood_Ash_Branch_Corner",
      "support": 15,
      "rotation": 9
    },
    {
      "x": -2,
      "y": 11,
      "z": -4,
      "name": "Wood_Ash_Branch_Corner",
      "support": 15,
      "rotation": 2
    },
    {
      "x": -2,
      "y": 12,
      "z": -4,
      "name": "Wood_Ash_Branch_Corner",
      "support": 15,
      "rotation": 11
    },
    {
      "x": -2,
      "y": 10,
      "z": -3,
      "name": "Wood_Ash_Branch_Corner",
      "support": 15,
      "rotation": 3
    },
    {
      "x": -2,
      "y": 11,
      "z": -3,
      "name": "Wood_Ash_Branch_Corner",
      "support": 15,
      "rotation": 10
    },
    {
      "x": -2,
      "y": 8,
      "z": 1,
      "name": "Wood_Ash_Branch_Short",
      "support": 15,
      "rotation": 3
    },
    {
      "x": -2,
      "y": 9,
      "z": 1,
      "name": "Wood_Ash_Branch_Long",
      "support": 15,
      "rotation": 5
    },
    {
      "x": -2,
      "y": 12,
      "z": 1,
      "name": "Wood_Ash_Branch_Long",
      "support": 15,
      "rotation": 5
    },
    {
      "x": -2,
      "y": 14,
      "z": 1,
      "name": "Wood_Ash_Branch_Corner",
      "support": 15,
      "rotation": 9
    },
    {
      "x": -2,
      "y": 10,
      "z": 3,
      "name": "Wood_Ash_Branch_Corner",
      "support": 15,
      "rotation": 3
    },
    {
      "x": -2,
      "y": 11,
      "z": 3,
      "name": "Wood_Ash_Branch_Long",
      "support": 15
    },
    {
      "x": -1,
      "y": 10,
      "z": -3,
      "name": "Wood_Ash_Branch_Long",
      "support": 15,
      "rotation": 5
    },
    {
      "x": -1,
      "y": 9,
      "z": -2,
      "name": "Wood_Ash_Branch_Short",
      "support": 15,
      "rotation": 3
    },
    {
      "x": -1,
      "y": -2,
      "z": -1,
      "name": "Wood_Ash_Roots"
    },
    {
      "x": -1,
      "y": -1,
      "z": -1,
      "name": "Wood_Ash_Trunk",
      "support": 15
    },
    {
      "x": -1,
      "y": 0,
      "z": -1,
      "name": "Wood_Ash_Trunk",
      "support": 15
    },
    {
      "x": -1,
      "y": 1,
      "z": -1,
      "name": "Wood_Ash_Trunk",
      "support": 15,
      "rotation": 4
    },
    {
      "x": -1,
      "y": 0,
      "z": 0,
      "name": "Wood_Ash_Roots"
    },
    {
      "x": -1,
      "y": 1,
      "z": 0,
      "name": "Wood_Ash_Trunk_Full",
      "support": 15
    },
    {
      "x": -1,
      "y": 2,
      "z": 0,
      "name": "Wood_Ash_Trunk",
      "support": 15
    },
    {
      "x": -1,
      "y": 3,
      "z": 0,
      "name": "Wood_Ash_Trunk_Full",
      "support": 15
    },
    {
      "x": -1,
      "y": 6,
      "z": 1,
      "name": "Wood_Ash_Roots"
    },
    {
      "x": -1,
      "y": 7,
      "z": 1,
      "name": "Wood_Ash_Trunk_Full",
      "support": 15
    },
    {
      "x": -1,
      "y": 8,
      "z": 1,
      "name": "Wood_Ash_Trunk",
      "support": 15
    },
    {
      "x": -1,
      "y": 9,
      "z": 1,
      "name": "Wood_Ash_Trunk_Full",
      "support": 15
    },
    {
      "x": -1,
      "y": 12,
      "z": 1,
      "name": "Wood_Ash_Branch_Corner",
      "support": 15,
      "rotation": 1
    },
    {
      "x": -1,
      "y": 13,
      "z": 1,
      "name": "Wood_Ash_Branch_Long",
      "support": 15
    },
    {
      "x": -1,
      "y": 14,
      "z": 1,
      "name": "Wood_Ash_Branch_Corner",
      "support": 15,
      "rotation": 11
    },
    {
      "x": -1,
      "y": 10,
      "z": 3,
      "name": "Wood_Ash_Branch_Long",
      "support": 15,
      "rotation": 5
    },
    {
      "x": 0,
      "y": 11,
      "z": -7,
      "name": "Wood_Ash_Branch_Corner",
      "support": 15,
      "rotation": 2
    },
    {
      "x": 0,
      "y": 12,
      "z": -7,
      "name": "Wood_Ash_Branch_Long",
      "support": 15
    },
    {
      "x": 0,
      "y": 13,
      "z": -7,
      "name": "Wood_Ash_Branch_Corner",
      "support": 15,
      "rotation": 9
    },
    {
      "x": 0,
      "y": 11,
      "z": -6,
      "name": "Wood_Ash_Branch_Long",
      "support": 15,
      "rotation": 4
    },
    {
      "x": 0,
      "y": 10,
      "z": -5,
      "name": "Wood_Ash_Branch_Corner",
      "support": 15,
      "rotation": 2
    },
    {
      "x": 0,
      "y": 11,
      "z": -5,
      "name": "Wood_Ash_Branch_Corner",
      "support": 15,
      "rotation": 10
    },
    {
      "x": 0,
      "y": 10,
      "z": -4,
      "name": "Wood_Ash_Trunk_Full",
      "support": 15,
      "rotation": 4
    },
    {
      "x": 0,
      "y": 10,
      "z": -3,
      "name": "Wood_Ash_Trunk_Full",
      "support": 15,
      "rotation": 4
    },
    {
      "x": 0,
      "y": -1,
      "z": -2,
      "name": "Wood_Ash_Roots"
    },
    {
      "x": 0,
      "y": 0,
      "z": -2,
      "name": "Wood_Ash_Trunk",
      "support": 15
    },
    {
      "x": 0,
      "y": 1,
      "z": -2,
      "name": "Wood_Ash_Trunk",
      "support": 15
    },
    {
      "x": 0,
      "y": 2,
      "z": -2,
      "name": "Wood_Ash_Trunk",
      "support": 15,
      "rotation": 4
    },
    {
      "x": 0,
      "y": 8,
      "z": -2,
      "name": "Wood_Ash_Roots"
    },
    {
      "x": 0,
      "y": 9,
      "z": -2,
      "name": "Wood_Ash_Trunk_Full",
      "support": 15
    },
    {
      "x": 0,
      "y": 10,
      "z": -2,
      "name": "Wood_Ash_Trunk_Full",
      "support": 15
    },
    {
      "x": 0,
      "y": 1,
      "z": -1,
      "name": "Wood_Ash_Branch_Long",
      "support": 15
    },
    {
      "x": 0,
      "y": 2,
      "z": -1,
      "name": "Wood_Ash_Trunk_Full",
      "support": 15
    },
    {
      "x": 0,
      "y": 3,
      "z": -1,
      "name": "Wood_Ash_Trunk_Full",
      "support": 15
    },
    {
      "x": 0,
      "y": 4,
      "z": -1,
      "name": "Wood_Ash_Trunk",
      "support": 15
    },
    {
      "x": 0,
      "y": 5,
      "z": -1,
      "name": "Wood_Ash_Trunk_Full",
      "support": 15
    },
    {
      "x": 0,
      "y": 8,
      "z": -1,
      "name": "Wood_Ash_Trunk_Full",
      "support": 15
    },
    {
      "x": 0,
      "y": 9,
      "z": -1,
      "name": "Wood_Ash_Trunk_Full",
      "support": 15
    },
    {
      "x": 0,
      "y": 10,
      "z": -1,
      "name": "Wood_Ash_Branch_Long",
      "support": 15
    },
    {
      "x": 0,
      "y": 11,
      "z": -1,
      "name": "Wood_Ash_Branch_Long",
      "support": 15
    },
    {
      "x": 0,
      "y": 12,
      "z": -1,
      "name": "Wood_Ash_Branch_Corner",
      "support": 15,
      "rotation": 9
    },
    {
      "x": 0,
      "y": 1,
      "z": 0,
      "name": "Wood_Ash_Roots"
    },
    {
      "x": 0,
      "y": 2,
      "z": 0,
      "name": "Wood_Ash_Trunk_Full",
      "support": 15
    },
    {
      "x": 0,
      "y": 3,
      "z": 0,
      "name": "Wood_Ash_Trunk_Full",
      "support": 15
    },
    {
      "x": 0,
      "y": 4,
      "z": 0,
      "name": "Wood_Ash_Trunk",
      "support": 15
    },
    {
      "x": 0,
      "y": 5,
      "z": 0,
      "name": "Wood_Ash_Trunk",
      "support": 15
    },
    {
      "x": 0,
      "y": 6,
      "z": 0,
      "name": "Wood_Ash_Trunk",
      "support": 15
    },
    {
      "x": 0,
      "y": 7,
      "z": 0,
      "name": "Wood_Ash_Trunk",
      "support": 15
    },
    {
      "x": 0,
      "y": 8,
      "z": 0,
      "name": "Wood_Ash_Trunk_Full",
      "support": 15
    },
    {
      "x": 0,
      "y": 2,
      "z": 1,
      "name": "Wood_Ash_Trunk_Full",
      "support": 15
    },
    {
      "x": 0,
      "y": 3,
      "z": 1,
      "name": "Wood_Ash_Trunk_Full",
      "support": 15
    },
    {
      "x": 0,
      "y": 4,
      "z": 1,
      "name": "Wood_Ash_Trunk_Full",
      "support": 15
    },
    {
      "x": 0,
      "y": 6,
      "z": 1,
      "name": "Wood_Ash_Trunk_Full",
      "support": 15
    },
    {
      "x": 0,
      "y": 7,
      "z": 1,
      "name": "Wood_Ash_Trunk",
      "support": 15
    },
    {
      "x": 0,
      "y": 8,
      "z": 1,
      "name": "Wood_Ash_Trunk_Full",
      "support": 15
    },
    {
      "x": 0,
      "y": 7,
      "z": 2,
      "name": "Wood_Ash_Branch_Short",
      "support": 15
    },
    {
      "x": 0,
      "y": 8,
      "z": 2,
      "name": "Wood_Ash_Trunk_Full",
      "support": 15
    },
    {
      "x": 0,
      "y": 9,
      "z": 2,
      "name": "Wood_Ash_Trunk_Full",
      "support": 15
    },
    {
      "x": 0,
      "y": 9,
      "z": 3,
      "name": "Wood_Ash_Trunk_Full",
      "support": 15
    },
    {
      "x": 0,
      "y": 10,
      "z": 3,
      "name": "Wood_Ash_Trunk_Full",
      "support": 15
    },
    {
      "x": 0,
      "y": 10,
      "z": 4,
      "name": "Wood_Ash_Branch_Long",
      "support": 15,
      "rotation": 4
    },
    {
      "x": 0,
      "y": 10,
      "z": 5,
      "name": "Wood_Ash_Branch_Corner",
      "support": 15
    },
    {
      "x": 0,
      "y": 11,
      "z": 5,
      "name": "Wood_Ash_Branch_Corner",
      "support": 15,
      "rotation": 8
    },
    {
      "x": 0,
      "y": 11,
      "z": 6,
      "name": "Wood_Ash_Branch_Corner",
      "support": 15
    },
    {
      "x": 0,
      "y": 12,
      "z": 6,
      "name": "Wood_Ash_Branch_Corner",
      "support": 15,
      "rotation": 8
    },
    {
      "x": 0,
      "y": 12,
      "z": 7,
      "name": "Wood_Ash_Branch_Long",
      "support": 15,
      "rotation": 4
    },
    {
      "x": 1,
      "y": 13,
      "z": -7,
      "name": "Wood_Ash_Branch_Long",
      "support": 15,
      "rotation": 5
    },
    {
      "x": 1,
      "y": 10,
      "z": -4,
      "name": "Wood_Ash_Branch_Long",
      "support": 15,
      "rotation": 5
    },
    {
      "x": 1,
      "y": 12,
      "z": -1,
      "name": "Wood_Ash_Branch_Long",
      "support": 15,
      "rotation": 5
    },
    {
      "x": 1,
      "y": 13,
      "z": -1,
      "name": "Wood_Ash_Branch_Corner",
      "support": 15,
      "rotation": 3
    },
    {
      "x": 1,
      "y": 14,
      "z": -1,
      "name": "Wood_Ash_Branch_Long",
      "support": 15
    },
    {
      "x": 1,
      "y": 15,
      "z": -1,
      "name": "Wood_Ash_Branch_Corner",
      "support": 15,
      "rotation": 9
    },
    {
      "x": 1,
      "y": -1,
      "z": 0,
      "name": "Wood_Ash_Roots"
    },
    {
      "x": 1,
      "y": 0,
      "z": 0,
      "name": "Wood_Ash_Trunk_Full",
      "support": 15
    },
    {
      "x": 1,
      "y": 1,
      "z": 0,
      "name": "Wood_Ash_Trunk",
      "support": 15
    },
    {
      "x": 1,
      "y": 2,
      "z": 0,
      "name": "Wood_Ash_Trunk",
      "support": 15
    },
    {
      "x": 1,
      "y": 3,
      "z": 0,
      "name": "Wood_Ash_Trunk_Full",
      "support": 15
    },
    {
      "x": 1,
      "y": 7,
      "z": 0,
      "name": "Wood_Ash_Trunk_Full",
      "support": 15
    },
    {
      "x": 1,
      "y": 8,
      "z": 0,
      "name": "Wood_Ash_Trunk_Full",
      "support": 15
    },
    {
      "x": 1,
      "y": 10,
      "z": 3,
      "name": "Wood_Ash_Branch_Long",
      "support": 15,
      "rotation": 5
    },
    {
      "x": 2,
      "y": 10,
      "z": -4,
      "name": "Wood_Ash_Branch_Corner",
      "support": 15,
      "rotation": 1
    },
    {
      "x": 2,
      "y": 11,
      "z": -4,
      "name": "Wood_Ash_Branch_Long",
      "support": 15
    },
    {
      "x": 2,
      "y": 12,
      "z": -1,
      "name": "Wood_Ash_Branch_Long",
      "support": 15,
      "rotation": 5
    },
    {
      "x": 2,
      "y": 13,
      "z": -1,
      "name": "Wood_Ash_Branch_Corner",
      "support": 15,
      "rotation": 1
    },
    {
      "x": 2,
      "y": 15,
      "z": -1,
      "name": "Wood_Ash_Branch_Long",
      "support": 15,
      "rotation": 5
    },
    {
      "x": 2,
      "y": 10,
      "z": 3,
      "name": "Wood_Ash_Branch_Corner",
      "support": 15,
      "rotation": 1
    },
    {
      "x": 2,
      "y": 11,
      "z": 3,
      "name": "Wood_Ash_Branch_Long",
      "support": 15
    },
    {
      "x": 2,
      "y": 12,
      "z": 3,
      "name": "Wood_Ash_Branch_Long",
      "support": 15
    },
    {
      "x": 2,
      "y": 13,
      "z": 3,
      "name": "Wood_Ash_Branch_Corner",
      "support": 15,
      "rotation": 8
    },
    {
      "x": 2,
      "y": 13,
      "z": 4,
      "name": "Wood_Ash_Branch_Long",
      "support": 15,
      "rotation": 4
    },
    {
      "x": 2,
      "y": 12,
      "z": 5,
      "name": "Wood_Ash_Branch_Corner",
      "support": 15
    },
    {
      "x": 2,
      "y": 13,
      "z": 5,
      "name": "Wood_Ash_Branch_Corner",
      "support": 15,
      "rotation": 10
    },
    {
      "x": 3,
      "y": 12,
      "z": -1,
      "name": "Wood_Ash_Branch_Corner",
      "support": 15,
      "rotation": 1
    },
    {
      "x": 3,
      "y": 13,
      "z": -1,
      "name": "Wood_Ash_Branch_Long",
      "support": 15
    },
    {
      "x": 3,
      "y": 14,
      "z": -1,
      "name": "Wood_Ash_Branch_Long",
      "support": 15
    },
    {
      "x": 3,
      "y": 15,
      "z": -1,
      "name": "Wood_Ash_Branch_Corner",
      "support": 15,
      "rotation": 11
    }
  ]
}