{
  "version": 8,
  "blockIdVersion": 11,
  "anchorX": 0,
  "anchorY": 14,
  "anchorZ": 0,
  "blocks": [
    {
      "x": -6,
      "y": 17,
      "z": -4,
      "name": "Plant_Large_Lilypad_Half"
    },
    {
      "x": -6,
      "y": 17,
      "z": -3,
      "name": "Plant_Large_Lilypad_Half"
    },
    {
      "x": -5,
      "y": 17,
      "z": -5,
      "name": "Plant_Large_Lilypad_Half"
    },
    {
      "x": -5,
      "y": 17,
      "z": -4,
      "name": "Plant_Large_Lilypad_Half"
    },
    {
      "x": -5,
      "y": 10,
      "z": -3,
      "name": "Wood_Banyan_Branch_Corner",
      "support": 15,
      "rotation": 2
    },
    {
      "x": -5,
      "y": 11,
      "z": -3,
      "name": "Wood_Banyan_Branch_Long",
      "support": 15
    },
    {
      "x": -5,
      "y": 12,
      "z": -3,
      "name": "Wood_Banyan_Branch_Long",
      "support": 15
    },
    {
      "x": -5,
      "y": 13,
      "z": -3,
      "name": "Wood_Banyan_Branch_Long",
      "support": 15
    },
    {
      "x": -5,
      "y": 14,
      "z": -3,
      "name": "Wood_Banyan_Branch_Long",
      "support": 15
    },
    {
      "x": -5,
      "y": 15,
      "z": -3,
      "name": "Wood_Banyan_Branch_Corner",
      "support": 15,
      "rotation": 9
    },
    {
      "x": -5,
      "y": 17,
      "z": -3,
      "name": "Plant_Large_Lilypad_Half"
    },
    {
      "x": -5,
      "y": 9,
      "z": -2,
      "name": "Wood_Banyan_Branch_Corner",
      "support": 15,
      "rotation": 3
    },
    {
      "x": -5,
      "y": 10,
      "z": -2,
      "name": "Wood_Banyan_Branch_Corner",
      "support": 15,
      "rotation": 10
    },
    {
      "x": -5,
      "y": 17,
      "z": -2,
      "name": "Plant_Large_Lilypad_Half"
    },
    {
      "x": -5,
      "y": 12,
      "z": 3,
      "name": "Plant_Large_Lilypad"
    },
    {
      "x": -5,
      "y": 13,
      "z": 3,
      "name": "Plant_Reeds_Marsh",
      "support": 15
    },
    {
      "x": -5,
      "y": 11,
      "z": 4,
      "name": "Wood_Banyan_Roots"
    },
    {
      "x": -5,
      "y": 12,
      "z": 4,
      "name": "Plant_Large_Lilypad"
    },
    {
      "x": -4,
      "y": 17,
      "z": -5,
      "name": "Plant_Large_Lilypad_Half"
    },
    {
      "x": -4,
      "y": 17,
      "z": -4,
      "name": "Plant_Large_Lilypad_Half"
    },
    {
      "x": -4,
      "y": 15,
      "z": -3,
      "name": "Wood_Banyan_Branch_Corner",
      "support": 15,
      "rotation": 1
    },
    {
      "x": -4,
      "y": 16,
      "z": -3,
      "name": "Wood_Banyan_Branch_Long",
      "support": 15
    },
    {
      "x": -4,
      "y": 17,
      "z": -3,
      "name": "Plant_Large_Lilypad_Half"
    },
    {
      "x": -4,
      "y": 7,
      "z": -2,
      "name": "Wood_Banyan_Branch_Corner",
      "support": 15,
      "rotation": 3
    },
    {
      "x": -4,
      "y": 8,
      "z": -2,
      "name": "Wood_Banyan_Branch_Long",
      "support": 15
    },
    {
      "x": -4,
      "y": 9,
      "z": -2,
      "name": "Wood_Banyan_Branch_Corner",
      "support": 15,
      "rotation": 11
    },
    {
      "x": -4,
      "y": 17,
      "z": -2,
      "name": "Plant_Large_Lilypad_Half"
    },
    {
      "x": -4,
      "y": 9,
      "z": 3,
      "name": "Wood_Banyan_Branch_Corner",
      "support": 15,
      "rotation": 3
    },
    {
      "x": -4,
      "y": 10,
      "z": 3,
      "name": "Wood_Banyan_Branch_Long",
      "support": 15
    },
    {
      "x": -4,
      "y": 11,
      "z": 3,
      "name": "Wood_Banyan_Branch_Long",
      "support": 15
    },
    {
      "x": -4,
      "y": 12,
      "z": 3,
      "name": "Plant_Large_Lilypad"
    },
    {
      "x": -4,
      "y": 13,
      "z": 3,
      "name": "Plant_Reeds_Arid",
      "support": 15
    },
    {
      "x": -4,
      "y": 14,
      "z": 3,
      "name": "Plant_Reeds_Arid",
      "filler": 1024
    },
    {
      "x": -4,
      "y": 12,
      "z": 4,
      "name": "Plant_Large_Lilypad"
    },
    {
      "x": -4,
      "y": 13,
      "z": 4,
      "name": "Plant_Grass_Wet_Overgrown",
      "support": 15
    },
    {
      "x": -4,
      "y": 14,
      "z": 4,
      "name": "Plant_Grass_Wet_Overgrown",
      "filler": 1024
    },
    {
      "x": -3,
      "y": 17,
      "z": -4,
      "name": "Plant_Large_Lilypad_Half"
    },
    {
      "x": -3,
      "y": 17,
      "z": -3,
      "name": "Plant_Large_Lilypad_Half"
    },
    {
      "x": -3,
      "y": -1,
      "z": -2,
      "name": "Wood_Banyan_Branch_Long",
      "support": 15
    },
    {
      "x": -3,
      "y": 0,
      "z": -2,
      "name": "Wood_Banyan_Branch_Long",
      "support": 15
    },
    {
      "x": -3,
      "y": 1,
      "z": -2,
      "name": "Wood_Banyan_Branch_Corner",
      "support": 15,
      "rotation": 8
    },
    {
      "x": -3,
      "y": 7,
      "z": -2,
      "name": "Wood_Banyan_Branch_Long",
      "support": 15,
      "rotation": 5
    },
    {
      "x": -3,
      "y": 1,
      "z": -1,
      "name": "Wood_Banyan_Branch_Long",
      "support": 15,
      "rotation": 4
    },
    {
      "x": -3,
      "y": 13,
      "z": -1,
      "name": "Plant_Large_Lilypad",
      "rotation": 3
    },
    {
      "x": -3,
      "y": 14,
      "z": -1,
      "name": "Plant_Large_Lilypad_Half"
    },
    {
      "x": -3,
      "y": -1,
      "z": 0,
      "name": "Wood_Banyan_Trunk",
      "support": 15
    },
    {
      "x": -3,
      "y": 0,
      "z": 0,
      "name": "Wood_Banyan_Trunk",
      "support": 15
    },
    {
      "x": -3,
      "y": 1,
      "z": 0,
      "name": "Wood_Banyan_Trunk",
      "support": 15
    },
    {
      "x": -3,
      "y": 2,
      "z": 0,
      "name": "Wood_Banyan_Trunk",
      "support": 15
    },
    {
      "x": -3,
      "y": 3,
      "z": 0,
      "name": "Wood_Banyan_Trunk",
      "support": 15
    },
    {
      "x": -3,
      "y": 4,
      "z": 0,
      "name": "Wood_Banyan_Trunk_Full",
      "support": 15
    },
    {
      "x": -3,
      "y": 13,
      "z": 0,
      "name": "Plant_Large_Lilypad",
      "rotation": 3
    },
    {
      "x": -3,
      "y": 14,
      "z": 0,
      "name": "Plant_Large_Lilypad_Half"
    },
    {
      "x": -3,
      "y": 13,
      "z": 1,
      "name": "Plant_Large_Lilypad",
      "rotation": 3
    },
    {
      "x": -3,
      "y": 14,
      "z": 1,
      "name": "Plant_Large_Lilypad_Half"
    },
    {
      "x": -3,
      "y": 9,
      "z": 3,
      "name": "Wood_Banyan_Branch_Long",
      "support": 15,
      "rotation": 5
    },
    {
      "x": -2,
      "y": 7,
      "z": -2,
      "name": "Wood_Banyan_Branch_Long",
      "support": 15,
      "rotation": 5
    },
    {
      "x": -2,
      "y": 13,
      "z": -2,
      "name": "Plant_Large_Lilypad",
      "rotation": 3
    },
    {
      "x": -2,
      "y": 14,
      "z": -2,
      "name": "Plant_Large_Lilypad_Half"
    },
    {
      "x": -2,
      "y": 13,
      "z": -1,
      "name": "Plant_Large_Lilypad",
      "rotation": 3
    },
    {
      "x": -2,
      "y": 14,
      "z": -1,
      "name": "Plant_Grass_Sharp_Wild",
      "support": 15
    },
    {
      "x": -2,
      "y": 15,
      "z": -1,
      "name": "Plant_Grass_Sharp_Wild",
      "filler": 1024
    },
    {
      "x": -2,
      "y": 2,
      "z": 0,
      "name": "Wood_Banyan_Branch_Long",
      "support": 15,
      "rotation": 5
    },
    {
      "x": -2,
      "y": 4,
      "z": 0,
      "name": "Wood_Banyan_Trunk",
      "support": 15,
      "rotation": 5
    },
    {
      "x": -2,
      "y": 13,
      "z": 0,
      "name": "Plant_Large_Lilypad",
      "rotation": 3
    },
    {
      "x": -2,
      "y": 14,
      "z": 0,
      "name": "Plant_Grass_Sharp_Short",
      "support": 15
    },
    {
      "x": -2,
      "y": 13,
      "z": 1,
      "name": "Plant_Large_Lilypad",
      "rotation": 3
    },
    {
      "x": -2,
      "y": 14,
      "z": 1,
      "name": "Empty"
    },
    {
      "x": -2,
      "y": 13,
      "z": 2,
      "name": "Plant_Large_Lilypad",
      "rotation": 3
    },
    {
      "x": -2,
      "y": 14,
      "z": 2,
      "name": "Plant_Large_Lilypad_Half"
    },
    {
      "x": -2,
      "y": 9,
      "z": 3,
      "name": "Wood_Banyan_Branch_Long",
      "support": 15,
      "rotation": 5
    },
    {
      "x": -1,
      "y": 13,
      "z": -3,
      "name": "Plant_Large_Lilypad",
      "rotation": 3
    },
    {
      "x": -1,
      "y": 14,
      "z": -3,
      "name": "Plant_Large_Lilypad_Half"
    },
    {
      "x": -1,
      "y": 7,
      "z": -2,
      "name": "Wood_Banyan_Branch_Long",
      "support": 15,
      "rotation": 5
    },
    {
      "x": -1,
      "y": 13,
      "z": -2,
      "name": "Plant_Large_Lilypad",
      "rotation": 3
    },
    {
      "x": -1,
      "y": 14,
      "z": -2,
      "name": "Plant_Grass_Sharp_Wild",
      "support": 15
    },
    {
      "x": -1,
      "y": 15,
      "z": -2,
      "name": "Plant_Grass_Sharp_Wild",
      "filler": 1024
    },
    {
      "x": -1,
      "y": 13,
      "z": -1,
      "name": "Plant_Large_Lilypad",
      "rotation": 3
    },
    {
      "x": -1,
      "y": 14,
      "z": -1,
      "name": "Plant_Grass_Sharp_Tall",
      "support": 15
    },
    {
      "x": -1,
      "y": 15,
      "z": -1,
      "name": "Plant_Grass_Sharp_Tall",
      "filler": 1024
    },
    {
      "x": -1,
      "y": 0,
      "z": 0,
      "name": "Wood_Banyan_Branch_Corner",
      "support": 15,
      "rotation": 2
    },
    {
      "x": -1,
      "y": 1,
      "z": 0,
      "name": "Wood_Banyan_Branch_Long",
      "support": 15
    },
    {
      "x": -1,
      "y": 2,
      "z": 0,
      "name": "Wood_Banyan_Branch_Corner",
      "support": 15,
      "rotation": 11
    },
    {
      "x": -1,
      "y": 3,
      "z": 0,
      "name": "Wood_Banyan_Roots"
    },
    {
      "x": -1,
      "y": 4,
      "z": 0,
      "name": "Wood_Banyan_Trunk",
      "support": 15,
      "rotation": 5
    },
    {
      "x": -1,
      "y": 7,
      "z": 0,
      "name": "Wood_Banyan_Branch_Corner",
      "support": 15,
      "rotation": 3
    },
    {
      "x": -1,
      "y": 8,
      "z": 0,
      "name": "Wood_Banyan_Branch_Corner",
      "support": 15,
      "rotation": 8
    },
    {
      "x": -1,
      "y": 12,
      "z": 0,
      "name": "Wood_Banyan_Roots"
    },
    {
      "x": -1,
      "y": 13,
      "z": 0,
      "name": "Plant_Large_Lilypad",
      "rotation": 3
    },
    {
      "x": -1,
      "y": 14,
      "z": 0,
      "name": "Empty"
    },
    {
      "x": -1,
      "y": -1,
      "z": 1,
      "name": "Wood_Banyan_Branch_Long",
      "support": 15
    },
    {
      "x": -1,
      "y": 0,
      "z": 1,
      "name": "Wood_Banyan_Branch_Corner",
      "support": 15,
      "rotation": 10
    },
    {
      "x": -1,
      "y": 8,
      "z": 1,
      "name": "Wood_Banyan_Branch_Long",
      "support": 15,
      "rotation": 4
    },
    {
      "x": -1,
      "y": 13,
      "z": 1,
      "name": "Plant_Large_Lilypad",
      "rotation": 3
    },
    {
      "x": -1,
      "y": 14,
      "z": 1,
      "name": "Empty"
    },
    {
      "x": -1,
      "y": 8,
      "z": 2,
      "name": "Wood_Banyan_Branch_Long",
      "support": 15,
      "rotation": 4
    },
    {
      "x": -1,
      "y": 13,
      "z": 2,
      "name": "Plant_Large_Lilypad",
      "rotation": 3
    },
    {
      "x": -1,
      "y": 14,
      "z": 2,
      "name": "Empty"
    },
    {
      "x": -1,
      "y": 8,
      "z": 3,
      "name": "Wood_Banyan_Branch_Corner",
      "support": 15
    },
    {
      "x": -1,
      "y": 9,
      "z": 3,
      "name": "Wood_Banyan_Branch_Corner",
      "support": 15,
      "rotation": 11
    },
    {
      "x": -1,
      "y": 13,
      "z": 3,
      "name": "Plant_Large_Lilypad",
      "rotation": 3
    },
    {
      "x": -1,
      "y": 14,
      "z": 3,
      "name": "Plant_Large_Lilypad_Half"
    },
    {
      "x": 0,
      "y": 13,
      "z": -3,
      "name": "Plant_Large_Lilypad",
      "rotation": 3
    },
    {
      "x": 0,
      "y": 14,
      "z": -3,
      "name": "Plant_Large_Lilypad_Half"
    },
    {
      "x": 0,
      "y": 7,
      "z": -2,
      "name": "Wood_Banyan_Trunk_Full",
      "support": 15,
      "rotation": 5
    },
    {
      "x": 0,
      "y": 13,
      "z": -2,
      "name": "Plant_Large_Lilypad",
      "rotation": 3
    },
    {
      "x": 0,
      "y": 14,
      "z": -2,
      "name": "Plant_Grass_Sharp_Short",
      "support": 15
    },
    {
      "x": 0,
      "y": 7,
      "z": -1,
      "name": "Wood_Banyan_Trunk",
      "support": 15,
      "rotation": 4
    },
    {
      "x": 0,
      "y": 13,
      "z": -1,
      "name": "Plant_Large_Lilypad",
      "rotation": 3
    },
    {
      "x": 0,
      "y": 14,
      "z": -1,
      "name": "Plant_Grass_Sharp_Short",
      "support": 15
    },
    {
      "x": 0,
      "y": 4,
      "z": 0,
      "name": "Wood_Banyan_Trunk_Full",
      "support": 15
    },
    {
      "x": 0,
      "y": 5,
      "z": 0,
      "name": "Wood_Banyan_Trunk",
      "support": 15
    },
    {
      "x": 0,
      "y": 6,
      "z": 0,
      "name": "Wood_Banyan_Trunk_Full",
      "support": 15
    },
    {
      "x": 0,
      "y": 7,
      "z": 0,
      "name": "Wood_Banyan_Trunk",
      "support": 15
    },
    {
      "x": 0,
      "y": 8,
      "z": 0,
      "name": "Wood_Banyan_Trunk",
      "support": 15
    },
    {
      "x": 0,
      "y": 9,
      "z": 0,
      "name": "Wood_Banyan_Trunk",
      "support": 15
    },
    {
      "x": 0,
      "y": 10,
      "z": 0,
      "name": "Wood_Banyan_Trunk",
      "support": 15
    },
    {
      "x": 0,
      "y": 11,
      "z": 0,
      "name": "Wood_Banyan_Trunk",
      "support": 15
    },
    {
      "x": 0,
      "y": 12,
      "z": 0,
      "name": "Wood_Banyan_Trunk",
      "support": 15
    },
    {
      "x": 0,
      "y": 13,
      "z": 0,
      "name": "Plant_Large_Lilypad",
      "rotation": 3
    },
    {
      "x": 0,
      "y": 14,
      "z": 0,
      "name": "Empty"
    },
    {
      "x": 0,
      "y": 12,
      "z": 1,
      "name": "Wood_Banyan_Roots"
    },
    {
      "x": 0,
      "y": 13,
      "z": 1,
      "name": "Plant_Large_Lilypad",
      "rotation": 3
    },
    {
      "x": 0,
      "y": 14,
      "z": 1,
      "name": "Empty"
    },
    {
      "x": 0,
      "y": 13,
      "z": 2,
      "name": "Plant_Large_Lilypad",
      "rotation": 3
    },
    {
      "x": 0,
      "y": 14,
      "z": 2,
      "name": "Empty"
    },
    {
      "x": 0,
      "y": 13,
      "z": 3,
      "name": "Plant_Large_Lilypad",
      "rotation": 3
    },
    {
      "x": 0,
      "y": 14,
      "z": 3,
      "name": "Plant_Large_Lilypad_Half"
    },
    {
      "x": 1,
      "y": 8,
      "z": -3,
      "name": "Wood_Banyan_Trunk_Full",
      "support": 15,
      "rotation": 5
    },
    {
      "x": 1,
      "y": 13,
      "z": -3,
      "name": "Plant_Large_Lilypad",
      "rotation": 3
    },
    {
      "x": 1,
      "y": 14,
      "z": -3,
      "name": "Plant_Large_Lilypad_Half"
    },
    {
      "x": 1,
      "y": 6,
      "z": -2,
      "name": "Wood_Banyan_Roots"
    },
    {
      "x": 1,
      "y": 7,
      "z": -2,
      "name": "Wood_Banyan_Trunk_Full",
      "support": 15
    },
    {
      "x": 1,
      "y": 8,
      "z": -2,
      "name": "Wood_Banyan_Trunk_Full",
      "support": 15
    },
    {
      "x": 1,
      "y": 13,
      "z": -2,
      "name": "Plant_Large_Lilypad",
      "rotation": 3
    },
    {
      "x": 1,
      "y": 14,
      "z": -2,
      "name": "Empty"
    },
    {
      "x": 1,
      "y": 12,
      "z": -1,
      "name": "Wood_Banyan_Roots"
    },
    {
      "x": 1,
      "y": 13,
      "z": -1,
      "name": "Plant_Large_Lilypad",
      "rotation": 3
    },
    {
      "x": 1,
      "y": 14,
      "z": -1,
      "name": "Empty"
    },
    {
      "x": 1,
      "y": 6,
      "z": 0,
      "name": "Wood_Banyan_Trunk",
      "support": 15,
      "rotation": 5
    },
    {
      "x": 1,
      "y": 13,
      "z": 0,
      "name": "Plant_Large_Lilypad",
      "rotation": 3
    },
    {
      "x": 1,
      "y": 14,
      "z": 0,
      "name": "Empty"
    },
    {
      "x": 1,
      "y": 6,
      "z": 1,
      "name": "Wood_Banyan_Trunk",
      "support": 15,
      "rotation": 4
    },
    {
      "x": 1,
      "y": 13,
      "z": 1,
      "name": "Plant_Large_Lilypad",
      "rotation": 3
    },
    {
      "x": 1,
      "y": 14,
      "z": 1,
      "name": "Empty"
    },
    {
      "x": 1,
      "y": 5,
      "z": 2,
      "name": "Wood_Banyan_Roots"
    },
    {
      "x": 1,
      "y": 6,
      "z": 2,
      "name": "Wood_Banyan_Trunk",
      "support": 15,
      "rotation": 4
    },
    {
      "x": 1,
      "y": 13,
      "z": 2,
      "name": "Plant_Large_Lilypad",
      "rotation": 3
    },
    {
      "x": 1,
      "y": 14,
      "z": 2,
      "name": "Plant_Grass_Sharp_Short",
      "support": 15
    },
    {
      "x": 1,
      "y": 6,
      "z": 3,
      "name": "Wood_Banyan_Trunk",
      "support": 15,
      "rotation": 4
    },
    {
      "x": 1,
      "y": 13,
      "z": 3,
      "name": "Plant_Large_Lilypad",
      "rotation": 3
    },
    {
      "x": 1,
      "y": 14,
      "z": 3,
      "name": "Plant_Large_Lilypad_Half"
    },
    {
      "x": 1,
      "y": 5,
      "z": 4,
      "name": "Wood_Banyan_Trunk_Full",
      "support": 15
    },
    {
      "x": 1,
      "y": 6,
      "z": 4,
      "name": "Wood_Banyan_Trunk_Full",
      "support": 15
    },
    {
      "x": 1,
      "y": -1,
      "z": 5,
      "name": "Wood_Banyan_Trunk",
      "support": 15
    },
    {
      "x": 1,
      "y": 0,
      "z": 5,
      "name": "Wood_Banyan_Trunk",
      "support": 15
    },
    {
      "x": 1,
      "y": 1,
      "z": 5,
      "name": "Wood_Banyan_Trunk",
      "support": 15
    },
    {
      "x": 1,
      "y": 2,
      "z": 5,
      "name": "Wood_Banyan_Trunk",
      "support": 15
    },
    {
      "x": 1,
      "y": 3,
      "z": 5,
      "name": "Wood_Banyan_Trunk",
      "support": 15
    },
    {
      "x": 1,
      "y": 4,
      "z": 5,
      "name": "Wood_Banyan_Trunk",
      "support": 15
    },
    {
      "x": 1,
      "y": 5,
      "z": 5,
      "name": "Wood_Banyan_Trunk_Full",
      "support": 15
    },
    {
      "x": 2,
      "y": 8,
      "z": -3,
      "name": "Wood_Banyan_Trunk",
      "support": 15,
      "rotation": 5
    },
    {
      "x": 2,
      "y": 13,
      "z": -2,
      "name": "Plant_Large_Lilypad",
      "rotation": 3
    },
    {
      "x": 2,
      "y": 14,
      "z": -2,
      "name": "Plant_Large_Lilypad_Half"
    },
    {
      "x": 2,
      "y": 13,
      "z": -1,
      "name": "Plant_Large_Lilypad",
      "rotation": 3
    },
    {
      "x": 2,
      "y": 14,
      "z": -1,
      "name": "Empty"
    },
    {
      "x": 2,
      "y": 4,
      "z": 0,
      "name": "Wood_Banyan_Roots"
    },
    {
      "x": 2,
      "y": 5,
      "z": 0,
      "name": "Wood_Banyan_Trunk_Full",
      "support": 15
    },
    {
      "x": 2,
      "y": 6,
      "z": 0,
      "name": "Wood_Banyan_Trunk_Full",
      "support": 15
    },
    {
      "x": 2,
      "y": 13,
      "z": 0,
      "name": "Plant_Large_Lilypad",
      "rotation": 3
    },
    {
      "x": 2,
      "y": 14,
      "z": 0,
      "name": "Plant_Grass_Sharp_Short",
      "support": 15
    },
    {
      "x": 2,
      "y": 13,
      "z": 1,
      "name": "Plant_Large_Lilypad",
      "rotation": 3
    },
    {
      "x": 2,
      "y": 14,
      "z": 1,
      "name": "Plant_Grass_Sharp_Tall",
      "support": 15
    },
    {
      "x": 2,
      "y": 15,
      "z": 1,
      "name": "Plant_Grass_Sharp_Tall",
      "filler": 1024
    },
    {
      "x": 2,
      "y": -1,
      "z": 2,
      "name": "Wood_Banyan_Branch_Long",
      "support": 15
    },
    {
      "x": 2,
      "y": 0,
      "z": 2,
      "name": "Wood_Banyan_Branch_Long",
      "support": 15
    },
    {
      "x": 2,
      "y": 1,
      "z": 2,
      "name": "Wood_Banyan_Branch_Corner",
      "support": 15,
      "rotation": 9
    },
    {
      "x": 2,
      "y": 13,
      "z": 2,
      "name": "Plant_Large_Lilypad",
      "rotation": 3
    },
    {
      "x": 2,
      "y": 14,
      "z": 2,
      "name": "Plant_Large_Lilypad_Half"
    },
    {
      "x": 2,
      "y": 6,
      "z": 4,
      "name": "Wood_Banyan_Branch_Long",
      "support": 15,
      "rotation": 5
    },
    {
      "x": 2,
      "y": 2,
      "z": 5,
      "name": "Wood_Banyan_Branch_Long",
      "support": 15,
      "rotation": 5
    },
    {
      "x": 3,
      "y": 12,
      "z": -5,
      "name": "Plant_Large_Lilypad"
    },
    {
      "x": 3,
      "y": 13,
      "z": -5,
      "name": "Plant_Grass_Wet_Overgrown",
      "support": 15
    },
    {
      "x": 3,
      "y": 14,
      "z": -5,
      "name": "Plant_Grass_Wet_Overgrown",
      "filler": 1024
    },
    {
      "x": 3,
      "y": 8,
      "z": -4,
      "name": "Wood_Banyan_Trunk_Full",
      "support": 15,
      "rotation": 5
    },
    {
      "x": 3,
      "y": 12,
      "z": -4,
      "name": "Plant_Large_Lilypad"
    },
    {
      "x": 3,
      "y": 13,
      "z": -4,
      "name": "Plant_Reeds_Marsh",
      "support": 15
    },
    {
      "x": 3,
      "y": -1,
      "z": -3,
      "name": "Wood_Banyan_Branch_Long",
      "support": 15
    },
    {
      "x": 3,
      "y": 0,
      "z": -3,
      "name": "Wood_Banyan_Branch_Long",
      "support": 15
    },
    {
      "x": 3,
      "y": 1,
      "z": -3,
      "name": "Wood_Banyan_Branch_Long",
      "support": 15
    },
    {
      "x": 3,
      "y": 2,
      "z": -3,
      "name": "Wood_Banyan_Branch_Corner",
      "support": 15,
      "rotation": 8
    },
    {
      "x": 3,
      "y": 8,
      "z": -3,
      "name": "Wood_Banyan_Trunk_Full",
      "support": 15,
      "rotation": 4
    },
    {
      "x": 3,
      "y": 2,
      "z": -2,
      "name": "Wood_Banyan_Branch_Long",
      "support": 15,
      "rotation": 4
    },
    {
      "x": 3,
      "y": -1,
      "z": -1,
      "name": "Wood_Banyan_Trunk",
      "support": 15
    },
    {
      "x": 3,
      "y": 0,
      "z": -1,
      "name": "Wood_Banyan_Trunk",
      "support": 15
    },
    {
      "x": 3,
      "y": 1,
      "z": -1,
      "name": "Wood_Banyan_Trunk_Full",
      "support": 15
    },
    {
      "x": 3,
      "y": 2,
      "z": -1,
      "name": "Wood_Banyan_Trunk",
      "support": 15
    },
    {
      "x": 3,
      "y": 3,
      "z": -1,
      "name": "Wood_Banyan_Trunk",
      "support": 15
    },
    {
      "x": 3,
      "y": 4,
      "z": -1,
      "name": "Wood_Banyan_Trunk_Full",
      "support": 15
    },
    {
      "x": 3,
      "y": 13,
      "z": -1,
      "name": "Plant_Large_Lilypad",
      "rotation": 3
    },
    {
      "x": 3,
      "y": 14,
      "z": -1,
      "name": "Plant_Large_Lilypad_Half"
    },
    {
      "x": 3,
      "y": 1,
      "z": 0,
      "name": "Wood_Banyan_Trunk",
      "support": 15,
      "rotation": 4
    },
    {
      "x": 3,
      "y": 4,
      "z": 0,
      "name": "Wood_Banyan_Trunk",
      "support": 15
    },
    {
      "x": 3,
      "y": 5,
      "z": 0,
      "name": "Wood_Banyan_Trunk_Full",
      "support": 15
    },
    {
      "x": 3,
      "y": 13,
      "z": 0,
      "name": "Plant_Large_Lilypad",
      "rotation": 3
    },
    {
      "x": 3,
      "y": 14,
      "z": 0,
      "name": "Plant_Large_Lilypad_Half"
    },
    {
      "x": 3,
      "y": 1,
      "z": 1,
      "name": "Wood_Banyan_Trunk",
      "support": 15,
      "rotation": 4
    },
    {
      "x": 3,
      "y": 13,
      "z": 1,
      "name": "Plant_Large_Lilypad",
      "rotation": 3
    },
    {
      "x": 3,
      "y": 14,
      "z": 1,
      "name": "Plant_Large_Lilypad_Half"
    },
    {
      "x": 3,
      "y": -1,
      "z": 2,
      "name": "Wood_Banyan_Trunk",
      "support": 15
    },
    {
      "x": 3,
      "y": 0,
      "z": 2,
      "name": "Wood_Banyan_Trunk",
      "support": 15
    },
    {
      "x": 3,
      "y": 1,
      "z": 2,
      "name": "Wood_Banyan_Trunk_Full",
      "support": 15
    },
    {
      "x": 3,
      "y": 12,
      "z": 3,
      "name": "Plant_Large_Lilypad"
    },
    {
      "x": 3,
      "y": 6,
      "z": 4,
      "name": "Wood_Banyan_Branch_Long",
      "support": 15,
      "rotation": 5
    },
    {
      "x": 3,
      "y": 11,
      "z": 4,
      "name": "Wood_Banyan_Roots"
    },
    {
      "x": 3,
      "y": 12,
      "z": 4,
      "name": "Plant_Large_Lilypad"
    },
    {
      "x": 3,
      "y": -1,
      "z": 5,
      "name": "Wood_Banyan_Branch_Long",
      "support": 15
    },
    {
      "x": 3,
      "y": 0,
      "z": 5,
      "name": "Wood_Banyan_Branch_Long",
      "support": 15
    },
    {
      "x": 3,
      "y": 1,
      "z": 5,
      "name": "Wood_Banyan_Branch_Long",
      "support": 15
    },
    {
      "x": 3,
      "y": 2,
      "z": 5,
      "name": "Wood_Banyan_Branch_Corner",
      "support": 15,
      "rotation": 11
    },
    {
      "x": 3,
      "y": 12,
      "z": 5,
      "name": "Plant_Large_Lilypad"
    },
    {
      "x": 3,
      "y": 13,
      "z": 5,
      "name": "Plant_Reeds_Marsh",
      "support": 15
    },
    {
      "x": 4,
      "y": 12,
      "z": -6,
      "name": "Plant_Large_Lilypad"
    },
    {
      "x": 4,
      "y": 11,
      "z": -5,
      "name": "Wood_Banyan_Roots"
    },
    {
      "x": 4,
      "y": 12,
      "z": -5,
      "name": "Plant_Large_Lilypad"
    },
    {
      "x": 4,
      "y": 13,
      "z": -5,
      "name": "Plant_Reeds_Arid",
      "support": 15
    },
    {
      "x": 4,
      "y": 14,
      "z": -5,
      "name": "Plant_Reeds_Arid",
      "filler": 1024
    },
    {
      "x": 4,
      "y": 7,
      "z": -4,
      "name": "Wood_Banyan_Roots"
    },
    {
      "x": 4,
      "y": 8,
      "z": -4,
      "name": "Wood_Banyan_Trunk_Full",
      "support": 15
    },
    {
      "x": 4,
      "y": 9,
      "z": -4,
      "name": "Wood_Banyan_Trunk",
      "support": 15
    },
    {
      "x": 4,
      "y": 10,
      "z": -4,
      "name": "Wood_Banyan_Trunk",
      "support": 15
    },
    {
      "x": 4,
      "y": 11,
      "z": -4,
      "name": "Wood_Banyan_Trunk",
      "support": 15
    },
    {
      "x": 4,
      "y": 12,
      "z": -4,
      "name": "Plant_Large_Lilypad"
    },
    {
      "x": 4,
      "y": 13,
      "z": -4,
      "name": "Plant_Reeds_Arid",
      "support": 15
    },
    {
      "x": 4,
      "y": 14,
      "z": -4,
      "name": "Plant_Reeds_Arid",
      "filler": 1024
    },
    {
      "x": 4,
      "y": 12,
      "z": -3,
      "name": "Plant_Large_Lilypad"
    },
    {
      "x": 4,
      "y": 13,
      "z": -3,
      "name": "Plant_Reeds_Marsh",
      "support": 15
    },
    {
      "x": 4,
      "y": 3,
      "z": -1,
      "name": "Wood_Banyan_Branch_Long",
      "support": 15,
      "rotation": 5
    },
    {
      "x": 4,
      "y": 5,
      "z": 0,
      "name": "Wood_Banyan_Branch_Long",
      "support": 15,
      "rotation": 5
    },
    {
      "x": 4,
      "y": 11,
      "z": 3,
      "name": "Wood_Banyan_Roots"
    },
    {
      "x": 4,
      "y": 12,
      "z": 3,
      "name": "Plant_Large_Lilypad"
    },
    {
      "x": 4,
      "y": 13,
      "z": 3,
      "name": "Plant_Reeds_Arid",
      "support": 15
    },
    {
      "x": 4,
      "y": 14,
      "z": 3,
      "name": "Plant_Reeds_Arid",
      "filler": 1024
    },
    {
      "x": 4,
      "y": 6,
      "z": 4,
      "name": "Wood_Banyan_Branch_Corner",
      "support": 15,
      "rotation": 1
    },
    {
      "x": 4,
      "y": 7,
      "z": 4,
      "name": "Wood_Banyan_Branch_Long",
      "support": 15
    },
    {
      "x": 4,
      "y": 8,
      "z": 4,
      "name": "Wood_Banyan_Branch_Long",
      "support": 15
    },
    {
      "x": 4,
      "y": 9,
      "z": 4,
      "name": "Wood_Banyan_Branch_Long",
      "support": 15
    },
    {
      "x": 4,
      "y": 10,
      "z": 4,
      "name": "Wood_Banyan_Branch_Long",
      "support": 15
    },
    {
      "x": 4,
      "y": 11,
      "z": 4,
      "name": "Wood_Banyan_Branch_Long",
      "support": 15
    },
    {
      "x": 4,
      "y": 12,
      "z": 4,
      "name": "Plant_Large_Lilypad"
    },
    {
      "x": 4,
      "y": 13,
      "z": 4,
      "name": "Plant_Grass_Wet_Overgrown",
      "support": 15
    },
    {
      "x": 4,
      "y": 14,
      "z": 4,
      "name": "Plant_Grass_Wet_Overgrown",
      "filler": 1024
    },
    {
      "x": 4,
      "y": 12,
      "z": 5,
      "name": "Plant_Large_Lilypad"
    },
    {
      "x": 5,
      "y": 12,
      "z": -6,
      "name": "Plant_Large_Lilypad"
    },
    {
      "x": 5,
      "y": 13,
      "z": -6,
      "name": "Plant_Grass_Wet_Overgrown",
      "support": 15
    },
    {
      "x": 5,
      "y": 14,
      "z": -6,
      "name": "Plant_Grass_Wet_Overgrown",
      "filler": 1024
    },
    {
      "x": 5,
      "y": 12,
      "z": -5,
      "name": "Plant_Large_Lilypad"
    },
    {
      "x": 5,
      "y": 11,
      "z": -4,
      "name": "Wood_Banyan_Roots"
    },
    {
      "x": 5,
      "y": 12,
      "z": -4,
      "name": "Plant_Large_Lilypad"
    },
    {
      "x": 5,
      "y": 13,
      "z": -4,
      "name": "Plant_Grass_Wet_Overgrown",
      "support": 15
    },
    {
      "x": 5,
      "y": 14,
      "z": -4,
      "name": "Plant_Grass_Wet_Overgrown",
      "filler": 1024
    },
    {
      "x": 5,
      "y": 12,
      "z": -3,
      "name": "Plant_Large_Lilypad"
    },
    {
      "x": 5,
      "y": 2,
      "z": -1,
      "name": "Wood_Banyan_Branch_Corner",
      "support": 15,
      "rotation": 3
    },
    {
      "x": 5,
      "y": 3,
      "z": -1,
      "name": "Wood_Banyan_Branch_Corner",
      "support": 15,
      "rotation": 11
    },
    {
      "x": 5,
      "y": 7,
      "z": -1,
      "name": "Plant_Large_Lilypad_Half"
    },
    {
      "x": 5,
      "y": 5,
      "z": 0,
      "name": "Wood_Banyan_Branch_Long",
      "support": 15,
      "rotation": 5
    },
    {
      "x": 5,
      "y": 7,
      "z": 0,
      "name": "Plant_Large_Lilypad_Half"
    },
    {
      "x": 5,
      "y": 7,
      "z": 1,
      "name": "Plant_Large_Lilypad_Half"
    },
    {
      "x": 5,
      "y": 12,
      "z": 3,
      "name": "Plant_Large_Lilypad"
    },
    {
      "x": 5,
      "y": 13,
      "z": 3,
      "name": "Plant_Reeds_Marsh",
      "support": 15
    },
    {
      "x": 5,
      "y": 12,
      "z": 4,
      "name": "Plant_Large_Lilypad"
    },
    {
      "x": 5,
      "y": 13,
      "z": 4,
      "name": "Plant_Reeds_Arid",
      "support": 15
    },
    {
      "x": 5,
      "y": 14,
      "z": 4,
      "name": "Plant_Reeds_Arid",
      "filler": 1024
    },
    {
      "x": 5,
      "y": 12,
      "z": 5,
      "name": "Plant_Large_Lilypad"
    },
    {
      "x": 5,
      "y": 13,
      "z": 5,
      "name": "Plant_Grass_Wet_Overgrown",
      "support": 15
    },
    {
      "x": 5,
      "y": 14,
      "z": 5,
      "name": "Plant_Grass_Wet_Overgrown",
      "filler": 1024
    },
    {
      "x": 6,
      "y": 12,
      "z": -5,
      "name": "Plant_Large_Lilypad"
    },
    {
      "x": 6,
      "y": 13,
      "z": -5,
      "name": "Plant_Reeds_Marsh",
      "support": 15
    },
    {
      "x": 6,
      "y": 12,
      "z": -4,
      "name": "Plant_Large_Lilypad"
    },
    {
      "x": 6,
      "y": 13,
      "z": -4,
      "name": "Plant_Reeds_Arid",
      "support": 15
    },
    {
      "x": 6,
      "y": 14,
      "z": -4,
      "name": "Plant_Reeds_Arid",
      "filler": 1024
    },
    {
      "x": 6,
      "y": 2,
      "z": -1,
      "name": "Wood_Banyan_Branch_Long",
      "support": 15,
      "rotation": 5
    },
    {
      "x": 6,
      "y": 7,
      "z": -1,
      "name": "Plant_Large_Lilypad_Half"
    },
    {
      "x": 6,
      "y": 5,
      "z": 0,
      "name": "Wood_Banyan_Branch_Corner",
      "support": 15,
      "rotation": 1
    },
    {
      "x": 6,
      "y": 6,
      "z": 0,
      "name": "Wood_Banyan_Branch_Long",
      "support": 15
    },
    {
      "x": 6,
      "y": 7,
      "z": 0,
      "name": "Plant_Large_Lilypad_Half"
    },
    {
      "x": 6,
      "y": 7,
      "z": 1,
      "name": "Plant_Large_Lilypad_Half"
    },
    {
      "x": 7,
      "y": -1,
      "z": -1,
      "name": "Wood_Banyan_Branch_Long",
      "support": 15
    },
    {
      "x": 7,
      "y": 0,
      "z": -1,
      "name": "Wood_Banyan_Branch_Long",
      "support": 15
    },
    {
      "x": 7,
      "y": 1,
      "z": -1,
      "name": "Wood_Banyan_Branch_Long",
      "support": 15
    },
    {
      "x": 7,
      "y": 2,
      "z": -1,
      "name": "Wood_Banyan_Branch_Corner",
      "support": 15,
      "rotation": 11
    },
    {
      "x": 7,
      "y": 7,
      "z": -1,
      "name": "Plant_Large_Lilypad_Half"
    },
    {
      "x": 7,
      "y": 7,
      "z": 0,
      "name": "Plant_Large_Lilypad_Half"
    },
    {
      "x": 7,
      "y": 7,
      "z": 1,
      "name": "Plant_Large_Lilypad_Half"
    }
  ],
  "fluids": [
    {
      "x": -5,
      "y": 10,
      "z": -3,
      "name": "Water_Source",
      "level": 1
    },
    {
      "x": -5,
      "y": 11,
      "z": -3,
      "name": "Water_Source",
      "level": 1
    },
    {
      "x": -5,
      "y": 12,
      "z": -3,
      "name": "Water_Source",
      "level": 1
    },
    {
      "x": -5,
      "y": 13,
      "z": -3,
      "name": "Water_Source",
      "level": 1
    },
    {
      "x": -5,
      "y": 9,
      "z": -2,
      "name": "Water_Source",
      "level": 1
    },
    {
      "x": -5,
      "y": 10,
      "z": -2,
      "name": "Water_Source",
      "level": 1
    },
    {
      "x": -5,
      "y": 13,
      "z": 3,
      "name": "Water_Source",
      "level": 1
    },
    {
      "x": -5,
      "y": 11,
      "z": 4,
      "name": "Water_Source",
      "level": 1
    },
    {
      "x": -4,
      "y": 7,
      "z": -2,
      "name": "Water_Source",
      "level": 1
    },
    {
      "x": -4,
      "y": 8,
      "z": -2,
      "name": "Water_Source",
      "level": 1
    },
    {
      "x": -4,
      "y": 9,
      "z": -2,
      "name": "Water_Source",
      "level": 1
    },
    {
      "x": -4,
      "y": 9,
      "z": 3,
      "name": "Water_Source",
      "level": 1
    },
    {
      "x": -4,
      "y": 10,
      "z": 3,
      "name": "Water_Source",
      "level": 1
    },
    {
      "x": -4,
      "y": 11,
      "z": 3,
      "name": "Water_Source",
      "level": 1
    },
    {
      "x": -4,
      "y": 13,
      "z": 3,
      "name": "Water_Source",
      "level": 1
    },
    {
      "x": -4,
      "y": 13,
      "z": 4,
      "name": "Water_Source",
      "level": 1
    },
    {
      "x": -3,
      "y": -1,
      "z": -2,
      "name": "Water_Source",
      "level": 1
    },
    {
      "x": -3,
      "y": 0,
      "z": -2,
      "name": "Water_Source",
      "level": 1
    },
    {
      "x": -3,
      "y": 1,
      "z": -2,
      "name": "Water_Source",
      "level": 1
    },
    {
      "x": -3,
      "y": 7,
      "z": -2,
      "name": "Water_Source",
      "level": 1
    },
    {
      "x": -3,
      "y": 1,
      "z": -1,
      "name": "Water_Source",
      "level": 1
    },
    {
      "x": -3,
      "y": 9,
      "z": 3,
      "name": "Water_Source",
      "level": 1
    },
    {
      "x": -2,
      "y": 7,
      "z": -2,
      "name": "Water_Source",
      "level": 1
    },
    {
      "x": -2,
      "y": 2,
      "z": 0,
      "name": "Water_Source",
      "level": 1
    },
    {
      "x": -2,
      "y": 9,
      "z": 3,
      "name": "Water_Source",
      "level": 1
    },
    {
      "x": -1,
      "y": 7,
      "z": -2,
      "name": "Water_Source",
      "level": 1
    },
    {
      "x": -1,
      "y": 0,
      "z": 0,
      "name": "Water_Source",
      "level": 1
    },
    {
      "x": -1,
      "y": 1,
      "z": 0,
      "name": "Water_Source",
      "level": 1
    },
    {
      "x": -1,
      "y": 2,
      "z": 0,
      "name": "Water_Source",
      "level": 1
    },
    {
      "x": -1,
      "y": 3,
      "z": 0,
      "name": "Water_Source",
      "level": 1
    },
    {
      "x": -1,
      "y": 7,
      "z": 0,
      "name": "Water_Source",
      "level": 1
    },
    {
      "x": -1,
      "y": 8,
      "z": 0,
      "name": "Water_Source",
      "level": 1
    },
    {
      "x": -1,
      "y": 12,
      "z": 0,
      "name": "Water_Source",
      "level": 1
    },
    {
      "x": -1,
      "y": -1,
      "z": 1,
      "name": "Water_Source",
      "level": 1
    },
    {
      "x": -1,
      "y": 0,
      "z": 1,
      "name": "Water_Source",
      "level": 1
    },
    {
      "x": -1,
      "y": 8,
      "z": 1,
      "name": "Water_Source",
      "level": 1
    },
    {
      "x": -1,
      "y": 8,
      "z": 2,
      "name": "Water_Source",
      "level": 1
    },
    {
      "x": -1,
      "y": 8,
      "z": 3,
      "name": "Water_Source",
      "level": 1
    },
    {
      "x": -1,
      "y": 9,
      "z": 3,
      "name": "Water_Source",
      "level": 1
    },
    {
      "x": 0,
      "y": 7,
      "z": 0,
      "name": "Water_Source",
      "level": 1
    },
    {
      "x": 1,
      "y": 6,
      "z": -2,
      "name": "Water_Source",
      "level": 1
    },
    {
      "x": 1,
      "y": 12,
      "z": -1,
      "name": "Water_Source",
      "level": 1
    },
    {
      "x": 1,
      "y": 5,
      "z": 2,
      "name": "Water_Source",
      "level": 1
    },
    {
      "x": 2,
      "y": 4,
      "z": 0,
      "name": "Water_Source",
      "level": 1
    },
    {
      "x": 2,
      "y": -1,
      "z": 2,
      "name": "Water_Source",
      "level": 1
    },
    {
      "x": 2,
      "y": 0,
      "z": 2,
      "name": "Water_Source",
      "level": 1
    },
    {
      "x": 2,
      "y": 1,
      "z": 2,
      "name": "Water_Source",
      "level": 1
    },
    {
      "x": 2,
      "y": 6,
      "z": 4,
      "name": "Water_Source",
      "level": 1
    },
    {
      "x": 2,
      "y": 2,
      "z": 5,
      "name": "Water_Source",
      "level": 1
    },
    {
      "x": 3,
      "y": 13,
      "z": -5,
      "name": "Water_Source",
      "level": 1
    },
    {
      "x": 3,
      "y": 13,
      "z": -4,
      "name": "Water_Source",
      "level": 1
    },
    {
      "x": 3,
      "y": -1,
      "z": -3,
      "name": "Water_Source",
      "level": 1
    },
    {
      "x": 3,
      "y": 0,
      "z": -3,
      "name": "Water_Source",
      "level": 1
    },
    {
      "x": 3,
      "y": 1,
      "z": -3,
      "name": "Water_Source",
      "level": 1
    },
    {
      "x": 3,
      "y": 2,
      "z": -3,
      "name": "Water_Source",
      "level": 1
    },
    {
      "x": 3,
      "y": 2,
      "z": -2,
      "name": "Water_Source",
      "level": 1
    },
    {
      "x": 3,
      "y": 6,
      "z": 4,
      "name": "Water_Source",
      "level": 1
    },
    {
      "x": 3,
      "y": 11,
      "z": 4,
      "name": "Water_Source",
      "level": 1
    },
    {
      "x": 3,
      "y": -1,
      "z": 5,
      "name": "Water_Source",
      "level": 1
    },
    {
      "x": 3,
      "y": 0,
      "z": 5,
      "name": "Water_Source",
      "level": 1
    },
    {
      "x": 3,
      "y": 1,
      "z": 5,
      "name": "Water_Source",
      "level": 1
    },
    {
      "x": 3,
      "y": 2,
      "z": 5,
      "name": "Water_Source",
      "level": 1
    },
    {
      "x": 3,
      "y": 13,
      "z": 5,
      "name": "Water_Source",
      "level": 1
    },
    {
      "x": 4,
      "y": 11,
      "z": -5,
      "name": "Water_Source",
      "level": 1
    },
    {
      "x": 4,
      "y": 13,
      "z": -5,
      "name": "Water_Source",
      "level": 1
    },
    {
      "x": 4,
      "y": 7,
      "z": -4,
      "name": "Water_Source",
      "level": 1
    },
    {
      "x": 4,
      "y": 13,
      "z": -4,
      "name": "Water_Source",
      "level": 1
    },
    {
      "x": 4,
      "y": 13,
      "z": -3,
      "name": "Water_Source",
      "level": 1
    },
    {
      "x": 4,
      "y": 3,
      "z": -1,
      "name": "Water_Source",
      "level": 1
    },
    {
      "x": 4,
      "y": 5,
      "z": 0,
      "name": "Water_Source",
      "level": 1
    },
    {
      "x": 4,
      "y": 11,
      "z": 3,
      "name": "Water_Source",
      "level": 1
    },
    {
      "x": 4,
      "y": 13,
      "z": 3,
      "name": "Water_Source",
      "level": 1
    },
    {
      "x": 4,
      "y": 6,
      "z": 4,
      "name": "Water_Source",
      "level": 1
    },
    {
      "x": 4,
      "y": 7,
      "z": 4,
      "name": "Water_Source",
      "level": 1
    },
    {
      "x": 4,
      "y": 8,
      "z": 4,
      "name": "Water_Source",
      "level": 1
    },
    {
      "x": 4,
      "y": 9,
      "z": 4,
      "name": "Water_Source",
      "level": 1
    },
    {
      "x": 4,
      "y": 10,
      "z": 4,
      "name": "Water_Source",
      "level": 1
    },
    {
      "x": 4,
      "y": 11,
      "z": 4,
      "name": "Water_Source",
      "level": 1
    },
    {
      "x": 4,
      "y": 13,
      "z": 4,
      "name": "Water_Source",
      "level": 1
    },
    {
      "x": 5,
      "y": 13,
      "z": -6,
      "name": "Water_Source",
      "level": 1
    },
    {
      "x": 5,
      "y": 11,
      "z": -4,
      "name": "Water_Source",
      "level": 1
    },
    {
      "x": 5,
      "y": 13,
      "z": -4,
      "name": "Water_Source",
      "level": 1
    },
    {
      "x": 5,
      "y": 2,
      "z": -1,
      "name": "Water_Source",
      "level": 1
    },
    {
      "x": 5,
      "y": 3,
      "z": -1,
      "name": "Water_Source",
      "level": 1
    },
    {
      "x": 5,
      "y": 7,
      "z": -1,
      "name": "Water_Source",
      "level": 1
    },
    {
      "x": 5,
      "y": 5,
      "z": 0,
      "name": "Water_Source",
      "level": 1
    },
    {
      "x": 5,
      "y": 7,
      "z": 0,
      "name": "Water_Source",
      "level": 1
    },
    {
      "x": 5,
      "y": 7,
      "z": 1,
      "name": "Water_Source",
      "level": 1
    },
    {
      "x": 5,
      "y": 13,
      "z": 3,
      "name": "Water_Source",
      "level": 1
    },
    {
      "x": 5,
      "y": 13,
      "z": 4,
      "name": "Water_Source",
      "level": 1
    },
    {
      "x": 5,
      "y": 13,
      "z": 5,
      "name": "Water_Source",
      "level": 1
    },
    {
      "x": 6,
      "y": 13,
      "z": -5,
      "name": "Water_Source",
      "level": 1
    },
    {
      "x": 6,
      "y": 13,
      "z": -4,
      "name": "Water_Source",
      "level": 1
    },
    {
      "x": 6,
      "y": 2,
      "z": -1,
      "name": "Water_Source",
      "level": 1
    },
    {
      "x": 6,
      "y": 7,
      "z": -1,
      "name": "Water_Source",
      "level": 1
    },
    {
      "x": 6,
      "y": 5,
      "z": 0,
      "name": "Water_Source",
      "level": 1
    },
    {
      "x": 6,
      "y": 6,
      "z": 0,
      "name": "Water_Source",
      "level": 1
    },
    {
      "x": 6,
      "y": 7,
      "z": 0,
      "name": "Water_Source",
      "level": 1
    },
    {
      "x": 6,
      "y": 7,
      "z": 1,
      "name": "Water_Source",
      "level": 1
    },
    {
      "x": 7,
      "y": -1,
      "z": -1,
      "name": "Water_Source",
      "level": 1
    },
    {
      "x": 7,
      "y": 0,
      "z": -1,
      "name": "Water_Source",
      "level": 1
    },
    {
      "x": 7,
      "y": 1,
      "z": -1,
      "name": "Water_Source",
      "level": 1
    },
    {
      "x": 7,
      "y": 2,
      "z": -1,
      "name": "Water_Source",
      "level": 1
    },
    {
      "x": 7,
      "y": 7,
      "z": -1,
      "name": "Water_Source",
      "level": 1
    },
    {
      "x": 7,
      "y": 7,
      "z": 0,
      "name": "Water_Source",
      "level": 1
    },
    {
      "x": 7,
      "y": 7,
      "z": 1,
      "name": "Water_Source",
      "level": 1
    }
  ]
}