{
  "version": 8,
  "blockIdVersion": 11,
  "anchorX": 0,
  "anchorY": 10,
  "anchorZ": 0,
  "blocks": [
    {
      "x": -9,
      "y": 8,
      "z": -6,
      "name": "Plant_Large_Lilypad"
    },
    {
      "x": -9,
      "y": 9,
      "z": -6,
      "name": "Plant_Reeds_Arid",
      "support": 15
    },
    {
      "x": -9,
      "y": 10,
      "z": -6,
      "name": "Plant_Reeds_Arid",
      "filler": 1024
    },
    {
      "x": -9,
      "y": 8,
      "z": -5,
      "name": "Plant_Large_Lilypad"
    },
    {
      "x": -9,
      "y": 9,
      "z": -5,
      "name": "Plant_Reeds_Marsh",
      "support": 15
    },
    {
      "x": -8,
      "y": 8,
      "z": -7,
      "name": "Plant_Large_Lilypad"
    },
    {
      "x": -8,
      "y": 8,
      "z": -6,
      "name": "Plant_Large_Lilypad"
    },
    {
      "x": -8,
      "y": 7,
      "z": -5,
      "name": "Wood_Banyan_Roots"
    },
    {
      "x": -8,
      "y": 8,
      "z": -5,
      "name": "Plant_Large_Lilypad"
    },
    {
      "x": -8,
      "y": 8,
      "z": -4,
      "name": "Plant_Large_Lilypad"
    },
    {
      "x": -7,
      "y": 8,
      "z": -7,
      "name": "Plant_Large_Lilypad"
    },
    {
      "x": -7,
      "y": 8,
      "z": -6,
      "name": "Plant_Large_Lilypad"
    },
    {
      "x": -7,
      "y": 6,
      "z": -5,
      "name": "Wood_Banyan_Branch_Corner",
      "support": 15,
      "rotation": 2
    },
    {
      "x": -7,
      "y": 7,
      "z": -5,
      "name": "Wood_Banyan_Branch_Long",
      "support": 15
    },
    {
      "x": -7,
      "y": 8,
      "z": -5,
      "name": "Plant_Large_Lilypad"
    },
    {
      "x": -7,
      "y": 6,
      "z": -4,
      "name": "Wood_Banyan_Branch_Long",
      "support": 15,
      "rotation": 4
    },
    {
      "x": -7,
      "y": 8,
      "z": -4,
      "name": "Plant_Large_Lilypad"
    },
    {
      "x": -7,
      "y": 9,
      "z": -4,
      "name": "Plant_Reeds_Arid",
      "support": 15
    },
    {
      "x": -7,
      "y": 10,
      "z": -4,
      "name": "Plant_Reeds_Arid",
      "filler": 1024
    },
    {
      "x": -7,
      "y": 5,
      "z": -3,
      "name": "Wood_Banyan_Branch_Corner",
      "support": 15,
      "rotation": 3
    },
    {
      "x": -7,
      "y": 6,
      "z": -3,
      "name": "Wood_Banyan_Branch_Corner",
      "support": 15,
      "rotation": 10
    },
    {
      "x": -6,
      "y": 8,
      "z": -6,
      "name": "Plant_Large_Lilypad"
    },
    {
      "x": -6,
      "y": 8,
      "z": -5,
      "name": "Plant_Large_Lilypad"
    },
    {
      "x": -6,
      "y": 5,
      "z": -3,
      "name": "Wood_Banyan_Branch_Long",
      "support": 15,
      "rotation": 5
    },
    {
      "x": -5,
      "y": 5,
      "z": -3,
      "name": "Wood_Banyan_Branch_Long",
      "support": 15,
      "rotation": 5
    },
    {
      "x": -5,
      "y": 9,
      "z": -1,
      "name": "Plant_Large_Lilypad"
    },
    {
      "x": -5,
      "y": 10,
      "z": -1,
      "name": "Plant_Large_Lilypad_Half"
    },
    {
      "x": -5,
      "y": 9,
      "z": 0,
      "name": "Plant_Large_Lilypad"
    },
    {
      "x": -5,
      "y": 10,
      "z": 0,
      "name": "Plant_Large_Lilypad_Half"
    },
    {
      "x": -5,
      "y": 9,
      "z": 1,
      "name": "Plant_Large_Lilypad"
    },
    {
      "x": -5,
      "y": 10,
      "z": 1,
      "name": "Plant_Large_Lilypad_Half"
    },
    {
      "x": -4,
      "y": 4,
      "z": -3,
      "name": "Wood_Banyan_Branch_Corner",
      "support": 15,
      "rotation": 2
    },
    {
      "x": -4,
      "y": 5,
      "z": -3,
      "name": "Wood_Banyan_Branch_Corner",
      "support": 15,
      "rotation": 11
    },
    {
      "x": -4,
      "y": 9,
      "z": -3,
      "name": "Plant_Large_Lilypad"
    },
    {
      "x": -4,
      "y": 10,
      "z": -3,
      "name": "Plant_Large_Lilypad_Half"
    },
    {
      "x": -4,
      "y": -5,
      "z": -2,
      "name": "Wood_Banyan_Branch_Long",
      "support": 15
    },
    {
      "x": -4,
      "y": -4,
      "z": -2,
      "name": "Wood_Banyan_Branch_Long",
      "support": 15
    },
    {
      "x": -4,
      "y": -3,
      "z": -2,
      "name": "Wood_Banyan_Branch_Long",
      "support": 15
    },
    {
      "x": -4,
      "y": -2,
      "z": -2,
      "name": "Wood_Banyan_Branch_Long",
      "support": 15
    },
    {
      "x": -4,
      "y": -1,
      "z": -2,
      "name": "Wood_Banyan_Branch_Long",
      "support": 15
    },
    {
      "x": -4,
      "y": 0,
      "z": -2,
      "name": "Wood_Banyan_Branch_Corner",
      "support": 15,
      "rotation": 8
    },
    {
      "x": -4,
      "y": 3,
      "z": -2,
      "name": "Wood_Banyan_Branch_Corner",
      "support": 15,
      "rotation": 2
    },
    {
      "x": -4,
      "y": 4,
      "z": -2,
      "name": "Wood_Banyan_Branch_Corner",
      "support": 15,
      "rotation": 10
    },
    {
      "x": -4,
      "y": 9,
      "z": -2,
      "name": "Plant_Large_Lilypad"
    },
    {
      "x": -4,
      "y": 10,
      "z": -2,
      "name": "Plant_Large_Lilypad_Half"
    },
    {
      "x": -4,
      "y": 0,
      "z": -1,
      "name": "Wood_Banyan_Branch_Long",
      "support": 15,
      "rotation": 4
    },
    {
      "x": -4,
      "y": 2,
      "z": -1,
      "name": "Wood_Banyan_Branch_Corner",
      "support": 15,
      "rotation": 3
    },
    {
      "x": -4,
      "y": 3,
      "z": -1,
      "name": "Wood_Banyan_Branch_Corner",
      "support": 15,
      "rotation": 10
    },
    {
      "x": -4,
      "y": 9,
      "z": -1,
      "name": "Plant_Large_Lilypad"
    },
    {
      "x": -4,
      "y": 0,
      "z": 0,
      "name": "Wood_Banyan_Branch_Corner",
      "support": 15
    },
    {
      "x": -4,
      "y": 1,
      "z": 0,
      "name": "Wood_Banyan_Branch_Long",
      "support": 15
    },
    {
      "x": -4,
      "y": 2,
      "z": 0,
      "name": "Wood_Banyan_Branch_Long",
      "support": 15
    },
    {
      "x": -4,
      "y": 3,
      "z": 0,
      "name": "Wood_Banyan_Branch_Long",
      "support": 15
    },
    {
      "x": -4,
      "y": 4,
      "z": 0,
      "name": "Wood_Banyan_Branch_Corner",
      "support": 15,
      "rotation": 9
    },
    {
      "x": -4,
      "y": 9,
      "z": 0,
      "name": "Plant_Large_Lilypad"
    },
    {
      "x": -4,
      "y": 10,
      "z": 0,
      "name": "Plant_Grass_Sharp_Short",
      "support": 15
    },
    {
      "x": -4,
      "y": 9,
      "z": 1,
      "name": "Plant_Large_Lilypad"
    },
    {
      "x": -4,
      "y": 9,
      "z": 2,
      "name": "Plant_Large_Lilypad"
    },
    {
      "x": -4,
      "y": 10,
      "z": 2,
      "name": "Plant_Large_Lilypad_Half"
    },
    {
      "x": -4,
      "y": 9,
      "z": 3,
      "name": "Plant_Large_Lilypad"
    },
    {
      "x": -4,
      "y": 10,
      "z": 3,
      "name": "Plant_Large_Lilypad_Half"
    },
    {
      "x": -3,
      "y": 9,
      "z": -4,
      "name": "Plant_Large_Lilypad"
    },
    {
      "x": -3,
      "y": 10,
      "z": -4,
      "name": "Plant_Large_Lilypad_Half"
    },
    {
      "x": -3,
      "y": 9,
      "z": -3,
      "name": "Plant_Large_Lilypad"
    },
    {
      "x": -3,
      "y": 10,
      "z": -3,
      "name": "Plant_Grass_Sharp_Wild",
      "support": 15
    },
    {
      "x": -3,
      "y": 11,
      "z": -3,
      "name": "Plant_Grass_Sharp_Wild",
      "filler": 1024
    },
    {
      "x": -3,
      "y": 9,
      "z": -2,
      "name": "Plant_Large_Lilypad"
    },
    {
      "x": -3,
      "y": 10,
      "z": -2,
      "name": "Plant_Grass_Sharp_Short",
      "support": 15
    },
    {
      "x": -3,
      "y": 2,
      "z": -1,
      "name": "Wood_Banyan_Branch_Long",
      "support": 15,
      "rotation": 5
    },
    {
      "x": -3,
      "y": 9,
      "z": -1,
      "name": "Plant_Large_Lilypad"
    },
    {
      "x": -3,
      "y": 4,
      "z": 0,
      "name": "Wood_Banyan_Branch_Corner",
      "support": 15,
      "rotation": 1
    },
    {
      "x": -3,
      "y": 5,
      "z": 0,
      "name": "Wood_Banyan_Branch_Long",
      "support": 15
    },
    {
      "x": -3,
      "y": 6,
      "z": 0,
      "name": "Wood_Banyan_Branch_Corner",
      "support": 15,
      "rotation": 9
    },
    {
      "x": -3,
      "y": 9,
      "z": 0,
      "name": "Plant_Large_Lilypad"
    },
    {
      "x": -3,
      "y": 9,
      "z": 1,
      "name": "Plant_Large_Lilypad"
    },
    {
      "x": -3,
      "y": 9,
      "z": 2,
      "name": "Plant_Large_Lilypad"
    },
    {
      "x": -3,
      "y": 9,
      "z": 3,
      "name": "Plant_Large_Lilypad"
    },
    {
      "x": -3,
      "y": 9,
      "z": 4,
      "name": "Plant_Large_Lilypad"
    },
    {
      "x": -3,
      "y": 10,
      "z": 4,
      "name": "Plant_Large_Lilypad_Half"
    },
    {
      "x": -2,
      "y": 9,
      "z": -4,
      "name": "Plant_Large_Lilypad"
    },
    {
      "x": -2,
      "y": 10,
      "z": -4,
      "name": "Plant_Large_Lilypad_Half"
    },
    {
      "x": -2,
      "y": 9,
      "z": -3,
      "name": "Plant_Large_Lilypad"
    },
    {
      "x": -2,
      "y": 10,
      "z": -3,
      "name": "Plant_Grass_Sharp_Tall",
      "support": 15
    },
    {
      "x": -2,
      "y": 11,
      "z": -3,
      "name": "Plant_Grass_Sharp_Tall",
      "filler": 1024
    },
    {
      "x": -2,
      "y": 9,
      "z": -2,
      "name": "Plant_Large_Lilypad"
    },
    {
      "x": -2,
      "y": -5,
      "z": -1,
      "name": "Wood_Banyan_Branch_Long",
      "support": 15
    },
    {
      "x": -2,
      "y": -4,
      "z": -1,
      "name": "Wood_Banyan_Branch_Long",
      "support": 15
    },
    {
      "x": -2,
      "y": -3,
      "z": -1,
      "name": "Wood_Banyan_Branch_Long",
      "support": 15
    },
    {
      "x": -2,
      "y": -2,
      "z": -1,
      "name": "Wood_Banyan_Branch_Long",
      "support": 15
    },
    {
      "x": -2,
      "y": -1,
      "z": -1,
      "name": "Wood_Banyan_Branch_Long",
      "support": 15
    },
    {
      "x": -2,
      "y": 0,
      "z": -1,
      "name": "Wood_Banyan_Roots"
    },
    {
      "x": -2,
      "y": 1,
      "z": -1,
      "name": "Wood_Banyan_Trunk_Full",
      "support": 15
    },
    {
      "x": -2,
      "y": 2,
      "z": -1,
      "name": "Wood_Banyan_Trunk",
      "support": 15
    },
    {
      "x": -2,
      "y": 3,
      "z": -1,
      "name": "Wood_Banyan_Trunk_Full",
      "support": 15,
      "rotation": 5
    },
    {
      "x": -2,
      "y": 9,
      "z": -1,
      "name": "Plant_Large_Lilypad"
    },
    {
      "x": -2,
      "y": 3,
      "z": 0,
      "name": "Wood_Banyan_Branch_Long",
      "support": 15,
      "rotation": 4
    },
    {
      "x": -2,
      "y": 6,
      "z": 0,
      "name": "Wood_Banyan_Branch_Long",
      "support": 15,
      "rotation": 5
    },
    {
      "x": -2,
      "y": 8,
      "z": 0,
      "name": "Wood_Banyan_Roots"
    },
    {
      "x": -2,
      "y": 9,
      "z": 0,
      "name": "Plant_Large_Lilypad"
    },
    {
      "x": -2,
      "y": 3,
      "z": 1,
      "name": "Wood_Banyan_Branch_Long",
      "support": 15,
      "rotation": 4
    },
    {
      "x": -2,
      "y": 9,
      "z": 1,
      "name": "Plant_Large_Lilypad"
    },
    {
      "x": -2,
      "y": 3,
      "z": 2,
      "name": "Wood_Banyan_Branch_Long",
      "support": 15,
      "rotation": 4
    },
    {
      "x": -2,
      "y": 9,
      "z": 2,
      "name": "Plant_Large_Lilypad"
    },
    {
      "x": -2,
      "y": -5,
      "z": 3,
      "name": "Wood_Banyan_Branch_Long",
      "support": 15
    },
    {
      "x": -2,
      "y": -4,
      "z": 3,
      "name": "Wood_Banyan_Branch_Long",
      "support": 15
    },
    {
      "x": -2,
      "y": -3,
      "z": 3,
      "name": "Wood_Banyan_Branch_Long",
      "support": 15
    },
    {
      "x": -2,
      "y": -2,
      "z": 3,
      "name": "Wood_Banyan_Branch_Long",
      "support": 15
    },
    {
      "x": -2,
      "y": -1,
      "z": 3,
      "name": "Wood_Banyan_Branch_Long",
      "support": 15
    },
    {
      "x": -2,
      "y": 0,
      "z": 3,
      "name": "Wood_Banyan_Branch_Long",
      "support": 15
    },
    {
      "x": -2,
      "y": 1,
      "z": 3,
      "name": "Wood_Banyan_Branch_Long",
      "support": 15
    },
    {
      "x": -2,
      "y": 2,
      "z": 3,
      "name": "Wood_Banyan_Branch_Long",
      "support": 15
    },
    {
      "x": -2,
      "y": 3,
      "z": 3,
      "name": "Wood_Banyan_Branch_Corner",
      "support": 15,
      "rotation": 10
    },
    {
      "x": -2,
      "y": 9,
      "z": 3,
      "name": "Plant_Large_Lilypad"
    },
    {
      "x": -2,
      "y": 9,
      "z": 4,
      "name": "Plant_Large_Lilypad"
    },
    {
      "x": -2,
      "y": 10,
      "z": 4,
      "name": "Plant_Large_Lilypad_Half"
    },
    {
      "x": -1,
      "y": 10,
      "z": -11,
      "name": "Plant_Large_Lilypad_Half"
    },
    {
      "x": -1,
      "y": 10,
      "z": -10,
      "name": "Plant_Large_Lilypad_Half"
    },
    {
      "x": -1,
      "y": 10,
      "z": -9,
      "name": "Plant_Large_Lilypad_Half"
    },
    {
      "x": -1,
      "y": 9,
      "z": -5,
      "name": "Plant_Large_Lilypad"
    },
    {
      "x": -1,
      "y": 10,
      "z": -5,
      "name": "Plant_Large_Lilypad_Half"
    },
    {
      "x": -1,
      "y": 9,
      "z": -4,
      "name": "Plant_Large_Lilypad"
    },
    {
      "x": -1,
      "y": 9,
      "z": -3,
      "name": "Plant_Large_Lilypad"
    },
    {
      "x": -1,
      "y": 9,
      "z": -2,
      "name": "Plant_Large_Lilypad"
    },
    {
      "x": -1,
      "y": 2,
      "z": -1,
      "name": "Wood_Banyan_Roots"
    },
    {
      "x": -1,
      "y": 3,
      "z": -1,
      "name": "Wood_Banyan_Trunk_Full",
      "support": 15
    },
    {
      "x": -1,
      "y": 4,
      "z": -1,
      "name": "Wood_Banyan_Trunk_Full",
      "support": 15
    },
    {
      "x": -1,
      "y": 9,
      "z": -1,
      "name": "Plant_Large_Lilypad"
    },
    {
      "x": -1,
      "y": 6,
      "z": 0,
      "name": "Wood_Banyan_Branch_Long",
      "support": 15,
      "rotation": 5
    },
    {
      "x": -1,
      "y": 9,
      "z": 0,
      "name": "Plant_Large_Lilypad"
    },
    {
      "x": -1,
      "y": 9,
      "z": 1,
      "name": "Plant_Large_Lilypad"
    },
    {
      "x": -1,
      "y": 9,
      "z": 2,
      "name": "Plant_Large_Lilypad"
    },
    {
      "x": -1,
      "y": 9,
      "z": 3,
      "name": "Plant_Large_Lilypad"
    },
    {
      "x": -1,
      "y": 9,
      "z": 4,
      "name": "Plant_Large_Lilypad"
    },
    {
      "x": -1,
      "y": 9,
      "z": 5,
      "name": "Plant_Large_Lilypad"
    },
    {
      "x": -1,
      "y": 10,
      "z": 5,
      "name": "Plant_Large_Lilypad_Half"
    },
    {
      "x": 0,
      "y": 10,
      "z": -11,
      "name": "Plant_Large_Lilypad_Half"
    },
    {
      "x": 0,
      "y": 7,
      "z": -10,
      "name": "Wood_Banyan_Branch_Corner",
      "support": 15,
      "rotation": 2
    },
    {
      "x": 0,
      "y": 8,
      "z": -10,
      "name": "Wood_Banyan_Branch_Long",
      "support": 15
    },
    {
      "x": 0,
      "y": 9,
      "z": -10,
      "name": "Wood_Banyan_Branch_Long",
      "support": 15
    },
    {
      "x": 0,
      "y": 10,
      "z": -10,
      "name": "Plant_Large_Lilypad_Half"
    },
    {
      "x": 0,
      "y": 7,
      "z": -9,
      "name": "Wood_Banyan_Branch_Long",
      "support": 15,
      "rotation": 4
    },
    {
      "x": 0,
      "y": 10,
      "z": -9,
      "name": "Plant_Large_Lilypad_Half"
    },
    {
      "x": 0,
      "y": 7,
      "z": -8,
      "name": "Wood_Banyan_Branch_Long",
      "support": 15,
      "rotation": 4
    },
    {
      "x": 0,
      "y": 7,
      "z": -7,
      "name": "Wood_Banyan_Branch_Long",
      "support": 15,
      "rotation": 4
    },
    {
      "x": 0,
      "y": -5,
      "z": -6,
      "name": "Wood_Banyan_Branch_Long",
      "support": 15
    },
    {
      "x": 0,
      "y": -4,
      "z": -6,
      "name": "Wood_Banyan_Branch_Long",
      "support": 15
    },
    {
      "x": 0,
      "y": -3,
      "z": -6,
      "name": "Wood_Banyan_Branch_Long",
      "support": 15
    },
    {
      "x": 0,
      "y": -2,
      "z": -6,
      "name": "Wood_Banyan_Branch_Long",
      "support": 15
    },
    {
      "x": 0,
      "y": -1,
      "z": -6,
      "name": "Wood_Banyan_Branch_Long",
      "support": 15
    },
    {
      "x": 0,
      "y": 0,
      "z": -6,
      "name": "Wood_Banyan_Branch_Long",
      "support": 15
    },
    {
      "x": 0,
      "y": 1,
      "z": -6,
      "name": "Wood_Banyan_Branch_Long",
      "support": 15
    },
    {
      "x": 0,
      "y": 2,
      "z": -6,
      "name": "Wood_Banyan_Branch_Corner",
      "support": 15,
      "rotation": 8
    },
    {
      "x": 0,
      "y": 7,
      "z": -6,
      "name": "Wood_Banyan_Branch_Long",
      "support": 15,
      "rotation": 4
    },
    {
      "x": 0,
      "y": 2,
      "z": -5,
      "name": "Wood_Banyan_Branch_Long",
      "support": 15,
      "rotation": 4
    },
    {
      "x": 0,
      "y": 7,
      "z": -5,
      "name": "Wood_Banyan_Branch_Long",
      "support": 15,
      "rotation": 4
    },
    {
      "x": 0,
      "y": 9,
      "z": -5,
      "name": "Plant_Large_Lilypad"
    },
    {
      "x": 0,
      "y": 10,
      "z": -5,
      "name": "Plant_Large_Lilypad_Half"
    },
    {
      "x": 0,
      "y": 1,
      "z": -4,
      "name": "Wood_Banyan_Roots"
    },
    {
      "x": 0,
      "y": 2,
      "z": -4,
      "name": "Wood_Banyan_Trunk",
      "support": 15
    },
    {
      "x": 0,
      "y": 3,
      "z": -4,
      "name": "Wood_Banyan_Trunk",
      "support": 15
    },
    {
      "x": 0,
      "y": 4,
      "z": -4,
      "name": "Wood_Banyan_Trunk",
      "support": 15
    },
    {
      "x": 0,
      "y": 5,
      "z": -4,
      "name": "Wood_Banyan_Trunk_Full",
      "support": 15
    },
    {
      "x": 0,
      "y": 7,
      "z": -4,
      "name": "Wood_Banyan_Branch_Long",
      "support": 15,
      "rotation": 4
    },
    {
      "x": 0,
      "y": 9,
      "z": -4,
      "name": "Plant_Large_Lilypad"
    },
    {
      "x": 0,
      "y": 5,
      "z": -3,
      "name": "Wood_Banyan_Trunk",
      "support": 15,
      "rotation": 4
    },
    {
      "x": 0,
      "y": 6,
      "z": -3,
      "name": "Wood_Banyan_Branch_Long",
      "support": 15
    },
    {
      "x": 0,
      "y": 7,
      "z": -3,
      "name": "Wood_Banyan_Branch_Corner",
      "support": 15,
      "rotation": 10
    },
    {
      "x": 0,
      "y": 9,
      "z": -3,
      "name": "Plant_Large_Lilypad"
    },
    {
      "x": 0,
      "y": 4,
      "z": -2,
      "name": "Wood_Banyan_Roots"
    },
    {
      "x": 0,
      "y": 5,
      "z": -2,
      "name": "Wood_Banyan_Trunk",
      "support": 15,
      "rotation": 4
    },
    {
      "x": 0,
      "y": 9,
      "z": -2,
      "name": "Plant_Large_Lilypad"
    },
    {
      "x": 0,
      "y": 5,
      "z": -1,
      "name": "Wood_Banyan_Trunk",
      "support": 15,
      "rotation": 4
    },
    {
      "x": 0,
      "y": 8,
      "z": -1,
      "name": "Wood_Banyan_Roots"
    },
    {
      "x": 0,
      "y": 9,
      "z": -1,
      "name": "Plant_Large_Lilypad"
    },
    {
      "x": 0,
      "y": 4,
      "z": 0,
      "name": "Wood_Banyan_Trunk_Full",
      "support": 15
    },
    {
      "x": 0,
      "y": 5,
      "z": 0,
      "name": "Wood_Banyan_Trunk",
      "support": 15
    },
    {
      "x": 0,
      "y": 6,
      "z": 0,
      "name": "Wood_Banyan_Trunk",
      "support": 15
    },
    {
      "x": 0,
      "y": 7,
      "z": 0,
      "name": "Wood_Banyan_Trunk",
      "support": 15
    },
    {
      "x": 0,
      "y": 8,
      "z": 0,
      "name": "Wood_Banyan_Trunk",
      "support": 15
    },
    {
      "x": 0,
      "y": 9,
      "z": 0,
      "name": "Plant_Large_Lilypad"
    },
    {
      "x": 0,
      "y": 8,
      "z": 1,
      "name": "Wood_Banyan_Roots"
    },
    {
      "x": 0,
      "y": 9,
      "z": 1,
      "name": "Plant_Large_Lilypad"
    },
    {
      "x": 0,
      "y": -5,
      "z": 2,
      "name": "Wood_Banyan_Branch_Long",
      "support": 15
    },
    {
      "x": 0,
      "y": -4,
      "z": 2,
      "name": "Wood_Banyan_Branch_Long",
      "support": 15
    },
    {
      "x": 0,
      "y": -3,
      "z": 2,
      "name": "Wood_Banyan_Branch_Long",
      "support": 15
    },
    {
      "x": 0,
      "y": -2,
      "z": 2,
      "name": "Wood_Banyan_Branch_Long",
      "support": 15
    },
    {
      "x": 0,
      "y": -1,
      "z": 2,
      "name": "Wood_Banyan_Branch_Long",
      "support": 15
    },
    {
      "x": 0,
      "y": 0,
      "z": 2,
      "name": "Wood_Banyan_Branch_Corner",
      "support": 15,
      "rotation": 9
    },
    {
      "x": 0,
      "y": 9,
      "z": 2,
      "name": "Plant_Large_Lilypad"
    },
    {
      "x": 0,
      "y": 9,
      "z": 3,
      "name": "Plant_Large_Lilypad"
    },
    {
      "x": 0,
      "y": 9,
      "z": 4,
      "name": "Plant_Large_Lilypad"
    },
    {
      "x": 0,
      "y": 9,
      "z": 5,
      "name": "Plant_Large_Lilypad"
    },
    {
      "x": 0,
      "y": 10,
      "z": 5,
      "name": "Plant_Large_Lilypad_Half"
    },
    {
      "x": 1,
      "y": 10,
      "z": -11,
      "name": "Plant_Large_Lilypad_Half"
    },
    {
      "x": 1,
      "y": 10,
      "z": -10,
      "name": "Plant_Large_Lilypad_Half"
    },
    {
      "x": 1,
      "y": 10,
      "z": -9,
      "name": "Plant_Large_Lilypad_Half"
    },
    {
      "x": 1,
      "y": 9,
      "z": -5,
      "name": "Plant_Large_Lilypad"
    },
    {
      "x": 1,
      "y": 10,
      "z": -5,
      "name": "Plant_Large_Lilypad_Half"
    },
    {
      "x": 1,
      "y": 9,
      "z": -4,
      "name": "Plant_Large_Lilypad"
    },
    {
      "x": 1,
      "y": 9,
      "z": -3,
      "name": "Plant_Large_Lilypad"
    },
    {
      "x": 1,
      "y": -5,
      "z": -2,
      "name": "Wood_Banyan_Branch_Long",
      "support": 15
    },
    {
      "x": 1,
      "y": -4,
      "z": -2,
      "name": "Wood_Banyan_Branch_Long",
      "support": 15
    },
    {
      "x": 1,
      "y": -3,
      "z": -2,
      "name": "Wood_Banyan_Branch_Long",
      "support": 15
    },
    {
      "x": 1,
      "y": -2,
      "z": -2,
      "name": "Wood_Banyan_Branch_Long",
      "support": 15
    },
    {
      "x": 1,
      "y": -1,
      "z": -2,
      "name": "Wood_Banyan_Branch_Long",
      "support": 15
    },
    {
      "x": 1,
      "y": 0,
      "z": -2,
      "name": "Wood_Banyan_Branch_Corner",
      "support": 15,
      "rotation": 9
    },
    {
      "x": 1,
      "y": 9,
      "z": -2,
      "name": "Plant_Large_Lilypad"
    },
    {
      "x": 1,
      "y": 9,
      "z": -1,
      "name": "Plant_Large_Lilypad"
    },
    {
      "x": 1,
      "y": 7,
      "z": 0,
      "name": "Wood_Banyan_Branch_Long",
      "support": 15,
      "rotation": 5
    },
    {
      "x": 1,
      "y": 9,
      "z": 0,
      "name": "Plant_Large_Lilypad"
    },
    {
      "x": 1,
      "y": 1,
      "z": 1,
      "name": "Wood_Banyan_Roots"
    },
    {
      "x": 1,
      "y": 2,
      "z": 1,
      "name": "Wood_Banyan_Trunk_Full",
      "support": 15
    },
    {
      "x": 1,
      "y": 3,
      "z": 1,
      "name": "Wood_Banyan_Trunk_Full",
      "support": 15
    },
    {
      "x": 1,
      "y": 4,
      "z": 1,
      "name": "Wood_Banyan_Trunk_Full",
      "support": 15
    },
    {
      "x": 1,
      "y": 9,
      "z": 1,
      "name": "Plant_Large_Lilypad"
    },
    {
      "x": 1,
      "y": 0,
      "z": 2,
      "name": "Wood_Banyan_Branch_Corner",
      "support": 15,
      "rotation": 1
    },
    {
      "x": 1,
      "y": 1,
      "z": 2,
      "name": "Wood_Banyan_Branch_Long",
      "support": 15
    },
    {
      "x": 1,
      "y": 2,
      "z": 2,
      "name": "Wood_Banyan_Branch_Long",
      "support": 15
    },
    {
      "x": 1,
      "y": 3,
      "z": 2,
      "name": "Wood_Banyan_Branch_Long",
      "support": 15
    },
    {
      "x": 1,
      "y": 4,
      "z": 2,
      "name": "Wood_Banyan_Branch_Corner",
      "support": 15,
      "rotation": 10
    },
    {
      "x": 1,
      "y": 9,
      "z": 2,
      "name": "Plant_Large_Lilypad"
    },
    {
      "x": 1,
      "y": 9,
      "z": 3,
      "name": "Plant_Large_Lilypad"
    },
    {
      "x": 1,
      "y": 9,
      "z": 4,
      "name": "Plant_Large_Lilypad"
    },
    {
      "x": 1,
      "y": 9,
      "z": 5,
      "name": "Plant_Large_Lilypad"
    },
    {
      "x": 1,
      "y": 10,
      "z": 5,
      "name": "Plant_Large_Lilypad_Half"
    },
    {
      "x": 2,
      "y": 9,
      "z": -4,
      "name": "Plant_Large_Lilypad"
    },
    {
      "x": 2,
      "y": 10,
      "z": -4,
      "name": "Plant_Large_Lilypad_Half"
    },
    {
      "x": 2,
      "y": 9,
      "z": -3,
      "name": "Plant_Large_Lilypad"
    },
    {
      "x": 2,
      "y": 0,
      "z": -2,
      "name": "Wood_Banyan_Branch_Long",
      "support": 15,
      "rotation": 5
    },
    {
      "x": 2,
      "y": 9,
      "z": -2,
      "name": "Plant_Large_Lilypad"
    },
    {
      "x": 2,
      "y": 9,
      "z": -1,
      "name": "Plant_Large_Lilypad"
    },
    {
      "x": 2,
      "y": 7,
      "z": 0,
      "name": "Wood_Banyan_Branch_Long",
      "support": 15,
      "rotation": 5
    },
    {
      "x": 2,
      "y": 9,
      "z": 0,
      "name": "Plant_Large_Lilypad"
    },
    {
      "x": 2,
      "y": 2,
      "z": 1,
      "name": "Wood_Banyan_Trunk_Full",
      "support": 15,
      "rotation": 5
    },
    {
      "x": 2,
      "y": 9,
      "z": 1,
      "name": "Plant_Large_Lilypad"
    },
    {
      "x": 2,
      "y": -5,
      "z": 2,
      "name": "Wood_Banyan_Branch_Long",
      "support": 15
    },
    {
      "x": 2,
      "y": -4,
      "z": 2,
      "name": "Wood_Banyan_Branch_Long",
      "support": 15
    },
    {
      "x": 2,
      "y": -3,
      "z": 2,
      "name": "Wood_Banyan_Branch_Long",
      "support": 15
    },
    {
      "x": 2,
      "y": -2,
      "z": 2,
      "name": "Wood_Banyan_Branch_Long",
      "support": 15
    },
    {
      "x": 2,
      "y": -1,
      "z": 2,
      "name": "Wood_Banyan_Branch_Long",
      "support": 15
    },
    {
      "x": 2,
      "y": 0,
      "z": 2,
      "name": "Wood_Banyan_Branch_Long",
      "support": 15
    },
    {
      "x": 2,
      "y": 1,
      "z": 2,
      "name": "Wood_Banyan_Branch_Long",
      "support": 15
    },
    {
      "x": 2,
      "y": 2,
      "z": 2,
      "name": "Wood_Banyan_Branch_Corner",
      "support": 15,
      "rotation": 10
    },
    {
      "x": 2,
      "y": 9,
      "z": 2,
      "name": "Plant_Large_Lilypad"
    },
    {
      "x": 2,
      "y": 9,
      "z": 3,
      "name": "Plant_Large_Lilypad"
    },
    {
      "x": 2,
      "y": 9,
      "z": 4,
      "name": "Plant_Large_Lilypad"
    },
    {
      "x": 2,
      "y": 10,
      "z": 4,
      "name": "Plant_Large_Lilypad_Half"
    },
    {
      "x": 3,
      "y": 9,
      "z": -4,
      "name": "Plant_Large_Lilypad"
    },
    {
      "x": 3,
      "y": 10,
      "z": -4,
      "name": "Plant_Large_Lilypad_Half"
    },
    {
      "x": 3,
      "y": 9,
      "z": -3,
      "name": "Plant_Large_Lilypad"
    },
    {
      "x": 3,
      "y": 0,
      "z": -2,
      "name": "Wood_Banyan_Trunk_Full",
      "support": 15,
      "rotation": 5
    },
    {
      "x": 3,
      "y": 1,
      "z": -2,
      "name": "Wood_Banyan_Branch_Long",
      "support": 15
    },
    {
      "x": 3,
      "y": 2,
      "z": -2,
      "name": "Wood_Banyan_Branch_Long",
      "support": 15
    },
    {
      "x": 3,
      "y": 3,
      "z": -2,
      "name": "Wood_Banyan_Branch_Long",
      "support": 15
    },
    {
      "x": 3,
      "y": 4,
      "z": -2,
      "name": "Wood_Banyan_Branch_Corner",
      "support": 15,
      "rotation": 8
    },
    {
      "x": 3,
      "y": 9,
      "z": -2,
      "name": "Plant_Large_Lilypad"
    },
    {
      "x": 3,
      "y": 4,
      "z": -1,
      "name": "Wood_Banyan_Branch_Long",
      "support": 15,
      "rotation": 4
    },
    {
      "x": 3,
      "y": 9,
      "z": -1,
      "name": "Plant_Large_Lilypad"
    },
    {
      "x": 3,
      "y": 4,
      "z": 0,
      "name": "Wood_Banyan_Trunk_Full",
      "support": 15
    },
    {
      "x": 3,
      "y": 5,
      "z": 0,
      "name": "Wood_Banyan_Branch_Long",
      "support": 15
    },
    {
      "x": 3,
      "y": 6,
      "z": 0,
      "name": "Wood_Banyan_Branch_Long",
      "support": 15
    },
    {
      "x": 3,
      "y": 7,
      "z": 0,
      "name": "Wood_Banyan_Branch_Corner",
      "support": 15,
      "rotation": 11
    },
    {
      "x": 3,
      "y": 9,
      "z": 0,
      "name": "Plant_Large_Lilypad"
    },
    {
      "x": 3,
      "y": -5,
      "z": 1,
      "name": "Wood_Banyan_Branch_Long",
      "support": 15
    },
    {
      "x": 3,
      "y": -4,
      "z": 1,
      "name": "Wood_Banyan_Branch_Long",
      "support": 15
    },
    {
      "x": 3,
      "y": -3,
      "z": 1,
      "name": "Wood_Banyan_Branch_Long",
      "support": 15
    },
    {
      "x": 3,
      "y": -2,
      "z": 1,
      "name": "Wood_Banyan_Branch_Long",
      "support": 15
    },
    {
      "x": 3,
      "y": -1,
      "z": 1,
      "name": "Wood_Banyan_Branch_Long",
      "support": 15
    },
    {
      "x": 3,
      "y": 0,
      "z": 1,
      "name": "Wood_Banyan_Roots"
    },
    {
      "x": 3,
      "y": 1,
      "z": 1,
      "name": "Wood_Banyan_Trunk_Full",
      "support": 15
    },
    {
      "x": 3,
      "y": 2,
      "z": 1,
      "name": "Wood_Banyan_Trunk_Full",
      "support": 15
    },
    {
      "x": 3,
      "y": 4,
      "z": 1,
      "name": "Wood_Banyan_Branch_Long",
      "support": 15,
      "rotation": 4
    },
    {
      "x": 3,
      "y": 9,
      "z": 1,
      "name": "Plant_Large_Lilypad"
    },
    {
      "x": 3,
      "y": 3,
      "z": 2,
      "name": "Wood_Banyan_Branch_Corner",
      "support": 15,
      "rotation": 3
    },
    {
      "x": 3,
      "y": 4,
      "z": 2,
      "name": "Wood_Banyan_Branch_Corner",
      "support": 15,
      "rotation": 10
    },
    {
      "x": 3,
      "y": 9,
      "z": 2,
      "name": "Plant_Large_Lilypad"
    },
    {
      "x": 3,
      "y": 10,
      "z": 2,
      "name": "Plant_Grass_Sharp_Short",
      "support": 15
    },
    {
      "x": 3,
      "y": 9,
      "z": 3,
      "name": "Plant_Large_Lilypad"
    },
    {
      "x": 3,
      "y": 10,
      "z": 3,
      "name": "Plant_Grass_Sharp_Tall",
      "support": 15
    },
    {
      "x": 3,
      "y": 11,
      "z": 3,
      "name": "Plant_Grass_Sharp_Tall",
      "filler": 1024
    },
    {
      "x": 3,
      "y": 9,
      "z": 4,
      "name": "Plant_Large_Lilypad"
    },
    {
      "x": 3,
      "y": 10,
      "z": 4,
      "name": "Plant_Large_Lilypad_Half"
    },
    {
      "x": 4,
      "y": 9,
      "z": -3,
      "name": "Plant_Large_Lilypad"
    },
    {
      "x": 4,
      "y": 10,
      "z": -3,
      "name": "Plant_Large_Lilypad_Half"
    },
    {
      "x": 4,
      "y": -5,
      "z": -2,
      "name": "Wood_Banyan_Branch_Long",
      "support": 15
    },
    {
      "x": 4,
      "y": -4,
      "z": -2,
      "name": "Wood_Banyan_Branch_Long",
      "support": 15
    },
    {
      "x": 4,
      "y": -3,
      "z": -2,
      "name": "Wood_Banyan_Branch_Long",
      "support": 15
    },
    {
      "x": 4,
      "y": -2,
      "z": -2,
      "name": "Wood_Banyan_Branch_Long",
      "support": 15
    },
    {
      "x": 4,
      "y": -1,
      "z": -2,
      "name": "Wood_Banyan_Branch_Long",
      "support": 15
    },
    {
      "x": 4,
      "y": 0,
      "z": -2,
      "name": "Wood_Banyan_Branch_Corner",
      "support": 15,
      "rotation": 11
    },
    {
      "x": 4,
      "y": 9,
      "z": -2,
      "name": "Plant_Large_Lilypad"
    },
    {
      "x": 4,
      "y": 10,
      "z": -2,
      "name": "Plant_Large_Lilypad_Half"
    },
    {
      "x": 4,
      "y": 9,
      "z": -1,
      "name": "Plant_Large_Lilypad"
    },
    {
      "x": 4,
      "y": 9,
      "z": 0,
      "name": "Plant_Large_Lilypad"
    },
    {
      "x": 4,
      "y": 9,
      "z": 1,
      "name": "Plant_Large_Lilypad"
    },
    {
      "x": 4,
      "y": 10,
      "z": 1,
      "name": "Plant_Grass_Sharp_Tall",
      "support": 15
    },
    {
      "x": 4,
      "y": 11,
      "z": 1,
      "name": "Plant_Grass_Sharp_Tall",
      "filler": 1024
    },
    {
      "x": 4,
      "y": 3,
      "z": 2,
      "name": "Wood_Banyan_Branch_Long",
      "support": 15,
      "rotation": 5
    },
    {
      "x": 4,
      "y": 9,
      "z": 2,
      "name": "Plant_Large_Lilypad"
    },
    {
      "x": 4,
      "y": 10,
      "z": 2,
      "name": "Plant_Large_Lilypad_Half"
    },
    {
      "x": 4,
      "y": 9,
      "z": 3,
      "name": "Plant_Large_Lilypad"
    },
    {
      "x": 4,
      "y": 10,
      "z": 3,
      "name": "Plant_Large_Lilypad_Half"
    },
    {
      "x": 5,
      "y": 9,
      "z": -1,
      "name": "Plant_Large_Lilypad"
    },
    {
      "x": 5,
      "y": 10,
      "z": -1,
      "name": "Plant_Large_Lilypad_Half"
    },
    {
      "x": 5,
      "y": 9,
      "z": 0,
      "name": "Plant_Large_Lilypad"
    },
    {
      "x": 5,
      "y": 10,
      "z": 0,
      "name": "Plant_Large_Lilypad_Half"
    },
    {
      "x": 5,
      "y": 9,
      "z": 1,
      "name": "Plant_Large_Lilypad"
    },
    {
      "x": 5,
      "y": 10,
      "z": 1,
      "name": "Plant_Large_Lilypad_Half"
    },
    {
      "x": 5,
      "y": -5,
      "z": 2,
      "name": "Wood_Banyan_Branch_Long",
      "support": 15
    },
    {
      "x": 5,
      "y": -4,
      "z": 2,
      "name": "Wood_Banyan_Branch_Long",
      "support": 15
    },
    {
      "x": 5,
      "y": -3,
      "z": 2,
      "name": "Wood_Banyan_Branch_Long",
      "support": 15
    },
    {
      "x": 5,
      "y": -2,
      "z": 2,
      "name": "Wood_Banyan_Branch_Long",
      "support": 15
    },
    {
      "x": 5,
      "y": -1,
      "z": 2,
      "name": "Wood_Banyan_Branch_Long",
      "support": 15
    },
    {
      "x": 5,
      "y": 0,
      "z": 2,
      "name": "Wood_Banyan_Branch_Long",
      "support": 15
    },
    {
      "x": 5,
      "y": 1,
      "z": 2,
      "name": "Wood_Banyan_Branch_Long",
      "support": 15
    },
    {
      "x": 5,
      "y": 2,
      "z": 2,
      "name": "Wood_Banyan_Branch_Long",
      "support": 15
    },
    {
      "x": 5,
      "y": 3,
      "z": 2,
      "name": "Wood_Banyan_Branch_Corner",
      "support": 15,
      "rotation": 11
    }
  ],
  "fluids": [
    {
      "x": -8,
      "y": 7,
      "z": -5,
      "name": "Water_Source",
      "level": 1
    },
    {
      "x": -7,
      "y": 6,
      "z": -5,
      "name": "Water_Source",
      "level": 1
    },
    {
      "x": -7,
      "y": 7,
      "z": -5,
      "name": "Water_Source",
      "level": 1
    },
    {
      "x": -7,
      "y": 6,
      "z": -4,
      "name": "Water_Source",
      "level": 1
    },
    {
      "x": -7,
      "y": 6,
      "z": -3,
      "name": "Water_Source",
      "level": 1
    },
    {
      "x": -6,
      "y": 5,
      "z": -3,
      "name": "Water_Source",
      "level": 1
    },
    {
      "x": -5,
      "y": 5,
      "z": -3,
      "name": "Water_Source",
      "level": 1
    },
    {
      "x": -4,
      "y": 4,
      "z": -3,
      "name": "Water_Source",
      "level": 1
    },
    {
      "x": -4,
      "y": 5,
      "z": -3,
      "name": "Water_Source",
      "level": 1
    },
    {
      "x": -4,
      "y": -5,
      "z": -2,
      "name": "Water_Source",
      "level": 1
    },
    {
      "x": -4,
      "y": -4,
      "z": -2,
      "name": "Water_Source",
      "level": 1
    },
    {
      "x": -4,
      "y": -3,
      "z": -2,
      "name": "Water_Source",
      "level": 1
    },
    {
      "x": -4,
      "y": -2,
      "z": -2,
      "name": "Water_Source",
      "level": 1
    },
    {
      "x": -4,
      "y": -1,
      "z": -2,
      "name": "Water_Source",
      "level": 1
    },
    {
      "x": -4,
      "y": 0,
      "z": -2,
      "name": "Water_Source",
      "level": 1
    },
    {
      "x": -4,
      "y": 3,
      "z": -2,
      "name": "Water_Source",
      "level": 1
    },
    {
      "x": -4,
      "y": 4,
      "z": -2,
      "name": "Water_Source",
      "level": 1
    },
    {
      "x": -4,
      "y": 0,
      "z": -1,
      "name": "Water_Source",
      "level": 1
    },
    {
      "x": -4,
      "y": 2,
      "z": -1,
      "name": "Water_Source",
      "level": 1
    },
    {
      "x": -4,
      "y": 3,
      "z": -1,
      "name": "Water_Source",
      "level": 1
    },
    {
      "x": -4,
      "y": 0,
      "z": 0,
      "name": "Water_Source",
      "level": 1
    },
    {
      "x": -4,
      "y": 1,
      "z": 0,
      "name": "Water_Source",
      "level": 1
    },
    {
      "x": -4,
      "y": 2,
      "z": 0,
      "name": "Water_Source",
      "level": 1
    },
    {
      "x": -4,
      "y": 3,
      "z": 0,
      "name": "Water_Source",
      "level": 1
    },
    {
      "x": -4,
      "y": 4,
      "z": 0,
      "name": "Water_Source",
      "level": 1
    },
    {
      "x": -3,
      "y": 4,
      "z": 0,
      "name": "Water_Source",
      "level": 1
    },
    {
      "x": -3,
      "y": 5,
      "z": 0,
      "name": "Water_Source",
      "level": 1
    },
    {
      "x": -3,
      "y": 6,
      "z": 0,
      "name": "Water_Source",
      "level": 1
    },
    {
      "x": -2,
      "y": -5,
      "z": -1,
      "name": "Water_Source",
      "level": 1
    },
    {
      "x": -2,
      "y": -4,
      "z": -1,
      "name": "Water_Source",
      "level": 1
    },
    {
      "x": -2,
      "y": -3,
      "z": -1,
      "name": "Water_Source",
      "level": 1
    },
    {
      "x": -2,
      "y": -2,
      "z": -1,
      "name": "Water_Source",
      "level": 1
    },
    {
      "x": -2,
      "y": -1,
      "z": -1,
      "name": "Water_Source",
      "level": 1
    },
    {
      "x": -2,
      "y": 0,
      "z": -1,
      "name": "Water_Source",
      "level": 1
    },
    {
      "x": -2,
      "y": 3,
      "z": 0,
      "name": "Water_Source",
      "level": 1
    },
    {
      "x": -2,
      "y": 6,
      "z": 0,
      "name": "Water_Source",
      "level": 1
    },
    {
      "x": -2,
      "y": 8,
      "z": 0,
      "name": "Water_Source",
      "level": 1
    },
    {
      "x": -2,
      "y": 3,
      "z": 1,
      "name": "Water_Source",
      "level": 1
    },
    {
      "x": -2,
      "y": 3,
      "z": 2,
      "name": "Water_Source",
      "level": 1
    },
    {
      "x": -2,
      "y": -5,
      "z": 3,
      "name": "Water_Source",
      "level": 1
    },
    {
      "x": -2,
      "y": -4,
      "z": 3,
      "name": "Water_Source",
      "level": 1
    },
    {
      "x": -2,
      "y": -3,
      "z": 3,
      "name": "Water_Source",
      "level": 1
    },
    {
      "x": -2,
      "y": -2,
      "z": 3,
      "name": "Water_Source",
      "level": 1
    },
    {
      "x": -2,
      "y": -1,
      "z": 3,
      "name": "Water_Source",
      "level": 1
    },
    {
      "x": -2,
      "y": 0,
      "z": 3,
      "name": "Water_Source",
      "level": 1
    },
    {
      "x": -2,
      "y": 1,
      "z": 3,
      "name": "Water_Source",
      "level": 1
    },
    {
      "x": -2,
      "y": 2,
      "z": 3,
      "name": "Water_Source",
      "level": 1
    },
    {
      "x": -2,
      "y": 3,
      "z": 3,
      "name": "Water_Source",
      "level": 1
    },
    {
      "x": -1,
      "y": 2,
      "z": -1,
      "name": "Water_Source",
      "level": 1
    },
    {
      "x": -1,
      "y": 6,
      "z": 0,
      "name": "Water_Source",
      "level": 1
    },
    {
      "x": 0,
      "y": 7,
      "z": -10,
      "name": "Water_Source",
      "level": 1
    },
    {
      "x": 0,
      "y": 8,
      "z": -10,
      "name": "Water_Source",
      "level": 1
    },
    {
      "x": 0,
      "y": 9,
      "z": -10,
      "name": "Water_Source",
      "level": 1
    },
    {
      "x": 0,
      "y": 7,
      "z": -9,
      "name": "Water_Source",
      "level": 1
    },
    {
      "x": 0,
      "y": 7,
      "z": -8,
      "name": "Water_Source",
      "level": 1
    },
    {
      "x": 0,
      "y": 7,
      "z": -7,
      "name": "Water_Source",
      "level": 1
    },
    {
      "x": 0,
      "y": -5,
      "z": -6,
      "name": "Water_Source",
      "level": 1
    },
    {
      "x": 0,
      "y": -4,
      "z": -6,
      "name": "Water_Source",
      "level": 1
    },
    {
      "x": 0,
      "y": -3,
      "z": -6,
      "name": "Water_Source",
      "level": 1
    },
    {
      "x": 0,
      "y": -2,
      "z": -6,
      "name": "Water_Source",
      "level": 1
    },
    {
      "x": 0,
      "y": -1,
      "z": -6,
      "name": "Water_Source",
      "level": 1
    },
    {
      "x": 0,
      "y": 0,
      "z": -6,
      "name": "Water_Source",
      "level": 1
    },
    {
      "x": 0,
      "y": 1,
      "z": -6,
      "name": "Water_Source",
      "level": 1
    },
    {
      "x": 0,
      "y": 2,
      "z": -6,
      "name": "Water_Source",
      "level": 1
    },
    {
      "x": 0,
      "y": 7,
      "z": -6,
      "name": "Water_Source",
      "level": 1
    },
    {
      "x": 0,
      "y": 2,
      "z": -5,
      "name": "Water_Source",
      "level": 1
    },
    {
      "x": 0,
      "y": 7,
      "z": -5,
      "name": "Water_Source",
      "level": 1
    },
    {
      "x": 0,
      "y": 1,
      "z": -4,
      "name": "Water_Source",
      "level": 1
    },
    {
      "x": 0,
      "y": 7,
      "z": -4,
      "name": "Water_Source",
      "level": 1
    },
    {
      "x": 0,
      "y": 6,
      "z": -3,
      "name": "Water_Source",
      "level": 1
    },
    {
      "x": 0,
      "y": 7,
      "z": -3,
      "name": "Water_Source",
      "level": 1
    },
    {
      "x": 0,
      "y": 4,
      "z": -2,
      "name": "Water_Source",
      "level": 1
    },
    {
      "x": 0,
      "y": 8,
      "z": -1,
      "name": "Water_Source",
      "level": 1
    },
    {
      "x": 0,
      "y": 8,
      "z": 1,
      "name": "Water_Source",
      "level": 1
    },
    {
      "x": 0,
      "y": -5,
      "z": 2,
      "name": "Water_Source",
      "level": 1
    },
    {
      "x": 0,
      "y": -4,
      "z": 2,
      "name": "Water_Source",
      "level": 1
    },
    {
      "x": 0,
      "y": -3,
      "z": 2,
      "name": "Water_Source",
      "level": 1
    },
    {
      "x": 0,
      "y": -2,
      "z": 2,
      "name": "Water_Source",
      "level": 1
    },
    {
      "x": 0,
      "y": -1,
      "z": 2,
      "name": "Water_Source",
      "level": 1
    },
    {
      "x": 0,
      "y": 0,
      "z": 2,
      "name": "Water_Source",
      "level": 1
    },
    {
      "x": 1,
      "y": -5,
      "z": -2,
      "name": "Water_Source",
      "level": 1
    },
    {
      "x": 1,
      "y": -4,
      "z": -2,
      "name": "Water_Source",
      "level": 1
    },
    {
      "x": 1,
      "y": -3,
      "z": -2,
      "name": "Water_Source",
      "level": 1
    },
    {
      "x": 1,
      "y": -2,
      "z": -2,
      "name": "Water_Source",
      "level": 1
    },
    {
      "x": 1,
      "y": -1,
      "z": -2,
      "name": "Water_Source",
      "level": 1
    },
    {
      "x": 1,
      "y": 0,
      "z": -2,
      "name": "Water_Source",
      "level": 1
    },
    {
      "x": 1,
      "y": 7,
      "z": 0,
      "name": "Water_Source",
      "level": 1
    },
    {
      "x": 1,
      "y": 1,
      "z": 1,
      "name": "Water_Source",
      "level": 1
    },
    {
      "x": 1,
      "y": 0,
      "z": 2,
      "name": "Water_Source",
      "level": 1
    },
    {
      "x": 1,
      "y": 1,
      "z": 2,
      "name": "Water_Source",
      "level": 1
    },
    {
      "x": 1,
      "y": 2,
      "z": 2,
      "name": "Water_Source",
      "level": 1
    },
    {
      "x": 1,
      "y": 3,
      "z": 2,
      "name": "Water_Source",
      "level": 1
    },
    {
      "x": 1,
      "y": 4,
      "z": 2,
      "name": "Water_Source",
      "level": 1
    },
    {
      "x": 2,
      "y": 0,
      "z": -2,
      "name": "Water_Source",
      "level": 1
    },
    {
      "x": 2,
      "y": 7,
      "z": 0,
      "name": "Water_Source",
      "level": 1
    },
    {
      "x": 2,
      "y": -5,
      "z": 2,
      "name": "Water_Source",
      "level": 1
    },
    {
      "x": 2,
      "y": -4,
      "z": 2,
      "name": "Water_Source",
      "level": 1
    },
    {
      "x": 2,
      "y": -3,
      "z": 2,
      "name": "Water_Source",
      "level": 1
    },
    {
      "x": 2,
      "y": -2,
      "z": 2,
      "name": "Water_Source",
      "level": 1
    },
    {
      "x": 2,
      "y": -1,
      "z": 2,
      "name": "Water_Source",
      "level": 1
    },
    {
      "x": 2,
      "y": 0,
      "z": 2,
      "name": "Water_Source",
      "level": 1
    },
    {
      "x": 2,
      "y": 1,
      "z": 2,
      "name": "Water_Source",
      "level": 1
    },
    {
      "x": 2,
      "y": 2,
      "z": 2,
      "name": "Water_Source",
      "level": 1
    },
    {
      "x": 3,
      "y": 1,
      "z": -2,
      "name": "Water_Source",
      "level": 1
    },
    {
      "x": 3,
      "y": 2,
      "z": -2,
      "name": "Water_Source",
      "level": 1
    },
    {
      "x": 3,
      "y": 3,
      "z": -2,
      "name": "Water_Source",
      "level": 1
    },
    {
      "x": 3,
      "y": 4,
      "z": -2,
      "name": "Water_Source",
      "level": 1
    },
    {
      "x": 3,
      "y": 4,
      "z": -1,
      "name": "Water_Source",
      "level": 1
    },
    {
      "x": 3,
      "y": 5,
      "z": 0,
      "name": "Water_Source",
      "level": 1
    },
    {
      "x": 3,
      "y": 6,
      "z": 0,
      "name": "Water_Source",
      "level": 1
    },
    {
      "x": 3,
      "y": 7,
      "z": 0,
      "name": "Water_Source",
      "level": 1
    },
    {
      "x": 3,
      "y": -5,
      "z": 1,
      "name": "Water_Source",
      "level": 1
    },
    {
      "x": 3,
      "y": -4,
      "z": 1,
      "name": "Water_Source",
      "level": 1
    },
    {
      "x": 3,
      "y": -3,
      "z": 1,
      "name": "Water_Source",
      "level": 1
    },
    {
      "x": 3,
      "y": -2,
      "z": 1,
      "name": "Water_Source",
      "level": 1
    },
    {
      "x": 3,
      "y": -1,
      "z": 1,
      "name": "Water_Source",
      "level": 1
    },
    {
      "x": 3,
      "y": 0,
      "z": 1,
      "name": "Water_Source",
      "level": 1
    },
    {
      "x": 3,
      "y": 4,
      "z": 1,
      "name": "Water_Source",
      "level": 1
    },
    {
      "x": 3,
      "y": 3,
      "z": 2,
      "name": "Water_Source",
      "level": 1
    },
    {
      "x": 3,
      "y": 4,
      "z": 2,
      "name": "Water_Source",
      "level": 1
    },
    {
      "x": 4,
      "y": -5,
      "z": -2,
      "name": "Water_Source",
      "level": 1
    },
    {
      "x": 4,
      "y": -4,
      "z": -2,
      "name": "Water_Source",
      "level": 1
    },
    {
      "x": 4,
      "y": -3,
      "z": -2,
      "name": "Water_Source",
      "level": 1
    },
    {
      "x": 4,
      "y": -2,
      "z": -2,
      "name": "Water_Source",
      "level": 1
    },
    {
      "x": 4,
      "y": -1,
      "z": -2,
      "name": "Water_Source",
      "level": 1
    },
    {
      "x": 4,
      "y": 0,
      "z": -2,
      "name": "Water_Source",
      "level": 1
    },
    {
      "x": 4,
      "y": 3,
      "z": 2,
      "name": "Water_Source",
      "level": 1
    },
    {
      "x": 5,
      "y": -5,
      "z": 2,
      "name": "Water_Source",
      "level": 1
    },
    {
      "x": 5,
      "y": -4,
      "z": 2,
      "name": "Water_Source",
      "level": 1
    },
    {
      "x": 5,
      "y": -3,
      "z": 2,
      "name": "Water_Source",
      "level": 1
    },
    {
      "x": 5,
      "y": -2,
      "z": 2,
      "name": "Water_Source",
      "level": 1
    },
    {
      "x": 5,
      "y": -1,
      "z": 2,
      "name": "Water_Source",
      "level": 1
    },
    {
      "x": 5,
      "y": 0,
      "z": 2,
      "name": "Water_Source",
      "level": 1
    },
    {
      "x": 5,
      "y": 1,
      "z": 2,
      "name": "Water_Source",
      "level": 1
    },
    {
      "x": 5,
      "y": 2,
      "z": 2,
      "name": "Water_Source",
      "level": 1
    },
    {
      "x": 5,
      "y": 3,
      "z": 2,
      "name": "Water_Source",
      "level": 1
    }
  ]
}