{
  "version": 8,
  "blockIdVersion": 11,
  "anchorX": 0,
  "anchorY": 15,
  "anchorZ": 0,
  "blocks": [
    {
      "x": -7,
      "y": 11,
      "z": -4,
      "name": "Plant_Large_Lilypad_Half"
    },
    {
      "x": -7,
      "y": 11,
      "z": -3,
      "name": "Plant_Large_Lilypad_Half"
    },
    {
      "x": -7,
      "y": 11,
      "z": -2,
      "name": "Plant_Large_Lilypad_Half"
    },
    {
      "x": -7,
      "y": 25,
      "z": 1,
      "name": "Plant_Large_Lilypad_Half"
    },
    {
      "x": -7,
      "y": 25,
      "z": 2,
      "name": "Plant_Large_Lilypad_Half"
    },
    {
      "x": -7,
      "y": 25,
      "z": 3,
      "name": "Plant_Large_Lilypad_Half"
    },
    {
      "x": -6,
      "y": 11,
      "z": -4,
      "name": "Plant_Large_Lilypad_Half"
    },
    {
      "x": -6,
      "y": 8,
      "z": -3,
      "name": "Wood_Banyan_Branch_Corner",
      "support": 15,
      "rotation": 2
    },
    {
      "x": -6,
      "y": 9,
      "z": -3,
      "name": "Wood_Banyan_Branch_Long",
      "support": 15
    },
    {
      "x": -6,
      "y": 10,
      "z": -3,
      "name": "Wood_Banyan_Branch_Long",
      "support": 15
    },
    {
      "x": -6,
      "y": 11,
      "z": -3,
      "name": "Plant_Large_Lilypad_Half"
    },
    {
      "x": -6,
      "y": 8,
      "z": -2,
      "name": "Wood_Banyan_Branch_Long",
      "support": 15,
      "rotation": 4
    },
    {
      "x": -6,
      "y": 11,
      "z": -2,
      "name": "Plant_Large_Lilypad_Half"
    },
    {
      "x": -6,
      "y": 8,
      "z": -1,
      "name": "Wood_Banyan_Branch_Long",
      "support": 15,
      "rotation": 4
    },
    {
      "x": -6,
      "y": 7,
      "z": 0,
      "name": "Wood_Banyan_Branch_Corner",
      "support": 15,
      "rotation": 3
    },
    {
      "x": -6,
      "y": 8,
      "z": 0,
      "name": "Wood_Banyan_Branch_Corner",
      "support": 15,
      "rotation": 10
    },
    {
      "x": -6,
      "y": 25,
      "z": 0,
      "name": "Plant_Large_Lilypad_Half"
    },
    {
      "x": -6,
      "y": 25,
      "z": 1,
      "name": "Plant_Large_Lilypad_Half"
    },
    {
      "x": -6,
      "y": 25,
      "z": 2,
      "name": "Plant_Large_Lilypad_Half"
    },
    {
      "x": -6,
      "y": 25,
      "z": 3,
      "name": "Plant_Large_Lilypad_Half"
    },
    {
      "x": -6,
      "y": 25,
      "z": 4,
      "name": "Plant_Large_Lilypad_Half"
    },
    {
      "x": -5,
      "y": 11,
      "z": -4,
      "name": "Plant_Large_Lilypad_Half"
    },
    {
      "x": -5,
      "y": 11,
      "z": -3,
      "name": "Plant_Large_Lilypad_Half"
    },
    {
      "x": -5,
      "y": 11,
      "z": -2,
      "name": "Plant_Large_Lilypad_Half"
    },
    {
      "x": -5,
      "y": 18,
      "z": -1,
      "name": "Plant_Large_Lilypad"
    },
    {
      "x": -5,
      "y": 19,
      "z": -1,
      "name": "Plant_Large_Lilypad_Half"
    },
    {
      "x": -5,
      "y": 7,
      "z": 0,
      "name": "Wood_Banyan_Branch_Long",
      "support": 15,
      "rotation": 5
    },
    {
      "x": -5,
      "y": 14,
      "z": 0,
      "name": "Wood_Banyan_Branch_Corner",
      "support": 15,
      "rotation": 3
    },
    {
      "x": -5,
      "y": 15,
      "z": 0,
      "name": "Wood_Banyan_Branch_Corner",
      "support": 15,
      "rotation": 8
    },
    {
      "x": -5,
      "y": 18,
      "z": 0,
      "name": "Plant_Large_Lilypad"
    },
    {
      "x": -5,
      "y": 19,
      "z": 0,
      "name": "Plant_Large_Lilypad_Half"
    },
    {
      "x": -5,
      "y": 25,
      "z": 0,
      "name": "Plant_Large_Lilypad_Half"
    },
    {
      "x": -5,
      "y": 15,
      "z": 1,
      "name": "Wood_Banyan_Branch_Long",
      "support": 15,
      "rotation": 4
    },
    {
      "x": -5,
      "y": 18,
      "z": 1,
      "name": "Plant_Large_Lilypad"
    },
    {
      "x": -5,
      "y": 19,
      "z": 1,
      "name": "Plant_Large_Lilypad_Half"
    },
    {
      "x": -5,
      "y": 25,
      "z": 1,
      "name": "Plant_Large_Lilypad_Half"
    },
    {
      "x": -5,
      "y": 15,
      "z": 2,
      "name": "Wood_Banyan_Branch_Corner",
      "support": 15
    },
    {
      "x": -5,
      "y": 16,
      "z": 2,
      "name": "Wood_Banyan_Branch_Long",
      "support": 15
    },
    {
      "x": -5,
      "y": 17,
      "z": 2,
      "name": "Wood_Banyan_Branch_Long",
      "support": 15
    },
    {
      "x": -5,
      "y": 18,
      "z": 2,
      "name": "Wood_Banyan_Branch_Long",
      "support": 15
    },
    {
      "x": -5,
      "y": 19,
      "z": 2,
      "name": "Wood_Banyan_Branch_Long",
      "support": 15
    },
    {
      "x": -5,
      "y": 20,
      "z": 2,
      "name": "Wood_Banyan_Branch_Long",
      "support": 15
    },
    {
      "x": -5,
      "y": 21,
      "z": 2,
      "name": "Wood_Banyan_Branch_Long",
      "support": 15
    },
    {
      "x": -5,
      "y": 22,
      "z": 2,
      "name": "Wood_Banyan_Branch_Long",
      "support": 15
    },
    {
      "x": -5,
      "y": 23,
      "z": 2,
      "name": "Wood_Banyan_Branch_Long",
      "support": 15
    },
    {
      "x": -5,
      "y": 24,
      "z": 2,
      "name": "Wood_Banyan_Branch_Long",
      "support": 15
    },
    {
      "x": -5,
      "y": 25,
      "z": 2,
      "name": "Plant_Large_Lilypad_Half"
    },
    {
      "x": -5,
      "y": 25,
      "z": 3,
      "name": "Plant_Large_Lilypad_Half"
    },
    {
      "x": -5,
      "y": 25,
      "z": 4,
      "name": "Plant_Large_Lilypad_Half"
    },
    {
      "x": -4,
      "y": 18,
      "z": -3,
      "name": "Plant_Large_Lilypad"
    },
    {
      "x": -4,
      "y": 19,
      "z": -3,
      "name": "Plant_Large_Lilypad_Half"
    },
    {
      "x": -4,
      "y": 18,
      "z": -2,
      "name": "Plant_Large_Lilypad"
    },
    {
      "x": -4,
      "y": 19,
      "z": -2,
      "name": "Plant_Large_Lilypad_Half"
    },
    {
      "x": -4,
      "y": 18,
      "z": -1,
      "name": "Plant_Large_Lilypad"
    },
    {
      "x": -4,
      "y": 7,
      "z": 0,
      "name": "Wood_Banyan_Branch_Long",
      "support": 15,
      "rotation": 5
    },
    {
      "x": -4,
      "y": 14,
      "z": 0,
      "name": "Wood_Banyan_Branch_Long",
      "support": 15,
      "rotation": 5
    },
    {
      "x": -4,
      "y": 18,
      "z": 0,
      "name": "Plant_Large_Lilypad"
    },
    {
      "x": -4,
      "y": 25,
      "z": 0,
      "name": "Plant_Large_Lilypad_Half"
    },
    {
      "x": -4,
      "y": 18,
      "z": 1,
      "name": "Plant_Large_Lilypad"
    },
    {
      "x": -4,
      "y": 25,
      "z": 1,
      "name": "Plant_Large_Lilypad_Half"
    },
    {
      "x": -4,
      "y": 18,
      "z": 2,
      "name": "Plant_Large_Lilypad"
    },
    {
      "x": -4,
      "y": 19,
      "z": 2,
      "name": "Plant_Large_Lilypad_Half"
    },
    {
      "x": -4,
      "y": 25,
      "z": 2,
      "name": "Plant_Large_Lilypad_Half"
    },
    {
      "x": -4,
      "y": 18,
      "z": 3,
      "name": "Plant_Large_Lilypad"
    },
    {
      "x": -4,
      "y": 19,
      "z": 3,
      "name": "Plant_Large_Lilypad_Half"
    },
    {
      "x": -4,
      "y": 25,
      "z": 3,
      "name": "Plant_Large_Lilypad_Half"
    },
    {
      "x": -4,
      "y": 25,
      "z": 4,
      "name": "Plant_Large_Lilypad_Half"
    },
    {
      "x": -4,
      "y": 22,
      "z": 6,
      "name": "Plant_Large_Lilypad_Half"
    },
    {
      "x": -4,
      "y": 22,
      "z": 7,
      "name": "Plant_Large_Lilypad_Half"
    },
    {
      "x": -3,
      "y": 18,
      "z": -4,
      "name": "Plant_Large_Lilypad"
    },
    {
      "x": -3,
      "y": 19,
      "z": -4,
      "name": "Plant_Large_Lilypad_Half"
    },
    {
      "x": -3,
      "y": 3,
      "z": -3,
      "name": "Wood_Banyan_Branch_Long",
      "support": 15
    },
    {
      "x": -3,
      "y": 4,
      "z": -3,
      "name": "Wood_Banyan_Branch_Corner",
      "support": 15,
      "rotation": 8
    },
    {
      "x": -3,
      "y": 18,
      "z": -3,
      "name": "Plant_Large_Lilypad"
    },
    {
      "x": -3,
      "y": 4,
      "z": -2,
      "name": "Wood_Banyan_Branch_Corner",
      "support": 15
    },
    {
      "x": -3,
      "y": 5,
      "z": -2,
      "name": "Wood_Banyan_Branch_Corner",
      "support": 15,
      "rotation": 8
    },
    {
      "x": -3,
      "y": 18,
      "z": -2,
      "name": "Plant_Large_Lilypad"
    },
    {
      "x": -3,
      "y": 5,
      "z": -1,
      "name": "Wood_Banyan_Branch_Long",
      "support": 15,
      "rotation": 4
    },
    {
      "x": -3,
      "y": 18,
      "z": -1,
      "name": "Plant_Large_Lilypad"
    },
    {
      "x": -3,
      "y": 1,
      "z": 0,
      "name": "Wood_Banyan_Roots"
    },
    {
      "x": -3,
      "y": 2,
      "z": 0,
      "name": "Wood_Banyan_Trunk_Full",
      "support": 15
    },
    {
      "x": -3,
      "y": 3,
      "z": 0,
      "name": "Wood_Banyan_Trunk_Full",
      "support": 15
    },
    {
      "x": -3,
      "y": 4,
      "z": 0,
      "name": "Wood_Banyan_Trunk_Full",
      "support": 15
    },
    {
      "x": -3,
      "y": 5,
      "z": 0,
      "name": "Wood_Banyan_Trunk",
      "support": 15
    },
    {
      "x": -3,
      "y": 6,
      "z": 0,
      "name": "Wood_Banyan_Trunk",
      "support": 15
    },
    {
      "x": -3,
      "y": 7,
      "z": 0,
      "name": "Wood_Banyan_Trunk",
      "support": 15
    },
    {
      "x": -3,
      "y": 8,
      "z": 0,
      "name": "Wood_Banyan_Trunk",
      "support": 15
    },
    {
      "x": -3,
      "y": 9,
      "z": 0,
      "name": "Wood_Banyan_Trunk_Full",
      "support": 15
    },
    {
      "x": -3,
      "y": 14,
      "z": 0,
      "name": "Wood_Banyan_Branch_Long",
      "support": 15,
      "rotation": 5
    },
    {
      "x": -3,
      "y": 18,
      "z": 0,
      "name": "Plant_Large_Lilypad"
    },
    {
      "x": -3,
      "y": -1,
      "z": 1,
      "name": "Wood_Banyan_Branch_Long",
      "support": 15
    },
    {
      "x": -3,
      "y": 0,
      "z": 1,
      "name": "Wood_Banyan_Branch_Long",
      "support": 15
    },
    {
      "x": -3,
      "y": 1,
      "z": 1,
      "name": "Wood_Banyan_Branch_Long",
      "support": 15
    },
    {
      "x": -3,
      "y": 2,
      "z": 1,
      "name": "Wood_Banyan_Branch_Corner",
      "support": 15,
      "rotation": 10
    },
    {
      "x": -3,
      "y": 18,
      "z": 1,
      "name": "Plant_Large_Lilypad"
    },
    {
      "x": -3,
      "y": 25,
      "z": 1,
      "name": "Plant_Large_Lilypad_Half"
    },
    {
      "x": -3,
      "y": 17,
      "z": 2,
      "name": "Wood_Banyan_Roots"
    },
    {
      "x": -3,
      "y": 18,
      "z": 2,
      "name": "Plant_Large_Lilypad"
    },
    {
      "x": -3,
      "y": 25,
      "z": 2,
      "name": "Plant_Large_Lilypad_Half"
    },
    {
      "x": -3,
      "y": 18,
      "z": 3,
      "name": "Plant_Large_Lilypad"
    },
    {
      "x": -3,
      "y": 25,
      "z": 3,
      "name": "Plant_Large_Lilypad_Half"
    },
    {
      "x": -3,
      "y": 18,
      "z": 4,
      "name": "Plant_Large_Lilypad"
    },
    {
      "x": -3,
      "y": 19,
      "z": 4,
      "name": "Plant_Large_Lilypad_Half"
    },
    {
      "x": -3,
      "y": 22,
      "z": 5,
      "name": "Plant_Large_Lilypad_Half"
    },
    {
      "x": -3,
      "y": 22,
      "z": 6,
      "name": "Plant_Large_Lilypad_Half"
    },
    {
      "x": -3,
      "y": 22,
      "z": 7,
      "name": "Plant_Large_Lilypad_Half"
    },
    {
      "x": -3,
      "y": 22,
      "z": 8,
      "name": "Plant_Large_Lilypad_Half"
    },
    {
      "x": -2,
      "y": 18,
      "z": -4,
      "name": "Plant_Large_Lilypad"
    },
    {
      "x": -2,
      "y": 19,
      "z": -4,
      "name": "Plant_Large_Lilypad_Half"
    },
    {
      "x": -2,
      "y": 18,
      "z": -3,
      "name": "Plant_Large_Lilypad"
    },
    {
      "x": -2,
      "y": 18,
      "z": -2,
      "name": "Plant_Large_Lilypad"
    },
    {
      "x": -2,
      "y": 18,
      "z": -1,
      "name": "Plant_Large_Lilypad"
    },
    {
      "x": -2,
      "y": 8,
      "z": 0,
      "name": "Wood_Banyan_Roots"
    },
    {
      "x": -2,
      "y": 9,
      "z": 0,
      "name": "Wood_Banyan_Trunk",
      "support": 15,
      "rotation": 5
    },
    {
      "x": -2,
      "y": 14,
      "z": 0,
      "name": "Wood_Banyan_Branch_Long",
      "support": 15,
      "rotation": 5
    },
    {
      "x": -2,
      "y": 18,
      "z": 0,
      "name": "Plant_Large_Lilypad"
    },
    {
      "x": -2,
      "y": 18,
      "z": 1,
      "name": "Plant_Large_Lilypad"
    },
    {
      "x": -2,
      "y": 18,
      "z": 2,
      "name": "Plant_Large_Lilypad"
    },
    {
      "x": -2,
      "y": 18,
      "z": 3,
      "name": "Plant_Large_Lilypad"
    },
    {
      "x": -2,
      "y": 15,
      "z": 4,
      "name": "Wood_Banyan_Branch_Corner",
      "support": 15,
      "rotation": 3
    },
    {
      "x": -2,
      "y": 16,
      "z": 4,
      "name": "Wood_Banyan_Branch_Corner",
      "support": 15,
      "rotation": 8
    },
    {
      "x": -2,
      "y": 18,
      "z": 4,
      "name": "Plant_Large_Lilypad"
    },
    {
      "x": -2,
      "y": 19,
      "z": 4,
      "name": "Plant_Large_Lilypad_Half"
    },
    {
      "x": -2,
      "y": 16,
      "z": 5,
      "name": "Wood_Banyan_Branch_Long",
      "support": 15,
      "rotation": 4
    },
    {
      "x": -2,
      "y": 22,
      "z": 5,
      "name": "Plant_Large_Lilypad_Half"
    },
    {
      "x": -2,
      "y": 16,
      "z": 6,
      "name": "Wood_Banyan_Branch_Corner",
      "support": 15
    },
    {
      "x": -2,
      "y": 17,
      "z": 6,
      "name": "Wood_Banyan_Branch_Long",
      "support": 15
    },
    {
      "x": -2,
      "y": 18,
      "z": 6,
      "name": "Wood_Banyan_Branch_Long",
      "support": 15
    },
    {
      "x": -2,
      "y": 19,
      "z": 6,
      "name": "Wood_Banyan_Branch_Long",
      "support": 15
    },
    {
      "x": -2,
      "y": 20,
      "z": 6,
      "name": "Wood_Banyan_Branch_Long",
      "support": 15
    },
    {
      "x": -2,
      "y": 21,
      "z": 6,
      "name": "Wood_Banyan_Branch_Long",
      "support": 15
    },
    {
      "x": -2,
      "y": 22,
      "z": 6,
      "name": "Plant_Large_Lilypad_Half"
    },
    {
      "x": -2,
      "y": 22,
      "z": 7,
      "name": "Plant_Large_Lilypad_Half"
    },
    {
      "x": -2,
      "y": 22,
      "z": 8,
      "name": "Plant_Large_Lilypad_Half"
    },
    {
      "x": -1,
      "y": 18,
      "z": -5,
      "name": "Plant_Large_Lilypad"
    },
    {
      "x": -1,
      "y": 19,
      "z": -5,
      "name": "Plant_Large_Lilypad_Half"
    },
    {
      "x": -1,
      "y": -1,
      "z": -4,
      "name": "Wood_Banyan_Branch_Long",
      "support": 15
    },
    {
      "x": -1,
      "y": 0,
      "z": -4,
      "name": "Wood_Banyan_Branch_Long",
      "support": 15
    },
    {
      "x": -1,
      "y": 1,
      "z": -4,
      "name": "Wood_Banyan_Branch_Long",
      "support": 15
    },
    {
      "x": -1,
      "y": 2,
      "z": -4,
      "name": "Wood_Banyan_Branch_Long",
      "support": 15
    },
    {
      "x": -1,
      "y": 3,
      "z": -4,
      "name": "Wood_Banyan_Branch_Long",
      "support": 15
    },
    {
      "x": -1,
      "y": 4,
      "z": -4,
      "name": "Wood_Banyan_Branch_Long",
      "support": 15
    },
    {
      "x": -1,
      "y": 5,
      "z": -4,
      "name": "Wood_Banyan_Branch_Long",
      "support": 15
    },
    {
      "x": -1,
      "y": 6,
      "z": -4,
      "name": "Wood_Banyan_Branch_Corner",
      "support": 15,
      "rotation": 8
    },
    {
      "x": -1,
      "y": 18,
      "z": -4,
      "name": "Plant_Large_Lilypad"
    },
    {
      "x": -1,
      "y": 6,
      "z": -3,
      "name": "Wood_Banyan_Branch_Long",
      "support": 15,
      "rotation": 4
    },
    {
      "x": -1,
      "y": 18,
      "z": -3,
      "name": "Plant_Large_Lilypad"
    },
    {
      "x": -1,
      "y": 5,
      "z": -2,
      "name": "Wood_Banyan_Roots"
    },
    {
      "x": -1,
      "y": 6,
      "z": -2,
      "name": "Wood_Banyan_Trunk_Full",
      "support": 15
    },
    {
      "x": -1,
      "y": 7,
      "z": -2,
      "name": "Wood_Banyan_Trunk_Full",
      "support": 15
    },
    {
      "x": -1,
      "y": 8,
      "z": -2,
      "name": "Wood_Banyan_Trunk_Full",
      "support": 15
    },
    {
      "x": -1,
      "y": 9,
      "z": -2,
      "name": "Wood_Banyan_Trunk_Full",
      "support": 15,
      "rotation": 4
    },
    {
      "x": -1,
      "y": 18,
      "z": -2,
      "name": "Plant_Large_Lilypad"
    },
    {
      "x": -1,
      "y": 9,
      "z": -1,
      "name": "Wood_Banyan_Trunk_Full",
      "support": 15,
      "rotation": 4
    },
    {
      "x": -1,
      "y": 18,
      "z": -1,
      "name": "Plant_Large_Lilypad"
    },
    {
      "x": -1,
      "y": 9,
      "z": 0,
      "name": "Wood_Banyan_Trunk",
      "support": 15,
      "rotation": 5
    },
    {
      "x": -1,
      "y": 14,
      "z": 0,
      "name": "Wood_Banyan_Branch_Long",
      "support": 15,
      "rotation": 5
    },
    {
      "x": -1,
      "y": 18,
      "z": 0,
      "name": "Plant_Large_Lilypad"
    },
    {
      "x": -1,
      "y": 18,
      "z": 1,
      "name": "Plant_Large_Lilypad"
    },
    {
      "x": -1,
      "y": 18,
      "z": 2,
      "name": "Plant_Large_Lilypad"
    },
    {
      "x": -1,
      "y": -1,
      "z": 3,
      "name": "Wood_Banyan_Branch_Long",
      "support": 15
    },
    {
      "x": -1,
      "y": 0,
      "z": 3,
      "name": "Wood_Banyan_Branch_Long",
      "support": 15
    },
    {
      "x": -1,
      "y": 1,
      "z": 3,
      "name": "Wood_Banyan_Branch_Long",
      "support": 15
    },
    {
      "x": -1,
      "y": 2,
      "z": 3,
      "name": "Wood_Banyan_Branch_Long",
      "support": 15
    },
    {
      "x": -1,
      "y": 3,
      "z": 3,
      "name": "Wood_Banyan_Branch_Long",
      "support": 15
    },
    {
      "x": -1,
      "y": 4,
      "z": 3,
      "name": "Wood_Banyan_Branch_Long",
      "support": 15
    },
    {
      "x": -1,
      "y": 5,
      "z": 3,
      "name": "Wood_Banyan_Branch_Corner",
      "support": 15,
      "rotation": 9
    },
    {
      "x": -1,
      "y": 18,
      "z": 3,
      "name": "Plant_Large_Lilypad"
    },
    {
      "x": -1,
      "y": 15,
      "z": 4,
      "name": "Wood_Banyan_Branch_Long",
      "support": 15,
      "rotation": 5
    },
    {
      "x": -1,
      "y": 18,
      "z": 4,
      "name": "Plant_Large_Lilypad"
    },
    {
      "x": -1,
      "y": 18,
      "z": 5,
      "name": "Plant_Large_Lilypad"
    },
    {
      "x": -1,
      "y": 19,
      "z": 5,
      "name": "Plant_Large_Lilypad_Half"
    },
    {
      "x": -1,
      "y": 22,
      "z": 6,
      "name": "Plant_Large_Lilypad_Half"
    },
    {
      "x": -1,
      "y": 22,
      "z": 7,
      "name": "Plant_Large_Lilypad_Half"
    },
    {
      "x": 0,
      "y": 18,
      "z": -5,
      "name": "Plant_Large_Lilypad"
    },
    {
      "x": 0,
      "y": 19,
      "z": -5,
      "name": "Plant_Large_Lilypad_Half"
    },
    {
      "x": 0,
      "y": 17,
      "z": -4,
      "name": "Wood_Banyan_Roots"
    },
    {
      "x": 0,
      "y": 18,
      "z": -4,
      "name": "Plant_Large_Lilypad"
    },
    {
      "x": 0,
      "y": 15,
      "z": -3,
      "name": "Wood_Banyan_Branch_Corner",
      "support": 15,
      "rotation": 2
    },
    {
      "x": 0,
      "y": 16,
      "z": -3,
      "name": "Wood_Banyan_Branch_Long",
      "support": 15
    },
    {
      "x": 0,
      "y": 17,
      "z": -3,
      "name": "Wood_Banyan_Branch_Long",
      "support": 15
    },
    {
      "x": 0,
      "y": 18,
      "z": -3,
      "name": "Plant_Large_Lilypad"
    },
    {
      "x": 0,
      "y": 3,
      "z": -2,
      "name": "Wood_Banyan_Branch_Long",
      "support": 15
    },
    {
      "x": 0,
      "y": 4,
      "z": -2,
      "name": "Wood_Banyan_Branch_Long",
      "support": 15
    },
    {
      "x": 0,
      "y": 5,
      "z": -2,
      "name": "Wood_Banyan_Branch_Long",
      "support": 15
    },
    {
      "x": 0,
      "y": 6,
      "z": -2,
      "name": "Wood_Banyan_Branch_Corner",
      "support": 15,
      "rotation": 11
    },
    {
      "x": 0,
      "y": 15,
      "z": -2,
      "name": "Wood_Banyan_Branch_Long",
      "support": 15,
      "rotation": 4
    },
    {
      "x": 0,
      "y": 18,
      "z": -2,
      "name": "Plant_Large_Lilypad"
    },
    {
      "x": 0,
      "y": 15,
      "z": -1,
      "name": "Wood_Banyan_Branch_Long",
      "support": 15,
      "rotation": 4
    },
    {
      "x": 0,
      "y": 17,
      "z": -1,
      "name": "Wood_Banyan_Roots"
    },
    {
      "x": 0,
      "y": 18,
      "z": -1,
      "name": "Plant_Large_Lilypad"
    },
    {
      "x": 0,
      "y": 5,
      "z": 0,
      "name": "Wood_Banyan_Branch_Long",
      "support": 15
    },
    {
      "x": 0,
      "y": 6,
      "z": 0,
      "name": "Wood_Banyan_Branch_Long",
      "support": 15
    },
    {
      "x": 0,
      "y": 7,
      "z": 0,
      "name": "Wood_Banyan_Branch_Long",
      "support": 15
    },
    {
      "x": 0,
      "y": 8,
      "z": 0,
      "name": "Wood_Banyan_Roots"
    },
    {
      "x": 0,
      "y": 9,
      "z": 0,
      "name": "Wood_Banyan_Trunk_Full",
      "support": 15
    },
    {
      "x": 0,
      "y": 10,
      "z": 0,
      "name": "Wood_Banyan_Trunk",
      "support": 15
    },
    {
      "x": 0,
      "y": 11,
      "z": 0,
      "name": "Wood_Banyan_Trunk",
      "support": 15
    },
    {
      "x": 0,
      "y": 12,
      "z": 0,
      "name": "Wood_Banyan_Trunk",
      "support": 15
    },
    {
      "x": 0,
      "y": 13,
      "z": 0,
      "name": "Wood_Banyan_Trunk",
      "support": 15
    },
    {
      "x": 0,
      "y": 14,
      "z": 0,
      "name": "Wood_Banyan_Trunk",
      "support": 15
    },
    {
      "x": 0,
      "y": 15,
      "z": 0,
      "name": "Wood_Banyan_Trunk_Full",
      "support": 15
    },
    {
      "x": 0,
      "y": 16,
      "z": 0,
      "name": "Wood_Banyan_Trunk_Full",
      "support": 15
    },
    {
      "x": 0,
      "y": 17,
      "z": 0,
      "name": "Wood_Banyan_Trunk_Full",
      "support": 15
    },
    {
      "x": 0,
      "y": 18,
      "z": 0,
      "name": "Plant_Large_Lilypad"
    },
    {
      "x": 0,
      "y": 14,
      "z": 1,
      "name": "Wood_Banyan_Branch_Long",
      "support": 15,
      "rotation": 4
    },
    {
      "x": 0,
      "y": 17,
      "z": 1,
      "name": "Wood_Banyan_Roots"
    },
    {
      "x": 0,
      "y": 18,
      "z": 1,
      "name": "Plant_Large_Lilypad"
    },
    {
      "x": 0,
      "y": 14,
      "z": 2,
      "name": "Wood_Banyan_Branch_Long",
      "support": 15,
      "rotation": 4
    },
    {
      "x": 0,
      "y": 18,
      "z": 2,
      "name": "Plant_Large_Lilypad"
    },
    {
      "x": 0,
      "y": 5,
      "z": 3,
      "name": "Wood_Banyan_Branch_Long",
      "support": 15,
      "rotation": 5
    },
    {
      "x": 0,
      "y": 14,
      "z": 3,
      "name": "Wood_Banyan_Branch_Long",
      "support": 15,
      "rotation": 4
    },
    {
      "x": 0,
      "y": 18,
      "z": 3,
      "name": "Plant_Large_Lilypad"
    },
    {
      "x": 0,
      "y": 14,
      "z": 4,
      "name": "Wood_Banyan_Branch_Corner",
      "support": 15
    },
    {
      "x": 0,
      "y": 15,
      "z": 4,
      "name": "Wood_Banyan_Branch_Corner",
      "support": 15,
      "rotation": 11
    },
    {
      "x": 0,
      "y": 18,
      "z": 4,
      "name": "Plant_Large_Lilypad"
    },
    {
      "x": 0,
      "y": 18,
      "z": 5,
      "name": "Plant_Large_Lilypad"
    },
    {
      "x": 0,
      "y": 19,
      "z": 5,
      "name": "Plant_Large_Lilypad_Half"
    },
    {
      "x": 1,
      "y": 18,
      "z": -5,
      "name": "Plant_Large_Lilypad"
    },
    {
      "x": 1,
      "y": 19,
      "z": -5,
      "name": "Plant_Large_Lilypad_Half"
    },
    {
      "x": 1,
      "y": 18,
      "z": -4,
      "name": "Plant_Large_Lilypad"
    },
    {
      "x": 1,
      "y": 18,
      "z": -3,
      "name": "Plant_Large_Lilypad"
    },
    {
      "x": 1,
      "y": 18,
      "z": -2,
      "name": "Plant_Large_Lilypad"
    },
    {
      "x": 1,
      "y": 17,
      "z": -1,
      "name": "Wood_Banyan_Roots"
    },
    {
      "x": 1,
      "y": 18,
      "z": -1,
      "name": "Plant_Large_Lilypad"
    },
    {
      "x": 1,
      "y": 11,
      "z": 0,
      "name": "Wood_Banyan_Trunk",
      "support": 15,
      "rotation": 5
    },
    {
      "x": 1,
      "y": 16,
      "z": 0,
      "name": "Wood_Banyan_Branch_Long",
      "support": 15,
      "rotation": 5
    },
    {
      "x": 1,
      "y": 18,
      "z": 0,
      "name": "Plant_Large_Lilypad"
    },
    {
      "x": 1,
      "y": 18,
      "z": 1,
      "name": "Plant_Large_Lilypad"
    },
    {
      "x": 1,
      "y": 18,
      "z": 2,
      "name": "Plant_Large_Lilypad"
    },
    {
      "x": 1,
      "y": 5,
      "z": 3,
      "name": "Wood_Banyan_Branch_Corner",
      "support": 15,
      "rotation": 1
    },
    {
      "x": 1,
      "y": 6,
      "z": 3,
      "name": "Wood_Banyan_Branch_Corner",
      "support": 15,
      "rotation": 9
    },
    {
      "x": 1,
      "y": 17,
      "z": 3,
      "name": "Wood_Banyan_Roots"
    },
    {
      "x": 1,
      "y": 18,
      "z": 3,
      "name": "Plant_Large_Lilypad"
    },
    {
      "x": 1,
      "y": 18,
      "z": 4,
      "name": "Plant_Large_Lilypad"
    },
    {
      "x": 1,
      "y": 18,
      "z": 5,
      "name": "Plant_Large_Lilypad"
    },
    {
      "x": 1,
      "y": 19,
      "z": 5,
      "name": "Plant_Large_Lilypad_Half"
    },
    {
      "x": 2,
      "y": 14,
      "z": -7,
      "name": "Plant_Large_Lilypad"
    },
    {
      "x": 2,
      "y": 15,
      "z": -7,
      "name": "Plant_Large_Lilypad_Half"
    },
    {
      "x": 2,
      "y": 14,
      "z": -6,
      "name": "Plant_Large_Lilypad"
    },
    {
      "x": 2,
      "y": 15,
      "z": -6,
      "name": "Plant_Large_Lilypad_Half"
    },
    {
      "x": 2,
      "y": 14,
      "z": -5,
      "name": "Plant_Large_Lilypad"
    },
    {
      "x": 2,
      "y": 15,
      "z": -5,
      "name": "Plant_Large_Lilypad_Half"
    },
    {
      "x": 2,
      "y": 18,
      "z": -4,
      "name": "Plant_Large_Lilypad"
    },
    {
      "x": 2,
      "y": 19,
      "z": -4,
      "name": "Plant_Large_Lilypad_Half"
    },
    {
      "x": 2,
      "y": 18,
      "z": -3,
      "name": "Plant_Large_Lilypad"
    },
    {
      "x": 2,
      "y": 18,
      "z": -2,
      "name": "Plant_Large_Lilypad"
    },
    {
      "x": 2,
      "y": 3,
      "z": -1,
      "name": "Wood_Banyan_Branch_Long",
      "support": 15
    },
    {
      "x": 2,
      "y": 4,
      "z": -1,
      "name": "Wood_Banyan_Branch_Long",
      "support": 15
    },
    {
      "x": 2,
      "y": 5,
      "z": -1,
      "name": "Wood_Banyan_Branch_Long",
      "support": 15
    },
    {
      "x": 2,
      "y": 6,
      "z": -1,
      "name": "Wood_Banyan_Branch_Corner",
      "support": 15,
      "rotation": 9
    },
    {
      "x": 2,
      "y": 18,
      "z": -1,
      "name": "Plant_Large_Lilypad"
    },
    {
      "x": 2,
      "y": 9,
      "z": 0,
      "name": "Wood_Banyan_Roots"
    },
    {
      "x": 2,
      "y": 10,
      "z": 0,
      "name": "Wood_Banyan_Trunk_Full",
      "support": 15
    },
    {
      "x": 2,
      "y": 11,
      "z": 0,
      "name": "Wood_Banyan_Trunk_Full",
      "support": 15
    },
    {
      "x": 2,
      "y": 16,
      "z": 0,
      "name": "Wood_Banyan_Branch_Corner",
      "support": 15,
      "rotation": 1
    },
    {
      "x": 2,
      "y": 17,
      "z": 0,
      "name": "Wood_Banyan_Branch_Long",
      "support": 15
    },
    {
      "x": 2,
      "y": 18,
      "z": 0,
      "name": "Plant_Large_Lilypad"
    },
    {
      "x": 2,
      "y": 18,
      "z": 1,
      "name": "Plant_Large_Lilypad"
    },
    {
      "x": 2,
      "y": 18,
      "z": 2,
      "name": "Plant_Large_Lilypad"
    },
    {
      "x": 2,
      "y": 6,
      "z": 3,
      "name": "Wood_Banyan_Branch_Long",
      "support": 15,
      "rotation": 5
    },
    {
      "x": 2,
      "y": 18,
      "z": 3,
      "name": "Plant_Large_Lilypad"
    },
    {
      "x": 2,
      "y": 18,
      "z": 4,
      "name": "Plant_Large_Lilypad"
    },
    {
      "x": 2,
      "y": 19,
      "z": 4,
      "name": "Plant_Large_Lilypad_Half"
    },
    {
      "x": 3,
      "y": 14,
      "z": -8,
      "name": "Plant_Large_Lilypad"
    },
    {
      "x": 3,
      "y": 15,
      "z": -8,
      "name": "Plant_Large_Lilypad_Half"
    },
    {
      "x": 3,
      "y": 14,
      "z": -7,
      "name": "Plant_Large_Lilypad"
    },
    {
      "x": 3,
      "y": 14,
      "z": -6,
      "name": "Plant_Large_Lilypad"
    },
    {
      "x": 3,
      "y": 14,
      "z": -5,
      "name": "Plant_Large_Lilypad"
    },
    {
      "x": 3,
      "y": 14,
      "z": -4,
      "name": "Plant_Large_Lilypad"
    },
    {
      "x": 3,
      "y": 15,
      "z": -4,
      "name": "Plant_Large_Lilypad_Half"
    },
    {
      "x": 3,
      "y": 18,
      "z": -4,
      "name": "Plant_Large_Lilypad"
    },
    {
      "x": 3,
      "y": 19,
      "z": -4,
      "name": "Plant_Large_Lilypad_Half"
    },
    {
      "x": 3,
      "y": 0,
      "z": -3,
      "name": "Wood_Banyan_Roots"
    },
    {
      "x": 3,
      "y": 1,
      "z": -3,
      "name": "Wood_Banyan_Trunk_Full",
      "support": 15
    },
    {
      "x": 3,
      "y": 2,
      "z": -3,
      "name": "Wood_Banyan_Trunk",
      "support": 15
    },
    {
      "x": 3,
      "y": 3,
      "z": -3,
      "name": "Wood_Banyan_Trunk",
      "support": 15
    },
    {
      "x": 3,
      "y": 4,
      "z": -3,
      "name": "Wood_Banyan_Trunk",
      "support": 15
    },
    {
      "x": 3,
      "y": 5,
      "z": -3,
      "name": "Wood_Banyan_Trunk_Full",
      "support": 15
    },
    {
      "x": 3,
      "y": 6,
      "z": -3,
      "name": "Wood_Banyan_Trunk_Full",
      "support": 15
    },
    {
      "x": 3,
      "y": 7,
      "z": -3,
      "name": "Wood_Banyan_Branch_Long",
      "support": 15
    },
    {
      "x": 3,
      "y": 8,
      "z": -3,
      "name": "Wood_Banyan_Branch_Long",
      "support": 15
    },
    {
      "x": 3,
      "y": 9,
      "z": -3,
      "name": "Wood_Banyan_Branch_Corner",
      "support": 15,
      "rotation": 9
    },
    {
      "x": 3,
      "y": 18,
      "z": -3,
      "name": "Plant_Large_Lilypad"
    },
    {
      "x": 3,
      "y": 6,
      "z": -2,
      "name": "Wood_Banyan_Trunk_Full",
      "support": 15,
      "rotation": 4
    },
    {
      "x": 3,
      "y": 17,
      "z": -2,
      "name": "Wood_Banyan_Roots"
    },
    {
      "x": 3,
      "y": 18,
      "z": -2,
      "name": "Plant_Large_Lilypad"
    },
    {
      "x": 3,
      "y": 6,
      "z": -1,
      "name": "Wood_Banyan_Trunk_Full",
      "support": 15,
      "rotation": 4
    },
    {
      "x": 3,
      "y": 18,
      "z": -1,
      "name": "Plant_Large_Lilypad"
    },
    {
      "x": 3,
      "y": 5,
      "z": 0,
      "name": "Wood_Banyan_Roots"
    },
    {
      "x": 3,
      "y": 6,
      "z": 0,
      "name": "Wood_Banyan_Trunk_Full",
      "support": 15
    },
    {
      "x": 3,
      "y": 7,
      "z": 0,
      "name": "Wood_Banyan_Trunk",
      "support": 15
    },
    {
      "x": 3,
      "y": 8,
      "z": 0,
      "name": "Wood_Banyan_Trunk",
      "support": 15
    },
    {
      "x": 3,
      "y": 9,
      "z": 0,
      "name": "Wood_Banyan_Trunk",
      "support": 15
    },
    {
      "x": 3,
      "y": 10,
      "z": 0,
      "name": "Wood_Banyan_Trunk_Full",
      "support": 15
    },
    {
      "x": 3,
      "y": 18,
      "z": 0,
      "name": "Plant_Large_Lilypad"
    },
    {
      "x": 3,
      "y": 8,
      "z": 1,
      "name": "Wood_Banyan_Trunk",
      "support": 15,
      "rotation": 4
    },
    {
      "x": 3,
      "y": 18,
      "z": 1,
      "name": "Plant_Large_Lilypad"
    },
    {
      "x": 3,
      "y": 6,
      "z": 2,
      "name": "Wood_Banyan_Roots"
    },
    {
      "x": 3,
      "y": 7,
      "z": 2,
      "name": "Wood_Banyan_Trunk_Full",
      "support": 15
    },
    {
      "x": 3,
      "y": 8,
      "z": 2,
      "name": "Wood_Banyan_Trunk_Full",
      "support": 15
    },
    {
      "x": 3,
      "y": 18,
      "z": 2,
      "name": "Plant_Large_Lilypad"
    },
    {
      "x": 3,
      "y": 2,
      "z": 3,
      "name": "Wood_Banyan_Roots"
    },
    {
      "x": 3,
      "y": 3,
      "z": 3,
      "name": "Wood_Banyan_Trunk",
      "support": 15
    },
    {
      "x": 3,
      "y": 4,
      "z": 3,
      "name": "Wood_Banyan_Trunk",
      "support": 15
    },
    {
      "x": 3,
      "y": 5,
      "z": 3,
      "name": "Wood_Banyan_Trunk",
      "support": 15
    },
    {
      "x": 3,
      "y": 6,
      "z": 3,
      "name": "Wood_Banyan_Trunk",
      "support": 15
    },
    {
      "x": 3,
      "y": 7,
      "z": 3,
      "name": "Wood_Banyan_Trunk_Full",
      "support": 15
    },
    {
      "x": 3,
      "y": 18,
      "z": 3,
      "name": "Plant_Large_Lilypad"
    },
    {
      "x": 3,
      "y": 7,
      "z": 4,
      "name": "Wood_Banyan_Branch_Long",
      "support": 15,
      "rotation": 4
    },
    {
      "x": 3,
      "y": 18,
      "z": 4,
      "name": "Plant_Large_Lilypad"
    },
    {
      "x": 3,
      "y": 19,
      "z": 4,
      "name": "Plant_Large_Lilypad_Half"
    },
    {
      "x": 3,
      "y": 7,
      "z": 5,
      "name": "Wood_Banyan_Branch_Long",
      "support": 15,
      "rotation": 4
    },
    {
      "x": 3,
      "y": 4,
      "z": 6,
      "name": "Wood_Banyan_Branch_Long",
      "support": 15
    },
    {
      "x": 3,
      "y": 5,
      "z": 6,
      "name": "Wood_Banyan_Branch_Long",
      "support": 15
    },
    {
      "x": 3,
      "y": 6,
      "z": 6,
      "name": "Wood_Banyan_Branch_Long",
      "support": 15
    },
    {
      "x": 3,
      "y": 7,
      "z": 6,
      "name": "Wood_Banyan_Branch_Corner",
      "support": 15,
      "rotation": 10
    },
    {
      "x": 4,
      "y": 14,
      "z": -8,
      "name": "Plant_Large_Lilypad"
    },
    {
      "x": 4,
      "y": 15,
      "z": -8,
      "name": "Plant_Large_Lilypad_Half"
    },
    {
      "x": 4,
      "y": 14,
      "z": -7,
      "name": "Plant_Large_Lilypad"
    },
    {
      "x": 4,
      "y": 9,
      "z": -6,
      "name": "Wood_Banyan_Roots"
    },
    {
      "x": 4,
      "y": 10,
      "z": -6,
      "name": "Wood_Banyan_Trunk",
      "support": 15
    },
    {
      "x": 4,
      "y": 11,
      "z": -6,
      "name": "Wood_Banyan_Trunk",
      "support": 15
    },
    {
      "x": 4,
      "y": 12,
      "z": -6,
      "name": "Wood_Banyan_Trunk",
      "support": 15
    },
    {
      "x": 4,
      "y": 13,
      "z": -6,
      "name": "Wood_Banyan_Trunk",
      "support": 15
    },
    {
      "x": 4,
      "y": 14,
      "z": -6,
      "name": "Plant_Large_Lilypad"
    },
    {
      "x": 4,
      "y": 15,
      "z": -6,
      "name": "Plant_Flower_Lotus_Purple",
      "support": 15
    },
    {
      "x": 4,
      "y": 10,
      "z": -5,
      "name": "Wood_Banyan_Branch_Long",
      "support": 15,
      "rotation": 4
    },
    {
      "x": 4,
      "y": 14,
      "z": -5,
      "name": "Plant_Large_Lilypad"
    },
    {
      "x": 4,
      "y": 10,
      "z": -4,
      "name": "Wood_Banyan_Branch_Long",
      "support": 15,
      "rotation": 4
    },
    {
      "x": 4,
      "y": 14,
      "z": -4,
      "name": "Plant_Large_Lilypad"
    },
    {
      "x": 4,
      "y": 15,
      "z": -4,
      "name": "Plant_Large_Lilypad_Half"
    },
    {
      "x": 4,
      "y": 9,
      "z": -3,
      "name": "Wood_Banyan_Branch_Corner",
      "support": 15,
      "rotation": 1
    },
    {
      "x": 4,
      "y": 10,
      "z": -3,
      "name": "Wood_Banyan_Branch_Corner",
      "support": 15,
      "rotation": 10
    },
    {
      "x": 4,
      "y": 18,
      "z": -3,
      "name": "Plant_Large_Lilypad"
    },
    {
      "x": 4,
      "y": 19,
      "z": -3,
      "name": "Plant_Large_Lilypad_Half"
    },
    {
      "x": 4,
      "y": 18,
      "z": -2,
      "name": "Plant_Large_Lilypad"
    },
    {
      "x": 4,
      "y": 19,
      "z": -2,
      "name": "Plant_Large_Lilypad_Half"
    },
    {
      "x": 4,
      "y": 18,
      "z": -1,
      "name": "Plant_Large_Lilypad"
    },
    {
      "x": 4,
      "y": 18,
      "z": 0,
      "name": "Plant_Large_Lilypad"
    },
    {
      "x": 4,
      "y": 18,
      "z": 1,
      "name": "Plant_Large_Lilypad"
    },
    {
      "x": 4,
      "y": 13,
      "z": 2,
      "name": "Plant_Large_Lilypad"
    },
    {
      "x": 4,
      "y": 18,
      "z": 2,
      "name": "Plant_Large_Lilypad"
    },
    {
      "x": 4,
      "y": 19,
      "z": 2,
      "name": "Plant_Large_Lilypad_Half"
    },
    {
      "x": 4,
      "y": 4,
      "z": 3,
      "name": "Wood_Banyan_Branch_Long",
      "support": 15
    },
    {
      "x": 4,
      "y": 5,
      "z": 3,
      "name": "Wood_Banyan_Branch_Long",
      "support": 15
    },
    {
      "x": 4,
      "y": 6,
      "z": 3,
      "name": "Wood_Banyan_Branch_Corner",
      "support": 15,
      "rotation": 11
    },
    {
      "x": 4,
      "y": 13,
      "z": 3,
      "name": "Plant_Large_Lilypad"
    },
    {
      "x": 4,
      "y": 14,
      "z": 3,
      "name": "Plant_Reeds_Marsh",
      "support": 15
    },
    {
      "x": 4,
      "y": 18,
      "z": 3,
      "name": "Plant_Large_Lilypad"
    },
    {
      "x": 4,
      "y": 19,
      "z": 3,
      "name": "Plant_Large_Lilypad_Half"
    },
    {
      "x": 5,
      "y": 14,
      "z": -8,
      "name": "Plant_Large_Lilypad"
    },
    {
      "x": 5,
      "y": 15,
      "z": -8,
      "name": "Plant_Large_Lilypad_Half"
    },
    {
      "x": 5,
      "y": 14,
      "z": -7,
      "name": "Plant_Large_Lilypad"
    },
    {
      "x": 5,
      "y": 14,
      "z": -6,
      "name": "Plant_Large_Lilypad"
    },
    {
      "x": 5,
      "y": 14,
      "z": -5,
      "name": "Plant_Large_Lilypad"
    },
    {
      "x": 5,
      "y": 14,
      "z": -4,
      "name": "Plant_Large_Lilypad"
    },
    {
      "x": 5,
      "y": 15,
      "z": -4,
      "name": "Plant_Large_Lilypad_Half"
    },
    {
      "x": 5,
      "y": 18,
      "z": -1,
      "name": "Plant_Large_Lilypad"
    },
    {
      "x": 5,
      "y": 19,
      "z": -1,
      "name": "Plant_Large_Lilypad_Half"
    },
    {
      "x": 5,
      "y": 18,
      "z": 0,
      "name": "Plant_Large_Lilypad"
    },
    {
      "x": 5,
      "y": 19,
      "z": 0,
      "name": "Plant_Large_Lilypad_Half"
    },
    {
      "x": 5,
      "y": 13,
      "z": 1,
      "name": "Plant_Large_Lilypad"
    },
    {
      "x": 5,
      "y": 18,
      "z": 1,
      "name": "Plant_Large_Lilypad"
    },
    {
      "x": 5,
      "y": 19,
      "z": 1,
      "name": "Plant_Large_Lilypad_Half"
    },
    {
      "x": 5,
      "y": 13,
      "z": 2,
      "name": "Plant_Large_Lilypad"
    },
    {
      "x": 5,
      "y": 14,
      "z": 2,
      "name": "Plant_Reeds_Marsh",
      "support": 15
    },
    {
      "x": 5,
      "y": 13,
      "z": 3,
      "name": "Plant_Large_Lilypad"
    },
    {
      "x": 5,
      "y": 14,
      "z": 3,
      "name": "Plant_Fern_Jungle",
      "support": 15
    },
    {
      "x": 5,
      "y": 13,
      "z": 4,
      "name": "Plant_Large_Lilypad"
    },
    {
      "x": 6,
      "y": 14,
      "z": -7,
      "name": "Plant_Large_Lilypad"
    },
    {
      "x": 6,
      "y": 15,
      "z": -7,
      "name": "Plant_Large_Lilypad_Half"
    },
    {
      "x": 6,
      "y": 14,
      "z": -6,
      "name": "Plant_Large_Lilypad"
    },
    {
      "x": 6,
      "y": 15,
      "z": -6,
      "name": "Plant_Large_Lilypad_Half"
    },
    {
      "x": 6,
      "y": 14,
      "z": -5,
      "name": "Plant_Large_Lilypad"
    },
    {
      "x": 6,
      "y": 15,
      "z": -5,
      "name": "Plant_Large_Lilypad_Half"
    },
    {
      "x": 6,
      "y": 13,
      "z": 1,
      "name": "Plant_Large_Lilypad"
    },
    {
      "x": 6,
      "y": 14,
      "z": 1,
      "name": "Plant_Reeds_Marsh",
      "support": 15
    },
    {
      "x": 6,
      "y": 13,
      "z": 2,
      "name": "Plant_Large_Lilypad"
    },
    {
      "x": 6,
      "y": 14,
      "z": 2,
      "name": "Plant_Reeds_Arid",
      "support": 15
    },
    {
      "x": 6,
      "y": 15,
      "z": 2,
      "name": "Plant_Reeds_Arid",
      "filler": 1024
    },
    {
      "x": 6,
      "y": 13,
      "z": 3,
      "name": "Plant_Large_Lilypad"
    },
    {
      "x": 6,
      "y": 13,
      "z": 4,
      "name": "Plant_Large_Lilypad"
    },
    {
      "x": 6,
      "y": 14,
      "z": 4,
      "name": "Plant_Reeds_Arid",
      "support": 15
    },
    {
      "x": 6,
      "y": 15,
      "z": 4,
      "name": "Plant_Reeds_Arid",
      "filler": 1024
    },
    {
      "x": 7,
      "y": 13,
      "z": 2,
      "name": "Plant_Large_Lilypad"
    },
    {
      "x": 7,
      "y": 13,
      "z": 3,
      "name": "Plant_Large_Lilypad"
    }
  ],
  "fluids": [
    {
      "x": -7,
      "y": 11,
      "z": -4,
      "name": "Water_Source",
      "level": 1
    },
    {
      "x": -7,
      "y": 11,
      "z": -3,
      "name": "Water_Source",
      "level": 1
    },
    {
      "x": -7,
      "y": 11,
      "z": -2,
      "name": "Water_Source",
      "level": 1
    },
    {
      "x": -6,
      "y": 11,
      "z": -4,
      "name": "Water_Source",
      "level": 1
    },
    {
      "x": -6,
      "y": 8,
      "z": -3,
      "name": "Water_Source",
      "level": 1
    },
    {
      "x": -6,
      "y": 9,
      "z": -3,
      "name": "Water_Source",
      "level": 1
    },
    {
      "x": -6,
      "y": 10,
      "z": -3,
      "name": "Water_Source",
      "level": 1
    },
    {
      "x": -6,
      "y": 11,
      "z": -3,
      "name": "Water_Source",
      "level": 1
    },
    {
      "x": -6,
      "y": 8,
      "z": -2,
      "name": "Water_Source",
      "level": 1
    },
    {
      "x": -6,
      "y": 11,
      "z": -2,
      "name": "Water_Source",
      "level": 1
    },
    {
      "x": -6,
      "y": 8,
      "z": -1,
      "name": "Water_Source",
      "level": 1
    },
    {
      "x": -6,
      "y": 7,
      "z": 0,
      "name": "Water_Source",
      "level": 1
    },
    {
      "x": -6,
      "y": 8,
      "z": 0,
      "name": "Water_Source",
      "level": 1
    },
    {
      "x": -5,
      "y": 11,
      "z": -4,
      "name": "Water_Source",
      "level": 1
    },
    {
      "x": -5,
      "y": 11,
      "z": -3,
      "name": "Water_Source",
      "level": 1
    },
    {
      "x": -5,
      "y": 11,
      "z": -2,
      "name": "Water_Source",
      "level": 1
    },
    {
      "x": -5,
      "y": 7,
      "z": 0,
      "name": "Water_Source",
      "level": 1
    },
    {
      "x": -5,
      "y": 14,
      "z": 0,
      "name": "Water_Source",
      "level": 1
    },
    {
      "x": -4,
      "y": 7,
      "z": 0,
      "name": "Water_Source",
      "level": 1
    },
    {
      "x": -4,
      "y": 14,
      "z": 0,
      "name": "Water_Source",
      "level": 1
    },
    {
      "x": -3,
      "y": 3,
      "z": -3,
      "name": "Water_Source",
      "level": 1
    },
    {
      "x": -3,
      "y": 4,
      "z": -3,
      "name": "Water_Source",
      "level": 1
    },
    {
      "x": -3,
      "y": 4,
      "z": -2,
      "name": "Water_Source",
      "level": 1
    },
    {
      "x": -3,
      "y": 5,
      "z": -2,
      "name": "Water_Source",
      "level": 1
    },
    {
      "x": -3,
      "y": 5,
      "z": -1,
      "name": "Water_Source",
      "level": 1
    },
    {
      "x": -3,
      "y": 1,
      "z": 0,
      "name": "Water_Source",
      "level": 1
    },
    {
      "x": -3,
      "y": 14,
      "z": 0,
      "name": "Water_Source",
      "level": 1
    },
    {
      "x": -3,
      "y": -1,
      "z": 1,
      "name": "Water_Source",
      "level": 1
    },
    {
      "x": -3,
      "y": 0,
      "z": 1,
      "name": "Water_Source",
      "level": 1
    },
    {
      "x": -3,
      "y": 1,
      "z": 1,
      "name": "Water_Source",
      "level": 1
    },
    {
      "x": -3,
      "y": 2,
      "z": 1,
      "name": "Water_Source",
      "level": 1
    },
    {
      "x": -2,
      "y": 8,
      "z": 0,
      "name": "Water_Source",
      "level": 1
    },
    {
      "x": -2,
      "y": 14,
      "z": 0,
      "name": "Water_Source",
      "level": 1
    },
    {
      "x": -1,
      "y": -1,
      "z": -4,
      "name": "Water_Source",
      "level": 1
    },
    {
      "x": -1,
      "y": 0,
      "z": -4,
      "name": "Water_Source",
      "level": 1
    },
    {
      "x": -1,
      "y": 1,
      "z": -4,
      "name": "Water_Source",
      "level": 1
    },
    {
      "x": -1,
      "y": 2,
      "z": -4,
      "name": "Water_Source",
      "level": 1
    },
    {
      "x": -1,
      "y": 3,
      "z": -4,
      "name": "Water_Source",
      "level": 1
    },
    {
      "x": -1,
      "y": 4,
      "z": -4,
      "name": "Water_Source",
      "level": 1
    },
    {
      "x": -1,
      "y": 5,
      "z": -4,
      "name": "Water_Source",
      "level": 1
    },
    {
      "x": -1,
      "y": 6,
      "z": -4,
      "name": "Water_Source",
      "level": 1
    },
    {
      "x": -1,
      "y": 6,
      "z": -3,
      "name": "Water_Source",
      "level": 1
    },
    {
      "x": -1,
      "y": 5,
      "z": -2,
      "name": "Water_Source",
      "level": 1
    },
    {
      "x": -1,
      "y": 14,
      "z": 0,
      "name": "Water_Source",
      "level": 1
    },
    {
      "x": -1,
      "y": -1,
      "z": 3,
      "name": "Water_Source",
      "level": 1
    },
    {
      "x": -1,
      "y": 0,
      "z": 3,
      "name": "Water_Source",
      "level": 1
    },
    {
      "x": -1,
      "y": 1,
      "z": 3,
      "name": "Water_Source",
      "level": 1
    },
    {
      "x": -1,
      "y": 2,
      "z": 3,
      "name": "Water_Source",
      "level": 1
    },
    {
      "x": -1,
      "y": 3,
      "z": 3,
      "name": "Water_Source",
      "level": 1
    },
    {
      "x": -1,
      "y": 4,
      "z": 3,
      "name": "Water_Source",
      "level": 1
    },
    {
      "x": -1,
      "y": 5,
      "z": 3,
      "name": "Water_Source",
      "level": 1
    },
    {
      "x": 0,
      "y": 3,
      "z": -2,
      "name": "Water_Source",
      "level": 1
    },
    {
      "x": 0,
      "y": 4,
      "z": -2,
      "name": "Water_Source",
      "level": 1
    },
    {
      "x": 0,
      "y": 5,
      "z": -2,
      "name": "Water_Source",
      "level": 1
    },
    {
      "x": 0,
      "y": 6,
      "z": -2,
      "name": "Water_Source",
      "level": 1
    },
    {
      "x": 0,
      "y": 8,
      "z": 0,
      "name": "Water_Source",
      "level": 1
    },
    {
      "x": 0,
      "y": 14,
      "z": 1,
      "name": "Water_Source",
      "level": 1
    },
    {
      "x": 0,
      "y": 14,
      "z": 2,
      "name": "Water_Source",
      "level": 1
    },
    {
      "x": 0,
      "y": 5,
      "z": 3,
      "name": "Water_Source",
      "level": 1
    },
    {
      "x": 0,
      "y": 14,
      "z": 3,
      "name": "Water_Source",
      "level": 1
    },
    {
      "x": 0,
      "y": 14,
      "z": 4,
      "name": "Water_Source",
      "level": 1
    },
    {
      "x": 1,
      "y": 5,
      "z": 3,
      "name": "Water_Source",
      "level": 1
    },
    {
      "x": 1,
      "y": 6,
      "z": 3,
      "name": "Water_Source",
      "level": 1
    },
    {
      "x": 2,
      "y": 3,
      "z": -1,
      "name": "Water_Source",
      "level": 1
    },
    {
      "x": 2,
      "y": 4,
      "z": -1,
      "name": "Water_Source",
      "level": 1
    },
    {
      "x": 2,
      "y": 5,
      "z": -1,
      "name": "Water_Source",
      "level": 1
    },
    {
      "x": 2,
      "y": 6,
      "z": -1,
      "name": "Water_Source",
      "level": 1
    },
    {
      "x": 2,
      "y": 9,
      "z": 0,
      "name": "Water_Source",
      "level": 1
    },
    {
      "x": 2,
      "y": 6,
      "z": 3,
      "name": "Water_Source",
      "level": 1
    },
    {
      "x": 3,
      "y": 0,
      "z": -3,
      "name": "Water_Source",
      "level": 1
    },
    {
      "x": 3,
      "y": 7,
      "z": -3,
      "name": "Water_Source",
      "level": 1
    },
    {
      "x": 3,
      "y": 8,
      "z": -3,
      "name": "Water_Source",
      "level": 1
    },
    {
      "x": 3,
      "y": 9,
      "z": -3,
      "name": "Water_Source",
      "level": 1
    },
    {
      "x": 3,
      "y": 5,
      "z": 0,
      "name": "Water_Source",
      "level": 1
    },
    {
      "x": 3,
      "y": 6,
      "z": 2,
      "name": "Water_Source",
      "level": 1
    },
    {
      "x": 3,
      "y": 2,
      "z": 3,
      "name": "Water_Source",
      "level": 1
    },
    {
      "x": 3,
      "y": 4,
      "z": 3,
      "name": "Water_Source",
      "level": 1
    },
    {
      "x": 3,
      "y": 7,
      "z": 4,
      "name": "Water_Source",
      "level": 1
    },
    {
      "x": 3,
      "y": 7,
      "z": 5,
      "name": "Water_Source",
      "level": 1
    },
    {
      "x": 3,
      "y": 4,
      "z": 6,
      "name": "Water_Source",
      "level": 1
    },
    {
      "x": 3,
      "y": 5,
      "z": 6,
      "name": "Water_Source",
      "level": 1
    },
    {
      "x": 3,
      "y": 6,
      "z": 6,
      "name": "Water_Source",
      "level": 1
    },
    {
      "x": 3,
      "y": 7,
      "z": 6,
      "name": "Water_Source",
      "level": 1
    },
    {
      "x": 4,
      "y": 9,
      "z": -6,
      "name": "Water_Source",
      "level": 1
    },
    {
      "x": 4,
      "y": 10,
      "z": -5,
      "name": "Water_Source",
      "level": 1
    },
    {
      "x": 4,
      "y": 10,
      "z": -4,
      "name": "Water_Source",
      "level": 1
    },
    {
      "x": 4,
      "y": 9,
      "z": -3,
      "name": "Water_Source",
      "level": 1
    },
    {
      "x": 4,
      "y": 10,
      "z": -3,
      "name": "Water_Source",
      "level": 1
    },
    {
      "x": 4,
      "y": 4,
      "z": 3,
      "name": "Water_Source",
      "level": 1
    },
    {
      "x": 4,
      "y": 5,
      "z": 3,
      "name": "Water_Source",
      "level": 1
    },
    {
      "x": 4,
      "y": 6,
      "z": 3,
      "name": "Water_Source",
      "level": 1
    }
  ]
}