{
  "version": 8,
  "blockIdVersion": 11,
  "anchorX": 1,
  "anchorY": 6,
  "anchorZ": 0,
  "blocks": [
    {
      "x": -1,
      "y": 6,
      "z": 2,
      "name": "Plant_Crop_Mushroom_Block_Blue_Branch",
      "support": 15
    },
    {
      "x": -1,
      "y": 7,
      "z": 2,
      "name": "Plant_Crop_Mushroom_Block_Blue_Branch",
      "support": 15
    },
    {
      "x": 0,
      "y": 1,
      "z": 0,
      "name": "Plant_Crop_Mushroom_Block_Blue_Mycelium"
    },
    {
      "x": 0,
      "y": 2,
      "z": 0,
      "name": "Plant_Crop_Mushroom_Block_Blue_Branch",
      "support": 15
    },
    {
      "x": 0,
      "y": 3,
      "z": 0,
      "name": "Plant_Crop_Mushroom_Block_Blue_Branch",
      "support": 15
    },
    {
      "x": 0,
      "y": 6,
      "z": 0,
      "name": "Plant_Crop_Mushroom_Block_Blue_Trunk"
    },
    {
      "x": 1,
      "y": 1,
      "z": -1,
      "name": "Plant_Crop_Mushroom_Block_Blue_Mycelium"
    },
    {
      "x": 1,
      "y": 2,
      "z": -1,
      "name": "Plant_Crop_Mushroom_Block_Blue_Branch",
      "support": 15
    },
    {
      "x": 1,
      "y": 7,
      "z": -1,
      "name": "Plant_Crop_Mushroom_Block_Blue_Trunk"
    },
    {
      "x": 1,
      "y": 0,
      "z": 0,
      "name": "Plant_Crop_Mushroom_Block_Blue_Mycelium"
    },
    {
      "x": 1,
      "y": 1,
      "z": 0,
      "name": "Rock_Crystal_Blue_Large",
      "rotation": 8
    },
    {
      "x": 1,
      "y": 2,
      "z": 0,
      "name": "Plant_Crop_Mushroom_Block_Blue_Trunk"
    },
    {
      "x": 1,
      "y": 3,
      "z": 0,
      "name": "Plant_Crop_Mushroom_Block_Blue_Trunk"
    },
    {
      "x": 1,
      "y": 4,
      "z": 0,
      "name": "Plant_Crop_Mushroom_Block_Blue_Trunk"
    },
    {
      "x": 1,
      "y": 5,
      "z": 0,
      "name": "Plant_Crop_Mushroom_Block_Blue_Trunk"
    },
    {
      "x": 1,
      "y": 6,
      "z": 0,
      "name": "Plant_Crop_Mushroom_Block_Blue_Trunk"
    },
    {
      "x": 1,
      "y": 7,
      "z": 0,
      "name": "Plant_Crop_Mushroom_Block_Blue_Trunk"
    },
    {
      "x": 1,
      "y": 1,
      "z": 1,
      "name": "Plant_Crop_Mushroom_Block_Blue_Mycelium"
    },
    {
      "x": 1,
      "y": 2,
      "z": 1,
      "name": "Plant_Crop_Mushroom_Block_Blue_Branch",
      "support": 15
    },
    {
      "x": 1,
      "y": 5,
      "z": 1,
      "name": "Plant_Crop_Mushroom_Block_Blue_Trunk"
    },
    {
      "x": 1,
      "y": 6,
      "z": 1,
      "name": "Plant_Crop_Mushroom_Block_Blue_Trunk"
    },
    {
      "x": 2,
      "y": 4,
      "z": -1,
      "name": "Plant_Crop_Mushroom_Block_Blue_Branch",
      "support": 15
    },
    {
      "x": 2,
      "y": 5,
      "z": -1,
      "name": "Plant_Crop_Mushroom_Block_Blue_Branch",
      "support": 15
    },
    {
      "x": 2,
      "y": 6,
      "z": -1,
      "name": "Plant_Crop_Mushroom_Block_Blue_Trunk"
    },
    {
      "x": 2,
      "y": 7,
      "z": -1,
      "name": "Plant_Crop_Mushroom_Block_Blue_Trunk"
    },
    {
      "x": 2,
      "y": 1,
      "z": 0,
      "name": "Plant_Crop_Mushroom_Block_Blue_Mycelium"
    },
    {
      "x": 2,
      "y": 2,
      "z": 0,
      "name": "Plant_Crop_Mushroom_Block_Blue_Branch",
      "support": 15
    },
    {
      "x": 2,
      "y": 7,
      "z": 0,
      "name": "Plant_Crop_Mushroom_Block_Blue_Trunk"
    },
    {
      "x": 2,
      "y": 6,
      "z": 1,
      "name": "Plant_Crop_Mushroom_Block_Blue_Branch",
      "support": 15
    },
    {
      "x": 2,
      "y": 7,
      "z": 1,
      "name": "Plant_Crop_Mushroom_Block_Blue_Branch",
      "support": 15
    },
    {
      "x": 4,
      "y": 4,
      "z": 0,
      "name": "Plant_Crop_Mushroom_Block_Blue_Mycelium"
    },
    {
      "x": 4,
      "y": 5,
      "z": 0,
      "name": "Plant_Crop_Mushroom_Block_Blue_Branch",
      "support": 15
    },
    {
      "x": 4,
      "y": 6,
      "z": 0,
      "name": "Plant_Crop_Mushroom_Block_Blue_Branch",
      "support": 15
    },
    {
      "x": 4,
      "y": 7,
      "z": 0,
      "name": "Plant_Crop_Mushroom_Block_Blue_Branch",
      "support": 15
    }
  ]
}