{
  "version": 8,
  "blockIdVersion": 11,
  "anchorX": 0,
  "anchorY": 3,
  "anchorZ": 0,
  "blocks": [
    {
      "x": -2,
      "y": 2,
      "z": -1,
      "name": "Plant_Large_Lilypad"
    },
    {
      "x": -2,
      "y": 3,
      "z": -1,
      "name": "Plant_Large_Lilypad_Half"
    },
    {
      "x": -2,
      "y": 2,
      "z": 0,
      "name": "Plant_Large_Lilypad"
    },
    {
      "x": -2,
      "y": 3,
      "z": 0,
      "name": "Plant_Large_Lilypad_Half"
    },
    {
      "x": -2,
      "y": 2,
      "z": 1,
      "name": "Plant_Large_Lilypad"
    },
    {
      "x": -2,
      "y": 3,
      "z": 1,
      "name": "Plant_Large_Lilypad_Half"
    },
    {
      "x": -1,
      "y": 2,
      "z": -2,
      "name": "Plant_Large_Lilypad"
    },
    {
      "x": -1,
      "y": 3,
      "z": -2,
      "name": "Plant_Large_Lilypad_Half"
    },
    {
      "x": -1,
      "y": 2,
      "z": -1,
      "name": "Plant_Large_Lilypad"
    },
    {
      "x": -1,
      "y": 1,
      "z": 0,
      "name": "Wood_Banyan_Roots"
    },
    {
      "x": -1,
      "y": 2,
      "z": 0,
      "name": "Plant_Large_Lilypad"
    },
    {
      "x": -1,
      "y": 2,
      "z": 1,
      "name": "Plant_Large_Lilypad"
    },
    {
      "x": -1,
      "y": 2,
      "z": 2,
      "name": "Plant_Large_Lilypad"
    },
    {
      "x": -1,
      "y": 3,
      "z": 2,
      "name": "Plant_Large_Lilypad_Half"
    },
    {
      "x": 0,
      "y": 2,
      "z": -2,
      "name": "Plant_Large_Lilypad"
    },
    {
      "x": 0,
      "y": 3,
      "z": -2,
      "name": "Plant_Large_Lilypad_Half"
    },
    {
      "x": 0,
      "y": 2,
      "z": -1,
      "name": "Plant_Large_Lilypad"
    },
    {
      "x": 0,
      "y": 0,
      "z": 0,
      "name": "Wood_Banyan_Branch_Long",
      "support": 15
    },
    {
      "x": 0,
      "y": 1,
      "z": 0,
      "name": "Wood_Banyan_Branch_Long",
      "support": 15
    },
    {
      "x": 0,
      "y": 2,
      "z": 0,
      "name": "Plant_Large_Lilypad"
    },
    {
      "x": 0,
      "y": 2,
      "z": 1,
      "name": "Plant_Large_Lilypad"
    },
    {
      "x": 0,
      "y": 2,
      "z": 2,
      "name": "Plant_Large_Lilypad"
    },
    {
      "x": 0,
      "y": 3,
      "z": 2,
      "name": "Plant_Large_Lilypad_Half"
    },
    {
      "x": 1,
      "y": 2,
      "z": -2,
      "name": "Plant_Large_Lilypad"
    },
    {
      "x": 1,
      "y": 3,
      "z": -2,
      "name": "Plant_Large_Lilypad_Half"
    },
    {
      "x": 1,
      "y": 1,
      "z": -1,
      "name": "Wood_Banyan_Roots"
    },
    {
      "x": 1,
      "y": 2,
      "z": -1,
      "name": "Plant_Large_Lilypad"
    },
    {
      "x": 1,
      "y": 2,
      "z": 0,
      "name": "Plant_Large_Lilypad"
    },
    {
      "x": 1,
      "y": 2,
      "z": 1,
      "name": "Plant_Large_Lilypad"
    },
    {
      "x": 1,
      "y": 2,
      "z": 2,
      "name": "Plant_Large_Lilypad"
    },
    {
      "x": 1,
      "y": 3,
      "z": 2,
      "name": "Plant_Large_Lilypad_Half"
    },
    {
      "x": 2,
      "y": 2,
      "z": -1,
      "name": "Plant_Large_Lilypad"
    },
    {
      "x": 2,
      "y": 3,
      "z": -1,
      "name": "Plant_Large_Lilypad_Half"
    },
    {
      "x": 2,
      "y": 2,
      "z": 0,
      "name": "Plant_Large_Lilypad"
    },
    {
      "x": 2,
      "y": 3,
      "z": 0,
      "name": "Plant_Large_Lilypad_Half"
    },
    {
      "x": 2,
      "y": 2,
      "z": 1,
      "name": "Plant_Large_Lilypad"
    },
    {
      "x": 2,
      "y": 3,
      "z": 1,
      "name": "Plant_Large_Lilypad_Half"
    }
  ],
  "fluids": [
    {
      "x": -1,
      "y": 1,
      "z": 0,
      "name": "Water_Source",
      "level": 1
    },
    {
      "x": 0,
      "y": 0,
      "z": 0,
      "name": "Water_Source",
      "level": 1
    },
    {
      "x": 0,
      "y": 1,
      "z": 0,
      "name": "Water_Source",
      "level": 1
    },
    {
      "x": 1,
      "y": 1,
      "z": -1,
      "name": "Water_Source",
      "level": 1
    }
  ]
}