{
  "version": 8,
  "blockIdVersion": 11,
  "anchorX": 0,
  "anchorY": 1,
  "anchorZ": 0,
  "blocks": [
    {
      "x": -4,
      "y": 1,
      "z": -4,
      "name": "Plant_Large_Lilypad_Half"
    },
    {
      "x": -4,
      "y": 1,
      "z": -3,
      "name": "Plant_Large_Lilypad_Half"
    },
    {
      "x": -3,
      "y": 1,
      "z": -4,
      "name": "Plant_Large_Lilypad_Half"
    },
    {
      "x": -3,
      "y": -2,
      "z": -3,
      "name": "Wood_Banyan_Branch_Long",
      "support": 15
    },
    {
      "x": -3,
      "y": -1,
      "z": -3,
      "name": "Wood_Banyan_Branch_Long",
      "support": 15
    },
    {
      "x": -3,
      "y": 0,
      "z": -3,
      "name": "Wood_Banyan_Branch_Long",
      "support": 15
    },
    {
      "x": -3,
      "y": 1,
      "z": -3,
      "name": "Plant_Large_Lilypad_Half"
    },
    {
      "x": -2,
      "y": 0,
      "z": -1,
      "name": "Plant_Large_Lilypad"
    },
    {
      "x": -2,
      "y": 1,
      "z": -1,
      "name": "Plant_Large_Lilypad_Half"
    },
    {
      "x": -2,
      "y": -1,
      "z": 0,
      "name": "Wood_Banyan_Roots"
    },
    {
      "x": -2,
      "y": 0,
      "z": 0,
      "name": "Plant_Large_Lilypad"
    },
    {
      "x": -2,
      "y": 1,
      "z": 0,
      "name": "Plant_Large_Lilypad_Half"
    },
    {
      "x": -2,
      "y": 0,
      "z": 1,
      "name": "Plant_Large_Lilypad"
    },
    {
      "x": -2,
      "y": 1,
      "z": 1,
      "name": "Plant_Large_Lilypad_Half"
    },
    {
      "x": -1,
      "y": 0,
      "z": -2,
      "name": "Plant_Large_Lilypad"
    },
    {
      "x": -1,
      "y": 1,
      "z": -2,
      "name": "Plant_Large_Lilypad_Half"
    },
    {
      "x": -1,
      "y": -1,
      "z": -1,
      "name": "Wood_Banyan_Roots"
    },
    {
      "x": -1,
      "y": 0,
      "z": -1,
      "name": "Plant_Large_Lilypad"
    },
    {
      "x": -1,
      "y": -1,
      "z": 0,
      "name": "Wood_Banyan_Branch_Corner",
      "support": 15,
      "rotation": 2
    },
    {
      "x": -1,
      "y": 0,
      "z": 0,
      "name": "Plant_Large_Lilypad"
    },
    {
      "x": -1,
      "y": -2,
      "z": 1,
      "name": "Wood_Banyan_Branch_Long",
      "support": 15
    },
    {
      "x": -1,
      "y": -1,
      "z": 1,
      "name": "Wood_Banyan_Branch_Corner",
      "support": 15,
      "rotation": 10
    },
    {
      "x": -1,
      "y": 0,
      "z": 1,
      "name": "Plant_Large_Lilypad"
    },
    {
      "x": -1,
      "y": 0,
      "z": 2,
      "name": "Plant_Large_Lilypad"
    },
    {
      "x": -1,
      "y": 1,
      "z": 2,
      "name": "Plant_Large_Lilypad_Half"
    },
    {
      "x": 0,
      "y": 0,
      "z": -2,
      "name": "Plant_Large_Lilypad"
    },
    {
      "x": 0,
      "y": 1,
      "z": -2,
      "name": "Plant_Large_Lilypad_Half"
    },
    {
      "x": 0,
      "y": 0,
      "z": -1,
      "name": "Plant_Large_Lilypad"
    },
    {
      "x": 0,
      "y": -2,
      "z": 0,
      "name": "Wood_Banyan_Branch_Long",
      "support": 15
    },
    {
      "x": 0,
      "y": -1,
      "z": 0,
      "name": "Wood_Banyan_Branch_Long",
      "support": 15
    },
    {
      "x": 0,
      "y": 0,
      "z": 0,
      "name": "Plant_Large_Lilypad"
    },
    {
      "x": 0,
      "y": 1,
      "z": 0,
      "name": "Plant_Flower_Lotus_Yellow",
      "support": 15
    },
    {
      "x": 0,
      "y": 0,
      "z": 1,
      "name": "Plant_Large_Lilypad"
    },
    {
      "x": 0,
      "y": 0,
      "z": 2,
      "name": "Plant_Large_Lilypad"
    },
    {
      "x": 0,
      "y": 1,
      "z": 2,
      "name": "Plant_Large_Lilypad_Half"
    },
    {
      "x": 1,
      "y": 0,
      "z": -2,
      "name": "Plant_Large_Lilypad"
    },
    {
      "x": 1,
      "y": 1,
      "z": -2,
      "name": "Plant_Large_Lilypad_Half"
    },
    {
      "x": 1,
      "y": 0,
      "z": -1,
      "name": "Plant_Large_Lilypad"
    },
    {
      "x": 1,
      "y": 0,
      "z": 0,
      "name": "Plant_Large_Lilypad"
    },
    {
      "x": 1,
      "y": -1,
      "z": 1,
      "name": "Wood_Banyan_Roots"
    },
    {
      "x": 1,
      "y": 0,
      "z": 1,
      "name": "Plant_Large_Lilypad"
    },
    {
      "x": 1,
      "y": 0,
      "z": 2,
      "name": "Plant_Large_Lilypad"
    },
    {
      "x": 1,
      "y": 1,
      "z": 2,
      "name": "Plant_Large_Lilypad_Half"
    },
    {
      "x": 2,
      "y": 0,
      "z": -1,
      "name": "Plant_Large_Lilypad"
    },
    {
      "x": 2,
      "y": 1,
      "z": -1,
      "name": "Plant_Large_Lilypad_Half"
    },
    {
      "x": 2,
      "y": 0,
      "z": 0,
      "name": "Plant_Large_Lilypad"
    },
    {
      "x": 2,
      "y": 1,
      "z": 0,
      "name": "Plant_Large_Lilypad_Half"
    },
    {
      "x": 2,
      "y": 0,
      "z": 1,
      "name": "Plant_Large_Lilypad"
    },
    {
      "x": 2,
      "y": 1,
      "z": 1,
      "name": "Plant_Large_Lilypad_Half"
    }
  ],
  "fluids": [
    {
      "x": -3,
      "y": -2,
      "z": -3,
      "name": "Water_Source",
      "level": 1
    },
    {
      "x": -3,
      "y": -1,
      "z": -3,
      "name": "Water_Source",
      "level": 1
    },
    {
      "x": -3,
      "y": 0,
      "z": -3,
      "name": "Water_Source",
      "level": 1
    },
    {
      "x": -2,
      "y": -1,
      "z": 0,
      "name": "Water_Source",
      "level": 1
    },
    {
      "x": -1,
      "y": -1,
      "z": -1,
      "name": "Water_Source",
      "level": 1
    },
    {
      "x": -1,
      "y": -1,
      "z": 0,
      "name": "Water_Source",
      "level": 1
    },
    {
      "x": -1,
      "y": -2,
      "z": 1,
      "name": "Water_Source",
      "level": 1
    },
    {
      "x": -1,
      "y": -1,
      "z": 1,
      "name": "Water_Source",
      "level": 1
    },
    {
      "x": 0,
      "y": -2,
      "z": 0,
      "name": "Water_Source",
      "level": 1
    },
    {
      "x": 0,
      "y": -1,
      "z": 0,
      "name": "Water_Source",
      "level": 1
    },
    {
      "x": 1,
      "y": -1,
      "z": 1,
      "name": "Water_Source",
      "level": 1
    }
  ]
}