{
  "version": 8,
  "blockIdVersion": 11,
  "anchorX": -1,
  "anchorY": 3,
  "anchorZ": -3,
  "blocks": [
    {
      "x": -10,
      "y": -1,
      "z": -1,
      "name": "Rock_Marble"
    },
    {
      "x": -10,
      "y": 0,
      "z": -1,
      "name": "Rock_Marble"
    },
    {
      "x": -10,
      "y": 1,
      "z": -1,
      "name": "Rock_Marble_SkyGrass"
    },
    {
      "x": -10,
      "y": -1,
      "z": 0,
      "name": "Rock_Marble"
    },
    {
      "x": -10,
      "y": 0,
      "z": 0,
      "name": "Rock_Marble"
    },
    {
      "x": -10,
      "y": 1,
      "z": 0,
      "name": "Rock_Marble_SkyGrass"
    },
    {
      "x": -10,
      "y": -1,
      "z": 1,
      "name": "Rock_Marble"
    },
    {
      "x": -10,
      "y": 0,
      "z": 1,
      "name": "Rock_Marble_SkyGrass"
    },
    {
      "x": -10,
      "y": 0,
      "z": 2,
      "name": "Rock_Marble_SkyGrass"
    },
    {
      "x": -9,
      "y": 0,
      "z": -4,
      "name": "Rock_Marble_SkyGrass"
    },
    {
      "x": -9,
      "y": -1,
      "z": -3,
      "name": "Rock_Marble"
    },
    {
      "x": -9,
      "y": 0,
      "z": -3,
      "name": "Rock_Marble_SkyGrass"
    },
    {
      "x": -9,
      "y": -1,
      "z": -2,
      "name": "Rock_Marble"
    },
    {
      "x": -9,
      "y": 0,
      "z": -2,
      "name": "Rock_Marble"
    },
    {
      "x": -9,
      "y": 1,
      "z": -2,
      "name": "Rock_Marble_SkyGrass"
    },
    {
      "x": -9,
      "y": -1,
      "z": -1,
      "name": "Rock_Marble"
    },
    {
      "x": -9,
      "y": 0,
      "z": -1,
      "name": "Rock_Marble"
    },
    {
      "x": -9,
      "y": 1,
      "z": -1,
      "name": "Rock_Marble_SkyGrass"
    },
    {
      "x": -9,
      "y": -1,
      "z": 0,
      "name": "Rock_Marble"
    },
    {
      "x": -9,
      "y": 0,
      "z": 0,
      "name": "Rock_Marble"
    },
    {
      "x": -9,
      "y": 1,
      "z": 0,
      "name": "Rock_Marble"
    },
    {
      "x": -9,
      "y": 2,
      "z": 0,
      "name": "Rock_Marble_SkyGrass"
    },
    {
      "x": -9,
      "y": -1,
      "z": 1,
      "name": "Rock_Marble"
    },
    {
      "x": -9,
      "y": 0,
      "z": 1,
      "name": "Rock_Marble"
    },
    {
      "x": -9,
      "y": 1,
      "z": 1,
      "name": "Rock_Marble"
    },
    {
      "x": -9,
      "y": 2,
      "z": 1,
      "name": "Rock_Marble_SkyGrass"
    },
    {
      "x": -9,
      "y": -1,
      "z": 2,
      "name": "Rock_Marble"
    },
    {
      "x": -9,
      "y": 0,
      "z": 2,
      "name": "Rock_Marble_SkyGrass"
    },
    {
      "x": -9,
      "y": -1,
      "z": 3,
      "name": "Rock_Marble"
    },
    {
      "x": -9,
      "y": 0,
      "z": 3,
      "name": "Rock_Marble_SkyGrass"
    },
    {
      "x": -8,
      "y": 0,
      "z": -8,
      "name": "Rock_Marble"
    },
    {
      "x": -8,
      "y": 1,
      "z": -8,
      "name": "Rock_Marble"
    },
    {
      "x": -8,
      "y": 2,
      "z": -8,
      "name": "Rock_Marble_SkyGrass"
    },
    {
      "x": -8,
      "y": 0,
      "z": -7,
      "name": "Rock_Marble"
    },
    {
      "x": -8,
      "y": 1,
      "z": -7,
      "name": "Rock_Marble"
    },
    {
      "x": -8,
      "y": 2,
      "z": -7,
      "name": "Rock_Marble_SkyGrass"
    },
    {
      "x": -8,
      "y": 0,
      "z": -6,
      "name": "Rock_Marble"
    },
    {
      "x": -8,
      "y": 1,
      "z": -6,
      "name": "Rock_Marble"
    },
    {
      "x": -8,
      "y": 2,
      "z": -6,
      "name": "Rock_Marble_SkyGrass"
    },
    {
      "x": -8,
      "y": 3,
      "z": -6,
      "name": "Plant_Grass_Sky",
      "support": 15
    },
    {
      "x": -8,
      "y": -1,
      "z": -5,
      "name": "Rock_Marble"
    },
    {
      "x": -8,
      "y": 0,
      "z": -5,
      "name": "Rock_Marble"
    },
    {
      "x": -8,
      "y": 1,
      "z": -5,
      "name": "Rock_Marble"
    },
    {
      "x": -8,
      "y": 2,
      "z": -5,
      "name": "Rock_Marble_SkyGrass"
    },
    {
      "x": -8,
      "y": -1,
      "z": -4,
      "name": "Rock_Marble"
    },
    {
      "x": -8,
      "y": 0,
      "z": -4,
      "name": "Rock_Marble"
    },
    {
      "x": -8,
      "y": 1,
      "z": -4,
      "name": "Rock_Marble"
    },
    {
      "x": -8,
      "y": 2,
      "z": -4,
      "name": "Rock_Marble_SkyGrass"
    },
    {
      "x": -8,
      "y": 3,
      "z": -4,
      "name": "Plant_Grass_Sky_Wild",
      "support": 15
    },
    {
      "x": -8,
      "y": 4,
      "z": -4,
      "name": "Plant_Grass_Sky_Wild",
      "filler": 1024
    },
    {
      "x": -8,
      "y": -1,
      "z": -3,
      "name": "Rock_Marble"
    },
    {
      "x": -8,
      "y": 0,
      "z": -3,
      "name": "Rock_Marble"
    },
    {
      "x": -8,
      "y": 1,
      "z": -3,
      "name": "Rock_Marble"
    },
    {
      "x": -8,
      "y": 2,
      "z": -3,
      "name": "Rock_Marble_SkyGrass"
    },
    {
      "x": -8,
      "y": -1,
      "z": -2,
      "name": "Rock_Marble"
    },
    {
      "x": -8,
      "y": 0,
      "z": -2,
      "name": "Rock_Marble"
    },
    {
      "x": -8,
      "y": 1,
      "z": -2,
      "name": "Rock_Marble"
    },
    {
      "x": -8,
      "y": 2,
      "z": -2,
      "name": "Rock_Marble_SkyGrass"
    },
    {
      "x": -8,
      "y": -1,
      "z": -1,
      "name": "Rock_Marble"
    },
    {
      "x": -8,
      "y": 0,
      "z": -1,
      "name": "Rock_Marble"
    },
    {
      "x": -8,
      "y": 1,
      "z": -1,
      "name": "Rock_Marble"
    },
    {
      "x": -8,
      "y": 2,
      "z": -1,
      "name": "Rock_Marble_SkyGrass"
    },
    {
      "x": -8,
      "y": -1,
      "z": 0,
      "name": "Rock_Marble"
    },
    {
      "x": -8,
      "y": 0,
      "z": 0,
      "name": "Rock_Marble"
    },
    {
      "x": -8,
      "y": 1,
      "z": 0,
      "name": "Rock_Marble"
    },
    {
      "x": -8,
      "y": 2,
      "z": 0,
      "name": "Rock_Marble_SkyGrass"
    },
    {
      "x": -8,
      "y": -1,
      "z": 1,
      "name": "Rock_Marble"
    },
    {
      "x": -8,
      "y": 0,
      "z": 1,
      "name": "Rock_Marble"
    },
    {
      "x": -8,
      "y": 1,
      "z": 1,
      "name": "Rock_Marble"
    },
    {
      "x": -8,
      "y": 2,
      "z": 1,
      "name": "Rock_Marble_SkyGrass"
    },
    {
      "x": -8,
      "y": -1,
      "z": 2,
      "name": "Rock_Marble"
    },
    {
      "x": -8,
      "y": 0,
      "z": 2,
      "name": "Rock_Marble"
    },
    {
      "x": -8,
      "y": 1,
      "z": 2,
      "name": "Rock_Marble"
    },
    {
      "x": -8,
      "y": 2,
      "z": 2,
      "name": "Rock_Marble_SkyGrass"
    },
    {
      "x": -8,
      "y": -1,
      "z": 3,
      "name": "Rock_Marble"
    },
    {
      "x": -8,
      "y": 0,
      "z": 3,
      "name": "Rock_Marble_SkyGrass"
    },
    {
      "x": -7,
      "y": 0,
      "z": -10,
      "name": "Rock_Marble"
    },
    {
      "x": -7,
      "y": 1,
      "z": -10,
      "name": "Rock_Marble_SkyGrass"
    },
    {
      "x": -7,
      "y": 0,
      "z": -9,
      "name": "Rock_Marble"
    },
    {
      "x": -7,
      "y": 1,
      "z": -9,
      "name": "Rock_Marble_SkyGrass"
    },
    {
      "x": -7,
      "y": -1,
      "z": -8,
      "name": "Rock_Marble"
    },
    {
      "x": -7,
      "y": 0,
      "z": -8,
      "name": "Rock_Marble"
    },
    {
      "x": -7,
      "y": 1,
      "z": -8,
      "name": "Rock_Marble"
    },
    {
      "x": -7,
      "y": 2,
      "z": -8,
      "name": "Rock_Marble_SkyGrass"
    },
    {
      "x": -7,
      "y": -1,
      "z": -7,
      "name": "Rock_Marble"
    },
    {
      "x": -7,
      "y": 0,
      "z": -7,
      "name": "Rock_Marble"
    },
    {
      "x": -7,
      "y": 1,
      "z": -7,
      "name": "Rock_Marble"
    },
    {
      "x": -7,
      "y": 2,
      "z": -7,
      "name": "Rock_Marble_SkyGrass"
    },
    {
      "x": -7,
      "y": 3,
      "z": -7,
      "name": "*Rock_Marble_Brick_Stairs_State_Definitions_Corner_Left",
      "rotation": 2
    },
    {
      "x": -7,
      "y": -1,
      "z": -6,
      "name": "Rock_Marble"
    },
    {
      "x": -7,
      "y": 0,
      "z": -6,
      "name": "Rock_Marble"
    },
    {
      "x": -7,
      "y": 1,
      "z": -6,
      "name": "Rock_Marble"
    },
    {
      "x": -7,
      "y": 2,
      "z": -6,
      "name": "Rock_Marble_SkyGrass"
    },
    {
      "x": -7,
      "y": 3,
      "z": -6,
      "name": "Rock_Marble_Brick_Stairs",
      "rotation": 3
    },
    {
      "x": -7,
      "y": 8,
      "z": -6,
      "name": "Rock_Marble_Brick_Smooth_Half",
      "rotation": 8
    },
    {
      "x": -7,
      "y": -1,
      "z": -5,
      "name": "Rock_Marble"
    },
    {
      "x": -7,
      "y": 0,
      "z": -5,
      "name": "Rock_Marble"
    },
    {
      "x": -7,
      "y": 1,
      "z": -5,
      "name": "Rock_Marble"
    },
    {
      "x": -7,
      "y": 2,
      "z": -5,
      "name": "Rock_Marble_SkyGrass"
    },
    {
      "x": -7,
      "y": 3,
      "z": -5,
      "name": "Rock_Marble_Brick_Stairs",
      "rotation": 3
    },
    {
      "x": -7,
      "y": -1,
      "z": -4,
      "name": "Rock_Marble"
    },
    {
      "x": -7,
      "y": 0,
      "z": -4,
      "name": "Rock_Marble"
    },
    {
      "x": -7,
      "y": 1,
      "z": -4,
      "name": "Rock_Marble"
    },
    {
      "x": -7,
      "y": 2,
      "z": -4,
      "name": "Rock_Marble_SkyGrass"
    },
    {
      "x": -7,
      "y": 3,
      "z": -4,
      "name": "Rock_Marble_Brick_Smooth_Half"
    },
    {
      "x": -7,
      "y": -1,
      "z": -3,
      "name": "Rock_Marble"
    },
    {
      "x": -7,
      "y": 0,
      "z": -3,
      "name": "Rock_Marble"
    },
    {
      "x": -7,
      "y": 1,
      "z": -3,
      "name": "Rock_Marble"
    },
    {
      "x": -7,
      "y": 2,
      "z": -3,
      "name": "Rock_Marble_SkyGrass"
    },
    {
      "x": -7,
      "y": -1,
      "z": -2,
      "name": "Rock_Marble"
    },
    {
      "x": -7,
      "y": 0,
      "z": -2,
      "name": "Rock_Marble"
    },
    {
      "x": -7,
      "y": 1,
      "z": -2,
      "name": "Rock_Marble"
    },
    {
      "x": -7,
      "y": 2,
      "z": -2,
      "name": "Rock_Marble_SkyGrass"
    },
    {
      "x": -7,
      "y": 3,
      "z": -2,
      "name": "Rock_Marble_Brick_Smooth_Half"
    },
    {
      "x": -7,
      "y": -1,
      "z": -1,
      "name": "Rock_Marble"
    },
    {
      "x": -7,
      "y": 0,
      "z": -1,
      "name": "Rock_Marble"
    },
    {
      "x": -7,
      "y": 1,
      "z": -1,
      "name": "Rock_Marble"
    },
    {
      "x": -7,
      "y": 2,
      "z": -1,
      "name": "Rock_Marble_SkyGrass"
    },
    {
      "x": -7,
      "y": 3,
      "z": -1,
      "name": "Rock_Marble_Brick_Stairs",
      "rotation": 3
    },
    {
      "x": -7,
      "y": -1,
      "z": 0,
      "name": "Rock_Marble"
    },
    {
      "x": -7,
      "y": 0,
      "z": 0,
      "name": "Rock_Marble"
    },
    {
      "x": -7,
      "y": 1,
      "z": 0,
      "name": "Rock_Marble"
    },
    {
      "x": -7,
      "y": 2,
      "z": 0,
      "name": "Rock_Marble_SkyGrass"
    },
    {
      "x": -7,
      "y": 3,
      "z": 0,
      "name": "Rock_Marble_Brick_Stairs",
      "rotation": 3
    },
    {
      "x": -7,
      "y": -1,
      "z": 1,
      "name": "Rock_Marble"
    },
    {
      "x": -7,
      "y": 0,
      "z": 1,
      "name": "Rock_Marble"
    },
    {
      "x": -7,
      "y": 1,
      "z": 1,
      "name": "Rock_Marble"
    },
    {
      "x": -7,
      "y": 2,
      "z": 1,
      "name": "Rock_Marble_SkyGrass"
    },
    {
      "x": -7,
      "y": 3,
      "z": 1,
      "name": "*Rock_Marble_Brick_Stairs_State_Definitions_Corner_Left",
      "rotation": 3
    },
    {
      "x": -7,
      "y": -1,
      "z": 2,
      "name": "Rock_Marble"
    },
    {
      "x": -7,
      "y": 0,
      "z": 2,
      "name": "Rock_Marble"
    },
    {
      "x": -7,
      "y": 1,
      "z": 2,
      "name": "Rock_Marble"
    },
    {
      "x": -7,
      "y": 2,
      "z": 2,
      "name": "Rock_Marble_SkyGrass"
    },
    {
      "x": -6,
      "y": 0,
      "z": -11,
      "name": "Rock_Marble"
    },
    {
      "x": -6,
      "y": 1,
      "z": -11,
      "name": "Rock_Marble_SkyGrass"
    },
    {
      "x": -6,
      "y": 0,
      "z": -10,
      "name": "Rock_Marble"
    },
    {
      "x": -6,
      "y": 1,
      "z": -10,
      "name": "Rock_Marble_SkyGrass"
    },
    {
      "x": -6,
      "y": -1,
      "z": -9,
      "name": "Rock_Marble"
    },
    {
      "x": -6,
      "y": 0,
      "z": -9,
      "name": "Rock_Marble"
    },
    {
      "x": -6,
      "y": 1,
      "z": -9,
      "name": "Rock_Marble"
    },
    {
      "x": -6,
      "y": 2,
      "z": -9,
      "name": "Rock_Marble_SkyGrass"
    },
    {
      "x": -6,
      "y": -1,
      "z": -8,
      "name": "Rock_Marble"
    },
    {
      "x": -6,
      "y": 0,
      "z": -8,
      "name": "Rock_Marble"
    },
    {
      "x": -6,
      "y": 1,
      "z": -8,
      "name": "Rock_Marble"
    },
    {
      "x": -6,
      "y": 2,
      "z": -8,
      "name": "Rock_Marble_SkyGrass"
    },
    {
      "x": -6,
      "y": -1,
      "z": -7,
      "name": "Rock_Marble"
    },
    {
      "x": -6,
      "y": 0,
      "z": -7,
      "name": "Rock_Marble"
    },
    {
      "x": -6,
      "y": 1,
      "z": -7,
      "name": "Rock_Marble"
    },
    {
      "x": -6,
      "y": 2,
      "z": -7,
      "name": "Rock_Marble_SkyGrass"
    },
    {
      "x": -6,
      "y": 3,
      "z": -7,
      "name": "Rock_Marble_Brick_Stairs",
      "rotation": 2
    },
    {
      "x": -6,
      "y": -1,
      "z": -6,
      "name": "Rock_Marble"
    },
    {
      "x": -6,
      "y": 0,
      "z": -6,
      "name": "Rock_Marble"
    },
    {
      "x": -6,
      "y": 1,
      "z": -6,
      "name": "Rock_Marble"
    },
    {
      "x": -6,
      "y": 2,
      "z": -6,
      "name": "Rock_Marble_SkyGrass"
    },
    {
      "x": -6,
      "y": 3,
      "z": -6,
      "name": "Rock_Marble_Brick"
    },
    {
      "x": -6,
      "y": 4,
      "z": -6,
      "name": "Rock_Marble_Brick_Pillar_Base"
    },
    {
      "x": -6,
      "y": 5,
      "z": -6,
      "name": "Rock_Marble_Brick_Pillar_Middle"
    },
    {
      "x": -6,
      "y": 6,
      "z": -6,
      "name": "Rock_Marble_Brick_Pillar_Middle"
    },
    {
      "x": -6,
      "y": 7,
      "z": -6,
      "name": "Rock_Marble_Brick_Pillar_Base",
      "rotation": 8
    },
    {
      "x": -6,
      "y": 8,
      "z": -6,
      "name": "Rock_Marble_Brick"
    },
    {
      "x": -6,
      "y": -1,
      "z": -5,
      "name": "Rock_Marble"
    },
    {
      "x": -6,
      "y": 0,
      "z": -5,
      "name": "Rock_Marble"
    },
    {
      "x": -6,
      "y": 1,
      "z": -5,
      "name": "Rock_Marble"
    },
    {
      "x": -6,
      "y": 2,
      "z": -5,
      "name": "Rock_Marble_SkyGrass"
    },
    {
      "x": -6,
      "y": 3,
      "z": -5,
      "name": "Rock_Marble_Brick"
    },
    {
      "x": -6,
      "y": 8,
      "z": -5,
      "name": "Rock_Marble_Brick"
    },
    {
      "x": -6,
      "y": 9,
      "z": -5,
      "name": "Plant_Crop_Mushroom_Shelve_Yellow"
    },
    {
      "x": -6,
      "y": -1,
      "z": -4,
      "name": "Rock_Marble"
    },
    {
      "x": -6,
      "y": 0,
      "z": -4,
      "name": "Rock_Marble"
    },
    {
      "x": -6,
      "y": 1,
      "z": -4,
      "name": "Rock_Marble"
    },
    {
      "x": -6,
      "y": 2,
      "z": -4,
      "name": "Rock_Marble_SkyGrass"
    },
    {
      "x": -6,
      "y": 3,
      "z": -4,
      "name": "Rock_Marble_Brick"
    },
    {
      "x": -6,
      "y": 4,
      "z": -4,
      "name": "Rock_Marble_Brick_Pillar_Base"
    },
    {
      "x": -6,
      "y": 5,
      "z": -4,
      "name": "Rock_Marble_Brick_Pillar_Middle"
    },
    {
      "x": -6,
      "y": 6,
      "z": -4,
      "name": "Rock_Marble_Brick_Pillar_Middle"
    },
    {
      "x": -6,
      "y": -1,
      "z": -3,
      "name": "Rock_Marble"
    },
    {
      "x": -6,
      "y": 0,
      "z": -3,
      "name": "Rock_Marble"
    },
    {
      "x": -6,
      "y": 1,
      "z": -3,
      "name": "Rock_Marble"
    },
    {
      "x": -6,
      "y": 2,
      "z": -3,
      "name": "Rock_Marble_SkyGrass"
    },
    {
      "x": -6,
      "y": 3,
      "z": -3,
      "name": "Rock_Marble_Brick"
    },
    {
      "x": -6,
      "y": -1,
      "z": -2,
      "name": "Rock_Marble"
    },
    {
      "x": -6,
      "y": 0,
      "z": -2,
      "name": "Rock_Marble"
    },
    {
      "x": -6,
      "y": 1,
      "z": -2,
      "name": "Rock_Marble"
    },
    {
      "x": -6,
      "y": 2,
      "z": -2,
      "name": "Rock_Marble_SkyGrass"
    },
    {
      "x": -6,
      "y": 3,
      "z": -2,
      "name": "Rock_Marble_Brick"
    },
    {
      "x": -6,
      "y": -1,
      "z": -1,
      "name": "Rock_Marble"
    },
    {
      "x": -6,
      "y": 0,
      "z": -1,
      "name": "Rock_Marble"
    },
    {
      "x": -6,
      "y": 1,
      "z": -1,
      "name": "Rock_Marble"
    },
    {
      "x": -6,
      "y": 2,
      "z": -1,
      "name": "Rock_Marble_SkyGrass"
    },
    {
      "x": -6,
      "y": 3,
      "z": -1,
      "name": "Rock_Marble_Brick"
    },
    {
      "x": -6,
      "y": -1,
      "z": 0,
      "name": "Rock_Marble"
    },
    {
      "x": -6,
      "y": 0,
      "z": 0,
      "name": "Rock_Marble"
    },
    {
      "x": -6,
      "y": 1,
      "z": 0,
      "name": "Rock_Marble"
    },
    {
      "x": -6,
      "y": 2,
      "z": 0,
      "name": "Rock_Marble_SkyGrass"
    },
    {
      "x": -6,
      "y": 3,
      "z": 0,
      "name": "Rock_Marble_Brick"
    },
    {
      "x": -6,
      "y": -1,
      "z": 1,
      "name": "Rock_Marble"
    },
    {
      "x": -6,
      "y": 0,
      "z": 1,
      "name": "Rock_Marble"
    },
    {
      "x": -6,
      "y": 1,
      "z": 1,
      "name": "Rock_Marble"
    },
    {
      "x": -6,
      "y": 2,
      "z": 1,
      "name": "Rock_Marble_SkyGrass"
    },
    {
      "x": -6,
      "y": 3,
      "z": 1,
      "name": "Rock_Marble_Brick_Stairs"
    },
    {
      "x": -6,
      "y": -1,
      "z": 2,
      "name": "Rock_Marble"
    },
    {
      "x": -6,
      "y": 0,
      "z": 2,
      "name": "Rock_Marble"
    },
    {
      "x": -6,
      "y": 1,
      "z": 2,
      "name": "Rock_Marble"
    },
    {
      "x": -6,
      "y": 2,
      "z": 2,
      "name": "Rock_Marble_SkyGrass"
    },
    {
      "x": -6,
      "y": -1,
      "z": 3,
      "name": "Rock_Marble"
    },
    {
      "x": -6,
      "y": 0,
      "z": 3,
      "name": "Rock_Marble"
    },
    {
      "x": -6,
      "y": 1,
      "z": 3,
      "name": "Rock_Marble_SkyGrass"
    },
    {
      "x": -5,
      "y": 0,
      "z": -11,
      "name": "Rock_Marble"
    },
    {
      "x": -5,
      "y": 1,
      "z": -11,
      "name": "Rock_Marble_SkyGrass"
    },
    {
      "x": -5,
      "y": 0,
      "z": -10,
      "name": "Rock_Marble"
    },
    {
      "x": -5,
      "y": 1,
      "z": -10,
      "name": "Rock_Marble"
    },
    {
      "x": -5,
      "y": 2,
      "z": -10,
      "name": "Rock_Marble_SkyGrass"
    },
    {
      "x": -5,
      "y": -1,
      "z": -9,
      "name": "Rock_Marble"
    },
    {
      "x": -5,
      "y": 0,
      "z": -9,
      "name": "Rock_Marble"
    },
    {
      "x": -5,
      "y": 1,
      "z": -9,
      "name": "Rock_Marble"
    },
    {
      "x": -5,
      "y": 2,
      "z": -9,
      "name": "Rock_Marble_SkyGrass"
    },
    {
      "x": -5,
      "y": -1,
      "z": -8,
      "name": "Rock_Marble"
    },
    {
      "x": -5,
      "y": 0,
      "z": -8,
      "name": "Rock_Marble"
    },
    {
      "x": -5,
      "y": 1,
      "z": -8,
      "name": "Rock_Marble"
    },
    {
      "x": -5,
      "y": 2,
      "z": -8,
      "name": "Rock_Marble_SkyGrass"
    },
    {
      "x": -5,
      "y": -1,
      "z": -7,
      "name": "Rock_Marble"
    },
    {
      "x": -5,
      "y": 0,
      "z": -7,
      "name": "Rock_Marble"
    },
    {
      "x": -5,
      "y": 1,
      "z": -7,
      "name": "Rock_Marble"
    },
    {
      "x": -5,
      "y": 2,
      "z": -7,
      "name": "Rock_Marble_SkyGrass"
    },
    {
      "x": -5,
      "y": 3,
      "z": -7,
      "name": "Rock_Marble_Brick_Smooth_Half"
    },
    {
      "x": -5,
      "y": -1,
      "z": -6,
      "name": "Rock_Marble"
    },
    {
      "x": -5,
      "y": 0,
      "z": -6,
      "name": "Rock_Marble"
    },
    {
      "x": -5,
      "y": 1,
      "z": -6,
      "name": "Rock_Marble"
    },
    {
      "x": -5,
      "y": 2,
      "z": -6,
      "name": "Rock_Marble_SkyGrass"
    },
    {
      "x": -5,
      "y": 3,
      "z": -6,
      "name": "Rock_Marble_Brick"
    },
    {
      "x": -5,
      "y": 8,
      "z": -6,
      "name": "Rock_Marble_Brick"
    },
    {
      "x": -5,
      "y": 9,
      "z": -6,
      "name": "Rubble_Marble",
      "support": 15
    },
    {
      "x": -5,
      "y": -1,
      "z": -5,
      "name": "Rock_Marble"
    },
    {
      "x": -5,
      "y": 0,
      "z": -5,
      "name": "Rock_Marble"
    },
    {
      "x": -5,
      "y": 1,
      "z": -5,
      "name": "Rock_Marble"
    },
    {
      "x": -5,
      "y": 2,
      "z": -5,
      "name": "Rock_Marble_SkyGrass"
    },
    {
      "x": -5,
      "y": 3,
      "z": -5,
      "name": "Rock_Marble_Brick"
    },
    {
      "x": -5,
      "y": -1,
      "z": -4,
      "name": "Rock_Marble"
    },
    {
      "x": -5,
      "y": 0,
      "z": -4,
      "name": "Rock_Marble"
    },
    {
      "x": -5,
      "y": 1,
      "z": -4,
      "name": "Rock_Marble"
    },
    {
      "x": -5,
      "y": 2,
      "z": -4,
      "name": "Rock_Marble_SkyGrass"
    },
    {
      "x": -5,
      "y": 3,
      "z": -4,
      "name": "Rock_Marble_Brick"
    },
    {
      "x": -5,
      "y": -1,
      "z": -3,
      "name": "Rock_Marble"
    },
    {
      "x": -5,
      "y": 0,
      "z": -3,
      "name": "Rock_Marble"
    },
    {
      "x": -5,
      "y": 1,
      "z": -3,
      "name": "Rock_Marble"
    },
    {
      "x": -5,
      "y": 2,
      "z": -3,
      "name": "Rock_Marble_SkyGrass"
    },
    {
      "x": -5,
      "y": 3,
      "z": -3,
      "name": "Rock_Marble_Brick"
    },
    {
      "x": -5,
      "y": -1,
      "z": -2,
      "name": "Rock_Marble"
    },
    {
      "x": -5,
      "y": 0,
      "z": -2,
      "name": "Rock_Marble"
    },
    {
      "x": -5,
      "y": 1,
      "z": -2,
      "name": "Rock_Marble"
    },
    {
      "x": -5,
      "y": 2,
      "z": -2,
      "name": "Rock_Marble_SkyGrass"
    },
    {
      "x": -5,
      "y": 3,
      "z": -2,
      "name": "Rock_Marble_Brick"
    },
    {
      "x": -5,
      "y": -1,
      "z": -1,
      "name": "Rock_Marble"
    },
    {
      "x": -5,
      "y": 0,
      "z": -1,
      "name": "Rock_Marble"
    },
    {
      "x": -5,
      "y": 1,
      "z": -1,
      "name": "Rock_Marble"
    },
    {
      "x": -5,
      "y": 2,
      "z": -1,
      "name": "Rock_Marble_SkyGrass"
    },
    {
      "x": -5,
      "y": 3,
      "z": -1,
      "name": "Rock_Marble_Brick"
    },
    {
      "x": -5,
      "y": 4,
      "z": -1,
      "name": "Rubble_Marble_Medium",
      "support": 15
    },
    {
      "x": -5,
      "y": -1,
      "z": 0,
      "name": "Rock_Marble"
    },
    {
      "x": -5,
      "y": 0,
      "z": 0,
      "name": "Rock_Marble"
    },
    {
      "x": -5,
      "y": 1,
      "z": 0,
      "name": "Rock_Marble"
    },
    {
      "x": -5,
      "y": 2,
      "z": 0,
      "name": "Rock_Marble_SkyGrass"
    },
    {
      "x": -5,
      "y": 3,
      "z": 0,
      "name": "Rock_Marble_Brick"
    },
    {
      "x": -5,
      "y": -1,
      "z": 1,
      "name": "Rock_Marble"
    },
    {
      "x": -5,
      "y": 0,
      "z": 1,
      "name": "Rock_Marble"
    },
    {
      "x": -5,
      "y": 1,
      "z": 1,
      "name": "Rock_Marble"
    },
    {
      "x": -5,
      "y": 2,
      "z": 1,
      "name": "Rock_Marble_SkyGrass"
    },
    {
      "x": -5,
      "y": 3,
      "z": 1,
      "name": "Rock_Marble_Brick_Stairs"
    },
    {
      "x": -5,
      "y": -1,
      "z": 2,
      "name": "Rock_Marble"
    },
    {
      "x": -5,
      "y": 0,
      "z": 2,
      "name": "Rock_Marble"
    },
    {
      "x": -5,
      "y": 1,
      "z": 2,
      "name": "Rock_Marble"
    },
    {
      "x": -5,
      "y": 2,
      "z": 2,
      "name": "Rock_Marble_SkyGrass"
    },
    {
      "x": -5,
      "y": -1,
      "z": 3,
      "name": "Rock_Marble"
    },
    {
      "x": -5,
      "y": 0,
      "z": 3,
      "name": "Rock_Marble"
    },
    {
      "x": -5,
      "y": 1,
      "z": 3,
      "name": "Rock_Marble_SkyGrass"
    },
    {
      "x": -5,
      "y": -1,
      "z": 4,
      "name": "Rock_Marble"
    },
    {
      "x": -5,
      "y": 0,
      "z": 4,
      "name": "Rock_Marble"
    },
    {
      "x": -5,
      "y": 1,
      "z": 4,
      "name": "Rock_Marble_SkyGrass"
    },
    {
      "x": -4,
      "y": 0,
      "z": -11,
      "name": "Rock_Marble"
    },
    {
      "x": -4,
      "y": 1,
      "z": -11,
      "name": "Rock_Marble_SkyGrass"
    },
    {
      "x": -4,
      "y": -1,
      "z": -10,
      "name": "Rock_Marble"
    },
    {
      "x": -4,
      "y": 0,
      "z": -10,
      "name": "Rock_Marble"
    },
    {
      "x": -4,
      "y": 1,
      "z": -10,
      "name": "Rock_Marble"
    },
    {
      "x": -4,
      "y": 2,
      "z": -10,
      "name": "Rock_Marble_SkyGrass"
    },
    {
      "x": -4,
      "y": -1,
      "z": -9,
      "name": "Rock_Marble"
    },
    {
      "x": -4,
      "y": 0,
      "z": -9,
      "name": "Rock_Marble"
    },
    {
      "x": -4,
      "y": 1,
      "z": -9,
      "name": "Rock_Marble"
    },
    {
      "x": -4,
      "y": 2,
      "z": -9,
      "name": "Rock_Marble_SkyGrass"
    },
    {
      "x": -4,
      "y": -1,
      "z": -8,
      "name": "Rock_Marble"
    },
    {
      "x": -4,
      "y": 0,
      "z": -8,
      "name": "Rock_Marble"
    },
    {
      "x": -4,
      "y": 1,
      "z": -8,
      "name": "Rock_Marble"
    },
    {
      "x": -4,
      "y": 2,
      "z": -8,
      "name": "Rock_Marble_SkyGrass"
    },
    {
      "x": -4,
      "y": -1,
      "z": -7,
      "name": "Rock_Marble"
    },
    {
      "x": -4,
      "y": 0,
      "z": -7,
      "name": "Rock_Marble"
    },
    {
      "x": -4,
      "y": 1,
      "z": -7,
      "name": "Rock_Marble"
    },
    {
      "x": -4,
      "y": 2,
      "z": -7,
      "name": "Rock_Marble_SkyGrass"
    },
    {
      "x": -4,
      "y": 3,
      "z": -7,
      "name": "Rock_Marble_Brick_Smooth_Half"
    },
    {
      "x": -4,
      "y": -1,
      "z": -6,
      "name": "Rock_Marble"
    },
    {
      "x": -4,
      "y": 0,
      "z": -6,
      "name": "Rock_Marble"
    },
    {
      "x": -4,
      "y": 1,
      "z": -6,
      "name": "Rock_Marble"
    },
    {
      "x": -4,
      "y": 2,
      "z": -6,
      "name": "Rock_Marble_SkyGrass"
    },
    {
      "x": -4,
      "y": 3,
      "z": -6,
      "name": "Rock_Marble_Brick"
    },
    {
      "x": -4,
      "y": 4,
      "z": -6,
      "name": "Rock_Marble_Brick_Pillar_Base"
    },
    {
      "x": -4,
      "y": 5,
      "z": -6,
      "name": "Rock_Marble_Brick_Pillar_Middle"
    },
    {
      "x": -4,
      "y": 6,
      "z": -6,
      "name": "Rock_Marble_Brick_Pillar_Middle"
    },
    {
      "x": -4,
      "y": 7,
      "z": -6,
      "name": "Rubble_Marble_Medium",
      "support": 15
    },
    {
      "x": -4,
      "y": -1,
      "z": -5,
      "name": "Rock_Marble"
    },
    {
      "x": -4,
      "y": 0,
      "z": -5,
      "name": "Rock_Marble"
    },
    {
      "x": -4,
      "y": 1,
      "z": -5,
      "name": "Rock_Marble"
    },
    {
      "x": -4,
      "y": 2,
      "z": -5,
      "name": "Rock_Marble_SkyGrass"
    },
    {
      "x": -4,
      "y": 3,
      "z": -5,
      "name": "Rock_Marble_Brick_Decorative"
    },
    {
      "x": -4,
      "y": -1,
      "z": -4,
      "name": "Rock_Marble"
    },
    {
      "x": -4,
      "y": 0,
      "z": -4,
      "name": "Rock_Marble"
    },
    {
      "x": -4,
      "y": 1,
      "z": -4,
      "name": "Rock_Marble"
    },
    {
      "x": -4,
      "y": 2,
      "z": -4,
      "name": "Rock_Marble_SkyGrass"
    },
    {
      "x": -4,
      "y": 3,
      "z": -4,
      "name": "Rock_Marble_Brick"
    },
    {
      "x": -4,
      "y": 4,
      "z": -4,
      "name": "Rubble_Marble_Medium",
      "support": 15
    },
    {
      "x": -4,
      "y": -1,
      "z": -3,
      "name": "Rock_Marble"
    },
    {
      "x": -4,
      "y": 0,
      "z": -3,
      "name": "Rock_Marble"
    },
    {
      "x": -4,
      "y": 1,
      "z": -3,
      "name": "Rock_Marble"
    },
    {
      "x": -4,
      "y": 2,
      "z": -3,
      "name": "Rock_Marble_SkyGrass"
    },
    {
      "x": -4,
      "y": 3,
      "z": -3,
      "name": "Rock_Marble_Brick"
    },
    {
      "x": -4,
      "y": -1,
      "z": -2,
      "name": "Rock_Marble"
    },
    {
      "x": -4,
      "y": 0,
      "z": -2,
      "name": "Rock_Marble"
    },
    {
      "x": -4,
      "y": 1,
      "z": -2,
      "name": "Rock_Marble"
    },
    {
      "x": -4,
      "y": 2,
      "z": -2,
      "name": "Rock_Marble_SkyGrass"
    },
    {
      "x": -4,
      "y": 3,
      "z": -2,
      "name": "Rock_Marble_Brick"
    },
    {
      "x": -4,
      "y": -1,
      "z": -1,
      "name": "Rock_Marble"
    },
    {
      "x": -4,
      "y": 0,
      "z": -1,
      "name": "Rock_Marble"
    },
    {
      "x": -4,
      "y": 1,
      "z": -1,
      "name": "Rock_Marble"
    },
    {
      "x": -4,
      "y": 2,
      "z": -1,
      "name": "Rock_Marble_SkyGrass"
    },
    {
      "x": -4,
      "y": 3,
      "z": -1,
      "name": "Rock_Marble_Brick_Decorative"
    },
    {
      "x": -4,
      "y": -1,
      "z": 0,
      "name": "Rock_Marble"
    },
    {
      "x": -4,
      "y": 0,
      "z": 0,
      "name": "Rock_Marble"
    },
    {
      "x": -4,
      "y": 1,
      "z": 0,
      "name": "Rock_Marble"
    },
    {
      "x": -4,
      "y": 2,
      "z": 0,
      "name": "Rock_Marble_SkyGrass"
    },
    {
      "x": -4,
      "y": 3,
      "z": 0,
      "name": "Rock_Marble_Brick"
    },
    {
      "x": -4,
      "y": 4,
      "z": 0,
      "name": "Rock_Marble_Brick_Pillar_Base"
    },
    {
      "x": -4,
      "y": 5,
      "z": 0,
      "name": "Rock_Marble_Brick_Pillar_Middle"
    },
    {
      "x": -4,
      "y": 6,
      "z": 0,
      "name": "Rubble_Marble",
      "support": 15
    },
    {
      "x": -4,
      "y": -1,
      "z": 1,
      "name": "Rock_Marble"
    },
    {
      "x": -4,
      "y": 0,
      "z": 1,
      "name": "Rock_Marble"
    },
    {
      "x": -4,
      "y": 1,
      "z": 1,
      "name": "Rock_Marble"
    },
    {
      "x": -4,
      "y": 2,
      "z": 1,
      "name": "Rock_Marble_SkyGrass"
    },
    {
      "x": -4,
      "y": 3,
      "z": 1,
      "name": "Rock_Marble_Brick_Smooth_Half",
      "rotation": 4
    },
    {
      "x": -4,
      "y": -1,
      "z": 2,
      "name": "Rock_Marble"
    },
    {
      "x": -4,
      "y": 0,
      "z": 2,
      "name": "Rock_Marble"
    },
    {
      "x": -4,
      "y": 1,
      "z": 2,
      "name": "Rock_Marble"
    },
    {
      "x": -4,
      "y": 2,
      "z": 2,
      "name": "Rock_Marble_SkyGrass"
    },
    {
      "x": -4,
      "y": -1,
      "z": 3,
      "name": "Rock_Marble"
    },
    {
      "x": -4,
      "y": 0,
      "z": 3,
      "name": "Rock_Marble"
    },
    {
      "x": -4,
      "y": 1,
      "z": 3,
      "name": "Rock_Marble"
    },
    {
      "x": -4,
      "y": 2,
      "z": 3,
      "name": "Rock_Marble_SkyGrass"
    },
    {
      "x": -4,
      "y": -1,
      "z": 4,
      "name": "Rock_Marble"
    },
    {
      "x": -4,
      "y": 0,
      "z": 4,
      "name": "Rock_Marble"
    },
    {
      "x": -4,
      "y": 1,
      "z": 4,
      "name": "Rock_Marble_SkyGrass"
    },
    {
      "x": -4,
      "y": -1,
      "z": 5,
      "name": "Rock_Marble"
    },
    {
      "x": -4,
      "y": 0,
      "z": 5,
      "name": "Rock_Marble_SkyGrass"
    },
    {
      "x": -3,
      "y": -1,
      "z": -11,
      "name": "Rock_Marble"
    },
    {
      "x": -3,
      "y": 0,
      "z": -11,
      "name": "Rock_Marble"
    },
    {
      "x": -3,
      "y": 1,
      "z": -11,
      "name": "Rock_Marble_SkyGrass"
    },
    {
      "x": -3,
      "y": -1,
      "z": -10,
      "name": "Rock_Marble"
    },
    {
      "x": -3,
      "y": 0,
      "z": -10,
      "name": "Rock_Marble"
    },
    {
      "x": -3,
      "y": 1,
      "z": -10,
      "name": "Rock_Marble"
    },
    {
      "x": -3,
      "y": 2,
      "z": -10,
      "name": "Rock_Marble_SkyGrass"
    },
    {
      "x": -3,
      "y": -1,
      "z": -9,
      "name": "Rock_Marble"
    },
    {
      "x": -3,
      "y": 0,
      "z": -9,
      "name": "Rock_Marble"
    },
    {
      "x": -3,
      "y": 1,
      "z": -9,
      "name": "Rock_Marble"
    },
    {
      "x": -3,
      "y": 2,
      "z": -9,
      "name": "Rock_Marble_SkyGrass"
    },
    {
      "x": -3,
      "y": -1,
      "z": -8,
      "name": "Rock_Marble"
    },
    {
      "x": -3,
      "y": 0,
      "z": -8,
      "name": "Rock_Marble"
    },
    {
      "x": -3,
      "y": 1,
      "z": -8,
      "name": "Rock_Marble"
    },
    {
      "x": -3,
      "y": 2,
      "z": -8,
      "name": "Rock_Marble_SkyGrass"
    },
    {
      "x": -3,
      "y": 3,
      "z": -8,
      "name": "Plant_Grass_Sky",
      "support": 15
    },
    {
      "x": -3,
      "y": -1,
      "z": -7,
      "name": "Rock_Marble"
    },
    {
      "x": -3,
      "y": 0,
      "z": -7,
      "name": "Rock_Marble"
    },
    {
      "x": -3,
      "y": 1,
      "z": -7,
      "name": "Rock_Marble"
    },
    {
      "x": -3,
      "y": 2,
      "z": -7,
      "name": "Rock_Marble_SkyGrass"
    },
    {
      "x": -3,
      "y": 3,
      "z": -7,
      "name": "Rock_Marble_Brick_Smooth_Half"
    },
    {
      "x": -3,
      "y": -1,
      "z": -6,
      "name": "Rock_Marble"
    },
    {
      "x": -3,
      "y": 0,
      "z": -6,
      "name": "Rock_Marble"
    },
    {
      "x": -3,
      "y": 1,
      "z": -6,
      "name": "Rock_Marble"
    },
    {
      "x": -3,
      "y": 2,
      "z": -6,
      "name": "Rock_Marble_SkyGrass"
    },
    {
      "x": -3,
      "y": 3,
      "z": -6,
      "name": "Rock_Marble_Brick"
    },
    {
      "x": -3,
      "y": -1,
      "z": -5,
      "name": "Rock_Marble"
    },
    {
      "x": -3,
      "y": 0,
      "z": -5,
      "name": "Rock_Marble"
    },
    {
      "x": -3,
      "y": 1,
      "z": -5,
      "name": "Rock_Marble"
    },
    {
      "x": -3,
      "y": 2,
      "z": -5,
      "name": "Rock_Marble_SkyGrass"
    },
    {
      "x": -3,
      "y": 3,
      "z": -5,
      "name": "Rock_Marble_Brick"
    },
    {
      "x": -3,
      "y": 4,
      "z": -5,
      "name": "Rubble_Marble",
      "support": 15
    },
    {
      "x": -3,
      "y": -1,
      "z": -4,
      "name": "Rock_Marble"
    },
    {
      "x": -3,
      "y": 0,
      "z": -4,
      "name": "Rock_Marble"
    },
    {
      "x": -3,
      "y": 1,
      "z": -4,
      "name": "Rock_Marble"
    },
    {
      "x": -3,
      "y": 2,
      "z": -4,
      "name": "Rock_Marble_SkyGrass"
    },
    {
      "x": -3,
      "y": 3,
      "z": -4,
      "name": "Rock_Marble_SkyGrass"
    },
    {
      "x": -3,
      "y": 4,
      "z": -4,
      "name": "Plant_Grass_Sky",
      "support": 15
    },
    {
      "x": -3,
      "y": -1,
      "z": -3,
      "name": "Rock_Marble"
    },
    {
      "x": -3,
      "y": 0,
      "z": -3,
      "name": "Rock_Marble"
    },
    {
      "x": -3,
      "y": 1,
      "z": -3,
      "name": "Rock_Marble"
    },
    {
      "x": -3,
      "y": 2,
      "z": -3,
      "name": "Rock_Marble_SkyGrass"
    },
    {
      "x": -3,
      "y": 3,
      "z": -3,
      "name": "Rock_Marble_SkyGrass"
    },
    {
      "x": -3,
      "y": 4,
      "z": -3,
      "name": "Plant_Grass_Sky_Long",
      "support": 15
    },
    {
      "x": -3,
      "y": 5,
      "z": -3,
      "name": "Plant_Grass_Sky_Long",
      "filler": 1024
    },
    {
      "x": -3,
      "y": -1,
      "z": -2,
      "name": "Rock_Marble"
    },
    {
      "x": -3,
      "y": 0,
      "z": -2,
      "name": "Rock_Marble"
    },
    {
      "x": -3,
      "y": 1,
      "z": -2,
      "name": "Rock_Marble"
    },
    {
      "x": -3,
      "y": 2,
      "z": -2,
      "name": "Rock_Marble_SkyGrass"
    },
    {
      "x": -3,
      "y": 3,
      "z": -2,
      "name": "Rock_Marble_Brick"
    },
    {
      "x": -3,
      "y": -1,
      "z": -1,
      "name": "Rock_Marble"
    },
    {
      "x": -3,
      "y": 0,
      "z": -1,
      "name": "Rock_Marble"
    },
    {
      "x": -3,
      "y": 1,
      "z": -1,
      "name": "Rock_Marble"
    },
    {
      "x": -3,
      "y": 2,
      "z": -1,
      "name": "Rock_Marble_SkyGrass"
    },
    {
      "x": -3,
      "y": 3,
      "z": -1,
      "name": "Rock_Marble_Brick"
    },
    {
      "x": -3,
      "y": 4,
      "z": -1,
      "name": "Rubble_Marble",
      "support": 15
    },
    {
      "x": -3,
      "y": -1,
      "z": 0,
      "name": "Rock_Marble"
    },
    {
      "x": -3,
      "y": 0,
      "z": 0,
      "name": "Rock_Marble"
    },
    {
      "x": -3,
      "y": 1,
      "z": 0,
      "name": "Rock_Marble"
    },
    {
      "x": -3,
      "y": 2,
      "z": 0,
      "name": "Rock_Marble_SkyGrass"
    },
    {
      "x": -3,
      "y": 3,
      "z": 0,
      "name": "Rock_Marble_Brick"
    },
    {
      "x": -3,
      "y": -1,
      "z": 1,
      "name": "Rock_Marble"
    },
    {
      "x": -3,
      "y": 0,
      "z": 1,
      "name": "Rock_Marble"
    },
    {
      "x": -3,
      "y": 1,
      "z": 1,
      "name": "Rock_Marble"
    },
    {
      "x": -3,
      "y": 2,
      "z": 1,
      "name": "Rock_Marble_SkyGrass"
    },
    {
      "x": -3,
      "y": 3,
      "z": 1,
      "name": "Rock_Marble_Brick_Stairs"
    },
    {
      "x": -3,
      "y": -1,
      "z": 2,
      "name": "Rock_Marble"
    },
    {
      "x": -3,
      "y": 0,
      "z": 2,
      "name": "Rock_Marble"
    },
    {
      "x": -3,
      "y": 1,
      "z": 2,
      "name": "Rock_Marble"
    },
    {
      "x": -3,
      "y": 2,
      "z": 2,
      "name": "Rock_Marble_SkyGrass"
    },
    {
      "x": -3,
      "y": 3,
      "z": 2,
      "name": "Plant_Grass_Sky_Long",
      "support": 15
    },
    {
      "x": -3,
      "y": 4,
      "z": 2,
      "name": "Plant_Grass_Sky_Long",
      "filler": 1024
    },
    {
      "x": -3,
      "y": -1,
      "z": 3,
      "name": "Rock_Marble"
    },
    {
      "x": -3,
      "y": 0,
      "z": 3,
      "name": "Rock_Marble"
    },
    {
      "x": -3,
      "y": 1,
      "z": 3,
      "name": "Rock_Marble"
    },
    {
      "x": -3,
      "y": 2,
      "z": 3,
      "name": "Rock_Marble_SkyGrass"
    },
    {
      "x": -3,
      "y": -1,
      "z": 4,
      "name": "Rock_Marble"
    },
    {
      "x": -3,
      "y": 0,
      "z": 4,
      "name": "Rock_Marble"
    },
    {
      "x": -3,
      "y": 1,
      "z": 4,
      "name": "Rock_Marble_SkyGrass"
    },
    {
      "x": -3,
      "y": -1,
      "z": 5,
      "name": "Rock_Marble"
    },
    {
      "x": -3,
      "y": 0,
      "z": 5,
      "name": "Rock_Marble_SkyGrass"
    },
    {
      "x": -2,
      "y": -1,
      "z": -11,
      "name": "Rock_Marble"
    },
    {
      "x": -2,
      "y": 0,
      "z": -11,
      "name": "Rock_Marble_SkyGrass"
    },
    {
      "x": -2,
      "y": -1,
      "z": -10,
      "name": "Rock_Marble"
    },
    {
      "x": -2,
      "y": 0,
      "z": -10,
      "name": "Rock_Marble"
    },
    {
      "x": -2,
      "y": 1,
      "z": -10,
      "name": "Rock_Marble"
    },
    {
      "x": -2,
      "y": 2,
      "z": -10,
      "name": "Rock_Marble_SkyGrass"
    },
    {
      "x": -2,
      "y": -1,
      "z": -9,
      "name": "Rock_Marble"
    },
    {
      "x": -2,
      "y": 0,
      "z": -9,
      "name": "Rock_Marble"
    },
    {
      "x": -2,
      "y": 1,
      "z": -9,
      "name": "Rock_Marble"
    },
    {
      "x": -2,
      "y": 2,
      "z": -9,
      "name": "Rock_Marble_SkyGrass"
    },
    {
      "x": -2,
      "y": -1,
      "z": -8,
      "name": "Rock_Marble"
    },
    {
      "x": -2,
      "y": 0,
      "z": -8,
      "name": "Rock_Marble"
    },
    {
      "x": -2,
      "y": 1,
      "z": -8,
      "name": "Rock_Marble"
    },
    {
      "x": -2,
      "y": 2,
      "z": -8,
      "name": "Rock_Marble_SkyGrass"
    },
    {
      "x": -2,
      "y": -1,
      "z": -7,
      "name": "Rock_Marble"
    },
    {
      "x": -2,
      "y": 0,
      "z": -7,
      "name": "Rock_Marble"
    },
    {
      "x": -2,
      "y": 1,
      "z": -7,
      "name": "Rock_Marble"
    },
    {
      "x": -2,
      "y": 2,
      "z": -7,
      "name": "Rock_Marble_SkyGrass"
    },
    {
      "x": -2,
      "y": 3,
      "z": -7,
      "name": "Rock_Marble_Brick_Stairs",
      "rotation": 2
    },
    {
      "x": -2,
      "y": -1,
      "z": -6,
      "name": "Rock_Marble"
    },
    {
      "x": -2,
      "y": 0,
      "z": -6,
      "name": "Rock_Marble"
    },
    {
      "x": -2,
      "y": 1,
      "z": -6,
      "name": "Rock_Marble"
    },
    {
      "x": -2,
      "y": 2,
      "z": -6,
      "name": "Rock_Marble_SkyGrass"
    },
    {
      "x": -2,
      "y": 3,
      "z": -6,
      "name": "Rock_Marble_Brick"
    },
    {
      "x": -2,
      "y": 4,
      "z": -6,
      "name": "Rock_Marble_Brick_Pillar_Base"
    },
    {
      "x": -2,
      "y": 5,
      "z": -6,
      "name": "Rock_Marble_Brick_Pillar_Middle"
    },
    {
      "x": -2,
      "y": 6,
      "z": -6,
      "name": "Rock_Marble_Brick_Pillar_Middle"
    },
    {
      "x": -2,
      "y": 7,
      "z": -6,
      "name": "Rock_Marble_Brick_Pillar_Base",
      "rotation": 8
    },
    {
      "x": -2,
      "y": 8,
      "z": -6,
      "name": "Rock_Marble_Brick"
    },
    {
      "x": -2,
      "y": -1,
      "z": -5,
      "name": "Rock_Marble"
    },
    {
      "x": -2,
      "y": 0,
      "z": -5,
      "name": "Rock_Marble"
    },
    {
      "x": -2,
      "y": 1,
      "z": -5,
      "name": "Rock_Marble"
    },
    {
      "x": -2,
      "y": 2,
      "z": -5,
      "name": "Rock_Marble_SkyGrass"
    },
    {
      "x": -2,
      "y": 3,
      "z": -5,
      "name": "Rock_Marble_Brick"
    },
    {
      "x": -2,
      "y": -1,
      "z": -4,
      "name": "Rock_Marble"
    },
    {
      "x": -2,
      "y": 0,
      "z": -4,
      "name": "Rock_Marble"
    },
    {
      "x": -2,
      "y": 1,
      "z": -4,
      "name": "Rock_Marble"
    },
    {
      "x": -2,
      "y": 2,
      "z": -4,
      "name": "Rock_Marble_SkyGrass"
    },
    {
      "x": -2,
      "y": 3,
      "z": -4,
      "name": "Rock_Marble_SkyGrass"
    },
    {
      "x": -2,
      "y": 4,
      "z": -4,
      "name": "Plant_Grass_Sky_Short",
      "support": 15
    },
    {
      "x": -2,
      "y": -1,
      "z": -3,
      "name": "Rock_Marble"
    },
    {
      "x": -2,
      "y": 0,
      "z": -3,
      "name": "Rock_Marble"
    },
    {
      "x": -2,
      "y": 1,
      "z": -3,
      "name": "Rock_Marble"
    },
    {
      "x": -2,
      "y": 2,
      "z": -3,
      "name": "Rock_Marble_SkyGrass"
    },
    {
      "x": -2,
      "y": 3,
      "z": -3,
      "name": "Rock_Marble_SkyGrass"
    },
    {
      "x": -2,
      "y": -1,
      "z": -2,
      "name": "Rock_Marble"
    },
    {
      "x": -2,
      "y": 0,
      "z": -2,
      "name": "Rock_Marble"
    },
    {
      "x": -2,
      "y": 1,
      "z": -2,
      "name": "Rock_Marble"
    },
    {
      "x": -2,
      "y": 2,
      "z": -2,
      "name": "Rock_Marble_SkyGrass"
    },
    {
      "x": -2,
      "y": 3,
      "z": -2,
      "name": "Rock_Marble_Brick"
    },
    {
      "x": -2,
      "y": -1,
      "z": -1,
      "name": "Rock_Marble"
    },
    {
      "x": -2,
      "y": 0,
      "z": -1,
      "name": "Rock_Marble"
    },
    {
      "x": -2,
      "y": 1,
      "z": -1,
      "name": "Rock_Marble"
    },
    {
      "x": -2,
      "y": 2,
      "z": -1,
      "name": "Rock_Marble_SkyGrass"
    },
    {
      "x": -2,
      "y": 3,
      "z": -1,
      "name": "Rock_Marble_Brick"
    },
    {
      "x": -2,
      "y": -1,
      "z": 0,
      "name": "Rock_Marble"
    },
    {
      "x": -2,
      "y": 0,
      "z": 0,
      "name": "Rock_Marble"
    },
    {
      "x": -2,
      "y": 1,
      "z": 0,
      "name": "Rock_Marble"
    },
    {
      "x": -2,
      "y": 2,
      "z": 0,
      "name": "Rock_Marble_SkyGrass"
    },
    {
      "x": -2,
      "y": 3,
      "z": 0,
      "name": "Rock_Marble_Brick"
    },
    {
      "x": -2,
      "y": 4,
      "z": 0,
      "name": "Rock_Marble_Brick_Pillar_Base"
    },
    {
      "x": -2,
      "y": -1,
      "z": 1,
      "name": "Rock_Marble"
    },
    {
      "x": -2,
      "y": 0,
      "z": 1,
      "name": "Rock_Marble"
    },
    {
      "x": -2,
      "y": 1,
      "z": 1,
      "name": "Rock_Marble"
    },
    {
      "x": -2,
      "y": 2,
      "z": 1,
      "name": "Rock_Marble_SkyGrass"
    },
    {
      "x": -2,
      "y": 3,
      "z": 1,
      "name": "Rock_Marble_Brick_Smooth_Half",
      "rotation": 4
    },
    {
      "x": -2,
      "y": -1,
      "z": 2,
      "name": "Rock_Marble"
    },
    {
      "x": -2,
      "y": 0,
      "z": 2,
      "name": "Rock_Marble"
    },
    {
      "x": -2,
      "y": 1,
      "z": 2,
      "name": "Rock_Marble"
    },
    {
      "x": -2,
      "y": 2,
      "z": 2,
      "name": "Rock_Marble_SkyGrass"
    },
    {
      "x": -2,
      "y": -1,
      "z": 3,
      "name": "Rock_Marble"
    },
    {
      "x": -2,
      "y": 0,
      "z": 3,
      "name": "Rock_Marble"
    },
    {
      "x": -2,
      "y": 1,
      "z": 3,
      "name": "Rock_Marble"
    },
    {
      "x": -2,
      "y": 2,
      "z": 3,
      "name": "Rock_Marble_SkyGrass"
    },
    {
      "x": -2,
      "y": -1,
      "z": 4,
      "name": "Rock_Marble"
    },
    {
      "x": -2,
      "y": 0,
      "z": 4,
      "name": "Rock_Marble_SkyGrass"
    },
    {
      "x": -2,
      "y": 0,
      "z": 5,
      "name": "Rock_Marble_SkyGrass"
    },
    {
      "x": -1,
      "y": -1,
      "z": -11,
      "name": "Rock_Marble"
    },
    {
      "x": -1,
      "y": 0,
      "z": -11,
      "name": "Rock_Marble_SkyGrass"
    },
    {
      "x": -1,
      "y": -1,
      "z": -10,
      "name": "Rock_Marble"
    },
    {
      "x": -1,
      "y": 0,
      "z": -10,
      "name": "Rock_Marble"
    },
    {
      "x": -1,
      "y": 1,
      "z": -10,
      "name": "Rock_Marble"
    },
    {
      "x": -1,
      "y": 2,
      "z": -10,
      "name": "Rock_Marble_SkyGrass"
    },
    {
      "x": -1,
      "y": -1,
      "z": -9,
      "name": "Rock_Marble"
    },
    {
      "x": -1,
      "y": 0,
      "z": -9,
      "name": "Rock_Marble"
    },
    {
      "x": -1,
      "y": 1,
      "z": -9,
      "name": "Rock_Marble"
    },
    {
      "x": -1,
      "y": 2,
      "z": -9,
      "name": "Rock_Marble_SkyGrass"
    },
    {
      "x": -1,
      "y": -1,
      "z": -8,
      "name": "Rock_Marble"
    },
    {
      "x": -1,
      "y": 0,
      "z": -8,
      "name": "Rock_Marble"
    },
    {
      "x": -1,
      "y": 1,
      "z": -8,
      "name": "Rock_Marble"
    },
    {
      "x": -1,
      "y": 2,
      "z": -8,
      "name": "Rock_Marble_SkyGrass"
    },
    {
      "x": -1,
      "y": 3,
      "z": -8,
      "name": "Rubble_Marble_Medium",
      "support": 15
    },
    {
      "x": -1,
      "y": -1,
      "z": -7,
      "name": "Rock_Marble"
    },
    {
      "x": -1,
      "y": 0,
      "z": -7,
      "name": "Rock_Marble"
    },
    {
      "x": -1,
      "y": 1,
      "z": -7,
      "name": "Rock_Marble"
    },
    {
      "x": -1,
      "y": 2,
      "z": -7,
      "name": "Rock_Marble_SkyGrass"
    },
    {
      "x": -1,
      "y": 3,
      "z": -7,
      "name": "Rock_Marble_SkyGrass"
    },
    {
      "x": -1,
      "y": 4,
      "z": -7,
      "name": "Plant_Grass_Sky",
      "support": 15
    },
    {
      "x": -1,
      "y": -1,
      "z": -6,
      "name": "Rock_Marble"
    },
    {
      "x": -1,
      "y": 0,
      "z": -6,
      "name": "Rock_Marble"
    },
    {
      "x": -1,
      "y": 1,
      "z": -6,
      "name": "Rock_Marble"
    },
    {
      "x": -1,
      "y": 2,
      "z": -6,
      "name": "Rock_Marble_SkyGrass"
    },
    {
      "x": -1,
      "y": 3,
      "z": -6,
      "name": "Rock_Marble_SkyGrass"
    },
    {
      "x": -1,
      "y": 8,
      "z": -6,
      "name": "Rock_Marble_Brick"
    },
    {
      "x": -1,
      "y": 9,
      "z": -6,
      "name": "Rubble_Marble",
      "support": 15
    },
    {
      "x": -1,
      "y": -1,
      "z": -5,
      "name": "Rock_Marble"
    },
    {
      "x": -1,
      "y": 0,
      "z": -5,
      "name": "Rock_Marble"
    },
    {
      "x": -1,
      "y": 1,
      "z": -5,
      "name": "Rock_Marble"
    },
    {
      "x": -1,
      "y": 2,
      "z": -5,
      "name": "Rock_Marble_SkyGrass"
    },
    {
      "x": -1,
      "y": 3,
      "z": -5,
      "name": "Rock_Marble_SkyGrass"
    },
    {
      "x": -1,
      "y": -1,
      "z": -4,
      "name": "Rock_Marble"
    },
    {
      "x": -1,
      "y": 0,
      "z": -4,
      "name": "Rock_Marble"
    },
    {
      "x": -1,
      "y": 1,
      "z": -4,
      "name": "Rock_Marble"
    },
    {
      "x": -1,
      "y": 2,
      "z": -4,
      "name": "Rock_Marble_SkyGrass"
    },
    {
      "x": -1,
      "y": 3,
      "z": -4,
      "name": "Rock_Marble_Brick"
    },
    {
      "x": -1,
      "y": -1,
      "z": -3,
      "name": "Rock_Marble"
    },
    {
      "x": -1,
      "y": 0,
      "z": -3,
      "name": "Rock_Marble"
    },
    {
      "x": -1,
      "y": 1,
      "z": -3,
      "name": "Rock_Marble"
    },
    {
      "x": -1,
      "y": 2,
      "z": -3,
      "name": "Rock_Marble_SkyGrass"
    },
    {
      "x": -1,
      "y": 3,
      "z": -3,
      "name": "Rock_Marble_Brick"
    },
    {
      "x": -1,
      "y": -1,
      "z": -2,
      "name": "Rock_Marble"
    },
    {
      "x": -1,
      "y": 0,
      "z": -2,
      "name": "Rock_Marble"
    },
    {
      "x": -1,
      "y": 1,
      "z": -2,
      "name": "Rock_Marble"
    },
    {
      "x": -1,
      "y": 2,
      "z": -2,
      "name": "Rock_Marble_SkyGrass"
    },
    {
      "x": -1,
      "y": 3,
      "z": -2,
      "name": "Rock_Marble_Brick"
    },
    {
      "x": -1,
      "y": -1,
      "z": -1,
      "name": "Rock_Marble"
    },
    {
      "x": -1,
      "y": 0,
      "z": -1,
      "name": "Rock_Marble"
    },
    {
      "x": -1,
      "y": 1,
      "z": -1,
      "name": "Rock_Marble"
    },
    {
      "x": -1,
      "y": 2,
      "z": -1,
      "name": "Rock_Marble_SkyGrass"
    },
    {
      "x": -1,
      "y": 3,
      "z": -1,
      "name": "Rock_Marble_Brick"
    },
    {
      "x": -1,
      "y": -1,
      "z": 0,
      "name": "Rock_Marble"
    },
    {
      "x": -1,
      "y": 0,
      "z": 0,
      "name": "Rock_Marble"
    },
    {
      "x": -1,
      "y": 1,
      "z": 0,
      "name": "Rock_Marble"
    },
    {
      "x": -1,
      "y": 2,
      "z": 0,
      "name": "Rock_Marble_SkyGrass"
    },
    {
      "x": -1,
      "y": 3,
      "z": 0,
      "name": "Rock_Marble_Brick"
    },
    {
      "x": -1,
      "y": -1,
      "z": 1,
      "name": "Rock_Marble"
    },
    {
      "x": -1,
      "y": 0,
      "z": 1,
      "name": "Rock_Marble"
    },
    {
      "x": -1,
      "y": 1,
      "z": 1,
      "name": "Rock_Marble"
    },
    {
      "x": -1,
      "y": 2,
      "z": 1,
      "name": "Rock_Marble_SkyGrass"
    },
    {
      "x": -1,
      "y": 3,
      "z": 1,
      "name": "Rock_Marble_Brick_Stairs"
    },
    {
      "x": -1,
      "y": -1,
      "z": 2,
      "name": "Rock_Marble"
    },
    {
      "x": -1,
      "y": 0,
      "z": 2,
      "name": "Rock_Marble"
    },
    {
      "x": -1,
      "y": 1,
      "z": 2,
      "name": "Rock_Marble"
    },
    {
      "x": -1,
      "y": 2,
      "z": 2,
      "name": "Rock_Marble_SkyGrass"
    },
    {
      "x": -1,
      "y": -1,
      "z": 3,
      "name": "Rock_Marble"
    },
    {
      "x": -1,
      "y": 0,
      "z": 3,
      "name": "Rock_Marble"
    },
    {
      "x": -1,
      "y": 1,
      "z": 3,
      "name": "Rock_Marble"
    },
    {
      "x": -1,
      "y": 2,
      "z": 3,
      "name": "Rock_Marble_SkyGrass"
    },
    {
      "x": -1,
      "y": -1,
      "z": 4,
      "name": "Rock_Marble"
    },
    {
      "x": -1,
      "y": 0,
      "z": 4,
      "name": "Rock_Marble_SkyGrass"
    },
    {
      "x": 0,
      "y": -1,
      "z": -11,
      "name": "Rock_Marble"
    },
    {
      "x": 0,
      "y": 0,
      "z": -11,
      "name": "Rock_Marble_SkyGrass"
    },
    {
      "x": 0,
      "y": -1,
      "z": -10,
      "name": "Rock_Marble"
    },
    {
      "x": 0,
      "y": 0,
      "z": -10,
      "name": "Rock_Marble"
    },
    {
      "x": 0,
      "y": 1,
      "z": -10,
      "name": "Rock_Marble"
    },
    {
      "x": 0,
      "y": 2,
      "z": -10,
      "name": "Rock_Marble_SkyGrass"
    },
    {
      "x": 0,
      "y": -1,
      "z": -9,
      "name": "Rock_Marble"
    },
    {
      "x": 0,
      "y": 0,
      "z": -9,
      "name": "Rock_Marble"
    },
    {
      "x": 0,
      "y": 1,
      "z": -9,
      "name": "Rock_Marble"
    },
    {
      "x": 0,
      "y": 2,
      "z": -9,
      "name": "Rock_Marble_SkyGrass"
    },
    {
      "x": 0,
      "y": -1,
      "z": -8,
      "name": "Rock_Marble"
    },
    {
      "x": 0,
      "y": 0,
      "z": -8,
      "name": "Rock_Marble"
    },
    {
      "x": 0,
      "y": 1,
      "z": -8,
      "name": "Rock_Marble"
    },
    {
      "x": 0,
      "y": 2,
      "z": -8,
      "name": "Rock_Marble_SkyGrass"
    },
    {
      "x": 0,
      "y": 3,
      "z": -8,
      "name": "Rock_Marble_SkyGrass"
    },
    {
      "x": 0,
      "y": 4,
      "z": -8,
      "name": "Plant_Grass_Sky_Short",
      "support": 15
    },
    {
      "x": 0,
      "y": -1,
      "z": -7,
      "name": "Rock_Marble"
    },
    {
      "x": 0,
      "y": 0,
      "z": -7,
      "name": "Rock_Marble"
    },
    {
      "x": 0,
      "y": 1,
      "z": -7,
      "name": "Rock_Marble"
    },
    {
      "x": 0,
      "y": 2,
      "z": -7,
      "name": "Rock_Marble_SkyGrass"
    },
    {
      "x": 0,
      "y": 3,
      "z": -7,
      "name": "Rock_Marble_SkyGrass"
    },
    {
      "x": 0,
      "y": -1,
      "z": -6,
      "name": "Rock_Marble"
    },
    {
      "x": 0,
      "y": 0,
      "z": -6,
      "name": "Rock_Marble"
    },
    {
      "x": 0,
      "y": 1,
      "z": -6,
      "name": "Rock_Marble"
    },
    {
      "x": 0,
      "y": 2,
      "z": -6,
      "name": "Rock_Marble_SkyGrass"
    },
    {
      "x": 0,
      "y": 3,
      "z": -6,
      "name": "Rock_Marble_SkyGrass"
    },
    {
      "x": 0,
      "y": 4,
      "z": -6,
      "name": "Rubble_Marble",
      "support": 15
    },
    {
      "x": 0,
      "y": 7,
      "z": -6,
      "name": "Rock_Marble_Brick_Pillar_Base",
      "rotation": 8
    },
    {
      "x": 0,
      "y": 8,
      "z": -6,
      "name": "Rock_Marble_Brick"
    },
    {
      "x": 0,
      "y": -1,
      "z": -5,
      "name": "Rock_Marble"
    },
    {
      "x": 0,
      "y": 0,
      "z": -5,
      "name": "Rock_Marble"
    },
    {
      "x": 0,
      "y": 1,
      "z": -5,
      "name": "Rock_Marble"
    },
    {
      "x": 0,
      "y": 2,
      "z": -5,
      "name": "Rock_Marble_SkyGrass"
    },
    {
      "x": 0,
      "y": 3,
      "z": -5,
      "name": "Rock_Marble_SkyGrass"
    },
    {
      "x": 0,
      "y": 4,
      "z": -5,
      "name": "Plant_Grass_Sky_Short",
      "support": 15
    },
    {
      "x": 0,
      "y": -1,
      "z": -4,
      "name": "Rock_Marble"
    },
    {
      "x": 0,
      "y": 0,
      "z": -4,
      "name": "Rock_Marble"
    },
    {
      "x": 0,
      "y": 1,
      "z": -4,
      "name": "Rock_Marble"
    },
    {
      "x": 0,
      "y": 2,
      "z": -4,
      "name": "Rock_Marble_SkyGrass"
    },
    {
      "x": 0,
      "y": 3,
      "z": -4,
      "name": "Rock_Marble_Brick"
    },
    {
      "x": 0,
      "y": -1,
      "z": -3,
      "name": "Rock_Marble"
    },
    {
      "x": 0,
      "y": 0,
      "z": -3,
      "name": "Rock_Marble"
    },
    {
      "x": 0,
      "y": 1,
      "z": -3,
      "name": "Rock_Marble"
    },
    {
      "x": 0,
      "y": 2,
      "z": -3,
      "name": "Rock_Marble_SkyGrass"
    },
    {
      "x": 0,
      "y": 3,
      "z": -3,
      "name": "Rock_Marble_SkyGrass"
    },
    {
      "x": 0,
      "y": 4,
      "z": -3,
      "name": "Plant_Grass_Sky",
      "support": 15
    },
    {
      "x": 0,
      "y": -1,
      "z": -2,
      "name": "Rock_Marble"
    },
    {
      "x": 0,
      "y": 0,
      "z": -2,
      "name": "Rock_Marble"
    },
    {
      "x": 0,
      "y": 1,
      "z": -2,
      "name": "Rock_Marble"
    },
    {
      "x": 0,
      "y": 2,
      "z": -2,
      "name": "Rock_Marble_SkyGrass"
    },
    {
      "x": 0,
      "y": 3,
      "z": -2,
      "name": "Rock_Marble_SkyGrass"
    },
    {
      "x": 0,
      "y": 4,
      "z": -2,
      "name": "Plant_Grass_Sky_Short",
      "support": 15
    },
    {
      "x": 0,
      "y": -1,
      "z": -1,
      "name": "Rock_Marble"
    },
    {
      "x": 0,
      "y": 0,
      "z": -1,
      "name": "Rock_Marble"
    },
    {
      "x": 0,
      "y": 1,
      "z": -1,
      "name": "Rock_Marble"
    },
    {
      "x": 0,
      "y": 2,
      "z": -1,
      "name": "Rock_Marble_SkyGrass"
    },
    {
      "x": 0,
      "y": 3,
      "z": -1,
      "name": "Rock_Marble_SkyGrass"
    },
    {
      "x": 0,
      "y": -1,
      "z": 0,
      "name": "Rock_Marble"
    },
    {
      "x": 0,
      "y": 0,
      "z": 0,
      "name": "Rock_Marble"
    },
    {
      "x": 0,
      "y": 1,
      "z": 0,
      "name": "Rock_Marble"
    },
    {
      "x": 0,
      "y": 2,
      "z": 0,
      "name": "Rock_Marble_SkyGrass"
    },
    {
      "x": 0,
      "y": 3,
      "z": 0,
      "name": "Rock_Marble_Brick"
    },
    {
      "x": 0,
      "y": 4,
      "z": 0,
      "name": "Rock_Marble_Brick_Pillar_Base"
    },
    {
      "x": 0,
      "y": 5,
      "z": 0,
      "name": "Rock_Marble_Brick_Pillar_Middle"
    },
    {
      "x": 0,
      "y": 6,
      "z": 0,
      "name": "Rock_Marble_Brick_Pillar_Middle"
    },
    {
      "x": 0,
      "y": 7,
      "z": 0,
      "name": "Rock_Marble_Brick_Pillar_Base",
      "rotation": 8
    },
    {
      "x": 0,
      "y": 8,
      "z": 0,
      "name": "Rock_Marble_Brick_Half"
    },
    {
      "x": 0,
      "y": -1,
      "z": 1,
      "name": "Rock_Marble"
    },
    {
      "x": 0,
      "y": 0,
      "z": 1,
      "name": "Rock_Marble"
    },
    {
      "x": 0,
      "y": 1,
      "z": 1,
      "name": "Rock_Marble"
    },
    {
      "x": 0,
      "y": 2,
      "z": 1,
      "name": "Rock_Marble_SkyGrass"
    },
    {
      "x": 0,
      "y": 3,
      "z": 1,
      "name": "Rock_Marble_Brick_Stairs"
    },
    {
      "x": 0,
      "y": -1,
      "z": 2,
      "name": "Rock_Marble"
    },
    {
      "x": 0,
      "y": 0,
      "z": 2,
      "name": "Rock_Marble"
    },
    {
      "x": 0,
      "y": 1,
      "z": 2,
      "name": "Rock_Marble"
    },
    {
      "x": 0,
      "y": 2,
      "z": 2,
      "name": "Rock_Marble_SkyGrass"
    },
    {
      "x": 0,
      "y": -1,
      "z": 3,
      "name": "Rock_Marble"
    },
    {
      "x": 0,
      "y": 0,
      "z": 3,
      "name": "Rock_Marble_SkyGrass"
    },
    {
      "x": 0,
      "y": 0,
      "z": 4,
      "name": "Rock_Marble_SkyGrass"
    },
    {
      "x": 1,
      "y": -1,
      "z": -11,
      "name": "Rock_Marble"
    },
    {
      "x": 1,
      "y": 0,
      "z": -11,
      "name": "Rock_Marble_SkyGrass"
    },
    {
      "x": 1,
      "y": -1,
      "z": -10,
      "name": "Rock_Marble"
    },
    {
      "x": 1,
      "y": 0,
      "z": -10,
      "name": "Rock_Marble"
    },
    {
      "x": 1,
      "y": 1,
      "z": -10,
      "name": "Rock_Marble"
    },
    {
      "x": 1,
      "y": 2,
      "z": -10,
      "name": "Rock_Marble_SkyGrass"
    },
    {
      "x": 1,
      "y": -1,
      "z": -9,
      "name": "Rock_Marble"
    },
    {
      "x": 1,
      "y": 0,
      "z": -9,
      "name": "Rock_Marble"
    },
    {
      "x": 1,
      "y": 1,
      "z": -9,
      "name": "Rock_Marble"
    },
    {
      "x": 1,
      "y": 2,
      "z": -9,
      "name": "Rock_Marble_SkyGrass"
    },
    {
      "x": 1,
      "y": 3,
      "z": -9,
      "name": "Plant_Grass_Sky_Short",
      "support": 15
    },
    {
      "x": 1,
      "y": -1,
      "z": -8,
      "name": "Rock_Marble"
    },
    {
      "x": 1,
      "y": 0,
      "z": -8,
      "name": "Rock_Marble"
    },
    {
      "x": 1,
      "y": 1,
      "z": -8,
      "name": "Rock_Marble"
    },
    {
      "x": 1,
      "y": 2,
      "z": -8,
      "name": "Rock_Marble_SkyGrass"
    },
    {
      "x": 1,
      "y": 3,
      "z": -8,
      "name": "Rock_Marble_SkyGrass"
    },
    {
      "x": 1,
      "y": 4,
      "z": -8,
      "name": "Plant_Grass_Sky",
      "support": 15
    },
    {
      "x": 1,
      "y": -1,
      "z": -7,
      "name": "Rock_Marble"
    },
    {
      "x": 1,
      "y": 0,
      "z": -7,
      "name": "Rock_Marble"
    },
    {
      "x": 1,
      "y": 1,
      "z": -7,
      "name": "Rock_Marble"
    },
    {
      "x": 1,
      "y": 2,
      "z": -7,
      "name": "Rock_Marble_SkyGrass"
    },
    {
      "x": 1,
      "y": 3,
      "z": -7,
      "name": "Rock_Marble_SkyGrass"
    },
    {
      "x": 1,
      "y": -1,
      "z": -6,
      "name": "Rock_Marble"
    },
    {
      "x": 1,
      "y": 0,
      "z": -6,
      "name": "Rock_Marble"
    },
    {
      "x": 1,
      "y": 1,
      "z": -6,
      "name": "Rock_Marble"
    },
    {
      "x": 1,
      "y": 2,
      "z": -6,
      "name": "Rock_Marble_SkyGrass"
    },
    {
      "x": 1,
      "y": 3,
      "z": -6,
      "name": "Rock_Marble_SkyGrass"
    },
    {
      "x": 1,
      "y": 4,
      "z": -6,
      "name": "Plant_Bush_Sky",
      "support": 15
    },
    {
      "x": 1,
      "y": 8,
      "z": -6,
      "name": "Rock_Marble_Brick"
    },
    {
      "x": 1,
      "y": -1,
      "z": -5,
      "name": "Rock_Marble"
    },
    {
      "x": 1,
      "y": 0,
      "z": -5,
      "name": "Rock_Marble"
    },
    {
      "x": 1,
      "y": 1,
      "z": -5,
      "name": "Rock_Marble"
    },
    {
      "x": 1,
      "y": 2,
      "z": -5,
      "name": "Rock_Marble_SkyGrass"
    },
    {
      "x": 1,
      "y": 3,
      "z": -5,
      "name": "Rock_Marble_SkyGrass"
    },
    {
      "x": 1,
      "y": -1,
      "z": -4,
      "name": "Rock_Marble"
    },
    {
      "x": 1,
      "y": 0,
      "z": -4,
      "name": "Rock_Marble"
    },
    {
      "x": 1,
      "y": 1,
      "z": -4,
      "name": "Rock_Marble"
    },
    {
      "x": 1,
      "y": 2,
      "z": -4,
      "name": "Rock_Marble_SkyGrass"
    },
    {
      "x": 1,
      "y": 3,
      "z": -4,
      "name": "Rock_Marble_SkyGrass"
    },
    {
      "x": 1,
      "y": 4,
      "z": -4,
      "name": "Plant_Grass_Sky_Long",
      "support": 15
    },
    {
      "x": 1,
      "y": 5,
      "z": -4,
      "name": "Plant_Grass_Sky_Long",
      "filler": 1024
    },
    {
      "x": 1,
      "y": -1,
      "z": -3,
      "name": "Rock_Marble"
    },
    {
      "x": 1,
      "y": 0,
      "z": -3,
      "name": "Rock_Marble"
    },
    {
      "x": 1,
      "y": 1,
      "z": -3,
      "name": "Rock_Marble"
    },
    {
      "x": 1,
      "y": 2,
      "z": -3,
      "name": "Rock_Marble_SkyGrass"
    },
    {
      "x": 1,
      "y": 3,
      "z": -3,
      "name": "Rock_Marble_SkyGrass"
    },
    {
      "x": 1,
      "y": -1,
      "z": -2,
      "name": "Rock_Marble"
    },
    {
      "x": 1,
      "y": 0,
      "z": -2,
      "name": "Rock_Marble"
    },
    {
      "x": 1,
      "y": 1,
      "z": -2,
      "name": "Rock_Marble"
    },
    {
      "x": 1,
      "y": 2,
      "z": -2,
      "name": "Rock_Marble_SkyGrass"
    },
    {
      "x": 1,
      "y": 3,
      "z": -2,
      "name": "Rock_Marble_SkyGrass"
    },
    {
      "x": 1,
      "y": -1,
      "z": -1,
      "name": "Rock_Marble"
    },
    {
      "x": 1,
      "y": 0,
      "z": -1,
      "name": "Rock_Marble"
    },
    {
      "x": 1,
      "y": 1,
      "z": -1,
      "name": "Rock_Marble"
    },
    {
      "x": 1,
      "y": 2,
      "z": -1,
      "name": "Rock_Marble_SkyGrass"
    },
    {
      "x": 1,
      "y": 3,
      "z": -1,
      "name": "Rock_Marble_SkyGrass"
    },
    {
      "x": 1,
      "y": 4,
      "z": -1,
      "name": "Rubble_Marble",
      "support": 15
    },
    {
      "x": 1,
      "y": -1,
      "z": 0,
      "name": "Rock_Marble"
    },
    {
      "x": 1,
      "y": 0,
      "z": 0,
      "name": "Rock_Marble"
    },
    {
      "x": 1,
      "y": 1,
      "z": 0,
      "name": "Rock_Marble"
    },
    {
      "x": 1,
      "y": 2,
      "z": 0,
      "name": "Rock_Marble_SkyGrass"
    },
    {
      "x": 1,
      "y": 3,
      "z": 0,
      "name": "Rock_Marble_Brick"
    },
    {
      "x": 1,
      "y": 8,
      "z": 0,
      "name": "Rock_Marble_Brick_Half"
    },
    {
      "x": 1,
      "y": -1,
      "z": 1,
      "name": "Rock_Marble"
    },
    {
      "x": 1,
      "y": 0,
      "z": 1,
      "name": "Rock_Marble"
    },
    {
      "x": 1,
      "y": 1,
      "z": 1,
      "name": "Rock_Marble"
    },
    {
      "x": 1,
      "y": 2,
      "z": 1,
      "name": "Rock_Marble_SkyGrass"
    },
    {
      "x": 1,
      "y": 3,
      "z": 1,
      "name": "Rock_Marble_Brick_Stairs"
    },
    {
      "x": 1,
      "y": -1,
      "z": 2,
      "name": "Rock_Marble"
    },
    {
      "x": 1,
      "y": 0,
      "z": 2,
      "name": "Rock_Marble"
    },
    {
      "x": 1,
      "y": 1,
      "z": 2,
      "name": "Rock_Marble"
    },
    {
      "x": 1,
      "y": 2,
      "z": 2,
      "name": "Rock_Marble_SkyGrass"
    },
    {
      "x": 1,
      "y": 3,
      "z": 2,
      "name": "Plant_Grass_Sky_Long",
      "support": 15
    },
    {
      "x": 1,
      "y": 4,
      "z": 2,
      "name": "Plant_Grass_Sky_Long",
      "filler": 1024
    },
    {
      "x": 1,
      "y": -1,
      "z": 3,
      "name": "Rock_Marble"
    },
    {
      "x": 1,
      "y": 0,
      "z": 3,
      "name": "Rock_Marble_SkyGrass"
    },
    {
      "x": 2,
      "y": 0,
      "z": -11,
      "name": "Rock_Marble"
    },
    {
      "x": 2,
      "y": 1,
      "z": -11,
      "name": "Rock_Marble_SkyGrass"
    },
    {
      "x": 2,
      "y": -1,
      "z": -10,
      "name": "Rock_Marble"
    },
    {
      "x": 2,
      "y": 0,
      "z": -10,
      "name": "Rock_Marble"
    },
    {
      "x": 2,
      "y": 1,
      "z": -10,
      "name": "Rock_Marble"
    },
    {
      "x": 2,
      "y": 2,
      "z": -10,
      "name": "Rock_Marble_SkyGrass"
    },
    {
      "x": 2,
      "y": -1,
      "z": -9,
      "name": "Rock_Marble"
    },
    {
      "x": 2,
      "y": 0,
      "z": -9,
      "name": "Rock_Marble"
    },
    {
      "x": 2,
      "y": 1,
      "z": -9,
      "name": "Rock_Marble"
    },
    {
      "x": 2,
      "y": 2,
      "z": -9,
      "name": "Rock_Marble_SkyGrass"
    },
    {
      "x": 2,
      "y": -1,
      "z": -8,
      "name": "Rock_Marble"
    },
    {
      "x": 2,
      "y": 0,
      "z": -8,
      "name": "Rock_Marble"
    },
    {
      "x": 2,
      "y": 1,
      "z": -8,
      "name": "Rock_Marble"
    },
    {
      "x": 2,
      "y": 2,
      "z": -8,
      "name": "Rock_Marble_SkyGrass"
    },
    {
      "x": 2,
      "y": 3,
      "z": -8,
      "name": "Rock_Marble_SkyGrass"
    },
    {
      "x": 2,
      "y": -1,
      "z": -7,
      "name": "Rock_Marble"
    },
    {
      "x": 2,
      "y": 0,
      "z": -7,
      "name": "Rock_Marble"
    },
    {
      "x": 2,
      "y": 1,
      "z": -7,
      "name": "Rock_Marble"
    },
    {
      "x": 2,
      "y": 2,
      "z": -7,
      "name": "Rock_Marble_SkyGrass"
    },
    {
      "x": 2,
      "y": 3,
      "z": -7,
      "name": "Rock_Marble_SkyGrass"
    },
    {
      "x": 2,
      "y": -1,
      "z": -6,
      "name": "Rock_Marble"
    },
    {
      "x": 2,
      "y": 0,
      "z": -6,
      "name": "Rock_Marble"
    },
    {
      "x": 2,
      "y": 1,
      "z": -6,
      "name": "Rock_Marble"
    },
    {
      "x": 2,
      "y": 2,
      "z": -6,
      "name": "Rock_Marble_SkyGrass"
    },
    {
      "x": 2,
      "y": 3,
      "z": -6,
      "name": "Rock_Marble_SkyGrass"
    },
    {
      "x": 2,
      "y": 4,
      "z": -6,
      "name": "Rock_Marble_Brick_Pillar_Base"
    },
    {
      "x": 2,
      "y": 5,
      "z": -6,
      "name": "Rock_Marble_Brick_Pillar_Middle"
    },
    {
      "x": 2,
      "y": 6,
      "z": -6,
      "name": "Rock_Marble_Brick_Pillar_Middle"
    },
    {
      "x": 2,
      "y": 7,
      "z": -6,
      "name": "Rock_Marble_Brick_Pillar_Base",
      "rotation": 8
    },
    {
      "x": 2,
      "y": 8,
      "z": -6,
      "name": "Rock_Marble_Brick"
    },
    {
      "x": 2,
      "y": 9,
      "z": -6,
      "name": "Rubble_Marble",
      "support": 15
    },
    {
      "x": 2,
      "y": -1,
      "z": -5,
      "name": "Rock_Marble"
    },
    {
      "x": 2,
      "y": 0,
      "z": -5,
      "name": "Rock_Marble"
    },
    {
      "x": 2,
      "y": 1,
      "z": -5,
      "name": "Rock_Marble"
    },
    {
      "x": 2,
      "y": 2,
      "z": -5,
      "name": "Rock_Marble_SkyGrass"
    },
    {
      "x": 2,
      "y": 3,
      "z": -5,
      "name": "Rock_Marble_SkyGrass"
    },
    {
      "x": 2,
      "y": 4,
      "z": -5,
      "name": "Plant_Bush_Sky",
      "support": 15
    },
    {
      "x": 2,
      "y": -1,
      "z": -4,
      "name": "Rock_Marble"
    },
    {
      "x": 2,
      "y": 0,
      "z": -4,
      "name": "Rock_Marble"
    },
    {
      "x": 2,
      "y": 1,
      "z": -4,
      "name": "Rock_Marble"
    },
    {
      "x": 2,
      "y": 2,
      "z": -4,
      "name": "Rock_Marble_SkyGrass"
    },
    {
      "x": 2,
      "y": 3,
      "z": -4,
      "name": "Rock_Marble_SkyGrass"
    },
    {
      "x": 2,
      "y": -1,
      "z": -3,
      "name": "Rock_Marble"
    },
    {
      "x": 2,
      "y": 0,
      "z": -3,
      "name": "Rock_Marble"
    },
    {
      "x": 2,
      "y": 1,
      "z": -3,
      "name": "Rock_Marble"
    },
    {
      "x": 2,
      "y": 2,
      "z": -3,
      "name": "Rock_Marble_SkyGrass"
    },
    {
      "x": 2,
      "y": 3,
      "z": -3,
      "name": "Rock_Marble_Brick"
    },
    {
      "x": 2,
      "y": -1,
      "z": -2,
      "name": "Rock_Marble"
    },
    {
      "x": 2,
      "y": 0,
      "z": -2,
      "name": "Rock_Marble"
    },
    {
      "x": 2,
      "y": 1,
      "z": -2,
      "name": "Rock_Marble"
    },
    {
      "x": 2,
      "y": 2,
      "z": -2,
      "name": "Rock_Marble_SkyGrass"
    },
    {
      "x": 2,
      "y": 3,
      "z": -2,
      "name": "Rock_Marble_SkyGrass"
    },
    {
      "x": 2,
      "y": 4,
      "z": -2,
      "name": "Plant_Grass_Sky_Wild",
      "support": 15
    },
    {
      "x": 2,
      "y": 5,
      "z": -2,
      "name": "Plant_Grass_Sky_Wild",
      "filler": 1024
    },
    {
      "x": 2,
      "y": -1,
      "z": -1,
      "name": "Rock_Marble"
    },
    {
      "x": 2,
      "y": 0,
      "z": -1,
      "name": "Rock_Marble"
    },
    {
      "x": 2,
      "y": 1,
      "z": -1,
      "name": "Rock_Marble"
    },
    {
      "x": 2,
      "y": 2,
      "z": -1,
      "name": "Rock_Marble_SkyGrass"
    },
    {
      "x": 2,
      "y": 3,
      "z": -1,
      "name": "Rock_Marble_SkyGrass"
    },
    {
      "x": 2,
      "y": 4,
      "z": -1,
      "name": "Plant_Grass_Sky",
      "support": 15
    },
    {
      "x": 2,
      "y": -1,
      "z": 0,
      "name": "Rock_Marble"
    },
    {
      "x": 2,
      "y": 0,
      "z": 0,
      "name": "Rock_Marble"
    },
    {
      "x": 2,
      "y": 1,
      "z": 0,
      "name": "Rock_Marble"
    },
    {
      "x": 2,
      "y": 2,
      "z": 0,
      "name": "Rock_Marble_SkyGrass"
    },
    {
      "x": 2,
      "y": 3,
      "z": 0,
      "name": "Rock_Marble_Brick"
    },
    {
      "x": 2,
      "y": 4,
      "z": 0,
      "name": "Rock_Marble_Brick_Pillar_Base"
    },
    {
      "x": 2,
      "y": 5,
      "z": 0,
      "name": "Rock_Marble_Brick_Pillar_Middle"
    },
    {
      "x": 2,
      "y": 6,
      "z": 0,
      "name": "Rock_Marble_Brick_Pillar_Middle"
    },
    {
      "x": 2,
      "y": 7,
      "z": 0,
      "name": "Rock_Marble_Brick_Pillar_Base",
      "rotation": 8
    },
    {
      "x": 2,
      "y": 8,
      "z": 0,
      "name": "Rock_Marble_Brick"
    },
    {
      "x": 2,
      "y": -1,
      "z": 1,
      "name": "Rock_Marble"
    },
    {
      "x": 2,
      "y": 0,
      "z": 1,
      "name": "Rock_Marble"
    },
    {
      "x": 2,
      "y": 1,
      "z": 1,
      "name": "Rock_Marble"
    },
    {
      "x": 2,
      "y": 2,
      "z": 1,
      "name": "Rock_Marble_SkyGrass"
    },
    {
      "x": 2,
      "y": 3,
      "z": 1,
      "name": "Plant_Bush_Sky",
      "support": 15
    },
    {
      "x": 2,
      "y": -1,
      "z": 2,
      "name": "Rock_Marble"
    },
    {
      "x": 2,
      "y": 0,
      "z": 2,
      "name": "Rock_Marble"
    },
    {
      "x": 2,
      "y": 1,
      "z": 2,
      "name": "Rock_Marble"
    },
    {
      "x": 2,
      "y": 2,
      "z": 2,
      "name": "Rock_Marble_SkyGrass"
    },
    {
      "x": 2,
      "y": 0,
      "z": 3,
      "name": "Rock_Marble_SkyGrass"
    },
    {
      "x": 3,
      "y": 0,
      "z": -11,
      "name": "Rock_Marble"
    },
    {
      "x": 3,
      "y": 1,
      "z": -11,
      "name": "Rock_Marble_SkyGrass"
    },
    {
      "x": 3,
      "y": -1,
      "z": -10,
      "name": "Rock_Marble"
    },
    {
      "x": 3,
      "y": 0,
      "z": -10,
      "name": "Rock_Marble"
    },
    {
      "x": 3,
      "y": 1,
      "z": -10,
      "name": "Rock_Marble_SkyGrass"
    },
    {
      "x": 3,
      "y": -1,
      "z": -9,
      "name": "Rock_Marble"
    },
    {
      "x": 3,
      "y": 0,
      "z": -9,
      "name": "Rock_Marble"
    },
    {
      "x": 3,
      "y": 1,
      "z": -9,
      "name": "Rock_Marble"
    },
    {
      "x": 3,
      "y": 2,
      "z": -9,
      "name": "Rock_Marble_SkyGrass"
    },
    {
      "x": 3,
      "y": 3,
      "z": -9,
      "name": "Plant_Grass_Sky",
      "support": 15
    },
    {
      "x": 3,
      "y": -1,
      "z": -8,
      "name": "Rock_Marble"
    },
    {
      "x": 3,
      "y": 0,
      "z": -8,
      "name": "Rock_Marble"
    },
    {
      "x": 3,
      "y": 1,
      "z": -8,
      "name": "Rock_Marble"
    },
    {
      "x": 3,
      "y": 2,
      "z": -8,
      "name": "Rock_Marble_SkyGrass"
    },
    {
      "x": 3,
      "y": -1,
      "z": -7,
      "name": "Rock_Marble"
    },
    {
      "x": 3,
      "y": 0,
      "z": -7,
      "name": "Rock_Marble"
    },
    {
      "x": 3,
      "y": 1,
      "z": -7,
      "name": "Rock_Marble"
    },
    {
      "x": 3,
      "y": 2,
      "z": -7,
      "name": "Rock_Marble_SkyGrass"
    },
    {
      "x": 3,
      "y": 3,
      "z": -7,
      "name": "Rock_Marble_SkyGrass"
    },
    {
      "x": 3,
      "y": 4,
      "z": -7,
      "name": "Plant_Grass_Sky",
      "support": 15
    },
    {
      "x": 3,
      "y": -1,
      "z": -6,
      "name": "Rock_Marble"
    },
    {
      "x": 3,
      "y": 0,
      "z": -6,
      "name": "Rock_Marble"
    },
    {
      "x": 3,
      "y": 1,
      "z": -6,
      "name": "Rock_Marble"
    },
    {
      "x": 3,
      "y": 2,
      "z": -6,
      "name": "Rock_Marble_SkyGrass"
    },
    {
      "x": 3,
      "y": 3,
      "z": -6,
      "name": "Rock_Marble_Brick"
    },
    {
      "x": 3,
      "y": 8,
      "z": -6,
      "name": "Rock_Marble_Brick"
    },
    {
      "x": 3,
      "y": 9,
      "z": -6,
      "name": "Rubble_Marble_Medium",
      "support": 15
    },
    {
      "x": 3,
      "y": -1,
      "z": -5,
      "name": "Rock_Marble"
    },
    {
      "x": 3,
      "y": 0,
      "z": -5,
      "name": "Rock_Marble"
    },
    {
      "x": 3,
      "y": 1,
      "z": -5,
      "name": "Rock_Marble"
    },
    {
      "x": 3,
      "y": 2,
      "z": -5,
      "name": "Rock_Marble_SkyGrass"
    },
    {
      "x": 3,
      "y": 3,
      "z": -5,
      "name": "Rock_Marble_Brick_Decorative"
    },
    {
      "x": 3,
      "y": -1,
      "z": -4,
      "name": "Rock_Marble"
    },
    {
      "x": 3,
      "y": 0,
      "z": -4,
      "name": "Rock_Marble"
    },
    {
      "x": 3,
      "y": 1,
      "z": -4,
      "name": "Rock_Marble"
    },
    {
      "x": 3,
      "y": 2,
      "z": -4,
      "name": "Rock_Marble_SkyGrass"
    },
    {
      "x": 3,
      "y": 3,
      "z": -4,
      "name": "Rock_Marble_Brick"
    },
    {
      "x": 3,
      "y": -1,
      "z": -3,
      "name": "Rock_Marble"
    },
    {
      "x": 3,
      "y": 0,
      "z": -3,
      "name": "Rock_Marble"
    },
    {
      "x": 3,
      "y": 1,
      "z": -3,
      "name": "Rock_Marble"
    },
    {
      "x": 3,
      "y": 2,
      "z": -3,
      "name": "Rock_Marble_SkyGrass"
    },
    {
      "x": 3,
      "y": 3,
      "z": -3,
      "name": "Rock_Marble_Brick"
    },
    {
      "x": 3,
      "y": 4,
      "z": -3,
      "name": "Rubble_Marble_Medium",
      "support": 15
    },
    {
      "x": 3,
      "y": -1,
      "z": -2,
      "name": "Rock_Marble"
    },
    {
      "x": 3,
      "y": 0,
      "z": -2,
      "name": "Rock_Marble"
    },
    {
      "x": 3,
      "y": 1,
      "z": -2,
      "name": "Rock_Marble"
    },
    {
      "x": 3,
      "y": 2,
      "z": -2,
      "name": "Rock_Marble_SkyGrass"
    },
    {
      "x": 3,
      "y": 3,
      "z": -2,
      "name": "Rock_Marble_Brick"
    },
    {
      "x": 3,
      "y": -1,
      "z": -1,
      "name": "Rock_Marble"
    },
    {
      "x": 3,
      "y": 0,
      "z": -1,
      "name": "Rock_Marble"
    },
    {
      "x": 3,
      "y": 1,
      "z": -1,
      "name": "Rock_Marble"
    },
    {
      "x": 3,
      "y": 2,
      "z": -1,
      "name": "Rock_Marble_SkyGrass"
    },
    {
      "x": 3,
      "y": 3,
      "z": -1,
      "name": "Rock_Marble_Brick_Decorative"
    },
    {
      "x": 3,
      "y": -1,
      "z": 0,
      "name": "Rock_Marble"
    },
    {
      "x": 3,
      "y": 0,
      "z": 0,
      "name": "Rock_Marble"
    },
    {
      "x": 3,
      "y": 1,
      "z": 0,
      "name": "Rock_Marble"
    },
    {
      "x": 3,
      "y": 2,
      "z": 0,
      "name": "Rock_Marble_SkyGrass"
    },
    {
      "x": 3,
      "y": 3,
      "z": 0,
      "name": "Rock_Marble_Brick"
    },
    {
      "x": 3,
      "y": 8,
      "z": 0,
      "name": "Rock_Marble_Brick"
    },
    {
      "x": 3,
      "y": -1,
      "z": 1,
      "name": "Rock_Marble"
    },
    {
      "x": 3,
      "y": 0,
      "z": 1,
      "name": "Rock_Marble"
    },
    {
      "x": 3,
      "y": 1,
      "z": 1,
      "name": "Rock_Marble"
    },
    {
      "x": 3,
      "y": 2,
      "z": 1,
      "name": "Rock_Marble_SkyGrass"
    },
    {
      "x": 3,
      "y": 3,
      "z": 1,
      "name": "Rubble_Marble_Medium",
      "support": 15
    },
    {
      "x": 3,
      "y": 8,
      "z": 1,
      "name": "Rock_Marble_Brick"
    },
    {
      "x": 3,
      "y": -1,
      "z": 2,
      "name": "Rock_Marble"
    },
    {
      "x": 3,
      "y": 0,
      "z": 2,
      "name": "Rock_Marble"
    },
    {
      "x": 3,
      "y": 1,
      "z": 2,
      "name": "Rock_Marble"
    },
    {
      "x": 3,
      "y": 2,
      "z": 2,
      "name": "Rock_Marble_SkyGrass"
    },
    {
      "x": 4,
      "y": 0,
      "z": -11,
      "name": "Rock_Marble"
    },
    {
      "x": 4,
      "y": 1,
      "z": -11,
      "name": "Rock_Marble_SkyGrass"
    },
    {
      "x": 4,
      "y": -1,
      "z": -10,
      "name": "Rock_Marble"
    },
    {
      "x": 4,
      "y": 0,
      "z": -10,
      "name": "Rock_Marble"
    },
    {
      "x": 4,
      "y": 1,
      "z": -10,
      "name": "Rock_Marble_SkyGrass"
    },
    {
      "x": 4,
      "y": -1,
      "z": -9,
      "name": "Rock_Marble"
    },
    {
      "x": 4,
      "y": 0,
      "z": -9,
      "name": "Rock_Marble"
    },
    {
      "x": 4,
      "y": 1,
      "z": -9,
      "name": "Rock_Marble"
    },
    {
      "x": 4,
      "y": 2,
      "z": -9,
      "name": "Rock_Marble_SkyGrass"
    },
    {
      "x": 4,
      "y": -1,
      "z": -8,
      "name": "Rock_Marble"
    },
    {
      "x": 4,
      "y": 0,
      "z": -8,
      "name": "Rock_Marble"
    },
    {
      "x": 4,
      "y": 1,
      "z": -8,
      "name": "Rock_Marble"
    },
    {
      "x": 4,
      "y": 2,
      "z": -8,
      "name": "Rock_Marble_SkyGrass"
    },
    {
      "x": 4,
      "y": -1,
      "z": -7,
      "name": "Rock_Marble"
    },
    {
      "x": 4,
      "y": 0,
      "z": -7,
      "name": "Rock_Marble"
    },
    {
      "x": 4,
      "y": 1,
      "z": -7,
      "name": "Rock_Marble"
    },
    {
      "x": 4,
      "y": 2,
      "z": -7,
      "name": "Rock_Marble_SkyGrass"
    },
    {
      "x": 4,
      "y": 3,
      "z": -7,
      "name": "Rock_Marble_Brick_Stairs",
      "rotation": 2
    },
    {
      "x": 4,
      "y": 8,
      "z": -7,
      "name": "Rock_Marble_Brick"
    },
    {
      "x": 4,
      "y": 9,
      "z": -7,
      "name": "Rock_Marble_Brick_Roof_Shallow",
      "rotation": 2
    },
    {
      "x": 4,
      "y": -1,
      "z": -6,
      "name": "Rock_Marble"
    },
    {
      "x": 4,
      "y": 0,
      "z": -6,
      "name": "Rock_Marble"
    },
    {
      "x": 4,
      "y": 1,
      "z": -6,
      "name": "Rock_Marble"
    },
    {
      "x": 4,
      "y": 2,
      "z": -6,
      "name": "Rock_Marble_SkyGrass"
    },
    {
      "x": 4,
      "y": 3,
      "z": -6,
      "name": "Rock_Marble_Brick"
    },
    {
      "x": 4,
      "y": 4,
      "z": -6,
      "name": "Rock_Marble_Brick_Pillar_Base"
    },
    {
      "x": 4,
      "y": 5,
      "z": -6,
      "name": "Rock_Marble_Brick_Pillar_Middle"
    },
    {
      "x": 4,
      "y": 6,
      "z": -6,
      "name": "Rock_Marble_Brick_Pillar_Middle"
    },
    {
      "x": 4,
      "y": 7,
      "z": -6,
      "name": "Rock_Marble_Brick_Pillar_Base",
      "rotation": 8
    },
    {
      "x": 4,
      "y": 8,
      "z": -6,
      "name": "Rock_Marble_Brick"
    },
    {
      "x": 4,
      "y": 9,
      "z": -6,
      "name": "Rock_Marble_Brick_Roof_Shallow",
      "filler": 32,
      "rotation": 2
    },
    {
      "x": 4,
      "y": -1,
      "z": -5,
      "name": "Rock_Marble"
    },
    {
      "x": 4,
      "y": 0,
      "z": -5,
      "name": "Rock_Marble"
    },
    {
      "x": 4,
      "y": 1,
      "z": -5,
      "name": "Rock_Marble"
    },
    {
      "x": 4,
      "y": 2,
      "z": -5,
      "name": "Rock_Marble_SkyGrass"
    },
    {
      "x": 4,
      "y": 3,
      "z": -5,
      "name": "Rock_Marble_Brick"
    },
    {
      "x": 4,
      "y": -1,
      "z": -4,
      "name": "Rock_Marble"
    },
    {
      "x": 4,
      "y": 0,
      "z": -4,
      "name": "Rock_Marble"
    },
    {
      "x": 4,
      "y": 1,
      "z": -4,
      "name": "Rock_Marble"
    },
    {
      "x": 4,
      "y": 2,
      "z": -4,
      "name": "Rock_Marble_SkyGrass"
    },
    {
      "x": 4,
      "y": 3,
      "z": -4,
      "name": "Rock_Marble_Brick"
    },
    {
      "x": 4,
      "y": 4,
      "z": -4,
      "name": "Rock_Marble_Brick_Pillar_Base"
    },
    {
      "x": 4,
      "y": 5,
      "z": -4,
      "name": "Rock_Marble_Brick_Pillar_Middle"
    },
    {
      "x": 4,
      "y": 6,
      "z": -4,
      "name": "Rock_Marble_Brick_Pillar_Middle"
    },
    {
      "x": 4,
      "y": 7,
      "z": -4,
      "name": "Rock_Marble_Brick_Pillar_Base",
      "rotation": 8
    },
    {
      "x": 4,
      "y": 8,
      "z": -4,
      "name": "Rock_Marble_Brick_Half"
    },
    {
      "x": 4,
      "y": -1,
      "z": -3,
      "name": "Rock_Marble"
    },
    {
      "x": 4,
      "y": 0,
      "z": -3,
      "name": "Rock_Marble"
    },
    {
      "x": 4,
      "y": 1,
      "z": -3,
      "name": "Rock_Marble"
    },
    {
      "x": 4,
      "y": 2,
      "z": -3,
      "name": "Rock_Marble_SkyGrass"
    },
    {
      "x": 4,
      "y": 3,
      "z": -3,
      "name": "Rock_Marble_Brick"
    },
    {
      "x": 4,
      "y": 8,
      "z": -3,
      "name": "Rock_Marble_Brick"
    },
    {
      "x": 4,
      "y": 9,
      "z": -3,
      "name": "Plant_Crop_Mushroom_Shelve_Yellow"
    },
    {
      "x": 4,
      "y": -1,
      "z": -2,
      "name": "Rock_Marble"
    },
    {
      "x": 4,
      "y": 0,
      "z": -2,
      "name": "Rock_Marble"
    },
    {
      "x": 4,
      "y": 1,
      "z": -2,
      "name": "Rock_Marble"
    },
    {
      "x": 4,
      "y": 2,
      "z": -2,
      "name": "Rock_Marble_SkyGrass"
    },
    {
      "x": 4,
      "y": 3,
      "z": -2,
      "name": "Rock_Marble_Brick"
    },
    {
      "x": 4,
      "y": 4,
      "z": -2,
      "name": "Rock_Marble_Brick_Pillar_Base"
    },
    {
      "x": 4,
      "y": 5,
      "z": -2,
      "name": "Rock_Marble_Brick_Pillar_Middle"
    },
    {
      "x": 4,
      "y": 6,
      "z": -2,
      "name": "Rock_Marble_Brick_Pillar_Middle"
    },
    {
      "x": 4,
      "y": 7,
      "z": -2,
      "name": "Rock_Marble_Brick_Pillar_Base",
      "rotation": 8
    },
    {
      "x": 4,
      "y": 8,
      "z": -2,
      "name": "Rock_Marble_Brick"
    },
    {
      "x": 4,
      "y": 9,
      "z": -2,
      "name": "Rubble_Marble",
      "support": 15
    },
    {
      "x": 4,
      "y": -1,
      "z": -1,
      "name": "Rock_Marble"
    },
    {
      "x": 4,
      "y": 0,
      "z": -1,
      "name": "Rock_Marble"
    },
    {
      "x": 4,
      "y": 1,
      "z": -1,
      "name": "Rock_Marble"
    },
    {
      "x": 4,
      "y": 2,
      "z": -1,
      "name": "Rock_Marble_SkyGrass"
    },
    {
      "x": 4,
      "y": 3,
      "z": -1,
      "name": "Rock_Marble_Brick"
    },
    {
      "x": 4,
      "y": 8,
      "z": -1,
      "name": "Rock_Marble_Brick"
    },
    {
      "x": 4,
      "y": -1,
      "z": 0,
      "name": "Rock_Marble"
    },
    {
      "x": 4,
      "y": 0,
      "z": 0,
      "name": "Rock_Marble"
    },
    {
      "x": 4,
      "y": 1,
      "z": 0,
      "name": "Rock_Marble"
    },
    {
      "x": 4,
      "y": 2,
      "z": 0,
      "name": "Rock_Marble_SkyGrass"
    },
    {
      "x": 4,
      "y": 3,
      "z": 0,
      "name": "Rock_Marble_Brick"
    },
    {
      "x": 4,
      "y": 4,
      "z": 0,
      "name": "Rock_Marble_Brick_Pillar_Base"
    },
    {
      "x": 4,
      "y": 5,
      "z": 0,
      "name": "Rock_Marble_Brick_Pillar_Middle"
    },
    {
      "x": 4,
      "y": 6,
      "z": 0,
      "name": "Rock_Marble_Brick_Pillar_Middle"
    },
    {
      "x": 4,
      "y": 7,
      "z": 0,
      "name": "Rock_Marble_Brick_Pillar_Base",
      "rotation": 8
    },
    {
      "x": 4,
      "y": 8,
      "z": 0,
      "name": "Rock_Marble_Brick"
    },
    {
      "x": 4,
      "y": -1,
      "z": 1,
      "name": "Rock_Marble"
    },
    {
      "x": 4,
      "y": 0,
      "z": 1,
      "name": "Rock_Marble"
    },
    {
      "x": 4,
      "y": 1,
      "z": 1,
      "name": "Rock_Marble"
    },
    {
      "x": 4,
      "y": 2,
      "z": 1,
      "name": "Rock_Marble_SkyGrass"
    },
    {
      "x": 4,
      "y": 3,
      "z": 1,
      "name": "Rock_Marble_Brick_Stairs"
    },
    {
      "x": 4,
      "y": 8,
      "z": 1,
      "name": "Rock_Marble_Brick"
    },
    {
      "x": 4,
      "y": 9,
      "z": 1,
      "name": "Rubble_Marble_Medium",
      "support": 15
    },
    {
      "x": 4,
      "y": -1,
      "z": 2,
      "name": "Rock_Marble"
    },
    {
      "x": 4,
      "y": 0,
      "z": 2,
      "name": "Rock_Marble"
    },
    {
      "x": 4,
      "y": 1,
      "z": 2,
      "name": "Rock_Marble"
    },
    {
      "x": 4,
      "y": 2,
      "z": 2,
      "name": "Rock_Marble_SkyGrass"
    },
    {
      "x": 4,
      "y": -1,
      "z": 3,
      "name": "Rock_Marble"
    },
    {
      "x": 4,
      "y": 0,
      "z": 3,
      "name": "Rock_Marble"
    },
    {
      "x": 4,
      "y": 1,
      "z": 3,
      "name": "Rock_Marble_SkyGrass"
    },
    {
      "x": 5,
      "y": -1,
      "z": -10,
      "name": "Rock_Marble"
    },
    {
      "x": 5,
      "y": 0,
      "z": -10,
      "name": "Rock_Marble"
    },
    {
      "x": 5,
      "y": 1,
      "z": -10,
      "name": "Rock_Marble_SkyGrass"
    },
    {
      "x": 5,
      "y": -1,
      "z": -9,
      "name": "Rock_Marble"
    },
    {
      "x": 5,
      "y": 0,
      "z": -9,
      "name": "Rock_Marble"
    },
    {
      "x": 5,
      "y": 1,
      "z": -9,
      "name": "Rock_Marble"
    },
    {
      "x": 5,
      "y": 2,
      "z": -9,
      "name": "Rock_Marble_SkyGrass"
    },
    {
      "x": 5,
      "y": -1,
      "z": -8,
      "name": "Rock_Marble"
    },
    {
      "x": 5,
      "y": 0,
      "z": -8,
      "name": "Rock_Marble"
    },
    {
      "x": 5,
      "y": 1,
      "z": -8,
      "name": "Rock_Marble"
    },
    {
      "x": 5,
      "y": 2,
      "z": -8,
      "name": "Rock_Marble_SkyGrass"
    },
    {
      "x": 5,
      "y": -1,
      "z": -7,
      "name": "Rock_Marble"
    },
    {
      "x": 5,
      "y": 0,
      "z": -7,
      "name": "Rock_Marble"
    },
    {
      "x": 5,
      "y": 1,
      "z": -7,
      "name": "Rock_Marble"
    },
    {
      "x": 5,
      "y": 2,
      "z": -7,
      "name": "Rock_Marble_SkyGrass"
    },
    {
      "x": 5,
      "y": 3,
      "z": -7,
      "name": "*Rock_Marble_Brick_Stairs_State_Definitions_Corner_Left",
      "rotation": 1
    },
    {
      "x": 5,
      "y": 8,
      "z": -7,
      "name": "Rock_Marble_Brick"
    },
    {
      "x": 5,
      "y": 9,
      "z": -7,
      "name": "Rock_Marble_Brick_Roof_Shallow",
      "rotation": 2
    },
    {
      "x": 5,
      "y": -1,
      "z": -6,
      "name": "Rock_Marble"
    },
    {
      "x": 5,
      "y": 0,
      "z": -6,
      "name": "Rock_Marble"
    },
    {
      "x": 5,
      "y": 1,
      "z": -6,
      "name": "Rock_Marble"
    },
    {
      "x": 5,
      "y": 2,
      "z": -6,
      "name": "Rock_Marble_SkyGrass"
    },
    {
      "x": 5,
      "y": 3,
      "z": -6,
      "name": "Rock_Marble_Brick_Stairs",
      "rotation": 1
    },
    {
      "x": 5,
      "y": 8,
      "z": -6,
      "name": "Rock_Marble_Brick"
    },
    {
      "x": 5,
      "y": 9,
      "z": -6,
      "name": "Rock_Marble_Brick_Roof_Shallow",
      "filler": 32,
      "rotation": 2
    },
    {
      "x": 5,
      "y": -1,
      "z": -5,
      "name": "Rock_Marble"
    },
    {
      "x": 5,
      "y": 0,
      "z": -5,
      "name": "Rock_Marble"
    },
    {
      "x": 5,
      "y": 1,
      "z": -5,
      "name": "Rock_Marble"
    },
    {
      "x": 5,
      "y": 2,
      "z": -5,
      "name": "Rock_Marble_SkyGrass"
    },
    {
      "x": 5,
      "y": 3,
      "z": -5,
      "name": "Rock_Marble_Brick_Stairs",
      "rotation": 1
    },
    {
      "x": 5,
      "y": 8,
      "z": -5,
      "name": "Rock_Marble_Brick_Smooth_Half",
      "rotation": 8
    },
    {
      "x": 5,
      "y": 9,
      "z": -5,
      "name": "Rock_Marble_Brick"
    },
    {
      "x": 5,
      "y": 10,
      "z": -5,
      "name": "Rubble_Marble",
      "support": 15
    },
    {
      "x": 5,
      "y": -1,
      "z": -4,
      "name": "Rock_Marble"
    },
    {
      "x": 5,
      "y": 0,
      "z": -4,
      "name": "Rock_Marble"
    },
    {
      "x": 5,
      "y": 1,
      "z": -4,
      "name": "Rock_Marble"
    },
    {
      "x": 5,
      "y": 2,
      "z": -4,
      "name": "Rock_Marble_SkyGrass"
    },
    {
      "x": 5,
      "y": 3,
      "z": -4,
      "name": "Rock_Marble_Brick_Stairs",
      "rotation": 1
    },
    {
      "x": 5,
      "y": 8,
      "z": -4,
      "name": "Rock_Marble_Brick"
    },
    {
      "x": 5,
      "y": 9,
      "z": -4,
      "name": "Rock_Marble_Brick_Half"
    },
    {
      "x": 5,
      "y": -1,
      "z": -3,
      "name": "Rock_Marble"
    },
    {
      "x": 5,
      "y": 0,
      "z": -3,
      "name": "Rock_Marble"
    },
    {
      "x": 5,
      "y": 1,
      "z": -3,
      "name": "Rock_Marble"
    },
    {
      "x": 5,
      "y": 2,
      "z": -3,
      "name": "Rock_Marble_SkyGrass"
    },
    {
      "x": 5,
      "y": 3,
      "z": -3,
      "name": "Rock_Marble_Brick_Stairs",
      "rotation": 1
    },
    {
      "x": 5,
      "y": 8,
      "z": -3,
      "name": "Rock_Marble_Brick"
    },
    {
      "x": 5,
      "y": 9,
      "z": -3,
      "name": "Rubble_Marble_Medium",
      "support": 15
    },
    {
      "x": 5,
      "y": -1,
      "z": -2,
      "name": "Rock_Marble"
    },
    {
      "x": 5,
      "y": 0,
      "z": -2,
      "name": "Rock_Marble"
    },
    {
      "x": 5,
      "y": 1,
      "z": -2,
      "name": "Rock_Marble"
    },
    {
      "x": 5,
      "y": 2,
      "z": -2,
      "name": "Rock_Marble_SkyGrass"
    },
    {
      "x": 5,
      "y": 3,
      "z": -2,
      "name": "Rock_Marble_Brick_Stairs",
      "rotation": 1
    },
    {
      "x": 5,
      "y": 8,
      "z": -2,
      "name": "Rock_Marble_Brick"
    },
    {
      "x": 5,
      "y": 9,
      "z": -2,
      "name": "Rock_Marble_Brick_Smooth_Half",
      "rotation": 8
    },
    {
      "x": 5,
      "y": 10,
      "z": -2,
      "name": "Rock_Marble_Brick_Roof_Shallow",
      "filler": 992
    },
    {
      "x": 5,
      "y": -1,
      "z": -1,
      "name": "Rock_Marble"
    },
    {
      "x": 5,
      "y": 0,
      "z": -1,
      "name": "Rock_Marble"
    },
    {
      "x": 5,
      "y": 1,
      "z": -1,
      "name": "Rock_Marble"
    },
    {
      "x": 5,
      "y": 2,
      "z": -1,
      "name": "Rock_Marble_SkyGrass"
    },
    {
      "x": 5,
      "y": 3,
      "z": -1,
      "name": "Rock_Marble_Brick_Stairs",
      "rotation": 1
    },
    {
      "x": 5,
      "y": 8,
      "z": -1,
      "name": "Rock_Marble_Brick"
    },
    {
      "x": 5,
      "y": 9,
      "z": -1,
      "name": "Rock_Marble_Brick"
    },
    {
      "x": 5,
      "y": 10,
      "z": -1,
      "name": "Rock_Marble_Brick_Roof_Shallow"
    },
    {
      "x": 5,
      "y": -1,
      "z": 0,
      "name": "Rock_Marble"
    },
    {
      "x": 5,
      "y": 0,
      "z": 0,
      "name": "Rock_Marble"
    },
    {
      "x": 5,
      "y": 1,
      "z": 0,
      "name": "Rock_Marble"
    },
    {
      "x": 5,
      "y": 2,
      "z": 0,
      "name": "Rock_Marble_SkyGrass"
    },
    {
      "x": 5,
      "y": 3,
      "z": 0,
      "name": "Rock_Marble_Brick_Stairs",
      "rotation": 1
    },
    {
      "x": 5,
      "y": 8,
      "z": 0,
      "name": "Rock_Marble_Brick"
    },
    {
      "x": 5,
      "y": 9,
      "z": 0,
      "name": "Rock_Marble_Brick_Roof_Shallow",
      "filler": 992
    },
    {
      "x": 5,
      "y": -1,
      "z": 1,
      "name": "Rock_Marble"
    },
    {
      "x": 5,
      "y": 0,
      "z": 1,
      "name": "Rock_Marble"
    },
    {
      "x": 5,
      "y": 1,
      "z": 1,
      "name": "Rock_Marble"
    },
    {
      "x": 5,
      "y": 2,
      "z": 1,
      "name": "Rock_Marble_SkyGrass"
    },
    {
      "x": 5,
      "y": 3,
      "z": 1,
      "name": "*Rock_Marble_Brick_Stairs_State_Definitions_Corner_Right",
      "rotation": 1
    },
    {
      "x": 5,
      "y": 8,
      "z": 1,
      "name": "Rock_Marble_Brick"
    },
    {
      "x": 5,
      "y": 9,
      "z": 1,
      "name": "Rock_Marble_Brick_Roof_Shallow"
    },
    {
      "x": 5,
      "y": -1,
      "z": 2,
      "name": "Rock_Marble"
    },
    {
      "x": 5,
      "y": 0,
      "z": 2,
      "name": "Rock_Marble"
    },
    {
      "x": 5,
      "y": 1,
      "z": 2,
      "name": "Rock_Marble"
    },
    {
      "x": 5,
      "y": 2,
      "z": 2,
      "name": "Rock_Marble_SkyGrass"
    },
    {
      "x": 5,
      "y": -1,
      "z": 3,
      "name": "Rock_Marble"
    },
    {
      "x": 5,
      "y": 0,
      "z": 3,
      "name": "Rock_Marble"
    },
    {
      "x": 5,
      "y": 1,
      "z": 3,
      "name": "Rock_Marble_SkyGrass"
    },
    {
      "x": 6,
      "y": 0,
      "z": -10,
      "name": "Rock_Marble"
    },
    {
      "x": 6,
      "y": 1,
      "z": -10,
      "name": "Rock_Marble_SkyGrass"
    },
    {
      "x": 6,
      "y": -1,
      "z": -9,
      "name": "Rock_Marble"
    },
    {
      "x": 6,
      "y": 0,
      "z": -9,
      "name": "Rock_Marble"
    },
    {
      "x": 6,
      "y": 1,
      "z": -9,
      "name": "Rock_Marble_SkyGrass"
    },
    {
      "x": 6,
      "y": -1,
      "z": -8,
      "name": "Rock_Marble"
    },
    {
      "x": 6,
      "y": 0,
      "z": -8,
      "name": "Rock_Marble"
    },
    {
      "x": 6,
      "y": 1,
      "z": -8,
      "name": "Rock_Marble"
    },
    {
      "x": 6,
      "y": 2,
      "z": -8,
      "name": "Rock_Marble_SkyGrass"
    },
    {
      "x": 6,
      "y": -1,
      "z": -7,
      "name": "Rock_Marble"
    },
    {
      "x": 6,
      "y": 0,
      "z": -7,
      "name": "Rock_Marble"
    },
    {
      "x": 6,
      "y": 1,
      "z": -7,
      "name": "Rock_Marble"
    },
    {
      "x": 6,
      "y": 2,
      "z": -7,
      "name": "Rock_Marble_SkyGrass"
    },
    {
      "x": 6,
      "y": -1,
      "z": -6,
      "name": "Rock_Marble"
    },
    {
      "x": 6,
      "y": 0,
      "z": -6,
      "name": "Rock_Marble"
    },
    {
      "x": 6,
      "y": 1,
      "z": -6,
      "name": "Rock_Marble"
    },
    {
      "x": 6,
      "y": 2,
      "z": -6,
      "name": "Rock_Marble_SkyGrass"
    },
    {
      "x": 6,
      "y": -1,
      "z": -5,
      "name": "Rock_Marble"
    },
    {
      "x": 6,
      "y": 0,
      "z": -5,
      "name": "Rock_Marble"
    },
    {
      "x": 6,
      "y": 1,
      "z": -5,
      "name": "Rock_Marble"
    },
    {
      "x": 6,
      "y": 2,
      "z": -5,
      "name": "Rock_Marble_SkyGrass"
    },
    {
      "x": 6,
      "y": -1,
      "z": -4,
      "name": "Rock_Marble"
    },
    {
      "x": 6,
      "y": 0,
      "z": -4,
      "name": "Rock_Marble"
    },
    {
      "x": 6,
      "y": 1,
      "z": -4,
      "name": "Rock_Marble"
    },
    {
      "x": 6,
      "y": 2,
      "z": -4,
      "name": "Rock_Marble_SkyGrass"
    },
    {
      "x": 6,
      "y": 0,
      "z": -3,
      "name": "Rock_Marble"
    },
    {
      "x": 6,
      "y": 1,
      "z": -3,
      "name": "Rock_Marble"
    },
    {
      "x": 6,
      "y": 2,
      "z": -3,
      "name": "Rock_Marble_SkyGrass"
    },
    {
      "x": 6,
      "y": -1,
      "z": -2,
      "name": "Rock_Marble"
    },
    {
      "x": 6,
      "y": 0,
      "z": -2,
      "name": "Rock_Marble"
