{
  "version": 8,
  "blockIdVersion": 11,
  "anchorX": 1,
  "anchorY": 10,
  "anchorZ": 0,
  "blocks": [
    {
      "x": -8,
      "y": 6,
      "z": -2,
      "name": "Plant_Leaves_Aspen"
    },
    {
      "x": -8,
      "y": 6,
      "z": -1,
      "name": "Plant_Leaves_Aspen"
    },
    {
      "x": -8,
      "y": 5,
      "z": 0,
      "name": "Wood_Birch_Branch_Corner",
      "support": 15,
      "rotation": 3
    },
    {
      "x": -8,
      "y": 6,
      "z": 0,
      "name": "Plant_Leaves_Aspen",
      "support": 15
    },
    {
      "x": -8,
      "y": 6,
      "z": 1,
      "name": "Plant_Leaves_Aspen"
    },
    {
      "x": -8,
      "y": 16,
      "z": 2,
      "name": "Plant_Leaves_Aspen"
    },
    {
      "x": -8,
      "y": 13,
      "z": 3,
      "name": "Plant_Leaves_Aspen"
    },
    {
      "x": -8,
      "y": 14,
      "z": 3,
      "name": "Plant_Leaves_Aspen"
    },
    {
      "x": -8,
      "y": 16,
      "z": 3,
      "name": "Plant_Leaves_Aspen"
    },
    {
      "x": -8,
      "y": 13,
      "z": 4,
      "name": "Plant_Leaves_Aspen"
    },
    {
      "x": -8,
      "y": 14,
      "z": 4,
      "name": "Plant_Leaves_Aspen"
    },
    {
      "x": -8,
      "y": 16,
      "z": 4,
      "name": "Plant_Leaves_Aspen"
    },
    {
      "x": -8,
      "y": 13,
      "z": 5,
      "name": "Plant_Leaves_Aspen"
    },
    {
      "x": -8,
      "y": 14,
      "z": 5,
      "name": "Plant_Leaves_Aspen"
    },
    {
      "x": -8,
      "y": 16,
      "z": 5,
      "name": "Plant_Leaves_Aspen"
    },
    {
      "x": -8,
      "y": 17,
      "z": 5,
      "name": "Plant_Leaves_Aspen"
    },
    {
      "x": -8,
      "y": 13,
      "z": 6,
      "name": "Plant_Leaves_Aspen"
    },
    {
      "x": -8,
      "y": 16,
      "z": 6,
      "name": "Plant_Leaves_Aspen"
    },
    {
      "x": -8,
      "y": 17,
      "z": 6,
      "name": "Plant_Leaves_Aspen"
    },
    {
      "x": -8,
      "y": 13,
      "z": 7,
      "name": "Plant_Leaves_Aspen"
    },
    {
      "x": -8,
      "y": 16,
      "z": 7,
      "name": "Plant_Leaves_Aspen"
    },
    {
      "x": -8,
      "y": 17,
      "z": 7,
      "name": "Plant_Leaves_Aspen"
    },
    {
      "x": -8,
      "y": 16,
      "z": 8,
      "name": "Plant_Leaves_Aspen"
    },
    {
      "x": -8,
      "y": 17,
      "z": 8,
      "name": "Plant_Leaves_Aspen"
    },
    {
      "x": -8,
      "y": 16,
      "z": 9,
      "name": "Plant_Leaves_Aspen"
    },
    {
      "x": -8,
      "y": 16,
      "z": 10,
      "name": "Plant_Leaves_Aspen"
    },
    {
      "x": -7,
      "y": 0,
      "z": -6,
      "name": "Wood_Birch_Trunk_Full",
      "support": 15
    },
    {
      "x": -7,
      "y": 0,
      "z": -5,
      "name": "Wood_Birch_Trunk",
      "support": 15
    },
    {
      "x": -7,
      "y": 1,
      "z": -5,
      "name": "Wood_Birch_Trunk_Full",
      "support": 15
    },
    {
      "x": -7,
      "y": 0,
      "z": -4,
      "name": "Wood_Birch_Trunk",
      "support": 15
    },
    {
      "x": -7,
      "y": 1,
      "z": -4,
      "name": "Wood_Birch_Trunk_Full",
      "support": 15
    },
    {
      "x": -7,
      "y": 2,
      "z": -4,
      "name": "Wood_Birch_Trunk_Full",
      "support": 15
    },
    {
      "x": -7,
      "y": 2,
      "z": -3,
      "name": "Wood_Birch_Trunk_Full",
      "support": 15
    },
    {
      "x": -7,
      "y": 3,
      "z": -3,
      "name": "Wood_Birch_Trunk_Full",
      "support": 15
    },
    {
      "x": -7,
      "y": 6,
      "z": -2,
      "name": "Plant_Leaves_Aspen"
    },
    {
      "x": -7,
      "y": 6,
      "z": -1,
      "name": "Plant_Leaves_Aspen"
    },
    {
      "x": -7,
      "y": 5,
      "z": 0,
      "name": "Wood_Birch_Branch_Long",
      "support": 15,
      "rotation": 5
    },
    {
      "x": -7,
      "y": 6,
      "z": 0,
      "name": "Plant_Leaves_Aspen"
    },
    {
      "x": -7,
      "y": 6,
      "z": 1,
      "name": "Plant_Leaves_Aspen"
    },
    {
      "x": -7,
      "y": 14,
      "z": 2,
      "name": "Plant_Leaves_Aspen"
    },
    {
      "x": -7,
      "y": 16,
      "z": 2,
      "name": "Plant_Leaves_Aspen"
    },
    {
      "x": -7,
      "y": 13,
      "z": 3,
      "name": "Plant_Leaves_Aspen"
    },
    {
      "x": -7,
      "y": 14,
      "z": 3,
      "name": "Plant_Leaves_Aspen"
    },
    {
      "x": -7,
      "y": 16,
      "z": 3,
      "name": "Plant_Leaves_Aspen"
    },
    {
      "x": -7,
      "y": 13,
      "z": 4,
      "name": "Plant_Leaves_Aspen"
    },
    {
      "x": -7,
      "y": 14,
      "z": 4,
      "name": "Plant_Leaves_Aspen"
    },
    {
      "x": -7,
      "y": 16,
      "z": 4,
      "name": "Plant_Leaves_Aspen"
    },
    {
      "x": -7,
      "y": 17,
      "z": 4,
      "name": "Plant_Leaves_Aspen"
    },
    {
      "x": -7,
      "y": 13,
      "z": 5,
      "name": "Plant_Leaves_Aspen"
    },
    {
      "x": -7,
      "y": 14,
      "z": 5,
      "name": "Plant_Leaves_Aspen"
    },
    {
      "x": -7,
      "y": 16,
      "z": 5,
      "name": "Plant_Leaves_Aspen"
    },
    {
      "x": -7,
      "y": 17,
      "z": 5,
      "name": "Plant_Leaves_Aspen"
    },
    {
      "x": -7,
      "y": 13,
      "z": 6,
      "name": "Wood_Birch_Branch_Corner",
      "support": 15,
      "rotation": 3
    },
    {
      "x": -7,
      "y": 14,
      "z": 6,
      "name": "Wood_Birch_Branch_Long",
      "support": 15
    },
    {
      "x": -7,
      "y": 15,
      "z": 6,
      "name": "Wood_Birch_Branch_Long",
      "support": 15
    },
    {
      "x": -7,
      "y": 16,
      "z": 6,
      "name": "Wood_Birch_Branch_Long",
      "support": 15
    },
    {
      "x": -7,
      "y": 17,
      "z": 6,
      "name": "Plant_Leaves_Aspen"
    },
    {
      "x": -7,
      "y": 12,
      "z": 7,
      "name": "Plant_Leaves_Aspen"
    },
    {
      "x": -7,
      "y": 13,
      "z": 7,
      "name": "Plant_Leaves_Aspen"
    },
    {
      "x": -7,
      "y": 14,
      "z": 7,
      "name": "Plant_Leaves_Aspen",
      "support": 15
    },
    {
      "x": -7,
      "y": 16,
      "z": 7,
      "name": "Plant_Leaves_Aspen"
    },
    {
      "x": -7,
      "y": 17,
      "z": 7,
      "name": "Plant_Leaves_Aspen"
    },
    {
      "x": -7,
      "y": 12,
      "z": 8,
      "name": "Plant_Leaves_Aspen"
    },
    {
      "x": -7,
      "y": 13,
      "z": 8,
      "name": "Plant_Leaves_Aspen",
      "support": 15
    },
    {
      "x": -7,
      "y": 16,
      "z": 8,
      "name": "Plant_Leaves_Aspen"
    },
    {
      "x": -7,
      "y": 17,
      "z": 8,
      "name": "Plant_Leaves_Aspen"
    },
    {
      "x": -7,
      "y": 12,
      "z": 9,
      "name": "Plant_Leaves_Aspen"
    },
    {
      "x": -7,
      "y": 13,
      "z": 9,
      "name": "Plant_Leaves_Aspen",
      "support": 15
    },
    {
      "x": -7,
      "y": 16,
      "z": 9,
      "name": "Plant_Leaves_Aspen"
    },
    {
      "x": -7,
      "y": 12,
      "z": 10,
      "name": "Plant_Leaves_Aspen"
    },
    {
      "x": -7,
      "y": 16,
      "z": 10,
      "name": "Plant_Leaves_Aspen"
    },
    {
      "x": -6,
      "y": 0,
      "z": -6,
      "name": "Wood_Birch_Trunk"
    },
    {
      "x": -6,
      "y": 1,
      "z": -6,
      "name": "Wood_Birch_Trunk",
      "support": 15
    },
    {
      "x": -6,
      "y": 2,
      "z": -6,
      "name": "Wood_Birch_Trunk_Full",
      "support": 15
    },
    {
      "x": -6,
      "y": 0,
      "z": -5,
      "name": "Wood_Birch_Trunk"
    },
    {
      "x": -6,
      "y": 1,
      "z": -5,
      "name": "Wood_Birch_Trunk"
    },
    {
      "x": -6,
      "y": 2,
      "z": -5,
      "name": "Wood_Birch_Trunk"
    },
    {
      "x": -6,
      "y": 3,
      "z": -5,
      "name": "Wood_Birch_Trunk_Full",
      "support": 15
    },
    {
      "x": -6,
      "y": 0,
      "z": -4,
      "name": "Wood_Birch_Trunk"
    },
    {
      "x": -6,
      "y": 1,
      "z": -4,
      "name": "Wood_Birch_Trunk"
    },
    {
      "x": -6,
      "y": 2,
      "z": -4,
      "name": "Wood_Birch_Trunk"
    },
    {
      "x": -6,
      "y": 3,
      "z": -4,
      "name": "Wood_Birch_Trunk_Full",
      "support": 15
    },
    {
      "x": -6,
      "y": 1,
      "z": -3,
      "name": "Wood_Birch_Trunk_Full",
      "support": 15
    },
    {
      "x": -6,
      "y": 2,
      "z": -3,
      "name": "Wood_Birch_Trunk",
      "support": 15
    },
    {
      "x": -6,
      "y": 3,
      "z": -3,
      "name": "Wood_Birch_Trunk",
      "support": 15
    },
    {
      "x": -6,
      "y": 4,
      "z": -3,
      "name": "Wood_Birch_Trunk_Full",
      "support": 15
    },
    {
      "x": -6,
      "y": 2,
      "z": -2,
      "name": "Wood_Birch_Trunk_Full",
      "support": 15
    },
    {
      "x": -6,
      "y": 4,
      "z": -2,
      "name": "Wood_Birch_Trunk_Full",
      "support": 15,
      "rotation": 4
    },
    {
      "x": -6,
      "y": 4,
      "z": -1,
      "name": "Wood_Birch_Trunk_Full",
      "support": 15,
      "rotation": 4
    },
    {
      "x": -6,
      "y": 6,
      "z": -1,
      "name": "Plant_Leaves_Aspen"
    },
    {
      "x": -6,
      "y": 4,
      "z": 0,
      "name": "Wood_Birch_Branch_Corner",
      "support": 15
    },
    {
      "x": -6,
      "y": 5,
      "z": 0,
      "name": "Wood_Birch_Branch_Corner",
      "support": 15,
      "rotation": 11
    },
    {
      "x": -6,
      "y": 6,
      "z": 0,
      "name": "Plant_Leaves_Aspen"
    },
    {
      "x": -6,
      "y": 14,
      "z": 2,
      "name": "Plant_Leaves_Aspen"
    },
    {
      "x": -6,
      "y": 13,
      "z": 3,
      "name": "Plant_Leaves_Aspen"
    },
    {
      "x": -6,
      "y": 14,
      "z": 3,
      "name": "Plant_Leaves_Aspen"
    },
    {
      "x": -6,
      "y": 16,
      "z": 3,
      "name": "Plant_Leaves_Aspen"
    },
    {
      "x": -6,
      "y": 13,
      "z": 4,
      "name": "Plant_Leaves_Aspen"
    },
    {
      "x": -6,
      "y": 14,
      "z": 4,
      "name": "Wood_Birch_Branch_Corner",
      "support": 15,
      "rotation": 2
    },
    {
      "x": -6,
      "y": 15,
      "z": 4,
      "name": "Wood_Birch_Branch_Long",
      "support": 15
    },
    {
      "x": -6,
      "y": 16,
      "z": 4,
      "name": "Plant_Leaves_Aspen"
    },
    {
      "x": -6,
      "y": 11,
      "z": 5,
      "name": "Wood_Birch_Branch_Corner",
      "support": 15,
      "rotation": 2
    },
    {
      "x": -6,
      "y": 12,
      "z": 5,
      "name": "Wood_Birch_Branch_Long",
      "support": 15
    },
    {
      "x": -6,
      "y": 13,
      "z": 5,
      "name": "Wood_Birch_Branch_Long",
      "support": 15
    },
    {
      "x": -6,
      "y": 14,
      "z": 5,
      "name": "Wood_Birch_Branch_Corner",
      "support": 15,
      "rotation": 10
    },
    {
      "x": -6,
      "y": 16,
      "z": 5,
      "name": "Plant_Leaves_Aspen"
    },
    {
      "x": -6,
      "y": 17,
      "z": 5,
      "name": "Plant_Leaves_Aspen"
    },
    {
      "x": -6,
      "y": 10,
      "z": 6,
      "name": "Wood_Birch_Trunk",
      "support": 15
    },
    {
      "x": -6,
      "y": 11,
      "z": 6,
      "name": "Wood_Birch_Trunk_Full",
      "support": 15
    },
    {
      "x": -6,
      "y": 12,
      "z": 6,
      "name": "Wood_Birch_Branch_Long",
      "support": 15
    },
    {
      "x": -6,
      "y": 13,
      "z": 6,
      "name": "Wood_Birch_Branch_Corner",
      "support": 15,
      "rotation": 11
    },
    {
      "x": -6,
      "y": 14,
      "z": 6,
      "name": "Plant_Leaves_Aspen"
    },
    {
      "x": -6,
      "y": 16,
      "z": 6,
      "name": "Plant_Leaves_Aspen"
    },
    {
      "x": -6,
      "y": 17,
      "z": 6,
      "name": "Plant_Leaves_Aspen"
    },
    {
      "x": -6,
      "y": 12,
      "z": 7,
      "name": "Plant_Leaves_Aspen"
    },
    {
      "x": -6,
      "y": 13,
      "z": 7,
      "name": "Plant_Leaves_Aspen"
    },
    {
      "x": -6,
      "y": 14,
      "z": 7,
      "name": "Plant_Leaves_Aspen",
      "support": 15
    },
    {
      "x": -6,
      "y": 16,
      "z": 7,
      "name": "Plant_Leaves_Aspen"
    },
    {
      "x": -6,
      "y": 17,
      "z": 7,
      "name": "Plant_Leaves_Aspen"
    },
    {
      "x": -6,
      "y": 12,
      "z": 8,
      "name": "Plant_Leaves_Aspen"
    },
    {
      "x": -6,
      "y": 13,
      "z": 8,
      "name": "Plant_Leaves_Aspen",
      "support": 15
    },
    {
      "x": -6,
      "y": 14,
      "z": 8,
      "name": "Plant_Leaves_Aspen",
      "support": 15
    },
    {
      "x": -6,
      "y": 16,
      "z": 8,
      "name": "Plant_Leaves_Aspen"
    },
    {
      "x": -6,
      "y": 17,
      "z": 8,
      "name": "Plant_Leaves_Aspen"
    },
    {
      "x": -6,
      "y": 12,
      "z": 9,
      "name": "Plant_Leaves_Aspen"
    },
    {
      "x": -6,
      "y": 13,
      "z": 9,
      "name": "Plant_Leaves_Aspen",
      "support": 15
    },
    {
      "x": -6,
      "y": 14,
      "z": 9,
      "name": "Plant_Leaves_Aspen",
      "support": 15
    },
    {
      "x": -6,
      "y": 16,
      "z": 9,
      "name": "Plant_Leaves_Aspen"
    },
    {
      "x": -6,
      "y": 12,
      "z": 10,
      "name": "Plant_Leaves_Aspen"
    },
    {
      "x": -6,
      "y": 13,
      "z": 10,
      "name": "Plant_Leaves_Aspen",
      "support": 15
    },
    {
      "x": -6,
      "y": 16,
      "z": 10,
      "name": "Plant_Leaves_Aspen"
    },
    {
      "x": -5,
      "y": 0,
      "z": -6,
      "name": "Wood_Birch_Trunk",
      "support": 15
    },
    {
      "x": -5,
      "y": 1,
      "z": -6,
      "name": "Wood_Birch_Trunk_Full",
      "support": 15
    },
    {
      "x": -5,
      "y": 0,
      "z": -5,
      "name": "Wood_Birch_Trunk",
      "support": 15
    },
    {
      "x": -5,
      "y": 1,
      "z": -5,
      "name": "Wood_Birch_Trunk"
    },
    {
      "x": -5,
      "y": 2,
      "z": -5,
      "name": "Wood_Birch_Trunk_Full",
      "support": 15
    },
    {
      "x": -5,
      "y": 0,
      "z": -4,
      "name": "Wood_Birch_Trunk"
    },
    {
      "x": -5,
      "y": 1,
      "z": -4,
      "name": "Wood_Birch_Trunk"
    },
    {
      "x": -5,
      "y": 2,
      "z": -4,
      "name": "Wood_Birch_Trunk"
    },
    {
      "x": -5,
      "y": 3,
      "z": -4,
      "name": "Wood_Birch_Trunk_Full",
      "support": 15
    },
    {
      "x": -5,
      "y": 2,
      "z": -3,
      "name": "Wood_Birch_Trunk_Full",
      "support": 15
    },
    {
      "x": -5,
      "y": 3,
      "z": -3,
      "name": "Wood_Birch_Trunk",
      "support": 15
    },
    {
      "x": -5,
      "y": 4,
      "z": -3,
      "name": "Wood_Birch_Trunk",
      "support": 15
    },
    {
      "x": -5,
      "y": 5,
      "z": -3,
      "name": "Wood_Birch_Trunk_Full",
      "support": 15
    },
    {
      "x": -5,
      "y": 3,
      "z": -2,
      "name": "Wood_Birch_Trunk_Full",
      "support": 15
    },
    {
      "x": -5,
      "y": 4,
      "z": -2,
      "name": "Wood_Birch_Trunk",
      "support": 15
    },
    {
      "x": -5,
      "y": 5,
      "z": -2,
      "name": "Wood_Birch_Trunk"
    },
    {
      "x": -5,
      "y": 6,
      "z": -2,
      "name": "Wood_Birch_Trunk_Full",
      "support": 15
    },
    {
      "x": -5,
      "y": 14,
      "z": 2,
      "name": "Plant_Leaves_Aspen"
    },
    {
      "x": -5,
      "y": 14,
      "z": 3,
      "name": "Plant_Leaves_Aspen"
    },
    {
      "x": -5,
      "y": 16,
      "z": 3,
      "name": "Plant_Leaves_Aspen"
    },
    {
      "x": -5,
      "y": 13,
      "z": 4,
      "name": "Plant_Leaves_Aspen"
    },
    {
      "x": -5,
      "y": 14,
      "z": 4,
      "name": "Plant_Leaves_Aspen"
    },
    {
      "x": -5,
      "y": 16,
      "z": 4,
      "name": "Plant_Leaves_Aspen"
    },
    {
      "x": -5,
      "y": 13,
      "z": 5,
      "name": "Plant_Leaves_Aspen"
    },
    {
      "x": -5,
      "y": 14,
      "z": 5,
      "name": "Plant_Leaves_Aspen"
    },
    {
      "x": -5,
      "y": 16,
      "z": 5,
      "name": "Plant_Leaves_Aspen"
    },
    {
      "x": -5,
      "y": 17,
      "z": 5,
      "name": "Plant_Leaves_Aspen"
    },
    {
      "x": -5,
      "y": 9,
      "z": 6,
      "name": "Wood_Birch_Trunk_Full",
      "support": 15
    },
    {
      "x": -5,
      "y": 10,
      "z": 6,
      "name": "Wood_Birch_Trunk_Full",
      "support": 15,
      "rotation": 5
    },
    {
      "x": -5,
      "y": 12,
      "z": 6,
      "name": "Plant_Leaves_Aspen"
    },
    {
      "x": -5,
      "y": 13,
      "z": 6,
      "name": "Plant_Leaves_Aspen"
    },
    {
      "x": -5,
      "y": 14,
      "z": 6,
      "name": "Plant_Leaves_Aspen"
    },
    {
      "x": -5,
      "y": 16,
      "z": 6,
      "name": "Plant_Leaves_Aspen"
    },
    {
      "x": -5,
      "y": 17,
      "z": 6,
      "name": "Plant_Leaves_Aspen"
    },
    {
      "x": -5,
      "y": 8,
      "z": 7,
      "name": "Wood_Birch_Branch_Corner",
      "support": 15,
      "rotation": 2
    },
    {
      "x": -5,
      "y": 9,
      "z": 7,
      "name": "Wood_Birch_Branch_Corner",
      "support": 15,
      "rotation": 10
    },
    {
      "x": -5,
      "y": 12,
      "z": 7,
      "name": "Plant_Leaves_Aspen"
    },
    {
      "x": -5,
      "y": 14,
      "z": 7,
      "name": "Plant_Leaves_Aspen",
      "support": 15
    },
    {
      "x": -5,
      "y": 16,
      "z": 7,
      "name": "Plant_Leaves_Aspen"
    },
    {
      "x": -5,
      "y": 17,
      "z": 7,
      "name": "Plant_Leaves_Aspen"
    },
    {
      "x": -5,
      "y": 8,
      "z": 8,
      "name": "Wood_Birch_Branch_Long",
      "support": 15,
      "rotation": 4
    },
    {
      "x": -5,
      "y": 11,
      "z": 8,
      "name": "Wood_Birch_Branch_Corner",
      "support": 15,
      "rotation": 2
    },
    {
      "x": -5,
      "y": 12,
      "z": 8,
      "name": "Wood_Birch_Branch_Long",
      "support": 15
    },
    {
      "x": -5,
      "y": 13,
      "z": 8,
      "name": "Wood_Birch_Branch_Corner",
      "support": 15,
      "rotation": 8
    },
    {
      "x": -5,
      "y": 14,
      "z": 8,
      "name": "Plant_Leaves_Aspen",
      "support": 15
    },
    {
      "x": -5,
      "y": 16,
      "z": 8,
      "name": "Plant_Leaves_Aspen"
    },
    {
      "x": -5,
      "y": 8,
      "z": 9,
      "name": "Wood_Birch_Branch_Corner",
      "support": 15
    },
    {
      "x": -5,
      "y": 9,
      "z": 9,
      "name": "Wood_Birch_Branch_Corner",
      "support": 15,
      "rotation": 8
    },
    {
      "x": -5,
      "y": 11,
      "z": 9,
      "name": "Wood_Birch_Branch_Long",
      "support": 15,
      "rotation": 4
    },
    {
      "x": -5,
      "y": 12,
      "z": 9,
      "name": "Wood_Birch_Branch_Corner",
      "support": 15
    },
    {
      "x": -5,
      "y": 13,
      "z": 9,
      "name": "Wood_Birch_Branch_Corner",
      "support": 15,
      "rotation": 10
    },
    {
      "x": -5,
      "y": 14,
      "z": 9,
      "name": "Plant_Leaves_Aspen",
      "support": 15
    },
    {
      "x": -5,
      "y": 16,
      "z": 9,
      "name": "Plant_Leaves_Aspen"
    },
    {
      "x": -5,
      "y": 9,
      "z": 10,
      "name": "Wood_Birch_Branch_Corner",
      "support": 15
    },
    {
      "x": -5,
      "y": 10,
      "z": 10,
      "name": "Wood_Birch_Branch_Long",
      "support": 15
    },
    {
      "x": -5,
      "y": 11,
      "z": 10,
      "name": "Wood_Birch_Branch_Corner",
      "support": 15,
      "rotation": 10
    },
    {
      "x": -5,
      "y": 12,
      "z": 10,
      "name": "Plant_Leaves_Aspen"
    },
    {
      "x": -5,
      "y": 13,
      "z": 10,
      "name": "Plant_Leaves_Aspen",
      "support": 15
    },
    {
      "x": -5,
      "y": 14,
      "z": 10,
      "name": "Plant_Leaves_Aspen",
      "support": 15
    },
    {
      "x": -4,
      "y": 12,
      "z": -7,
      "name": "Plant_Leaves_Aspen"
    },
    {
      "x": -4,
      "y": 12,
      "z": -6,
      "name": "Plant_Leaves_Aspen"
    },
    {
      "x": -4,
      "y": 3,
      "z": -3,
      "name": "Wood_Birch_Trunk_Full",
      "support": 15
    },
    {
      "x": -4,
      "y": 4,
      "z": -3,
      "name": "Wood_Birch_Trunk",
      "support": 15
    },
    {
      "x": -4,
      "y": 5,
      "z": -3,
      "name": "Wood_Birch_Trunk",
      "support": 15
    },
    {
      "x": -4,
      "y": 6,
      "z": -3,
      "name": "Wood_Birch_Trunk_Full",
      "support": 15
    },
    {
      "x": -4,
      "y": 4,
      "z": -2,
      "name": "Wood_Birch_Trunk_Full",
      "support": 15
    },
    {
      "x": -4,
      "y": 5,
      "z": -2,
      "name": "Wood_Birch_Trunk",
      "support": 15
    },
    {
      "x": -4,
      "y": 6,
      "z": -2,
      "name": "Wood_Birch_Trunk"
    },
    {
      "x": -4,
      "y": 7,
      "z": -2,
      "name": "Wood_Birch_Trunk_Full",
      "support": 15
    },
    {
      "x": -4,
      "y": 6,
      "z": -1,
      "name": "Wood_Birch_Trunk_Full",
      "support": 15
    },
    {
      "x": -4,
      "y": 7,
      "z": -1,
      "name": "Wood_Birch_Trunk_Full",
      "support": 15
    },
    {
      "x": -4,
      "y": 14,
      "z": 3,
      "name": "Plant_Leaves_Aspen"
    },
    {
      "x": -4,
      "y": 14,
      "z": 4,
      "name": "Plant_Leaves_Aspen"
    },
    {
      "x": -4,
      "y": 16,
      "z": 4,
      "name": "Plant_Leaves_Aspen"
    },
    {
      "x": -4,
      "y": 14,
      "z": 5,
      "name": "Plant_Leaves_Aspen"
    },
    {
      "x": -4,
      "y": 16,
      "z": 5,
      "name": "Plant_Leaves_Aspen"
    },
    {
      "x": -4,
      "y": 9,
      "z": 6,
      "name": "Wood_Birch_Trunk_Full",
      "support": 15,
      "rotation": 5
    },
    {
      "x": -4,
      "y": 12,
      "z": 6,
      "name": "Plant_Leaves_Aspen"
    },
    {
      "x": -4,
      "y": 16,
      "z": 6,
      "name": "Plant_Leaves_Aspen"
    },
    {
      "x": -4,
      "y": 12,
      "z": 7,
      "name": "Plant_Leaves_Aspen"
    },
    {
      "x": -4,
      "y": 16,
      "z": 7,
      "name": "Plant_Leaves_Aspen"
    },
    {
      "x": -4,
      "y": 12,
      "z": 8,
      "name": "Plant_Leaves_Aspen"
    },
    {
      "x": -4,
      "y": 13,
      "z": 8,
      "name": "Plant_Leaves_Aspen",
      "support": 15
    },
    {
      "x": -4,
      "y": 16,
      "z": 8,
      "name": "Plant_Leaves_Aspen"
    },
    {
      "x": -4,
      "y": 12,
      "z": 9,
      "name": "Plant_Leaves_Aspen"
    },
    {
      "x": -4,
      "y": 13,
      "z": 9,
      "name": "Plant_Leaves_Aspen",
      "support": 15
    },
    {
      "x": -4,
      "y": 16,
      "z": 9,
      "name": "Plant_Leaves_Aspen"
    },
    {
      "x": -4,
      "y": 12,
      "z": 10,
      "name": "Plant_Leaves_Aspen"
    },
    {
      "x": -4,
      "y": 13,
      "z": 10,
      "name": "Plant_Leaves_Aspen",
      "support": 15
    },
    {
      "x": -3,
      "y": 10,
      "z": -7,
      "name": "Plant_Leaves_Aspen"
    },
    {
      "x": -3,
      "y": 11,
      "z": -7,
      "name": "Wood_Birch_Branch_Corner",
      "support": 15,
      "rotation": 2
    },
    {
      "x": -3,
      "y": 12,
      "z": -7,
      "name": "Wood_Birch_Branch_Long",
      "support": 15
    },
    {
      "x": -3,
      "y": 13,
      "z": -7,
      "name": "Plant_Leaves_Aspen",
      "support": 15
    },
    {
      "x": -3,
      "y": 14,
      "z": -7,
      "name": "Plant_Leaves_Aspen"
    },
    {
      "x": -3,
      "y": 10,
      "z": -6,
      "name": "Wood_Birch_Branch_Corner",
      "support": 15,
      "rotation": 3
    },
    {
      "x": -3,
      "y": 11,
      "z": -6,
      "name": "Wood_Birch_Branch_Corner",
      "support": 15,
      "rotation": 10
    },
    {
      "x": -3,
      "y": 12,
      "z": -6,
      "name": "Plant_Leaves_Aspen"
    },
    {
      "x": -3,
      "y": 14,
      "z": -6,
      "name": "Plant_Leaves_Aspen"
    },
    {
      "x": -3,
      "y": 14,
      "z": -5,
      "name": "Plant_Leaves_Aspen"
    },
    {
      "x": -3,
      "y": 6,
      "z": -2,
      "name": "Wood_Birch_Trunk_Full",
      "support": 15
    },
    {
      "x": -3,
      "y": 7,
      "z": -2,
      "name": "Wood_Birch_Trunk_Full",
      "support": 15
    },
    {
      "x": -3,
      "y": 6,
      "z": -1,
      "name": "Wood_Birch_Trunk_Full",
      "support": 15
    },
    {
      "x": -3,
      "y": 7,
      "z": -1,
      "name": "Wood_Birch_Trunk"
    },
    {
      "x": -3,
      "y": 8,
      "z": -1,
      "name": "Wood_Birch_Trunk_Full",
      "support": 15,
      "rotation": 5
    },
    {
      "x": -3,
      "y": 7,
      "z": 0,
      "name": "Wood_Birch_Trunk_Full",
      "support": 15,
      "rotation": 5
    },
    {
      "x": -3,
      "y": 16,
      "z": 5,
      "name": "Plant_Leaves_Aspen"
    },
    {
      "x": -3,
      "y": 8,
      "z": 6,
      "name": "Wood_Birch_Trunk_Full",
      "support": 15,
      "rotation": 5
    },
    {
      "x": -3,
      "y": 9,
      "z": 6,
      "name": "Wood_Birch_Trunk_Full",
      "support": 15,
      "rotation": 5
    },
    {
      "x": -3,
      "y": 16,
      "z": 6,
      "name": "Plant_Leaves_Aspen"
    },
    {
      "x": -3,
      "y": 16,
      "z": 7,
      "name": "Plant_Leaves_Aspen"
    },
    {
      "x": -3,
      "y": 12,
      "z": 8,
      "name": "Plant_Leaves_Aspen"
    },
    {
      "x": -3,
      "y": 12,
      "z": 9,
      "name": "Plant_Leaves_Aspen"
    },
    {
      "x": -2,
      "y": 10,
      "z": -7,
      "name": "Plant_Leaves_Aspen"
    },
    {
      "x": -2,
      "y": 12,
      "z": -7,
      "name": "Plant_Leaves_Aspen"
    },
    {
      "x": -2,
      "y": 13,
      "z": -7,
      "name": "Plant_Leaves_Aspen"
    },
    {
      "x": -2,
      "y": 14,
      "z": -7,
      "name": "Plant_Leaves_Aspen"
    },
    {
      "x": -2,
      "y": 10,
      "z": -6,
      "name": "Wood_Birch_Branch_Long",
      "support": 15,
      "rotation": 5
    },
    {
      "x": -2,
      "y": 12,
      "z": -6,
      "name": "Wood_Birch_Branch_Corner",
      "support": 15,
      "rotation": 3
    },
    {
      "x": -2,
      "y": 13,
      "z": -6,
      "name": "Wood_Birch_Branch_Long",
      "support": 15
    },
    {
      "x": -2,
      "y": 14,
      "z": -6,
      "name": "Wood_Birch_Branch_Corner",
      "support": 15,
      "rotation": 9
    },
    {
      "x": -2,
      "y": 15,
      "z": -6,
      "name": "Plant_Leaves_Aspen"
    },
    {
      "x": -2,
      "y": 10,
      "z": -5,
      "name": "Plant_Leaves_Aspen"
    },
    {
      "x": -2,
      "y": 14,
      "z": -5,
      "name": "Plant_Leaves_Aspen"
    },
    {
      "x": -2,
      "y": 7,
      "z": -1,
      "name": "Wood_Birch_Trunk_Full",
      "support": 15,
      "rotation": 5
    },
    {
      "x": -2,
      "y": 8,
      "z": -1,
      "name": "Wood_Birch_Trunk_Full",
      "support": 15,
      "rotation": 5
    },
    {
      "x": -2,
      "y": 7,
      "z": 0,
      "name": "Wood_Birch_Trunk",
      "support": 15,
      "rotation": 5
    },
    {
      "x": -2,
      "y": 8,
      "z": 0,
      "name": "Wood_Birch_Trunk_Full",
      "support": 15,
      "rotation": 5
    },
    {
      "x": -2,
      "y": 7,
      "z": 1,
      "name": "Wood_Birch_Trunk_Full",
      "support": 15,
      "rotation": 5
    },
    {
      "x": -2,
      "y": 8,
      "z": 1,
      "name": "Wood_Birch_Trunk_Full",
      "support": 15,
      "rotation": 5
    },
    {
      "x": -2,
      "y": 9,
      "z": 5,
      "name": "Wood_Birch_Trunk_Full",
      "support": 15,
      "rotation": 5
    },
    {
      "x": -2,
      "y": 8,
      "z": 6,
      "name": "Wood_Birch_Trunk_Full",
      "support": 15,
      "rotation": 5
    },
    {
      "x": -2,
      "y": 9,
      "z": 6,
      "name": "Wood_Birch_Trunk_Full",
      "support": 15,
      "rotation": 5
    },
    {
      "x": -2,
      "y": 19,
      "z": 9,
      "name": "Plant_Leaves_Aspen",
      "support": 15
    },
    {
      "x": -2,
      "y": 20,
      "z": 9,
      "name": "Plant_Leaves_Aspen",
      "support": 15
    },
    {
      "x": -2,
      "y": 19,
      "z": 10,
      "name": "Plant_Leaves_Aspen",
      "support": 15
    },
    {
      "x": -2,
      "y": 20,
      "z": 10,
      "name": "Plant_Leaves_Aspen",
      "support": 15
    },
    {
      "x": -1,
      "y": 10,
      "z": -7,
      "name": "Plant_Leaves_Aspen"
    },
    {
      "x": -1,
      "y": 14,
      "z": -7,
      "name": "Plant_Leaves_Aspen"
    },
    {
      "x": -1,
      "y": 15,
      "z": -7,
      "name": "Plant_Leaves_Aspen"
    },
    {
      "x": -1,
      "y": 7,
      "z": -6,
      "name": "Wood_Birch_Branch_Corner",
      "support": 15,
      "rotation": 2
    },
    {
      "x": -1,
      "y": 8,
      "z": -6,
      "name": "Wood_Birch_Branch_Long",
      "support": 15
    },
    {
      "x": -1,
      "y": 9,
      "z": -6,
      "name": "Wood_Birch_Branch_Long",
      "support": 15
    },
    {
      "x": -1,
      "y": 10,
      "z": -6,
      "name": "Wood_Birch_Branch_Corner",
      "support": 15,
      "rotation": 9
    },
    {
      "x": -1,
      "y": 11,
      "z": -6,
      "name": "Plant_Leaves_Aspen",
      "support": 15
    },
    {
      "x": -1,
      "y": 12,
      "z": -6,
      "name": "Wood_Birch_Branch_Corner",
      "support": 15,
      "rotation": 1
    },
    {
      "x": -1,
      "y": 14,
      "z": -6,
      "name": "Wood_Birch_Branch_Long",
      "support": 15,
      "rotation": 5
    },
    {
      "x": -1,
      "y": 15,
      "z": -6,
      "name": "Plant_Leaves_Aspen"
    },
    {
      "x": -1,
      "y": 7,
      "z": -5,
      "name": "Wood_Birch_Branch_Long",
      "support": 15,
      "rotation": 4
    },
    {
      "x": -1,
      "y": 10,
      "z": -5,
      "name": "Plant_Leaves_Aspen"
    },
    {
      "x": -1,
      "y": 11,
      "z": -5,
      "name": "Plant_Leaves_Aspen",
      "support": 15
    },
    {
      "x": -1,
      "y": 14,
      "z": -5,
      "name": "Plant_Leaves_Aspen"
    },
    {
      "x": -1,
      "y": 15,
      "z": -5,
      "name": "Plant_Leaves_Aspen"
    },
    {
      "x": -1,
      "y": 7,
      "z": -4,
      "name": "Wood_Birch_Branch_Long",
      "support": 15,
      "rotation": 4
    },
    {
      "x": -1,
      "y": 14,
      "z": -4,
      "name": "Plant_Leaves_Aspen"
    },
    {
      "x": -1,
      "y": 7,
      "z": -3,
      "name": "Wood_Birch_Trunk_Full",
      "support": 15,
      "rotation": 4
    },
    {
      "x": -1,
      "y": 7,
      "z": -2,
      "name": "Wood_Birch_Trunk",
      "support": 15,
      "rotation": 4
    },
    {
      "x": -1,
      "y": 7,
      "z": -1,
      "name": "Wood_Birch_Trunk",
      "support": 15,
      "rotation": 4
    },
    {
      "x": -1,
      "y": 7,
      "z": 0,
      "name": "Wood_Birch_Trunk_Full",
      "support": 15,
      "rotation": 5
    },
    {
      "x": -1,
      "y": 8,
      "z": 0,
      "name": "Wood_Birch_Trunk",
      "support": 15,
      "rotation": 5
    },
    {
      "x": -1,
      "y": 8,
      "z": 1,
      "name": "Wood_Birch_Trunk",
      "support": 15,
      "rotation": 5
    },
    {
      "x": -1,
      "y": 9,
      "z": 1,
      "name": "Wood_Birch_Trunk_Full",
      "support": 15,
      "rotation": 5
    },
    {
      "x": -1,
      "y": 8,
      "z": 2,
      "name": "Wood_Birch_Trunk_Full",
      "support": 15,
      "rotation": 5
    },
    {
      "x": -1,
      "y": 10,
      "z": 4,
      "name": "Wood_Birch_Branch_Short",
      "support": 15,
      "rotation": 2
    },
    {
      "x": -1,
      "y": 9,
      "z": 5,
      "name": "Wood_Birch_Trunk_Full",
      "support": 15,
      "rotation": 5
    },
    {
      "x": -1,
      "y": 10,
      "z": 5,
      "name": "Wood_Birch_Trunk_Full",
      "support": 15,
      "rotation": 5
    },
    {
      "x": -1,
      "y": 8,
      "z": 6,
      "name": "Wood_Birch_Trunk_Full",
      "support": 15,
      "rotation": 5
    },
    {
      "x": -1,
      "y": 9,
      "z": 6,
      "name": "Wood_Birch_Trunk_Full",
      "support": 15
    },
    {
      "x": -1,
      "y": 10,
      "z": 6,
      "name": "Wood_Birch_Trunk_Full",
      "support": 15
    },
    {
      "x": -1,
      "y": 11,
      "z": 6,
      "name": "Wood_Birch_Trunk_Half",
      "rotation": 7
    },
    {
      "x": -1,
      "y": 9,
      "z": 7,
      "name": "Wood_Birch_Trunk_Full",
      "support": 15
    },
    {
      "x": -1,
      "y": 10,
      "z": 7,
      "name": "Wood_Birch_Branch_Short",
      "support": 15
    },
    {
      "x": -1,
      "y": 11,
      "z": 7,
      "name": "Plant_Leaves_Aspen",
      "support": 15
    },
    {
      "x": -1,
      "y": 11,
      "z": 8,
      "name": "Plant_Leaves_Aspen",
      "support": 15
    },
    {
      "x": -1,
      "y": 19,
      "z": 8,
      "name": "Plant_Leaves_Aspen",
      "support": 15
    },
    {
      "x": -1,
      "y": 17,
      "z": 9,
      "name": "Plant_Leaves_Aspen",
      "support": 15
    },
    {
      "x": -1,
      "y": 19,
      "z": 9,
      "name": "Plant_Leaves_Aspen"
    },
    {
      "x": -1,
      "y": 20,
      "z": 9,
      "name": "Plant_Leaves_Aspen",
      "support": 15
    },
    {
      "x": -1,
      "y": 17,
      "z": 10,
      "name": "Plant_Leaves_Aspen",
      "support": 15
    },
    {
      "x": -1,
      "y": 19,
      "z": 10,
      "name": "Plant_Leaves_Aspen"
    },
    {
      "x": -1,
      "y": 20,
      "z": 10,
      "name": "Plant_Leaves_Aspen",
      "support": 15
    },
    {
      "x": 0,
      "y": 14,
      "z": -7,
      "name": "Plant_Leaves_Aspen"
    },
    {
      "x": 0,
      "y": 10,
      "z": -6,
      "name": "Wood_Birch_Branch_Corner",
      "support": 15,
      "rotation": 1
    },
    {
      "x": 0,
      "y": 11,
      "z": -6,
      "name": "Wood_Birch_Branch_Long",
      "support": 15
    },
    {
      "x": 0,
      "y": 12,
      "z": -6,
      "name": "Wood_Birch_Branch_Long",
      "support": 15
    },
    {
      "x": 0,
      "y": 13,
      "z": -6,
      "name": "Wood_Birch_Branch_Long",
      "support": 15
    },
    {
      "x": 0,
      "y": 14,
      "z": -6,
      "name": "Wood_Birch_Branch_Corner",
      "support": 15,
      "rotation": 11
    },
    {
      "x": 0,
      "y": 15,
      "z": -6,
      "name": "Plant_Leaves_Aspen"
    },
    {
      "x": 0,
      "y": 10,
      "z": -5,
      "name": "Plant_Leaves_Aspen"
    },
    {
      "x": 0,
      "y": 14,
      "z": -5,
      "name": "Plant_Leaves_Aspen"
    },
    {
      "x": 0,
      "y": 14,
      "z": -4,
      "name": "Plant_Leaves_Aspen"
    },
    {
      "x": 0,
      "y": 8,
      "z": 0,
      "name": "Wood_Birch_Trunk_Full",
      "support": 15,
      "rotation": 5
    },
    {
      "x": 0,
      "y": 8,
      "z": 1,
      "name": "Wood_Birch_Trunk_Full",
      "support": 15,
      "rotation": 5
    },
    {
      "x": 0,
      "y": 9,
      "z": 1,
      "name": "Wood_Birch_Trunk",
      "support": 15,
      "rotation": 5
    },
    {
      "x": 0,
      "y": 8,
      "z": 2,
      "name": "Wood_Birch_Trunk_Full",
      "support": 15,
      "rotation": 5
    },
    {
      "x": 0,
      "y": 10,
      "z": 5,
      "name": "Wood_Birch_Trunk_Full",
      "support": 15,
      "rotation": 5
    },
    {
      "x": 0,
      "y": 11,
      "z": 5,
      "name": "Wood_Birch_Trunk_Full",
      "support": 15,
      "rotation": 5
    },
    {
      "x": 0,
      "y": 9,
      "z": 6,
      "name": "Wood_Birch_Trunk_Full",
      "support": 15
    },
    {
      "x": 0,
      "y": 10,
      "z": 6,
      "name": "Wood_Birch_Trunk",
      "support": 15
    },
    {
      "x": 0,
      "y": 11,
      "z": 6,
      "name": "Wood_Birch_Trunk",
      "support": 15
    },
    {
      "x": 0,
      "y": 12,
      "z": 6,
      "name": "Wood_Birch_Trunk_Full",
      "support": 15
    },
    {
      "x": 0,
      "y": 10,
      "z": 7,
      "name": "Wood_Birch_Trunk_Full",
      "support": 15
    },
    {
      "x": 0,
      "y": 11,
      "z": 7,
      "name": "Wood_Birch_Trunk",
      "support": 15
    },
    {
      "x": 0,
      "y": 12,
      "z": 7,
      "name": "Wood_Birch_Trunk_Stairs",
      "rotation": 3
    },
    {
      "x": 0,
      "y": 11,
      "z": 8,
      "name": "Plant_Leaves_Aspen",
      "support": 15
    },
    {
      "x": 0,
      "y": 19,
      "z": 8,
      "name": "Plant_Leaves_Aspen"
    },
    {
      "x": 0,
      "y": 17,
      "z": 9,
      "name": "Plant_Leaves_Aspen",
      "support": 15
    },
    {
      "x": 0,
      "y": 19,
      "z": 9,
      "name": "Plant_Leaves_Aspen"
    },
    {
      "x": 0,
      "y": 20,
      "z": 9,
      "name": "Plant_Leaves_Aspen",
      "support": 15
    },
    {
      "x": 0,
      "y": 17,
      "z": 10,
      "name": "Wood_Birch_Branch_Corner",
      "support": 15,
      "rotation": 3
    },
    {
      "x": 0,
      "y": 18,
      "z": 10,
      "name": "Wood_Birch_Branch_Long",
      "support": 15
    },
    {
      "x": 0,
      "y": 19,
      "z": 10,
      "name": "Wood_Birch_Branch_Long",
      "support": 15
    },
    {
      "x": 0,
      "y": 20,
      "z": 10,
      "name": "Wood_Birch_Branch_Corner",
      "support": 15,
      "rotation": 9
    },
    {
      "x": 1,
      "y": 14,
      "z": -7,
      "name": "Plant_Leaves_Aspen"
    },
    {
      "x": 1,
      "y": 14,
      "z": -6,
      "name": "Plant_Leaves_Aspen"
    },
    {
      "x": 1,
      "y": 14,
      "z": -5,
      "name": "Plant_Leaves_Aspen"
    },
    {
      "x": 1,
      "y": 8,
      "z": 1,
      "name": "Wood_Birch_Trunk_Full",
      "support": 15,
      "rotation": 5
    },
    {
      "x": 1,
      "y": 9,
      "z": 1,
      "name": "Wood_Birch_Trunk_Full",
      "support": 15,
      "rotation": 5
    },
    {
      "x": 1,
      "y": 10,
      "z": 1,
      "name": "Wood_Birch_Trunk_Full",
      "support": 15,
      "rotation": 5
    },
    {
      "x": 1,
      "y": 11,
      "z": 6,
      "name": "Wood_Birch_Trunk_Full",
      "support": 15
    },
    {
      "x": 1,
      "y": 12,
      "z": 6,
      "name": "Wood_Birch_Trunk",
      "support": 15
    },
    {
      "x": 1,
      "y": 13,
      "z": 6,
      "name": "Wood_Birch_Trunk",
      "support": 15
    },
    {
      "x": 1,
      "y": 14,
      "z": 6,
      "name": "Wood_Birch_Trunk_Full",
      "support": 15
    },
    {
      "x": 1,
      "y": 11,
      "z": 7,
      "name": "Plant_Leaves_Aspen",
      "support": 15
    },
    {
      "x": 1,
      "y": 12,
      "z": 7,
      "name": "Wood_Birch_Trunk_Full",
      "support": 15
    },
    {
      "x": 1,
      "y": 13,
      "z": 7,
      "name": "Wood_Birch_Trunk_Full",
      "support": 15
    },
    {
      "x": 1,
      "y": 19,
      "z": 8,
      "name": "Plant_Leaves_Aspen"
    },
    {
      "x": 1,
      "y": 17,
      "z": 9,
      "name": "Plant_Leaves_Aspen",
      "support": 15
    },
    {
      "x": 1,
      "y": 19,
      "z": 9,
      "name": "Plant_Leaves_Aspen"
    },
    {
      "x": 1,
      "y": 20,
      "z": 9,
      "name": "Plant_Leaves_Aspen"
    },
    {
      "x": 1,
      "y": 17,
      "z": 10,
      "name": "Wood_Birch_Branch_Long",
      "support": 15,
      "rotation": 5
    },
    {
      "x": 1,
      "y": 19,
      "z": 10,
      "name": "Wood_Birch_Branch_Corner",
      "support": 15,
      "rotation": 1
    },
    {
      "x": 1,
      "y": 20,
      "z": 10,
      "name": "Wood_Birch_Branch_Corner",
      "support": 15,
      "rotation": 11
    },
    {
      "x": 2,
      "y": 17,
      "z": -7,
      "name": "Plant_Leaves_Aspen"
    },
    {
      "x": 2,
      "y": 17,
      "z": -6,
      "name": "Plant_Leaves_Aspen"
    },
    {
      "x": 2,
      "y": 17,
      "z": -5,
      "name": "Plant_Leaves_Aspen"
    },
    {
      "x": 2,
      "y": 17,
      "z": -4,
      "name": "Plant_Leaves_Aspen"
    },
    {
      "x": 2,
      "y": 17,
      "z": -3,
      "name": "Plant_Leaves_Aspen"
    },
    {
      "x": 2,
      "y": 17,
      "z": -2,
      "name": "Plant_Leaves_Aspen"
    },
    {
      "x": 2,
      "y": 10,
      "z": 0,
      "name": "Wood_Birch_Trunk_Full",
      "support": 15,
      "rotation": 5
    },
    {
      "x": 2,
      "y": 9,
      "z": 1,
      "name": "Wood_Birch_Trunk_Full",
      "support": 15,
      "rotation": 5
    },
    {
      "x": 2,
      "y": 10,
      "z": 1,
      "name": "Wood_Birch_Trunk_Full",
      "support": 15,
      "rotation": 5
    },
    {
      "x": 2,
      "y": 14,
      "z": 3,
      "name": "Wood_Birch_Branch_Corner",
      "support": 15,
      "rotation": 3
    },
    {
      "x": 2,
      "y": 12,
      "z": 6,
      "name": "Wood_Birch_Trunk_Full",
      "support": 15
    },
    {
      "x": 2,
      "y": 13,
      "z": 6,
      "name": "Wood_Birch_Trunk",
      "support": 15
    },
    {
      "x": 2,
      "y": 14,
      "z": 6,
      "name": "Wood_Birch_Trunk"
    },
    {
      "x": 2,
      "y": 15,
      "z": 6,
      "name": "Wood_Birch_Trunk_Full",
      "support": 15
    },
    {
      "x": 2,
      "y": 13,
      "z": 7,
      "name": "Wood_Birch_Trunk_Full",
      "support": 15
    },
    {
      "x": 2,
      "y": 14,
      "z": 7,
      "name": "Wood_Birch_Trunk_Full",
      "support": 15
    },
    {
      "x": 2,
      "y": 19,
      "z": 8,
      "name": "Plant_Leaves_Aspen"
    },
    {
      "x": 2,
      "y": 19,
      "z": 9,
      "name": "Plant_Leaves_Aspen"
    },
    {
      "x": 2,
      "y": 17,
      "z": 10,
      "name": "Wood_Birch_Branch_Long",
      "support": 15,
      "rotation": 5
    },
    {
      "x": 2,
      "y": 19,
      "z": 10,
      "name": "Plant_Leaves_Aspen"
    },
    {
      "x": 2,
      "y": 20,
      "z": 10,
      "name": "Plant_Leaves_Aspen"
    },
    {
      "x": 3,
      "y": 17,
      "z": -7,
      "name": "Plant_Leaves_Aspen"
    },
    {
      "x": 3,
      "y": 17,
      "z": -6,
      "name": "Plant_Leaves_Aspen"
    },
    {
      "x": 3,
      "y": 18,
      "z": -6,
      "name": "Plant_Leaves_Aspen"
    },
    {
      "x": 3,
      "y": 14,
      "z": -5,
      "name": "Plant_Leaves_Aspen"
    },
    {
      "x": 3,
      "y": 17,
      "z": -5,
      "name": "Plant_Leaves_Aspen"
    },
    {
      "x": 3,
      "y": 18,
      "z": -5,
      "name": "Plant_Leaves_Aspen"
    },
    {
      "x": 3,
      "y": 14,
      "z": -4,
      "name": "Plant_Leaves_Aspen"
    },
    {
      "x": 3,
      "y": 17,
      "z": -4,
      "name": "Plant_Leaves_Aspen"
    },
    {
      "x": 3,
      "y": 18,
      "z": -4,
      "name": "Plant_Leaves_Aspen"
    },
    {
      "x": 3,
      "y": 14,
      "z": -3,
      "name": "Plant_Leaves_Aspen"
    },
    {
      "x": 3,
      "y": 17,
      "z": -3,
      "name": "Plant_Leaves_Aspen"
    },
    {
      "x": 3,
      "y": 17,
      "z": -2,
      "name": "Plant_Leaves_Aspen"
    },
    {
      "x": 3,
      "y": 11,
      "z": -1,
      "name": "Wood_Birch_Trunk_Full",
      "support": 15
    },
    {
      "x": 3,
      "y": 12,
      "z": -1,
      "name": "Wood_Birch_Trunk",
      "support": 15
    },
    {
      "x": 3,
      "y": 13,
      "z": -1,
      "name": "Wood_Birch_Trunk_Full",
      "support": 15
    },
    {
      "x": 3,
      "y": 14,
      "z": -1,
      "name": "Wood_Birch_Branch_Corner",
      "support": 15,
      "rotation": 9
    },
    {
      "x": 3,
      "y": 10,
      "z": 0,
      "name": "Wood_Birch_Trunk_Full",
      "support": 15
    },
    {
      "x": 3,
      "y": 11,
      "z": 0,
      "name": "Wood_Birch_Trunk_Full",
      "support": 15
    },
    {
      "x": 3,
      "y": 10,
      "z": 1,
      "name": "Wood_Birch_Trunk_Full",
      "support": 15,
      "rotation": 5
    },
    {
      "x": 3,
      "y": 19,
      "z": 1,
      "name": "Plant_Leaves_Aspen"
    },
    {
      "x": 3,
      "y": 19,
      "z": 2,
      "name": "Plant_Leaves_Aspen"
    },
    {
      "x": 3,
      "y": 14,
      "z": 3,
      "name": "Wood_Birch_Branch_Corner",
      "support": 15,
      "rotation": 1
    },
    {
      "x": 3,
      "y": 15,
      "z": 3,
      "name": "Wood_Birch_Branch_Corner",
      "support": 15,
      "rotation": 8
    },
    {
      "x": 3,
      "y": 19,
      "z": 3,
      "name": "Plant_Leaves_Aspen"
    },
    {
      "x": 3,
      "y": 15,
      "z": 4,
      "name": "Wood_Birch_Branch_Long",
      "support": 15,
      "rotation": 4
    },
    {
      "x": 3,
      "y": 15,
      "z": 5,
      "name": "Wood_Birch_Trunk_Full",
      "support": 15
    },
    {
      "x": 3,
      "y": 16,
      "z": 5,
      "name": "Wood_Birch_Trunk_Full",
      "support": 15
    },
    {
      "x": 3,
      "y": 14,
      "z": 6,
      "name": "Wood_Birch_Trunk_Full",
      "support": 15
    },
    {
      "x": 3,
      "y": 15,
      "z": 6,
      "name": "Wood_Birch_Trunk"
    },
    {
      "x": 3,
      "y": 16,
      "z": 6,
      "name": "Wood_Birch_Trunk"
    },
    {
      "x": 3,
      "y": 17,
      "z": 6,
      "name": "Wood_Birch_Trunk_Full",
      "support": 15
    },
    {
      "x": 3,
      "y": 14,
      "z": 7,
      "name": "Wood_Birch_Trunk_Full",
      "support": 15
    },
    {
      "x": 3,
      "y": 15,
      "z": 7,
      "name": "Wood_Birch_Trunk",
      "support": 15,
      "rotation": 4
    },
    {
      "x": 3,
      "y": 15,
      "z": 8,
      "name": "Wood_Birch_Trunk_Full",
      "support": 15,
      "rotation": 4
    },
    {
      "x": 3,
      "y": 15,
      "z": 9,
      "name": "Wood_Birch_Branch_Long",
      "support": 15,
      "rotation": 4
    },
    {
      "x": 3,
      "y": 19,
      "z": 9,
      "name": "Plant_Leaves_Aspen"
    },
    {
      "x": 3,
      "y": 15,
      "z": 10,
      "name": "Wood_Birch_Branch_Corner",
      "support": 15
    },
    {
      "x": 3,
      "y": 16,
      "z": 10,
      "name": "Wood_Birch_Branch_Long",
      "support": 15
    },
    {
      "x": 3,
      "y": 17,
      "z": 10,
      "name": "Wood_Birch_Branch_Corner",
      "support": 15,
      "rotation": 11
    },
    {
      "x": 3,
      "y": 19,
      "z": 10,
      "name": "Plant_Leaves_Aspen"
    },
    {
      "x": 4,
      "y": 17,
      "z": -7,
      "name": "Plant_Leaves_Aspen"
    },
    {
      "x": 4,
      "y": 18,
      "z": -7,
      "name": "Plant_Leaves_Aspen"
    },
    {
      "x": 4,
      "y": 14,
      "z": -6,
      "name": "Plant_Leaves_Aspen"
    },
    {
      "x": 4,
      "y": 17,
      "z": -6,
      "name": "Plant_Leaves_Aspen"
    },
    {
      "x": 4,
      "y": 18,
      "z": -6,
      "name": "Plant_Leaves_Aspen"
    },
    {
      "x": 4,
      "y": 14,
      "z": -5,
      "name": "Plant_Leaves_Aspen"
    },
    {
      "x": 4,
      "y": 15,
      "z": -5,
      "name": "Plant_Leaves_Aspen"
    },
    {
      "x": 4,
      "y": 17,
      "z": -5,
      "name": "Plant_Leaves_Aspen"
    },
    {
      "x": 4,
      "y": 18,
      "z": -5,
      "name": "Plant_Leaves_Aspen"
    },
    {
      "x": 4,
      "y": 14,
      "z": -4,
      "name": "Plant_Leaves_Aspen"
    },
    {
      "x": 4,
      "y": 15,
      "z": -4,
      "name": "Plant_Leaves_Aspen"
    },
    {
      "x": 4,
      "y": 17,
      "z": -4,
      "name": "Plant_Leaves_Aspen"
    },
    {
      "x": 4,
      "y": 18,
      "z": -4,
      "name": "Plant_Leaves_Aspen"
    },
    {
      "x": 4,
      "y": 14,
      "z": -3,
      "name": "Plant_Leaves_Aspen"
    },
    {
      "x": 4,
      "y": 15,
      "z": -3,
      "name": "Plant_Leaves_Aspen"
    },
    {
      "x": 4,
      "y": 17,
      "z": -3,
      "name": "Plant_Leaves_Aspen"
    },
    {
      "x": 4,
      "y": 18,
      "z": -3,
      "name": "Plant_Leaves_Aspen"
    },
    {
      "x": 4,
      "y": 14,
      "z": -2,
      "name": "Plant_Leaves_Aspen"
    },
    {
      "x": 4,
      "y": 17,
      "z": -2,
      "name": "Plant_Leaves_Aspen"
    },
    {
      "x": 4,
      "y": 14,
      "z": -1,
      "name": "Wood_Birch_Branch_Long",
      "support": 15,
      "rotation": 5
    },
    {
      "x": 4,
      "y": 17,
      "z": -1,
      "name": "Plant_Leaves_Aspen"
    },
    {
      "x": 4,
      "y": 19,
      "z": 0,
      "name": "Plant_Leaves_Aspen"
    },
    {
      "x": 4,
      "y": 19,
      "z": 1,
      "name": "Plant_Leaves_Aspen"
    },
    {
      "x": 4,
      "y": 19,
      "z": 2,
      "name": "Plant_Leaves_Aspen"
    },
    {
      "x": 4,
      "y": 20,
      "z": 2,
      "name": "Plant_Leaves_Aspen"
    },
    {
      "x": 4,
      "y": 19,
      "z": 3,
      "name": "Plant_Leaves_Aspen"
    },
    {
      "x": 4,
      "y": 19,
      "z": 4,
      "name": "Plant_Leaves_Aspen"
    },
    {
      "x": 4,
      "y": 16,
      "z": 5,
      "name": "Wood_Birch_Trunk_Full",
      "support": 15
    },
    {
      "x": 4,
      "y": 17,
      "z": 5,
      "name": "Wood_Birch_Trunk_Full",
      "support": 15
    },
    {
      "x": 4,
      "y": 15,
      "z": 6,
      "name": "Wood_Birch_Trunk_Full",
      "support": 15
    },
    {
      "x": 4,
      "y": 16,
      "z": 6,
      "name": "Wood_Birch_Trunk"
    },
    {
      "x": 4,
      "y": 17,
      "z": 6,
      "name": "Wood_Birch_Trunk"
    },
    {
      "x": 4,
      "y": 18,
      "z": 6,
      "name": "Wood_Birch_Trunk_Full",
      "support": 15
    },
    {
      "x": 4,
      "y": 15,
      "z": 7,
      "name": "Wood_Birch_Trunk_Full",
      "support": 15
    },
    {
      "x": 4,
      "y": 16,
      "z": 7,
      "name": "Wood_Birch_Trunk"
    },
    {
      "x": 4,
      "y": 17,
      "z": 7,
      "name": "Wood_Birch_Trunk"
    },
    {
      "x": 5,
      "y": 17,
      "z": -7,
      "name": "Plant_Leaves_Aspen"
    },
    {
      "x": 5,
      "y": 18,
      "z": -7,
      "name": "Plant_Leaves_Aspen"
    },
    {
      "x": 5,
      "y": 14,
      "z": -6,
      "name": "Plant_Leaves_Aspen"
    },
    {
      "x": 5,
      "y": 17,
      "z": -6,
      "name": "Plant_Leaves_Aspen"
    },
    {
      "x": 5,
      "y": 18,
      "z": -6,
      "name": "Plant_Leaves_Aspen"
    },
    {
      "x": 5,
      "y": 14,
      "z": -5,
      "name": "Plant_Leaves_Aspen"
    },
    {
      "x": 5,
      "y": 15,
      "z": -5,
      "name": "Wood_Birch_Branch_Corner",
      "support": 15,
      "rotation": 2
    },
    {
      "x": 5,
      "y": 16,
      "z": -5,
      "name": "Wood_Birch_Branch_Long",
      "support": 15
    },
    {
      "x": 5,
      "y": 17,
      "z": -5,
      "name": "Wood_Birch_Branch_Long",
      "support": 15
    },
    {
      "x": 5,
      "y": 18,
      "z": -5,
      "name": "Plant_Leaves_Aspen"
    },
    {
      "x": 5,
      "y": 14,
      "z": -4,
      "name": "Plant_Leaves_Aspen"
    },
    {
      "x": 5,
      "y": 15,
      "z": -4,
      "name": "Wood_Birch_Branch_Long",
      "support": 15,
      "rotation": 4
    },
    {
      "x": 5,
      "y": 17,
      "z": -4,
      "name": "Plant_Leaves_Aspen"
    },
    {
      "x": 5,
      "y": 18,
      "z": -4,
      "name": "Plant_Leaves_Aspen"
    },
    {
      "x": 5,
      "y": 14,
      "z": -3,
      "name": "Plant_Leaves_Aspen"
    },
    {
      "x": 5,
      "y": 15,
      "z": -3,
      "name": "Wood_Birch_Branch_Long",
      "support": 15,
      "rotation": 4
    },
    {
      "x": 5,
      "y": 17,
      "z": -3,
      "name": "Plant_Leaves_Aspen"
    },
    {
      "x": 5,
      "y": 18,
      "z": -3,
      "name": "Plant_Leaves_Aspen"
    },
    {
      "x": 5,
      "y": 14,
      "z": -2,
      "name": "Plant_Leaves_Aspen"
    },
    {
      "x": 5,
      "y": 15,
      "z": -2,
      "name": "Wood_Birch_Branch_Long",
      "support": 15,
      "rotation": 4
    },
    {
      "x": 5,
      "y": 17,
      "z": -2,
      "name": "Plant_Leaves_Aspen"
    },
    {
      "x": 5,
      "y": 14,
      "z": -1,
      "name": "Wood_Birch_Branch_Corner",
      "support": 15,
      "rotation": 1
    },
    {
      "x": 5,
      "y": 15,
      "z": -1,
      "name": "Wood_Birch_Branch_Corner",
      "support": 15,
      "rotation": 10
    },
    {
      "x": 5,
      "y": 17,
      "z": -1,
      "name": "Plant_Leaves_Aspen"
    },
    {
      "x": 5,
      "y": 19,
      "z": 0,
      "name": "Plant_Leaves_Aspen"
    },
    {
      "x": 5,
      "y": 19,
      "z": 1,
      "name": "Plant_Leaves_Aspen"
    },
    {
      "x": 5,
      "y": 20,
      "z": 1,
      "name": "Plant_Leaves_Aspen"
    },
    {
      "x": 5,
      "y": 17,
      "z": 2,
      "name": "Wood_Birch_Branch_Corner",
      "support": 15,
      "rotation": 2
    },
    {
      "x": 5,
      "y": 18,
      "z": 2,
      "name": "Wood_Birch_Branch_Long",
      "support": 15
    },
    {
      "x": 5,
      "y": 19,
      "z": 2,
      "name": "Wood_Birch_Branch_Long",
      "support": 15
    },
    {
      "x": 5,
      "y": 20,
      "z": 2,
      "name": "Plant_Leaves_Aspen"
    },
    {
      "x": 5,
      "y": 17,
      "z": 3,
      "name": "Wood_Birch_Branch_Long",
      "support": 15,
      "rotation": 4
    },
    {
      "x": 5,
      "y": 19,
      "z": 3,
      "name": "Plant_Leaves_Aspen"
    },
    {
      "x": 5,
      "y": 20,
      "z": 3,
      "name": "Plant_Leaves_Aspen"
    },
    {
      "x": 5,
      "y": 17,
      "z": 4,
      "name": "Wood_Birch_Branch_Long",
      "support": 15,
      "rotation": 4
    },
    {
      "x": 5,
      "y": 19,
      "z": 4,
      "name": "Plant_Leaves_Aspen"
    },
    {
      "x": 5,
      "y": 16,
      "z": 5,
      "name": "Wood_Birch_Trunk_Half",
      "rotation": 6
    },
    {
      "x": 5,
      "y": 17,
      "z": 5,
      "name": "Wood_Birch_Trunk_Full",
      "support": 15
    },
    {
      "x": 5,
      "y": 18,
      "z": 5,
      "name": "Wood_Birch_Trunk_Full",
      "support": 15
    },
    {
      "x": 5,
      "y": 15,
      "z": 6,
      "name": "Wood_Birch_Trunk_Full",
      "support": 15
    },
    {
      "x": 5,
      "y": 16,
      "z": 6,
      "name": "Wood_Birch_Trunk"
    },
    {
      "x": 5,
      "y": 17,
      "z": 6,
      "name": "Wood_Birch_Trunk"
    },
    {
      "x": 5,
      "y": 18,
      "z": 6,
      "name": "Wood_Birch_Trunk"
    },
    {
      "x": 5,
      "y": 19,
      "z": 6,
      "name": "Wood_Birch_Trunk_Full",
      "support": 15
    },
    {
      "x": 5,
      "y": 16,
      "z": 7,
      "name": "Wood_Birch_Trunk_Full",
      "support": 15
    },
    {
      "x": 5,
      "y": 17,
      "z": 7,
      "name": "Wood_Birch_Trunk",
      "support": 15
    },
    {
      "x": 5,
      "y": 18,
      "z": 7,
      "name": "Wood_Birch_Trunk"
    },
    {
      "x": 5,
      "y": 17,
      "z": 8,
      "name": "Wood_Birch_Trunk_Half",
      "rotation": 4
    },
    {
      "x": 6,
      "y": 17,
      "z": -7,
      "name": "Plant_Leaves_Aspen"
    },
    {
      "x": 6,
      "y": 18,
      "z": -7,
      "name": "Plant_Leaves_Aspen"
    },
    {
      "x": 6,
      "y": 14,
      "z": -6,
      "name": "Plant_Leaves_Aspen"
    },
    {
      "x": 6,
      "y": 17,
      "z": -6,
      "name": "Plant_Leaves_Aspen"
    },
    {
      "x": 6,
      "y": 18,
      "z": -6,
      "name": "Plant_Leaves_Aspen"
    },
    {
      "x": 6,
      "y": 14,
      "z": -5,
      "name": "Plant_Leaves_Aspen"
    },
    {
      "x": 6,
      "y": 17,
      "z": -5,
      "name": "Plant_Leaves_Aspen"
    },
    {
      "x": 6,
      "y": 18,
      "z": -5,
      "name": "Plant_Leaves_Aspen"
    },
    {
      "x": 6,
      "y": 14,
      "z": -4,
      "name": "Plant_Leaves_Aspen"
    },
    {
      "x": 6,
      "y": 15,
      "z": -4,
      "name": "Plant_Leaves_Aspen"
    },
    {
      "x": 6,
      "y": 17,
      "z": -4,
      "name": "Plant_Leaves_Aspen"
    },
    {
      "x": 6,
      "y": 18,
      "z": -4,
      "name": "Plant_Leaves_Aspen"
    },
    {
      "x": 6,
      "y": 14,
      "z": -3,
      "name": "Plant_Leaves_Aspen"
    },
    {
      "x": 6,
      "y": 15,
      "z": -3,
      "name": "Plant_Leaves_Aspen"
    },
    {
      "x": 6,
      "y": 17,
      "z": -3,
      "name": "Plant_Leaves_Aspen"
    },
    {
      "x": 6,
      "y": 18,
      "z": -3,
      "name": "Plant_Leaves_Aspen"
    },
    {
      "x": 6,
      "y": 14,
      "z": -2,
      "name": "Plant_Leaves_Aspen"
    },
    {
      "x": 6,
      "y": 17,
      "z": -2,
      "name": "Plant_Leaves_Aspen"
    },
    {
      "x": 6,
      "y": 17,
      "z": -1,
      "name": "Plant_Leaves_Aspen"
    },
    {
      "x": 6,
      "y": 19,
      "z": 0,
      "name": "Plant_Leaves_Aspen"
    },
    {
      "x": 6,
      "y": 19,
      "z": 1,
      "name": "Plant_Leaves_Aspen"
    },
    {
      "x": 6,
      "y": 19,
      "z": 2,
      "name": "Plant_Leaves_Aspen"
    },
    {
      "x": 6,
      "y": 20,
      "z": 2,
      "name": "Plant_Leaves_Aspen"
    },
    {
      "x": 6,
      "y": 19,
      "z": 3,
      "name": "Plant_Leaves_Aspen"
    },
    {
      "x": 6,
      "y": 19,
      "z": 4,
      "name": "Plant_Leaves_Aspen"
    },
    {
      "x": 6,
      "y": 17,
      "z": 6,
      "name": "Wood_Birch_Trunk_Full",
      "support": 15
    },
    {
      "x": 6,
      "y": 18,
      "z": 6,
      "name": "Wood_Birch_Trunk"
    },
    {
      "x": 6,
      "y": 19,
      "z": 6,
      "name": "Wood_Birch_Trunk_Full",
      "support": 15
    },
    {
      "x": 6,
      "y": 17,
      "z": 7,
      "name": "Wood_Birch_Trunk_Full",
      "support": 15
    },
    {
      "x": 6,
      "y": 18,
      "z": 7,
      "name": "Wood_Birch_Trunk",
      "support": 15
    },
    {
      "x": 6,
      "y": 19,
      "z": 7,
      "name": "Wood_Birch_Trunk_Full",
      "support": 15
    },
    {
      "x": 6,
      "y": 18,
      "z": 8,
      "name": "Wood_Birch_Trunk_Half",
      "rotation": 4
    },
    {
      "x": 7,
      "y": 17,
      "z": -7,
      "name": "Plant_Leaves_Aspen"
    },
    {
      "x": 7,
      "y": 17,
      "z": -6,
      "name": "Plant_Leaves_Aspen"
    },
    {
      "x": 7,
      "y": 18,
      "z": -6,
      "name": "Plant_Leaves_Aspen"
    },
    {
      "x": 7,
      "y": 14,
      "z": -5,
      "name": "Plant_Leaves_Aspen"
    },
    {
      "x": 7,
      "y": 17,
      "z": -5,
      "name": "Plant_Leaves_Aspen"
    },
    {
      "x": 7,
      "y": 18,
      "z": -5,
      "name": "Plant_Leaves_Aspen"
    },
    {
      "x": 7,
      "y": 14,
      "z": -4,
      "name": "Plant_Leaves_Aspen"
    },
    {
      "x": 7,
      "y": 17,
      "z": -4,
      "name": "Plant_Leaves_Aspen"
    },
    {
      "x": 7,
      "y": 18,
      "z": -4,
      "name": "Plant_Leaves_Aspen"
    },
    {
      "x": 7,
      "y": 14,
      "z": -3,
      "name": "Plant_Leaves_Aspen"
    },
    {
      "x": 7,
      "y": 17,
      "z": -3,
      "name": "Plant_Leaves_Aspen"
    },
    {
      "x": 7,
      "y": 17,
      "z": -2,
      "name": "Plant_Leaves_Aspen"
    },
    {
      "x": 7,
      "y": 19,
      "z": 1,
      "name": "Plant_Leaves_Aspen"
    },
    {
      "x": 7,
      "y": 19,
      "z": 2,
      "name": "Plant_Leaves_Aspen"
    },
    {
      "x": 7,
      "y": 19,
      "z": 3,
      "name": "Plant_Leaves_Aspen"
    },
    {
      "x": 7,
      "y": 18,
      "z": 6,
      "name": "Wood_Birch_Trunk_Full",
      "support": 15
    },
    {
      "x": 7,
      "y": 19,
      "z": 6,
      "name": "Wood_Birch_Trunk_Full",
      "support": 15
    },
    {
      "x": 7,
      "y": 18,
      "z": 7,
      "name": "Wood_Birch_Trunk_Full",
      "support": 15
    },
    {
      "x": 7,
      "y": 19,
      "z": 7,
      "name": "Wood_Birch_Trunk_Full",
      "support": 15
    },
    {
      "x": 7,
      "y": 20,
      "z": 7,
      "name": "Wood_Birch_Trunk_Full",
      "support": 15
    },
    {
      "x": 7,
      "y": 18,
      "z": 8,
      "name": "Wood_Birch_Trunk_Half",
      "rotation": 4
    },
    {
      "x": 7,
      "y": 19,
      "z": 8,
      "name": "Wood_Birch_Trunk_Full",
      "support": 15
    },
    {
      "x": 7,
      "y": 20,
      "z": 8,
      "name": "Wood_Birch_Trunk_Half"
    },
    {
      "x": 8,
      "y": 17,
      "z": -6,
      "name": "Plant_Leaves_Aspen"
    },
    {
      "x": 8,
      "y": 17,
      "z": -5,
      "name": "Plant_Leaves_Aspen"
    },
    {
      "x": 8,
      "y": 17,
      "z": -4,
      "name": "Plant_Leaves_Aspen"
    },
    {
      "x": 8,
      "y": 17,
      "z": -3,
      "name": "Plant_Leaves_Aspen"
    },
    {
      "x": 8,
      "y": 18,
      "z": 6,
      "name": "Wood_Birch_Trunk_Full",
      "support": 15
    },
    {
      "x": 8,
      "y": 19,
      "z": 6,
      "name": "Wood_Birch_Trunk_Full",
      "support": 15
    },
    {
      "x": 8,
      "y": 19,
      "z": 7,
      "name": "Wood_Birch_Trunk_Full",
      "support": 15
    },
    {
      "x": 8,
      "y": 20,
      "z": 7,
      "name": "Wood_Birch_Trunk_Full",
      "support": 15
    },
    {
      "x": 8,
      "y": 19,
      "z": 8,
      "name": "Wood_Birch_Trunk_Full",
      "support": 15
    },
    {
      "x": 8,
      "y": 20,
      "z": 8,
      "name": "Wood_Birch_Trunk_Full",
      "support": 15
    }
  ]
}