{
  "version": 8,
  "blockIdVersion": 11,
  "anchorX": 0,
  "anchorY": 0,
  "anchorZ": 0,
  "blocks": [
    {
      "x": -4,
      "y": -8,
      "z": -3,
      "name": "Wood_Birch_Trunk_Full"
    },
    {
      "x": -4,
      "y": -7,
      "z": -3,
      "name": "Wood_Birch_Trunk_Full"
    },
    {
      "x": -4,
      "y": 24,
      "z": -2,
      "name": "Plant_Leaves_Aspen"
    },
    {
      "x": -4,
      "y": 28,
      "z": -2,
      "name": "Plant_Leaves_Aspen"
    },
    {
      "x": -4,
      "y": 24,
      "z": -1,
      "name": "Plant_Leaves_Aspen"
    },
    {
      "x": -4,
      "y": 28,
      "z": -1,
      "name": "Plant_Leaves_Aspen"
    },
    {
      "x": -4,
      "y": 24,
      "z": 0,
      "name": "Plant_Leaves_Aspen"
    },
    {
      "x": -4,
      "y": 28,
      "z": 0,
      "name": "Plant_Leaves_Aspen"
    },
    {
      "x": -4,
      "y": 24,
      "z": 1,
      "name": "Plant_Leaves_Aspen"
    },
    {
      "x": -4,
      "y": -5,
      "z": 2,
      "name": "Wood_Birch_Branch_Long",
      "rotation": 5
    },
    {
      "x": -4,
      "y": 24,
      "z": 2,
      "name": "Plant_Leaves_Aspen"
    },
    {
      "x": -4,
      "y": 22,
      "z": 3,
      "name": "Plant_Leaves_Aspen"
    },
    {
      "x": -4,
      "y": 22,
      "z": 4,
      "name": "Plant_Leaves_Aspen"
    },
    {
      "x": -4,
      "y": 22,
      "z": 5,
      "name": "Plant_Leaves_Aspen"
    },
    {
      "x": -3,
      "y": -8,
      "z": -3,
      "name": "Wood_Birch_Trunk_Full",
      "rotation": 4
    },
    {
      "x": -3,
      "y": 24,
      "z": -3,
      "name": "Plant_Leaves_Aspen"
    },
    {
      "x": -3,
      "y": 28,
      "z": -3,
      "name": "Plant_Leaves_Aspen"
    },
    {
      "x": -3,
      "y": -8,
      "z": -2,
      "name": "Wood_Birch_Trunk_Full",
      "rotation": 4
    },
    {
      "x": -3,
      "y": 8,
      "z": -2,
      "name": "Wood_Birch_Branch_Corner",
      "rotation": 3
    },
    {
      "x": -3,
      "y": 9,
      "z": -2,
      "name": "Wood_Birch_Branch_Long"
    },
    {
      "x": -3,
      "y": 10,
      "z": -2,
      "name": "Wood_Birch_Branch_Corner",
      "rotation": 9
    },
    {
      "x": -3,
      "y": 24,
      "z": -2,
      "name": "Plant_Leaves_Aspen"
    },
    {
      "x": -3,
      "y": 28,
      "z": -2,
      "name": "Plant_Leaves_Aspen"
    },
    {
      "x": -3,
      "y": 24,
      "z": -1,
      "name": "Plant_Leaves_Aspen"
    },
    {
      "x": -3,
      "y": 28,
      "z": -1,
      "name": "Plant_Leaves_Aspen"
    },
    {
      "x": -3,
      "y": 24,
      "z": 0,
      "name": "Plant_Leaves_Aspen"
    },
    {
      "x": -3,
      "y": 28,
      "z": 0,
      "name": "Plant_Leaves_Aspen"
    },
    {
      "x": -3,
      "y": 24,
      "z": 1,
      "name": "Plant_Leaves_Aspen"
    },
    {
      "x": -3,
      "y": 28,
      "z": 1,
      "name": "Plant_Leaves_Aspen"
    },
    {
      "x": -3,
      "y": -5,
      "z": 2,
      "name": "Wood_Birch_Branch_Corner",
      "rotation": 1
    },
    {
      "x": -3,
      "y": -4,
      "z": 2,
      "name": "Wood_Birch_Branch_Long"
    },
    {
      "x": -3,
      "y": -3,
      "z": 2,
      "name": "Wood_Birch_Branch_Long"
    },
    {
      "x": -3,
      "y": -2,
      "z": 2,
      "name": "Wood_Birch_Branch_Corner",
      "rotation": 9
    },
    {
      "x": -3,
      "y": 22,
      "z": 2,
      "name": "Plant_Leaves_Aspen"
    },
    {
      "x": -3,
      "y": 24,
      "z": 2,
      "name": "Plant_Leaves_Aspen"
    },
    {
      "x": -3,
      "y": 22,
      "z": 3,
      "name": "Plant_Leaves_Aspen"
    },
    {
      "x": -3,
      "y": 24,
      "z": 3,
      "name": "Plant_Leaves_Aspen"
    },
    {
      "x": -3,
      "y": 22,
      "z": 4,
      "name": "Plant_Leaves_Aspen"
    },
    {
      "x": -3,
      "y": 22,
      "z": 5,
      "name": "Plant_Leaves_Aspen"
    },
    {
      "x": -3,
      "y": 22,
      "z": 6,
      "name": "Plant_Leaves_Aspen"
    },
    {
      "x": -2,
      "y": 16,
      "z": -5,
      "name": "Plant_Leaves_Aspen"
    },
    {
      "x": -2,
      "y": 16,
      "z": -4,
      "name": "Plant_Leaves_Aspen"
    },
    {
      "x": -2,
      "y": 24,
      "z": -4,
      "name": "Plant_Leaves_Aspen"
    },
    {
      "x": -2,
      "y": 28,
      "z": -4,
      "name": "Plant_Leaves_Aspen"
    },
    {
      "x": -2,
      "y": 16,
      "z": -3,
      "name": "Plant_Leaves_Aspen"
    },
    {
      "x": -2,
      "y": 24,
      "z": -3,
      "name": "Plant_Leaves_Aspen"
    },
    {
      "x": -2,
      "y": 28,
      "z": -3,
      "name": "Plant_Leaves_Aspen"
    },
    {
      "x": -2,
      "y": -8,
      "z": -2,
      "name": "Wood_Birch_Trunk_Full"
    },
    {
      "x": -2,
      "y": -1,
      "z": -2,
      "name": "Wood_Birch_Trunk_Full"
    },
    {
      "x": -2,
      "y": 0,
      "z": -2,
      "name": "Wood_Birch_Trunk"
    },
    {
      "x": -2,
      "y": 1,
      "z": -2,
      "name": "Wood_Birch_Trunk_Full"
    },
    {
      "x": -2,
      "y": 8,
      "z": -2,
      "name": "Wood_Birch_Branch_Long",
      "rotation": 5
    },
    {
      "x": -2,
      "y": 9,
      "z": -2,
      "name": "Wood_Birch_Branch_Corner",
      "rotation": 3
    },
    {
      "x": -2,
      "y": 10,
      "z": -2,
      "name": "Wood_Birch_Branch_Long",
      "rotation": 5
    },
    {
      "x": -2,
      "y": 16,
      "z": -2,
      "name": "Plant_Leaves_Aspen"
    },
    {
      "x": -2,
      "y": 24,
      "z": -2,
      "name": "Plant_Leaves_Aspen"
    },
    {
      "x": -2,
      "y": 28,
      "z": -2,
      "name": "Plant_Leaves_Aspen"
    },
    {
      "x": -2,
      "y": -8,
      "z": -1,
      "name": "Wood_Birch_Trunk_Full"
    },
    {
      "x": -2,
      "y": -7,
      "z": -1,
      "name": "Wood_Birch_Trunk_Full"
    },
    {
      "x": -2,
      "y": -3,
      "z": -1,
      "name": "Wood_Birch_Trunk_Full"
    },
    {
      "x": -2,
      "y": -2,
      "z": -1,
      "name": "Wood_Birch_Trunk"
    },
    {
      "x": -2,
      "y": -1,
      "z": -1,
      "name": "Wood_Birch_Trunk"
    },
    {
      "x": -2,
      "y": 0,
      "z": -1,
      "name": "Wood_Birch_Trunk"
    },
    {
      "x": -2,
      "y": 1,
      "z": -1,
      "name": "Wood_Birch_Trunk"
    },
    {
      "x": -2,
      "y": 2,
      "z": -1,
      "name": "Wood_Birch_Trunk"
    },
    {
      "x": -2,
      "y": 3,
      "z": -1,
      "name": "Wood_Birch_Trunk_Full"
    },
    {
      "x": -2,
      "y": 4,
      "z": -1,
      "name": "Wood_Birch_Trunk_Half",
      "rotation": 7
    },
    {
      "x": -2,
      "y": 14,
      "z": -1,
      "name": "Wood_Birch_Trunk_Full"
    },
    {
      "x": -2,
      "y": 15,
      "z": -1,
      "name": "Wood_Birch_Trunk"
    },
    {
      "x": -2,
      "y": 16,
      "z": -1,
      "name": "Wood_Birch_Trunk"
    },
    {
      "x": -2,
      "y": 17,
      "z": -1,
      "name": "Wood_Birch_Trunk_Full"
    },
    {
      "x": -2,
      "y": 24,
      "z": -1,
      "name": "Plant_Leaves_Aspen"
    },
    {
      "x": -2,
      "y": 28,
      "z": -1,
      "name": "Plant_Leaves_Aspen"
    },
    {
      "x": -2,
      "y": 29,
      "z": -1,
      "name": "Plant_Leaves_Aspen"
    },
    {
      "x": -2,
      "y": 24,
      "z": 0,
      "name": "Plant_Leaves_Aspen"
    },
    {
      "x": -2,
      "y": 28,
      "z": 0,
      "name": "Plant_Leaves_Aspen"
    },
    {
      "x": -2,
      "y": 16,
      "z": 1,
      "name": "Wood_Birch_Trunk_Full",
      "rotation": 4
    },
    {
      "x": -2,
      "y": 22,
      "z": 1,
      "name": "Plant_Leaves_Aspen"
    },
    {
      "x": -2,
      "y": 24,
      "z": 1,
      "name": "Plant_Leaves_Aspen"
    },
    {
      "x": -2,
      "y": 28,
      "z": 1,
      "name": "Plant_Leaves_Aspen"
    },
    {
      "x": -2,
      "y": -2,
      "z": 2,
      "name": "Wood_Birch_Branch_Long",
      "rotation": 5
    },
    {
      "x": -2,
      "y": 16,
      "z": 2,
      "name": "Wood_Birch_Trunk_Full",
      "rotation": 4
    },
    {
      "x": -2,
      "y": 17,
      "z": 2,
      "name": "Wood_Birch_Trunk_Full",
      "rotation": 4
    },
    {
      "x": -2,
      "y": 22,
      "z": 2,
      "name": "Plant_Leaves_Aspen"
    },
    {
      "x": -2,
      "y": 24,
      "z": 2,
      "name": "Plant_Leaves_Aspen"
    },
    {
      "x": -2,
      "y": 28,
      "z": 2,
      "name": "Plant_Leaves_Aspen"
    },
    {
      "x": -2,
      "y": 17,
      "z": 3,
      "name": "Wood_Birch_Trunk_Full",
      "rotation": 4
    },
    {
      "x": -2,
      "y": 18,
      "z": 3,
      "name": "Wood_Birch_Trunk_Full",
      "rotation": 4
    },
    {
      "x": -2,
      "y": 19,
      "z": 3,
      "name": "Plant_Leaves_Aspen"
    },
    {
      "x": -2,
      "y": 22,
      "z": 3,
      "name": "Plant_Leaves_Aspen"
    },
    {
      "x": -2,
      "y": 24,
      "z": 3,
      "name": "Plant_Leaves_Aspen"
    },
    {
      "x": -2,
      "y": 18,
      "z": 4,
      "name": "Wood_Birch_Trunk_Full",
      "rotation": 4
    },
    {
      "x": -2,
      "y": 19,
      "z": 4,
      "name": "Plant_Leaves_Aspen"
    },
    {
      "x": -2,
      "y": 22,
      "z": 4,
      "name": "Plant_Leaves_Aspen"
    },
    {
      "x": -2,
      "y": 23,
      "z": 4,
      "name": "Plant_Leaves_Aspen"
    },
    {
      "x": -2,
      "y": 24,
      "z": 4,
      "name": "Plant_Leaves_Aspen"
    },
    {
      "x": -2,
      "y": 19,
      "z": 5,
      "name": "Plant_Leaves_Aspen"
    },
    {
      "x": -2,
      "y": 22,
      "z": 5,
      "name": "Plant_Leaves_Aspen"
    },
    {
      "x": -2,
      "y": 22,
      "z": 6,
      "name": "Plant_Leaves_Aspen"
    },
    {
      "x": -1,
      "y": 16,
      "z": -6,
      "name": "Plant_Leaves_Aspen"
    },
    {
      "x": -1,
      "y": 16,
      "z": -5,
      "name": "Plant_Leaves_Aspen"
    },
    {
      "x": -1,
      "y": 24,
      "z": -5,
      "name": "Plant_Leaves_Aspen"
    },
    {
      "x": -1,
      "y": 16,
      "z": -4,
      "name": "Plant_Leaves_Aspen"
    },
    {
      "x": -1,
      "y": 24,
      "z": -4,
      "name": "Plant_Leaves_Aspen"
    },
    {
      "x": -1,
      "y": 28,
      "z": -4,
      "name": "Plant_Leaves_Aspen"
    },
    {
      "x": -1,
      "y": 16,
      "z": -3,
      "name": "Plant_Leaves_Aspen"
    },
    {
      "x": -1,
      "y": 24,
      "z": -3,
      "name": "Plant_Leaves_Aspen"
    },
    {
      "x": -1,
      "y": 28,
      "z": -3,
      "name": "Plant_Leaves_Aspen"
    },
    {
      "x": -1,
      "y": -8,
      "z": -2,
      "name": "Wood_Birch_Trunk_Full"
    },
    {
      "x": -1,
      "y": -7,
      "z": -2,
      "name": "Wood_Birch_Trunk"
    },
    {
      "x": -1,
      "y": -6,
      "z": -2,
      "name": "Wood_Birch_Trunk_Full"
    },
    {
      "x": -1,
      "y": -3,
      "z": -2,
      "name": "Wood_Birch_Trunk_Full"
    },
    {
      "x": -1,
      "y": -2,
      "z": -2,
      "name": "Wood_Birch_Trunk"
    },
    {
      "x": -1,
      "y": -1,
      "z": -2,
      "name": "Wood_Birch_Trunk"
    },
    {
      "x": -1,
      "y": 0,
      "z": -2,
      "name": "Wood_Birch_Trunk"
    },
    {
      "x": -1,
      "y": 1,
      "z": -2,
      "name": "Wood_Birch_Trunk"
    },
    {
      "x": -1,
      "y": 2,
      "z": -2,
      "name": "Wood_Birch_Trunk_Full"
    },
    {
      "x": -1,
      "y": 3,
      "z": -2,
      "name": "Wood_Birch_Trunk_Stairs",
      "rotation": 3
    },
    {
      "x": -1,
      "y": 8,
      "z": -2,
      "name": "Wood_Birch_Branch_Long",
      "rotation": 5
    },
    {
      "x": -1,
      "y": 9,
      "z": -2,
      "name": "Wood_Birch_Branch_Corner",
      "rotation": 1
    },
    {
      "x": -1,
      "y": 10,
      "z": -2,
      "name": "Wood_Birch_Branch_Corner",
      "rotation": 11
    },
    {
      "x": -1,
      "y": 16,
      "z": -2,
      "name": "Plant_Leaves_Aspen"
    },
    {
      "x": -1,
      "y": 24,
      "z": -2,
      "name": "Plant_Leaves_Aspen"
    },
    {
      "x": -1,
      "y": 25,
      "z": -2,
      "name": "Plant_Leaves_Aspen"
    },
    {
      "x": -1,
      "y": 28,
      "z": -2,
      "name": "Plant_Leaves_Aspen"
    },
    {
      "x": -1,
      "y": 29,
      "z": -2,
      "name": "Plant_Leaves_Aspen"
    },
    {
      "x": -1,
      "y": -8,
      "z": -1,
      "name": "Wood_Birch_Trunk_Full"
    },
    {
      "x": -1,
      "y": -7,
      "z": -1,
      "name": "Wood_Birch_Trunk"
    },
    {
      "x": -1,
      "y": -6,
      "z": -1,
      "name": "Wood_Birch_Trunk"
    },
    {
      "x": -1,
      "y": -5,
      "z": -1,
      "name": "Wood_Birch_Trunk"
    },
    {
      "x": -1,
      "y": -4,
      "z": -1,
      "name": "Wood_Birch_Trunk"
    },
    {
      "x": -1,
      "y": -3,
      "z": -1,
      "name": "Wood_Birch_Trunk"
    },
    {
      "x": -1,
      "y": -2,
      "z": -1,
      "name": "Wood_Birch_Trunk"
    },
    {
      "x": -1,
      "y": -1,
      "z": -1,
      "name": "Wood_Birch_Trunk"
    },
    {
      "x": -1,
      "y": 0,
      "z": -1,
      "name": "Wood_Birch_Trunk"
    },
    {
      "x": -1,
      "y": 1,
      "z": -1,
      "name": "Wood_Birch_Trunk"
    },
    {
      "x": -1,
      "y": 2,
      "z": -1,
      "name": "Wood_Birch_Trunk"
    },
    {
      "x": -1,
      "y": 3,
      "z": -1,
      "name": "Wood_Birch_Trunk"
    },
    {
      "x": -1,
      "y": 4,
      "z": -1,
      "name": "Wood_Birch_Trunk"
    },
    {
      "x": -1,
      "y": 5,
      "z": -1,
      "name": "Wood_Birch_Trunk_Full"
    },
    {
      "x": -1,
      "y": 6,
      "z": -1,
      "name": "Wood_Birch_Trunk_Half",
      "rotation": 7
    },
    {
      "x": -1,
      "y": 12,
      "z": -1,
      "name": "Wood_Birch_Trunk_Full"
    },
    {
      "x": -1,
      "y": 13,
      "z": -1,
      "name": "Wood_Birch_Trunk"
    },
    {
      "x": -1,
      "y": 14,
      "z": -1,
      "name": "Wood_Birch_Trunk"
    },
    {
      "x": -1,
      "y": 15,
      "z": -1,
      "name": "Wood_Birch_Trunk"
    },
    {
      "x": -1,
      "y": 16,
      "z": -1,
      "name": "Wood_Birch_Trunk"
    },
    {
      "x": -1,
      "y": 17,
      "z": -1,
      "name": "Wood_Birch_Trunk"
    },
    {
      "x": -1,
      "y": 18,
      "z": -1,
      "name": "Wood_Birch_Trunk"
    },
    {
      "x": -1,
      "y": 19,
      "z": -1,
      "name": "Wood_Birch_Trunk"
    },
    {
      "x": -1,
      "y": 20,
      "z": -1,
      "name": "Wood_Birch_Trunk"
    },
    {
      "x": -1,
      "y": 21,
      "z": -1,
      "name": "Wood_Birch_Trunk_Full"
    },
    {
      "x": -1,
      "y": 22,
      "z": -1,
      "name": "Wood_Birch_Branch_Long"
    },
    {
      "x": -1,
      "y": 23,
      "z": -1,
      "name": "Wood_Birch_Branch_Long"
    },
    {
      "x": -1,
      "y": 24,
      "z": -1,
      "name": "Wood_Birch_Branch_Long"
    },
    {
      "x": -1,
      "y": 25,
      "z": -1,
      "name": "Wood_Birch_Branch_Long"
    },
    {
      "x": -1,
      "y": 26,
      "z": -1,
      "name": "Wood_Birch_Branch_Long"
    },
    {
      "x": -1,
      "y": 27,
      "z": -1,
      "name": "Wood_Birch_Branch_Long"
    },
    {
      "x": -1,
      "y": 28,
      "z": -1,
      "name": "Wood_Birch_Branch_Long"
    },
    {
      "x": -1,
      "y": 29,
      "z": -1,
      "name": "Plant_Leaves_Aspen"
    },
    {
      "x": -1,
      "y": -7,
      "z": 0,
      "name": "Wood_Birch_Trunk"
    },
    {
      "x": -1,
      "y": -6,
      "z": 0,
      "name": "Wood_Birch_Trunk"
    },
    {
      "x": -1,
      "y": -5,
      "z": 0,
      "name": "Wood_Birch_Trunk"
    },
    {
      "x": -1,
      "y": -4,
      "z": 0,
      "name": "Wood_Birch_Trunk_Full"
    },
    {
      "x": -1,
      "y": 0,
      "z": 0,
      "name": "Wood_Birch_Trunk_Full"
    },
    {
      "x": -1,
      "y": 1,
      "z": 0,
      "name": "Wood_Birch_Trunk"
    },
    {
      "x": -1,
      "y": 2,
      "z": 0,
      "name": "Wood_Birch_Trunk_Full"
    },
    {
      "x": -1,
      "y": 3,
      "z": 0,
      "name": "Wood_Birch_Trunk_Half",
      "rotation": 7
    },
    {
      "x": -1,
      "y": 4,
      "z": 0,
      "name": "Wood_Birch_Trunk_Half",
      "rotation": 7
    },
    {
      "x": -1,
      "y": 13,
      "z": 0,
      "name": "Wood_Birch_Trunk_Full"
    },
    {
      "x": -1,
      "y": 14,
      "z": 0,
      "name": "Wood_Birch_Trunk"
    },
    {
      "x": -1,
      "y": 15,
      "z": 0,
      "name": "Wood_Birch_Trunk"
    },
    {
      "x": -1,
      "y": 16,
      "z": 0,
      "name": "Wood_Birch_Trunk"
    },
    {
      "x": -1,
      "y": 17,
      "z": 0,
      "name": "Wood_Birch_Trunk"
    },
    {
      "x": -1,
      "y": 18,
      "z": 0,
      "name": "Wood_Birch_Trunk_Full"
    },
    {
      "x": -1,
      "y": 24,
      "z": 0,
      "name": "Plant_Leaves_Aspen"
    },
    {
      "x": -1,
      "y": 25,
      "z": 0,
      "name": "Plant_Leaves_Aspen"
    },
    {
      "x": -1,
      "y": 28,
      "z": 0,
      "name": "Plant_Leaves_Aspen"
    },
    {
      "x": -1,
      "y": 29,
      "z": 0,
      "name": "Plant_Leaves_Aspen"
    },
    {
      "x": -1,
      "y": -1,
      "z": 1,
      "name": "Wood_Birch_Trunk_Full"
    },
    {
      "x": -1,
      "y": 0,
      "z": 1,
      "name": "Wood_Birch_Trunk"
    },
    {
      "x": -1,
      "y": 1,
      "z": 1,
      "name": "Wood_Birch_Trunk_Full"
    },
    {
      "x": -1,
      "y": 15,
      "z": 1,
      "name": "Wood_Birch_Trunk_Full"
    },
    {
      "x": -1,
      "y": 16,
      "z": 1,
      "name": "Wood_Birch_Trunk_Full"
    },
    {
      "x": -1,
      "y": 22,
      "z": 1,
      "name": "Plant_Leaves_Aspen"
    },
    {
      "x": -1,
      "y": 24,
      "z": 1,
      "name": "Plant_Leaves_Aspen"
    },
    {
      "x": -1,
      "y": 28,
      "z": 1,
      "name": "Plant_Leaves_Aspen"
    },
    {
      "x": -1,
      "y": -2,
      "z": 2,
      "name": "Wood_Birch_Trunk_Full"
    },
    {
      "x": -1,
      "y": -1,
      "z": 2,
      "name": "Wood_Birch_Trunk_Full"
    },
    {
      "x": -1,
      "y": 22,
      "z": 2,
      "name": "Plant_Leaves_Aspen"
    },
    {
      "x": -1,
      "y": 24,
      "z": 2,
      "name": "Plant_Leaves_Aspen"
    },
    {
      "x": -1,
      "y": 28,
      "z": 2,
      "name": "Plant_Leaves_Aspen"
    },
    {
      "x": -1,
      "y": -8,
      "z": 3,
      "name": "Wood_Birch_Branch_Corner",
      "rotation": 2
    },
    {
      "x": -1,
      "y": -7,
      "z": 3,
      "name": "Wood_Birch_Branch_Long"
    },
    {
      "x": -1,
      "y": -6,
      "z": 3,
      "name": "Wood_Birch_Branch_Long"
    },
    {
      "x": -1,
      "y": -5,
      "z": 3,
      "name": "Wood_Birch_Branch_Long"
    },
    {
      "x": -1,
      "y": -4,
      "z": 3,
      "name": "Wood_Birch_Trunk_Full"
    },
    {
      "x": -1,
      "y": -3,
      "z": 3,
      "name": "Wood_Birch_Trunk"
    },
    {
      "x": -1,
      "y": -2,
      "z": 3,
      "name": "Wood_Birch_Trunk_Full"
    },
    {
      "x": -1,
      "y": 19,
      "z": 3,
      "name": "Plant_Leaves_Aspen"
    },
    {
      "x": -1,
      "y": 22,
      "z": 3,
      "name": "Plant_Leaves_Aspen"
    },
    {
      "x": -1,
      "y": 23,
      "z": 3,
      "name": "Plant_Leaves_Aspen"
    },
    {
      "x": -1,
      "y": 24,
      "z": 3,
      "name": "Plant_Leaves_Aspen"
    },
    {
      "x": -1,
      "y": -8,
      "z": 4,
      "name": "Wood_Birch_Branch_Long",
      "rotation": 4
    },
    {
      "x": -1,
      "y": -6,
      "z": 4,
      "name": "Wood_Birch_Branch_Corner",
      "rotation": 8
    },
    {
      "x": -1,
      "y": 18,
      "z": 4,
      "name": "Wood_Birch_Trunk_Full"
    },
    {
      "x": -1,
      "y": 19,
      "z": 4,
      "name": "Wood_Birch_Trunk_Full"
    },
    {
      "x": -1,
      "y": 20,
      "z": 4,
      "name": "Wood_Birch_Branch_Long"
    },
    {
      "x": -1,
      "y": 21,
      "z": 4,
      "name": "Wood_Birch_Branch_Long"
    },
    {
      "x": -1,
      "y": 22,
      "z": 4,
      "name": "Wood_Birch_Branch_Long"
    },
    {
      "x": -1,
      "y": 23,
      "z": 4,
      "name": "Plant_Leaves_Aspen"
    },
    {
      "x": -1,
      "y": 24,
      "z": 4,
      "name": "Plant_Leaves_Aspen"
    },
    {
      "x": -1,
      "y": -8,
      "z": 5,
      "name": "Wood_Birch_Branch_Corner"
    },
    {
      "x": -1,
      "y": -7,
      "z": 5,
      "name": "Wood_Birch_Branch_Long"
    },
    {
      "x": -1,
      "y": -6,
      "z": 5,
      "name": "Wood_Birch_Branch_Corner",
      "rotation": 10
    },
    {
      "x": -1,
      "y": 19,
      "z": 5,
      "name": "Plant_Leaves_Aspen"
    },
    {
      "x": -1,
      "y": 22,
      "z": 5,
      "name": "Plant_Leaves_Aspen"
    },
    {
      "x": -1,
      "y": 23,
      "z": 5,
      "name": "Plant_Leaves_Aspen"
    },
    {
      "x": -1,
      "y": 22,
      "z": 6,
      "name": "Plant_Leaves_Aspen"
    },
    {
      "x": 0,
      "y": 16,
      "z": -7,
      "name": "Plant_Leaves_Aspen"
    },
    {
      "x": 0,
      "y": 16,
      "z": -6,
      "name": "Plant_Leaves_Aspen"
    },
    {
      "x": 0,
      "y": 16,
      "z": -5,
      "name": "Plant_Leaves_Aspen"
    },
    {
      "x": 0,
      "y": 24,
      "z": -5,
      "name": "Plant_Leaves_Aspen"
    },
    {
      "x": 0,
      "y": 16,
      "z": -4,
      "name": "Plant_Leaves_Aspen"
    },
    {
      "x": 0,
      "y": 24,
      "z": -4,
      "name": "Plant_Leaves_Aspen"
    },
    {
      "x": 0,
      "y": 28,
      "z": -4,
      "name": "Plant_Leaves_Aspen"
    },
    {
      "x": 0,
      "y": 16,
      "z": -3,
      "name": "Plant_Leaves_Aspen"
    },
    {
      "x": 0,
      "y": 24,
      "z": -3,
      "name": "Plant_Leaves_Aspen"
    },
    {
      "x": 0,
      "y": 28,
      "z": -3,
      "name": "Plant_Leaves_Aspen"
    },
    {
      "x": 0,
      "y": 3,
      "z": -2,
      "name": "Wood_Birch_Trunk_Full"
    },
    {
      "x": 0,
      "y": 4,
      "z": -2,
      "name": "Wood_Birch_Trunk"
    },
    {
      "x": 0,
      "y": 5,
      "z": -2,
      "name": "Wood_Birch_Trunk"
    },
    {
      "x": 0,
      "y": 6,
      "z": -2,
      "name": "Wood_Birch_Trunk_Full"
    },
    {
      "x": 0,
      "y": 7,
      "z": -2,
      "name": "Wood_Birch_Trunk_Half",
      "rotation": 7
    },
    {
      "x": 0,
      "y": 8,
      "z": -2,
      "name": "Wood_Birch_Branch_Long",
      "rotation": 5
    },
    {
      "x": 0,
      "y": 11,
      "z": -2,
      "name": "Wood_Birch_Trunk_Full"
    },
    {
      "x": 0,
      "y": 12,
      "z": -2,
      "name": "Wood_Birch_Trunk_Full"
    },
    {
      "x": 0,
      "y": 16,
      "z": -2,
      "name": "Plant_Leaves_Aspen"
    },
    {
      "x": 0,
      "y": 24,
      "z": -2,
      "name": "Plant_Leaves_Aspen"
    },
    {
      "x": 0,
      "y": 25,
      "z": -2,
      "name": "Plant_Leaves_Aspen"
    },
    {
      "x": 0,
      "y": 28,
      "z": -2,
      "name": "Plant_Leaves_Aspen"
    },
    {
      "x": 0,
      "y": -7,
      "z": -1,
      "name": "Wood_Birch_Trunk_Full"
    },
    {
      "x": 0,
      "y": -6,
      "z": -1,
      "name": "Wood_Birch_Trunk"
    },
    {
      "x": 0,
      "y": -5,
      "z": -1,
      "name": "Wood_Birch_Trunk"
    },
    {
      "x": 0,
      "y": -4,
      "z": -1,
      "name": "Wood_Birch_Trunk_Full"
    },
    {
      "x": 0,
      "y": -1,
      "z": -1,
      "name": "Wood_Birch_Trunk_Full"
    },
    {
      "x": 0,
      "y": 0,
      "z": -1,
      "name": "Wood_Birch_Trunk"
    },
    {
      "x": 0,
      "y": 1,
      "z": -1,
      "name": "Wood_Birch_Trunk"
    },
    {
      "x": 0,
      "y": 2,
      "z": -1,
      "name": "Wood_Birch_Trunk"
    },
    {
      "x": 0,
      "y": 3,
      "z": -1,
      "name": "Wood_Birch_Trunk"
    },
    {
      "x": 0,
      "y": 4,
      "z": -1,
      "name": "Wood_Birch_Trunk"
    },
    {
      "x": 0,
      "y": 5,
      "z": -1,
      "name": "Wood_Birch_Trunk"
    },
    {
      "x": 0,
      "y": 6,
      "z": -1,
      "name": "Wood_Birch_Trunk"
    },
    {
      "x": 0,
      "y": 7,
      "z": -1,
      "name": "Wood_Birch_Trunk_Full"
    },
    {
      "x": 0,
      "y": 8,
      "z": -1,
      "name": "Wood_Birch_Trunk_Full"
    },
    {
      "x": 0,
      "y": 10,
      "z": -1,
      "name": "Wood_Birch_Trunk_Full"
    },
    {
      "x": 0,
      "y": 11,
      "z": -1,
      "name": "Wood_Birch_Trunk"
    },
    {
      "x": 0,
      "y": 12,
      "z": -1,
      "name": "Wood_Birch_Trunk"
    },
    {
      "x": 0,
      "y": 13,
      "z": -1,
      "name": "Wood_Birch_Trunk_Full"
    },
    {
      "x": 0,
      "y": 16,
      "z": -1,
      "name": "Plant_Leaves_Aspen"
    },
    {
      "x": 0,
      "y": 19,
      "z": -1,
      "name": "Wood_Birch_Branch_Corner",
      "rotation": 1
    },
    {
      "x": 0,
      "y": 20,
      "z": -1,
      "name": "Wood_Birch_Branch_Long"
    },
    {
      "x": 0,
      "y": 21,
      "z": -1,
      "name": "Wood_Birch_Branch_Long"
    },
    {
      "x": 0,
      "y": 22,
      "z": -1,
      "name": "Wood_Birch_Branch_Long"
    },
    {
      "x": 0,
      "y": 23,
      "z": -1,
      "name": "Wood_Birch_Branch_Long"
    },
    {
      "x": 0,
      "y": 24,
      "z": -1,
      "name": "Wood_Birch_Branch_Long"
    },
    {
      "x": 0,
      "y": 25,
      "z": -1,
      "name": "Plant_Leaves_Aspen"
    },
    {
      "x": 0,
      "y": 28,
      "z": -1,
      "name": "Plant_Leaves_Aspen"
    },
    {
      "x": 0,
      "y": 29,
      "z": -1,
      "name": "Plant_Leaves_Aspen"
    },
    {
      "x": 0,
      "y": -7,
      "z": 0,
      "name": "Wood_Birch_Trunk_Full"
    },
    {
      "x": 0,
      "y": -6,
      "z": 0,
      "name": "Wood_Birch_Trunk_Full"
    },
    {
      "x": 0,
      "y": 0,
      "z": 0,
      "name": "Wood_Birch_Trunk_Full"
    },
    {
      "x": 0,
      "y": 1,
      "z": 0,
      "name": "Wood_Birch_Trunk"
    },
    {
      "x": 0,
      "y": 2,
      "z": 0,
      "name": "Wood_Birch_Trunk"
    },
    {
      "x": 0,
      "y": 3,
      "z": 0,
      "name": "Wood_Birch_Trunk"
    },
    {
      "x": 0,
      "y": 4,
      "z": 0,
      "name": "Wood_Birch_Trunk_Full"
    },
    {
      "x": 0,
      "y": 5,
      "z": 0,
      "name": "Wood_Birch_Trunk_Half",
      "rotation": 7
    },
    {
      "x": 0,
      "y": 16,
      "z": 0,
      "name": "Plant_Leaves_Aspen"
    },
    {
      "x": 0,
      "y": 24,
      "z": 0,
      "name": "Plant_Leaves_Aspen"
    },
    {
      "x": 0,
      "y": 25,
      "z": 0,
      "name": "Plant_Leaves_Aspen"
    },
    {
      "x": 0,
      "y": 28,
      "z": 0,
      "name": "Plant_Leaves_Aspen"
    },
    {
      "x": 0,
      "y": -1,
      "z": 1,
      "name": "Wood_Birch_Trunk_Full"
    },
    {
      "x": 0,
      "y": 0,
      "z": 1,
      "name": "Wood_Birch_Trunk"
    },
    {
      "x": 0,
      "y": 1,
      "z": 1,
      "name": "Wood_Birch_Trunk"
    },
    {
      "x": 0,
      "y": 2,
      "z": 1,
      "name": "Wood_Birch_Trunk_Full"
    },
    {
      "x": 0,
      "y": 3,
      "z": 1,
      "name": "Wood_Birch_Trunk_Stairs"
    },
    {
      "x": 0,
      "y": 16,
      "z": 1,
      "name": "Plant_Leaves_Aspen"
    },
    {
      "x": 0,
      "y": 22,
      "z": 1,
      "name": "Plant_Leaves_Aspen"
    },
    {
      "x": 0,
      "y": 24,
      "z": 1,
      "name": "Plant_Leaves_Aspen"
    },
    {
      "x": 0,
      "y": 28,
      "z": 1,
      "name": "Plant_Leaves_Aspen"
    },
    {
      "x": 0,
      "y": 22,
      "z": 2,
      "name": "Plant_Leaves_Aspen"
    },
    {
      "x": 0,
      "y": 24,
      "z": 2,
      "name": "Plant_Leaves_Aspen"
    },
    {
      "x": 0,
      "y": 28,
      "z": 2,
      "name": "Plant_Leaves_Aspen"
    },
    {
      "x": 0,
      "y": 19,
      "z": 3,
      "name": "Plant_Leaves_Aspen"
    },
    {
      "x": 0,
      "y": 22,
      "z": 3,
      "name": "Plant_Leaves_Aspen"
    },
    {
      "x": 0,
      "y": 24,
      "z": 3,
      "name": "Plant_Leaves_Aspen"
    },
    {
      "x": 0,
      "y": 19,
      "z": 4,
      "name": "Plant_Leaves_Aspen"
    },
    {
      "x": 0,
      "y": 22,
      "z": 4,
      "name": "Plant_Leaves_Aspen"
    },
    {
      "x": 0,
      "y": 23,
      "z": 4,
      "name": "Plant_Leaves_Aspen"
    },
    {
      "x": 0,
      "y": 24,
      "z": 4,
      "name": "Plant_Leaves_Aspen"
    },
    {
      "x": 0,
      "y": 19,
      "z": 5,
      "name": "Plant_Leaves_Aspen"
    },
    {
      "x": 0,
      "y": 22,
      "z": 5,
      "name": "Plant_Leaves_Aspen"
    },
    {
      "x": 0,
      "y": 22,
      "z": 6,
      "name": "Plant_Leaves_Aspen"
    },
    {
      "x": 1,
      "y": 16,
      "z": -7,
      "name": "Plant_Leaves_Aspen"
    },
    {
      "x": 1,
      "y": 16,
      "z": -6,
      "name": "Plant_Leaves_Aspen"
    },
    {
      "x": 1,
      "y": 16,
      "z": -5,
      "name": "Plant_Leaves_Aspen"
    },
    {
      "x": 1,
      "y": 24,
      "z": -5,
      "name": "Plant_Leaves_Aspen"
    },
    {
      "x": 1,
      "y": 16,
      "z": -4,
      "name": "Plant_Leaves_Aspen"
    },
    {
      "x": 1,
      "y": 17,
      "z": -4,
      "name": "Plant_Leaves_Aspen"
    },
    {
      "x": 1,
      "y": 24,
      "z": -4,
      "name": "Plant_Leaves_Aspen"
    },
    {
      "x": 1,
      "y": -5,
      "z": -3,
      "name": "Wood_Birch_Branch_Corner",
      "rotation": 2
    },
    {
      "x": 1,
      "y": -4,
      "z": -3,
      "name": "Wood_Birch_Branch_Corner",
      "rotation": 9
    },
    {
      "x": 1,
      "y": 14,
      "z": -3,
      "name": "Wood_Birch_Branch_Corner",
      "rotation": 2
    },
    {
      "x": 1,
      "y": 15,
      "z": -3,
      "name": "Wood_Birch_Branch_Corner",
      "rotation": 9
    },
    {
      "x": 1,
      "y": 16,
      "z": -3,
      "name": "Plant_Leaves_Aspen"
    },
    {
      "x": 1,
      "y": 17,
      "z": -3,
      "name": "Plant_Leaves_Aspen"
    },
    {
      "x": 1,
      "y": 24,
      "z": -3,
      "name": "Plant_Leaves_Aspen"
    },
    {
      "x": 1,
      "y": 25,
      "z": -3,
      "name": "Plant_Leaves_Aspen"
    },
    {
      "x": 1,
      "y": 28,
      "z": -3,
      "name": "Plant_Leaves_Aspen"
    },
    {
      "x": 1,
      "y": -5,
      "z": -2,
      "name": "Wood_Birch_Branch_Long",
      "rotation": 4
    },
    {
      "x": 1,
      "y": 4,
      "z": -2,
      "name": "Wood_Birch_Trunk_Half",
      "rotation": 5
    },
    {
      "x": 1,
      "y": 5,
      "z": -2,
      "name": "Wood_Birch_Trunk_Half",
      "rotation": 5
    },
    {
      "x": 1,
      "y": 6,
      "z": -2,
      "name": "Wood_Birch_Trunk_Full"
    },
    {
      "x": 1,
      "y": 7,
      "z": -2,
      "name": "Wood_Birch_Trunk"
    },
    {
      "x": 1,
      "y": 8,
      "z": -2,
      "name": "Wood_Birch_Trunk"
    },
    {
      "x": 1,
      "y": 9,
      "z": -2,
      "name": "Wood_Birch_Trunk"
    },
    {
      "x": 1,
      "y": 10,
      "z": -2,
      "name": "Wood_Birch_Trunk_Full"
    },
    {
      "x": 1,
      "y": 11,
      "z": -2,
      "name": "Wood_Birch_Branch_Long"
    },
    {
      "x": 1,
      "y": 12,
      "z": -2,
      "name": "Wood_Birch_Branch_Long"
    },
    {
      "x": 1,
      "y": 13,
      "z": -2,
      "name": "Wood_Birch_Branch_Long"
    },
    {
      "x": 1,
      "y": 14,
      "z": -2,
      "name": "Wood_Birch_Branch_Corner",
      "rotation": 10
    },
    {
      "x": 1,
      "y": 16,
      "z": -2,
      "name": "Plant_Leaves_Aspen"
    },
    {
      "x": 1,
      "y": 17,
      "z": -2,
      "name": "Plant_Leaves_Aspen"
    },
    {
      "x": 1,
      "y": 24,
      "z": -2,
      "name": "Plant_Leaves_Aspen"
    },
    {
      "x": 1,
      "y": 25,
      "z": -2,
      "name": "Plant_Leaves_Aspen"
    },
    {
      "x": 1,
      "y": 28,
      "z": -2,
      "name": "Plant_Leaves_Aspen"
    },
    {
      "x": 1,
      "y": -5,
      "z": -1,
      "name": "Wood_Birch_Branch_Corner"
    },
    {
      "x": 1,
      "y": -4,
      "z": -1,
      "name": "Wood_Birch_Branch_Long"
    },
    {
      "x": 1,
      "y": -3,
      "z": -1,
      "name": "Wood_Birch_Branch_Long"
    },
    {
      "x": 1,
      "y": -2,
      "z": -1,
      "name": "Wood_Birch_Trunk_Full"
    },
    {
      "x": 1,
      "y": -1,
      "z": -1,
      "name": "Wood_Birch_Trunk_Full"
    },
    {
      "x": 1,
      "y": 2,
      "z": -1,
      "name": "Wood_Birch_Trunk_Full"
    },
    {
      "x": 1,
      "y": 3,
      "z": -1,
      "name": "Wood_Birch_Trunk"
    },
    {
      "x": 1,
      "y": 4,
      "z": -1,
      "name": "Wood_Birch_Trunk"
    },
    {
      "x": 1,
      "y": 5,
      "z": -1,
      "name": "Wood_Birch_Trunk"
    },
    {
      "x": 1,
      "y": 6,
      "z": -1,
      "name": "Wood_Birch_Trunk"
    },
    {
      "x": 1,
      "y": 7,
      "z": -1,
      "name": "Wood_Birch_Trunk"
    },
    {
      "x": 1,
      "y": 8,
      "z": -1,
      "name": "Wood_Birch_Trunk"
    },
    {
      "x": 1,
      "y": 9,
      "z": -1,
      "name": "Wood_Birch_Trunk"
    },
    {
      "x": 1,
      "y": 10,
      "z": -1,
      "name": "Wood_Birch_Trunk"
    },
    {
      "x": 1,
      "y": 11,
      "z": -1,
      "name": "Wood_Birch_Trunk_Full"
    },
    {
      "x": 1,
      "y": 16,
      "z": -1,
      "name": "Plant_Leaves_Aspen"
    },
    {
      "x": 1,
      "y": 24,
      "z": -1,
      "name": "Plant_Leaves_Aspen"
    },
    {
      "x": 1,
      "y": 25,
      "z": -1,
      "name": "Plant_Leaves_Aspen"
    },
    {
      "x": 1,
      "y": 28,
      "z": -1,
      "name": "Plant_Leaves_Aspen"
    },
    {
      "x": 1,
      "y": -1,
      "z": 0,
      "name": "Wood_Birch_Trunk_Full"
    },
    {
      "x": 1,
      "y": 0,
      "z": 0,
      "name": "Wood_Birch_Trunk"
    },
    {
      "x": 1,
      "y": 1,
      "z": 0,
      "name": "Wood_Birch_Trunk"
    },
    {
      "x": 1,
      "y": 2,
      "z": 0,
      "name": "Wood_Birch_Trunk"
    },
    {
      "x": 1,
      "y": 3,
      "z": 0,
      "name": "Wood_Birch_Trunk"
    },
    {
      "x": 1,
      "y": 4,
      "z": 0,
      "name": "Wood_Birch_Trunk"
    },
    {
      "x": 1,
      "y": 5,
      "z": 0,
      "name": "Wood_Birch_Trunk"
    },
    {
      "x": 1,
      "y": 6,
      "z": 0,
      "name": "Wood_Birch_Trunk_Full"
    },
    {
      "x": 1,
      "y": 7,
      "z": 0,
      "name": "Wood_Birch_Trunk_Half",
      "rotation": 7
    },
    {
      "x": 1,
      "y": 16,
      "z": 0,
      "name": "Plant_Leaves_Aspen"
    },
    {
      "x": 1,
      "y": 21,
      "z": 0,
      "name": "Plant_Leaves_Aspen"
    },
    {
      "x": 1,
      "y": 24,
      "z": 0,
      "name": "Plant_Leaves_Aspen"
    },
    {
      "x": 1,
      "y": 25,
      "z": 0,
      "name": "Plant_Leaves_Aspen"
    },
    {
      "x": 1,
      "y": 28,
      "z": 0,
      "name": "Plant_Leaves_Aspen"
    },
    {
      "x": 1,
      "y": -2,
      "z": 1,
      "name": "Wood_Birch_Trunk_Full"
    },
    {
      "x": 1,
      "y": -1,
      "z": 1,
      "name": "Wood_Birch_Trunk"
    },
    {
      "x": 1,
      "y": 0,
      "z": 1,
      "name": "Wood_Birch_Trunk_Full"
    },
    {
      "x": 1,
      "y": 1,
      "z": 1,
      "name": "Wood_Birch_Trunk_Half",
      "rotation": 4
    },
    {
      "x": 1,
      "y": 2,
      "z": 1,
      "name": "Wood_Birch_Trunk_Half",
      "rotation": 4
    },
    {
      "x": 1,
      "y": 16,
      "z": 1,
      "name": "Plant_Leaves_Aspen"
    },
    {
      "x": 1,
      "y": 21,
      "z": 1,
      "name": "Plant_Leaves_Aspen"
    },
    {
      "x": 1,
      "y": 24,
      "z": 1,
      "name": "Plant_Leaves_Aspen"
    },
    {
      "x": 1,
      "y": 28,
      "z": 1,
      "name": "Plant_Leaves_Aspen"
    },
    {
      "x": 1,
      "y": -1,
      "z": 2,
      "name": "Wood_Birch_Trunk_Full"
    },
    {
      "x": 1,
      "y": 21,
      "z": 2,
      "name": "Plant_Leaves_Aspen"
    },
    {
      "x": 1,
      "y": 22,
      "z": 2,
      "name": "Plant_Leaves_Aspen"
    },
    {
      "x": 1,
      "y": 24,
      "z": 2,
      "name": "Plant_Leaves_Aspen"
    },
    {
      "x": 1,
      "y": 22,
      "z": 3,
      "name": "Plant_Leaves_Aspen"
    },
    {
      "x": 1,
      "y": 24,
      "z": 3,
      "name": "Plant_Leaves_Aspen"
    },
    {
      "x": 1,
      "y": 22,
      "z": 4,
      "name": "Plant_Leaves_Aspen"
    },
    {
      "x": 1,
      "y": 24,
      "z": 4,
      "name": "Plant_Leaves_Aspen"
    },
    {
      "x": 1,
      "y": 22,
      "z": 5,
      "name": "Plant_Leaves_Aspen"
    },
    {
      "x": 1,
      "y": 22,
      "z": 6,
      "name": "Plant_Leaves_Aspen"
    },
    {
      "x": 2,
      "y": 16,
      "z": -7,
      "name": "Plant_Leaves_Aspen"
    },
    {
      "x": 2,
      "y": 16,
      "z": -6,
      "name": "Plant_Leaves_Aspen"
    },
    {
      "x": 2,
      "y": -7,
      "z": -5,
      "name": "Wood_Birch_Branch_Corner",
      "rotation": 2
    },
    {
      "x": 2,
      "y": -6,
      "z": -5,
      "name": "Wood_Birch_Branch_Corner",
      "rotation": 8
    },
    {
      "x": 2,
      "y": 16,
      "z": -5,
      "name": "Plant_Leaves_Aspen"
    },
    {
      "x": 2,
      "y": 24,
      "z": -5,
      "name": "Plant_Leaves_Aspen"
    },
    {
      "x": 2,
      "y": -7,
      "z": -4,
      "name": "Wood_Birch_Branch_Long",
      "rotation": 4
    },
    {
      "x": 2,
      "y": -6,
      "z": -4,
      "name": "Wood_Birch_Branch_Corner",
      "rotation": 10
    },
    {
      "x": 2,
      "y": 16,
      "z": -4,
      "name": "Plant_Leaves_Aspen"
    },
    {
      "x": 2,
      "y": 17,
      "z": -4,
      "name": "Plant_Leaves_Aspen"
    },
    {
      "x": 2,
      "y": 24,
      "z": -4,
      "name": "Plant_Leaves_Aspen"
    },
    {
      "x": 2,
      "y": -7,
      "z": -3,
      "name": "Wood_Birch_Branch_Corner"
    },
    {
      "x": 2,
      "y": -6,
      "z": -3,
      "name": "Wood_Birch_Branch_Long"
    },
    {
      "x": 2,
      "y": -5,
      "z": -3,
      "name": "Wood_Birch_Branch_Long"
    },
    {
      "x": 2,
      "y": -4,
      "z": -3,
      "name": "Wood_Birch_Branch_Corner",
      "rotation": 11
    },
    {
      "x": 2,
      "y": 10,
      "z": -3,
      "name": "Wood_Birch_Branch_Corner",
      "rotation": 8
    },
    {
      "x": 2,
      "y": 15,
      "z": -3,
      "name": "Wood_Birch_Branch_Corner",
      "rotation": 1
    },
    {
      "x": 2,
      "y": 16,
      "z": -3,
      "name": "Wood_Birch_Branch_Long"
    },
    {
      "x": 2,
      "y": 17,
      "z": -3,
      "name": "Plant_Leaves_Aspen"
    },
    {
      "x": 2,
      "y": 24,
      "z": -3,
      "name": "Plant_Leaves_Aspen"
    },
    {
      "x": 2,
      "y": 9,
      "z": -2,
      "name": "Wood_Birch_Branch_Corner",
      "rotation": 2
    },
    {
      "x": 2,
      "y": 10,
      "z": -2,
      "name": "Wood_Birch_Branch_Corner",
      "rotation": 10
    },
    {
      "x": 2,
      "y": 16,
      "z": -2,
      "name": "Plant_Leaves_Aspen"
    },
    {
      "x": 2,
      "y": 17,
      "z": -2,
      "name": "Plant_Leaves_Aspen"
    },
    {
      "x": 2,
      "y": 24,
      "z": -2,
      "name": "Plant_Leaves_Aspen"
    },
    {
      "x": 2,
      "y": 25,
      "z": -2,
      "name": "Plant_Leaves_Aspen"
    },
    {
      "x": 2,
      "y": 28,
      "z": -2,
      "name": "Plant_Leaves_Aspen"
    },
    {
      "x": 2,
      "y": 4,
      "z": -1,
      "name": "Wood_Birch_Trunk_Half",
      "rotation": 5
    },
    {
      "x": 2,
      "y": 5,
      "z": -1,
      "name": "Wood_Birch_Trunk_Full"
    },
    {
      "x": 2,
      "y": 6,
      "z": -1,
      "name": "Wood_Birch_Trunk"
    },
    {
      "x": 2,
      "y": 7,
      "z": -1,
      "name": "Wood_Birch_Trunk"
    },
    {
      "x": 2,
      "y": 8,
      "z": -1,
      "name": "Wood_Birch_Trunk"
    },
    {
      "x": 2,
      "y": 9,
      "z": -1,
      "name": "Wood_Birch_Trunk_Full"
    },
    {
      "x": 2,
      "y": 10,
      "z": -1,
      "name": "Plant_Leaves_Aspen"
    },
    {
      "x": 2,
      "y": 16,
      "z": -1,
      "name": "Plant_Leaves_Aspen"
    },
    {
      "x": 2,
      "y": 21,
      "z": -1,
      "name": "Plant_Leaves_Aspen"
    },
    {
      "x": 2,
      "y": 24,
      "z": -1,
      "name": "Plant_Leaves_Aspen"
    },
    {
      "x": 2,
      "y": 25,
      "z": -1,
      "name": "Plant_Leaves_Aspen"
    },
    {
      "x": 2,
      "y": 28,
      "z": -1,
      "name": "Plant_Leaves_Aspen"
    },
    {
      "x": 2,
      "y": 5,
      "z": 0,
      "name": "Wood_Birch_Trunk_Half",
      "rotation": 5
    },
    {
      "x": 2,
      "y": 6,
      "z": 0,
      "name": "Wood_Birch_Trunk_Half",
      "rotation": 5
    },
    {
      "x": 2,
      "y": 7,
      "z": 0,
      "name": "Wood_Birch_Trunk_Full"
    },
    {
      "x": 2,
      "y": 8,
      "z": 0,
      "name": "Wood_Birch_Trunk"
    },
    {
      "x": 2,
      "y": 9,
      "z": 0,
      "name": "Wood_Birch_Trunk"
    },
    {
      "x": 2,
      "y": 10,
      "z": 0,
      "name": "Wood_Birch_Trunk_Full"
    },
    {
      "x": 2,
      "y": 16,
      "z": 0,
      "name": "Plant_Leaves_Aspen"
    },
    {
      "x": 2,
      "y": 21,
      "z": 0,
      "name": "Plant_Leaves_Aspen"
    },
    {
      "x": 2,
      "y": 24,
      "z": 0,
      "name": "Plant_Leaves_Aspen"
    },
    {
      "x": 2,
      "y": 25,
      "z": 0,
      "name": "Plant_Leaves_Aspen"
    },
    {
      "x": 2,
      "y": 28,
      "z": 0,
      "name": "Plant_Leaves_Aspen"
    },
    {
      "x": 2,
      "y": -7,
      "z": 1,
      "name": "Wood_Birch_Trunk_Full"
    },
    {
      "x": 2,
      "y": -6,
      "z": 1,
      "name": "Wood_Birch_Trunk_Full"
    },
    {
      "x": 2,
      "y": -3,
      "z": 1,
      "name": "Wood_Birch_Trunk_Full"
    },
    {
      "x": 2,
      "y": -2,
      "z": 1,
      "name": "Wood_Birch_Trunk"
    },
    {
      "x": 2,
      "y": -1,
      "z": 1,
      "name": "Wood_Birch_Trunk_Full"
    },
    {
      "x": 2,
      "y": 8,
      "z": 1,
      "name": "Wood_Birch_Trunk_Half",
      "rotation": 4
    },
    {
      "x": 2,
      "y": 9,
      "z": 1,
      "name": "Wood_Birch_Trunk_Half",
      "rotation": 4
    },
    {
      "x": 2,
      "y": 16,
      "z": 1,
      "name": "Plant_Leaves_Aspen"
    },
    {
      "x": 2,
      "y": 21,
      "z": 1,
      "name": "Plant_Leaves_Aspen"
    },
    {
      "x": 2,
      "y": 24,
      "z": 1,
      "name": "Plant_Leaves_Aspen"
    },
    {
      "x": 2,
      "y": -2,
      "z": 2,
      "name": "Wood_Birch_Trunk_Full"
    },
    {
      "x": 2,
      "y": -1,
      "z": 2,
      "name": "Wood_Birch_Trunk_Full"
    },
    {
      "x": 2,
      "y": 21,
      "z": 2,
      "name": "Plant_Leaves_Aspen"
    },
    {
      "x": 2,
      "y": 24,
      "z": 2,
      "name": "Plant_Leaves_Aspen"
    },
    {
      "x": 2,
      "y": 21,
      "z": 3,
      "name": "Plant_Leaves_Aspen"
    },
    {
      "x": 2,
      "y": 22,
      "z": 3,
      "name": "Plant_Leaves_Aspen"
    },
    {
      "x": 2,
      "y": 24,
      "z": 3,
      "name": "Plant_Leaves_Aspen"
    },
    {
      "x": 2,
      "y": 22,
      "z": 4,
      "name": "Plant_Leaves_Aspen"
    },
    {
      "x": 2,
      "y": 24,
      "z": 4,
      "name": "Plant_Leaves_Aspen"
    },
    {
      "x": 2,
      "y": 22,
      "z": 5,
      "name": "Plant_Leaves_Aspen"
    },
    {
      "x": 3,
      "y": 16,
      "z": -7,
      "name": "Plant_Leaves_Aspen"
    },
    {
      "x": 3,
      "y": 16,
      "z": -6,
      "name": "Plant_Leaves_Aspen"
    },
    {
      "x": 3,
      "y": 16,
      "z": -5,
      "name": "Plant_Leaves_Aspen"
    },
    {
      "x": 3,
      "y": 16,
      "z": -4,
      "name": "Plant_Leaves_Aspen"
    },
    {
      "x": 3,
      "y": 17,
      "z": -4,
      "name": "Plant_Leaves_Aspen"
    },
    {
      "x": 3,
      "y": 24,
      "z": -4,
      "name": "Plant_Leaves_Aspen"
    },
    {
      "x": 3,
      "y": 10,
      "z": -3,
      "name": "Plant_Leaves_Aspen"
    },
    {
      "x": 3,
      "y": 16,
      "z": -3,
      "name": "Plant_Leaves_Aspen"
    },
    {
      "x": 3,
      "y": 17,
      "z": -3,
      "name": "Plant_Leaves_Aspen"
    },
    {
      "x": 3,
      "y": 24,
      "z": -3,
      "name": "Plant_Leaves_Aspen"
    },
    {
      "x": 3,
      "y": 10,
      "z": -2,
      "name": "Plant_Leaves_Aspen"
    },
    {
      "x": 3,
      "y": 16,
      "z": -2,
      "name": "Plant_Leaves_Aspen"
    },
    {
      "x": 3,
      "y": 17,
      "z": -2,
      "name": "Plant_Leaves_Aspen"
    },
    {
      "x": 3,
      "y": 21,
      "z": -2,
      "name": "Plant_Leaves_Aspen"
    },
    {
      "x": 3,
      "y": 24,
      "z": -2,
      "name": "Plant_Leaves_Aspen"
    },
    {
      "x": 3,
      "y": 7,
      "z": -1,
      "name": "Wood_Birch_Branch_Long",
      "rotation": 5
    },
    {
      "x": 3,
      "y": 10,
      "z": -1,
      "name": "Plant_Leaves_Aspen"
    },
    {
      "x": 3,
      "y": 16,
      "z": -1,
      "name": "Plant_Leaves_Aspen"
    },
    {
      "x": 3,
      "y": 21,
      "z": -1,
      "name": "Plant_Leaves_Aspen"
    },
    {
      "x": 3,
      "y": 24,
      "z": -1,
      "name": "Plant_Leaves_Aspen"
    },
    {
      "x": 3,
      "y": 9,
      "z": 0,
      "name": "Wood_Birch_Trunk_Full"
    },
    {
      "x": 3,
      "y": 10,
      "z": 0,
      "name": "Wood_Birch_Trunk"
    },
    {
      "x": 3,
      "y": 11,
      "z": 0,
      "name": "Wood_Birch_Trunk"
    },
    {
      "x": 3,
      "y": 12,
      "z": 0,
      "name": "Wood_Birch_Trunk_Full"
    },
    {
      "x": 3,
      "y": 16,
      "z": 0,
      "name": "Plant_Leaves_Aspen"
    },
    {
      "x": 3,
      "y": 18,
      "z": 0,
      "name": "Plant_Leaves_Aspen"
    },
    {
      "x": 3,
      "y": 21,
      "z": 0,
      "name": "Plant_Leaves_Aspen"
    },
    {
      "x": 3,
      "y": 24,
      "z": 0,
      "name": "Plant_Leaves_Aspen"
    },
    {
      "x": 3,
      "y": -8,
      "z": 1,
      "name": "Wood_Birch_Trunk_Full",
      "rotation": 5
    },
    {
      "x": 3,
      "y": -7,
      "z": 1,
      "name": "Wood_Birch_Trunk"
    },
    {
      "x": 3,
      "y": -6,
      "z": 1,
      "name": "Wood_Birch_Trunk"
    },
    {
      "x": 3,
      "y": -5,
      "z": 1,
      "name": "Wood_Birch_Trunk"
    },
    {
      "x": 3,
      "y": -4,
      "z": 1,
      "name": "Wood_Birch_Trunk"
    },
    {
      "x": 3,
      "y": -3,
      "z": 1,
      "name": "Wood_Birch_Trunk"
    },
    {
      "x": 3,
      "y": -2,
      "z": 1,
      "name": "Wood_Birch_Trunk"
    },
    {
      "x": 3,
      "y": -1,
      "z": 1,
      "name": "Wood_Birch_Trunk_Full"
    },
    {
      "x": 3,
      "y": 10,
      "z": 1,
      "name": "Plant_Leaves_Aspen"
    },
    {
      "x": 3,
      "y": 16,
      "z": 1,
      "name": "Plant_Leaves_Aspen"
    },
    {
      "x": 3,
      "y": 17,
      "z": 1,
      "name": "Plant_Leaves_Aspen"
    },
    {
      "x": 3,
      "y": 18,
      "z": 1,
      "name": "Plant_Leaves_Aspen"
    },
    {
      "x": 3,
      "y": 21,
      "z": 1,
      "name": "Plant_Leaves_Aspen"
    },
    {
      "x": 3,
      "y": 22,
      "z": 1,
      "name": "Plant_Leaves_Aspen"
    },
    {
      "x": 3,
      "y": 24,
      "z": 1,
      "name": "Plant_Leaves_Aspen"
    },
    {
      "x": 3,
      "y": -6,
      "z": 2,
      "name": "Wood_Birch_Trunk_Full"
    },
    {
      "x": 3,
      "y": -5,
      "z": 2,
      "name": "Wood_Birch_Trunk_Full"
    },
    {
      "x": 3,
      "y": -3,
      "z": 2,
      "name": "Wood_Birch_Trunk_Full"
    },
    {
      "x": 3,
      "y": -2,
      "z": 2,
      "name": "Wood_Birch_Trunk_Full"
    },
    {
      "x": 3,
      "y": 17,
      "z": 2,
      "name": "Plant_Leaves_Aspen"
    },
    {
      "x": 3,
      "y": 19,
      "z": 2,
      "name": "Plant_Leaves_Aspen"
    },
    {
      "x": 3,
      "y": 21,
      "z": 2,
      "name": "Plant_Leaves_Aspen"
    },
    {
      "x": 3,
      "y": 24,
      "z": 2,
      "name": "Plant_Leaves_Aspen"
    },
    {
      "x": 3,
      "y": 21,
      "z": 3,
      "name": "Plant_Leaves_Aspen"
    },
    {
      "x": 3,
      "y": 24,
      "z": 3,
      "name": "Plant_Leaves_Aspen"
    },
    {
      "x": 3,
      "y": 21,
      "z": 4,
      "name": "Plant_Leaves_Aspen"
    },
    {
      "x": 4,
      "y": 16,
      "z": -7,
      "name": "Plant_Leaves_Aspen"
    },
    {
      "x": 4,
      "y": 16,
      "z": -6,
      "name": "Plant_Leaves_Aspen"
    },
    {
      "x": 4,
      "y": 16,
      "z": -5,
      "name": "Plant_Leaves_Aspen"
    },
    {
      "x": 4,
      "y": 10,
      "z": -4,
      "name": "Plant_Leaves_Aspen"
    },
    {
      "x": 4,
      "y": 16,
      "z": -4,
      "name": "Plant_Leaves_Aspen"
    },
    {
      "x": 4,
      "y": 10,
      "z": -3,
      "name": "Plant_Leaves_Aspen"
    },
    {
      "x": 4,
      "y": 16,
      "z": -3,
      "name": "Plant_Leaves_Aspen"
    },
    {
      "x": 4,
      "y": 24,
      "z": -3,
      "name": "Plant_Leaves_Aspen"
    },
    {
      "x": 4,
      "y": 10,
      "z": -2,
      "name": "Plant_Leaves_Aspen"
    },
    {
      "x": 4,
      "y": 16,
      "z": -2,
      "name": "Plant_Leaves_Aspen"
    },
    {
      "x": 4,
      "y": 21,
      "z": -2,
      "name": "Plant_Leaves_Aspen"
    },
    {
      "x": 4,
      "y": 24,
      "z": -2,
      "name": "Plant_Leaves_Aspen"
    },
    {
      "x": 4,
      "y": -7,
      "z": -1,
      "name": "Wood_Birch_Branch_Corner"
    },
    {
      "x": 4,
      "y": -6,
      "z": -1,
      "name": "Wood_Birch_Branch_Long"
    },
    {
      "x": 4,
      "y": -5,
      "z": -1,
      "name": "Wood_Birch_Branch_Long"
    },
    {
      "x": 4,
      "y": -4,
      "z": -1,
      "name": "Wood_Birch_Branch_Corner",
      "rotation": 8
    },
    {
      "x": 4,
      "y": 7,
      "z": -1,
      "name": "Wood_Birch_Branch_Corner",
      "rotation": 1
    },
    {
      "x": 4,
      "y": 8,
      "z": -1,
      "name": "Wood_Birch_Branch_Corner",
      "rotation": 9
    },
    {
      "x": 4,
      "y": 10,
      "z": -1,
      "name": "Plant_Leaves_Aspen"
    },
    {
      "x": 4,
      "y": 11,
      "z": -1,
      "name": "Plant_Leaves_Aspen"
    },
    {
      "x": 4,
      "y": 16,
      "z": -1,
      "name": "Plant_Leaves_Aspen"
    },
    {
      "x": 4,
      "y": 18,
      "z": -1,
      "name": "Wood_Birch_Branch_Corner",
      "rotation": 2
    },
    {
      "x": 4,
      "y": 19,
      "z": -1,
      "name": "Wood_Birch_Branch_Long"
    },
    {
      "x": 4,
      "y": 20,
      "z": -1,
      "name": "Wood_Birch_Branch_Long"
    },
    {
      "x": 4,
      "y": 21,
      "z": -1,
      "name": "Plant_Leaves_Aspen"
    },
    {
      "x": 4,
      "y": 24,
      "z": -1,
      "name": "Plant_Leaves_Aspen"
    },
    {
      "x": 4,
      "y": -4,
      "z": 0,
      "name": "Wood_Birch_Branch_Long",
      "rotation": 4
    },
    {
      "x": 4,
      "y": 10,
      "z": 0,
      "name": "Plant_Leaves_Aspen"
    },
    {
      "x": 4,
      "y": 12,
      "z": 0,
      "name": "Wood_Birch_Trunk_Full"
    },
    {
      "x": 4,
      "y": 13,
      "z": 0,
      "name": "Wood_Birch_Trunk"
    },
    {
      "x": 4,
      "y": 14,
      "z": 0,
      "name": "Wood_Birch_Trunk_Full"
    },
    {
      "x": 4,
      "y": 16,
      "z": 0,
      "name": "Plant_Leaves_Aspen"
    },
    {
      "x": 4,
      "y": 18,
      "z": 0,
      "name": "Wood_Birch_Branch_Long",
      "rotation": 4
    },
    {
      "x": 4,
      "y": 19,
      "z": 0,
      "name": "Plant_Leaves_Aspen"
    },
    {
      "x": 4,
      "y": 21,
      "z": 0,
      "name": "Plant_Leaves_Aspen"
    },
    {
      "x": 4,
      "y": 22,
      "z": 0,
      "name": "Plant_Leaves_Aspen"
    },
    {
      "x": 4,
      "y": 24,
      "z": 0,
      "name": "Plant_Leaves_Aspen"
    },
    {
      "x": 4,
      "y": -8,
      "z": 1,
      "name": "Wood_Birch_Trunk_Full",
      "rotation": 5
    },
    {
      "x": 4,
      "y": -5,
      "z": 1,
      "name": "Wood_Birch_Trunk_Full"
    },
    {
      "x": 4,
      "y": -4,
      "z": 1,
      "name": "Wood_Birch_Trunk"
    },
    {
      "x": 4,
      "y": -3,
      "z": 1,
      "name": "Wood_Birch_Trunk_Full"
    },
    {
      "x": 4,
      "y": 10,
      "z": 1,
      "name": "Plant_Leaves_Aspen"
    },
    {
      "x": 4,
      "y": 14,
      "z": 1,
      "name": "Wood_Birch_Trunk_Full"
    },
    {
      "x": 4,
      "y": 15,
      "z": 1,
      "name": "Wood_Birch_Trunk"
    },
    {
      "x": 4,
      "y": 16,
      "z": 1,
      "name": "Wood_Birch_Trunk_Full"
    },
    {
      "x": 4,
      "y": 17,
      "z": 1,
      "name": "Wood_Birch_Branch_Long"
    },
    {
      "x": 4,
      "y": 18,
      "z": 1,
      "name": "Wood_Birch_Branch_Long"
    },
    {
      "x": 4,
      "y": 19,
      "z": 1,
      "name": "Wood_Birch_Branch_Long"
    },
    {
      "x": 4,
      "y": 20,
      "z": 1,
      "name": "Wood_Birch_Branch_Long"
    },
    {
      "x": 4,
      "y": 21,
      "z": 1,
      "name": "Wood_Birch_Branch_Long"
    },
    {
      "x": 4,
      "y": 22,
      "z": 1,
      "name": "Plant_Leaves_Aspen"
    },
    {
      "x": 4,
      "y": 24,
      "z": 1,
      "name": "Plant_Leaves_Aspen"
    },
    {
      "x": 4,
      "y": 10,
      "z": 2,
      "name": "Plant_Leaves_Aspen"
    },
    {
      "x": 4,
      "y": 14,
      "z": 2,
      "name": "Wood_Birch_Branch_Long",
      "rotation": 4
    },
    {
      "x": 4,
      "y": 17,
      "z": 2,
      "name": "Plant_Leaves_Aspen"
    },
    {
      "x": 4,
      "y": 19,
      "z": 2,
      "name": "Plant_Leaves_Aspen"
    },
    {
      "x": 4,
      "y": 21,
      "z": 2,
      "name": "Plant_Leaves_Aspen"
    },
    {
      "x": 4,
      "y": 22,
      "z": 2,
      "name": "Plant_Leaves_Aspen"
    },
    {
      "x": 4,
      "y": 24,
      "z": 2,
      "name": "Plant_Leaves_Aspen"
    },
    {
      "x": 4,
      "y": 13,
      "z": 3,
      "name": "Wood_Birch_Branch_Corner"
    },
    {
      "x": 4,
      "y": 14,
      "z": 3,
      "name": "Wood_Birch_Branch_Corner",
      "rotation": 10
    },
    {
      "x": 4,
      "y": 19,
      "z": 3,
      "name": "Plant_Leaves_Aspen"
    },
    {
      "x": 4,
      "y": 21,
      "z": 3,
      "name": "Plant_Leaves_Aspen"
    },
    {
      "x": 4,
      "y": 19,
      "z": 4,
      "name": "Plant_Leaves_Aspen"
    },
    {
      "x": 4,
      "y": 21,
      "z": 4,
      "name": "Plant_Leaves_Aspen"
    },
    {
      "x": 5,
      "y": 16,
      "z": -6,
      "name": "Plant_Leaves_Aspen"
    },
    {
      "x": 5,
      "y": 16,
      "z": -5,
      "name": "Plant_Leaves_Aspen"
    },
    {
      "x": 5,
      "y": 10,
      "z": -4,
      "name": "Plant_Leaves_Aspen"
    },
    {
      "x": 5,
      "y": 16,
      "z": -4,
      "name": "Plant_Leaves_Aspen"
    },
    {
      "x": 5,
      "y": 10,
      "z": -3,
      "name": "Plant_Leaves_Aspen"
    },
    {
      "x": 5,
      "y": 16,
      "z": -3,
      "name": "Plant_Leaves_Aspen"
    },
    {
      "x": 5,
      "y": 10,
      "z": -2,
      "name": "Plant_Leaves_Aspen"
    },
    {
      "x": 5,
      "y": 11,
      "z": -2,
      "name": "Plant_Leaves_Aspen"
    },
    {
      "x": 5,
      "y": 16,
      "z": -2,
      "name": "Plant_Leaves_Aspen"
    },
    {
      "x": 5,
      "y": 21,
      "z": -2,
      "name": "Plant_Leaves_Aspen"
    },
    {
      "x": 5,
      "y": 24,
      "z": -2,
      "name": "Plant_Leaves_Aspen"
    },
    {
      "x": 5,
      "y": 8,
      "z": -1,
      "name": "Wood_Birch_Branch_Corner",
      "rotation": 1
    },
    {
      "x": 5,
      "y": 9,
      "z": -1,
      "name": "Wood_Birch_Branch_Long"
    },
    {
      "x": 5,
      "y": 10,
      "z": -1,
      "name": "Wood_Birch_Branch_Long"
    },
    {
      "x": 5,
      "y": 11,
      "z": -1,
      "name": "Plant_Leaves_Aspen"
    },
    {
      "x": 5,
      "y": 16,
      "z": -1,
      "name": "Plant_Leaves_Aspen"
    },
    {
      "x": 5,
      "y": 19,
      "z": -1,
      "name": "Plant_Leaves_Aspen"
    },
    {
      "x": 5,
      "y": 21,
      "z": -1,
      "name": "Plant_Leaves_Aspen"
    },
    {
      "x": 5,
      "y": 24,
      "z": -1,
      "name": "Plant_Leaves_Aspen"
    },
    {
      "x": 5,
      "y": 10,
      "z": 0,
      "name": "Plant_Leaves_Aspen"
    },
    {
      "x": 5,
      "y": 11,
      "z": 0,
      "name": "Plant_Leaves_Aspen"
    },
    {
      "x": 5,
      "y": 16,
      "z": 0,
      "name": "Plant_Leaves_Aspen"
    },
    {
      "x": 5,
      "y": 19,
      "z": 0,
      "name": "Plant_Leaves_Aspen"
    },
    {
      "x": 5,
      "y": 21,
      "z": 0,
      "name": "Plant_Leaves_Aspen"
    },
    {
      "x": 5,
      "y": 24,
      "z": 0,
      "name": "Plant_Leaves_Aspen"
    },
    {
      "x": 5,
      "y": -8,
      "z": 1,
      "name": "Wood_Birch_Trunk_Full"
    },
    {
      "x": 5,
      "y": -7,
      "z": 1,
      "name": "Wood_Birch_Trunk_Full"
    },
    {
      "x": 5,
      "y": 10,
      "z": 1,
      "name": "Plant_Leaves_Aspen"
    },
    {
      "x": 5,
      "y": 15,
      "z": 1,
      "name": "Wood_Birch_Branch_Corner",
      "rotation": 1
    },
    {
      "x": 5,
      "y": 16,
      "z": 1,
      "name": "Wood_Birch_Branch_Corner",
      "rotation": 9
    },
    {
      "x": 5,
      "y": 19,
      "z": 1,
      "name": "Plant_Leaves_Aspen"
    },
    {
      "x": 5,
      "y": 21,
      "z": 1,
      "name": "Plant_Leaves_Aspen"
    },
    {
      "x": 5,
      "y": 22,
      "z": 1,
      "name": "Plant_Leaves_Aspen"
    },
    {
      "x": 5,
      "y": 24,
      "z": 1,
      "name": "Plant_Leaves_Aspen"
    },
    {
      "x": 5,
      "y": 10,
      "z": 2,
      "name": "Plant_Leaves_Aspen"
    },
    {
      "x": 5,
      "y": 19,
      "z": 2,
      "name": "Plant_Leaves_Aspen"
    },
    {
      "x": 5,
      "y": 21,
      "z": 2,
      "name": "Plant_Leaves_Aspen"
    },
    {
      "x": 5,
      "y": 19,
      "z": 3,
      "name": "Plant_Leaves_Aspen"
    },
    {
      "x": 5,
      "y": 21,
      "z": 3,
      "name": "Plant_Leaves_Aspen"
    },
    {
      "x": 5,
      "y": 19,
      "z": 4,
      "name": "Plant_Leaves_Aspen"
    },
    {
      "x": 5,
      "y": 21,
      "z": 4,
      "name": "Plant_Leaves_Aspen"
    },
    {
      "x": 5,
      "y": 19,
      "z": 5,
      "name": "Plant_Leaves_Aspen"
    },
    {
      "x": 6,
      "y": 16,
      "z": -5,
      "name": "Plant_Leaves_Aspen"
    },
    {
      "x": 6,
      "y": 10,
      "z": -4,
      "name": "Plant_Leaves_Aspen"
    },
    {
      "x": 6,
      "y": 16,
      "z": -4,
      "name": "Plant_Leaves_Aspen"
    },
    {
      "x": 6,
      "y": 10,
      "z": -3,
      "name": "Plant_Leaves_Aspen"
    },
    {
      "x": 6,
      "y": 16,
      "z": -3,
      "name": "Plant_Leaves_Aspen"
    },
    {
      "x": 6,
      "y": 10,
      "z": -2,
      "name": "Plant_Leaves_Aspen"
    },
    {
      "x": 6,
      "y": 16,
      "z": -2,
      "name": "Plant_Leaves_Aspen"
    },
    {
      "x": 6,
      "y": 10,
      "z": -1,
      "name": "Plant_Leaves_Aspen"
    },
    {
      "x": 6,
      "y": 11,
      "z": -1,
      "name": "Plant_Leaves_Aspen"
    },
    {
      "x": 6,
      "y": 16,
      "z": -1,
      "name": "Plant_Leaves_Aspen"
    },
    {
      "x": 6,
      "y": 19,
      "z": -1,
      "name": "Plant_Leaves_Aspen"
    },
    {
      "x": 6,
      "y": 21,
      "z": -1,
      "name": "Plant_Leaves_Aspen"
    },
    {
      "x": 6,
      "y": 10,
      "z": 0,
      "name": "Plant_Leaves_Aspen"
    },
    {
      "x": 6,
      "y": 19,
      "z": 0,
      "name": "Plant_Leaves_Aspen"
    },
    {
      "x": 6,
      "y": 21,
      "z": 0,
      "name": "Plant_Leaves_Aspen"
    },
    {
      "x": 6,
      "y": 10,
      "z": 1,
      "name": "Plant_Leaves_Aspen"
    },
    {
      "x": 6,
      "y": 16,
      "z": 1,
      "name": "Wood_Birch_Branch_Long",
      "rotation": 5
    },
    {
      "x": 6,
      "y": 19,
      "z": 1,
      "name": "Plant_Leaves_Aspen"
    },
    {
      "x": 6,
      "y": 21,
      "z": 1,
      "name": "Plant_Leaves_Aspen"
    },
    {
      "x": 6,
      "y": 10,
      "z": 2,
      "name": "Plant_Leaves_Aspen"
    },
    {
      "x": 6,
      "y": 19,
      "z": 2,
      "name": "Plant_Leaves_Aspen"
    },
    {
      "x": 6,
      "y": 20,
      "z": 2,
      "name": "Plant_Leaves_Aspen"
    },
    {
      "x": 6,
      "y": 21,
      "z": 2,
      "name": "Plant_Leaves_Aspen"
    },
    {
      "x": 6,
      "y": 19,
      "z": 3,
      "name": "Plant_Leaves_Aspen"
    },
    {
      "x": 6,
      "y": 21,
      "z": 3,
      "name": "Plant_Leaves_Aspen"
    },
    {
      "x": 6,
      "y": 19,
      "z": 4,
      "name": "Plant_Leaves_Aspen"
    },
    {
      "x": 6,
      "y": 19,
      "z": 5,
      "name": "Plant_Leaves_Aspen"
    },
    {
      "x": 7,
      "y": 10,
      "z": -3,
      "name": "Plant_Leaves_Aspen"
    },
    {
      "x": 7,
      "y": 10,
      "z": -2,
      "name": "Plant_Leaves_Aspen"
    },
    {
      "x": 7,
      "y": 19,
      "z": -2,
      "name": "Plant_Leaves_Aspen"
    },
    {
      "x": 7,
      "y": 10,
      "z": -1,
      "name": "Plant_Leaves_Aspen"
    },
    {
      "x": 7,
      "y": 19,
      "z": -1,
      "name": "Plant_Leaves_Aspen"
    },
    {
      "x": 7,
      "y": 10,
      "z": 0,
      "name": "Plant_Leaves_Aspen"
    },
    {
      "x": 7,
      "y": 19,
      "z": 0,
      "name": "Plant_Leaves_Aspen"
    },
    {
      "x": 7,
      "y": 21,
      "z": 0,
      "name": "Plant_Leaves_Aspen"
    },
    {
      "x": 7,
      "y": 10,
      "z": 1,
      "name": "Plant_Leaves_Aspen"
    },
    {
      "x": 7,
      "y": 16,
      "z": 1,
      "name": "Wood_Birch_Branch_Corner",
      "rotation": 1
    },
    {
      "x": 7,
      "y": 17,
      "z": 1,
      "name": "Wood_Birch_Branch_Corner",
      "rotation": 8
    },
    {
      "x": 7,
      "y": 19,
      "z": 1,
      "name": "Plant_Leaves_Aspen"
    },
    {
      "x": 7,
      "y": 20,
      "z": 1,
      "name": "Plant_Leaves_Aspen"
    },
    {
      "x": 7,
      "y": 21,
      "z": 1,
      "name": "Plant_Leaves_Aspen"
    },
    {
      "x": 7,
      "y": 17,
      "z": 2,
      "name": "Wood_Birch_Branch_Corner"
    },
    {
      "x": 7,
      "y": 18,
      "z": 2,
      "name": "Wood_Birch_Branch_Long"
    },
    {
      "x": 7,
      "y": 19,
      "z": 2,
      "name": "Wood_Birch_Branch_Long"
    },
    {
      "x": 7,
      "y": 20,
      "z": 2,
      "name": "Plant_Leaves_Aspen"
    },
    {
      "x": 7,
      "y": 21,
      "z": 2,
      "name": "Plant_Leaves_Aspen"
    },
    {
      "x": 7,
      "y": 19,
      "z": 3,
      "name": "Plant_Leaves_Aspen"
    },
    {
      "x": 7,
      "y": 20,
      "z": 3,
      "name": "Plant_Leaves_Aspen"
    },
    {
      "x": 7,
      "y": 19,
      "z": 4,
      "name": "Plant_Leaves_Aspen"
    },
    {
      "x": 7,
      "y": 19,
      "z": 5,
      "name": "Plant_Leaves_Aspen"
    },
    {
      "x": 7,
      "y": 19,
      "z": 6,
      "name": "Plant_Leaves_Aspen"
    },
    {
      "x": 8,
      "y": 10,
      "z": -2,
      "name": "Plant_Leaves_Aspen"
    },
    {
      "x": 8,
      "y": 10,
      "z": -1,
      "name": "Plant_Leaves_Aspen"
    },
    {
      "x": 8,
      "y": 19,
      "z": -1,
      "name": "Plant_Leaves_Aspen"
    },
    {
      "x": 8,
      "y": 10,
      "z": 0,
      "name": "Plant_Leaves_Aspen"
    },
    {
      "x": 8,
      "y": 19,
      "z": 0,
      "name": "Plant_Leaves_Aspen"
    },
    {
      "x": 8,
      "y": 19,
      "z": 1,
      "name": "Plant_Leaves_Aspen"
    },
    {
      "x": 8,
      "y": 19,
      "z": 2,
      "name": "Plant_Leaves_Aspen"
    },
    {
      "x": 8,
      "y": 20,
      "z": 2,
      "name": "Plant_Leaves_Aspen"
    },
    {
      "x": 8,
      "y": 19,
      "z": 3,
      "name": "Plant_Leaves_Aspen"
    },
    {
      "x": 8,
      "y": 19,
      "z": 4,
      "name": "Plant_Leaves_Aspen"
    },
    {
      "x": 8,
      "y": 19,
      "z": 5,
      "name": "Plant_Leaves_Aspen"
    },
    {
      "x": 9,
      "y": 19,
      "z": -1,
      "name": "Plant_Leaves_Aspen"
    },
    {
      "x": 9,
      "y": 19,
      "z": 0,
      "name": "Plant_Leaves_Aspen"
    },
    {
      "x": 9,
      "y": 19,
      "z": 1,
      "name": "Plant_Leaves_Aspen"
    },
    {
      "x": 9,
      "y": 19,
      "z": 2,
      "name": "Plant_Leaves_Aspen"
    },
    {
      "x": 9,
      "y": 19,
      "z": 3,
      "name": "Plant_Leaves_Aspen"
    },
    {
      "x": 9,
      "y": 19,
      "z": 4,
      "name": "Plant_Leaves_Aspen"
    },
    {
      "x": 9,
      "y": 19,
      "z": 5,
      "name": "Plant_Leaves_Aspen"
    },
    {
      "x": 10,
      "y": 19,
      "z": 0,
      "name": "Plant_Leaves_Aspen"
    },
    {
      "x": 10,
      "y": 19,
      "z": 1,
      "name": "Plant_Leaves_Aspen"
    },
    {
      "x": 10,
      "y": 19,
      "z": 2,
      "name": "Plant_Leaves_Aspen"
    },
    {
      "x": 10,
      "y": 19,
      "z": 3,
      "name": "Plant_Leaves_Aspen"
    },
    {
      "x": 10,
      "y": 19,
      "z": 4,
      "name": "Plant_Leaves_Aspen"
    }
  ]
}