{
  "version": 8,
  "blockIdVersion": 11,
  "anchorX": 0,
  "anchorY": 0,
  "anchorZ": 0,
  "blocks": [
    {
      "x": -4,
      "y": 4,
      "z": -1,
      "name": "Rock_Crystal_Blue_Small",
      "rotation": 8
    },
    {
      "x": -4,
      "y": 5,
      "z": -1,
      "name": "Plant_Coral_Block_Blue"
    },
    {
      "x": -4,
      "y": 5,
      "z": 0,
      "name": "Plant_Coral_Block_Blue"
    },
    {
      "x": -4,
      "y": 5,
      "z": 1,
      "name": "Plant_Coral_Block_Blue"
    },
    {
      "x": -4,
      "y": 6,
      "z": 1,
      "name": "Plant_Coral_Bush_Blue"
    },
    {
      "x": -3,
      "y": 5,
      "z": -2,
      "name": "Plant_Coral_Block_Blue"
    },
    {
      "x": -3,
      "y": 5,
      "z": -1,
      "name": "Plant_Coral_Block_Blue"
    },
    {
      "x": -3,
      "y": 9,
      "z": -1,
      "name": "Wood_Ice_Branch_Corner",
      "support": 15,
      "rotation": 2
    },
    {
      "x": -3,
      "y": 10,
      "z": -1,
      "name": "Wood_Ice_Branch_Corner",
      "support": 15,
      "rotation": 9
    },
    {
      "x": -3,
      "y": 4,
      "z": 0,
      "name": "Wood_Ice_Roots"
    },
    {
      "x": -3,
      "y": 5,
      "z": 0,
      "name": "Plant_Coral_Block_Blue"
    },
    {
      "x": -3,
      "y": 6,
      "z": 0,
      "name": "Plant_Coral_Model_Blue"
    },
    {
      "x": -3,
      "y": 9,
      "z": 0,
      "name": "Wood_Ice_Branch_Corner",
      "support": 15
    },
    {
      "x": -3,
      "y": 10,
      "z": 0,
      "name": "Wood_Ice_Branch_Corner",
      "support": 15,
      "rotation": 11
    },
    {
      "x": -3,
      "y": 5,
      "z": 1,
      "name": "Plant_Coral_Block_Blue"
    },
    {
      "x": -3,
      "y": 5,
      "z": 2,
      "name": "Plant_Coral_Block_Blue"
    },
    {
      "x": -2,
      "y": 12,
      "z": -3,
      "name": "Plant_Coral_Block_Blue"
    },
    {
      "x": -2,
      "y": 13,
      "z": -3,
      "name": "Plant_Coral_Bush_Blue"
    },
    {
      "x": -2,
      "y": 5,
      "z": -2,
      "name": "Plant_Coral_Block_Blue"
    },
    {
      "x": -2,
      "y": 12,
      "z": -2,
      "name": "Plant_Coral_Block_Blue"
    },
    {
      "x": -2,
      "y": 4,
      "z": -1,
      "name": "Rock_Crystal_Blue_Medium",
      "rotation": 8
    },
    {
      "x": -2,
      "y": 5,
      "z": -1,
      "name": "Plant_Coral_Block_Blue"
    },
    {
      "x": -2,
      "y": 6,
      "z": -1,
      "name": "Plant_Coral_Bush_Blue"
    },
    {
      "x": -2,
      "y": 8,
      "z": -1,
      "name": "Plant_Coral_Block_Blue"
    },
    {
      "x": -2,
      "y": 10,
      "z": -1,
      "name": "Wood_Ice_Branch_Long",
      "support": 15,
      "rotation": 5
    },
    {
      "x": -2,
      "y": 12,
      "z": -1,
      "name": "Plant_Coral_Block_Blue"
    },
    {
      "x": -2,
      "y": 5,
      "z": 0,
      "name": "Plant_Coral_Block_Blue"
    },
    {
      "x": -2,
      "y": 6,
      "z": 0,
      "name": "Rock_Crystal_Blue_Large"
    },
    {
      "x": -2,
      "y": 8,
      "z": 0,
      "name": "Plant_Coral_Block_Blue"
    },
    {
      "x": -2,
      "y": 4,
      "z": 1,
      "name": "Wood_Ice_Roots"
    },
    {
      "x": -2,
      "y": 5,
      "z": 1,
      "name": "Plant_Coral_Block_Blue"
    },
    {
      "x": -2,
      "y": 8,
      "z": 1,
      "name": "Plant_Coral_Block_Blue"
    },
    {
      "x": -2,
      "y": 9,
      "z": 1,
      "name": "Plant_Coral_Bush_Blue"
    },
    {
      "x": -2,
      "y": 5,
      "z": 2,
      "name": "Plant_Coral_Block_Blue"
    },
    {
      "x": -2,
      "y": 6,
      "z": 2,
      "name": "Plant_Coral_Model_Blue"
    },
    {
      "x": -1,
      "y": 12,
      "z": -4,
      "name": "Plant_Coral_Block_Blue"
    },
    {
      "x": -1,
      "y": 12,
      "z": -3,
      "name": "Plant_Coral_Block_Blue"
    },
    {
      "x": -1,
      "y": 5,
      "z": -2,
      "name": "Plant_Coral_Block_Blue"
    },
    {
      "x": -1,
      "y": 6,
      "z": -2,
      "name": "Rock_Crystal_Blue_Small"
    },
    {
      "x": -1,
      "y": 11,
      "z": -2,
      "name": "Wood_Ice_Roots"
    },
    {
      "x": -1,
      "y": 12,
      "z": -2,
      "name": "Plant_Coral_Block_Blue"
    },
    {
      "x": -1,
      "y": 5,
      "z": -1,
      "name": "Plant_Coral_Block_Blue"
    },
    {
      "x": -1,
      "y": 8,
      "z": -1,
      "name": "Plant_Coral_Block_Blue"
    },
    {
      "x": -1,
      "y": 9,
      "z": -1,
      "name": "Wood_Ice_Trunk_Full",
      "support": 15
    },
    {
      "x": -1,
      "y": 10,
      "z": -1,
      "name": "Wood_Ice_Trunk_Full",
      "support": 15
    },
    {
      "x": -1,
      "y": 11,
      "z": -1,
      "name": "Wood_Ice_Trunk_Half",
      "rotation": 7
    },
    {
      "x": -1,
      "y": 12,
      "z": -1,
      "name": "Plant_Coral_Block_Blue"
    },
    {
      "x": -1,
      "y": -1,
      "z": 0,
      "name": "Wood_Ice_Trunk_Full",
      "support": 15
    },
    {
      "x": -1,
      "y": 0,
      "z": 0,
      "name": "Wood_Ice_Trunk_Full",
      "support": 15
    },
    {
      "x": -1,
      "y": 2,
      "z": 0,
      "name": "Wood_Ice_Trunk_Full",
      "support": 15
    },
    {
      "x": -1,
      "y": 3,
      "z": 0,
      "name": "Wood_Ice_Trunk",
      "support": 15
    },
    {
      "x": -1,
      "y": 4,
      "z": 0,
      "name": "Wood_Ice_Trunk_Full",
      "support": 15
    },
    {
      "x": -1,
      "y": 5,
      "z": 0,
      "name": "Plant_Coral_Block_Blue"
    },
    {
      "x": -1,
      "y": 7,
      "z": 0,
      "name": "Wood_Ice_Trunk_Full",
      "support": 15
    },
    {
      "x": -1,
      "y": 8,
      "z": 0,
      "name": "Wood_Ice_Trunk_Full",
      "support": 15
    },
    {
      "x": -1,
      "y": 9,
      "z": 0,
      "name": "Wood_Ice_Trunk_Full",
      "support": 15
    },
    {
      "x": -1,
      "y": 12,
      "z": 0,
      "name": "Plant_Coral_Block_Blue"
    },
    {
      "x": -1,
      "y": 4,
      "z": 1,
      "name": "Wood_Ice_Trunk_Full",
      "support": 15
    },
    {
      "x": -1,
      "y": 5,
      "z": 1,
      "name": "Wood_Ice_Trunk",
      "support": 15
    },
    {
      "x": -1,
      "y": 6,
      "z": 1,
      "name": "Wood_Ice_Trunk",
      "support": 15
    },
    {
      "x": -1,
      "y": 7,
      "z": 1,
      "name": "Wood_Ice_Trunk_Full",
      "support": 15
    },
    {
      "x": -1,
      "y": 8,
      "z": 1,
      "name": "Plant_Coral_Block_Blue"
    },
    {
      "x": -1,
      "y": 4,
      "z": 2,
      "name": "Rock_Crystal_Blue_Medium",
      "rotation": 8
    },
    {
      "x": -1,
      "y": 5,
      "z": 2,
      "name": "Plant_Coral_Block_Blue"
    },
    {
      "x": -1,
      "y": 6,
      "z": 2,
      "name": "Plant_Coral_Bush_Blue"
    },
    {
      "x": -1,
      "y": 9,
      "z": 3,
      "name": "Plant_Coral_Block_Blue"
    },
    {
      "x": -1,
      "y": 10,
      "z": 3,
      "name": "Plant_Coral_Model_Blue"
    },
    {
      "x": -1,
      "y": 9,
      "z": 4,
      "name": "Plant_Coral_Block_Blue"
    },
    {
      "x": -1,
      "y": 9,
      "z": 5,
      "name": "Plant_Coral_Block_Blue"
    },
    {
      "x": 0,
      "y": 12,
      "z": -4,
      "name": "Plant_Coral_Block_Blue"
    },
    {
      "x": 0,
      "y": 13,
      "z": -4,
      "name": "Plant_Coral_Bush_Blue"
    },
    {
      "x": 0,
      "y": 10,
      "z": -3,
      "name": "Wood_Ice_Branch_Corner",
      "support": 15,
      "rotation": 3
    },
    {
      "x": 0,
      "y": 11,
      "z": -3,
      "name": "Wood_Ice_Branch_Corner",
      "support": 15,
      "rotation": 8
    },
    {
      "x": 0,
      "y": 12,
      "z": -3,
      "name": "Plant_Coral_Block_Blue"
    },
    {
      "x": 0,
      "y": 13,
      "z": -3,
      "name": "Plant_Coral_Model_Blue"
    },
    {
      "x": 0,
      "y": 11,
      "z": -2,
      "name": "Wood_Ice_Trunk",
      "support": 15,
      "rotation": 4
    },
    {
      "x": 0,
      "y": 12,
      "z": -2,
      "name": "Plant_Coral_Block_Blue"
    },
    {
      "x": 0,
      "y": -1,
      "z": -1,
      "name": "Wood_Ice_Trunk_Full",
      "support": 15
    },
    {
      "x": 0,
      "y": 0,
      "z": -1,
      "name": "Wood_Ice_Trunk",
      "support": 15
    },
    {
      "x": 0,
      "y": 1,
      "z": -1,
      "name": "Wood_Ice_Trunk_Full",
      "support": 15
    },
    {
      "x": 0,
      "y": 2,
      "z": -1,
      "name": "Plant_Coral_Block_Blue"
    },
    {
      "x": 0,
      "y": 5,
      "z": -1,
      "name": "Plant_Coral_Block_Blue"
    },
    {
      "x": 0,
      "y": 6,
      "z": -1,
      "name": "Rock_Crystal_Blue_Small"
    },
    {
      "x": 0,
      "y": 9,
      "z": -1,
      "name": "Wood_Ice_Roots"
    },
    {
      "x": 0,
      "y": 10,
      "z": -1,
      "name": "Wood_Ice_Trunk_Full",
      "support": 15
    },
    {
      "x": 0,
      "y": 11,
      "z": -1,
      "name": "Wood_Ice_Trunk",
      "support": 15
    },
    {
      "x": 0,
      "y": 12,
      "z": -1,
      "name": "Plant_Coral_Block_Blue"
    },
    {
      "x": 0,
      "y": 13,
      "z": -1,
      "name": "Plant_Coral_Bush_Blue"
    },
    {
      "x": 0,
      "y": -1,
      "z": 0,
      "name": "Wood_Ice_Trunk_Full",
      "support": 15
    },
    {
      "x": 0,
      "y": 0,
      "z": 0,
      "name": "Wood_Ice_Trunk",
      "support": 15
    },
    {
      "x": 0,
      "y": 1,
      "z": 0,
      "name": "Wood_Ice_Trunk",
      "support": 15
    },
    {
      "x": 0,
      "y": 2,
      "z": 0,
      "name": "Wood_Ice_Trunk",
      "support": 15
    },
    {
      "x": 0,
      "y": 3,
      "z": 0,
      "name": "Wood_Ice_Trunk_Full",
      "support": 15
    },
    {
      "x": 0,
      "y": 5,
      "z": 0,
      "name": "Plant_Coral_Block_Blue"
    },
    {
      "x": 0,
      "y": 7,
      "z": 0,
      "name": "Wood_Ice_Branch_Long",
      "support": 15,
      "rotation": 5
    },
    {
      "x": 0,
      "y": 12,
      "z": 0,
      "name": "Plant_Coral_Block_Blue"
    },
    {
      "x": 0,
      "y": -1,
      "z": 1,
      "name": "Wood_Ice_Trunk_Full",
      "support": 15
    },
    {
      "x": 0,
      "y": 2,
      "z": 1,
      "name": "Wood_Ice_Trunk_Full",
      "support": 15
    },
    {
      "x": 0,
      "y": 3,
      "z": 1,
      "name": "Wood_Ice_Trunk",
      "support": 15
    },
    {
      "x": 0,
      "y": 4,
      "z": 1,
      "name": "Wood_Ice_Trunk",
      "support": 15
    },
    {
      "x": 0,
      "y": 5,
      "z": 1,
      "name": "Plant_Coral_Block_Blue"
    },
    {
      "x": 0,
      "y": 5,
      "z": 2,
      "name": "Wood_Ice_Trunk_Full",
      "support": 15
    },
    {
      "x": 0,
      "y": 6,
      "z": 2,
      "name": "Wood_Ice_Trunk",
      "support": 15
    },
    {
      "x": 0,
      "y": 7,
      "z": 2,
      "name": "Wood_Ice_Trunk_Full",
      "support": 15
    },
    {
      "x": 0,
      "y": 9,
      "z": 2,
      "name": "Plant_Coral_Block_Blue"
    },
    {
      "x": 0,
      "y": 9,
      "z": 3,
      "name": "Plant_Coral_Block_Blue"
    },
    {
      "x": 0,
      "y": 8,
      "z": 4,
      "name": "Rock_Crystal_Blue_Medium",
      "rotation": 8
    },
    {
      "x": 0,
      "y": 9,
      "z": 4,
      "name": "Plant_Coral_Block_Blue"
    },
    {
      "x": 0,
      "y": 10,
      "z": 4,
      "name": "Plant_Coral_Bush_Blue"
    },
    {
      "x": 0,
      "y": 9,
      "z": 5,
      "name": "Plant_Coral_Block_Blue"
    },
    {
      "x": 0,
      "y": 10,
      "z": 5,
      "name": "Rock_Crystal_Blue_Medium"
    },
    {
      "x": 0,
      "y": 9,
      "z": 6,
      "name": "Plant_Coral_Block_Blue"
    },
    {
      "x": 0,
      "y": 10,
      "z": 6,
      "name": "Plant_Coral_Model_Blue"
    },
    {
      "x": 1,
      "y": 12,
      "z": -4,
      "name": "Plant_Coral_Block_Blue"
    },
    {
      "x": 1,
      "y": 9,
      "z": -3,
      "name": "Wood_Ice_Branch_Corner",
      "support": 15,
      "rotation": 1
    },
    {
      "x": 1,
      "y": 10,
      "z": -3,
      "name": "Wood_Ice_Branch_Corner",
      "support": 15,
      "rotation": 11
    },
    {
      "x": 1,
      "y": 12,
      "z": -3,
      "name": "Plant_Coral_Block_Blue"
    },
    {
      "x": 1,
      "y": 11,
      "z": -2,
      "name": "Rock_Crystal_Blue_Large",
      "rotation": 8
    },
    {
      "x": 1,
      "y": 12,
      "z": -2,
      "name": "Plant_Coral_Block_Blue"
    },
    {
      "x": 1,
      "y": 13,
      "z": -2,
      "name": "Plant_Coral_Model_Violet"
    },
    {
      "x": 1,
      "y": 1,
      "z": -1,
      "name": "Rock_Crystal_Blue_Small",
      "rotation": 8
    },
    {
      "x": 1,
      "y": 2,
      "z": -1,
      "name": "Plant_Coral_Block_Blue"
    },
    {
      "x": 1,
      "y": 11,
      "z": -1,
      "name": "Wood_Ice_Roots"
    },
    {
      "x": 1,
      "y": 12,
      "z": -1,
      "name": "Plant_Coral_Block_Blue"
    },
    {
      "x": 1,
      "y": -1,
      "z": 0,
      "name": "Wood_Ice_Trunk_Full",
      "support": 15
    },
    {
      "x": 1,
      "y": 0,
      "z": 0,
      "name": "Wood_Ice_Trunk_Full",
      "support": 15
    },
    {
      "x": 1,
      "y": 2,
      "z": 0,
      "name": "Plant_Coral_Block_Blue"
    },
    {
      "x": 1,
      "y": 3,
      "z": 0,
      "name": "Plant_Coral_Model_Blue"
    },
    {
      "x": 1,
      "y": 7,
      "z": 0,
      "name": "Wood_Ice_Branch_Long",
      "support": 15,
      "rotation": 5
    },
    {
      "x": 1,
      "y": 12,
      "z": 0,
      "name": "Plant_Coral_Block_Blue"
    },
    {
      "x": 1,
      "y": 13,
      "z": 0,
      "name": "Plant_Coral_Model_Blue"
    },
    {
      "x": 1,
      "y": 3,
      "z": 1,
      "name": "Wood_Ice_Branch_Corner",
      "support": 15,
      "rotation": 1
    },
    {
      "x": 1,
      "y": 4,
      "z": 1,
      "name": "Wood_Ice_Branch_Corner",
      "support": 15,
      "rotation": 9
    },
    {
      "x": 1,
      "y": 6,
      "z": 2,
      "name": "Wood_Ice_Roots"
    },
    {
      "x": 1,
      "y": 7,
      "z": 2,
      "name": "Wood_Ice_Trunk_Full",
      "support": 15
    },
    {
      "x": 1,
      "y": 8,
      "z": 2,
      "name": "Wood_Ice_Trunk",
      "support": 15
    },
    {
      "x": 1,
      "y": 9,
      "z": 2,
      "name": "Plant_Coral_Block_Blue"
    },
    {
      "x": 1,
      "y": 10,
      "z": 2,
      "name": "Plant_Coral_Bush_Blue"
    },
    {
      "x": 1,
      "y": 7,
      "z": 3,
      "name": "Wood_Ice_Branch_Corner",
      "support": 15,
      "rotation": 2
    },
    {
      "x": 1,
      "y": 8,
      "z": 3,
      "name": "Wood_Ice_Branch_Corner",
      "support": 15,
      "rotation": 8
    },
    {
      "x": 1,
      "y": 9,
      "z": 3,
      "name": "Plant_Coral_Block_Blue"
    },
    {
      "x": 1,
      "y": 7,
      "z": 4,
      "name": "Wood_Ice_Trunk_Full",
      "support": 15,
      "rotation": 4
    },
    {
      "x": 1,
      "y": 9,
      "z": 4,
      "name": "Plant_Coral_Block_Blue"
    },
    {
      "x": 1,
      "y": 7,
      "z": 5,
      "name": "Wood_Ice_Trunk_Stairs",
      "rotation": 10
    },
    {
      "x": 1,
      "y": 8,
      "z": 5,
      "name": "Wood_Ice_Trunk",
      "support": 15
    },
    {
      "x": 1,
      "y": 9,
      "z": 5,
      "name": "Plant_Coral_Block_Blue"
    },
    {
      "x": 1,
      "y": 10,
      "z": 5,
      "name": "Plant_Coral_Model_Violet"
    },
    {
      "x": 1,
      "y": 9,
      "z": 6,
      "name": "Plant_Coral_Block_Blue"
    },
    {
      "x": 2,
      "y": 11,
      "z": -3,
      "name": "Rock_Crystal_Blue_Small",
      "rotation": 8
    },
    {
      "x": 2,
      "y": 12,
      "z": -3,
      "name": "Plant_Coral_Block_Blue"
    },
    {
      "x": 2,
      "y": 12,
      "z": -2,
      "name": "Plant_Coral_Block_Blue"
    },
    {
      "x": 2,
      "y": 7,
      "z": -1,
      "name": "Wood_Ice_Branch_Corner",
      "support": 15
    },
    {
      "x": 2,
      "y": 8,
      "z": -1,
      "name": "Wood_Ice_Branch_Corner",
      "support": 15,
      "rotation": 8
    },
    {
      "x": 2,
      "y": 11,
      "z": -1,
      "name": "Rock_Crystal_Blue_Small",
      "rotation": 8
    },
    {
      "x": 2,
      "y": 12,
      "z": -1,
      "name": "Plant_Coral_Block_Blue"
    },
    {
      "x": 2,
      "y": 7,
      "z": 0,
      "name": "Wood_Ice_Branch_Corner",
      "support": 15,
      "rotation": 1
    },
    {
      "x": 2,
      "y": 8,
      "z": 0,
      "name": "Wood_Ice_Branch_Corner",
      "support": 15,
      "rotation": 10
    },
    {
      "x": 2,
      "y": 2,
      "z": 1,
      "name": "Wood_Ice_Branch_Corner",
      "support": 15,
      "rotation": 3
    },
    {
      "x": 2,
      "y": 4,
      "z": 1,
      "name": "Wood_Ice_Branch_Long",
      "support": 15,
      "rotation": 5
    },
    {
      "x": 2,
      "y": 8,
      "z": 2,
      "name": "Rock_Crystal_Blue_Small",
      "rotation": 8
    },
    {
      "x": 2,
      "y": 9,
      "z": 2,
      "name": "Plant_Coral_Block_Blue"
    },
    {
      "x": 2,
      "y": 9,
      "z": 3,
      "name": "Plant_Coral_Block_Blue"
    },
    {
      "x": 2,
      "y": 10,
      "z": 3,
      "name": "Plant_Coral_Model_Violet"
    },
    {
      "x": 2,
      "y": 9,
      "z": 4,
      "name": "Plant_Coral_Block_Blue"
    },
    {
      "x": 2,
      "y": 8,
      "z": 5,
      "name": "Rock_Crystal_Blue_Small",
      "rotation": 8
    },
    {
      "x": 2,
      "y": 9,
      "z": 5,
      "name": "Plant_Coral_Block_Blue"
    },
    {
      "x": 2,
      "y": 10,
      "z": 5,
      "name": "Plant_Coral_Bush_Blue"
    },
    {
      "x": 2,
      "y": 9,
      "z": 6,
      "name": "Plant_Coral_Block_Blue"
    },
    {
      "x": 3,
      "y": 2,
      "z": 1,
      "name": "Wood_Ice_Branch_Corner",
      "support": 15,
      "rotation": 1
    },
    {
      "x": 3,
      "y": 3,
      "z": 1,
      "name": "Wood_Ice_Branch_Long",
      "support": 15
    },
    {
      "x": 3,
      "y": 4,
      "z": 1,
      "name": "Wood_Ice_Branch_Corner",
      "support": 15,
      "rotation": 11
    },
    {
      "x": 3,
      "y": 9,
      "z": 3,
      "name": "Plant_Coral_Block_Blue"
    },
    {
      "x": 3,
      "y": 10,
      "z": 3,
      "name": "Plant_Coral_Model_Blue"
    },
    {
      "x": 3,
      "y": 8,
      "z": 4,
      "name": "Rock_Crystal_Blue_Small",
      "rotation": 8
    },
    {
      "x": 3,
      "y": 9,
      "z": 4,
      "name": "Plant_Coral_Block_Blue"
    },
    {
      "x": 3,
      "y": 9,
      "z": 5,
      "name": "Plant_Coral_Block_Blue"
    }
  ]
}